Workbook

Sheet Mode d'emploi
A1: 2 · Une page par semaine
A2: Proposition de tableau de gestion des stocks — Excel et Google Sheets
A4: L'idée | B4: Chaque semaine a son propre onglet, avec seulement quelques colonnes : c'est lisible même sur téléphone. Un onglet Récap additionne les 4 semaines tout seul.
A6: Comment faire | B6: 1. Remplis l'onglet Produits une seule fois.
B7: 2. Chaque semaine, ouvre l'onglet de la semaine : Stock et Commandé le vendredi, Reçu à la livraison.
B8: 3. L'onglet Récap du mois se met à jour tout seul : total commandé, total reçu, dernier stock compté.
B9: 4. Nouveau mois : Fichier > Faire une copie, puis efface les cases jaunes des 4 semaines.
A11: Les onglets | B11: Produits — ta liste.
B12: Semaine 1 à Semaine 4 — une page par semaine.
B13: Récap du mois — les totaux, calculés.
A15: Couleurs | B15: Cases jaunes = à remplir. Cases blanches = calculées toutes seules, ne pas y toucher.
B16: Chiffres en bleu = exemple pour montrer le fonctionnement, à effacer.
B17: Rouge = il manque quelque chose (livraison incomplète, stock trop bas).
A19: Google Sheets | B19: Fichier > Importer > Importer ce fichier. Tout fonctionne pareil, y compris sur téléphone.

Sheet Produits
A1: Mes produits
A2: Une ligne par produit. Tout le reste du fichier se remplit à partir de cette liste.
A4: Produit | B4: Fournisseur | C4: Unité
A5: Farine T55 | B5: Metro | C5: kg
A6: Farine T45 | B6: Metro | C6: kg
A7: Sucre semoule | B7: Metro | C7: kg
A8: Sucre glace | B8: Metro | C8: kg
A9: Beurre doux | B9: Crèmerie | C9: kg
A10: Crème liquide 35% | B10: Crèmerie | C10: L
A11: Lait entier | B11: Crèmerie | C11: L
A12: Oeufs | B12: Crèmerie | C12: pièce
A13: Chocolat blanc | B13: Transgourmet | C13: kg
A14: Chocolat noir 70% | B14: Transgourmet | C14: kg
A15: Levure chimique | B15: Transgourmet | C15: kg
A16: Vanille (gousse) | B16: Transgourmet | C16: pièce

Sheet Semaine 1
A1: Semaine 1
A2: Stock = ce qu'il reste · Commandé = ce que tu demandes · Reçu = ce qui est arrivé
A3: Date du comptage :
A5: Produit | B5: Fournisseur | C5: Unité | D5: Stock | E5: Commandé | F5: Reçu | G5: Écart | H5: Total dispo
A6: =IF(Produits!$A$5="","",Produits!$A$5) | B6: =IF(Produits!$A$5="","",Produits!$B$5) | C6: =IF(Produits!$A$5="","",Produits!$C$5) | D6: 8 | E6: 10 | F6: 7 | G6: =IF(OR(E6="",F6=""),"",F6-E6) | H6: =IF(AND(D6="",F6=""),"",N(D6)+N(F6))
A7: =IF(Produits!$A$6="","",Produits!$A$6) | B7: =IF(Produits!$A$6="","",Produits!$B$6) | C7: =IF(Produits!$A$6="","",Produits!$C$6) | D7: 2 | E7: 5 | F7: 5 | G7: =IF(OR(E7="",F7=""),"",F7-E7) | H7: =IF(AND(D7="",F7=""),"",N(D7)+N(F7))
A8: =IF(Produits!$A$7="","",Produits!$A$7) | B8: =IF(Produits!$A$7="","",Produits!$B$7) | C8: =IF(Produits!$A$7="","",Produits!$C$7) | D8: 6 | E8: 10 | F8: 10 | G8: =IF(OR(E8="",F8=""),"",F8-E8) | H8: =IF(AND(D8="",F8=""),"",N(D8)+N(F8))
A9: =IF(Produits!$A$8="","",Produits!$A$8) | B9: =IF(Produits!$A$8="","",Produits!$B$8) | C9: =IF(Produits!$A$8="","",Produits!$C$8) | D9: 1 | E9: 3 | F9: 3 | G9: =IF(OR(E9="",F9=""),"",F9-E9) | H9: =IF(AND(D9="",F9=""),"",N(D9)+N(F9))
A10: =IF(Produits!$A$9="","",Produits!$A$9) | B10: =IF(Produits!$A$9="","",Produits!$B$9) | C10: =IF(Produits!$A$9="","",Produits!$C$9) | D10: 3 | E10: 5 | F10: 5 | G10: =IF(OR(E10="",F10=""),"",F10-E10) | H10: =IF(AND(D10="",F10=""),"",N(D10)+N(F10))
A11: =IF(Produits!$A$10="","",Produits!$A$10) | B11: =IF(Produits!$A$10="","",Produits!$B$10) | C11: =IF(Produits!$A$10="","",Produits!$C$10) | D11: 4 | E11: 12 | F11: 12 | G11: =IF(OR(E11="",F11=""),"",F11-E11) | H11: =IF(AND(D11="",F11=""),"",N(D11)+N(F11))
A12: =IF(Produits!$A$11="","",Produits!$A$11) | B12: =IF(Produits!$A$11="","",Produits!$B$11) | C12: =IF(Produits!$A$11="","",Produits!$C$11) | D12: 3 | E12: 6 | F12: 6 | G12: =IF(OR(E12="",F12=""),"",F12-E12) | H12: =IF(AND(D12="",F12=""),"",N(D12)+N(F12))
A13: =IF(Produits!$A$12="","",Produits!$A$12) | B13: =IF(Produits!$A$12="","",Produits!$B$12) | C13: =IF(Produits!$A$12="","",Produits!$C$12) | D13: 40 | E13: 90 | F13: 90 | G13: =IF(OR(E13="",F13=""),"",F13-E13) | H13: =IF(AND(D13="",F13=""),"",N(D13)+N(F13))
A14: =IF(Produits!$A$13="","",Produits!$A$13) | B14: =IF(Produits!$A$13="","",Produits!$B$13) | C14: =IF(Produits!$A$13="","",Produits!$C$13) | D14: 1.5 | E14: 3 | F14: 2 | G14: =IF(OR(E14="",F14=""),"",F14-E14) | H14: =IF(AND(D14="",F14=""),"",N(D14)+N(F14))
A15: =IF(Produits!$A$14="","",Produits!$A$14) | B15: =IF(Produits!$A$14="","",Produits!$B$14) | C15: =IF(Produits!$A$14="","",Produits!$C$14) | D15: 2 | E15: 2 | F15: 2 | G15: =IF(OR(E15="",F15=""),"",F15-E15) | H15: =IF(AND(D15="",F15=""),"",N(D15)+N(F15))
A16: =IF(Produits!$A$15="","",Produits!$A$15) | B16: =IF(Produits!$A$15="","",Produits!$B$15) | C16: =IF(Produits!$A$15="","",Produits!$C$15) | D16: 0.4 | E16: 1 | F16: 1 | G16: =IF(OR(E16="",F16=""),"",F16-E16) | H16: =IF(AND(D16="",F16=""),"",N(D16)+N(F16))
A17: =IF(Produits!$A$16="","",Produits!$A$16) | B17: =IF(Produits!$A$16="","",Produits!$B$16) | C17: =IF(Produits!$A$16="","",Produits!$C$16) | D17: 6 | E17: 0 | F17: 0 | G17: =IF(OR(E17="",F17=""),"",F17-E17) | H17: =IF(AND(D17="",F17=""),"",N(D17)+N(F17))
A18: =IF(Produits!$A$17="","",Produits!$A$17) | B18: =IF(Produits!$A$17="","",Produits!$B$17) | C18: =IF(Produits!$A$17="","",Produits!$C$17) | G18: =IF(OR(E18="",F18=""),"",F18-E18) | H18: =IF(AND(D18="",F18=""),"",N(D18)+N(F18))
A19: =IF(Produits!$A$18="","",Produits!$A$18) | B19: =IF(Produits!$A$18="","",Produits!$B$18) | C19: =IF(Produits!$A$18="","",Produits!$C$18) | G19: =IF(OR(E19="",F19=""),"",F19-E19) | H19: =IF(AND(D19="",F19=""),"",N(D19)+N(F19))
A20: =IF(Produits!$A$19="","",Produits!$A$19) | B20: =IF(Produits!$A$19="","",Produits!$B$19) | C20: =IF(Produits!$A$19="","",Produits!$C$19) | G20: =IF(OR(E20="",F20=""),"",F20-E20) | H20: =IF(AND(D20="",F20=""),"",N(D20)+N(F20))
A21: =IF(Produits!$A$20="","",Produits!$A$20) | B21: =IF(Produits!$A$20="","",Produits!$B$20) | C21: =IF(Produits!$A$20="","",Produits!$C$20) | G21: =IF(OR(E21="",F21=""),"",F21-E21) | H21: =IF(AND(D21="",F21=""),"",N(D21)+N(F21))
A22: =IF(Produits!$A$21="","",Produits!$A$21) | B22: =IF(Produits!$A$21="","",Produits!$B$21) | C22: =IF(Produits!$A$21="","",Produits!$C$21) | G22: =IF(OR(E22="",F22=""),"",F22-E22) | H22: =IF(AND(D22="",F22=""),"",N(D22)+N(F22))
A23: =IF(Produits!$A$22="","",Produits!$A$22) | B23: =IF(Produits!$A$22="","",Produits!$B$22) | C23: =IF(Produits!$A$22="","",Produits!$C$22) | G23: =IF(OR(E23="",F23=""),"",F23-E23) | H23: =IF(AND(D23="",F23=""),"",N(D23)+N(F23))
A24: =IF(Produits!$A$23="","",Produits!$A$23) | B24: =IF(Produits!$A$23="","",Produits!$B$23) | C24: =IF(Produits!$A$23="","",Produits!$C$23) | G24: =IF(OR(E24="",F24=""),"",F24-E24) | H24: =IF(AND(D24="",F24=""),"",N(D24)+N(F24))
A25: =IF(Produits!$A$24="","",Produits!$A$24) | B25: =IF(Produits!$A$24="","",Produits!$B$24) | C25: =IF(Produits!$A$24="","",Produits!$C$24) | G25: =IF(OR(E25="",F25=""),"",F25-E25) | H25: =IF(AND(D25="",F25=""),"",N(D25)+N(F25))
A26: =IF(Produits!$A$25="","",Produits!$A$25) | B26: =IF(Produits!$A$25="","",Produits!$B$25) | C26: =IF(Produits!$A$25="","",Produits!$C$25) | G26: =IF(OR(E26="",F26=""),"",F26-E26) | H26: =IF(AND(D26="",F26=""),"",N(D26)+N(F26))
A27: =IF(Produits!$A$26="","",Produits!$A$26) | B27: =IF(Produits!$A$26="","",Produits!$B$26) | C27: =IF(Produits!$A$26="","",Produits!$C$26) | G27: =IF(OR(E27="",F27=""),"",F27-E27) | H27: =IF(AND(D27="",F27=""),"",N(D27)+N(F27))
A28: =IF(Produits!$A$27="","",Produits!$A$27) | B28: =IF(Produits!$A$27="","",Produits!$B$27) | C28: =IF(Produits!$A$27="","",Produits!$C$27) | G28: =IF(OR(E28="",F28=""),"",F28-E28) | H28: =IF(AND(D28="",F28=""),"",N(D28)+N(F28))
A29: =IF(Produits!$A$28="","",Produits!$A$28) | B29: =IF(Produits!$A$28="","",Produits!$B$28) | C29: =IF(Produits!$A$28="","",Produits!$C$28) | G29: =IF(OR(E29="",F29=""),"",F29-E29) | H29: =IF(AND(D29="",F29=""),"",N(D29)+N(F29))
A30: =IF(Produits!$A$29="","",Produits!$A$29) | B30: =IF(Produits!$A$29="","",Produits!$B$29) | C30: =IF(Produits!$A$29="","",Produits!$C$29) | G30: =IF(OR(E30="",F30=""),"",F30-E30) | H30: =IF(AND(D30="",F30=""),"",N(D30)+N(F30))
A31: =IF(Produits!$A$30="","",Produits!$A$30) | B31: =IF(Produits!$A$30="","",Produits!$B$30) | C31: =IF(Produits!$A$30="","",Produits!$C$30) | G31: =IF(OR(E31="",F31=""),"",F31-E31) | H31: =IF(AND(D31="",F31=""),"",N(D31)+N(F31))
A32: =IF(Produits!$A$31="","",Produits!$A$31) | B32: =IF(Produits!$A$31="","",Produits!$B$31) | C32: =IF(Produits!$A$31="","",Produits!$C$31) | G32: =IF(OR(E32="",F32=""),"",F32-E32) | H32: =IF(AND(D32="",F32=""),"",N(D32)+N(F32))
A33: =IF(Produits!$A$32="","",Produits!$A$32) | B33: =IF(Produits!$A$32="","",Produits!$B$32) | C33: =IF(Produits!$A$32="","",Produits!$C$32) | G33: =IF(OR(E33="",F33=""),"",F33-E33) | H33: =IF(AND(D33="",F33=""),"",N(D33)+N(F33))
A34: =IF(Produits!$A$33="","",Produits!$A$33) | B34: =IF(Produits!$A$33="","",Produits!$B$33) | C34: =IF(Produits!$A$33="","",Produits!$C$33) | G34: =IF(OR(E34="",F34=""),"",F34-E34) | H34: =IF(AND(D34="",F34=""),"",N(D34)+N(F34))
A35: =IF(Produits!$A$34="","",Produits!$A$34) | B35: =IF(Produits!$A$34="","",Produits!$B$34) | C35: =IF(Produits!$A$34="","",Produits!$C$34) | G35: =IF(OR(E35="",F35=""),"",F35-E35) | H35: =IF(AND(D35="",F35=""),"",N(D35)+N(F35))
A36: =IF(Produits!$A$35="","",Produits!$A$35) | B36: =IF(Produits!$A$35="","",Produits!$B$35) | C36: =IF(Produits!$A$35="","",Produits!$C$35) | G36: =IF(OR(E36="",F36=""),"",F36-E36) | H36: =IF(AND(D36="",F36=""),"",N(D36)+N(F36))
A37: =IF(Produits!$A$36="","",Produits!$A$36) | B37: =IF(Produits!$A$36="","",Produits!$B$36) | C37: =IF(Produits!$A$36="","",Produits!$C$36) | G37: =IF(OR(E37="",F37=""),"",F37-E37) | H37: =IF(AND(D37="",F37=""),"",N(D37)+N(F37))
A38: =IF(Produits!$A$37="","",Produits!$A$37) | B38: =IF(Produits!$A$37="","",Produits!$B$37) | C38: =IF(Produits!$A$37="","",Produits!$C$37) | G38: =IF(OR(E38="",F38=""),"",F38-E38) | H38: =IF(AND(D38="",F38=""),"",N(D38)+N(F38))
A39: =IF(Produits!$A$38="","",Produits!$A$38) | B39: =IF(Produits!$A$38="","",Produits!$B$38) | C39: =IF(Produits!$A$38="","",Produits!$C$38) | G39: =IF(OR(E39="",F39=""),"",F39-E39) | H39: =IF(AND(D39="",F39=""),"",N(D39)+N(F39))
A40: =IF(Produits!$A$39="","",Produits!$A$39) | B40: =IF(Produits!$A$39="","",Produits!$B$39) | C40: =IF(Produits!$A$39="","",Produits!$C$39) | G40: =IF(OR(E40="",F40=""),"",F40-E40) | H40: =IF(AND(D40="",F40=""),"",N(D40)+N(F40))
A41: =IF(Produits!$A$40="","",Produits!$A$40) | B41: =IF(Produits!$A$40="","",Produits!$B$40) | C41: =IF(Produits!$A$40="","",Produits!$C$40) | G41: =IF(OR(E41="",F41=""),"",F41-E41) | H41: =IF(AND(D41="",F41=""),"",N(D41)+N(F41))
...

Sheet Semaine 2
A1: Semaine 2
A2: Stock = ce qu'il reste · Commandé = ce que tu demandes · Reçu = ce qui est arrivé
A3: Date du comptage :
A5: Produit | B5: Fournisseur | C5: Unité | D5: Stock | E5: Commandé | F5: Reçu | G5: Écart | H5: Total dispo
A6: =IF(Produits!$A$5="","",Produits!$A$5) | B6: =IF(Produits!$A$5="","",Produits!$B$5) | C6: =IF(Produits!$A$5="","",Produits!$C$5) | D6: 5 | E6: 10 | F6: 10 | G6: =IF(OR(E6="",F6=""),"",F6-E6) | H6: =IF(AND(D6="",F6=""),"",N(D6)+N(F6))
A7: =IF(Produits!$A$6="","",Produits!$A$6) | B7: =IF(Produits!$A$6="","",Produits!$B$6) | C7: =IF(Produits!$A$6="","",Produits!$C$6) | D7: 3 | E7: 3 | F7: 3 | G7: =IF(OR(E7="",F7=""),"",F7-E7) | H7: =IF(AND(D7="",F7=""),"",N(D7)+N(F7))
A8: =IF(Produits!$A$7="","",Produits!$A$7) | B8: =IF(Produits!$A$7="","",Produits!$B$7) | C8: =IF(Produits!$A$7="","",Produits!$C$7) | D8: 7 | E8: 5 | F8: 5 | G8: =IF(OR(E8="",F8=""),"",F8-E8) | H8: =IF(AND(D8="",F8=""),"",N(D8)+N(F8))
A9: =IF(Produits!$A$8="","",Produits!$A$8) | B9: =IF(Produits!$A$8="","",Produits!$B$8) | C9: =IF(Produits!$A$8="","",Produits!$C$8) | D9: 2 | E9: 0 | F9: 0 | G9: =IF(OR(E9="",F9=""),"",F9-E9) | H9: =IF(AND(D9="",F9=""),"",N(D9)+N(F9))
A10: =IF(Produits!$A$9="","",Produits!$A$9) | B10: =IF(Produits!$A$9="","",Produits!$B$9) | C10: =IF(Produits!$A$9="","",Produits!$C$9) | D10: 4 | E10: 5 | F10: 5 | G10: =IF(OR(E10="",F10=""),"",F10-E10) | H10: =IF(AND(D10="",F10=""),"",N(D10)+N(F10))
A11: =IF(Produits!$A$10="","",Produits!$A$10) | B11: =IF(Produits!$A$10="","",Produits!$B$10) | C11: =IF(Produits!$A$10="","",Produits!$C$10) | D11: 5 | E11: 10 | F11: 10 | G11: =IF(OR(E11="",F11=""),"",F11-E11) | H11: =IF(AND(D11="",F11=""),"",N(D11)+N(F11))
A12: =IF(Produits!$A$11="","",Produits!$A$11) | B12: =IF(Produits!$A$11="","",Produits!$B$11) | C12: =IF(Produits!$A$11="","",Produits!$C$11) | D12: 4 | E12: 6 | F12: 6 | G12: =IF(OR(E12="",F12=""),"",F12-E12) | H12: =IF(AND(D12="",F12=""),"",N(D12)+N(F12))
A13: =IF(Produits!$A$12="","",Produits!$A$12) | B13: =IF(Produits!$A$12="","",Produits!$B$12) | C13: =IF(Produits!$A$12="","",Produits!$C$12) | D13: 50 | E13: 60 | F13: 60 | G13: =IF(OR(E13="",F13=""),"",F13-E13) | H13: =IF(AND(D13="",F13=""),"",N(D13)+N(F13))
A14: =IF(Produits!$A$13="","",Produits!$A$13) | B14: =IF(Produits!$A$13="","",Produits!$B$13) | C14: =IF(Produits!$A$13="","",Produits!$C$13) | D14: 2 | E14: 2 | F14: 2 | G14: =IF(OR(E14="",F14=""),"",F14-E14) | H14: =IF(AND(D14="",F14=""),"",N(D14)+N(F14))
A15: =IF(Produits!$A$14="","",Produits!$A$14) | B15: =IF(Produits!$A$14="","",Produits!$B$14) | C15: =IF(Produits!$A$14="","",Produits!$C$14) | D15: 2 | E15: 2 | F15: 2 | G15: =IF(OR(E15="",F15=""),"",F15-E15) | H15: =IF(AND(D15="",F15=""),"",N(D15)+N(F15))
A16: =IF(Produits!$A$15="","",Produits!$A$15) | B16: =IF(Produits!$A$15="","",Produits!$B$15) | C16: =IF(Produits!$A$15="","",Produits!$C$15) | D16: 0.6 | E16: 0 | F16: 0 | G16: =IF(OR(E16="",F16=""),"",F16-E16) | H16: =IF(AND(D16="",F16=""),"",N(D16)+N(F16))
A17: =IF(Produits!$A$16="","",Produits!$A$16) | B17: =IF(Produits!$A$16="","",Produits!$B$16) | C17: =IF(Produits!$A$16="","",Produits!$C$16) | D17: 6 | E17: 0 | F17: 0 | G17: =IF(OR(E17="",F17=""),"",F17-E17) | H17: =IF(AND(D17="",F17=""),"",N(D17)+N(F17))
A18: =IF(Produits!$A$17="","",Produits!$A$17) | B18: =IF(Produits!$A$17="","",Produits!$B$17) | C18: =IF(Produits!$A$17="","",Produits!$C$17) | G18: =IF(OR(E18="",F18=""),"",F18-E18) | H18: =IF(AND(D18="",F18=""),"",N(D18)+N(F18))
A19: =IF(Produits!$A$18="","",Produits!$A$18) | B19: =IF(Produits!$A$18="","",Produits!$B$18) | C19: =IF(Produits!$A$18="","",Produits!$C$18) | G19: =IF(OR(E19="",F19=""),"",F19-E19) | H19: =IF(AND(D19="",F19=""),"",N(D19)+N(F19))
A20: =IF(Produits!$A$19="","",Produits!$A$19) | B20: =IF(Produits!$A$19="","",Produits!$B$19) | C20: =IF(Produits!$A$19="","",Produits!$C$19) | G20: =IF(OR(E20="",F20=""),"",F20-E20) | H20: =IF(AND(D20="",F20=""),"",N(D20)+N(F20))
A21: =IF(Produits!$A$20="","",Produits!$A$20) | B21: =IF(Produits!$A$20="","",Produits!$B$20) | C21: =IF(Produits!$A$20="","",Produits!$C$20) | G21: =IF(OR(E21="",F21=""),"",F21-E21) | H21: =IF(AND(D21="",F21=""),"",N(D21)+N(F21))
A22: =IF(Produits!$A$21="","",Produits!$A$21) | B22: =IF(Produits!$A$21="","",Produits!$B$21) | C22: =IF(Produits!$A$21="","",Produits!$C$21) | G22: =IF(OR(E22="",F22=""),"",F22-E22) | H22: =IF(AND(D22="",F22=""),"",N(D22)+N(F22))
A23: =IF(Produits!$A$22="","",Produits!$A$22) | B23: =IF(Produits!$A$22="","",Produits!$B$22) | C23: =IF(Produits!$A$22="","",Produits!$C$22) | G23: =IF(OR(E23="",F23=""),"",F23-E23) | H23: =IF(AND(D23="",F23=""),"",N(D23)+N(F23))
A24: =IF(Produits!$A$23="","",Produits!$A$23) | B24: =IF(Produits!$A$23="","",Produits!$B$23) | C24: =IF(Produits!$A$23="","",Produits!$C$23) | G24: =IF(OR(E24="",F24=""),"",F24-E24) | H24: =IF(AND(D24="",F24=""),"",N(D24)+N(F24))
A25: =IF(Produits!$A$24="","",Produits!$A$24) | B25: =IF(Produits!$A$24="","",Produits!$B$24) | C25: =IF(Produits!$A$24="","",Produits!$C$24) | G25: =IF(OR(E25="",F25=""),"",F25-E25) | H25: =IF(AND(D25="",F25=""),"",N(D25)+N(F25))
A26: =IF(Produits!$A$25="","",Produits!$A$25) | B26: =IF(Produits!$A$25="","",Produits!$B$25) | C26: =IF(Produits!$A$25="","",Produits!$C$25) | G26: =IF(OR(E26="",F26=""),"",F26-E26) | H26: =IF(AND(D26="",F26=""),"",N(D26)+N(F26))
A27: =IF(Produits!$A$26="","",Produits!$A$26) | B27: =IF(Produits!$A$26="","",Produits!$B$26) | C27: =IF(Produits!$A$26="","",Produits!$C$26) | G27: =IF(OR(E27="",F27=""),"",F27-E27) | H27: =IF(AND(D27="",F27=""),"",N(D27)+N(F27))
A28: =IF(Produits!$A$27="","",Produits!$A$27) | B28: =IF(Produits!$A$27="","",Produits!$B$27) | C28: =IF(Produits!$A$27="","",Produits!$C$27) | G28: =IF(OR(E28="",F28=""),"",F28-E28) | H28: =IF(AND(D28="",F28=""),"",N(D28)+N(F28))
A29: =IF(Produits!$A$28="","",Produits!$A$28) | B29: =IF(Produits!$A$28="","",Produits!$B$28) | C29: =IF(Produits!$A$28="","",Produits!$C$28) | G29: =IF(OR(E29="",F29=""),"",F29-E29) | H29: =IF(AND(D29="",F29=""),"",N(D29)+N(F29))
A30: =IF(Produits!$A$29="","",Produits!$A$29) | B30: =IF(Produits!$A$29="","",Produits!$B$29) | C30: =IF(Produits!$A$29="","",Produits!$C$29) | G30: =IF(OR(E30="",F30=""),"",F30-E30) | H30: =IF(AND(D30="",F30=""),"",N(D30)+N(F30))
A31: =IF(Produits!$A$30="","",Produits!$A$30) | B31: =IF(Produits!$A$30="","",Produits!$B$30) | C31: =IF(Produits!$A$30="","",Produits!$C$30) | G31: =IF(OR(E31="",F31=""),"",F31-E31) | H31: =IF(AND(D31="",F31=""),"",N(D31)+N(F31))
A32: =IF(Produits!$A$31="","",Produits!$A$31) | B32: =IF(Produits!$A$31="","",Produits!$B$31) | C32: =IF(Produits!$A$31="","",Produits!$C$31) | G32: =IF(OR(E32="",F32=""),"",F32-E32) | H32: =IF(AND(D32="",F32=""),"",N(D32)+N(F32))
A33: =IF(Produits!$A$32="","",Produits!$A$32) | B33: =IF(Produits!$A$32="","",Produits!$B$32) | C33: =IF(Produits!$A$32="","",Produits!$C$32) | G33: =IF(OR(E33="",F33=""),"",F33-E33) | H33: =IF(AND(D33="",F33=""),"",N(D33)+N(F33))
A34: =IF(Produits!$A$33="","",Produits!$A$33) | B34: =IF(Produits!$A$33="","",Produits!$B$33) | C34: =IF(Produits!$A$33="","",Produits!$C$33) | G34: =IF(OR(E34="",F34=""),"",F34-E34) | H34: =IF(AND(D34="",F34=""),"",N(D34)+N(F34))
A35: =IF(Produits!$A$34="","",Produits!$A$34) | B35: =IF(Produits!$A$34="","",Produits!$B$34) | C35: =IF(Produits!$A$34="","",Produits!$C$34) | G35: =IF(OR(E35="",F35=""),"",F35-E35) | H35: =IF(AND(D35="",F35=""),"",N(D35)+N(F35))
A36: =IF(Produits!$A$35="","",Produits!$A$35) | B36: =IF(Produits!$A$35="","",Produits!$B$35) | C36: =IF(Produits!$A$35="","",Produits!$C$35) | G36: =IF(OR(E36="",F36=""),"",F36-E36) | H36: =IF(AND(D36="",F36=""),"",N(D36)+N(F36))
A37: =IF(Produits!$A$36="","",Produits!$A$36) | B37: =IF(Produits!$A$36="","",Produits!$B$36) | C37: =IF(Produits!$A$36="","",Produits!$C$36) | G37: =IF(OR(E37="",F37=""),"",F37-E37) | H37: =IF(AND(D37="",F37=""),"",N(D37)+N(F37))
A38: =IF(Produits!$A$37="","",Produits!$A$37) | B38: =IF(Produits!$A$37="","",Produits!$B$37) | C38: =IF(Produits!$A$37="","",Produits!$C$37) | G38: =IF(OR(E38="",F38=""),"",F38-E38) | H38: =IF(AND(D38="",F38=""),"",N(D38)+N(F38))
A39: =IF(Produits!$A$38="","",Produits!$A$38) | B39: =IF(Produits!$A$38="","",Produits!$B$38) | C39: =IF(Produits!$A$38="","",Produits!$C$38) | G39: =IF(OR(E39="",F39=""),"",F39-E39) | H39: =IF(AND(D39="",F39=""),"",N(D39)+N(F39))
A40: =IF(Produits!$A$39="","",Produits!$A$39) | B40: =IF(Produits!$A$39="","",Produits!$B$39) | C40: =IF(Produits!$A$39="","",Produits!$C$39) | G40: =IF(OR(E40="",F40=""),"",F40-E40) | H40: =IF(AND(D40="",F40=""),"",N(D40)+N(F40))
A41: =IF(Produits!$A$40="","",Produits!$A$40) | B41: =IF(Produits!$A$40="","",Produits!$B$40) | C41: =IF(Produits!$A$40="","",Produits!$C$40) | G41: =IF(OR(E41="",F41=""),"",F41-E41) | H41: =IF(AND(D41="",F41=""),"",N(D41)+N(F41))
...

Sheet Semaine 3
A1: Semaine 3
A2: Stock = ce qu'il reste · Commandé = ce que tu demandes · Reçu = ce qui est arrivé
A3: Date du comptage :
A5: Produit | B5: Fournisseur | C5: Unité | D5: Stock | E5: Commandé | F5: Reçu | G5: Écart | H5: Total dispo
A6: =IF(Produits!$A$5="","",Produits!$A$5) | B6: =IF(Produits!$A$5="","",Produits!$B$5) | C6: =IF(Produits!$A$5="","",Produits!$C$5) | G6: =IF(OR(E6="",F6=""),"",F6-E6) | H6: =IF(AND(D6="",F6=""),"",N(D6)+N(F6))
A7: =IF(Produits!$A$6="","",Produits!$A$6) | B7: =IF(Produits!$A$6="","",Produits!$B$6) | C7: =IF(Produits!$A$6="","",Produits!$C$6) | G7: =IF(OR(E7="",F7=""),"",F7-E7) | H7: =IF(AND(D7="",F7=""),"",N(D7)+N(F7))
A8: =IF(Produits!$A$7="","",Produits!$A$7) | B8: =IF(Produits!$A$7="","",Produits!$B$7) | C8: =IF(Produits!$A$7="","",Produits!$C$7) | G8: =IF(OR(E8="",F8=""),"",F8-E8) | H8: =IF(AND(D8="",F8=""),"",N(D8)+N(F8))
A9: =IF(Produits!$A$8="","",Produits!$A$8) | B9: =IF(Produits!$A$8="","",Produits!$B$8) | C9: =IF(Produits!$A$8="","",Produits!$C$8) | G9: =IF(OR(E9="",F9=""),"",F9-E9) | H9: =IF(AND(D9="",F9=""),"",N(D9)+N(F9))
A10: =IF(Produits!$A$9="","",Produits!$A$9) | B10: =IF(Produits!$A$9="","",Produits!$B$9) | C10: =IF(Produits!$A$9="","",Produits!$C$9) | G10: =IF(OR(E10="",F10=""),"",F10-E10) | H10: =IF(AND(D10="",F10=""),"",N(D10)+N(F10))
A11: =IF(Produits!$A$10="","",Produits!$A$10) | B11: =IF(Produits!$A$10="","",Produits!$B$10) | C11: =IF(Produits!$A$10="","",Produits!$C$10) | G11: =IF(OR(E11="",F11=""),"",F11-E11) | H11: =IF(AND(D11="",F11=""),"",N(D11)+N(F11))
A12: =IF(Produits!$A$11="","",Produits!$A$11) | B12: =IF(Produits!$A$11="","",Produits!$B$11) | C12: =IF(Produits!$A$11="","",Produits!$C$11) | G12: =IF(OR(E12="",F12=""),"",F12-E12) | H12: =IF(AND(D12="",F12=""),"",N(D12)+N(F12))
A13: =IF(Produits!$A$12="","",Produits!$A$12) | B13: =IF(Produits!$A$12="","",Produits!$B$12) | C13: =IF(Produits!$A$12="","",Produits!$C$12) | G13: =IF(OR(E13="",F13=""),"",F13-E13) | H13: =IF(AND(D13="",F13=""),"",N(D13)+N(F13))
A14: =IF(Produits!$A$13="","",Produits!$A$13) | B14: =IF(Produits!$A$13="","",Produits!$B$13) | C14: =IF(Produits!$A$13="","",Produits!$C$13) | G14: =IF(OR(E14="",F14=""),"",F14-E14) | H14: =IF(AND(D14="",F14=""),"",N(D14)+N(F14))
A15: =IF(Produits!$A$14="","",Produits!$A$14) | B15: =IF(Produits!$A$14="","",Produits!$B$14) | C15: =IF(Produits!$A$14="","",Produits!$C$14) | G15: =IF(OR(E15="",F15=""),"",F15-E15) | H15: =IF(AND(D15="",F15=""),"",N(D15)+N(F15))
A16: =IF(Produits!$A$15="","",Produits!$A$15) | B16: =IF(Produits!$A$15="","",Produits!$B$15) | C16: =IF(Produits!$A$15="","",Produits!$C$15) | G16: =IF(OR(E16="",F16=""),"",F16-E16) | H16: =IF(AND(D16="",F16=""),"",N(D16)+N(F16))
A17: =IF(Produits!$A$16="","",Produits!$A$16) | B17: =IF(Produits!$A$16="","",Produits!$B$16) | C17: =IF(Produits!$A$16="","",Produits!$C$16) | G17: =IF(OR(E17="",F17=""),"",F17-E17) | H17: =IF(AND(D17="",F17=""),"",N(D17)+N(F17))
A18: =IF(Produits!$A$17="","",Produits!$A$17) | B18: =IF(Produits!$A$17="","",Produits!$B$17) | C18: =IF(Produits!$A$17="","",Produits!$C$17) | G18: =IF(OR(E18="",F18=""),"",F18-E18) | H18: =IF(AND(D18="",F18=""),"",N(D18)+N(F18))
A19: =IF(Produits!$A$18="","",Produits!$A$18) | B19: =IF(Produits!$A$18="","",Produits!$B$18) | C19: =IF(Produits!$A$18="","",Produits!$C$18) | G19: =IF(OR(E19="",F19=""),"",F19-E19) | H19: =IF(AND(D19="",F19=""),"",N(D19)+N(F19))
A20: =IF(Produits!$A$19="","",Produits!$A$19) | B20: =IF(Produits!$A$19="","",Produits!$B$19) | C20: =IF(Produits!$A$19="","",Produits!$C$19) | G20: =IF(OR(E20="",F20=""),"",F20-E20) | H20: =IF(AND(D20="",F20=""),"",N(D20)+N(F20))
A21: =IF(Produits!$A$20="","",Produits!$A$20) | B21: =IF(Produits!$A$20="","",Produits!$B$20) | C21: =IF(Produits!$A$20="","",Produits!$C$20) | G21: =IF(OR(E21="",F21=""),"",F21-E21) | H21: =IF(AND(D21="",F21=""),"",N(D21)+N(F21))
A22: =IF(Produits!$A$21="","",Produits!$A$21) | B22: =IF(Produits!$A$21="","",Produits!$B$21) | C22: =IF(Produits!$A$21="","",Produits!$C$21) | G22: =IF(OR(E22="",F22=""),"",F22-E22) | H22: =IF(AND(D22="",F22=""),"",N(D22)+N(F22))
A23: =IF(Produits!$A$22="","",Produits!$A$22) | B23: =IF(Produits!$A$22="","",Produits!$B$22) | C23: =IF(Produits!$A$22="","",Produits!$C$22) | G23: =IF(OR(E23="",F23=""),"",F23-E23) | H23: =IF(AND(D23="",F23=""),"",N(D23)+N(F23))
A24: =IF(Produits!$A$23="","",Produits!$A$23) | B24: =IF(Produits!$A$23="","",Produits!$B$23) | C24: =IF(Produits!$A$23="","",Produits!$C$23) | G24: =IF(OR(E24="",F24=""),"",F24-E24) | H24: =IF(AND(D24="",F24=""),"",N(D24)+N(F24))
A25: =IF(Produits!$A$24="","",Produits!$A$24) | B25: =IF(Produits!$A$24="","",Produits!$B$24) | C25: =IF(Produits!$A$24="","",Produits!$C$24) | G25: =IF(OR(E25="",F25=""),"",F25-E25) | H25: =IF(AND(D25="",F25=""),"",N(D25)+N(F25))
A26: =IF(Produits!$A$25="","",Produits!$A$25) | B26: =IF(Produits!$A$25="","",Produits!$B$25) | C26: =IF(Produits!$A$25="","",Produits!$C$25) | G26: =IF(OR(E26="",F26=""),"",F26-E26) | H26: =IF(AND(D26="",F26=""),"",N(D26)+N(F26))
A27: =IF(Produits!$A$26="","",Produits!$A$26) | B27: =IF(Produits!$A$26="","",Produits!$B$26) | C27: =IF(Produits!$A$26="","",Produits!$C$26) | G27: =IF(OR(E27="",F27=""),"",F27-E27) | H27: =IF(AND(D27="",F27=""),"",N(D27)+N(F27))
A28: =IF(Produits!$A$27="","",Produits!$A$27) | B28: =IF(Produits!$A$27="","",Produits!$B$27) | C28: =IF(Produits!$A$27="","",Produits!$C$27) | G28: =IF(OR(E28="",F28=""),"",F28-E28) | H28: =IF(AND(D28="",F28=""),"",N(D28)+N(F28))
A29: =IF(Produits!$A$28="","",Produits!$A$28) | B29: =IF(Produits!$A$28="","",Produits!$B$28) | C29: =IF(Produits!$A$28="","",Produits!$C$28) | G29: =IF(OR(E29="",F29=""),"",F29-E29) | H29: =IF(AND(D29="",F29=""),"",N(D29)+N(F29))
A30: =IF(Produits!$A$29="","",Produits!$A$29) | B30: =IF(Produits!$A$29="","",Produits!$B$29) | C30: =IF(Produits!$A$29="","",Produits!$C$29) | G30: =IF(OR(E30="",F30=""),"",F30-E30) | H30: =IF(AND(D30="",F30=""),"",N(D30)+N(F30))
A31: =IF(Produits!$A$30="","",Produits!$A$30) | B31: =IF(Produits!$A$30="","",Produits!$B$30) | C31: =IF(Produits!$A$30="","",Produits!$C$30) | G31: =IF(OR(E31="",F31=""),"",F31-E31) | H31: =IF(AND(D31="",F31=""),"",N(D31)+N(F31))
A32: =IF(Produits!$A$31="","",Produits!$A$31) | B32: =IF(Produits!$A$31="","",Produits!$B$31) | C32: =IF(Produits!$A$31="","",Produits!$C$31) | G32: =IF(OR(E32="",F32=""),"",F32-E32) | H32: =IF(AND(D32="",F32=""),"",N(D32)+N(F32))
A33: =IF(Produits!$A$32="","",Produits!$A$32) | B33: =IF(Produits!$A$32="","",Produits!$B$32) | C33: =IF(Produits!$A$32="","",Produits!$C$32) | G33: =IF(OR(E33="",F33=""),"",F33-E33) | H33: =IF(AND(D33="",F33=""),"",N(D33)+N(F33))
A34: =IF(Produits!$A$33="","",Produits!$A$33) | B34: =IF(Produits!$A$33="","",Produits!$B$33) | C34: =IF(Produits!$A$33="","",Produits!$C$33) | G34: =IF(OR(E34="",F34=""),"",F34-E34) | H34: =IF(AND(D34="",F34=""),"",N(D34)+N(F34))
A35: =IF(Produits!$A$34="","",Produits!$A$34) | B35: =IF(Produits!$A$34="","",Produits!$B$34) | C35: =IF(Produits!$A$34="","",Produits!$C$34) | G35: =IF(OR(E35="",F35=""),"",F35-E35) | H35: =IF(AND(D35="",F35=""),"",N(D35)+N(F35))
A36: =IF(Produits!$A$35="","",Produits!$A$35) | B36: =IF(Produits!$A$35="","",Produits!$B$35) | C36: =IF(Produits!$A$35="","",Produits!$C$35) | G36: =IF(OR(E36="",F36=""),"",F36-E36) | H36: =IF(AND(D36="",F36=""),"",N(D36)+N(F36))
A37: =IF(Produits!$A$36="","",Produits!$A$36) | B37: =IF(Produits!$A$36="","",Produits!$B$36) | C37: =IF(Produits!$A$36="","",Produits!$C$36) | G37: =IF(OR(E37="",F37=""),"",F37-E37) | H37: =IF(AND(D37="",F37=""),"",N(D37)+N(F37))
A38: =IF(Produits!$A$37="","",Produits!$A$37) | B38: =IF(Produits!$A$37="","",Produits!$B$37) | C38: =IF(Produits!$A$37="","",Produits!$C$37) | G38: =IF(OR(E38="",F38=""),"",F38-E38) | H38: =IF(AND(D38="",F38=""),"",N(D38)+N(F38))
A39: =IF(Produits!$A$38="","",Produits!$A$38) | B39: =IF(Produits!$A$38="","",Produits!$B$38) | C39: =IF(Produits!$A$38="","",Produits!$C$38) | G39: =IF(OR(E39="",F39=""),"",F39-E39) | H39: =IF(AND(D39="",F39=""),"",N(D39)+N(F39))
A40: =IF(Produits!$A$39="","",Produits!$A$39) | B40: =IF(Produits!$A$39="","",Produits!$B$39) | C40: =IF(Produits!$A$39="","",Produits!$C$39) | G40: =IF(OR(E40="",F40=""),"",F40-E40) | H40: =IF(AND(D40="",F40=""),"",N(D40)+N(F40))
A41: =IF(Produits!$A$40="","",Produits!$A$40) | B41: =IF(Produits!$A$40="","",Produits!$B$40) | C41: =IF(Produits!$A$40="","",Produits!$C$40) | G41: =IF(OR(E41="",F41=""),"",F41-E41) | H41: =IF(AND(D41="",F41=""),"",N(D41)+N(F41))
...

Sheet Semaine 4
A1: Semaine 4
A2: Stock = ce qu'il reste · Commandé = ce que tu demandes · Reçu = ce qui est arrivé
A3: Date du comptage :
A5: Produit | B5: Fournisseur | C5: Unité | D5: Stock | E5: Commandé | F5: Reçu | G5: Écart | H5: Total dispo
A6: =IF(Produits!$A$5="","",Produits!$A$5) | B6: =IF(Produits!$A$5="","",Produits!$B$5) | C6: =IF(Produits!$A$5="","",Produits!$C$5) | G6: =IF(OR(E6="",F6=""),"",F6-E6) | H6: =IF(AND(D6="",F6=""),"",N(D6)+N(F6))
A7: =IF(Produits!$A$6="","",Produits!$A$6) | B7: =IF(Produits!$A$6="","",Produits!$B$6) | C7: =IF(Produits!$A$6="","",Produits!$C$6) | G7: =IF(OR(E7="",F7=""),"",F7-E7) | H7: =IF(AND(D7="",F7=""),"",N(D7)+N(F7))
A8: =IF(Produits!$A$7="","",Produits!$A$7) | B8: =IF(Produits!$A$7="","",Produits!$B$7) | C8: =IF(Produits!$A$7="","",Produits!$C$7) | G8: =IF(OR(E8="",F8=""),"",F8-E8) | H8: =IF(AND(D8="",F8=""),"",N(D8)+N(F8))
A9: =IF(Produits!$A$8="","",Produits!$A$8) | B9: =IF(Produits!$A$8="","",Produits!$B$8) | C9: =IF(Produits!$A$8="","",Produits!$C$8) | G9: =IF(OR(E9="",F9=""),"",F9-E9) | H9: =IF(AND(D9="",F9=""),"",N(D9)+N(F9))
A10: =IF(Produits!$A$9="","",Produits!$A$9) | B10: =IF(Produits!$A$9="","",Produits!$B$9) | C10: =IF(Produits!$A$9="","",Produits!$C$9) | G10: =IF(OR(E10="",F10=""),"",F10-E10) | H10: =IF(AND(D10="",F10=""),"",N(D10)+N(F10))
A11: =IF(Produits!$A$10="","",Produits!$A$10) | B11: =IF(Produits!$A$10="","",Produits!$B$10) | C11: =IF(Produits!$A$10="","",Produits!$C$10) | G11: =IF(OR(E11="",F11=""),"",F11-E11) | H11: =IF(AND(D11="",F11=""),"",N(D11)+N(F11))
A12: =IF(Produits!$A$11="","",Produits!$A$11) | B12: =IF(Produits!$A$11="","",Produits!$B$11) | C12: =IF(Produits!$A$11="","",Produits!$C$11) | G12: =IF(OR(E12="",F12=""),"",F12-E12) | H12: =IF(AND(D12="",F12=""),"",N(D12)+N(F12))
A13: =IF(Produits!$A$12="","",Produits!$A$12) | B13: =IF(Produits!$A$12="","",Produits!$B$12) | C13: =IF(Produits!$A$12="","",Produits!$C$12) | G13: =IF(OR(E13="",F13=""),"",F13-E13) | H13: =IF(AND(D13="",F13=""),"",N(D13)+N(F13))
A14: =IF(Produits!$A$13="","",Produits!$A$13) | B14: =IF(Produits!$A$13="","",Produits!$B$13) | C14: =IF(Produits!$A$13="","",Produits!$C$13) | G14: =IF(OR(E14="",F14=""),"",F14-E14) | H14: =IF(AND(D14="",F14=""),"",N(D14)+N(F14))
A15: =IF(Produits!$A$14="","",Produits!$A$14) | B15: =IF(Produits!$A$14="","",Produits!$B$14) | C15: =IF(Produits!$A$14="","",Produits!$C$14) | G15: =IF(OR(E15="",F15=""),"",F15-E15) | H15: =IF(AND(D15="",F15=""),"",N(D15)+N(F15))
A16: =IF(Produits!$A$15="","",Produits!$A$15) | B16: =IF(Produits!$A$15="","",Produits!$B$15) | C16: =IF(Produits!$A$15="","",Produits!$C$15) | G16: =IF(OR(E16="",F16=""),"",F16-E16) | H16: =IF(AND(D16="",F16=""),"",N(D16)+N(F16))
A17: =IF(Produits!$A$16="","",Produits!$A$16) | B17: =IF(Produits!$A$16="","",Produits!$B$16) | C17: =IF(Produits!$A$16="","",Produits!$C$16) | G17: =IF(OR(E17="",F17=""),"",F17-E17) | H17: =IF(AND(D17="",F17=""),"",N(D17)+N(F17))
A18: =IF(Produits!$A$17="","",Produits!$A$17) | B18: =IF(Produits!$A$17="","",Produits!$B$17) | C18: =IF(Produits!$A$17="","",Produits!$C$17) | G18: =IF(OR(E18="",F18=""),"",F18-E18) | H18: =IF(AND(D18="",F18=""),"",N(D18)+N(F18))
A19: =IF(Produits!$A$18="","",Produits!$A$18) | B19: =IF(Produits!$A$18="","",Produits!$B$18) | C19: =IF(Produits!$A$18="","",Produits!$C$18) | G19: =IF(OR(E19="",F19=""),"",F19-E19) | H19: =IF(AND(D19="",F19=""),"",N(D19)+N(F19))
A20: =IF(Produits!$A$19="","",Produits!$A$19) | B20: =IF(Produits!$A$19="","",Produits!$B$19) | C20: =IF(Produits!$A$19="","",Produits!$C$19) | G20: =IF(OR(E20="",F20=""),"",F20-E20) | H20: =IF(AND(D20="",F20=""),"",N(D20)+N(F20))
A21: =IF(Produits!$A$20="","",Produits!$A$20) | B21: =IF(Produits!$A$20="","",Produits!$B$20) | C21: =IF(Produits!$A$20="","",Produits!$C$20) | G21: =IF(OR(E21="",F21=""),"",F21-E21) | H21: =IF(AND(D21="",F21=""),"",N(D21)+N(F21))
A22: =IF(Produits!$A$21="","",Produits!$A$21) | B22: =IF(Produits!$A$21="","",Produits!$B$21) | C22: =IF(Produits!$A$21="","",Produits!$C$21) | G22: =IF(OR(E22="",F22=""),"",F22-E22) | H22: =IF(AND(D22="",F22=""),"",N(D22)+N(F22))
A23: =IF(Produits!$A$22="","",Produits!$A$22) | B23: =IF(Produits!$A$22="","",Produits!$B$22) | C23: =IF(Produits!$A$22="","",Produits!$C$22) | G23: =IF(OR(E23="",F23=""),"",F23-E23) | H23: =IF(AND(D23="",F23=""),"",N(D23)+N(F23))
A24: =IF(Produits!$A$23="","",Produits!$A$23) | B24: =IF(Produits!$A$23="","",Produits!$B$23) | C24: =IF(Produits!$A$23="","",Produits!$C$23) | G24: =IF(OR(E24="",F24=""),"",F24-E24) | H24: =IF(AND(D24="",F24=""),"",N(D24)+N(F24))
A25: =IF(Produits!$A$24="","",Produits!$A$24) | B25: =IF(Produits!$A$24="","",Produits!$B$24) | C25: =IF(Produits!$A$24="","",Produits!$C$24) | G25: =IF(OR(E25="",F25=""),"",F25-E25) | H25: =IF(AND(D25="",F25=""),"",N(D25)+N(F25))
A26: =IF(Produits!$A$25="","",Produits!$A$25) | B26: =IF(Produits!$A$25="","",Produits!$B$25) | C26: =IF(Produits!$A$25="","",Produits!$C$25) | G26: =IF(OR(E26="",F26=""),"",F26-E26) | H26: =IF(AND(D26="",F26=""),"",N(D26)+N(F26))
A27: =IF(Produits!$A$26="","",Produits!$A$26) | B27: =IF(Produits!$A$26="","",Produits!$B$26) | C27: =IF(Produits!$A$26="","",Produits!$C$26) | G27: =IF(OR(E27="",F27=""),"",F27-E27) | H27: =IF(AND(D27="",F27=""),"",N(D27)+N(F27))
A28: =IF(Produits!$A$27="","",Produits!$A$27) | B28: =IF(Produits!$A$27="","",Produits!$B$27) | C28: =IF(Produits!$A$27="","",Produits!$C$27) | G28: =IF(OR(E28="",F28=""),"",F28-E28) | H28: =IF(AND(D28="",F28=""),"",N(D28)+N(F28))
A29: =IF(Produits!$A$28="","",Produits!$A$28) | B29: =IF(Produits!$A$28="","",Produits!$B$28) | C29: =IF(Produits!$A$28="","",Produits!$C$28) | G29: =IF(OR(E29="",F29=""),"",F29-E29) | H29: =IF(AND(D29="",F29=""),"",N(D29)+N(F29))
A30: =IF(Produits!$A$29="","",Produits!$A$29) | B30: =IF(Produits!$A$29="","",Produits!$B$29) | C30: =IF(Produits!$A$29="","",Produits!$C$29) | G30: =IF(OR(E30="",F30=""),"",F30-E30) | H30: =IF(AND(D30="",F30=""),"",N(D30)+N(F30))
A31: =IF(Produits!$A$30="","",Produits!$A$30) | B31: =IF(Produits!$A$30="","",Produits!$B$30) | C31: =IF(Produits!$A$30="","",Produits!$C$30) | G31: =IF(OR(E31="",F31=""),"",F31-E31) | H31: =IF(AND(D31="",F31=""),"",N(D31)+N(F31))
A32: =IF(Produits!$A$31="","",Produits!$A$31) | B32: =IF(Produits!$A$31="","",Produits!$B$31) | C32: =IF(Produits!$A$31="","",Produits!$C$31) | G32: =IF(OR(E32="",F32=""),"",F32-E32) | H32: =IF(AND(D32="",F32=""),"",N(D32)+N(F32))
A33: =IF(Produits!$A$32="","",Produits!$A$32) | B33: =IF(Produits!$A$32="","",Produits!$B$32) | C33: =IF(Produits!$A$32="","",Produits!$C$32) | G33: =IF(OR(E33="",F33=""),"",F33-E33) | H33: =IF(AND(D33="",F33=""),"",N(D33)+N(F33))
A34: =IF(Produits!$A$33="","",Produits!$A$33) | B34: =IF(Produits!$A$33="","",Produits!$B$33) | C34: =IF(Produits!$A$33="","",Produits!$C$33) | G34: =IF(OR(E34="",F34=""),"",F34-E34) | H34: =IF(AND(D34="",F34=""),"",N(D34)+N(F34))
A35: =IF(Produits!$A$34="","",Produits!$A$34) | B35: =IF(Produits!$A$34="","",Produits!$B$34) | C35: =IF(Produits!$A$34="","",Produits!$C$34) | G35: =IF(OR(E35="",F35=""),"",F35-E35) | H35: =IF(AND(D35="",F35=""),"",N(D35)+N(F35))
A36: =IF(Produits!$A$35="","",Produits!$A$35) | B36: =IF(Produits!$A$35="","",Produits!$B$35) | C36: =IF(Produits!$A$35="","",Produits!$C$35) | G36: =IF(OR(E36="",F36=""),"",F36-E36) | H36: =IF(AND(D36="",F36=""),"",N(D36)+N(F36))
A37: =IF(Produits!$A$36="","",Produits!$A$36) | B37: =IF(Produits!$A$36="","",Produits!$B$36) | C37: =IF(Produits!$A$36="","",Produits!$C$36) | G37: =IF(OR(E37="",F37=""),"",F37-E37) | H37: =IF(AND(D37="",F37=""),"",N(D37)+N(F37))
A38: =IF(Produits!$A$37="","",Produits!$A$37) | B38: =IF(Produits!$A$37="","",Produits!$B$37) | C38: =IF(Produits!$A$37="","",Produits!$C$37) | G38: =IF(OR(E38="",F38=""),"",F38-E38) | H38: =IF(AND(D38="",F38=""),"",N(D38)+N(F38))
A39: =IF(Produits!$A$38="","",Produits!$A$38) | B39: =IF(Produits!$A$38="","",Produits!$B$38) | C39: =IF(Produits!$A$38="","",Produits!$C$38) | G39: =IF(OR(E39="",F39=""),"",F39-E39) | H39: =IF(AND(D39="",F39=""),"",N(D39)+N(F39))
A40: =IF(Produits!$A$39="","",Produits!$A$39) | B40: =IF(Produits!$A$39="","",Produits!$B$39) | C40: =IF(Produits!$A$39="","",Produits!$C$39) | G40: =IF(OR(E40="",F40=""),"",F40-E40) | H40: =IF(AND(D40="",F40=""),"",N(D40)+N(F40))
A41: =IF(Produits!$A$40="","",Produits!$A$40) | B41: =IF(Produits!$A$40="","",Produits!$B$40) | C41: =IF(Produits!$A$40="","",Produits!$C$40) | G41: =IF(OR(E41="",F41=""),"",F41-E41) | H41: =IF(AND(D41="",F41=""),"",N(D41)+N(F41))
...

Sheet Récap du mois
A1: Récap du mois
A2: Calculé à partir des 4 semaines — rien à remplir ici
A4: Produit | B4: Unité | C4: Commandé S1 | D4: Commandé S2 | E4: Commandé S3 | F4: Commandé S4 | G4: Total commandé | H4: Total reçu | I4: Manque | J4: Dernier stock
A5: =IF(Produits!$A$5="","",Produits!$A$5) | B5: =IF(Produits!$A$5="","",Produits!$C$5) | C5: =IF('Semaine 1'!E6="","",'Semaine 1'!E6) | D5: =IF('Semaine 2'!E6="","",'Semaine 2'!E6) | E5: =IF('Semaine 3'!E6="","",'Semaine 3'!E6) | F5: =IF('Semaine 4'!E6="","",'Semaine 4'!E6) | G5: =IF(COUNT('Semaine 1'!E6,'Semaine 2'!E6,'Semaine 3'!E6,'Semaine 4'!E6)=0,"",SUM('Semaine 1'!E6,'Semaine 2'!E6,'Semaine 3'!E6,'Semaine 4'!E6)) | H5: =IF(COUNT('Semaine 1'!F6,'Semaine 2'!F6,'Semaine 3'!F6,'Semaine 4'!F6)=0,"",SUM('Semaine 1'!F6,'Semaine 2'!F6,'Semaine 3'!F6,'Semaine 4'!F6)) | I5: =IF(OR(G5="",H5=""),"",H5-G5) | J5: =IF('Semaine 4'!D6<>"",'Semaine 4'!D6,IF('Semaine 3'!D6<>"",'Semaine 3'!D6,IF('Semaine 2'!D6<>"",'Semaine 2'!D6,IF('Semaine 1'!D6<>"",'Semaine 1'!D6,""))))
A6: =IF(Produits!$A$6="","",Produits!$A$6) | B6: =IF(Produits!$A$6="","",Produits!$C$6) | C6: =IF('Semaine 1'!E7="","",'Semaine 1'!E7) | D6: =IF('Semaine 2'!E7="","",'Semaine 2'!E7) | E6: =IF('Semaine 3'!E7="","",'Semaine 3'!E7) | F6: =IF('Semaine 4'!E7="","",'Semaine 4'!E7) | G6: =IF(COUNT('Semaine 1'!E7,'Semaine 2'!E7,'Semaine 3'!E7,'Semaine 4'!E7)=0,"",SUM('Semaine 1'!E7,'Semaine 2'!E7,'Semaine 3'!E7,'Semaine 4'!E7)) | H6: =IF(COUNT('Semaine 1'!F7,'Semaine 2'!F7,'Semaine 3'!F7,'Semaine 4'!F7)=0,"",SUM('Semaine 1'!F7,'Semaine 2'!F7,'Semaine 3'!F7,'Semaine 4'!F7)) | I6: =IF(OR(G6="",H6=""),"",H6-G6) | J6: =IF('Semaine 4'!D7<>"",'Semaine 4'!D7,IF('Semaine 3'!D7<>"",'Semaine 3'!D7,IF('Semaine 2'!D7<>"",'Semaine 2'!D7,IF('Semaine 1'!D7<>"",'Semaine 1'!D7,""))))
A7: =IF(Produits!$A$7="","",Produits!$A$7) | B7: =IF(Produits!$A$7="","",Produits!$C$7) | C7: =IF('Semaine 1'!E8="","",'Semaine 1'!E8) | D7: =IF('Semaine 2'!E8="","",'Semaine 2'!E8) | E7: =IF('Semaine 3'!E8="","",'Semaine 3'!E8) | F7: =IF('Semaine 4'!E8="","",'Semaine 4'!E8) | G7: =IF(COUNT('Semaine 1'!E8,'Semaine 2'!E8,'Semaine 3'!E8,'Semaine 4'!E8)=0,"",SUM('Semaine 1'!E8,'Semaine 2'!E8,'Semaine 3'!E8,'Semaine 4'!E8)) | H7: =IF(COUNT('Semaine 1'!F8,'Semaine 2'!F8,'Semaine 3'!F8,'Semaine 4'!F8)=0,"",SUM('Semaine 1'!F8,'Semaine 2'!F8,'Semaine 3'!F8,'Semaine 4'!F8)) | I7: =IF(OR(G7="",H7=""),"",H7-G7) | J7: =IF('Semaine 4'!D8<>"",'Semaine 4'!D8,IF('Semaine 3'!D8<>"",'Semaine 3'!D8,IF('Semaine 2'!D8<>"",'Semaine 2'!D8,IF('Semaine 1'!D8<>"",'Semaine 1'!D8,""))))
A8: =IF(Produits!$A$8="","",Produits!$A$8) | B8: =IF(Produits!$A$8="","",Produits!$C$8) | C8: =IF('Semaine 1'!E9="","",'Semaine 1'!E9) | D8: =IF('Semaine 2'!E9="","",'Semaine 2'!E9) | E8: =IF('Semaine 3'!E9="","",'Semaine 3'!E9) | F8: =IF('Semaine 4'!E9="","",'Semaine 4'!E9) | G8: =IF(COUNT('Semaine 1'!E9,'Semaine 2'!E9,'Semaine 3'!E9,'Semaine 4'!E9)=0,"",SUM('Semaine 1'!E9,'Semaine 2'!E9,'Semaine 3'!E9,'Semaine 4'!E9)) | H8: =IF(COUNT('Semaine 1'!F9,'Semaine 2'!F9,'Semaine 3'!F9,'Semaine 4'!F9)=0,"",SUM('Semaine 1'!F9,'Semaine 2'!F9,'Semaine 3'!F9,'Semaine 4'!F9)) | I8: =IF(OR(G8="",H8=""),"",H8-G8) | J8: =IF('Semaine 4'!D9<>"",'Semaine 4'!D9,IF('Semaine 3'!D9<>"",'Semaine 3'!D9,IF('Semaine 2'!D9<>"",'Semaine 2'!D9,IF('Semaine 1'!D9<>"",'Semaine 1'!D9,""))))
A9: =IF(Produits!$A$9="","",Produits!$A$9) | B9: =IF(Produits!$A$9="","",Produits!$C$9) | C9: =IF('Semaine 1'!E10="","",'Semaine 1'!E10) | D9: =IF('Semaine 2'!E10="","",'Semaine 2'!E10) | E9: =IF('Semaine 3'!E10="","",'Semaine 3'!E10) | F9: =IF('Semaine 4'!E10="","",'Semaine 4'!E10) | G9: =IF(COUNT('Semaine 1'!E10,'Semaine 2'!E10,'Semaine 3'!E10,'Semaine 4'!E10)=0,"",SUM('Semaine 1'!E10,'Semaine 2'!E10,'Semaine 3'!E10,'Semaine 4'!E10)) | H9: =IF(COUNT('Semaine 1'!F10,'Semaine 2'!F10,'Semaine 3'!F10,'Semaine 4'!F10)=0,"",SUM('Semaine 1'!F10,'Semaine 2'!F10,'Semaine 3'!F10,'Semaine 4'!F10)) | I9: =IF(OR(G9="",H9=""),"",H9-G9) | J9: =IF('Semaine 4'!D10<>"",'Semaine 4'!D10,IF('Semaine 3'!D10<>"",'Semaine 3'!D10,IF('Semaine 2'!D10<>"",'Semaine 2'!D10,IF('Semaine 1'!D10<>"",'Semaine 1'!D10,""))))
A10: =IF(Produits!$A$10="","",Produits!$A$10) | B10: =IF(Produits!$A$10="","",Produits!$C$10) | C10: =IF('Semaine 1'!E11="","",'Semaine 1'!E11) | D10: =IF('Semaine 2'!E11="","",'Semaine 2'!E11) | E10: =IF('Semaine 3'!E11="","",'Semaine 3'!E11) | F10: =IF('Semaine 4'!E11="","",'Semaine 4'!E11) | G10: =IF(COUNT('Semaine 1'!E11,'Semaine 2'!E11,'Semaine 3'!E11,'Semaine 4'!E11)=0,"",SUM('Semaine 1'!E11,'Semaine 2'!E11,'Semaine 3'!E11,'Semaine 4'!E11)) | H10: =IF(COUNT('Semaine 1'!F11,'Semaine 2'!F11,'Semaine 3'!F11,'Semaine 4'!F11)=0,"",SUM('Semaine 1'!F11,'Semaine 2'!F11,'Semaine 3'!F11,'Semaine 4'!F11)) | I10: =IF(OR(G10="",H10=""),"",H10-G10) | J10: =IF('Semaine 4'!D11<>"",'Semaine 4'!D11,IF('Semaine 3'!D11<>"",'Semaine 3'!D11,IF('Semaine 2'!D11<>"",'Semaine 2'!D11,IF('Semaine 1'!D11<>"",'Semaine 1'!D11,""))))
A11: =IF(Produits!$A$11="","",Produits!$A$11) | B11: =IF(Produits!$A$11="","",Produits!$C$11) | C11: =IF('Semaine 1'!E12="","",'Semaine 1'!E12) | D11: =IF('Semaine 2'!E12="","",'Semaine 2'!E12) | E11: =IF('Semaine 3'!E12="","",'Semaine 3'!E12) | F11: =IF('Semaine 4'!E12="","",'Semaine 4'!E12) | G11: =IF(COUNT('Semaine 1'!E12,'Semaine 2'!E12,'Semaine 3'!E12,'Semaine 4'!E12)=0,"",SUM('Semaine 1'!E12,'Semaine 2'!E12,'Semaine 3'!E12,'Semaine 4'!E12)) | H11: =IF(COUNT('Semaine 1'!F12,'Semaine 2'!F12,'Semaine 3'!F12,'Semaine 4'!F12)=0,"",SUM('Semaine 1'!F12,'Semaine 2'!F12,'Semaine 3'!F12,'Semaine 4'!F12)) | I11: =IF(OR(G11="",H11=""),"",H11-G11) | J11: =IF('Semaine 4'!D12<>"",'Semaine 4'!D12,IF('Semaine 3'!D12<>"",'Semaine 3'!D12,IF('Semaine 2'!D12<>"",'Semaine 2'!D12,IF('Semaine 1'!D12<>"",'Semaine 1'!D12,""))))
A12: =IF(Produits!$A$12="","",Produits!$A$12) | B12: =IF(Produits!$A$12="","",Produits!$C$12) | C12: =IF('Semaine 1'!E13="","",'Semaine 1'!E13) | D12: =IF('Semaine 2'!E13="","",'Semaine 2'!E13) | E12: =IF('Semaine 3'!E13="","",'Semaine 3'!E13) | F12: =IF('Semaine 4'!E13="","",'Semaine 4'!E13) | G12: =IF(COUNT('Semaine 1'!E13,'Semaine 2'!E13,'Semaine 3'!E13,'Semaine 4'!E13)=0,"",SUM('Semaine 1'!E13,'Semaine 2'!E13,'Semaine 3'!E13,'Semaine 4'!E13)) | H12: =IF(COUNT('Semaine 1'!F13,'Semaine 2'!F13,'Semaine 3'!F13,'Semaine 4'!F13)=0,"",SUM('Semaine 1'!F13,'Semaine 2'!F13,'Semaine 3'!F13,'Semaine 4'!F13)) | I12: =IF(OR(G12="",H12=""),"",H12-G12) | J12: =IF('Semaine 4'!D13<>"",'Semaine 4'!D13,IF('Semaine 3'!D13<>"",'Semaine 3'!D13,IF('Semaine 2'!D13<>"",'Semaine 2'!D13,IF('Semaine 1'!D13<>"",'Semaine 1'!D13,""))))
A13: =IF(Produits!$A$13="","",Produits!$A$13) | B13: =IF(Produits!$A$13="","",Produits!$C$13) | C13: =IF('Semaine 1'!E14="","",'Semaine 1'!E14) | D13: =IF('Semaine 2'!E14="","",'Semaine 2'!E14) | E13: =IF('Semaine 3'!E14="","",'Semaine 3'!E14) | F13: =IF('Semaine 4'!E14="","",'Semaine 4'!E14) | G13: =IF(COUNT('Semaine 1'!E14,'Semaine 2'!E14,'Semaine 3'!E14,'Semaine 4'!E14)=0,"",SUM('Semaine 1'!E14,'Semaine 2'!E14,'Semaine 3'!E14,'Semaine 4'!E14)) | H13: =IF(COUNT('Semaine 1'!F14,'Semaine 2'!F14,'Semaine 3'!F14,'Semaine 4'!F14)=0,"",SUM('Semaine 1'!F14,'Semaine 2'!F14,'Semaine 3'!F14,'Semaine 4'!F14)) | I13: =IF(OR(G13="",H13=""),"",H13-G13) | J13: =IF('Semaine 4'!D14<>"",'Semaine 4'!D14,IF('Semaine 3'!D14<>"",'Semaine 3'!D14,IF('Semaine 2'!D14<>"",'Semaine 2'!D14,IF('Semaine 1'!D14<>"",'Semaine 1'!D14,""))))
A14: =IF(Produits!$A$14="","",Produits!$A$14) | B14: =IF(Produits!$A$14="","",Produits!$C$14) | C14: =IF('Semaine 1'!E15="","",'Semaine 1'!E15) | D14: =IF('Semaine 2'!E15="","",'Semaine 2'!E15) | E14: =IF('Semaine 3'!E15="","",'Semaine 3'!E15) | F14: =IF('Semaine 4'!E15="","",'Semaine 4'!E15) | G14: =IF(COUNT('Semaine 1'!E15,'Semaine 2'!E15,'Semaine 3'!E15,'Semaine 4'!E15)=0,"",SUM('Semaine 1'!E15,'Semaine 2'!E15,'Semaine 3'!E15,'Semaine 4'!E15)) | H14: =IF(COUNT('Semaine 1'!F15,'Semaine 2'!F15,'Semaine 3'!F15,'Semaine 4'!F15)=0,"",SUM('Semaine 1'!F15,'Semaine 2'!F15,'Semaine 3'!F15,'Semaine 4'!F15)) | I14: =IF(OR(G14="",H14=""),"",H14-G14) | J14: =IF('Semaine 4'!D15<>"",'Semaine 4'!D15,IF('Semaine 3'!D15<>"",'Semaine 3'!D15,IF('Semaine 2'!D15<>"",'Semaine 2'!D15,IF('Semaine 1'!D15<>"",'Semaine 1'!D15,""))))
A15: =IF(Produits!$A$15="","",Produits!$A$15) | B15: =IF(Produits!$A$15="","",Produits!$C$15) | C15: =IF('Semaine 1'!E16="","",'Semaine 1'!E16) | D15: =IF('Semaine 2'!E16="","",'Semaine 2'!E16) | E15: =IF('Semaine 3'!E16="","",'Semaine 3'!E16) | F15: =IF('Semaine 4'!E16="","",'Semaine 4'!E16) | G15: =IF(COUNT('Semaine 1'!E16,'Semaine 2'!E16,'Semaine 3'!E16,'Semaine 4'!E16)=0,"",SUM('Semaine 1'!E16,'Semaine 2'!E16,'Semaine 3'!E16,'Semaine 4'!E16)) | H15: =IF(COUNT('Semaine 1'!F16,'Semaine 2'!F16,'Semaine 3'!F16,'Semaine 4'!F16)=0,"",SUM('Semaine 1'!F16,'Semaine 2'!F16,'Semaine 3'!F16,'Semaine 4'!F16)) | I15: =IF(OR(G15="",H15=""),"",H15-G15) | J15: =IF('Semaine 4'!D16<>"",'Semaine 4'!D16,IF('Semaine 3'!D16<>"",'Semaine 3'!D16,IF('Semaine 2'!D16<>"",'Semaine 2'!D16,IF('Semaine 1'!D16<>"",'Semaine 1'!D16,""))))
A16: =IF(Produits!$A$16="","",Produits!$A$16) | B16: =IF(Produits!$A$16="","",Produits!$C$16) | C16: =IF('Semaine 1'!E17="","",'Semaine 1'!E17) | D16: =IF('Semaine 2'!E17="","",'Semaine 2'!E17) | E16: =IF('Semaine 3'!E17="","",'Semaine 3'!E17) | F16: =IF('Semaine 4'!E17="","",'Semaine 4'!E17) | G16: =IF(COUNT('Semaine 1'!E17,'Semaine 2'!E17,'Semaine 3'!E17,'Semaine 4'!E17)=0,"",SUM('Semaine 1'!E17,'Semaine 2'!E17,'Semaine 3'!E17,'Semaine 4'!E17)) | H16: =IF(COUNT('Semaine 1'!F17,'Semaine 2'!F17,'Semaine 3'!F17,'Semaine 4'!F17)=0,"",SUM('Semaine 1'!F17,'Semaine 2'!F17,'Semaine 3'!F17,'Semaine 4'!F17)) | I16: =IF(OR(G16="",H16=""),"",H16-G16) | J16: =IF('Semaine 4'!D17<>"",'Semaine 4'!D17,IF('Semaine 3'!D17<>"",'Semaine 3'!D17,IF('Semaine 2'!D17<>"",'Semaine 2'!D17,IF('Semaine 1'!D17<>"",'Semaine 1'!D17,""))))
A17: =IF(Produits!$A$17="","",Produits!$A$17) | B17: =IF(Produits!$A$17="","",Produits!$C$17) | C17: =IF('Semaine 1'!E18="","",'Semaine 1'!E18) | D17: =IF('Semaine 2'!E18="","",'Semaine 2'!E18) | E17: =IF('Semaine 3'!E18="","",'Semaine 3'!E18) | F17: =IF('Semaine 4'!E18="","",'Semaine 4'!E18) | G17: =IF(COUNT('Semaine 1'!E18,'Semaine 2'!E18,'Semaine 3'!E18,'Semaine 4'!E18)=0,"",SUM('Semaine 1'!E18,'Semaine 2'!E18,'Semaine 3'!E18,'Semaine 4'!E18)) | H17: =IF(COUNT('Semaine 1'!F18,'Semaine 2'!F18,'Semaine 3'!F18,'Semaine 4'!F18)=0,"",SUM('Semaine 1'!F18,'Semaine 2'!F18,'Semaine 3'!F18,'Semaine 4'!F18)) | I17: =IF(OR(G17="",H17=""),"",H17-G17) | J17: =IF('Semaine 4'!D18<>"",'Semaine 4'!D18,IF('Semaine 3'!D18<>"",'Semaine 3'!D18,IF('Semaine 2'!D18<>"",'Semaine 2'!D18,IF('Semaine 1'!D18<>"",'Semaine 1'!D18,""))))
A18: =IF(Produits!$A$18="","",Produits!$A$18) | B18: =IF(Produits!$A$18="","",Produits!$C$18) | C18: =IF('Semaine 1'!E19="","",'Semaine 1'!E19) | D18: =IF('Semaine 2'!E19="","",'Semaine 2'!E19) | E18: =IF('Semaine 3'!E19="","",'Semaine 3'!E19) | F18: =IF('Semaine 4'!E19="","",'Semaine 4'!E19) | G18: =IF(COUNT('Semaine 1'!E19,'Semaine 2'!E19,'Semaine 3'!E19,'Semaine 4'!E19)=0,"",SUM('Semaine 1'!E19,'Semaine 2'!E19,'Semaine 3'!E19,'Semaine 4'!E19)) | H18: =IF(COUNT('Semaine 1'!F19,'Semaine 2'!F19,'Semaine 3'!F19,'Semaine 4'!F19)=0,"",SUM('Semaine 1'!F19,'Semaine 2'!F19,'Semaine 3'!F19,'Semaine 4'!F19)) | I18: =IF(OR(G18="",H18=""),"",H18-G18) | J18: =IF('Semaine 4'!D19<>"",'Semaine 4'!D19,IF('Semaine 3'!D19<>"",'Semaine 3'!D19,IF('Semaine 2'!D19<>"",'Semaine 2'!D19,IF('Semaine 1'!D19<>"",'Semaine 1'!D19,""))))
A19: =IF(Produits!$A$19="","",Produits!$A$19) | B19: =IF(Produits!$A$19="","",Produits!$C$19) | C19: =IF('Semaine 1'!E20="","",'Semaine 1'!E20) | D19: =IF('Semaine 2'!E20="","",'Semaine 2'!E20) | E19: =IF('Semaine 3'!E20="","",'Semaine 3'!E20) | F19: =IF('Semaine 4'!E20="","",'Semaine 4'!E20) | G19: =IF(COUNT('Semaine 1'!E20,'Semaine 2'!E20,'Semaine 3'!E20,'Semaine 4'!E20)=0,"",SUM('Semaine 1'!E20,'Semaine 2'!E20,'Semaine 3'!E20,'Semaine 4'!E20)) | H19: =IF(COUNT('Semaine 1'!F20,'Semaine 2'!F20,'Semaine 3'!F20,'Semaine 4'!F20)=0,"",SUM('Semaine 1'!F20,'Semaine 2'!F20,'Semaine 3'!F20,'Semaine 4'!F20)) | I19: =IF(OR(G19="",H19=""),"",H19-G19) | J19: =IF('Semaine 4'!D20<>"",'Semaine 4'!D20,IF('Semaine 3'!D20<>"",'Semaine 3'!D20,IF('Semaine 2'!D20<>"",'Semaine 2'!D20,IF('Semaine 1'!D20<>"",'Semaine 1'!D20,""))))
A20: =IF(Produits!$A$20="","",Produits!$A$20) | B20: =IF(Produits!$A$20="","",Produits!$C$20) | C20: =IF('Semaine 1'!E21="","",'Semaine 1'!E21) | D20: =IF('Semaine 2'!E21="","",'Semaine 2'!E21) | E20: =IF('Semaine 3'!E21="","",'Semaine 3'!E21) | F20: =IF('Semaine 4'!E21="","",'Semaine 4'!E21) | G20: =IF(COUNT('Semaine 1'!E21,'Semaine 2'!E21,'Semaine 3'!E21,'Semaine 4'!E21)=0,"",SUM('Semaine 1'!E21,'Semaine 2'!E21,'Semaine 3'!E21,'Semaine 4'!E21)) | H20: =IF(COUNT('Semaine 1'!F21,'Semaine 2'!F21,'Semaine 3'!F21,'Semaine 4'!F21)=0,"",SUM('Semaine 1'!F21,'Semaine 2'!F21,'Semaine 3'!F21,'Semaine 4'!F21)) | I20: =IF(OR(G20="",H20=""),"",H20-G20) | J20: =IF('Semaine 4'!D21<>"",'Semaine 4'!D21,IF('Semaine 3'!D21<>"",'Semaine 3'!D21,IF('Semaine 2'!D21<>"",'Semaine 2'!D21,IF('Semaine 1'!D21<>"",'Semaine 1'!D21,""))))
A21: =IF(Produits!$A$21="","",Produits!$A$21) | B21: =IF(Produits!$A$21="","",Produits!$C$21) | C21: =IF('Semaine 1'!E22="","",'Semaine 1'!E22) | D21: =IF('Semaine 2'!E22="","",'Semaine 2'!E22) | E21: =IF('Semaine 3'!E22="","",'Semaine 3'!E22) | F21: =IF('Semaine 4'!E22="","",'Semaine 4'!E22) | G21: =IF(COUNT('Semaine 1'!E22,'Semaine 2'!E22,'Semaine 3'!E22,'Semaine 4'!E22)=0,"",SUM('Semaine 1'!E22,'Semaine 2'!E22,'Semaine 3'!E22,'Semaine 4'!E22)) | H21: =IF(COUNT('Semaine 1'!F22,'Semaine 2'!F22,'Semaine 3'!F22,'Semaine 4'!F22)=0,"",SUM('Semaine 1'!F22,'Semaine 2'!F22,'Semaine 3'!F22,'Semaine 4'!F22)) | I21: =IF(OR(G21="",H21=""),"",H21-G21) | J21: =IF('Semaine 4'!D22<>"",'Semaine 4'!D22,IF('Semaine 3'!D22<>"",'Semaine 3'!D22,IF('Semaine 2'!D22<>"",'Semaine 2'!D22,IF('Semaine 1'!D22<>"",'Semaine 1'!D22,""))))
A22: =IF(Produits!$A$22="","",Produits!$A$22) | B22: =IF(Produits!$A$22="","",Produits!$C$22) | C22: =IF('Semaine 1'!E23="","",'Semaine 1'!E23) | D22: =IF('Semaine 2'!E23="","",'Semaine 2'!E23) | E22: =IF('Semaine 3'!E23="","",'Semaine 3'!E23) | F22: =IF('Semaine 4'!E23="","",'Semaine 4'!E23) | G22: =IF(COUNT('Semaine 1'!E23,'Semaine 2'!E23,'Semaine 3'!E23,'Semaine 4'!E23)=0,"",SUM('Semaine 1'!E23,'Semaine 2'!E23,'Semaine 3'!E23,'Semaine 4'!E23)) | H22: =IF(COUNT('Semaine 1'!F23,'Semaine 2'!F23,'Semaine 3'!F23,'Semaine 4'!F23)=0,"",SUM('Semaine 1'!F23,'Semaine 2'!F23,'Semaine 3'!F23,'Semaine 4'!F23)) | I22: =IF(OR(G22="",H22=""),"",H22-G22) | J22: =IF('Semaine 4'!D23<>"",'Semaine 4'!D23,IF('Semaine 3'!D23<>"",'Semaine 3'!D23,IF('Semaine 2'!D23<>"",'Semaine 2'!D23,IF('Semaine 1'!D23<>"",'Semaine 1'!D23,""))))
A23: =IF(Produits!$A$23="","",Produits!$A$23) | B23: =IF(Produits!$A$23="","",Produits!$C$23) | C23: =IF('Semaine 1'!E24="","",'Semaine 1'!E24) | D23: =IF('Semaine 2'!E24="","",'Semaine 2'!E24) | E23: =IF('Semaine 3'!E24="","",'Semaine 3'!E24) | F23: =IF('Semaine 4'!E24="","",'Semaine 4'!E24) | G23: =IF(COUNT('Semaine 1'!E24,'Semaine 2'!E24,'Semaine 3'!E24,'Semaine 4'!E24)=0,"",SUM('Semaine 1'!E24,'Semaine 2'!E24,'Semaine 3'!E24,'Semaine 4'!E24)) | H23: =IF(COUNT('Semaine 1'!F24,'Semaine 2'!F24,'Semaine 3'!F24,'Semaine 4'!F24)=0,"",SUM('Semaine 1'!F24,'Semaine 2'!F24,'Semaine 3'!F24,'Semaine 4'!F24)) | I23: =IF(OR(G23="",H23=""),"",H23-G23) | J23: =IF('Semaine 4'!D24<>"",'Semaine 4'!D24,IF('Semaine 3'!D24<>"",'Semaine 3'!D24,IF('Semaine 2'!D24<>"",'Semaine 2'!D24,IF('Semaine 1'!D24<>"",'Semaine 1'!D24,""))))
A24: =IF(Produits!$A$24="","",Produits!$A$24) | B24: =IF(Produits!$A$24="","",Produits!$C$24) | C24: =IF('Semaine 1'!E25="","",'Semaine 1'!E25) | D24: =IF('Semaine 2'!E25="","",'Semaine 2'!E25) | E24: =IF('Semaine 3'!E25="","",'Semaine 3'!E25) | F24: =IF('Semaine 4'!E25="","",'Semaine 4'!E25) | G24: =IF(COUNT('Semaine 1'!E25,'Semaine 2'!E25,'Semaine 3'!E25,'Semaine 4'!E25)=0,"",SUM('Semaine 1'!E25,'Semaine 2'!E25,'Semaine 3'!E25,'Semaine 4'!E25)) | H24: =IF(COUNT('Semaine 1'!F25,'Semaine 2'!F25,'Semaine 3'!F25,'Semaine 4'!F25)=0,"",SUM('Semaine 1'!F25,'Semaine 2'!F25,'Semaine 3'!F25,'Semaine 4'!F25)) | I24: =IF(OR(G24="",H24=""),"",H24-G24) | J24: =IF('Semaine 4'!D25<>"",'Semaine 4'!D25,IF('Semaine 3'!D25<>"",'Semaine 3'!D25,IF('Semaine 2'!D25<>"",'Semaine 2'!D25,IF('Semaine 1'!D25<>"",'Semaine 1'!D25,""))))
A25: =IF(Produits!$A$25="","",Produits!$A$25) | B25: =IF(Produits!$A$25="","",Produits!$C$25) | C25: =IF('Semaine 1'!E26="","",'Semaine 1'!E26) | D25: =IF('Semaine 2'!E26="","",'Semaine 2'!E26) | E25: =IF('Semaine 3'!E26="","",'Semaine 3'!E26) | F25: =IF('Semaine 4'!E26="","",'Semaine 4'!E26) | G25: =IF(COUNT('Semaine 1'!E26,'Semaine 2'!E26,'Semaine 3'!E26,'Semaine 4'!E26)=0,"",SUM('Semaine 1'!E26,'Semaine 2'!E26,'Semaine 3'!E26,'Semaine 4'!E26)) | H25: =IF(COUNT('Semaine 1'!F26,'Semaine 2'!F26,'Semaine 3'!F26,'Semaine 4'!F26)=0,"",SUM('Semaine 1'!F26,'Semaine 2'!F26,'Semaine 3'!F26,'Semaine 4'!F26)) | I25: =IF(OR(G25="",H25=""),"",H25-G25) | J25: =IF('Semaine 4'!D26<>"",'Semaine 4'!D26,IF('Semaine 3'!D26<>"",'Semaine 3'!D26,IF('Semaine 2'!D26<>"",'Semaine 2'!D26,IF('Semaine 1'!D26<>"",'Semaine 1'!D26,""))))
A26: =IF(Produits!$A$26="","",Produits!$A$26) | B26: =IF(Produits!$A$26="","",Produits!$C$26) | C26: =IF('Semaine 1'!E27="","",'Semaine 1'!E27) | D26: =IF('Semaine 2'!E27="","",'Semaine 2'!E27) | E26: =IF('Semaine 3'!E27="","",'Semaine 3'!E27) | F26: =IF('Semaine 4'!E27="","",'Semaine 4'!E27) | G26: =IF(COUNT('Semaine 1'!E27,'Semaine 2'!E27,'Semaine 3'!E27,'Semaine 4'!E27)=0,"",SUM('Semaine 1'!E27,'Semaine 2'!E27,'Semaine 3'!E27,'Semaine 4'!E27)) | H26: =IF(COUNT('Semaine 1'!F27,'Semaine 2'!F27,'Semaine 3'!F27,'Semaine 4'!F27)=0,"",SUM('Semaine 1'!F27,'Semaine 2'!F27,'Semaine 3'!F27,'Semaine 4'!F27)) | I26: =IF(OR(G26="",H26=""),"",H26-G26) | J26: =IF('Semaine 4'!D27<>"",'Semaine 4'!D27,IF('Semaine 3'!D27<>"",'Semaine 3'!D27,IF('Semaine 2'!D27<>"",'Semaine 2'!D27,IF('Semaine 1'!D27<>"",'Semaine 1'!D27,""))))
A27: =IF(Produits!$A$27="","",Produits!$A$27) | B27: =IF(Produits!$A$27="","",Produits!$C$27) | C27: =IF('Semaine 1'!E28="","",'Semaine 1'!E28) | D27: =IF('Semaine 2'!E28="","",'Semaine 2'!E28) | E27: =IF('Semaine 3'!E28="","",'Semaine 3'!E28) | F27: =IF('Semaine 4'!E28="","",'Semaine 4'!E28) | G27: =IF(COUNT('Semaine 1'!E28,'Semaine 2'!E28,'Semaine 3'!E28,'Semaine 4'!E28)=0,"",SUM('Semaine 1'!E28,'Semaine 2'!E28,'Semaine 3'!E28,'Semaine 4'!E28)) | H27: =IF(COUNT('Semaine 1'!F28,'Semaine 2'!F28,'Semaine 3'!F28,'Semaine 4'!F28)=0,"",SUM('Semaine 1'!F28,'Semaine 2'!F28,'Semaine 3'!F28,'Semaine 4'!F28)) | I27: =IF(OR(G27="",H27=""),"",H27-G27) | J27: =IF('Semaine 4'!D28<>"",'Semaine 4'!D28,IF('Semaine 3'!D28<>"",'Semaine 3'!D28,IF('Semaine 2'!D28<>"",'Semaine 2'!D28,IF('Semaine 1'!D28<>"",'Semaine 1'!D28,""))))
A28: =IF(Produits!$A$28="","",Produits!$A$28) | B28: =IF(Produits!$A$28="","",Produits!$C$28) | C28: =IF('Semaine 1'!E29="","",'Semaine 1'!E29) | D28: =IF('Semaine 2'!E29="","",'Semaine 2'!E29) | E28: =IF('Semaine 3'!E29="","",'Semaine 3'!E29) | F28: =IF('Semaine 4'!E29="","",'Semaine 4'!E29) | G28: =IF(COUNT('Semaine 1'!E29,'Semaine 2'!E29,'Semaine 3'!E29,'Semaine 4'!E29)=0,"",SUM('Semaine 1'!E29,'Semaine 2'!E29,'Semaine 3'!E29,'Semaine 4'!E29)) | H28: =IF(COUNT('Semaine 1'!F29,'Semaine 2'!F29,'Semaine 3'!F29,'Semaine 4'!F29)=0,"",SUM('Semaine 1'!F29,'Semaine 2'!F29,'Semaine 3'!F29,'Semaine 4'!F29)) | I28: =IF(OR(G28="",H28=""),"",H28-G28) | J28: =IF('Semaine 4'!D29<>"",'Semaine 4'!D29,IF('Semaine 3'!D29<>"",'Semaine 3'!D29,IF('Semaine 2'!D29<>"",'Semaine 2'!D29,IF('Semaine 1'!D29<>"",'Semaine 1'!D29,""))))
A29: =IF(Produits!$A$29="","",Produits!$A$29) | B29: =IF(Produits!$A$29="","",Produits!$C$29) | C29: =IF('Semaine 1'!E30="","",'Semaine 1'!E30) | D29: =IF('Semaine 2'!E30="","",'Semaine 2'!E30) | E29: =IF('Semaine 3'!E30="","",'Semaine 3'!E30) | F29: =IF('Semaine 4'!E30="","",'Semaine 4'!E30) | G29: =IF(COUNT('Semaine 1'!E30,'Semaine 2'!E30,'Semaine 3'!E30,'Semaine 4'!E30)=0,"",SUM('Semaine 1'!E30,'Semaine 2'!E30,'Semaine 3'!E30,'Semaine 4'!E30)) | H29: =IF(COUNT('Semaine 1'!F30,'Semaine 2'!F30,'Semaine 3'!F30,'Semaine 4'!F30)=0,"",SUM('Semaine 1'!F30,'Semaine 2'!F30,'Semaine 3'!F30,'Semaine 4'!F30)) | I29: =IF(OR(G29="",H29=""),"",H29-G29) | J29: =IF('Semaine 4'!D30<>"",'Semaine 4'!D30,IF('Semaine 3'!D30<>"",'Semaine 3'!D30,IF('Semaine 2'!D30<>"",'Semaine 2'!D30,IF('Semaine 1'!D30<>"",'Semaine 1'!D30,""))))
A30: =IF(Produits!$A$30="","",Produits!$A$30) | B30: =IF(Produits!$A$30="","",Produits!$C$30) | C30: =IF('Semaine 1'!E31="","",'Semaine 1'!E31) | D30: =IF('Semaine 2'!E31="","",'Semaine 2'!E31) | E30: =IF('Semaine 3'!E31="","",'Semaine 3'!E31) | F30: =IF('Semaine 4'!E31="","",'Semaine 4'!E31) | G30: =IF(COUNT('Semaine 1'!E31,'Semaine 2'!E31,'Semaine 3'!E31,'Semaine 4'!E31)=0,"",SUM('Semaine 1'!E31,'Semaine 2'!E31,'Semaine 3'!E31,'Semaine 4'!E31)) | H30: =IF(COUNT('Semaine 1'!F31,'Semaine 2'!F31,'Semaine 3'!F31,'Semaine 4'!F31)=0,"",SUM('Semaine 1'!F31,'Semaine 2'!F31,'Semaine 3'!F31,'Semaine 4'!F31)) | I30: =IF(OR(G30="",H30=""),"",H30-G30) | J30: =IF('Semaine 4'!D31<>"",'Semaine 4'!D31,IF('Semaine 3'!D31<>"",'Semaine 3'!D31,IF('Semaine 2'!D31<>"",'Semaine 2'!D31,IF('Semaine 1'!D31<>"",'Semaine 1'!D31,""))))
A31: =IF(Produits!$A$31="","",Produits!$A$31) | B31: =IF(Produits!$A$31="","",Produits!$C$31) | C31: =IF('Semaine 1'!E32="","",'Semaine 1'!E32) | D31: =IF('Semaine 2'!E32="","",'Semaine 2'!E32) | E31: =IF('Semaine 3'!E32="","",'Semaine 3'!E32) | F31: =IF('Semaine 4'!E32="","",'Semaine 4'!E32) | G31: =IF(COUNT('Semaine 1'!E32,'Semaine 2'!E32,'Semaine 3'!E32,'Semaine 4'!E32)=0,"",SUM('Semaine 1'!E32,'Semaine 2'!E32,'Semaine 3'!E32,'Semaine 4'!E32)) | H31: =IF(COUNT('Semaine 1'!F32,'Semaine 2'!F32,'Semaine 3'!F32,'Semaine 4'!F32)=0,"",SUM('Semaine 1'!F32,'Semaine 2'!F32,'Semaine 3'!F32,'Semaine 4'!F32)) | I31: =IF(OR(G31="",H31=""),"",H31-G31) | J31: =IF('Semaine 4'!D32<>"",'Semaine 4'!D32,IF('Semaine 3'!D32<>"",'Semaine 3'!D32,IF('Semaine 2'!D32<>"",'Semaine 2'!D32,IF('Semaine 1'!D32<>"",'Semaine 1'!D32,""))))
A32: =IF(Produits!$A$32="","",Produits!$A$32) | B32: =IF(Produits!$A$32="","",Produits!$C$32) | C32: =IF('Semaine 1'!E33="","",'Semaine 1'!E33) | D32: =IF('Semaine 2'!E33="","",'Semaine 2'!E33) | E32: =IF('Semaine 3'!E33="","",'Semaine 3'!E33) | F32: =IF('Semaine 4'!E33="","",'Semaine 4'!E33) | G32: =IF(COUNT('Semaine 1'!E33,'Semaine 2'!E33,'Semaine 3'!E33,'Semaine 4'!E33)=0,"",SUM('Semaine 1'!E33,'Semaine 2'!E33,'Semaine 3'!E33,'Semaine 4'!E33)) | H32: =IF(COUNT('Semaine 1'!F33,'Semaine 2'!F33,'Semaine 3'!F33,'Semaine 4'!F33)=0,"",SUM('Semaine 1'!F33,'Semaine 2'!F33,'Semaine 3'!F33,'Semaine 4'!F33)) | I32: =IF(OR(G32="",H32=""),"",H32-G32) | J32: =IF('Semaine 4'!D33<>"",'Semaine 4'!D33,IF('Semaine 3'!D33<>"",'Semaine 3'!D33,IF('Semaine 2'!D33<>"",'Semaine 2'!D33,IF('Semaine 1'!D33<>"",'Semaine 1'!D33,""))))
