Workbook

Sheet Mode d'emploi
A1: 5 · La liste de courses
A2: Proposition de tableau de gestion des stocks — Excel et Google Sheets
A4: L'idée | B4: Pour chaque produit, tu indiques une fois pour toutes ton stock minimum et ton stock idéal. Le vendredi, tu comptes ce qu'il reste : le fichier te propose la quantité à commander et signale en orange ce qui est passé sous le minimum. Tu restes libre de commander autre chose.
A6: Comment faire | B6: 1. Onglet Produits : produit, fournisseur, unité, stock minimum, stock idéal.
B7: 2. Le vendredi : colonne Stock. La colonne Suggéré se remplit (stock idéal − stock restant).
B8: 3. Tu écris ce que tu commandes vraiment dans Commandé (tu peux suivre la suggestion ou pas).
B9: 4. À la livraison : Reçu. Nouveau mois : duplique l'onglet du mois.
A11: Les onglets | B11: Produits — ta liste, avec stock minimum et stock idéal.
B12: Octobre 2026 — 4 semaines ; orange = sous le minimum, rouge = livraison incomplète.
A14: Couleurs | B14: Cases jaunes = à remplir. Cases blanches = calculées toutes seules, ne pas y toucher.
B15: Chiffres en bleu = exemple pour montrer le fonctionnement, à effacer.
B16: Rouge = il manque quelque chose (livraison incomplète, stock trop bas).
A18: Google Sheets | B18: Fichier > Importer > Importer ce fichier. Tout fonctionne pareil, y compris sur téléphone.

Sheet Produits
A1: Mes produits
A2: Une ligne par produit. Tout le reste du fichier se remplit à partir de cette liste.
A4: Produit | B4: Fournisseur | C4: Unité | D4: Stock minimum | E4: Stock idéal
A5: Farine T55 | B5: Metro | C5: kg | D5: 5 | E5: 15
A6: Farine T45 | B6: Metro | C6: kg | D6: 3 | E6: 8
A7: Sucre semoule | B7: Metro | C7: kg | D7: 5 | E7: 15
A8: Sucre glace | B8: Metro | C8: kg | D8: 2 | E8: 4
A9: Beurre doux | B9: Crèmerie | C9: kg | D9: 4 | E9: 8
A10: Crème liquide 35% | B10: Crèmerie | C10: L | D10: 6 | E10: 15
A11: Lait entier | B11: Crèmerie | C11: L | D11: 5 | E11: 10
A12: Oeufs | B12: Crèmerie | C12: pièce | D12: 60 | E12: 150
A13: Chocolat blanc | B13: Transgourmet | C13: kg | D13: 2 | E13: 4
A14: Chocolat noir 70% | B14: Transgourmet | C14: kg | D14: 2 | E14: 4
A15: Levure chimique | B15: Transgourmet | C15: kg | D15: 0.5 | E15: 1
A16: Vanille (gousse) | B16: Transgourmet | C16: pièce | D16: 5 | E16: 10

Sheet Octobre 2026
A1: Octobre 2026
A2: Suggéré = stock idéal − stock restant (arrondi). Orange = sous le minimum.
A4: Produit | B4: Fournisseur | C4: Unité | D4: Stock mini | E4: Semaine 1 | I4: Semaine 2 | M4: Semaine 3 | Q4: Semaine 4 | U4: Total du mois
E6: Stock | F6: Suggéré | G6: Commandé | H6: Reçu | I6: Stock | J6: Suggéré | K6: Commandé | L6: Reçu | M6: Stock | N6: Suggéré | O6: Commandé | P6: Reçu | Q6: Stock | R6: Suggéré | S6: Commandé | T6: Reçu | U6: Commandé | V6: Reçu
A7: =IF(Produits!$A$5="","",Produits!$A$5) | B7: =IF(Produits!$A$5="","",Produits!$B$5) | C7: =IF(Produits!$A$5="","",Produits!$C$5) | D7: =IF(Produits!$A$5="","",Produits!$D$5) | E7: 8 | F7: =IF(OR(E7="",Produits!$E$5=""),"",MAX(0,CEILING(Produits!$E$5-E7,1))) | G7: 10 | H7: 7 | I7: 5 | J7: =IF(OR(I7="",Produits!$E$5=""),"",MAX(0,CEILING(Produits!$E$5-I7,1))) | K7: 10 | L7: 10 | N7: =IF(OR(M7="",Produits!$E$5=""),"",MAX(0,CEILING(Produits!$E$5-M7,1))) | R7: =IF(OR(Q7="",Produits!$E$5=""),"",MAX(0,CEILING(Produits!$E$5-Q7,1))) | U7: =IF(COUNT(G7,K7,O7,S7)=0,"",SUM(G7,K7,O7,S7)) | V7: =IF(COUNT(H7,L7,P7,T7)=0,"",SUM(H7,L7,P7,T7))
A8: =IF(Produits!$A$6="","",Produits!$A$6) | B8: =IF(Produits!$A$6="","",Produits!$B$6) | C8: =IF(Produits!$A$6="","",Produits!$C$6) | D8: =IF(Produits!$A$6="","",Produits!$D$6) | E8: 2 | F8: =IF(OR(E8="",Produits!$E$6=""),"",MAX(0,CEILING(Produits!$E$6-E8,1))) | G8: 5 | H8: 5 | I8: 3 | J8: =IF(OR(I8="",Produits!$E$6=""),"",MAX(0,CEILING(Produits!$E$6-I8,1))) | K8: 3 | L8: 3 | N8: =IF(OR(M8="",Produits!$E$6=""),"",MAX(0,CEILING(Produits!$E$6-M8,1))) | R8: =IF(OR(Q8="",Produits!$E$6=""),"",MAX(0,CEILING(Produits!$E$6-Q8,1))) | U8: =IF(COUNT(G8,K8,O8,S8)=0,"",SUM(G8,K8,O8,S8)) | V8: =IF(COUNT(H8,L8,P8,T8)=0,"",SUM(H8,L8,P8,T8))
A9: =IF(Produits!$A$7="","",Produits!$A$7) | B9: =IF(Produits!$A$7="","",Produits!$B$7) | C9: =IF(Produits!$A$7="","",Produits!$C$7) | D9: =IF(Produits!$A$7="","",Produits!$D$7) | E9: 6 | F9: =IF(OR(E9="",Produits!$E$7=""),"",MAX(0,CEILING(Produits!$E$7-E9,1))) | G9: 10 | H9: 10 | I9: 7 | J9: =IF(OR(I9="",Produits!$E$7=""),"",MAX(0,CEILING(Produits!$E$7-I9,1))) | K9: 5 | L9: 5 | N9: =IF(OR(M9="",Produits!$E$7=""),"",MAX(0,CEILING(Produits!$E$7-M9,1))) | R9: =IF(OR(Q9="",Produits!$E$7=""),"",MAX(0,CEILING(Produits!$E$7-Q9,1))) | U9: =IF(COUNT(G9,K9,O9,S9)=0,"",SUM(G9,K9,O9,S9)) | V9: =IF(COUNT(H9,L9,P9,T9)=0,"",SUM(H9,L9,P9,T9))
A10: =IF(Produits!$A$8="","",Produits!$A$8) | B10: =IF(Produits!$A$8="","",Produits!$B$8) | C10: =IF(Produits!$A$8="","",Produits!$C$8) | D10: =IF(Produits!$A$8="","",Produits!$D$8) | E10: 1 | F10: =IF(OR(E10="",Produits!$E$8=""),"",MAX(0,CEILING(Produits!$E$8-E10,1))) | G10: 3 | H10: 3 | I10: 2 | J10: =IF(OR(I10="",Produits!$E$8=""),"",MAX(0,CEILING(Produits!$E$8-I10,1))) | K10: 0 | L10: 0 | N10: =IF(OR(M10="",Produits!$E$8=""),"",MAX(0,CEILING(Produits!$E$8-M10,1))) | R10: =IF(OR(Q10="",Produits!$E$8=""),"",MAX(0,CEILING(Produits!$E$8-Q10,1))) | U10: =IF(COUNT(G10,K10,O10,S10)=0,"",SUM(G10,K10,O10,S10)) | V10: =IF(COUNT(H10,L10,P10,T10)=0,"",SUM(H10,L10,P10,T10))
A11: =IF(Produits!$A$9="","",Produits!$A$9) | B11: =IF(Produits!$A$9="","",Produits!$B$9) | C11: =IF(Produits!$A$9="","",Produits!$C$9) | D11: =IF(Produits!$A$9="","",Produits!$D$9) | E11: 3 | F11: =IF(OR(E11="",Produits!$E$9=""),"",MAX(0,CEILING(Produits!$E$9-E11,1))) | G11: 5 | H11: 5 | I11: 4 | J11: =IF(OR(I11="",Produits!$E$9=""),"",MAX(0,CEILING(Produits!$E$9-I11,1))) | K11: 5 | L11: 5 | N11: =IF(OR(M11="",Produits!$E$9=""),"",MAX(0,CEILING(Produits!$E$9-M11,1))) | R11: =IF(OR(Q11="",Produits!$E$9=""),"",MAX(0,CEILING(Produits!$E$9-Q11,1))) | U11: =IF(COUNT(G11,K11,O11,S11)=0,"",SUM(G11,K11,O11,S11)) | V11: =IF(COUNT(H11,L11,P11,T11)=0,"",SUM(H11,L11,P11,T11))
A12: =IF(Produits!$A$10="","",Produits!$A$10) | B12: =IF(Produits!$A$10="","",Produits!$B$10) | C12: =IF(Produits!$A$10="","",Produits!$C$10) | D12: =IF(Produits!$A$10="","",Produits!$D$10) | E12: 4 | F12: =IF(OR(E12="",Produits!$E$10=""),"",MAX(0,CEILING(Produits!$E$10-E12,1))) | G12: 12 | H12: 12 | I12: 5 | J12: =IF(OR(I12="",Produits!$E$10=""),"",MAX(0,CEILING(Produits!$E$10-I12,1))) | K12: 10 | L12: 10 | N12: =IF(OR(M12="",Produits!$E$10=""),"",MAX(0,CEILING(Produits!$E$10-M12,1))) | R12: =IF(OR(Q12="",Produits!$E$10=""),"",MAX(0,CEILING(Produits!$E$10-Q12,1))) | U12: =IF(COUNT(G12,K12,O12,S12)=0,"",SUM(G12,K12,O12,S12)) | V12: =IF(COUNT(H12,L12,P12,T12)=0,"",SUM(H12,L12,P12,T12))
A13: =IF(Produits!$A$11="","",Produits!$A$11) | B13: =IF(Produits!$A$11="","",Produits!$B$11) | C13: =IF(Produits!$A$11="","",Produits!$C$11) | D13: =IF(Produits!$A$11="","",Produits!$D$11) | E13: 3 | F13: =IF(OR(E13="",Produits!$E$11=""),"",MAX(0,CEILING(Produits!$E$11-E13,1))) | G13: 6 | H13: 6 | I13: 4 | J13: =IF(OR(I13="",Produits!$E$11=""),"",MAX(0,CEILING(Produits!$E$11-I13,1))) | K13: 6 | L13: 6 | N13: =IF(OR(M13="",Produits!$E$11=""),"",MAX(0,CEILING(Produits!$E$11-M13,1))) | R13: =IF(OR(Q13="",Produits!$E$11=""),"",MAX(0,CEILING(Produits!$E$11-Q13,1))) | U13: =IF(COUNT(G13,K13,O13,S13)=0,"",SUM(G13,K13,O13,S13)) | V13: =IF(COUNT(H13,L13,P13,T13)=0,"",SUM(H13,L13,P13,T13))
A14: =IF(Produits!$A$12="","",Produits!$A$12) | B14: =IF(Produits!$A$12="","",Produits!$B$12) | C14: =IF(Produits!$A$12="","",Produits!$C$12) | D14: =IF(Produits!$A$12="","",Produits!$D$12) | E14: 40 | F14: =IF(OR(E14="",Produits!$E$12=""),"",MAX(0,CEILING(Produits!$E$12-E14,1))) | G14: 90 | H14: 90 | I14: 50 | J14: =IF(OR(I14="",Produits!$E$12=""),"",MAX(0,CEILING(Produits!$E$12-I14,1))) | K14: 60 | L14: 60 | N14: =IF(OR(M14="",Produits!$E$12=""),"",MAX(0,CEILING(Produits!$E$12-M14,1))) | R14: =IF(OR(Q14="",Produits!$E$12=""),"",MAX(0,CEILING(Produits!$E$12-Q14,1))) | U14: =IF(COUNT(G14,K14,O14,S14)=0,"",SUM(G14,K14,O14,S14)) | V14: =IF(COUNT(H14,L14,P14,T14)=0,"",SUM(H14,L14,P14,T14))
A15: =IF(Produits!$A$13="","",Produits!$A$13) | B15: =IF(Produits!$A$13="","",Produits!$B$13) | C15: =IF(Produits!$A$13="","",Produits!$C$13) | D15: =IF(Produits!$A$13="","",Produits!$D$13) | E15: 1.5 | F15: =IF(OR(E15="",Produits!$E$13=""),"",MAX(0,CEILING(Produits!$E$13-E15,1))) | G15: 3 | H15: 2 | I15: 2 | J15: =IF(OR(I15="",Produits!$E$13=""),"",MAX(0,CEILING(Produits!$E$13-I15,1))) | K15: 2 | L15: 2 | N15: =IF(OR(M15="",Produits!$E$13=""),"",MAX(0,CEILING(Produits!$E$13-M15,1))) | R15: =IF(OR(Q15="",Produits!$E$13=""),"",MAX(0,CEILING(Produits!$E$13-Q15,1))) | U15: =IF(COUNT(G15,K15,O15,S15)=0,"",SUM(G15,K15,O15,S15)) | V15: =IF(COUNT(H15,L15,P15,T15)=0,"",SUM(H15,L15,P15,T15))
A16: =IF(Produits!$A$14="","",Produits!$A$14) | B16: =IF(Produits!$A$14="","",Produits!$B$14) | C16: =IF(Produits!$A$14="","",Produits!$C$14) | D16: =IF(Produits!$A$14="","",Produits!$D$14) | E16: 2 | F16: =IF(OR(E16="",Produits!$E$14=""),"",MAX(0,CEILING(Produits!$E$14-E16,1))) | G16: 2 | H16: 2 | I16: 2 | J16: =IF(OR(I16="",Produits!$E$14=""),"",MAX(0,CEILING(Produits!$E$14-I16,1))) | K16: 2 | L16: 2 | N16: =IF(OR(M16="",Produits!$E$14=""),"",MAX(0,CEILING(Produits!$E$14-M16,1))) | R16: =IF(OR(Q16="",Produits!$E$14=""),"",MAX(0,CEILING(Produits!$E$14-Q16,1))) | U16: =IF(COUNT(G16,K16,O16,S16)=0,"",SUM(G16,K16,O16,S16)) | V16: =IF(COUNT(H16,L16,P16,T16)=0,"",SUM(H16,L16,P16,T16))
A17: =IF(Produits!$A$15="","",Produits!$A$15) | B17: =IF(Produits!$A$15="","",Produits!$B$15) | C17: =IF(Produits!$A$15="","",Produits!$C$15) | D17: =IF(Produits!$A$15="","",Produits!$D$15) | E17: 0.4 | F17: =IF(OR(E17="",Produits!$E$15=""),"",MAX(0,CEILING(Produits!$E$15-E17,1))) | G17: 1 | H17: 1 | I17: 0.6 | J17: =IF(OR(I17="",Produits!$E$15=""),"",MAX(0,CEILING(Produits!$E$15-I17,1))) | K17: 0 | L17: 0 | N17: =IF(OR(M17="",Produits!$E$15=""),"",MAX(0,CEILING(Produits!$E$15-M17,1))) | R17: =IF(OR(Q17="",Produits!$E$15=""),"",MAX(0,CEILING(Produits!$E$15-Q17,1))) | U17: =IF(COUNT(G17,K17,O17,S17)=0,"",SUM(G17,K17,O17,S17)) | V17: =IF(COUNT(H17,L17,P17,T17)=0,"",SUM(H17,L17,P17,T17))
A18: =IF(Produits!$A$16="","",Produits!$A$16) | B18: =IF(Produits!$A$16="","",Produits!$B$16) | C18: =IF(Produits!$A$16="","",Produits!$C$16) | D18: =IF(Produits!$A$16="","",Produits!$D$16) | E18: 6 | F18: =IF(OR(E18="",Produits!$E$16=""),"",MAX(0,CEILING(Produits!$E$16-E18,1))) | G18: 0 | H18: 0 | I18: 6 | J18: =IF(OR(I18="",Produits!$E$16=""),"",MAX(0,CEILING(Produits!$E$16-I18,1))) | K18: 0 | L18: 0 | N18: =IF(OR(M18="",Produits!$E$16=""),"",MAX(0,CEILING(Produits!$E$16-M18,1))) | R18: =IF(OR(Q18="",Produits!$E$16=""),"",MAX(0,CEILING(Produits!$E$16-Q18,1))) | U18: =IF(COUNT(G18,K18,O18,S18)=0,"",SUM(G18,K18,O18,S18)) | V18: =IF(COUNT(H18,L18,P18,T18)=0,"",SUM(H18,L18,P18,T18))
A19: =IF(Produits!$A$17="","",Produits!$A$17) | B19: =IF(Produits!$A$17="","",Produits!$B$17) | C19: =IF(Produits!$A$17="","",Produits!$C$17) | D19: =IF(Produits!$A$17="","",Produits!$D$17) | F19: =IF(OR(E19="",Produits!$E$17=""),"",MAX(0,CEILING(Produits!$E$17-E19,1))) | J19: =IF(OR(I19="",Produits!$E$17=""),"",MAX(0,CEILING(Produits!$E$17-I19,1))) | N19: =IF(OR(M19="",Produits!$E$17=""),"",MAX(0,CEILING(Produits!$E$17-M19,1))) | R19: =IF(OR(Q19="",Produits!$E$17=""),"",MAX(0,CEILING(Produits!$E$17-Q19,1))) | U19: =IF(COUNT(G19,K19,O19,S19)=0,"",SUM(G19,K19,O19,S19)) | V19: =IF(COUNT(H19,L19,P19,T19)=0,"",SUM(H19,L19,P19,T19))
A20: =IF(Produits!$A$18="","",Produits!$A$18) | B20: =IF(Produits!$A$18="","",Produits!$B$18) | C20: =IF(Produits!$A$18="","",Produits!$C$18) | D20: =IF(Produits!$A$18="","",Produits!$D$18) | F20: =IF(OR(E20="",Produits!$E$18=""),"",MAX(0,CEILING(Produits!$E$18-E20,1))) | J20: =IF(OR(I20="",Produits!$E$18=""),"",MAX(0,CEILING(Produits!$E$18-I20,1))) | N20: =IF(OR(M20="",Produits!$E$18=""),"",MAX(0,CEILING(Produits!$E$18-M20,1))) | R20: =IF(OR(Q20="",Produits!$E$18=""),"",MAX(0,CEILING(Produits!$E$18-Q20,1))) | U20: =IF(COUNT(G20,K20,O20,S20)=0,"",SUM(G20,K20,O20,S20)) | V20: =IF(COUNT(H20,L20,P20,T20)=0,"",SUM(H20,L20,P20,T20))
A21: =IF(Produits!$A$19="","",Produits!$A$19) | B21: =IF(Produits!$A$19="","",Produits!$B$19) | C21: =IF(Produits!$A$19="","",Produits!$C$19) | D21: =IF(Produits!$A$19="","",Produits!$D$19) | F21: =IF(OR(E21="",Produits!$E$19=""),"",MAX(0,CEILING(Produits!$E$19-E21,1))) | J21: =IF(OR(I21="",Produits!$E$19=""),"",MAX(0,CEILING(Produits!$E$19-I21,1))) | N21: =IF(OR(M21="",Produits!$E$19=""),"",MAX(0,CEILING(Produits!$E$19-M21,1))) | R21: =IF(OR(Q21="",Produits!$E$19=""),"",MAX(0,CEILING(Produits!$E$19-Q21,1))) | U21: =IF(COUNT(G21,K21,O21,S21)=0,"",SUM(G21,K21,O21,S21)) | V21: =IF(COUNT(H21,L21,P21,T21)=0,"",SUM(H21,L21,P21,T21))
A22: =IF(Produits!$A$20="","",Produits!$A$20) | B22: =IF(Produits!$A$20="","",Produits!$B$20) | C22: =IF(Produits!$A$20="","",Produits!$C$20) | D22: =IF(Produits!$A$20="","",Produits!$D$20) | F22: =IF(OR(E22="",Produits!$E$20=""),"",MAX(0,CEILING(Produits!$E$20-E22,1))) | J22: =IF(OR(I22="",Produits!$E$20=""),"",MAX(0,CEILING(Produits!$E$20-I22,1))) | N22: =IF(OR(M22="",Produits!$E$20=""),"",MAX(0,CEILING(Produits!$E$20-M22,1))) | R22: =IF(OR(Q22="",Produits!$E$20=""),"",MAX(0,CEILING(Produits!$E$20-Q22,1))) | U22: =IF(COUNT(G22,K22,O22,S22)=0,"",SUM(G22,K22,O22,S22)) | V22: =IF(COUNT(H22,L22,P22,T22)=0,"",SUM(H22,L22,P22,T22))
A23: =IF(Produits!$A$21="","",Produits!$A$21) | B23: =IF(Produits!$A$21="","",Produits!$B$21) | C23: =IF(Produits!$A$21="","",Produits!$C$21) | D23: =IF(Produits!$A$21="","",Produits!$D$21) | F23: =IF(OR(E23="",Produits!$E$21=""),"",MAX(0,CEILING(Produits!$E$21-E23,1))) | J23: =IF(OR(I23="",Produits!$E$21=""),"",MAX(0,CEILING(Produits!$E$21-I23,1))) | N23: =IF(OR(M23="",Produits!$E$21=""),"",MAX(0,CEILING(Produits!$E$21-M23,1))) | R23: =IF(OR(Q23="",Produits!$E$21=""),"",MAX(0,CEILING(Produits!$E$21-Q23,1))) | U23: =IF(COUNT(G23,K23,O23,S23)=0,"",SUM(G23,K23,O23,S23)) | V23: =IF(COUNT(H23,L23,P23,T23)=0,"",SUM(H23,L23,P23,T23))
A24: =IF(Produits!$A$22="","",Produits!$A$22) | B24: =IF(Produits!$A$22="","",Produits!$B$22) | C24: =IF(Produits!$A$22="","",Produits!$C$22) | D24: =IF(Produits!$A$22="","",Produits!$D$22) | F24: =IF(OR(E24="",Produits!$E$22=""),"",MAX(0,CEILING(Produits!$E$22-E24,1))) | J24: =IF(OR(I24="",Produits!$E$22=""),"",MAX(0,CEILING(Produits!$E$22-I24,1))) | N24: =IF(OR(M24="",Produits!$E$22=""),"",MAX(0,CEILING(Produits!$E$22-M24,1))) | R24: =IF(OR(Q24="",Produits!$E$22=""),"",MAX(0,CEILING(Produits!$E$22-Q24,1))) | U24: =IF(COUNT(G24,K24,O24,S24)=0,"",SUM(G24,K24,O24,S24)) | V24: =IF(COUNT(H24,L24,P24,T24)=0,"",SUM(H24,L24,P24,T24))
A25: =IF(Produits!$A$23="","",Produits!$A$23) | B25: =IF(Produits!$A$23="","",Produits!$B$23) | C25: =IF(Produits!$A$23="","",Produits!$C$23) | D25: =IF(Produits!$A$23="","",Produits!$D$23) | F25: =IF(OR(E25="",Produits!$E$23=""),"",MAX(0,CEILING(Produits!$E$23-E25,1))) | J25: =IF(OR(I25="",Produits!$E$23=""),"",MAX(0,CEILING(Produits!$E$23-I25,1))) | N25: =IF(OR(M25="",Produits!$E$23=""),"",MAX(0,CEILING(Produits!$E$23-M25,1))) | R25: =IF(OR(Q25="",Produits!$E$23=""),"",MAX(0,CEILING(Produits!$E$23-Q25,1))) | U25: =IF(COUNT(G25,K25,O25,S25)=0,"",SUM(G25,K25,O25,S25)) | V25: =IF(COUNT(H25,L25,P25,T25)=0,"",SUM(H25,L25,P25,T25))
A26: =IF(Produits!$A$24="","",Produits!$A$24) | B26: =IF(Produits!$A$24="","",Produits!$B$24) | C26: =IF(Produits!$A$24="","",Produits!$C$24) | D26: =IF(Produits!$A$24="","",Produits!$D$24) | F26: =IF(OR(E26="",Produits!$E$24=""),"",MAX(0,CEILING(Produits!$E$24-E26,1))) | J26: =IF(OR(I26="",Produits!$E$24=""),"",MAX(0,CEILING(Produits!$E$24-I26,1))) | N26: =IF(OR(M26="",Produits!$E$24=""),"",MAX(0,CEILING(Produits!$E$24-M26,1))) | R26: =IF(OR(Q26="",Produits!$E$24=""),"",MAX(0,CEILING(Produits!$E$24-Q26,1))) | U26: =IF(COUNT(G26,K26,O26,S26)=0,"",SUM(G26,K26,O26,S26)) | V26: =IF(COUNT(H26,L26,P26,T26)=0,"",SUM(H26,L26,P26,T26))
A27: =IF(Produits!$A$25="","",Produits!$A$25) | B27: =IF(Produits!$A$25="","",Produits!$B$25) | C27: =IF(Produits!$A$25="","",Produits!$C$25) | D27: =IF(Produits!$A$25="","",Produits!$D$25) | F27: =IF(OR(E27="",Produits!$E$25=""),"",MAX(0,CEILING(Produits!$E$25-E27,1))) | J27: =IF(OR(I27="",Produits!$E$25=""),"",MAX(0,CEILING(Produits!$E$25-I27,1))) | N27: =IF(OR(M27="",Produits!$E$25=""),"",MAX(0,CEILING(Produits!$E$25-M27,1))) | R27: =IF(OR(Q27="",Produits!$E$25=""),"",MAX(0,CEILING(Produits!$E$25-Q27,1))) | U27: =IF(COUNT(G27,K27,O27,S27)=0,"",SUM(G27,K27,O27,S27)) | V27: =IF(COUNT(H27,L27,P27,T27)=0,"",SUM(H27,L27,P27,T27))
A28: =IF(Produits!$A$26="","",Produits!$A$26) | B28: =IF(Produits!$A$26="","",Produits!$B$26) | C28: =IF(Produits!$A$26="","",Produits!$C$26) | D28: =IF(Produits!$A$26="","",Produits!$D$26) | F28: =IF(OR(E28="",Produits!$E$26=""),"",MAX(0,CEILING(Produits!$E$26-E28,1))) | J28: =IF(OR(I28="",Produits!$E$26=""),"",MAX(0,CEILING(Produits!$E$26-I28,1))) | N28: =IF(OR(M28="",Produits!$E$26=""),"",MAX(0,CEILING(Produits!$E$26-M28,1))) | R28: =IF(OR(Q28="",Produits!$E$26=""),"",MAX(0,CEILING(Produits!$E$26-Q28,1))) | U28: =IF(COUNT(G28,K28,O28,S28)=0,"",SUM(G28,K28,O28,S28)) | V28: =IF(COUNT(H28,L28,P28,T28)=0,"",SUM(H28,L28,P28,T28))
A29: =IF(Produits!$A$27="","",Produits!$A$27) | B29: =IF(Produits!$A$27="","",Produits!$B$27) | C29: =IF(Produits!$A$27="","",Produits!$C$27) | D29: =IF(Produits!$A$27="","",Produits!$D$27) | F29: =IF(OR(E29="",Produits!$E$27=""),"",MAX(0,CEILING(Produits!$E$27-E29,1))) | J29: =IF(OR(I29="",Produits!$E$27=""),"",MAX(0,CEILING(Produits!$E$27-I29,1))) | N29: =IF(OR(M29="",Produits!$E$27=""),"",MAX(0,CEILING(Produits!$E$27-M29,1))) | R29: =IF(OR(Q29="",Produits!$E$27=""),"",MAX(0,CEILING(Produits!$E$27-Q29,1))) | U29: =IF(COUNT(G29,K29,O29,S29)=0,"",SUM(G29,K29,O29,S29)) | V29: =IF(COUNT(H29,L29,P29,T29)=0,"",SUM(H29,L29,P29,T29))
A30: =IF(Produits!$A$28="","",Produits!$A$28) | B30: =IF(Produits!$A$28="","",Produits!$B$28) | C30: =IF(Produits!$A$28="","",Produits!$C$28) | D30: =IF(Produits!$A$28="","",Produits!$D$28) | F30: =IF(OR(E30="",Produits!$E$28=""),"",MAX(0,CEILING(Produits!$E$28-E30,1))) | J30: =IF(OR(I30="",Produits!$E$28=""),"",MAX(0,CEILING(Produits!$E$28-I30,1))) | N30: =IF(OR(M30="",Produits!$E$28=""),"",MAX(0,CEILING(Produits!$E$28-M30,1))) | R30: =IF(OR(Q30="",Produits!$E$28=""),"",MAX(0,CEILING(Produits!$E$28-Q30,1))) | U30: =IF(COUNT(G30,K30,O30,S30)=0,"",SUM(G30,K30,O30,S30)) | V30: =IF(COUNT(H30,L30,P30,T30)=0,"",SUM(H30,L30,P30,T30))
A31: =IF(Produits!$A$29="","",Produits!$A$29) | B31: =IF(Produits!$A$29="","",Produits!$B$29) | C31: =IF(Produits!$A$29="","",Produits!$C$29) | D31: =IF(Produits!$A$29="","",Produits!$D$29) | F31: =IF(OR(E31="",Produits!$E$29=""),"",MAX(0,CEILING(Produits!$E$29-E31,1))) | J31: =IF(OR(I31="",Produits!$E$29=""),"",MAX(0,CEILING(Produits!$E$29-I31,1))) | N31: =IF(OR(M31="",Produits!$E$29=""),"",MAX(0,CEILING(Produits!$E$29-M31,1))) | R31: =IF(OR(Q31="",Produits!$E$29=""),"",MAX(0,CEILING(Produits!$E$29-Q31,1))) | U31: =IF(COUNT(G31,K31,O31,S31)=0,"",SUM(G31,K31,O31,S31)) | V31: =IF(COUNT(H31,L31,P31,T31)=0,"",SUM(H31,L31,P31,T31))
A32: =IF(Produits!$A$30="","",Produits!$A$30) | B32: =IF(Produits!$A$30="","",Produits!$B$30) | C32: =IF(Produits!$A$30="","",Produits!$C$30) | D32: =IF(Produits!$A$30="","",Produits!$D$30) | F32: =IF(OR(E32="",Produits!$E$30=""),"",MAX(0,CEILING(Produits!$E$30-E32,1))) | J32: =IF(OR(I32="",Produits!$E$30=""),"",MAX(0,CEILING(Produits!$E$30-I32,1))) | N32: =IF(OR(M32="",Produits!$E$30=""),"",MAX(0,CEILING(Produits!$E$30-M32,1))) | R32: =IF(OR(Q32="",Produits!$E$30=""),"",MAX(0,CEILING(Produits!$E$30-Q32,1))) | U32: =IF(COUNT(G32,K32,O32,S32)=0,"",SUM(G32,K32,O32,S32)) | V32: =IF(COUNT(H32,L32,P32,T32)=0,"",SUM(H32,L32,P32,T32))
A33: =IF(Produits!$A$31="","",Produits!$A$31) | B33: =IF(Produits!$A$31="","",Produits!$B$31) | C33: =IF(Produits!$A$31="","",Produits!$C$31) | D33: =IF(Produits!$A$31="","",Produits!$D$31) | F33: =IF(OR(E33="",Produits!$E$31=""),"",MAX(0,CEILING(Produits!$E$31-E33,1))) | J33: =IF(OR(I33="",Produits!$E$31=""),"",MAX(0,CEILING(Produits!$E$31-I33,1))) | N33: =IF(OR(M33="",Produits!$E$31=""),"",MAX(0,CEILING(Produits!$E$31-M33,1))) | R33: =IF(OR(Q33="",Produits!$E$31=""),"",MAX(0,CEILING(Produits!$E$31-Q33,1))) | U33: =IF(COUNT(G33,K33,O33,S33)=0,"",SUM(G33,K33,O33,S33)) | V33: =IF(COUNT(H33,L33,P33,T33)=0,"",SUM(H33,L33,P33,T33))
A34: =IF(Produits!$A$32="","",Produits!$A$32) | B34: =IF(Produits!$A$32="","",Produits!$B$32) | C34: =IF(Produits!$A$32="","",Produits!$C$32) | D34: =IF(Produits!$A$32="","",Produits!$D$32) | F34: =IF(OR(E34="",Produits!$E$32=""),"",MAX(0,CEILING(Produits!$E$32-E34,1))) | J34: =IF(OR(I34="",Produits!$E$32=""),"",MAX(0,CEILING(Produits!$E$32-I34,1))) | N34: =IF(OR(M34="",Produits!$E$32=""),"",MAX(0,CEILING(Produits!$E$32-M34,1))) | R34: =IF(OR(Q34="",Produits!$E$32=""),"",MAX(0,CEILING(Produits!$E$32-Q34,1))) | U34: =IF(COUNT(G34,K34,O34,S34)=0,"",SUM(G34,K34,O34,S34)) | V34: =IF(COUNT(H34,L34,P34,T34)=0,"",SUM(H34,L34,P34,T34))
A35: =IF(Produits!$A$33="","",Produits!$A$33) | B35: =IF(Produits!$A$33="","",Produits!$B$33) | C35: =IF(Produits!$A$33="","",Produits!$C$33) | D35: =IF(Produits!$A$33="","",Produits!$D$33) | F35: =IF(OR(E35="",Produits!$E$33=""),"",MAX(0,CEILING(Produits!$E$33-E35,1))) | J35: =IF(OR(I35="",Produits!$E$33=""),"",MAX(0,CEILING(Produits!$E$33-I35,1))) | N35: =IF(OR(M35="",Produits!$E$33=""),"",MAX(0,CEILING(Produits!$E$33-M35,1))) | R35: =IF(OR(Q35="",Produits!$E$33=""),"",MAX(0,CEILING(Produits!$E$33-Q35,1))) | U35: =IF(COUNT(G35,K35,O35,S35)=0,"",SUM(G35,K35,O35,S35)) | V35: =IF(COUNT(H35,L35,P35,T35)=0,"",SUM(H35,L35,P35,T35))
A36: =IF(Produits!$A$34="","",Produits!$A$34) | B36: =IF(Produits!$A$34="","",Produits!$B$34) | C36: =IF(Produits!$A$34="","",Produits!$C$34) | D36: =IF(Produits!$A$34="","",Produits!$D$34) | F36: =IF(OR(E36="",Produits!$E$34=""),"",MAX(0,CEILING(Produits!$E$34-E36,1))) | J36: =IF(OR(I36="",Produits!$E$34=""),"",MAX(0,CEILING(Produits!$E$34-I36,1))) | N36: =IF(OR(M36="",Produits!$E$34=""),"",MAX(0,CEILING(Produits!$E$34-M36,1))) | R36: =IF(OR(Q36="",Produits!$E$34=""),"",MAX(0,CEILING(Produits!$E$34-Q36,1))) | U36: =IF(COUNT(G36,K36,O36,S36)=0,"",SUM(G36,K36,O36,S36)) | V36: =IF(COUNT(H36,L36,P36,T36)=0,"",SUM(H36,L36,P36,T36))
A37: =IF(Produits!$A$35="","",Produits!$A$35) | B37: =IF(Produits!$A$35="","",Produits!$B$35) | C37: =IF(Produits!$A$35="","",Produits!$C$35) | D37: =IF(Produits!$A$35="","",Produits!$D$35) | F37: =IF(OR(E37="",Produits!$E$35=""),"",MAX(0,CEILING(Produits!$E$35-E37,1))) | J37: =IF(OR(I37="",Produits!$E$35=""),"",MAX(0,CEILING(Produits!$E$35-I37,1))) | N37: =IF(OR(M37="",Produits!$E$35=""),"",MAX(0,CEILING(Produits!$E$35-M37,1))) | R37: =IF(OR(Q37="",Produits!$E$35=""),"",MAX(0,CEILING(Produits!$E$35-Q37,1))) | U37: =IF(COUNT(G37,K37,O37,S37)=0,"",SUM(G37,K37,O37,S37)) | V37: =IF(COUNT(H37,L37,P37,T37)=0,"",SUM(H37,L37,P37,T37))
A38: =IF(Produits!$A$36="","",Produits!$A$36) | B38: =IF(Produits!$A$36="","",Produits!$B$36) | C38: =IF(Produits!$A$36="","",Produits!$C$36) | D38: =IF(Produits!$A$36="","",Produits!$D$36) | F38: =IF(OR(E38="",Produits!$E$36=""),"",MAX(0,CEILING(Produits!$E$36-E38,1))) | J38: =IF(OR(I38="",Produits!$E$36=""),"",MAX(0,CEILING(Produits!$E$36-I38,1))) | N38: =IF(OR(M38="",Produits!$E$36=""),"",MAX(0,CEILING(Produits!$E$36-M38,1))) | R38: =IF(OR(Q38="",Produits!$E$36=""),"",MAX(0,CEILING(Produits!$E$36-Q38,1))) | U38: =IF(COUNT(G38,K38,O38,S38)=0,"",SUM(G38,K38,O38,S38)) | V38: =IF(COUNT(H38,L38,P38,T38)=0,"",SUM(H38,L38,P38,T38))
A39: =IF(Produits!$A$37="","",Produits!$A$37) | B39: =IF(Produits!$A$37="","",Produits!$B$37) | C39: =IF(Produits!$A$37="","",Produits!$C$37) | D39: =IF(Produits!$A$37="","",Produits!$D$37) | F39: =IF(OR(E39="",Produits!$E$37=""),"",MAX(0,CEILING(Produits!$E$37-E39,1))) | J39: =IF(OR(I39="",Produits!$E$37=""),"",MAX(0,CEILING(Produits!$E$37-I39,1))) | N39: =IF(OR(M39="",Produits!$E$37=""),"",MAX(0,CEILING(Produits!$E$37-M39,1))) | R39: =IF(OR(Q39="",Produits!$E$37=""),"",MAX(0,CEILING(Produits!$E$37-Q39,1))) | U39: =IF(COUNT(G39,K39,O39,S39)=0,"",SUM(G39,K39,O39,S39)) | V39: =IF(COUNT(H39,L39,P39,T39)=0,"",SUM(H39,L39,P39,T39))
A40: =IF(Produits!$A$38="","",Produits!$A$38) | B40: =IF(Produits!$A$38="","",Produits!$B$38) | C40: =IF(Produits!$A$38="","",Produits!$C$38) | D40: =IF(Produits!$A$38="","",Produits!$D$38) | F40: =IF(OR(E40="",Produits!$E$38=""),"",MAX(0,CEILING(Produits!$E$38-E40,1))) | J40: =IF(OR(I40="",Produits!$E$38=""),"",MAX(0,CEILING(Produits!$E$38-I40,1))) | N40: =IF(OR(M40="",Produits!$E$38=""),"",MAX(0,CEILING(Produits!$E$38-M40,1))) | R40: =IF(OR(Q40="",Produits!$E$38=""),"",MAX(0,CEILING(Produits!$E$38-Q40,1))) | U40: =IF(COUNT(G40,K40,O40,S40)=0,"",SUM(G40,K40,O40,S40)) | V40: =IF(COUNT(H40,L40,P40,T40)=0,"",SUM(H40,L40,P40,T40))
A41: =IF(Produits!$A$39="","",Produits!$A$39) | B41: =IF(Produits!$A$39="","",Produits!$B$39) | C41: =IF(Produits!$A$39="","",Produits!$C$39) | D41: =IF(Produits!$A$39="","",Produits!$D$39) | F41: =IF(OR(E41="",Produits!$E$39=""),"",MAX(0,CEILING(Produits!$E$39-E41,1))) | J41: =IF(OR(I41="",Produits!$E$39=""),"",MAX(0,CEILING(Produits!$E$39-I41,1))) | N41: =IF(OR(M41="",Produits!$E$39=""),"",MAX(0,CEILING(Produits!$E$39-M41,1))) | R41: =IF(OR(Q41="",Produits!$E$39=""),"",MAX(0,CEILING(Produits!$E$39-Q41,1))) | U41: =IF(COUNT(G41,K41,O41,S41)=0,"",SUM(G41,K41,O41,S41)) | V41: =IF(COUNT(H41,L41,P41,T41)=0,"",SUM(H41,L41,P41,T41))
A42: =IF(Produits!$A$40="","",Produits!$A$40) | B42: =IF(Produits!$A$40="","",Produits!$B$40) | C42: =IF(Produits!$A$40="","",Produits!$C$40) | D42: =IF(Produits!$A$40="","",Produits!$D$40) | F42: =IF(OR(E42="",Produits!$E$40=""),"",MAX(0,CEILING(Produits!$E$40-E42,1))) | J42: =IF(OR(I42="",Produits!$E$40=""),"",MAX(0,CEILING(Produits!$E$40-I42,1))) | N42: =IF(OR(M42="",Produits!$E$40=""),"",MAX(0,CEILING(Produits!$E$40-M42,1))) | R42: =IF(OR(Q42="",Produits!$E$40=""),"",MAX(0,CEILING(Produits!$E$40-Q42,1))) | U42: =IF(COUNT(G42,K42,O42,S42)=0,"",SUM(G42,K42,O42,S42)) | V42: =IF(COUNT(H42,L42,P42,T42)=0,"",SUM(H42,L42,P42,T42))
...
