Workbook

Sheet Mode d'emploi
A1: 8 · Suivi sur l'année
A2: Proposition de tableau de gestion des stocks — Excel et Google Sheets
A4: L'idée | B4: Un fichier pour toute l'année : un onglet par mois (déjà prêts), et un onglet Année qui montre, produit par produit, combien tu as reçu chaque mois, ta moyenne mensuelle et ton plus gros mois. C'est ce qui permet de voir combien tu rachètes en général de chaque produit.
A6: Comment faire | B6: 1. Remplis l'onglet Produits une seule fois.
B7: 2. Chaque semaine : dans l'onglet du mois en cours, Stock, Commandé, Reçu.
B8: 3. L'onglet Année se remplit tout seul au fil des mois.
B9: 4. Rien à dupliquer : les 12 mois sont déjà là.
A11: Les onglets | B11: Année 2026 — reçu par mois, moyenne, maximum.
B12: Produits — ta liste.
B13: Janvier à Décembre — un onglet par mois.
A15: Couleurs | B15: Cases jaunes = à remplir. Cases blanches = calculées toutes seules, ne pas y toucher.
B16: Chiffres en bleu = exemple pour montrer le fonctionnement, à effacer.
B17: Rouge = il manque quelque chose (livraison incomplète, stock trop bas).
A19: Google Sheets | B19: Fichier > Importer > Importer ce fichier. Tout fonctionne pareil, y compris sur téléphone.

Sheet Année 2026
A1: Année 2026 — quantités reçues par mois
A2: Calculé à partir des 12 onglets mensuels — rien à remplir
A4: Produit | B4: Unité | C4: Janv. | D4: Févr. | E4: Mars | F4: Avr. | G4: Mai | H4: Juin | I4: Juil. | J4: Août | K4: Sept. | L4: Oct. | M4: Nov. | N4: Déc. | O4: Total | P4: Moyenne / mois | Q4: Plus gros mois
A5: =IF(Produits!$A$5="","",Produits!$A$5) | B5: =IF(Produits!$A$5="","",Produits!$C$5) | C5: =IF(N('Janvier'!Q7)=0,"",N('Janvier'!Q7)) | D5: =IF(N('Février'!Q7)=0,"",N('Février'!Q7)) | E5: =IF(N('Mars'!Q7)=0,"",N('Mars'!Q7)) | F5: =IF(N('Avril'!Q7)=0,"",N('Avril'!Q7)) | G5: =IF(N('Mai'!Q7)=0,"",N('Mai'!Q7)) | H5: =IF(N('Juin'!Q7)=0,"",N('Juin'!Q7)) | I5: =IF(N('Juillet'!Q7)=0,"",N('Juillet'!Q7)) | J5: =IF(N('Août'!Q7)=0,"",N('Août'!Q7)) | K5: =IF(N('Septembre'!Q7)=0,"",N('Septembre'!Q7)) | L5: =IF(N('Octobre'!Q7)=0,"",N('Octobre'!Q7)) | M5: =IF(N('Novembre'!Q7)=0,"",N('Novembre'!Q7)) | N5: =IF(N('Décembre'!Q7)=0,"",N('Décembre'!Q7)) | O5: =IF(COUNT(C5:N5)=0,"",SUM(C5:N5)) | P5: =IF(COUNT(C5:N5)=0,"",ROUND(AVERAGE(C5:N5),1)) | Q5: =IF(COUNT(C5:N5)=0,"",MAX(C5:N5))
A6: =IF(Produits!$A$6="","",Produits!$A$6) | B6: =IF(Produits!$A$6="","",Produits!$C$6) | C6: =IF(N('Janvier'!Q8)=0,"",N('Janvier'!Q8)) | D6: =IF(N('Février'!Q8)=0,"",N('Février'!Q8)) | E6: =IF(N('Mars'!Q8)=0,"",N('Mars'!Q8)) | F6: =IF(N('Avril'!Q8)=0,"",N('Avril'!Q8)) | G6: =IF(N('Mai'!Q8)=0,"",N('Mai'!Q8)) | H6: =IF(N('Juin'!Q8)=0,"",N('Juin'!Q8)) | I6: =IF(N('Juillet'!Q8)=0,"",N('Juillet'!Q8)) | J6: =IF(N('Août'!Q8)=0,"",N('Août'!Q8)) | K6: =IF(N('Septembre'!Q8)=0,"",N('Septembre'!Q8)) | L6: =IF(N('Octobre'!Q8)=0,"",N('Octobre'!Q8)) | M6: =IF(N('Novembre'!Q8)=0,"",N('Novembre'!Q8)) | N6: =IF(N('Décembre'!Q8)=0,"",N('Décembre'!Q8)) | O6: =IF(COUNT(C6:N6)=0,"",SUM(C6:N6)) | P6: =IF(COUNT(C6:N6)=0,"",ROUND(AVERAGE(C6:N6),1)) | Q6: =IF(COUNT(C6:N6)=0,"",MAX(C6:N6))
A7: =IF(Produits!$A$7="","",Produits!$A$7) | B7: =IF(Produits!$A$7="","",Produits!$C$7) | C7: =IF(N('Janvier'!Q9)=0,"",N('Janvier'!Q9)) | D7: =IF(N('Février'!Q9)=0,"",N('Février'!Q9)) | E7: =IF(N('Mars'!Q9)=0,"",N('Mars'!Q9)) | F7: =IF(N('Avril'!Q9)=0,"",N('Avril'!Q9)) | G7: =IF(N('Mai'!Q9)=0,"",N('Mai'!Q9)) | H7: =IF(N('Juin'!Q9)=0,"",N('Juin'!Q9)) | I7: =IF(N('Juillet'!Q9)=0,"",N('Juillet'!Q9)) | J7: =IF(N('Août'!Q9)=0,"",N('Août'!Q9)) | K7: =IF(N('Septembre'!Q9)=0,"",N('Septembre'!Q9)) | L7: =IF(N('Octobre'!Q9)=0,"",N('Octobre'!Q9)) | M7: =IF(N('Novembre'!Q9)=0,"",N('Novembre'!Q9)) | N7: =IF(N('Décembre'!Q9)=0,"",N('Décembre'!Q9)) | O7: =IF(COUNT(C7:N7)=0,"",SUM(C7:N7)) | P7: =IF(COUNT(C7:N7)=0,"",ROUND(AVERAGE(C7:N7),1)) | Q7: =IF(COUNT(C7:N7)=0,"",MAX(C7:N7))
A8: =IF(Produits!$A$8="","",Produits!$A$8) | B8: =IF(Produits!$A$8="","",Produits!$C$8) | C8: =IF(N('Janvier'!Q10)=0,"",N('Janvier'!Q10)) | D8: =IF(N('Février'!Q10)=0,"",N('Février'!Q10)) | E8: =IF(N('Mars'!Q10)=0,"",N('Mars'!Q10)) | F8: =IF(N('Avril'!Q10)=0,"",N('Avril'!Q10)) | G8: =IF(N('Mai'!Q10)=0,"",N('Mai'!Q10)) | H8: =IF(N('Juin'!Q10)=0,"",N('Juin'!Q10)) | I8: =IF(N('Juillet'!Q10)=0,"",N('Juillet'!Q10)) | J8: =IF(N('Août'!Q10)=0,"",N('Août'!Q10)) | K8: =IF(N('Septembre'!Q10)=0,"",N('Septembre'!Q10)) | L8: =IF(N('Octobre'!Q10)=0,"",N('Octobre'!Q10)) | M8: =IF(N('Novembre'!Q10)=0,"",N('Novembre'!Q10)) | N8: =IF(N('Décembre'!Q10)=0,"",N('Décembre'!Q10)) | O8: =IF(COUNT(C8:N8)=0,"",SUM(C8:N8)) | P8: =IF(COUNT(C8:N8)=0,"",ROUND(AVERAGE(C8:N8),1)) | Q8: =IF(COUNT(C8:N8)=0,"",MAX(C8:N8))
A9: =IF(Produits!$A$9="","",Produits!$A$9) | B9: =IF(Produits!$A$9="","",Produits!$C$9) | C9: =IF(N('Janvier'!Q11)=0,"",N('Janvier'!Q11)) | D9: =IF(N('Février'!Q11)=0,"",N('Février'!Q11)) | E9: =IF(N('Mars'!Q11)=0,"",N('Mars'!Q11)) | F9: =IF(N('Avril'!Q11)=0,"",N('Avril'!Q11)) | G9: =IF(N('Mai'!Q11)=0,"",N('Mai'!Q11)) | H9: =IF(N('Juin'!Q11)=0,"",N('Juin'!Q11)) | I9: =IF(N('Juillet'!Q11)=0,"",N('Juillet'!Q11)) | J9: =IF(N('Août'!Q11)=0,"",N('Août'!Q11)) | K9: =IF(N('Septembre'!Q11)=0,"",N('Septembre'!Q11)) | L9: =IF(N('Octobre'!Q11)=0,"",N('Octobre'!Q11)) | M9: =IF(N('Novembre'!Q11)=0,"",N('Novembre'!Q11)) | N9: =IF(N('Décembre'!Q11)=0,"",N('Décembre'!Q11)) | O9: =IF(COUNT(C9:N9)=0,"",SUM(C9:N9)) | P9: =IF(COUNT(C9:N9)=0,"",ROUND(AVERAGE(C9:N9),1)) | Q9: =IF(COUNT(C9:N9)=0,"",MAX(C9:N9))
A10: =IF(Produits!$A$10="","",Produits!$A$10) | B10: =IF(Produits!$A$10="","",Produits!$C$10) | C10: =IF(N('Janvier'!Q12)=0,"",N('Janvier'!Q12)) | D10: =IF(N('Février'!Q12)=0,"",N('Février'!Q12)) | E10: =IF(N('Mars'!Q12)=0,"",N('Mars'!Q12)) | F10: =IF(N('Avril'!Q12)=0,"",N('Avril'!Q12)) | G10: =IF(N('Mai'!Q12)=0,"",N('Mai'!Q12)) | H10: =IF(N('Juin'!Q12)=0,"",N('Juin'!Q12)) | I10: =IF(N('Juillet'!Q12)=0,"",N('Juillet'!Q12)) | J10: =IF(N('Août'!Q12)=0,"",N('Août'!Q12)) | K10: =IF(N('Septembre'!Q12)=0,"",N('Septembre'!Q12)) | L10: =IF(N('Octobre'!Q12)=0,"",N('Octobre'!Q12)) | M10: =IF(N('Novembre'!Q12)=0,"",N('Novembre'!Q12)) | N10: =IF(N('Décembre'!Q12)=0,"",N('Décembre'!Q12)) | O10: =IF(COUNT(C10:N10)=0,"",SUM(C10:N10)) | P10: =IF(COUNT(C10:N10)=0,"",ROUND(AVERAGE(C10:N10),1)) | Q10: =IF(COUNT(C10:N10)=0,"",MAX(C10:N10))
A11: =IF(Produits!$A$11="","",Produits!$A$11) | B11: =IF(Produits!$A$11="","",Produits!$C$11) | C11: =IF(N('Janvier'!Q13)=0,"",N('Janvier'!Q13)) | D11: =IF(N('Février'!Q13)=0,"",N('Février'!Q13)) | E11: =IF(N('Mars'!Q13)=0,"",N('Mars'!Q13)) | F11: =IF(N('Avril'!Q13)=0,"",N('Avril'!Q13)) | G11: =IF(N('Mai'!Q13)=0,"",N('Mai'!Q13)) | H11: =IF(N('Juin'!Q13)=0,"",N('Juin'!Q13)) | I11: =IF(N('Juillet'!Q13)=0,"",N('Juillet'!Q13)) | J11: =IF(N('Août'!Q13)=0,"",N('Août'!Q13)) | K11: =IF(N('Septembre'!Q13)=0,"",N('Septembre'!Q13)) | L11: =IF(N('Octobre'!Q13)=0,"",N('Octobre'!Q13)) | M11: =IF(N('Novembre'!Q13)=0,"",N('Novembre'!Q13)) | N11: =IF(N('Décembre'!Q13)=0,"",N('Décembre'!Q13)) | O11: =IF(COUNT(C11:N11)=0,"",SUM(C11:N11)) | P11: =IF(COUNT(C11:N11)=0,"",ROUND(AVERAGE(C11:N11),1)) | Q11: =IF(COUNT(C11:N11)=0,"",MAX(C11:N11))
A12: =IF(Produits!$A$12="","",Produits!$A$12) | B12: =IF(Produits!$A$12="","",Produits!$C$12) | C12: =IF(N('Janvier'!Q14)=0,"",N('Janvier'!Q14)) | D12: =IF(N('Février'!Q14)=0,"",N('Février'!Q14)) | E12: =IF(N('Mars'!Q14)=0,"",N('Mars'!Q14)) | F12: =IF(N('Avril'!Q14)=0,"",N('Avril'!Q14)) | G12: =IF(N('Mai'!Q14)=0,"",N('Mai'!Q14)) | H12: =IF(N('Juin'!Q14)=0,"",N('Juin'!Q14)) | I12: =IF(N('Juillet'!Q14)=0,"",N('Juillet'!Q14)) | J12: =IF(N('Août'!Q14)=0,"",N('Août'!Q14)) | K12: =IF(N('Septembre'!Q14)=0,"",N('Septembre'!Q14)) | L12: =IF(N('Octobre'!Q14)=0,"",N('Octobre'!Q14)) | M12: =IF(N('Novembre'!Q14)=0,"",N('Novembre'!Q14)) | N12: =IF(N('Décembre'!Q14)=0,"",N('Décembre'!Q14)) | O12: =IF(COUNT(C12:N12)=0,"",SUM(C12:N12)) | P12: =IF(COUNT(C12:N12)=0,"",ROUND(AVERAGE(C12:N12),1)) | Q12: =IF(COUNT(C12:N12)=0,"",MAX(C12:N12))
A13: =IF(Produits!$A$13="","",Produits!$A$13) | B13: =IF(Produits!$A$13="","",Produits!$C$13) | C13: =IF(N('Janvier'!Q15)=0,"",N('Janvier'!Q15)) | D13: =IF(N('Février'!Q15)=0,"",N('Février'!Q15)) | E13: =IF(N('Mars'!Q15)=0,"",N('Mars'!Q15)) | F13: =IF(N('Avril'!Q15)=0,"",N('Avril'!Q15)) | G13: =IF(N('Mai'!Q15)=0,"",N('Mai'!Q15)) | H13: =IF(N('Juin'!Q15)=0,"",N('Juin'!Q15)) | I13: =IF(N('Juillet'!Q15)=0,"",N('Juillet'!Q15)) | J13: =IF(N('Août'!Q15)=0,"",N('Août'!Q15)) | K13: =IF(N('Septembre'!Q15)=0,"",N('Septembre'!Q15)) | L13: =IF(N('Octobre'!Q15)=0,"",N('Octobre'!Q15)) | M13: =IF(N('Novembre'!Q15)=0,"",N('Novembre'!Q15)) | N13: =IF(N('Décembre'!Q15)=0,"",N('Décembre'!Q15)) | O13: =IF(COUNT(C13:N13)=0,"",SUM(C13:N13)) | P13: =IF(COUNT(C13:N13)=0,"",ROUND(AVERAGE(C13:N13),1)) | Q13: =IF(COUNT(C13:N13)=0,"",MAX(C13:N13))
A14: =IF(Produits!$A$14="","",Produits!$A$14) | B14: =IF(Produits!$A$14="","",Produits!$C$14) | C14: =IF(N('Janvier'!Q16)=0,"",N('Janvier'!Q16)) | D14: =IF(N('Février'!Q16)=0,"",N('Février'!Q16)) | E14: =IF(N('Mars'!Q16)=0,"",N('Mars'!Q16)) | F14: =IF(N('Avril'!Q16)=0,"",N('Avril'!Q16)) | G14: =IF(N('Mai'!Q16)=0,"",N('Mai'!Q16)) | H14: =IF(N('Juin'!Q16)=0,"",N('Juin'!Q16)) | I14: =IF(N('Juillet'!Q16)=0,"",N('Juillet'!Q16)) | J14: =IF(N('Août'!Q16)=0,"",N('Août'!Q16)) | K14: =IF(N('Septembre'!Q16)=0,"",N('Septembre'!Q16)) | L14: =IF(N('Octobre'!Q16)=0,"",N('Octobre'!Q16)) | M14: =IF(N('Novembre'!Q16)=0,"",N('Novembre'!Q16)) | N14: =IF(N('Décembre'!Q16)=0,"",N('Décembre'!Q16)) | O14: =IF(COUNT(C14:N14)=0,"",SUM(C14:N14)) | P14: =IF(COUNT(C14:N14)=0,"",ROUND(AVERAGE(C14:N14),1)) | Q14: =IF(COUNT(C14:N14)=0,"",MAX(C14:N14))
A15: =IF(Produits!$A$15="","",Produits!$A$15) | B15: =IF(Produits!$A$15="","",Produits!$C$15) | C15: =IF(N('Janvier'!Q17)=0,"",N('Janvier'!Q17)) | D15: =IF(N('Février'!Q17)=0,"",N('Février'!Q17)) | E15: =IF(N('Mars'!Q17)=0,"",N('Mars'!Q17)) | F15: =IF(N('Avril'!Q17)=0,"",N('Avril'!Q17)) | G15: =IF(N('Mai'!Q17)=0,"",N('Mai'!Q17)) | H15: =IF(N('Juin'!Q17)=0,"",N('Juin'!Q17)) | I15: =IF(N('Juillet'!Q17)=0,"",N('Juillet'!Q17)) | J15: =IF(N('Août'!Q17)=0,"",N('Août'!Q17)) | K15: =IF(N('Septembre'!Q17)=0,"",N('Septembre'!Q17)) | L15: =IF(N('Octobre'!Q17)=0,"",N('Octobre'!Q17)) | M15: =IF(N('Novembre'!Q17)=0,"",N('Novembre'!Q17)) | N15: =IF(N('Décembre'!Q17)=0,"",N('Décembre'!Q17)) | O15: =IF(COUNT(C15:N15)=0,"",SUM(C15:N15)) | P15: =IF(COUNT(C15:N15)=0,"",ROUND(AVERAGE(C15:N15),1)) | Q15: =IF(COUNT(C15:N15)=0,"",MAX(C15:N15))
A16: =IF(Produits!$A$16="","",Produits!$A$16) | B16: =IF(Produits!$A$16="","",Produits!$C$16) | C16: =IF(N('Janvier'!Q18)=0,"",N('Janvier'!Q18)) | D16: =IF(N('Février'!Q18)=0,"",N('Février'!Q18)) | E16: =IF(N('Mars'!Q18)=0,"",N('Mars'!Q18)) | F16: =IF(N('Avril'!Q18)=0,"",N('Avril'!Q18)) | G16: =IF(N('Mai'!Q18)=0,"",N('Mai'!Q18)) | H16: =IF(N('Juin'!Q18)=0,"",N('Juin'!Q18)) | I16: =IF(N('Juillet'!Q18)=0,"",N('Juillet'!Q18)) | J16: =IF(N('Août'!Q18)=0,"",N('Août'!Q18)) | K16: =IF(N('Septembre'!Q18)=0,"",N('Septembre'!Q18)) | L16: =IF(N('Octobre'!Q18)=0,"",N('Octobre'!Q18)) | M16: =IF(N('Novembre'!Q18)=0,"",N('Novembre'!Q18)) | N16: =IF(N('Décembre'!Q18)=0,"",N('Décembre'!Q18)) | O16: =IF(COUNT(C16:N16)=0,"",SUM(C16:N16)) | P16: =IF(COUNT(C16:N16)=0,"",ROUND(AVERAGE(C16:N16),1)) | Q16: =IF(COUNT(C16:N16)=0,"",MAX(C16:N16))
A17: =IF(Produits!$A$17="","",Produits!$A$17) | B17: =IF(Produits!$A$17="","",Produits!$C$17) | C17: =IF(N('Janvier'!Q19)=0,"",N('Janvier'!Q19)) | D17: =IF(N('Février'!Q19)=0,"",N('Février'!Q19)) | E17: =IF(N('Mars'!Q19)=0,"",N('Mars'!Q19)) | F17: =IF(N('Avril'!Q19)=0,"",N('Avril'!Q19)) | G17: =IF(N('Mai'!Q19)=0,"",N('Mai'!Q19)) | H17: =IF(N('Juin'!Q19)=0,"",N('Juin'!Q19)) | I17: =IF(N('Juillet'!Q19)=0,"",N('Juillet'!Q19)) | J17: =IF(N('Août'!Q19)=0,"",N('Août'!Q19)) | K17: =IF(N('Septembre'!Q19)=0,"",N('Septembre'!Q19)) | L17: =IF(N('Octobre'!Q19)=0,"",N('Octobre'!Q19)) | M17: =IF(N('Novembre'!Q19)=0,"",N('Novembre'!Q19)) | N17: =IF(N('Décembre'!Q19)=0,"",N('Décembre'!Q19)) | O17: =IF(COUNT(C17:N17)=0,"",SUM(C17:N17)) | P17: =IF(COUNT(C17:N17)=0,"",ROUND(AVERAGE(C17:N17),1)) | Q17: =IF(COUNT(C17:N17)=0,"",MAX(C17:N17))
A18: =IF(Produits!$A$18="","",Produits!$A$18) | B18: =IF(Produits!$A$18="","",Produits!$C$18) | C18: =IF(N('Janvier'!Q20)=0,"",N('Janvier'!Q20)) | D18: =IF(N('Février'!Q20)=0,"",N('Février'!Q20)) | E18: =IF(N('Mars'!Q20)=0,"",N('Mars'!Q20)) | F18: =IF(N('Avril'!Q20)=0,"",N('Avril'!Q20)) | G18: =IF(N('Mai'!Q20)=0,"",N('Mai'!Q20)) | H18: =IF(N('Juin'!Q20)=0,"",N('Juin'!Q20)) | I18: =IF(N('Juillet'!Q20)=0,"",N('Juillet'!Q20)) | J18: =IF(N('Août'!Q20)=0,"",N('Août'!Q20)) | K18: =IF(N('Septembre'!Q20)=0,"",N('Septembre'!Q20)) | L18: =IF(N('Octobre'!Q20)=0,"",N('Octobre'!Q20)) | M18: =IF(N('Novembre'!Q20)=0,"",N('Novembre'!Q20)) | N18: =IF(N('Décembre'!Q20)=0,"",N('Décembre'!Q20)) | O18: =IF(COUNT(C18:N18)=0,"",SUM(C18:N18)) | P18: =IF(COUNT(C18:N18)=0,"",ROUND(AVERAGE(C18:N18),1)) | Q18: =IF(COUNT(C18:N18)=0,"",MAX(C18:N18))
A19: =IF(Produits!$A$19="","",Produits!$A$19) | B19: =IF(Produits!$A$19="","",Produits!$C$19) | C19: =IF(N('Janvier'!Q21)=0,"",N('Janvier'!Q21)) | D19: =IF(N('Février'!Q21)=0,"",N('Février'!Q21)) | E19: =IF(N('Mars'!Q21)=0,"",N('Mars'!Q21)) | F19: =IF(N('Avril'!Q21)=0,"",N('Avril'!Q21)) | G19: =IF(N('Mai'!Q21)=0,"",N('Mai'!Q21)) | H19: =IF(N('Juin'!Q21)=0,"",N('Juin'!Q21)) | I19: =IF(N('Juillet'!Q21)=0,"",N('Juillet'!Q21)) | J19: =IF(N('Août'!Q21)=0,"",N('Août'!Q21)) | K19: =IF(N('Septembre'!Q21)=0,"",N('Septembre'!Q21)) | L19: =IF(N('Octobre'!Q21)=0,"",N('Octobre'!Q21)) | M19: =IF(N('Novembre'!Q21)=0,"",N('Novembre'!Q21)) | N19: =IF(N('Décembre'!Q21)=0,"",N('Décembre'!Q21)) | O19: =IF(COUNT(C19:N19)=0,"",SUM(C19:N19)) | P19: =IF(COUNT(C19:N19)=0,"",ROUND(AVERAGE(C19:N19),1)) | Q19: =IF(COUNT(C19:N19)=0,"",MAX(C19:N19))
A20: =IF(Produits!$A$20="","",Produits!$A$20) | B20: =IF(Produits!$A$20="","",Produits!$C$20) | C20: =IF(N('Janvier'!Q22)=0,"",N('Janvier'!Q22)) | D20: =IF(N('Février'!Q22)=0,"",N('Février'!Q22)) | E20: =IF(N('Mars'!Q22)=0,"",N('Mars'!Q22)) | F20: =IF(N('Avril'!Q22)=0,"",N('Avril'!Q22)) | G20: =IF(N('Mai'!Q22)=0,"",N('Mai'!Q22)) | H20: =IF(N('Juin'!Q22)=0,"",N('Juin'!Q22)) | I20: =IF(N('Juillet'!Q22)=0,"",N('Juillet'!Q22)) | J20: =IF(N('Août'!Q22)=0,"",N('Août'!Q22)) | K20: =IF(N('Septembre'!Q22)=0,"",N('Septembre'!Q22)) | L20: =IF(N('Octobre'!Q22)=0,"",N('Octobre'!Q22)) | M20: =IF(N('Novembre'!Q22)=0,"",N('Novembre'!Q22)) | N20: =IF(N('Décembre'!Q22)=0,"",N('Décembre'!Q22)) | O20: =IF(COUNT(C20:N20)=0,"",SUM(C20:N20)) | P20: =IF(COUNT(C20:N20)=0,"",ROUND(AVERAGE(C20:N20),1)) | Q20: =IF(COUNT(C20:N20)=0,"",MAX(C20:N20))
A21: =IF(Produits!$A$21="","",Produits!$A$21) | B21: =IF(Produits!$A$21="","",Produits!$C$21) | C21: =IF(N('Janvier'!Q23)=0,"",N('Janvier'!Q23)) | D21: =IF(N('Février'!Q23)=0,"",N('Février'!Q23)) | E21: =IF(N('Mars'!Q23)=0,"",N('Mars'!Q23)) | F21: =IF(N('Avril'!Q23)=0,"",N('Avril'!Q23)) | G21: =IF(N('Mai'!Q23)=0,"",N('Mai'!Q23)) | H21: =IF(N('Juin'!Q23)=0,"",N('Juin'!Q23)) | I21: =IF(N('Juillet'!Q23)=0,"",N('Juillet'!Q23)) | J21: =IF(N('Août'!Q23)=0,"",N('Août'!Q23)) | K21: =IF(N('Septembre'!Q23)=0,"",N('Septembre'!Q23)) | L21: =IF(N('Octobre'!Q23)=0,"",N('Octobre'!Q23)) | M21: =IF(N('Novembre'!Q23)=0,"",N('Novembre'!Q23)) | N21: =IF(N('Décembre'!Q23)=0,"",N('Décembre'!Q23)) | O21: =IF(COUNT(C21:N21)=0,"",SUM(C21:N21)) | P21: =IF(COUNT(C21:N21)=0,"",ROUND(AVERAGE(C21:N21),1)) | Q21: =IF(COUNT(C21:N21)=0,"",MAX(C21:N21))
A22: =IF(Produits!$A$22="","",Produits!$A$22) | B22: =IF(Produits!$A$22="","",Produits!$C$22) | C22: =IF(N('Janvier'!Q24)=0,"",N('Janvier'!Q24)) | D22: =IF(N('Février'!Q24)=0,"",N('Février'!Q24)) | E22: =IF(N('Mars'!Q24)=0,"",N('Mars'!Q24)) | F22: =IF(N('Avril'!Q24)=0,"",N('Avril'!Q24)) | G22: =IF(N('Mai'!Q24)=0,"",N('Mai'!Q24)) | H22: =IF(N('Juin'!Q24)=0,"",N('Juin'!Q24)) | I22: =IF(N('Juillet'!Q24)=0,"",N('Juillet'!Q24)) | J22: =IF(N('Août'!Q24)=0,"",N('Août'!Q24)) | K22: =IF(N('Septembre'!Q24)=0,"",N('Septembre'!Q24)) | L22: =IF(N('Octobre'!Q24)=0,"",N('Octobre'!Q24)) | M22: =IF(N('Novembre'!Q24)=0,"",N('Novembre'!Q24)) | N22: =IF(N('Décembre'!Q24)=0,"",N('Décembre'!Q24)) | O22: =IF(COUNT(C22:N22)=0,"",SUM(C22:N22)) | P22: =IF(COUNT(C22:N22)=0,"",ROUND(AVERAGE(C22:N22),1)) | Q22: =IF(COUNT(C22:N22)=0,"",MAX(C22:N22))
A23: =IF(Produits!$A$23="","",Produits!$A$23) | B23: =IF(Produits!$A$23="","",Produits!$C$23) | C23: =IF(N('Janvier'!Q25)=0,"",N('Janvier'!Q25)) | D23: =IF(N('Février'!Q25)=0,"",N('Février'!Q25)) | E23: =IF(N('Mars'!Q25)=0,"",N('Mars'!Q25)) | F23: =IF(N('Avril'!Q25)=0,"",N('Avril'!Q25)) | G23: =IF(N('Mai'!Q25)=0,"",N('Mai'!Q25)) | H23: =IF(N('Juin'!Q25)=0,"",N('Juin'!Q25)) | I23: =IF(N('Juillet'!Q25)=0,"",N('Juillet'!Q25)) | J23: =IF(N('Août'!Q25)=0,"",N('Août'!Q25)) | K23: =IF(N('Septembre'!Q25)=0,"",N('Septembre'!Q25)) | L23: =IF(N('Octobre'!Q25)=0,"",N('Octobre'!Q25)) | M23: =IF(N('Novembre'!Q25)=0,"",N('Novembre'!Q25)) | N23: =IF(N('Décembre'!Q25)=0,"",N('Décembre'!Q25)) | O23: =IF(COUNT(C23:N23)=0,"",SUM(C23:N23)) | P23: =IF(COUNT(C23:N23)=0,"",ROUND(AVERAGE(C23:N23),1)) | Q23: =IF(COUNT(C23:N23)=0,"",MAX(C23:N23))
A24: =IF(Produits!$A$24="","",Produits!$A$24) | B24: =IF(Produits!$A$24="","",Produits!$C$24) | C24: =IF(N('Janvier'!Q26)=0,"",N('Janvier'!Q26)) | D24: =IF(N('Février'!Q26)=0,"",N('Février'!Q26)) | E24: =IF(N('Mars'!Q26)=0,"",N('Mars'!Q26)) | F24: =IF(N('Avril'!Q26)=0,"",N('Avril'!Q26)) | G24: =IF(N('Mai'!Q26)=0,"",N('Mai'!Q26)) | H24: =IF(N('Juin'!Q26)=0,"",N('Juin'!Q26)) | I24: =IF(N('Juillet'!Q26)=0,"",N('Juillet'!Q26)) | J24: =IF(N('Août'!Q26)=0,"",N('Août'!Q26)) | K24: =IF(N('Septembre'!Q26)=0,"",N('Septembre'!Q26)) | L24: =IF(N('Octobre'!Q26)=0,"",N('Octobre'!Q26)) | M24: =IF(N('Novembre'!Q26)=0,"",N('Novembre'!Q26)) | N24: =IF(N('Décembre'!Q26)=0,"",N('Décembre'!Q26)) | O24: =IF(COUNT(C24:N24)=0,"",SUM(C24:N24)) | P24: =IF(COUNT(C24:N24)=0,"",ROUND(AVERAGE(C24:N24),1)) | Q24: =IF(COUNT(C24:N24)=0,"",MAX(C24:N24))
A25: =IF(Produits!$A$25="","",Produits!$A$25) | B25: =IF(Produits!$A$25="","",Produits!$C$25) | C25: =IF(N('Janvier'!Q27)=0,"",N('Janvier'!Q27)) | D25: =IF(N('Février'!Q27)=0,"",N('Février'!Q27)) | E25: =IF(N('Mars'!Q27)=0,"",N('Mars'!Q27)) | F25: =IF(N('Avril'!Q27)=0,"",N('Avril'!Q27)) | G25: =IF(N('Mai'!Q27)=0,"",N('Mai'!Q27)) | H25: =IF(N('Juin'!Q27)=0,"",N('Juin'!Q27)) | I25: =IF(N('Juillet'!Q27)=0,"",N('Juillet'!Q27)) | J25: =IF(N('Août'!Q27)=0,"",N('Août'!Q27)) | K25: =IF(N('Septembre'!Q27)=0,"",N('Septembre'!Q27)) | L25: =IF(N('Octobre'!Q27)=0,"",N('Octobre'!Q27)) | M25: =IF(N('Novembre'!Q27)=0,"",N('Novembre'!Q27)) | N25: =IF(N('Décembre'!Q27)=0,"",N('Décembre'!Q27)) | O25: =IF(COUNT(C25:N25)=0,"",SUM(C25:N25)) | P25: =IF(COUNT(C25:N25)=0,"",ROUND(AVERAGE(C25:N25),1)) | Q25: =IF(COUNT(C25:N25)=0,"",MAX(C25:N25))
A26: =IF(Produits!$A$26="","",Produits!$A$26) | B26: =IF(Produits!$A$26="","",Produits!$C$26) | C26: =IF(N('Janvier'!Q28)=0,"",N('Janvier'!Q28)) | D26: =IF(N('Février'!Q28)=0,"",N('Février'!Q28)) | E26: =IF(N('Mars'!Q28)=0,"",N('Mars'!Q28)) | F26: =IF(N('Avril'!Q28)=0,"",N('Avril'!Q28)) | G26: =IF(N('Mai'!Q28)=0,"",N('Mai'!Q28)) | H26: =IF(N('Juin'!Q28)=0,"",N('Juin'!Q28)) | I26: =IF(N('Juillet'!Q28)=0,"",N('Juillet'!Q28)) | J26: =IF(N('Août'!Q28)=0,"",N('Août'!Q28)) | K26: =IF(N('Septembre'!Q28)=0,"",N('Septembre'!Q28)) | L26: =IF(N('Octobre'!Q28)=0,"",N('Octobre'!Q28)) | M26: =IF(N('Novembre'!Q28)=0,"",N('Novembre'!Q28)) | N26: =IF(N('Décembre'!Q28)=0,"",N('Décembre'!Q28)) | O26: =IF(COUNT(C26:N26)=0,"",SUM(C26:N26)) | P26: =IF(COUNT(C26:N26)=0,"",ROUND(AVERAGE(C26:N26),1)) | Q26: =IF(COUNT(C26:N26)=0,"",MAX(C26:N26))
A27: =IF(Produits!$A$27="","",Produits!$A$27) | B27: =IF(Produits!$A$27="","",Produits!$C$27) | C27: =IF(N('Janvier'!Q29)=0,"",N('Janvier'!Q29)) | D27: =IF(N('Février'!Q29)=0,"",N('Février'!Q29)) | E27: =IF(N('Mars'!Q29)=0,"",N('Mars'!Q29)) | F27: =IF(N('Avril'!Q29)=0,"",N('Avril'!Q29)) | G27: =IF(N('Mai'!Q29)=0,"",N('Mai'!Q29)) | H27: =IF(N('Juin'!Q29)=0,"",N('Juin'!Q29)) | I27: =IF(N('Juillet'!Q29)=0,"",N('Juillet'!Q29)) | J27: =IF(N('Août'!Q29)=0,"",N('Août'!Q29)) | K27: =IF(N('Septembre'!Q29)=0,"",N('Septembre'!Q29)) | L27: =IF(N('Octobre'!Q29)=0,"",N('Octobre'!Q29)) | M27: =IF(N('Novembre'!Q29)=0,"",N('Novembre'!Q29)) | N27: =IF(N('Décembre'!Q29)=0,"",N('Décembre'!Q29)) | O27: =IF(COUNT(C27:N27)=0,"",SUM(C27:N27)) | P27: =IF(COUNT(C27:N27)=0,"",ROUND(AVERAGE(C27:N27),1)) | Q27: =IF(COUNT(C27:N27)=0,"",MAX(C27:N27))
A28: =IF(Produits!$A$28="","",Produits!$A$28) | B28: =IF(Produits!$A$28="","",Produits!$C$28) | C28: =IF(N('Janvier'!Q30)=0,"",N('Janvier'!Q30)) | D28: =IF(N('Février'!Q30)=0,"",N('Février'!Q30)) | E28: =IF(N('Mars'!Q30)=0,"",N('Mars'!Q30)) | F28: =IF(N('Avril'!Q30)=0,"",N('Avril'!Q30)) | G28: =IF(N('Mai'!Q30)=0,"",N('Mai'!Q30)) | H28: =IF(N('Juin'!Q30)=0,"",N('Juin'!Q30)) | I28: =IF(N('Juillet'!Q30)=0,"",N('Juillet'!Q30)) | J28: =IF(N('Août'!Q30)=0,"",N('Août'!Q30)) | K28: =IF(N('Septembre'!Q30)=0,"",N('Septembre'!Q30)) | L28: =IF(N('Octobre'!Q30)=0,"",N('Octobre'!Q30)) | M28: =IF(N('Novembre'!Q30)=0,"",N('Novembre'!Q30)) | N28: =IF(N('Décembre'!Q30)=0,"",N('Décembre'!Q30)) | O28: =IF(COUNT(C28:N28)=0,"",SUM(C28:N28)) | P28: =IF(COUNT(C28:N28)=0,"",ROUND(AVERAGE(C28:N28),1)) | Q28: =IF(COUNT(C28:N28)=0,"",MAX(C28:N28))
A29: =IF(Produits!$A$29="","",Produits!$A$29) | B29: =IF(Produits!$A$29="","",Produits!$C$29) | C29: =IF(N('Janvier'!Q31)=0,"",N('Janvier'!Q31)) | D29: =IF(N('Février'!Q31)=0,"",N('Février'!Q31)) | E29: =IF(N('Mars'!Q31)=0,"",N('Mars'!Q31)) | F29: =IF(N('Avril'!Q31)=0,"",N('Avril'!Q31)) | G29: =IF(N('Mai'!Q31)=0,"",N('Mai'!Q31)) | H29: =IF(N('Juin'!Q31)=0,"",N('Juin'!Q31)) | I29: =IF(N('Juillet'!Q31)=0,"",N('Juillet'!Q31)) | J29: =IF(N('Août'!Q31)=0,"",N('Août'!Q31)) | K29: =IF(N('Septembre'!Q31)=0,"",N('Septembre'!Q31)) | L29: =IF(N('Octobre'!Q31)=0,"",N('Octobre'!Q31)) | M29: =IF(N('Novembre'!Q31)=0,"",N('Novembre'!Q31)) | N29: =IF(N('Décembre'!Q31)=0,"",N('Décembre'!Q31)) | O29: =IF(COUNT(C29:N29)=0,"",SUM(C29:N29)) | P29: =IF(COUNT(C29:N29)=0,"",ROUND(AVERAGE(C29:N29),1)) | Q29: =IF(COUNT(C29:N29)=0,"",MAX(C29:N29))
A30: =IF(Produits!$A$30="","",Produits!$A$30) | B30: =IF(Produits!$A$30="","",Produits!$C$30) | C30: =IF(N('Janvier'!Q32)=0,"",N('Janvier'!Q32)) | D30: =IF(N('Février'!Q32)=0,"",N('Février'!Q32)) | E30: =IF(N('Mars'!Q32)=0,"",N('Mars'!Q32)) | F30: =IF(N('Avril'!Q32)=0,"",N('Avril'!Q32)) | G30: =IF(N('Mai'!Q32)=0,"",N('Mai'!Q32)) | H30: =IF(N('Juin'!Q32)=0,"",N('Juin'!Q32)) | I30: =IF(N('Juillet'!Q32)=0,"",N('Juillet'!Q32)) | J30: =IF(N('Août'!Q32)=0,"",N('Août'!Q32)) | K30: =IF(N('Septembre'!Q32)=0,"",N('Septembre'!Q32)) | L30: =IF(N('Octobre'!Q32)=0,"",N('Octobre'!Q32)) | M30: =IF(N('Novembre'!Q32)=0,"",N('Novembre'!Q32)) | N30: =IF(N('Décembre'!Q32)=0,"",N('Décembre'!Q32)) | O30: =IF(COUNT(C30:N30)=0,"",SUM(C30:N30)) | P30: =IF(COUNT(C30:N30)=0,"",ROUND(AVERAGE(C30:N30),1)) | Q30: =IF(COUNT(C30:N30)=0,"",MAX(C30:N30))
A31: =IF(Produits!$A$31="","",Produits!$A$31) | B31: =IF(Produits!$A$31="","",Produits!$C$31) | C31: =IF(N('Janvier'!Q33)=0,"",N('Janvier'!Q33)) | D31: =IF(N('Février'!Q33)=0,"",N('Février'!Q33)) | E31: =IF(N('Mars'!Q33)=0,"",N('Mars'!Q33)) | F31: =IF(N('Avril'!Q33)=0,"",N('Avril'!Q33)) | G31: =IF(N('Mai'!Q33)=0,"",N('Mai'!Q33)) | H31: =IF(N('Juin'!Q33)=0,"",N('Juin'!Q33)) | I31: =IF(N('Juillet'!Q33)=0,"",N('Juillet'!Q33)) | J31: =IF(N('Août'!Q33)=0,"",N('Août'!Q33)) | K31: =IF(N('Septembre'!Q33)=0,"",N('Septembre'!Q33)) | L31: =IF(N('Octobre'!Q33)=0,"",N('Octobre'!Q33)) | M31: =IF(N('Novembre'!Q33)=0,"",N('Novembre'!Q33)) | N31: =IF(N('Décembre'!Q33)=0,"",N('Décembre'!Q33)) | O31: =IF(COUNT(C31:N31)=0,"",SUM(C31:N31)) | P31: =IF(COUNT(C31:N31)=0,"",ROUND(AVERAGE(C31:N31),1)) | Q31: =IF(COUNT(C31:N31)=0,"",MAX(C31:N31))
A32: =IF(Produits!$A$32="","",Produits!$A$32) | B32: =IF(Produits!$A$32="","",Produits!$C$32) | C32: =IF(N('Janvier'!Q34)=0,"",N('Janvier'!Q34)) | D32: =IF(N('Février'!Q34)=0,"",N('Février'!Q34)) | E32: =IF(N('Mars'!Q34)=0,"",N('Mars'!Q34)) | F32: =IF(N('Avril'!Q34)=0,"",N('Avril'!Q34)) | G32: =IF(N('Mai'!Q34)=0,"",N('Mai'!Q34)) | H32: =IF(N('Juin'!Q34)=0,"",N('Juin'!Q34)) | I32: =IF(N('Juillet'!Q34)=0,"",N('Juillet'!Q34)) | J32: =IF(N('Août'!Q34)=0,"",N('Août'!Q34)) | K32: =IF(N('Septembre'!Q34)=0,"",N('Septembre'!Q34)) | L32: =IF(N('Octobre'!Q34)=0,"",N('Octobre'!Q34)) | M32: =IF(N('Novembre'!Q34)=0,"",N('Novembre'!Q34)) | N32: =IF(N('Décembre'!Q34)=0,"",N('Décembre'!Q34)) | O32: =IF(COUNT(C32:N32)=0,"",SUM(C32:N32)) | P32: =IF(COUNT(C32:N32)=0,"",ROUND(AVERAGE(C32:N32),1)) | Q32: =IF(COUNT(C32:N32)=0,"",MAX(C32:N32))
A33: =IF(Produits!$A$33="","",Produits!$A$33) | B33: =IF(Produits!$A$33="","",Produits!$C$33) | C33: =IF(N('Janvier'!Q35)=0,"",N('Janvier'!Q35)) | D33: =IF(N('Février'!Q35)=0,"",N('Février'!Q35)) | E33: =IF(N('Mars'!Q35)=0,"",N('Mars'!Q35)) | F33: =IF(N('Avril'!Q35)=0,"",N('Avril'!Q35)) | G33: =IF(N('Mai'!Q35)=0,"",N('Mai'!Q35)) | H33: =IF(N('Juin'!Q35)=0,"",N('Juin'!Q35)) | I33: =IF(N('Juillet'!Q35)=0,"",N('Juillet'!Q35)) | J33: =IF(N('Août'!Q35)=0,"",N('Août'!Q35)) | K33: =IF(N('Septembre'!Q35)=0,"",N('Septembre'!Q35)) | L33: =IF(N('Octobre'!Q35)=0,"",N('Octobre'!Q35)) | M33: =IF(N('Novembre'!Q35)=0,"",N('Novembre'!Q35)) | N33: =IF(N('Décembre'!Q35)=0,"",N('Décembre'!Q35)) | O33: =IF(COUNT(C33:N33)=0,"",SUM(C33:N33)) | P33: =IF(COUNT(C33:N33)=0,"",ROUND(AVERAGE(C33:N33),1)) | Q33: =IF(COUNT(C33:N33)=0,"",MAX(C33:N33))
A34: =IF(Produits!$A$34="","",Produits!$A$34) | B34: =IF(Produits!$A$34="","",Produits!$C$34) | C34: =IF(N('Janvier'!Q36)=0,"",N('Janvier'!Q36)) | D34: =IF(N('Février'!Q36)=0,"",N('Février'!Q36)) | E34: =IF(N('Mars'!Q36)=0,"",N('Mars'!Q36)) | F34: =IF(N('Avril'!Q36)=0,"",N('Avril'!Q36)) | G34: =IF(N('Mai'!Q36)=0,"",N('Mai'!Q36)) | H34: =IF(N('Juin'!Q36)=0,"",N('Juin'!Q36)) | I34: =IF(N('Juillet'!Q36)=0,"",N('Juillet'!Q36)) | J34: =IF(N('Août'!Q36)=0,"",N('Août'!Q36)) | K34: =IF(N('Septembre'!Q36)=0,"",N('Septembre'!Q36)) | L34: =IF(N('Octobre'!Q36)=0,"",N('Octobre'!Q36)) | M34: =IF(N('Novembre'!Q36)=0,"",N('Novembre'!Q36)) | N34: =IF(N('Décembre'!Q36)=0,"",N('Décembre'!Q36)) | O34: =IF(COUNT(C34:N34)=0,"",SUM(C34:N34)) | P34: =IF(COUNT(C34:N34)=0,"",ROUND(AVERAGE(C34:N34),1)) | Q34: =IF(COUNT(C34:N34)=0,"",MAX(C34:N34))
A35: =IF(Produits!$A$35="","",Produits!$A$35) | B35: =IF(Produits!$A$35="","",Produits!$C$35) | C35: =IF(N('Janvier'!Q37)=0,"",N('Janvier'!Q37)) | D35: =IF(N('Février'!Q37)=0,"",N('Février'!Q37)) | E35: =IF(N('Mars'!Q37)=0,"",N('Mars'!Q37)) | F35: =IF(N('Avril'!Q37)=0,"",N('Avril'!Q37)) | G35: =IF(N('Mai'!Q37)=0,"",N('Mai'!Q37)) | H35: =IF(N('Juin'!Q37)=0,"",N('Juin'!Q37)) | I35: =IF(N('Juillet'!Q37)=0,"",N('Juillet'!Q37)) | J35: =IF(N('Août'!Q37)=0,"",N('Août'!Q37)) | K35: =IF(N('Septembre'!Q37)=0,"",N('Septembre'!Q37)) | L35: =IF(N('Octobre'!Q37)=0,"",N('Octobre'!Q37)) | M35: =IF(N('Novembre'!Q37)=0,"",N('Novembre'!Q37)) | N35: =IF(N('Décembre'!Q37)=0,"",N('Décembre'!Q37)) | O35: =IF(COUNT(C35:N35)=0,"",SUM(C35:N35)) | P35: =IF(COUNT(C35:N35)=0,"",ROUND(AVERAGE(C35:N35),1)) | Q35: =IF(COUNT(C35:N35)=0,"",MAX(C35:N35))
A36: =IF(Produits!$A$36="","",Produits!$A$36) | B36: =IF(Produits!$A$36="","",Produits!$C$36) | C36: =IF(N('Janvier'!Q38)=0,"",N('Janvier'!Q38)) | D36: =IF(N('Février'!Q38)=0,"",N('Février'!Q38)) | E36: =IF(N('Mars'!Q38)=0,"",N('Mars'!Q38)) | F36: =IF(N('Avril'!Q38)=0,"",N('Avril'!Q38)) | G36: =IF(N('Mai'!Q38)=0,"",N('Mai'!Q38)) | H36: =IF(N('Juin'!Q38)=0,"",N('Juin'!Q38)) | I36: =IF(N('Juillet'!Q38)=0,"",N('Juillet'!Q38)) | J36: =IF(N('Août'!Q38)=0,"",N('Août'!Q38)) | K36: =IF(N('Septembre'!Q38)=0,"",N('Septembre'!Q38)) | L36: =IF(N('Octobre'!Q38)=0,"",N('Octobre'!Q38)) | M36: =IF(N('Novembre'!Q38)=0,"",N('Novembre'!Q38)) | N36: =IF(N('Décembre'!Q38)=0,"",N('Décembre'!Q38)) | O36: =IF(COUNT(C36:N36)=0,"",SUM(C36:N36)) | P36: =IF(COUNT(C36:N36)=0,"",ROUND(AVERAGE(C36:N36),1)) | Q36: =IF(COUNT(C36:N36)=0,"",MAX(C36:N36))
A37: =IF(Produits!$A$37="","",Produits!$A$37) | B37: =IF(Produits!$A$37="","",Produits!$C$37) | C37: =IF(N('Janvier'!Q39)=0,"",N('Janvier'!Q39)) | D37: =IF(N('Février'!Q39)=0,"",N('Février'!Q39)) | E37: =IF(N('Mars'!Q39)=0,"",N('Mars'!Q39)) | F37: =IF(N('Avril'!Q39)=0,"",N('Avril'!Q39)) | G37: =IF(N('Mai'!Q39)=0,"",N('Mai'!Q39)) | H37: =IF(N('Juin'!Q39)=0,"",N('Juin'!Q39)) | I37: =IF(N('Juillet'!Q39)=0,"",N('Juillet'!Q39)) | J37: =IF(N('Août'!Q39)=0,"",N('Août'!Q39)) | K37: =IF(N('Septembre'!Q39)=0,"",N('Septembre'!Q39)) | L37: =IF(N('Octobre'!Q39)=0,"",N('Octobre'!Q39)) | M37: =IF(N('Novembre'!Q39)=0,"",N('Novembre'!Q39)) | N37: =IF(N('Décembre'!Q39)=0,"",N('Décembre'!Q39)) | O37: =IF(COUNT(C37:N37)=0,"",SUM(C37:N37)) | P37: =IF(COUNT(C37:N37)=0,"",ROUND(AVERAGE(C37:N37),1)) | Q37: =IF(COUNT(C37:N37)=0,"",MAX(C37:N37))
A38: =IF(Produits!$A$38="","",Produits!$A$38) | B38: =IF(Produits!$A$38="","",Produits!$C$38) | C38: =IF(N('Janvier'!Q40)=0,"",N('Janvier'!Q40)) | D38: =IF(N('Février'!Q40)=0,"",N('Février'!Q40)) | E38: =IF(N('Mars'!Q40)=0,"",N('Mars'!Q40)) | F38: =IF(N('Avril'!Q40)=0,"",N('Avril'!Q40)) | G38: =IF(N('Mai'!Q40)=0,"",N('Mai'!Q40)) | H38: =IF(N('Juin'!Q40)=0,"",N('Juin'!Q40)) | I38: =IF(N('Juillet'!Q40)=0,"",N('Juillet'!Q40)) | J38: =IF(N('Août'!Q40)=0,"",N('Août'!Q40)) | K38: =IF(N('Septembre'!Q40)=0,"",N('Septembre'!Q40)) | L38: =IF(N('Octobre'!Q40)=0,"",N('Octobre'!Q40)) | M38: =IF(N('Novembre'!Q40)=0,"",N('Novembre'!Q40)) | N38: =IF(N('Décembre'!Q40)=0,"",N('Décembre'!Q40)) | O38: =IF(COUNT(C38:N38)=0,"",SUM(C38:N38)) | P38: =IF(COUNT(C38:N38)=0,"",ROUND(AVERAGE(C38:N38),1)) | Q38: =IF(COUNT(C38:N38)=0,"",MAX(C38:N38))
A39: =IF(Produits!$A$39="","",Produits!$A$39) | B39: =IF(Produits!$A$39="","",Produits!$C$39) | C39: =IF(N('Janvier'!Q41)=0,"",N('Janvier'!Q41)) | D39: =IF(N('Février'!Q41)=0,"",N('Février'!Q41)) | E39: =IF(N('Mars'!Q41)=0,"",N('Mars'!Q41)) | F39: =IF(N('Avril'!Q41)=0,"",N('Avril'!Q41)) | G39: =IF(N('Mai'!Q41)=0,"",N('Mai'!Q41)) | H39: =IF(N('Juin'!Q41)=0,"",N('Juin'!Q41)) | I39: =IF(N('Juillet'!Q41)=0,"",N('Juillet'!Q41)) | J39: =IF(N('Août'!Q41)=0,"",N('Août'!Q41)) | K39: =IF(N('Septembre'!Q41)=0,"",N('Septembre'!Q41)) | L39: =IF(N('Octobre'!Q41)=0,"",N('Octobre'!Q41)) | M39: =IF(N('Novembre'!Q41)=0,"",N('Novembre'!Q41)) | N39: =IF(N('Décembre'!Q41)=0,"",N('Décembre'!Q41)) | O39: =IF(COUNT(C39:N39)=0,"",SUM(C39:N39)) | P39: =IF(COUNT(C39:N39)=0,"",ROUND(AVERAGE(C39:N39),1)) | Q39: =IF(COUNT(C39:N39)=0,"",MAX(C39:N39))
A40: =IF(Produits!$A$40="","",Produits!$A$40) | B40: =IF(Produits!$A$40="","",Produits!$C$40) | C40: =IF(N('Janvier'!Q42)=0,"",N('Janvier'!Q42)) | D40: =IF(N('Février'!Q42)=0,"",N('Février'!Q42)) | E40: =IF(N('Mars'!Q42)=0,"",N('Mars'!Q42)) | F40: =IF(N('Avril'!Q42)=0,"",N('Avril'!Q42)) | G40: =IF(N('Mai'!Q42)=0,"",N('Mai'!Q42)) | H40: =IF(N('Juin'!Q42)=0,"",N('Juin'!Q42)) | I40: =IF(N('Juillet'!Q42)=0,"",N('Juillet'!Q42)) | J40: =IF(N('Août'!Q42)=0,"",N('Août'!Q42)) | K40: =IF(N('Septembre'!Q42)=0,"",N('Septembre'!Q42)) | L40: =IF(N('Octobre'!Q42)=0,"",N('Octobre'!Q42)) | M40: =IF(N('Novembre'!Q42)=0,"",N('Novembre'!Q42)) | N40: =IF(N('Décembre'!Q42)=0,"",N('Décembre'!Q42)) | O40: =IF(COUNT(C40:N40)=0,"",SUM(C40:N40)) | P40: =IF(COUNT(C40:N40)=0,"",ROUND(AVERAGE(C40:N40),1)) | Q40: =IF(COUNT(C40:N40)=0,"",MAX(C40:N40))
A41: =IF(Produits!$A$41="","",Produits!$A$41) | B41: =IF(Produits!$A$41="","",Produits!$C$41) | C41: =IF(N('Janvier'!Q43)=0,"",N('Janvier'!Q43)) | D41: =IF(N('Février'!Q43)=0,"",N('Février'!Q43)) | E41: =IF(N('Mars'!Q43)=0,"",N('Mars'!Q43)) | F41: =IF(N('Avril'!Q43)=0,"",N('Avril'!Q43)) | G41: =IF(N('Mai'!Q43)=0,"",N('Mai'!Q43)) | H41: =IF(N('Juin'!Q43)=0,"",N('Juin'!Q43)) | I41: =IF(N('Juillet'!Q43)=0,"",N('Juillet'!Q43)) | J41: =IF(N('Août'!Q43)=0,"",N('Août'!Q43)) | K41: =IF(N('Septembre'!Q43)=0,"",N('Septembre'!Q43)) | L41: =IF(N('Octobre'!Q43)=0,"",N('Octobre'!Q43)) | M41: =IF(N('Novembre'!Q43)=0,"",N('Novembre'!Q43)) | N41: =IF(N('Décembre'!Q43)=0,"",N('Décembre'!Q43)) | O41: =IF(COUNT(C41:N41)=0,"",SUM(C41:N41)) | P41: =IF(COUNT(C41:N41)=0,"",ROUND(AVERAGE(C41:N41),1)) | Q41: =IF(COUNT(C41:N41)=0,"",MAX(C41:N41))
...

Sheet Produits
A1: Mes produits
A2: Une ligne par produit. Tout le reste du fichier se remplit à partir de cette liste.
A4: Produit | B4: Fournisseur | C4: Unité
A5: Farine T55 | B5: Metro | C5: kg
A6: Farine T45 | B6: Metro | C6: kg
A7: Sucre semoule | B7: Metro | C7: kg
A8: Sucre glace | B8: Metro | C8: kg
A9: Beurre doux | B9: Crèmerie | C9: kg
A10: Crème liquide 35% | B10: Crèmerie | C10: L
A11: Lait entier | B11: Crèmerie | C11: L
A12: Oeufs | B12: Crèmerie | C12: pièce
A13: Chocolat blanc | B13: Transgourmet | C13: kg
A14: Chocolat noir 70% | B14: Transgourmet | C14: kg
A15: Levure chimique | B15: Transgourmet | C15: kg
A16: Vanille (gousse) | B16: Transgourmet | C16: pièce

Sheet Janvier
A1: Janvier 2026
A2: Stock = ce qu'il reste · Commandé = ce que tu demandes · Reçu = ce qui est arrivé
A4: Produit | B4: Fournisseur | C4: Unité | D4: Semaine 1 | G4: Semaine 2 | J4: Semaine 3 | M4: Semaine 4 | P4: Total du mois
D6: Stock | E6: Commandé | F6: Reçu | G6: Stock | H6: Commandé | I6: Reçu | J6: Stock | K6: Commandé | L6: Reçu | M6: Stock | N6: Commandé | O6: Reçu | P6: Commandé | Q6: Reçu | R6: Écart | S6: Dernier stock
A7: =IF(Produits!$A$5="","",Produits!$A$5) | B7: =IF(Produits!$A$5="","",Produits!$B$5) | C7: =IF(Produits!$A$5="","",Produits!$C$5) | P7: =IF(COUNT(E7,H7,K7,N7)=0,"",SUM(E7,H7,K7,N7)) | Q7: =IF(COUNT(F7,I7,L7,O7)=0,"",SUM(F7,I7,L7,O7)) | R7: =IF(OR(P7="",Q7=""),"",Q7-P7) | S7: =IF(M7<>"",M7,IF(J7<>"",J7,IF(G7<>"",G7,IF(D7<>"",D7,""))))
A8: =IF(Produits!$A$6="","",Produits!$A$6) | B8: =IF(Produits!$A$6="","",Produits!$B$6) | C8: =IF(Produits!$A$6="","",Produits!$C$6) | P8: =IF(COUNT(E8,H8,K8,N8)=0,"",SUM(E8,H8,K8,N8)) | Q8: =IF(COUNT(F8,I8,L8,O8)=0,"",SUM(F8,I8,L8,O8)) | R8: =IF(OR(P8="",Q8=""),"",Q8-P8) | S8: =IF(M8<>"",M8,IF(J8<>"",J8,IF(G8<>"",G8,IF(D8<>"",D8,""))))
A9: =IF(Produits!$A$7="","",Produits!$A$7) | B9: =IF(Produits!$A$7="","",Produits!$B$7) | C9: =IF(Produits!$A$7="","",Produits!$C$7) | P9: =IF(COUNT(E9,H9,K9,N9)=0,"",SUM(E9,H9,K9,N9)) | Q9: =IF(COUNT(F9,I9,L9,O9)=0,"",SUM(F9,I9,L9,O9)) | R9: =IF(OR(P9="",Q9=""),"",Q9-P9) | S9: =IF(M9<>"",M9,IF(J9<>"",J9,IF(G9<>"",G9,IF(D9<>"",D9,""))))
A10: =IF(Produits!$A$8="","",Produits!$A$8) | B10: =IF(Produits!$A$8="","",Produits!$B$8) | C10: =IF(Produits!$A$8="","",Produits!$C$8) | P10: =IF(COUNT(E10,H10,K10,N10)=0,"",SUM(E10,H10,K10,N10)) | Q10: =IF(COUNT(F10,I10,L10,O10)=0,"",SUM(F10,I10,L10,O10)) | R10: =IF(OR(P10="",Q10=""),"",Q10-P10) | S10: =IF(M10<>"",M10,IF(J10<>"",J10,IF(G10<>"",G10,IF(D10<>"",D10,""))))
A11: =IF(Produits!$A$9="","",Produits!$A$9) | B11: =IF(Produits!$A$9="","",Produits!$B$9) | C11: =IF(Produits!$A$9="","",Produits!$C$9) | P11: =IF(COUNT(E11,H11,K11,N11)=0,"",SUM(E11,H11,K11,N11)) | Q11: =IF(COUNT(F11,I11,L11,O11)=0,"",SUM(F11,I11,L11,O11)) | R11: =IF(OR(P11="",Q11=""),"",Q11-P11) | S11: =IF(M11<>"",M11,IF(J11<>"",J11,IF(G11<>"",G11,IF(D11<>"",D11,""))))
A12: =IF(Produits!$A$10="","",Produits!$A$10) | B12: =IF(Produits!$A$10="","",Produits!$B$10) | C12: =IF(Produits!$A$10="","",Produits!$C$10) | P12: =IF(COUNT(E12,H12,K12,N12)=0,"",SUM(E12,H12,K12,N12)) | Q12: =IF(COUNT(F12,I12,L12,O12)=0,"",SUM(F12,I12,L12,O12)) | R12: =IF(OR(P12="",Q12=""),"",Q12-P12) | S12: =IF(M12<>"",M12,IF(J12<>"",J12,IF(G12<>"",G12,IF(D12<>"",D12,""))))
A13: =IF(Produits!$A$11="","",Produits!$A$11) | B13: =IF(Produits!$A$11="","",Produits!$B$11) | C13: =IF(Produits!$A$11="","",Produits!$C$11) | P13: =IF(COUNT(E13,H13,K13,N13)=0,"",SUM(E13,H13,K13,N13)) | Q13: =IF(COUNT(F13,I13,L13,O13)=0,"",SUM(F13,I13,L13,O13)) | R13: =IF(OR(P13="",Q13=""),"",Q13-P13) | S13: =IF(M13<>"",M13,IF(J13<>"",J13,IF(G13<>"",G13,IF(D13<>"",D13,""))))
A14: =IF(Produits!$A$12="","",Produits!$A$12) | B14: =IF(Produits!$A$12="","",Produits!$B$12) | C14: =IF(Produits!$A$12="","",Produits!$C$12) | P14: =IF(COUNT(E14,H14,K14,N14)=0,"",SUM(E14,H14,K14,N14)) | Q14: =IF(COUNT(F14,I14,L14,O14)=0,"",SUM(F14,I14,L14,O14)) | R14: =IF(OR(P14="",Q14=""),"",Q14-P14) | S14: =IF(M14<>"",M14,IF(J14<>"",J14,IF(G14<>"",G14,IF(D14<>"",D14,""))))
A15: =IF(Produits!$A$13="","",Produits!$A$13) | B15: =IF(Produits!$A$13="","",Produits!$B$13) | C15: =IF(Produits!$A$13="","",Produits!$C$13) | P15: =IF(COUNT(E15,H15,K15,N15)=0,"",SUM(E15,H15,K15,N15)) | Q15: =IF(COUNT(F15,I15,L15,O15)=0,"",SUM(F15,I15,L15,O15)) | R15: =IF(OR(P15="",Q15=""),"",Q15-P15) | S15: =IF(M15<>"",M15,IF(J15<>"",J15,IF(G15<>"",G15,IF(D15<>"",D15,""))))
A16: =IF(Produits!$A$14="","",Produits!$A$14) | B16: =IF(Produits!$A$14="","",Produits!$B$14) | C16: =IF(Produits!$A$14="","",Produits!$C$14) | P16: =IF(COUNT(E16,H16,K16,N16)=0,"",SUM(E16,H16,K16,N16)) | Q16: =IF(COUNT(F16,I16,L16,O16)=0,"",SUM(F16,I16,L16,O16)) | R16: =IF(OR(P16="",Q16=""),"",Q16-P16) | S16: =IF(M16<>"",M16,IF(J16<>"",J16,IF(G16<>"",G16,IF(D16<>"",D16,""))))
A17: =IF(Produits!$A$15="","",Produits!$A$15) | B17: =IF(Produits!$A$15="","",Produits!$B$15) | C17: =IF(Produits!$A$15="","",Produits!$C$15) | P17: =IF(COUNT(E17,H17,K17,N17)=0,"",SUM(E17,H17,K17,N17)) | Q17: =IF(COUNT(F17,I17,L17,O17)=0,"",SUM(F17,I17,L17,O17)) | R17: =IF(OR(P17="",Q17=""),"",Q17-P17) | S17: =IF(M17<>"",M17,IF(J17<>"",J17,IF(G17<>"",G17,IF(D17<>"",D17,""))))
A18: =IF(Produits!$A$16="","",Produits!$A$16) | B18: =IF(Produits!$A$16="","",Produits!$B$16) | C18: =IF(Produits!$A$16="","",Produits!$C$16) | P18: =IF(COUNT(E18,H18,K18,N18)=0,"",SUM(E18,H18,K18,N18)) | Q18: =IF(COUNT(F18,I18,L18,O18)=0,"",SUM(F18,I18,L18,O18)) | R18: =IF(OR(P18="",Q18=""),"",Q18-P18) | S18: =IF(M18<>"",M18,IF(J18<>"",J18,IF(G18<>"",G18,IF(D18<>"",D18,""))))
A19: =IF(Produits!$A$17="","",Produits!$A$17) | B19: =IF(Produits!$A$17="","",Produits!$B$17) | C19: =IF(Produits!$A$17="","",Produits!$C$17) | P19: =IF(COUNT(E19,H19,K19,N19)=0,"",SUM(E19,H19,K19,N19)) | Q19: =IF(COUNT(F19,I19,L19,O19)=0,"",SUM(F19,I19,L19,O19)) | R19: =IF(OR(P19="",Q19=""),"",Q19-P19) | S19: =IF(M19<>"",M19,IF(J19<>"",J19,IF(G19<>"",G19,IF(D19<>"",D19,""))))
A20: =IF(Produits!$A$18="","",Produits!$A$18) | B20: =IF(Produits!$A$18="","",Produits!$B$18) | C20: =IF(Produits!$A$18="","",Produits!$C$18) | P20: =IF(COUNT(E20,H20,K20,N20)=0,"",SUM(E20,H20,K20,N20)) | Q20: =IF(COUNT(F20,I20,L20,O20)=0,"",SUM(F20,I20,L20,O20)) | R20: =IF(OR(P20="",Q20=""),"",Q20-P20) | S20: =IF(M20<>"",M20,IF(J20<>"",J20,IF(G20<>"",G20,IF(D20<>"",D20,""))))
A21: =IF(Produits!$A$19="","",Produits!$A$19) | B21: =IF(Produits!$A$19="","",Produits!$B$19) | C21: =IF(Produits!$A$19="","",Produits!$C$19) | P21: =IF(COUNT(E21,H21,K21,N21)=0,"",SUM(E21,H21,K21,N21)) | Q21: =IF(COUNT(F21,I21,L21,O21)=0,"",SUM(F21,I21,L21,O21)) | R21: =IF(OR(P21="",Q21=""),"",Q21-P21) | S21: =IF(M21<>"",M21,IF(J21<>"",J21,IF(G21<>"",G21,IF(D21<>"",D21,""))))
A22: =IF(Produits!$A$20="","",Produits!$A$20) | B22: =IF(Produits!$A$20="","",Produits!$B$20) | C22: =IF(Produits!$A$20="","",Produits!$C$20) | P22: =IF(COUNT(E22,H22,K22,N22)=0,"",SUM(E22,H22,K22,N22)) | Q22: =IF(COUNT(F22,I22,L22,O22)=0,"",SUM(F22,I22,L22,O22)) | R22: =IF(OR(P22="",Q22=""),"",Q22-P22) | S22: =IF(M22<>"",M22,IF(J22<>"",J22,IF(G22<>"",G22,IF(D22<>"",D22,""))))
A23: =IF(Produits!$A$21="","",Produits!$A$21) | B23: =IF(Produits!$A$21="","",Produits!$B$21) | C23: =IF(Produits!$A$21="","",Produits!$C$21) | P23: =IF(COUNT(E23,H23,K23,N23)=0,"",SUM(E23,H23,K23,N23)) | Q23: =IF(COUNT(F23,I23,L23,O23)=0,"",SUM(F23,I23,L23,O23)) | R23: =IF(OR(P23="",Q23=""),"",Q23-P23) | S23: =IF(M23<>"",M23,IF(J23<>"",J23,IF(G23<>"",G23,IF(D23<>"",D23,""))))
A24: =IF(Produits!$A$22="","",Produits!$A$22) | B24: =IF(Produits!$A$22="","",Produits!$B$22) | C24: =IF(Produits!$A$22="","",Produits!$C$22) | P24: =IF(COUNT(E24,H24,K24,N24)=0,"",SUM(E24,H24,K24,N24)) | Q24: =IF(COUNT(F24,I24,L24,O24)=0,"",SUM(F24,I24,L24,O24)) | R24: =IF(OR(P24="",Q24=""),"",Q24-P24) | S24: =IF(M24<>"",M24,IF(J24<>"",J24,IF(G24<>"",G24,IF(D24<>"",D24,""))))
A25: =IF(Produits!$A$23="","",Produits!$A$23) | B25: =IF(Produits!$A$23="","",Produits!$B$23) | C25: =IF(Produits!$A$23="","",Produits!$C$23) | P25: =IF(COUNT(E25,H25,K25,N25)=0,"",SUM(E25,H25,K25,N25)) | Q25: =IF(COUNT(F25,I25,L25,O25)=0,"",SUM(F25,I25,L25,O25)) | R25: =IF(OR(P25="",Q25=""),"",Q25-P25) | S25: =IF(M25<>"",M25,IF(J25<>"",J25,IF(G25<>"",G25,IF(D25<>"",D25,""))))
A26: =IF(Produits!$A$24="","",Produits!$A$24) | B26: =IF(Produits!$A$24="","",Produits!$B$24) | C26: =IF(Produits!$A$24="","",Produits!$C$24) | P26: =IF(COUNT(E26,H26,K26,N26)=0,"",SUM(E26,H26,K26,N26)) | Q26: =IF(COUNT(F26,I26,L26,O26)=0,"",SUM(F26,I26,L26,O26)) | R26: =IF(OR(P26="",Q26=""),"",Q26-P26) | S26: =IF(M26<>"",M26,IF(J26<>"",J26,IF(G26<>"",G26,IF(D26<>"",D26,""))))
A27: =IF(Produits!$A$25="","",Produits!$A$25) | B27: =IF(Produits!$A$25="","",Produits!$B$25) | C27: =IF(Produits!$A$25="","",Produits!$C$25) | P27: =IF(COUNT(E27,H27,K27,N27)=0,"",SUM(E27,H27,K27,N27)) | Q27: =IF(COUNT(F27,I27,L27,O27)=0,"",SUM(F27,I27,L27,O27)) | R27: =IF(OR(P27="",Q27=""),"",Q27-P27) | S27: =IF(M27<>"",M27,IF(J27<>"",J27,IF(G27<>"",G27,IF(D27<>"",D27,""))))
A28: =IF(Produits!$A$26="","",Produits!$A$26) | B28: =IF(Produits!$A$26="","",Produits!$B$26) | C28: =IF(Produits!$A$26="","",Produits!$C$26) | P28: =IF(COUNT(E28,H28,K28,N28)=0,"",SUM(E28,H28,K28,N28)) | Q28: =IF(COUNT(F28,I28,L28,O28)=0,"",SUM(F28,I28,L28,O28)) | R28: =IF(OR(P28="",Q28=""),"",Q28-P28) | S28: =IF(M28<>"",M28,IF(J28<>"",J28,IF(G28<>"",G28,IF(D28<>"",D28,""))))
A29: =IF(Produits!$A$27="","",Produits!$A$27) | B29: =IF(Produits!$A$27="","",Produits!$B$27) | C29: =IF(Produits!$A$27="","",Produits!$C$27) | P29: =IF(COUNT(E29,H29,K29,N29)=0,"",SUM(E29,H29,K29,N29)) | Q29: =IF(COUNT(F29,I29,L29,O29)=0,"",SUM(F29,I29,L29,O29)) | R29: =IF(OR(P29="",Q29=""),"",Q29-P29) | S29: =IF(M29<>"",M29,IF(J29<>"",J29,IF(G29<>"",G29,IF(D29<>"",D29,""))))
A30: =IF(Produits!$A$28="","",Produits!$A$28) | B30: =IF(Produits!$A$28="","",Produits!$B$28) | C30: =IF(Produits!$A$28="","",Produits!$C$28) | P30: =IF(COUNT(E30,H30,K30,N30)=0,"",SUM(E30,H30,K30,N30)) | Q30: =IF(COUNT(F30,I30,L30,O30)=0,"",SUM(F30,I30,L30,O30)) | R30: =IF(OR(P30="",Q30=""),"",Q30-P30) | S30: =IF(M30<>"",M30,IF(J30<>"",J30,IF(G30<>"",G30,IF(D30<>"",D30,""))))
A31: =IF(Produits!$A$29="","",Produits!$A$29) | B31: =IF(Produits!$A$29="","",Produits!$B$29) | C31: =IF(Produits!$A$29="","",Produits!$C$29) | P31: =IF(COUNT(E31,H31,K31,N31)=0,"",SUM(E31,H31,K31,N31)) | Q31: =IF(COUNT(F31,I31,L31,O31)=0,"",SUM(F31,I31,L31,O31)) | R31: =IF(OR(P31="",Q31=""),"",Q31-P31) | S31: =IF(M31<>"",M31,IF(J31<>"",J31,IF(G31<>"",G31,IF(D31<>"",D31,""))))
A32: =IF(Produits!$A$30="","",Produits!$A$30) | B32: =IF(Produits!$A$30="","",Produits!$B$30) | C32: =IF(Produits!$A$30="","",Produits!$C$30) | P32: =IF(COUNT(E32,H32,K32,N32)=0,"",SUM(E32,H32,K32,N32)) | Q32: =IF(COUNT(F32,I32,L32,O32)=0,"",SUM(F32,I32,L32,O32)) | R32: =IF(OR(P32="",Q32=""),"",Q32-P32) | S32: =IF(M32<>"",M32,IF(J32<>"",J32,IF(G32<>"",G32,IF(D32<>"",D32,""))))
A33: =IF(Produits!$A$31="","",Produits!$A$31) | B33: =IF(Produits!$A$31="","",Produits!$B$31) | C33: =IF(Produits!$A$31="","",Produits!$C$31) | P33: =IF(COUNT(E33,H33,K33,N33)=0,"",SUM(E33,H33,K33,N33)) | Q33: =IF(COUNT(F33,I33,L33,O33)=0,"",SUM(F33,I33,L33,O33)) | R33: =IF(OR(P33="",Q33=""),"",Q33-P33) | S33: =IF(M33<>"",M33,IF(J33<>"",J33,IF(G33<>"",G33,IF(D33<>"",D33,""))))
A34: =IF(Produits!$A$32="","",Produits!$A$32) | B34: =IF(Produits!$A$32="","",Produits!$B$32) | C34: =IF(Produits!$A$32="","",Produits!$C$32) | P34: =IF(COUNT(E34,H34,K34,N34)=0,"",SUM(E34,H34,K34,N34)) | Q34: =IF(COUNT(F34,I34,L34,O34)=0,"",SUM(F34,I34,L34,O34)) | R34: =IF(OR(P34="",Q34=""),"",Q34-P34) | S34: =IF(M34<>"",M34,IF(J34<>"",J34,IF(G34<>"",G34,IF(D34<>"",D34,""))))
A35: =IF(Produits!$A$33="","",Produits!$A$33) | B35: =IF(Produits!$A$33="","",Produits!$B$33) | C35: =IF(Produits!$A$33="","",Produits!$C$33) | P35: =IF(COUNT(E35,H35,K35,N35)=0,"",SUM(E35,H35,K35,N35)) | Q35: =IF(COUNT(F35,I35,L35,O35)=0,"",SUM(F35,I35,L35,O35)) | R35: =IF(OR(P35="",Q35=""),"",Q35-P35) | S35: =IF(M35<>"",M35,IF(J35<>"",J35,IF(G35<>"",G35,IF(D35<>"",D35,""))))
A36: =IF(Produits!$A$34="","",Produits!$A$34) | B36: =IF(Produits!$A$34="","",Produits!$B$34) | C36: =IF(Produits!$A$34="","",Produits!$C$34) | P36: =IF(COUNT(E36,H36,K36,N36)=0,"",SUM(E36,H36,K36,N36)) | Q36: =IF(COUNT(F36,I36,L36,O36)=0,"",SUM(F36,I36,L36,O36)) | R36: =IF(OR(P36="",Q36=""),"",Q36-P36) | S36: =IF(M36<>"",M36,IF(J36<>"",J36,IF(G36<>"",G36,IF(D36<>"",D36,""))))
A37: =IF(Produits!$A$35="","",Produits!$A$35) | B37: =IF(Produits!$A$35="","",Produits!$B$35) | C37: =IF(Produits!$A$35="","",Produits!$C$35) | P37: =IF(COUNT(E37,H37,K37,N37)=0,"",SUM(E37,H37,K37,N37)) | Q37: =IF(COUNT(F37,I37,L37,O37)=0,"",SUM(F37,I37,L37,O37)) | R37: =IF(OR(P37="",Q37=""),"",Q37-P37) | S37: =IF(M37<>"",M37,IF(J37<>"",J37,IF(G37<>"",G37,IF(D37<>"",D37,""))))
A38: =IF(Produits!$A$36="","",Produits!$A$36) | B38: =IF(Produits!$A$36="","",Produits!$B$36) | C38: =IF(Produits!$A$36="","",Produits!$C$36) | P38: =IF(COUNT(E38,H38,K38,N38)=0,"",SUM(E38,H38,K38,N38)) | Q38: =IF(COUNT(F38,I38,L38,O38)=0,"",SUM(F38,I38,L38,O38)) | R38: =IF(OR(P38="",Q38=""),"",Q38-P38) | S38: =IF(M38<>"",M38,IF(J38<>"",J38,IF(G38<>"",G38,IF(D38<>"",D38,""))))
A39: =IF(Produits!$A$37="","",Produits!$A$37) | B39: =IF(Produits!$A$37="","",Produits!$B$37) | C39: =IF(Produits!$A$37="","",Produits!$C$37) | P39: =IF(COUNT(E39,H39,K39,N39)=0,"",SUM(E39,H39,K39,N39)) | Q39: =IF(COUNT(F39,I39,L39,O39)=0,"",SUM(F39,I39,L39,O39)) | R39: =IF(OR(P39="",Q39=""),"",Q39-P39) | S39: =IF(M39<>"",M39,IF(J39<>"",J39,IF(G39<>"",G39,IF(D39<>"",D39,""))))
A40: =IF(Produits!$A$38="","",Produits!$A$38) | B40: =IF(Produits!$A$38="","",Produits!$B$38) | C40: =IF(Produits!$A$38="","",Produits!$C$38) | P40: =IF(COUNT(E40,H40,K40,N40)=0,"",SUM(E40,H40,K40,N40)) | Q40: =IF(COUNT(F40,I40,L40,O40)=0,"",SUM(F40,I40,L40,O40)) | R40: =IF(OR(P40="",Q40=""),"",Q40-P40) | S40: =IF(M40<>"",M40,IF(J40<>"",J40,IF(G40<>"",G40,IF(D40<>"",D40,""))))
A41: =IF(Produits!$A$39="","",Produits!$A$39) | B41: =IF(Produits!$A$39="","",Produits!$B$39) | C41: =IF(Produits!$A$39="","",Produits!$C$39) | P41: =IF(COUNT(E41,H41,K41,N41)=0,"",SUM(E41,H41,K41,N41)) | Q41: =IF(COUNT(F41,I41,L41,O41)=0,"",SUM(F41,I41,L41,O41)) | R41: =IF(OR(P41="",Q41=""),"",Q41-P41) | S41: =IF(M41<>"",M41,IF(J41<>"",J41,IF(G41<>"",G41,IF(D41<>"",D41,""))))
A42: =IF(Produits!$A$40="","",Produits!$A$40) | B42: =IF(Produits!$A$40="","",Produits!$B$40) | C42: =IF(Produits!$A$40="","",Produits!$C$40) | P42: =IF(COUNT(E42,H42,K42,N42)=0,"",SUM(E42,H42,K42,N42)) | Q42: =IF(COUNT(F42,I42,L42,O42)=0,"",SUM(F42,I42,L42,O42)) | R42: =IF(OR(P42="",Q42=""),"",Q42-P42) | S42: =IF(M42<>"",M42,IF(J42<>"",J42,IF(G42<>"",G42,IF(D42<>"",D42,""))))
...

Sheet Février
A1: Février 2026
A2: Stock = ce qu'il reste · Commandé = ce que tu demandes · Reçu = ce qui est arrivé
A4: Produit | B4: Fournisseur | C4: Unité | D4: Semaine 1 | G4: Semaine 2 | J4: Semaine 3 | M4: Semaine 4 | P4: Total du mois
D6: Stock | E6: Commandé | F6: Reçu | G6: Stock | H6: Commandé | I6: Reçu | J6: Stock | K6: Commandé | L6: Reçu | M6: Stock | N6: Commandé | O6: Reçu | P6: Commandé | Q6: Reçu | R6: Écart | S6: Dernier stock
A7: =IF(Produits!$A$5="","",Produits!$A$5) | B7: =IF(Produits!$A$5="","",Produits!$B$5) | C7: =IF(Produits!$A$5="","",Produits!$C$5) | P7: =IF(COUNT(E7,H7,K7,N7)=0,"",SUM(E7,H7,K7,N7)) | Q7: =IF(COUNT(F7,I7,L7,O7)=0,"",SUM(F7,I7,L7,O7)) | R7: =IF(OR(P7="",Q7=""),"",Q7-P7) | S7: =IF(M7<>"",M7,IF(J7<>"",J7,IF(G7<>"",G7,IF(D7<>"",D7,""))))
A8: =IF(Produits!$A$6="","",Produits!$A$6) | B8: =IF(Produits!$A$6="","",Produits!$B$6) | C8: =IF(Produits!$A$6="","",Produits!$C$6) | P8: =IF(COUNT(E8,H8,K8,N8)=0,"",SUM(E8,H8,K8,N8)) | Q8: =IF(COUNT(F8,I8,L8,O8)=0,"",SUM(F8,I8,L8,O8)) | R8: =IF(OR(P8="",Q8=""),"",Q8-P8) | S8: =IF(M8<>"",M8,IF(J8<>"",J8,IF(G8<>"",G8,IF(D8<>"",D8,""))))
A9: =IF(Produits!$A$7="","",Produits!$A$7) | B9: =IF(Produits!$A$7="","",Produits!$B$7) | C9: =IF(Produits!$A$7="","",Produits!$C$7) | P9: =IF(COUNT(E9,H9,K9,N9)=0,"",SUM(E9,H9,K9,N9)) | Q9: =IF(COUNT(F9,I9,L9,O9)=0,"",SUM(F9,I9,L9,O9)) | R9: =IF(OR(P9="",Q9=""),"",Q9-P9) | S9: =IF(M9<>"",M9,IF(J9<>"",J9,IF(G9<>"",G9,IF(D9<>"",D9,""))))
A10: =IF(Produits!$A$8="","",Produits!$A$8) | B10: =IF(Produits!$A$8="","",Produits!$B$8) | C10: =IF(Produits!$A$8="","",Produits!$C$8) | P10: =IF(COUNT(E10,H10,K10,N10)=0,"",SUM(E10,H10,K10,N10)) | Q10: =IF(COUNT(F10,I10,L10,O10)=0,"",SUM(F10,I10,L10,O10)) | R10: =IF(OR(P10="",Q10=""),"",Q10-P10) | S10: =IF(M10<>"",M10,IF(J10<>"",J10,IF(G10<>"",G10,IF(D10<>"",D10,""))))
A11: =IF(Produits!$A$9="","",Produits!$A$9) | B11: =IF(Produits!$A$9="","",Produits!$B$9) | C11: =IF(Produits!$A$9="","",Produits!$C$9) | P11: =IF(COUNT(E11,H11,K11,N11)=0,"",SUM(E11,H11,K11,N11)) | Q11: =IF(COUNT(F11,I11,L11,O11)=0,"",SUM(F11,I11,L11,O11)) | R11: =IF(OR(P11="",Q11=""),"",Q11-P11) | S11: =IF(M11<>"",M11,IF(J11<>"",J11,IF(G11<>"",G11,IF(D11<>"",D11,""))))
A12: =IF(Produits!$A$10="","",Produits!$A$10) | B12: =IF(Produits!$A$10="","",Produits!$B$10) | C12: =IF(Produits!$A$10="","",Produits!$C$10) | P12: =IF(COUNT(E12,H12,K12,N12)=0,"",SUM(E12,H12,K12,N12)) | Q12: =IF(COUNT(F12,I12,L12,O12)=0,"",SUM(F12,I12,L12,O12)) | R12: =IF(OR(P12="",Q12=""),"",Q12-P12) | S12: =IF(M12<>"",M12,IF(J12<>"",J12,IF(G12<>"",G12,IF(D12<>"",D12,""))))
A13: =IF(Produits!$A$11="","",Produits!$A$11) | B13: =IF(Produits!$A$11="","",Produits!$B$11) | C13: =IF(Produits!$A$11="","",Produits!$C$11) | P13: =IF(COUNT(E13,H13,K13,N13)=0,"",SUM(E13,H13,K13,N13)) | Q13: =IF(COUNT(F13,I13,L13,O13)=0,"",SUM(F13,I13,L13,O13)) | R13: =IF(OR(P13="",Q13=""),"",Q13-P13) | S13: =IF(M13<>"",M13,IF(J13<>"",J13,IF(G13<>"",G13,IF(D13<>"",D13,""))))
A14: =IF(Produits!$A$12="","",Produits!$A$12) | B14: =IF(Produits!$A$12="","",Produits!$B$12) | C14: =IF(Produits!$A$12="","",Produits!$C$12) | P14: =IF(COUNT(E14,H14,K14,N14)=0,"",SUM(E14,H14,K14,N14)) | Q14: =IF(COUNT(F14,I14,L14,O14)=0,"",SUM(F14,I14,L14,O14)) | R14: =IF(OR(P14="",Q14=""),"",Q14-P14) | S14: =IF(M14<>"",M14,IF(J14<>"",J14,IF(G14<>"",G14,IF(D14<>"",D14,""))))
A15: =IF(Produits!$A$13="","",Produits!$A$13) | B15: =IF(Produits!$A$13="","",Produits!$B$13) | C15: =IF(Produits!$A$13="","",Produits!$C$13) | P15: =IF(COUNT(E15,H15,K15,N15)=0,"",SUM(E15,H15,K15,N15)) | Q15: =IF(COUNT(F15,I15,L15,O15)=0,"",SUM(F15,I15,L15,O15)) | R15: =IF(OR(P15="",Q15=""),"",Q15-P15) | S15: =IF(M15<>"",M15,IF(J15<>"",J15,IF(G15<>"",G15,IF(D15<>"",D15,""))))
A16: =IF(Produits!$A$14="","",Produits!$A$14) | B16: =IF(Produits!$A$14="","",Produits!$B$14) | C16: =IF(Produits!$A$14="","",Produits!$C$14) | P16: =IF(COUNT(E16,H16,K16,N16)=0,"",SUM(E16,H16,K16,N16)) | Q16: =IF(COUNT(F16,I16,L16,O16)=0,"",SUM(F16,I16,L16,O16)) | R16: =IF(OR(P16="",Q16=""),"",Q16-P16) | S16: =IF(M16<>"",M16,IF(J16<>"",J16,IF(G16<>"",G16,IF(D16<>"",D16,""))))
A17: =IF(Produits!$A$15="","",Produits!$A$15) | B17: =IF(Produits!$A$15="","",Produits!$B$15) | C17: =IF(Produits!$A$15="","",Produits!$C$15) | P17: =IF(COUNT(E17,H17,K17,N17)=0,"",SUM(E17,H17,K17,N17)) | Q17: =IF(COUNT(F17,I17,L17,O17)=0,"",SUM(F17,I17,L17,O17)) | R17: =IF(OR(P17="",Q17=""),"",Q17-P17) | S17: =IF(M17<>"",M17,IF(J17<>"",J17,IF(G17<>"",G17,IF(D17<>"",D17,""))))
A18: =IF(Produits!$A$16="","",Produits!$A$16) | B18: =IF(Produits!$A$16="","",Produits!$B$16) | C18: =IF(Produits!$A$16="","",Produits!$C$16) | P18: =IF(COUNT(E18,H18,K18,N18)=0,"",SUM(E18,H18,K18,N18)) | Q18: =IF(COUNT(F18,I18,L18,O18)=0,"",SUM(F18,I18,L18,O18)) | R18: =IF(OR(P18="",Q18=""),"",Q18-P18) | S18: =IF(M18<>"",M18,IF(J18<>"",J18,IF(G18<>"",G18,IF(D18<>"",D18,""))))
A19: =IF(Produits!$A$17="","",Produits!$A$17) | B19: =IF(Produits!$A$17="","",Produits!$B$17) | C19: =IF(Produits!$A$17="","",Produits!$C$17) | P19: =IF(COUNT(E19,H19,K19,N19)=0,"",SUM(E19,H19,K19,N19)) | Q19: =IF(COUNT(F19,I19,L19,O19)=0,"",SUM(F19,I19,L19,O19)) | R19: =IF(OR(P19="",Q19=""),"",Q19-P19) | S19: =IF(M19<>"",M19,IF(J19<>"",J19,IF(G19<>"",G19,IF(D19<>"",D19,""))))
A20: =IF(Produits!$A$18="","",Produits!$A$18) | B20: =IF(Produits!$A$18="","",Produits!$B$18) | C20: =IF(Produits!$A$18="","",Produits!$C$18) | P20: =IF(COUNT(E20,H20,K20,N20)=0,"",SUM(E20,H20,K20,N20)) | Q20: =IF(COUNT(F20,I20,L20,O20)=0,"",SUM(F20,I20,L20,O20)) | R20: =IF(OR(P20="",Q20=""),"",Q20-P20) | S20: =IF(M20<>"",M20,IF(J20<>"",J20,IF(G20<>"",G20,IF(D20<>"",D20,""))))
A21: =IF(Produits!$A$19="","",Produits!$A$19) | B21: =IF(Produits!$A$19="","",Produits!$B$19) | C21: =IF(Produits!$A$19="","",Produits!$C$19) | P21: =IF(COUNT(E21,H21,K21,N21)=0,"",SUM(E21,H21,K21,N21)) | Q21: =IF(COUNT(F21,I21,L21,O21)=0,"",SUM(F21,I21,L21,O21)) | R21: =IF(OR(P21="",Q21=""),"",Q21-P21) | S21: =IF(M21<>"",M21,IF(J21<>"",J21,IF(G21<>"",G21,IF(D21<>"",D21,""))))
A22: =IF(Produits!$A$20="","",Produits!$A$20) | B22: =IF(Produits!$A$20="","",Produits!$B$20) | C22: =IF(Produits!$A$20="","",Produits!$C$20) | P22: =IF(COUNT(E22,H22,K22,N22)=0,"",SUM(E22,H22,K22,N22)) | Q22: =IF(COUNT(F22,I22,L22,O22)=0,"",SUM(F22,I22,L22,O22)) | R22: =IF(OR(P22="",Q22=""),"",Q22-P22) | S22: =IF(M22<>"",M22,IF(J22<>"",J22,IF(G22<>"",G22,IF(D22<>"",D22,""))))
A23: =IF(Produits!$A$21="","",Produits!$A$21) | B23: =IF(Produits!$A$21="","",Produits!$B$21) | C23: =IF(Produits!$A$21="","",Produits!$C$21) | P23: =IF(COUNT(E23,H23,K23,N23)=0,"",SUM(E23,H23,K23,N23)) | Q23: =IF(COUNT(F23,I23,L23,O23)=0,"",SUM(F23,I23,L23,O23)) | R23: =IF(OR(P23="",Q23=""),"",Q23-P23) | S23: =IF(M23<>"",M23,IF(J23<>"",J23,IF(G23<>"",G23,IF(D23<>"",D23,""))))
A24: =IF(Produits!$A$22="","",Produits!$A$22) | B24: =IF(Produits!$A$22="","",Produits!$B$22) | C24: =IF(Produits!$A$22="","",Produits!$C$22) | P24: =IF(COUNT(E24,H24,K24,N24)=0,"",SUM(E24,H24,K24,N24)) | Q24: =IF(COUNT(F24,I24,L24,O24)=0,"",SUM(F24,I24,L24,O24)) | R24: =IF(OR(P24="",Q24=""),"",Q24-P24) | S24: =IF(M24<>"",M24,IF(J24<>"",J24,IF(G24<>"",G24,IF(D24<>"",D24,""))))
A25: =IF(Produits!$A$23="","",Produits!$A$23) | B25: =IF(Produits!$A$23="","",Produits!$B$23) | C25: =IF(Produits!$A$23="","",Produits!$C$23) | P25: =IF(COUNT(E25,H25,K25,N25)=0,"",SUM(E25,H25,K25,N25)) | Q25: =IF(COUNT(F25,I25,L25,O25)=0,"",SUM(F25,I25,L25,O25)) | R25: =IF(OR(P25="",Q25=""),"",Q25-P25) | S25: =IF(M25<>"",M25,IF(J25<>"",J25,IF(G25<>"",G25,IF(D25<>"",D25,""))))
A26: =IF(Produits!$A$24="","",Produits!$A$24) | B26: =IF(Produits!$A$24="","",Produits!$B$24) | C26: =IF(Produits!$A$24="","",Produits!$C$24) | P26: =IF(COUNT(E26,H26,K26,N26)=0,"",SUM(E26,H26,K26,N26)) | Q26: =IF(COUNT(F26,I26,L26,O26)=0,"",SUM(F26,I26,L26,O26)) | R26: =IF(OR(P26="",Q26=""),"",Q26-P26) | S26: =IF(M26<>"",M26,IF(J26<>"",J26,IF(G26<>"",G26,IF(D26<>"",D26,""))))
A27: =IF(Produits!$A$25="","",Produits!$A$25) | B27: =IF(Produits!$A$25="","",Produits!$B$25) | C27: =IF(Produits!$A$25="","",Produits!$C$25) | P27: =IF(COUNT(E27,H27,K27,N27)=0,"",SUM(E27,H27,K27,N27)) | Q27: =IF(COUNT(F27,I27,L27,O27)=0,"",SUM(F27,I27,L27,O27)) | R27: =IF(OR(P27="",Q27=""),"",Q27-P27) | S27: =IF(M27<>"",M27,IF(J27<>"",J27,IF(G27<>"",G27,IF(D27<>"",D27,""))))
A28: =IF(Produits!$A$26="","",Produits!$A$26) | B28: =IF(Produits!$A$26="","",Produits!$B$26) | C28: =IF(Produits!$A$26="","",Produits!$C$26) | P28: =IF(COUNT(E28,H28,K28,N28)=0,"",SUM(E28,H28,K28,N28)) | Q28: =IF(COUNT(F28,I28,L28,O28)=0,"",SUM(F28,I28,L28,O28)) | R28: =IF(OR(P28="",Q28=""),"",Q28-P28) | S28: =IF(M28<>"",M28,IF(J28<>"",J28,IF(G28<>"",G28,IF(D28<>"",D28,""))))
A29: =IF(Produits!$A$27="","",Produits!$A$27) | B29: =IF(Produits!$A$27="","",Produits!$B$27) | C29: =IF(Produits!$A$27="","",Produits!$C$27) | P29: =IF(COUNT(E29,H29,K29,N29)=0,"",SUM(E29,H29,K29,N29)) | Q29: =IF(COUNT(F29,I29,L29,O29)=0,"",SUM(F29,I29,L29,O29)) | R29: =IF(OR(P29="",Q29=""),"",Q29-P29) | S29: =IF(M29<>"",M29,IF(J29<>"",J29,IF(G29<>"",G29,IF(D29<>"",D29,""))))
A30: =IF(Produits!$A$28="","",Produits!$A$28) | B30: =IF(Produits!$A$28="","",Produits!$B$28) | C30: =IF(Produits!$A$28="","",Produits!$C$28) | P30: =IF(COUNT(E30,H30,K30,N30)=0,"",SUM(E30,H30,K30,N30)) | Q30: =IF(COUNT(F30,I30,L30,O30)=0,"",SUM(F30,I30,L30,O30)) | R30: =IF(OR(P30="",Q30=""),"",Q30-P30) | S30: =IF(M30<>"",M30,IF(J30<>"",J30,IF(G30<>"",G30,IF(D30<>"",D30,""))))
A31: =IF(Produits!$A$29="","",Produits!$A$29) | B31: =IF(Produits!$A$29="","",Produits!$B$29) | C31: =IF(Produits!$A$29="","",Produits!$C$29) | P31: =IF(COUNT(E31,H31,K31,N31)=0,"",SUM(E31,H31,K31,N31)) | Q31: =IF(COUNT(F31,I31,L31,O31)=0,"",SUM(F31,I31,L31,O31)) | R31: =IF(OR(P31="",Q31=""),"",Q31-P31) | S31: =IF(M31<>"",M31,IF(J31<>"",J31,IF(G31<>"",G31,IF(D31<>"",D31,""))))
A32: =IF(Produits!$A$30="","",Produits!$A$30) | B32: =IF(Produits!$A$30="","",Produits!$B$30) | C32: =IF(Produits!$A$30="","",Produits!$C$30) | P32: =IF(COUNT(E32,H32,K32,N32)=0,"",SUM(E32,H32,K32,N32)) | Q32: =IF(COUNT(F32,I32,L32,O32)=0,"",SUM(F32,I32,L32,O32)) | R32: =IF(OR(P32="",Q32=""),"",Q32-P32) | S32: =IF(M32<>"",M32,IF(J32<>"",J32,IF(G32<>"",G32,IF(D32<>"",D32,""))))
A33: =IF(Produits!$A$31="","",Produits!$A$31) | B33: =IF(Produits!$A$31="","",Produits!$B$31) | C33: =IF(Produits!$A$31="","",Produits!$C$31) | P33: =IF(COUNT(E33,H33,K33,N33)=0,"",SUM(E33,H33,K33,N33)) | Q33: =IF(COUNT(F33,I33,L33,O33)=0,"",SUM(F33,I33,L33,O33)) | R33: =IF(OR(P33="",Q33=""),"",Q33-P33) | S33: =IF(M33<>"",M33,IF(J33<>"",J33,IF(G33<>"",G33,IF(D33<>"",D33,""))))
A34: =IF(Produits!$A$32="","",Produits!$A$32) | B34: =IF(Produits!$A$32="","",Produits!$B$32) | C34: =IF(Produits!$A$32="","",Produits!$C$32) | P34: =IF(COUNT(E34,H34,K34,N34)=0,"",SUM(E34,H34,K34,N34)) | Q34: =IF(COUNT(F34,I34,L34,O34)=0,"",SUM(F34,I34,L34,O34)) | R34: =IF(OR(P34="",Q34=""),"",Q34-P34) | S34: =IF(M34<>"",M34,IF(J34<>"",J34,IF(G34<>"",G34,IF(D34<>"",D34,""))))
A35: =IF(Produits!$A$33="","",Produits!$A$33) | B35: =IF(Produits!$A$33="","",Produits!$B$33) | C35: =IF(Produits!$A$33="","",Produits!$C$33) | P35: =IF(COUNT(E35,H35,K35,N35)=0,"",SUM(E35,H35,K35,N35)) | Q35: =IF(COUNT(F35,I35,L35,O35)=0,"",SUM(F35,I35,L35,O35)) | R35: =IF(OR(P35="",Q35=""),"",Q35-P35) | S35: =IF(M35<>"",M35,IF(J35<>"",J35,IF(G35<>"",G35,IF(D35<>"",D35,""))))
A36: =IF(Produits!$A$34="","",Produits!$A$34) | B36: =IF(Produits!$A$34="","",Produits!$B$34) | C36: =IF(Produits!$A$34="","",Produits!$C$34) | P36: =IF(COUNT(E36,H36,K36,N36)=0,"",SUM(E36,H36,K36,N36)) | Q36: =IF(COUNT(F36,I36,L36,O36)=0,"",SUM(F36,I36,L36,O36)) | R36: =IF(OR(P36="",Q36=""),"",Q36-P36) | S36: =IF(M36<>"",M36,IF(J36<>"",J36,IF(G36<>"",G36,IF(D36<>"",D36,""))))
A37: =IF(Produits!$A$35="","",Produits!$A$35) | B37: =IF(Produits!$A$35="","",Produits!$B$35) | C37: =IF(Produits!$A$35="","",Produits!$C$35) | P37: =IF(COUNT(E37,H37,K37,N37)=0,"",SUM(E37,H37,K37,N37)) | Q37: =IF(COUNT(F37,I37,L37,O37)=0,"",SUM(F37,I37,L37,O37)) | R37: =IF(OR(P37="",Q37=""),"",Q37-P37) | S37: =IF(M37<>"",M37,IF(J37<>"",J37,IF(G37<>"",G37,IF(D37<>"",D37,""))))
A38: =IF(Produits!$A$36="","",Produits!$A$36) | B38: =IF(Produits!$A$36="","",Produits!$B$36) | C38: =IF(Produits!$A$36="","",Produits!$C$36) | P38: =IF(COUNT(E38,H38,K38,N38)=0,"",SUM(E38,H38,K38,N38)) | Q38: =IF(COUNT(F38,I38,L38,O38)=0,"",SUM(F38,I38,L38,O38)) | R38: =IF(OR(P38="",Q38=""),"",Q38-P38) | S38: =IF(M38<>"",M38,IF(J38<>"",J38,IF(G38<>"",G38,IF(D38<>"",D38,""))))
A39: =IF(Produits!$A$37="","",Produits!$A$37) | B39: =IF(Produits!$A$37="","",Produits!$B$37) | C39: =IF(Produits!$A$37="","",Produits!$C$37) | P39: =IF(COUNT(E39,H39,K39,N39)=0,"",SUM(E39,H39,K39,N39)) | Q39: =IF(COUNT(F39,I39,L39,O39)=0,"",SUM(F39,I39,L39,O39)) | R39: =IF(OR(P39="",Q39=""),"",Q39-P39) | S39: =IF(M39<>"",M39,IF(J39<>"",J39,IF(G39<>"",G39,IF(D39<>"",D39,""))))
