Workbook

Sheet Mode d'emploi
A1: 9 · Stock en euros
A2: Proposition de tableau de gestion des stocks — Excel et Google Sheets
A4: L'idée | B4: En plus des quantités, le fichier calcule la valeur de ton stock en euros et ce que tu as dépensé chez chaque fournisseur. Utile le jour de l'inventaire : tu comptes, la valeur totale se fait toute seule.
A6: Comment faire | B6: 1. Onglet Produits : produit, fournisseur, unité, prix unitaire.
B7: 2. Onglet du mois : Stock, Commandé, Reçu chaque semaine. La valeur du stock s'affiche.
B8: 3. Jour d'inventaire : onglet Inventaire, tape les quantités comptées, le total en euros se calcule.
B9: 4. Onglet Dépenses : combien tu as dépensé chez chaque fournisseur ce mois-ci.
A11: Les onglets | B11: Produits — ta liste, avec les prix.
B12: Octobre 2026 — la saisie de la semaine + valeur.
B13: Inventaire — comptage complet et valeur totale.
B14: Dépenses — total par fournisseur.
A16: Couleurs | B16: Cases jaunes = à remplir. Cases blanches = calculées toutes seules, ne pas y toucher.
B17: Chiffres en bleu = exemple pour montrer le fonctionnement, à effacer.
B18: Rouge = il manque quelque chose (livraison incomplète, stock trop bas).
A20: Google Sheets | B20: Fichier > Importer > Importer ce fichier. Tout fonctionne pareil, y compris sur téléphone.

Sheet Produits
A1: Mes produits
A2: Une ligne par produit. Tout le reste du fichier se remplit à partir de cette liste.
A4: Produit | B4: Fournisseur | C4: Unité | D4: Prix unitaire (€)
A5: Farine T55 | B5: Metro | C5: kg | D5: 0.9
A6: Farine T45 | B6: Metro | C6: kg | D6: 1.1
A7: Sucre semoule | B7: Metro | C7: kg | D7: 1.2
A8: Sucre glace | B8: Metro | C8: kg | D8: 1.8
A9: Beurre doux | B9: Crèmerie | C9: kg | D9: 8.5
A10: Crème liquide 35% | B10: Crèmerie | C10: L | D10: 4.2
A11: Lait entier | B11: Crèmerie | C11: L | D11: 1.1
A12: Oeufs | B12: Crèmerie | C12: pièce | D12: 0.25
A13: Chocolat blanc | B13: Transgourmet | C13: kg | D13: 14
A14: Chocolat noir 70% | B14: Transgourmet | C14: kg | D14: 13
A15: Levure chimique | B15: Transgourmet | C15: kg | D15: 6
A16: Vanille (gousse) | B16: Transgourmet | C16: pièce | D16: 2.5

Sheet Octobre 2026
A1: Octobre 2026
A2: Valeur = stock × prix unitaire (onglet Produits)
A4: Produit | B4: Fournisseur | C4: Unité | D4: Semaine 1 | H4: Semaine 2 | L4: Semaine 3 | P4: Semaine 4 | T4: Total du mois
D6: Stock | E6: Valeur | F6: Commandé | G6: Reçu | H6: Stock | I6: Valeur | J6: Commandé | K6: Reçu | L6: Stock | M6: Valeur | N6: Commandé | O6: Reçu | P6: Stock | Q6: Valeur | R6: Commandé | S6: Reçu | T6: Reçu | U6: Dépense (€)
A7: =IF(Produits!$A$5="","",Produits!$A$5) | B7: =IF(Produits!$A$5="","",Produits!$B$5) | C7: =IF(Produits!$A$5="","",Produits!$C$5) | D7: 8 | E7: =IF(D7="","",D7*N(Produits!$D$5)) | F7: 10 | G7: 7 | H7: 5 | I7: =IF(H7="","",H7*N(Produits!$D$5)) | J7: 10 | K7: 10 | M7: =IF(L7="","",L7*N(Produits!$D$5)) | Q7: =IF(P7="","",P7*N(Produits!$D$5)) | T7: =IF(COUNT(G7,K7,O7,S7)=0,"",SUM(G7,K7,O7,S7)) | U7: =IF(T7="","",T7*N(Produits!$D$5))
A8: =IF(Produits!$A$6="","",Produits!$A$6) | B8: =IF(Produits!$A$6="","",Produits!$B$6) | C8: =IF(Produits!$A$6="","",Produits!$C$6) | D8: 2 | E8: =IF(D8="","",D8*N(Produits!$D$6)) | F8: 5 | G8: 5 | H8: 3 | I8: =IF(H8="","",H8*N(Produits!$D$6)) | J8: 3 | K8: 3 | M8: =IF(L8="","",L8*N(Produits!$D$6)) | Q8: =IF(P8="","",P8*N(Produits!$D$6)) | T8: =IF(COUNT(G8,K8,O8,S8)=0,"",SUM(G8,K8,O8,S8)) | U8: =IF(T8="","",T8*N(Produits!$D$6))
A9: =IF(Produits!$A$7="","",Produits!$A$7) | B9: =IF(Produits!$A$7="","",Produits!$B$7) | C9: =IF(Produits!$A$7="","",Produits!$C$7) | D9: 6 | E9: =IF(D9="","",D9*N(Produits!$D$7)) | F9: 10 | G9: 10 | H9: 7 | I9: =IF(H9="","",H9*N(Produits!$D$7)) | J9: 5 | K9: 5 | M9: =IF(L9="","",L9*N(Produits!$D$7)) | Q9: =IF(P9="","",P9*N(Produits!$D$7)) | T9: =IF(COUNT(G9,K9,O9,S9)=0,"",SUM(G9,K9,O9,S9)) | U9: =IF(T9="","",T9*N(Produits!$D$7))
A10: =IF(Produits!$A$8="","",Produits!$A$8) | B10: =IF(Produits!$A$8="","",Produits!$B$8) | C10: =IF(Produits!$A$8="","",Produits!$C$8) | D10: 1 | E10: =IF(D10="","",D10*N(Produits!$D$8)) | F10: 3 | G10: 3 | H10: 2 | I10: =IF(H10="","",H10*N(Produits!$D$8)) | J10: 0 | K10: 0 | M10: =IF(L10="","",L10*N(Produits!$D$8)) | Q10: =IF(P10="","",P10*N(Produits!$D$8)) | T10: =IF(COUNT(G10,K10,O10,S10)=0,"",SUM(G10,K10,O10,S10)) | U10: =IF(T10="","",T10*N(Produits!$D$8))
A11: =IF(Produits!$A$9="","",Produits!$A$9) | B11: =IF(Produits!$A$9="","",Produits!$B$9) | C11: =IF(Produits!$A$9="","",Produits!$C$9) | D11: 3 | E11: =IF(D11="","",D11*N(Produits!$D$9)) | F11: 5 | G11: 5 | H11: 4 | I11: =IF(H11="","",H11*N(Produits!$D$9)) | J11: 5 | K11: 5 | M11: =IF(L11="","",L11*N(Produits!$D$9)) | Q11: =IF(P11="","",P11*N(Produits!$D$9)) | T11: =IF(COUNT(G11,K11,O11,S11)=0,"",SUM(G11,K11,O11,S11)) | U11: =IF(T11="","",T11*N(Produits!$D$9))
A12: =IF(Produits!$A$10="","",Produits!$A$10) | B12: =IF(Produits!$A$10="","",Produits!$B$10) | C12: =IF(Produits!$A$10="","",Produits!$C$10) | D12: 4 | E12: =IF(D12="","",D12*N(Produits!$D$10)) | F12: 12 | G12: 12 | H12: 5 | I12: =IF(H12="","",H12*N(Produits!$D$10)) | J12: 10 | K12: 10 | M12: =IF(L12="","",L12*N(Produits!$D$10)) | Q12: =IF(P12="","",P12*N(Produits!$D$10)) | T12: =IF(COUNT(G12,K12,O12,S12)=0,"",SUM(G12,K12,O12,S12)) | U12: =IF(T12="","",T12*N(Produits!$D$10))
A13: =IF(Produits!$A$11="","",Produits!$A$11) | B13: =IF(Produits!$A$11="","",Produits!$B$11) | C13: =IF(Produits!$A$11="","",Produits!$C$11) | D13: 3 | E13: =IF(D13="","",D13*N(Produits!$D$11)) | F13: 6 | G13: 6 | H13: 4 | I13: =IF(H13="","",H13*N(Produits!$D$11)) | J13: 6 | K13: 6 | M13: =IF(L13="","",L13*N(Produits!$D$11)) | Q13: =IF(P13="","",P13*N(Produits!$D$11)) | T13: =IF(COUNT(G13,K13,O13,S13)=0,"",SUM(G13,K13,O13,S13)) | U13: =IF(T13="","",T13*N(Produits!$D$11))
A14: =IF(Produits!$A$12="","",Produits!$A$12) | B14: =IF(Produits!$A$12="","",Produits!$B$12) | C14: =IF(Produits!$A$12="","",Produits!$C$12) | D14: 40 | E14: =IF(D14="","",D14*N(Produits!$D$12)) | F14: 90 | G14: 90 | H14: 50 | I14: =IF(H14="","",H14*N(Produits!$D$12)) | J14: 60 | K14: 60 | M14: =IF(L14="","",L14*N(Produits!$D$12)) | Q14: =IF(P14="","",P14*N(Produits!$D$12)) | T14: =IF(COUNT(G14,K14,O14,S14)=0,"",SUM(G14,K14,O14,S14)) | U14: =IF(T14="","",T14*N(Produits!$D$12))
A15: =IF(Produits!$A$13="","",Produits!$A$13) | B15: =IF(Produits!$A$13="","",Produits!$B$13) | C15: =IF(Produits!$A$13="","",Produits!$C$13) | D15: 1.5 | E15: =IF(D15="","",D15*N(Produits!$D$13)) | F15: 3 | G15: 2 | H15: 2 | I15: =IF(H15="","",H15*N(Produits!$D$13)) | J15: 2 | K15: 2 | M15: =IF(L15="","",L15*N(Produits!$D$13)) | Q15: =IF(P15="","",P15*N(Produits!$D$13)) | T15: =IF(COUNT(G15,K15,O15,S15)=0,"",SUM(G15,K15,O15,S15)) | U15: =IF(T15="","",T15*N(Produits!$D$13))
A16: =IF(Produits!$A$14="","",Produits!$A$14) | B16: =IF(Produits!$A$14="","",Produits!$B$14) | C16: =IF(Produits!$A$14="","",Produits!$C$14) | D16: 2 | E16: =IF(D16="","",D16*N(Produits!$D$14)) | F16: 2 | G16: 2 | H16: 2 | I16: =IF(H16="","",H16*N(Produits!$D$14)) | J16: 2 | K16: 2 | M16: =IF(L16="","",L16*N(Produits!$D$14)) | Q16: =IF(P16="","",P16*N(Produits!$D$14)) | T16: =IF(COUNT(G16,K16,O16,S16)=0,"",SUM(G16,K16,O16,S16)) | U16: =IF(T16="","",T16*N(Produits!$D$14))
A17: =IF(Produits!$A$15="","",Produits!$A$15) | B17: =IF(Produits!$A$15="","",Produits!$B$15) | C17: =IF(Produits!$A$15="","",Produits!$C$15) | D17: 0.4 | E17: =IF(D17="","",D17*N(Produits!$D$15)) | F17: 1 | G17: 1 | H17: 0.6 | I17: =IF(H17="","",H17*N(Produits!$D$15)) | J17: 0 | K17: 0 | M17: =IF(L17="","",L17*N(Produits!$D$15)) | Q17: =IF(P17="","",P17*N(Produits!$D$15)) | T17: =IF(COUNT(G17,K17,O17,S17)=0,"",SUM(G17,K17,O17,S17)) | U17: =IF(T17="","",T17*N(Produits!$D$15))
A18: =IF(Produits!$A$16="","",Produits!$A$16) | B18: =IF(Produits!$A$16="","",Produits!$B$16) | C18: =IF(Produits!$A$16="","",Produits!$C$16) | D18: 6 | E18: =IF(D18="","",D18*N(Produits!$D$16)) | F18: 0 | G18: 0 | H18: 6 | I18: =IF(H18="","",H18*N(Produits!$D$16)) | J18: 0 | K18: 0 | M18: =IF(L18="","",L18*N(Produits!$D$16)) | Q18: =IF(P18="","",P18*N(Produits!$D$16)) | T18: =IF(COUNT(G18,K18,O18,S18)=0,"",SUM(G18,K18,O18,S18)) | U18: =IF(T18="","",T18*N(Produits!$D$16))
A19: =IF(Produits!$A$17="","",Produits!$A$17) | B19: =IF(Produits!$A$17="","",Produits!$B$17) | C19: =IF(Produits!$A$17="","",Produits!$C$17) | E19: =IF(D19="","",D19*N(Produits!$D$17)) | I19: =IF(H19="","",H19*N(Produits!$D$17)) | M19: =IF(L19="","",L19*N(Produits!$D$17)) | Q19: =IF(P19="","",P19*N(Produits!$D$17)) | T19: =IF(COUNT(G19,K19,O19,S19)=0,"",SUM(G19,K19,O19,S19)) | U19: =IF(T19="","",T19*N(Produits!$D$17))
A20: =IF(Produits!$A$18="","",Produits!$A$18) | B20: =IF(Produits!$A$18="","",Produits!$B$18) | C20: =IF(Produits!$A$18="","",Produits!$C$18) | E20: =IF(D20="","",D20*N(Produits!$D$18)) | I20: =IF(H20="","",H20*N(Produits!$D$18)) | M20: =IF(L20="","",L20*N(Produits!$D$18)) | Q20: =IF(P20="","",P20*N(Produits!$D$18)) | T20: =IF(COUNT(G20,K20,O20,S20)=0,"",SUM(G20,K20,O20,S20)) | U20: =IF(T20="","",T20*N(Produits!$D$18))
A21: =IF(Produits!$A$19="","",Produits!$A$19) | B21: =IF(Produits!$A$19="","",Produits!$B$19) | C21: =IF(Produits!$A$19="","",Produits!$C$19) | E21: =IF(D21="","",D21*N(Produits!$D$19)) | I21: =IF(H21="","",H21*N(Produits!$D$19)) | M21: =IF(L21="","",L21*N(Produits!$D$19)) | Q21: =IF(P21="","",P21*N(Produits!$D$19)) | T21: =IF(COUNT(G21,K21,O21,S21)=0,"",SUM(G21,K21,O21,S21)) | U21: =IF(T21="","",T21*N(Produits!$D$19))
A22: =IF(Produits!$A$20="","",Produits!$A$20) | B22: =IF(Produits!$A$20="","",Produits!$B$20) | C22: =IF(Produits!$A$20="","",Produits!$C$20) | E22: =IF(D22="","",D22*N(Produits!$D$20)) | I22: =IF(H22="","",H22*N(Produits!$D$20)) | M22: =IF(L22="","",L22*N(Produits!$D$20)) | Q22: =IF(P22="","",P22*N(Produits!$D$20)) | T22: =IF(COUNT(G22,K22,O22,S22)=0,"",SUM(G22,K22,O22,S22)) | U22: =IF(T22="","",T22*N(Produits!$D$20))
A23: =IF(Produits!$A$21="","",Produits!$A$21) | B23: =IF(Produits!$A$21="","",Produits!$B$21) | C23: =IF(Produits!$A$21="","",Produits!$C$21) | E23: =IF(D23="","",D23*N(Produits!$D$21)) | I23: =IF(H23="","",H23*N(Produits!$D$21)) | M23: =IF(L23="","",L23*N(Produits!$D$21)) | Q23: =IF(P23="","",P23*N(Produits!$D$21)) | T23: =IF(COUNT(G23,K23,O23,S23)=0,"",SUM(G23,K23,O23,S23)) | U23: =IF(T23="","",T23*N(Produits!$D$21))
A24: =IF(Produits!$A$22="","",Produits!$A$22) | B24: =IF(Produits!$A$22="","",Produits!$B$22) | C24: =IF(Produits!$A$22="","",Produits!$C$22) | E24: =IF(D24="","",D24*N(Produits!$D$22)) | I24: =IF(H24="","",H24*N(Produits!$D$22)) | M24: =IF(L24="","",L24*N(Produits!$D$22)) | Q24: =IF(P24="","",P24*N(Produits!$D$22)) | T24: =IF(COUNT(G24,K24,O24,S24)=0,"",SUM(G24,K24,O24,S24)) | U24: =IF(T24="","",T24*N(Produits!$D$22))
A25: =IF(Produits!$A$23="","",Produits!$A$23) | B25: =IF(Produits!$A$23="","",Produits!$B$23) | C25: =IF(Produits!$A$23="","",Produits!$C$23) | E25: =IF(D25="","",D25*N(Produits!$D$23)) | I25: =IF(H25="","",H25*N(Produits!$D$23)) | M25: =IF(L25="","",L25*N(Produits!$D$23)) | Q25: =IF(P25="","",P25*N(Produits!$D$23)) | T25: =IF(COUNT(G25,K25,O25,S25)=0,"",SUM(G25,K25,O25,S25)) | U25: =IF(T25="","",T25*N(Produits!$D$23))
A26: =IF(Produits!$A$24="","",Produits!$A$24) | B26: =IF(Produits!$A$24="","",Produits!$B$24) | C26: =IF(Produits!$A$24="","",Produits!$C$24) | E26: =IF(D26="","",D26*N(Produits!$D$24)) | I26: =IF(H26="","",H26*N(Produits!$D$24)) | M26: =IF(L26="","",L26*N(Produits!$D$24)) | Q26: =IF(P26="","",P26*N(Produits!$D$24)) | T26: =IF(COUNT(G26,K26,O26,S26)=0,"",SUM(G26,K26,O26,S26)) | U26: =IF(T26="","",T26*N(Produits!$D$24))
A27: =IF(Produits!$A$25="","",Produits!$A$25) | B27: =IF(Produits!$A$25="","",Produits!$B$25) | C27: =IF(Produits!$A$25="","",Produits!$C$25) | E27: =IF(D27="","",D27*N(Produits!$D$25)) | I27: =IF(H27="","",H27*N(Produits!$D$25)) | M27: =IF(L27="","",L27*N(Produits!$D$25)) | Q27: =IF(P27="","",P27*N(Produits!$D$25)) | T27: =IF(COUNT(G27,K27,O27,S27)=0,"",SUM(G27,K27,O27,S27)) | U27: =IF(T27="","",T27*N(Produits!$D$25))
A28: =IF(Produits!$A$26="","",Produits!$A$26) | B28: =IF(Produits!$A$26="","",Produits!$B$26) | C28: =IF(Produits!$A$26="","",Produits!$C$26) | E28: =IF(D28="","",D28*N(Produits!$D$26)) | I28: =IF(H28="","",H28*N(Produits!$D$26)) | M28: =IF(L28="","",L28*N(Produits!$D$26)) | Q28: =IF(P28="","",P28*N(Produits!$D$26)) | T28: =IF(COUNT(G28,K28,O28,S28)=0,"",SUM(G28,K28,O28,S28)) | U28: =IF(T28="","",T28*N(Produits!$D$26))
A29: =IF(Produits!$A$27="","",Produits!$A$27) | B29: =IF(Produits!$A$27="","",Produits!$B$27) | C29: =IF(Produits!$A$27="","",Produits!$C$27) | E29: =IF(D29="","",D29*N(Produits!$D$27)) | I29: =IF(H29="","",H29*N(Produits!$D$27)) | M29: =IF(L29="","",L29*N(Produits!$D$27)) | Q29: =IF(P29="","",P29*N(Produits!$D$27)) | T29: =IF(COUNT(G29,K29,O29,S29)=0,"",SUM(G29,K29,O29,S29)) | U29: =IF(T29="","",T29*N(Produits!$D$27))
A30: =IF(Produits!$A$28="","",Produits!$A$28) | B30: =IF(Produits!$A$28="","",Produits!$B$28) | C30: =IF(Produits!$A$28="","",Produits!$C$28) | E30: =IF(D30="","",D30*N(Produits!$D$28)) | I30: =IF(H30="","",H30*N(Produits!$D$28)) | M30: =IF(L30="","",L30*N(Produits!$D$28)) | Q30: =IF(P30="","",P30*N(Produits!$D$28)) | T30: =IF(COUNT(G30,K30,O30,S30)=0,"",SUM(G30,K30,O30,S30)) | U30: =IF(T30="","",T30*N(Produits!$D$28))
A31: =IF(Produits!$A$29="","",Produits!$A$29) | B31: =IF(Produits!$A$29="","",Produits!$B$29) | C31: =IF(Produits!$A$29="","",Produits!$C$29) | E31: =IF(D31="","",D31*N(Produits!$D$29)) | I31: =IF(H31="","",H31*N(Produits!$D$29)) | M31: =IF(L31="","",L31*N(Produits!$D$29)) | Q31: =IF(P31="","",P31*N(Produits!$D$29)) | T31: =IF(COUNT(G31,K31,O31,S31)=0,"",SUM(G31,K31,O31,S31)) | U31: =IF(T31="","",T31*N(Produits!$D$29))
A32: =IF(Produits!$A$30="","",Produits!$A$30) | B32: =IF(Produits!$A$30="","",Produits!$B$30) | C32: =IF(Produits!$A$30="","",Produits!$C$30) | E32: =IF(D32="","",D32*N(Produits!$D$30)) | I32: =IF(H32="","",H32*N(Produits!$D$30)) | M32: =IF(L32="","",L32*N(Produits!$D$30)) | Q32: =IF(P32="","",P32*N(Produits!$D$30)) | T32: =IF(COUNT(G32,K32,O32,S32)=0,"",SUM(G32,K32,O32,S32)) | U32: =IF(T32="","",T32*N(Produits!$D$30))
A33: =IF(Produits!$A$31="","",Produits!$A$31) | B33: =IF(Produits!$A$31="","",Produits!$B$31) | C33: =IF(Produits!$A$31="","",Produits!$C$31) | E33: =IF(D33="","",D33*N(Produits!$D$31)) | I33: =IF(H33="","",H33*N(Produits!$D$31)) | M33: =IF(L33="","",L33*N(Produits!$D$31)) | Q33: =IF(P33="","",P33*N(Produits!$D$31)) | T33: =IF(COUNT(G33,K33,O33,S33)=0,"",SUM(G33,K33,O33,S33)) | U33: =IF(T33="","",T33*N(Produits!$D$31))
A34: =IF(Produits!$A$32="","",Produits!$A$32) | B34: =IF(Produits!$A$32="","",Produits!$B$32) | C34: =IF(Produits!$A$32="","",Produits!$C$32) | E34: =IF(D34="","",D34*N(Produits!$D$32)) | I34: =IF(H34="","",H34*N(Produits!$D$32)) | M34: =IF(L34="","",L34*N(Produits!$D$32)) | Q34: =IF(P34="","",P34*N(Produits!$D$32)) | T34: =IF(COUNT(G34,K34,O34,S34)=0,"",SUM(G34,K34,O34,S34)) | U34: =IF(T34="","",T34*N(Produits!$D$32))
A35: =IF(Produits!$A$33="","",Produits!$A$33) | B35: =IF(Produits!$A$33="","",Produits!$B$33) | C35: =IF(Produits!$A$33="","",Produits!$C$33) | E35: =IF(D35="","",D35*N(Produits!$D$33)) | I35: =IF(H35="","",H35*N(Produits!$D$33)) | M35: =IF(L35="","",L35*N(Produits!$D$33)) | Q35: =IF(P35="","",P35*N(Produits!$D$33)) | T35: =IF(COUNT(G35,K35,O35,S35)=0,"",SUM(G35,K35,O35,S35)) | U35: =IF(T35="","",T35*N(Produits!$D$33))
A36: =IF(Produits!$A$34="","",Produits!$A$34) | B36: =IF(Produits!$A$34="","",Produits!$B$34) | C36: =IF(Produits!$A$34="","",Produits!$C$34) | E36: =IF(D36="","",D36*N(Produits!$D$34)) | I36: =IF(H36="","",H36*N(Produits!$D$34)) | M36: =IF(L36="","",L36*N(Produits!$D$34)) | Q36: =IF(P36="","",P36*N(Produits!$D$34)) | T36: =IF(COUNT(G36,K36,O36,S36)=0,"",SUM(G36,K36,O36,S36)) | U36: =IF(T36="","",T36*N(Produits!$D$34))
A37: =IF(Produits!$A$35="","",Produits!$A$35) | B37: =IF(Produits!$A$35="","",Produits!$B$35) | C37: =IF(Produits!$A$35="","",Produits!$C$35) | E37: =IF(D37="","",D37*N(Produits!$D$35)) | I37: =IF(H37="","",H37*N(Produits!$D$35)) | M37: =IF(L37="","",L37*N(Produits!$D$35)) | Q37: =IF(P37="","",P37*N(Produits!$D$35)) | T37: =IF(COUNT(G37,K37,O37,S37)=0,"",SUM(G37,K37,O37,S37)) | U37: =IF(T37="","",T37*N(Produits!$D$35))
A38: =IF(Produits!$A$36="","",Produits!$A$36) | B38: =IF(Produits!$A$36="","",Produits!$B$36) | C38: =IF(Produits!$A$36="","",Produits!$C$36) | E38: =IF(D38="","",D38*N(Produits!$D$36)) | I38: =IF(H38="","",H38*N(Produits!$D$36)) | M38: =IF(L38="","",L38*N(Produits!$D$36)) | Q38: =IF(P38="","",P38*N(Produits!$D$36)) | T38: =IF(COUNT(G38,K38,O38,S38)=0,"",SUM(G38,K38,O38,S38)) | U38: =IF(T38="","",T38*N(Produits!$D$36))
A39: =IF(Produits!$A$37="","",Produits!$A$37) | B39: =IF(Produits!$A$37="","",Produits!$B$37) | C39: =IF(Produits!$A$37="","",Produits!$C$37) | E39: =IF(D39="","",D39*N(Produits!$D$37)) | I39: =IF(H39="","",H39*N(Produits!$D$37)) | M39: =IF(L39="","",L39*N(Produits!$D$37)) | Q39: =IF(P39="","",P39*N(Produits!$D$37)) | T39: =IF(COUNT(G39,K39,O39,S39)=0,"",SUM(G39,K39,O39,S39)) | U39: =IF(T39="","",T39*N(Produits!$D$37))
A40: =IF(Produits!$A$38="","",Produits!$A$38) | B40: =IF(Produits!$A$38="","",Produits!$B$38) | C40: =IF(Produits!$A$38="","",Produits!$C$38) | E40: =IF(D40="","",D40*N(Produits!$D$38)) | I40: =IF(H40="","",H40*N(Produits!$D$38)) | M40: =IF(L40="","",L40*N(Produits!$D$38)) | Q40: =IF(P40="","",P40*N(Produits!$D$38)) | T40: =IF(COUNT(G40,K40,O40,S40)=0,"",SUM(G40,K40,O40,S40)) | U40: =IF(T40="","",T40*N(Produits!$D$38))
A41: =IF(Produits!$A$39="","",Produits!$A$39) | B41: =IF(Produits!$A$39="","",Produits!$B$39) | C41: =IF(Produits!$A$39="","",Produits!$C$39) | E41: =IF(D41="","",D41*N(Produits!$D$39)) | I41: =IF(H41="","",H41*N(Produits!$D$39)) | M41: =IF(L41="","",L41*N(Produits!$D$39)) | Q41: =IF(P41="","",P41*N(Produits!$D$39)) | T41: =IF(COUNT(G41,K41,O41,S41)=0,"",SUM(G41,K41,O41,S41)) | U41: =IF(T41="","",T41*N(Produits!$D$39))
A42: =IF(Produits!$A$40="","",Produits!$A$40) | B42: =IF(Produits!$A$40="","",Produits!$B$40) | C42: =IF(Produits!$A$40="","",Produits!$C$40) | E42: =IF(D42="","",D42*N(Produits!$D$40)) | I42: =IF(H42="","",H42*N(Produits!$D$40)) | M42: =IF(L42="","",L42*N(Produits!$D$40)) | Q42: =IF(P42="","",P42*N(Produits!$D$40)) | T42: =IF(COUNT(G42,K42,O42,S42)=0,"",SUM(G42,K42,O42,S42)) | U42: =IF(T42="","",T42*N(Produits!$D$40))
...

Sheet Inventaire
A1: Inventaire
A2: Le jour de l'inventaire : compte tout, tape les quantités, la valeur se calcule.
A3: Date de l'inventaire : | B3: =DATE(2026,12,31)
A5: Produit | B5: Unité | C5: Quantité comptée | D5: Prix unitaire | E5: Valeur
A6: =IF(Produits!$A$5="","",Produits!$A$5) | B6: =IF(Produits!$A$5="","",Produits!$C$5) | D6: =IF(A6="","",N(Produits!D5)) | E6: =IF(C6="","",C6*N(D6))
A7: =IF(Produits!$A$6="","",Produits!$A$6) | B7: =IF(Produits!$A$6="","",Produits!$C$6) | D7: =IF(A7="","",N(Produits!D6)) | E7: =IF(C7="","",C7*N(D7))
A8: =IF(Produits!$A$7="","",Produits!$A$7) | B8: =IF(Produits!$A$7="","",Produits!$C$7) | D8: =IF(A8="","",N(Produits!D7)) | E8: =IF(C8="","",C8*N(D8))
A9: =IF(Produits!$A$8="","",Produits!$A$8) | B9: =IF(Produits!$A$8="","",Produits!$C$8) | D9: =IF(A9="","",N(Produits!D8)) | E9: =IF(C9="","",C9*N(D9))
A10: =IF(Produits!$A$9="","",Produits!$A$9) | B10: =IF(Produits!$A$9="","",Produits!$C$9) | D10: =IF(A10="","",N(Produits!D9)) | E10: =IF(C10="","",C10*N(D10))
A11: =IF(Produits!$A$10="","",Produits!$A$10) | B11: =IF(Produits!$A$10="","",Produits!$C$10) | D11: =IF(A11="","",N(Produits!D10)) | E11: =IF(C11="","",C11*N(D11))
A12: =IF(Produits!$A$11="","",Produits!$A$11) | B12: =IF(Produits!$A$11="","",Produits!$C$11) | D12: =IF(A12="","",N(Produits!D11)) | E12: =IF(C12="","",C12*N(D12))
A13: =IF(Produits!$A$12="","",Produits!$A$12) | B13: =IF(Produits!$A$12="","",Produits!$C$12) | D13: =IF(A13="","",N(Produits!D12)) | E13: =IF(C13="","",C13*N(D13))
A14: =IF(Produits!$A$13="","",Produits!$A$13) | B14: =IF(Produits!$A$13="","",Produits!$C$13) | D14: =IF(A14="","",N(Produits!D13)) | E14: =IF(C14="","",C14*N(D14))
A15: =IF(Produits!$A$14="","",Produits!$A$14) | B15: =IF(Produits!$A$14="","",Produits!$C$14) | D15: =IF(A15="","",N(Produits!D14)) | E15: =IF(C15="","",C15*N(D15))
A16: =IF(Produits!$A$15="","",Produits!$A$15) | B16: =IF(Produits!$A$15="","",Produits!$C$15) | D16: =IF(A16="","",N(Produits!D15)) | E16: =IF(C16="","",C16*N(D16))
A17: =IF(Produits!$A$16="","",Produits!$A$16) | B17: =IF(Produits!$A$16="","",Produits!$C$16) | D17: =IF(A17="","",N(Produits!D16)) | E17: =IF(C17="","",C17*N(D17))
A18: =IF(Produits!$A$17="","",Produits!$A$17) | B18: =IF(Produits!$A$17="","",Produits!$C$17) | D18: =IF(A18="","",N(Produits!D17)) | E18: =IF(C18="","",C18*N(D18))
A19: =IF(Produits!$A$18="","",Produits!$A$18) | B19: =IF(Produits!$A$18="","",Produits!$C$18) | D19: =IF(A19="","",N(Produits!D18)) | E19: =IF(C19="","",C19*N(D19))
A20: =IF(Produits!$A$19="","",Produits!$A$19) | B20: =IF(Produits!$A$19="","",Produits!$C$19) | D20: =IF(A20="","",N(Produits!D19)) | E20: =IF(C20="","",C20*N(D20))
A21: =IF(Produits!$A$20="","",Produits!$A$20) | B21: =IF(Produits!$A$20="","",Produits!$C$20) | D21: =IF(A21="","",N(Produits!D20)) | E21: =IF(C21="","",C21*N(D21))
A22: =IF(Produits!$A$21="","",Produits!$A$21) | B22: =IF(Produits!$A$21="","",Produits!$C$21) | D22: =IF(A22="","",N(Produits!D21)) | E22: =IF(C22="","",C22*N(D22))
A23: =IF(Produits!$A$22="","",Produits!$A$22) | B23: =IF(Produits!$A$22="","",Produits!$C$22) | D23: =IF(A23="","",N(Produits!D22)) | E23: =IF(C23="","",C23*N(D23))
A24: =IF(Produits!$A$23="","",Produits!$A$23) | B24: =IF(Produits!$A$23="","",Produits!$C$23) | D24: =IF(A24="","",N(Produits!D23)) | E24: =IF(C24="","",C24*N(D24))
A25: =IF(Produits!$A$24="","",Produits!$A$24) | B25: =IF(Produits!$A$24="","",Produits!$C$24) | D25: =IF(A25="","",N(Produits!D24)) | E25: =IF(C25="","",C25*N(D25))
A26: =IF(Produits!$A$25="","",Produits!$A$25) | B26: =IF(Produits!$A$25="","",Produits!$C$25) | D26: =IF(A26="","",N(Produits!D25)) | E26: =IF(C26="","",C26*N(D26))
A27: =IF(Produits!$A$26="","",Produits!$A$26) | B27: =IF(Produits!$A$26="","",Produits!$C$26) | D27: =IF(A27="","",N(Produits!D26)) | E27: =IF(C27="","",C27*N(D27))
A28: =IF(Produits!$A$27="","",Produits!$A$27) | B28: =IF(Produits!$A$27="","",Produits!$C$27) | D28: =IF(A28="","",N(Produits!D27)) | E28: =IF(C28="","",C28*N(D28))
A29: =IF(Produits!$A$28="","",Produits!$A$28) | B29: =IF(Produits!$A$28="","",Produits!$C$28) | D29: =IF(A29="","",N(Produits!D28)) | E29: =IF(C29="","",C29*N(D29))
A30: =IF(Produits!$A$29="","",Produits!$A$29) | B30: =IF(Produits!$A$29="","",Produits!$C$29) | D30: =IF(A30="","",N(Produits!D29)) | E30: =IF(C30="","",C30*N(D30))
A31: =IF(Produits!$A$30="","",Produits!$A$30) | B31: =IF(Produits!$A$30="","",Produits!$C$30) | D31: =IF(A31="","",N(Produits!D30)) | E31: =IF(C31="","",C31*N(D31))
A32: =IF(Produits!$A$31="","",Produits!$A$31) | B32: =IF(Produits!$A$31="","",Produits!$C$31) | D32: =IF(A32="","",N(Produits!D31)) | E32: =IF(C32="","",C32*N(D32))
A33: =IF(Produits!$A$32="","",Produits!$A$32) | B33: =IF(Produits!$A$32="","",Produits!$C$32) | D33: =IF(A33="","",N(Produits!D32)) | E33: =IF(C33="","",C33*N(D33))
A34: =IF(Produits!$A$33="","",Produits!$A$33) | B34: =IF(Produits!$A$33="","",Produits!$C$33) | D34: =IF(A34="","",N(Produits!D33)) | E34: =IF(C34="","",C34*N(D34))
A35: =IF(Produits!$A$34="","",Produits!$A$34) | B35: =IF(Produits!$A$34="","",Produits!$C$34) | D35: =IF(A35="","",N(Produits!D34)) | E35: =IF(C35="","",C35*N(D35))
A36: =IF(Produits!$A$35="","",Produits!$A$35) | B36: =IF(Produits!$A$35="","",Produits!$C$35) | D36: =IF(A36="","",N(Produits!D35)) | E36: =IF(C36="","",C36*N(D36))
A37: =IF(Produits!$A$36="","",Produits!$A$36) | B37: =IF(Produits!$A$36="","",Produits!$C$36) | D37: =IF(A37="","",N(Produits!D36)) | E37: =IF(C37="","",C37*N(D37))
A38: =IF(Produits!$A$37="","",Produits!$A$37) | B38: =IF(Produits!$A$37="","",Produits!$C$37) | D38: =IF(A38="","",N(Produits!D37)) | E38: =IF(C38="","",C38*N(D38))
A39: =IF(Produits!$A$38="","",Produits!$A$38) | B39: =IF(Produits!$A$38="","",Produits!$C$38) | D39: =IF(A39="","",N(Produits!D38)) | E39: =IF(C39="","",C39*N(D39))
A40: =IF(Produits!$A$39="","",Produits!$A$39) | B40: =IF(Produits!$A$39="","",Produits!$C$39) | D40: =IF(A40="","",N(Produits!D39)) | E40: =IF(C40="","",C40*N(D40))
A41: =IF(Produits!$A$40="","",Produits!$A$40) | B41: =IF(Produits!$A$40="","",Produits!$C$40) | D41: =IF(A41="","",N(Produits!D40)) | E41: =IF(C41="","",C41*N(D41))
...

Sheet Dépenses
A1: Dépenses par fournisseur — Octobre 2026
A2: Quantités reçues × prix unitaire
A4: Fournisseur | B4: Dépensé ce mois-ci
A5: Metro | B5: =IF(A5="","",SUMIF('Octobre 2026'!$B$7:$B$46,A5,'Octobre 2026'!$U$7:$U$46))
A6: Crèmerie | B6: =IF(A6="","",SUMIF('Octobre 2026'!$B$7:$B$46,A6,'Octobre 2026'!$U$7:$U$46))
A7: Transgourmet | B7: =IF(A7="","",SUMIF('Octobre 2026'!$B$7:$B$46,A7,'Octobre 2026'!$U$7:$U$46))
B8: =IF(A8="","",SUMIF('Octobre 2026'!$B$7:$B$46,A8,'Octobre 2026'!$U$7:$U$46))
B9: =IF(A9="","",SUMIF('Octobre 2026'!$B$7:$B$46,A9,'Octobre 2026'!$U$7:$U$46))
B10: =IF(A10="","",SUMIF('Octobre 2026'!$B$7:$B$46,A10,'Octobre 2026'!$U$7:$U$46))
A11: Total | B11: =SUM(B5:B10)
