Workbook

Sheet Mode d'emploi
A1: 10 · Le carnet vertical (téléphone)
A2: Proposition de tableau de gestion des stocks — Excel et Google Sheets
A4: L'idée | B4: Pensé pour le téléphone : pas de défilement de côté. Les 4 semaines sont les unes sous les autres, avec seulement 5 colonnes et une grande écriture. Le bilan du mois est tout en bas.
A6: Comment faire | B6: 1. Remplis l'onglet Produits une seule fois.
B7: 2. Fais défiler jusqu'à la semaine en cours : Stock, Commandé, Reçu.
B8: 3. Le bilan du mois en bas de page se calcule tout seul.
B9: 4. Nouveau mois : duplique l'onglet du mois.
A11: Les onglets | B11: Produits — ta liste.
B12: Octobre 2026 — les 4 semaines empilées + le bilan.
A14: Couleurs | B14: Cases jaunes = à remplir. Cases blanches = calculées toutes seules, ne pas y toucher.
B15: Chiffres en bleu = exemple pour montrer le fonctionnement, à effacer.
B16: Rouge = il manque quelque chose (livraison incomplète, stock trop bas).
A18: Google Sheets | B18: Fichier > Importer > Importer ce fichier. Tout fonctionne pareil, y compris sur téléphone.

Sheet Produits
A1: Mes produits
A2: Une ligne par produit. Tout le reste du fichier se remplit à partir de cette liste.
A4: Produit | B4: Fournisseur | C4: Unité
A5: Farine T55 | B5: Metro | C5: kg
A6: Farine T45 | B6: Metro | C6: kg
A7: Sucre semoule | B7: Metro | C7: kg
A8: Sucre glace | B8: Metro | C8: kg
A9: Beurre doux | B9: Crèmerie | C9: kg
A10: Crème liquide 35% | B10: Crèmerie | C10: L
A11: Lait entier | B11: Crèmerie | C11: L
A12: Oeufs | B12: Crèmerie | C12: pièce
A13: Chocolat blanc | B13: Transgourmet | C13: kg
A14: Chocolat noir 70% | B14: Transgourmet | C14: kg
A15: Levure chimique | B15: Transgourmet | C15: kg
A16: Vanille (gousse) | B16: Transgourmet | C16: pièce

Sheet Octobre 2026
A1: Octobre 2026
A2: Fais défiler vers le bas pour les semaines suivantes
A4: SEMAINE 1
A5: Produit | B5: Stock | C5: Commandé | D5: Reçu | E5: Écart
A6: =IF(Produits!$A$5="","",Produits!$A$5&" ("&Produits!$C$5&")") | B6: 8 | C6: 10 | D6: 7 | E6: =IF(OR(C6="",D6=""),"",D6-C6)
A7: =IF(Produits!$A$6="","",Produits!$A$6&" ("&Produits!$C$6&")") | B7: 2 | C7: 5 | D7: 5 | E7: =IF(OR(C7="",D7=""),"",D7-C7)
A8: =IF(Produits!$A$7="","",Produits!$A$7&" ("&Produits!$C$7&")") | B8: 6 | C8: 10 | D8: 10 | E8: =IF(OR(C8="",D8=""),"",D8-C8)
A9: =IF(Produits!$A$8="","",Produits!$A$8&" ("&Produits!$C$8&")") | B9: 1 | C9: 3 | D9: 3 | E9: =IF(OR(C9="",D9=""),"",D9-C9)
A10: =IF(Produits!$A$9="","",Produits!$A$9&" ("&Produits!$C$9&")") | B10: 3 | C10: 5 | D10: 5 | E10: =IF(OR(C10="",D10=""),"",D10-C10)
A11: =IF(Produits!$A$10="","",Produits!$A$10&" ("&Produits!$C$10&")") | B11: 4 | C11: 12 | D11: 12 | E11: =IF(OR(C11="",D11=""),"",D11-C11)
A12: =IF(Produits!$A$11="","",Produits!$A$11&" ("&Produits!$C$11&")") | B12: 3 | C12: 6 | D12: 6 | E12: =IF(OR(C12="",D12=""),"",D12-C12)
A13: =IF(Produits!$A$12="","",Produits!$A$12&" ("&Produits!$C$12&")") | B13: 40 | C13: 90 | D13: 90 | E13: =IF(OR(C13="",D13=""),"",D13-C13)
A14: =IF(Produits!$A$13="","",Produits!$A$13&" ("&Produits!$C$13&")") | B14: 1.5 | C14: 3 | D14: 2 | E14: =IF(OR(C14="",D14=""),"",D14-C14)
A15: =IF(Produits!$A$14="","",Produits!$A$14&" ("&Produits!$C$14&")") | B15: 2 | C15: 2 | D15: 2 | E15: =IF(OR(C15="",D15=""),"",D15-C15)
A16: =IF(Produits!$A$15="","",Produits!$A$15&" ("&Produits!$C$15&")") | B16: 0.4 | C16: 1 | D16: 1 | E16: =IF(OR(C16="",D16=""),"",D16-C16)
A17: =IF(Produits!$A$16="","",Produits!$A$16&" ("&Produits!$C$16&")") | B17: 6 | C17: 0 | D17: 0 | E17: =IF(OR(C17="",D17=""),"",D17-C17)
A18: =IF(Produits!$A$17="","",Produits!$A$17&" ("&Produits!$C$17&")") | E18: =IF(OR(C18="",D18=""),"",D18-C18)
A19: =IF(Produits!$A$18="","",Produits!$A$18&" ("&Produits!$C$18&")") | E19: =IF(OR(C19="",D19=""),"",D19-C19)
A20: =IF(Produits!$A$19="","",Produits!$A$19&" ("&Produits!$C$19&")") | E20: =IF(OR(C20="",D20=""),"",D20-C20)
A21: =IF(Produits!$A$20="","",Produits!$A$20&" ("&Produits!$C$20&")") | E21: =IF(OR(C21="",D21=""),"",D21-C21)
A22: =IF(Produits!$A$21="","",Produits!$A$21&" ("&Produits!$C$21&")") | E22: =IF(OR(C22="",D22=""),"",D22-C22)
A23: =IF(Produits!$A$22="","",Produits!$A$22&" ("&Produits!$C$22&")") | E23: =IF(OR(C23="",D23=""),"",D23-C23)
A24: =IF(Produits!$A$23="","",Produits!$A$23&" ("&Produits!$C$23&")") | E24: =IF(OR(C24="",D24=""),"",D24-C24)
A25: =IF(Produits!$A$24="","",Produits!$A$24&" ("&Produits!$C$24&")") | E25: =IF(OR(C25="",D25=""),"",D25-C25)
A26: =IF(Produits!$A$25="","",Produits!$A$25&" ("&Produits!$C$25&")") | E26: =IF(OR(C26="",D26=""),"",D26-C26)
A27: =IF(Produits!$A$26="","",Produits!$A$26&" ("&Produits!$C$26&")") | E27: =IF(OR(C27="",D27=""),"",D27-C27)
A28: =IF(Produits!$A$27="","",Produits!$A$27&" ("&Produits!$C$27&")") | E28: =IF(OR(C28="",D28=""),"",D28-C28)
A29: =IF(Produits!$A$28="","",Produits!$A$28&" ("&Produits!$C$28&")") | E29: =IF(OR(C29="",D29=""),"",D29-C29)
A30: =IF(Produits!$A$29="","",Produits!$A$29&" ("&Produits!$C$29&")") | E30: =IF(OR(C30="",D30=""),"",D30-C30)
A31: =IF(Produits!$A$30="","",Produits!$A$30&" ("&Produits!$C$30&")") | E31: =IF(OR(C31="",D31=""),"",D31-C31)
A32: =IF(Produits!$A$31="","",Produits!$A$31&" ("&Produits!$C$31&")") | E32: =IF(OR(C32="",D32=""),"",D32-C32)
A33: =IF(Produits!$A$32="","",Produits!$A$32&" ("&Produits!$C$32&")") | E33: =IF(OR(C33="",D33=""),"",D33-C33)
A34: =IF(Produits!$A$33="","",Produits!$A$33&" ("&Produits!$C$33&")") | E34: =IF(OR(C34="",D34=""),"",D34-C34)
A35: =IF(Produits!$A$34="","",Produits!$A$34&" ("&Produits!$C$34&")") | E35: =IF(OR(C35="",D35=""),"",D35-C35)
A36: =IF(Produits!$A$35="","",Produits!$A$35&" ("&Produits!$C$35&")") | E36: =IF(OR(C36="",D36=""),"",D36-C36)
A37: =IF(Produits!$A$36="","",Produits!$A$36&" ("&Produits!$C$36&")") | E37: =IF(OR(C37="",D37=""),"",D37-C37)
A38: =IF(Produits!$A$37="","",Produits!$A$37&" ("&Produits!$C$37&")") | E38: =IF(OR(C38="",D38=""),"",D38-C38)
A39: =IF(Produits!$A$38="","",Produits!$A$38&" ("&Produits!$C$38&")") | E39: =IF(OR(C39="",D39=""),"",D39-C39)
A40: =IF(Produits!$A$39="","",Produits!$A$39&" ("&Produits!$C$39&")") | E40: =IF(OR(C40="",D40=""),"",D40-C40)
A41: =IF(Produits!$A$40="","",Produits!$A$40&" ("&Produits!$C$40&")") | E41: =IF(OR(C41="",D41=""),"",D41-C41)
...
