Workbook

Sheet Mode d'emploi
A1: 13 · La liste à cocher
A2: Proposition de tableau de gestion des stocks — Excel et Google Sheets
A4: L'idée | B4: Une page par semaine, comme une liste de courses. Le vendredi tu remplis ton stock et ce que tu commandes, puis tu coches « Commandé ». Le lundi, tu coches « Reçu » ligne par ligne en vérifiant les cartons : la ligne se barre et devient grise. Ce qui reste non barré n'est pas arrivé.
A6: Comment faire | B6: 1. Remplis l'onglet Produits une seule fois.
B7: 2. Vendredi : Stock, Quantité à commander, puis choisis ✓ dans « Commandé ? ».
B8: 3. Lundi : pour chaque produit livré, tape la quantité reçue et choisis ✓ dans « Reçu ? ».
B9: 4. Rouge = reçu moins que commandé. Le récap du mois additionne les 4 semaines.
A11: Les onglets | B11: Produits — ta liste.
B12: Semaine 1 à 4 — une liste à cocher par semaine.
B13: Récap du mois — les totaux.
A15: Couleurs | B15: Cases jaunes = à remplir. Cases blanches = calculées toutes seules, ne pas y toucher.
B16: Chiffres en bleu = exemple pour montrer le fonctionnement, à effacer.
B17: Rouge = il manque quelque chose (livraison incomplète, stock trop bas).
A19: Google Sheets | B19: Fichier > Importer > Importer ce fichier. Tout fonctionne pareil, y compris sur téléphone.

Sheet Produits
A1: Mes produits
A2: Une ligne par produit. Tout le reste du fichier se remplit à partir de cette liste.
A4: Produit | B4: Fournisseur | C4: Unité
A5: Farine T55 | B5: Metro | C5: kg
A6: Farine T45 | B6: Metro | C6: kg
A7: Sucre semoule | B7: Metro | C7: kg
A8: Sucre glace | B8: Metro | C8: kg
A9: Beurre doux | B9: Crèmerie | C9: kg
A10: Crème liquide 35% | B10: Crèmerie | C10: L
A11: Lait entier | B11: Crèmerie | C11: L
A12: Oeufs | B12: Crèmerie | C12: pièce
A13: Chocolat blanc | B13: Transgourmet | C13: kg
A14: Chocolat noir 70% | B14: Transgourmet | C14: kg
A15: Levure chimique | B15: Transgourmet | C15: kg
A16: Vanille (gousse) | B16: Transgourmet | C16: pièce

Sheet Semaine 1
A1: Semaine 1
A2: Coche ✓ au fur et à mesure — la ligne se barre quand c'est reçu
A4: Produit | B4: Fournisseur | C4: Unité | D4: Stock | E4: À commander | F4: Commandé ? | G4: Reçu | H4: Reçu ? | I4: Écart
A5: =IF(Produits!$A$5="","",Produits!$A$5) | B5: =IF(Produits!$A$5="","",Produits!$B$5) | C5: =IF(Produits!$A$5="","",Produits!$C$5) | D5: 8 | E5: 10 | F5: ✓ | G5: 7 | H5: ✓ | I5: =IF(OR(E5="",G5=""),"",G5-E5)
A6: =IF(Produits!$A$6="","",Produits!$A$6) | B6: =IF(Produits!$A$6="","",Produits!$B$6) | C6: =IF(Produits!$A$6="","",Produits!$C$6) | D6: 2 | E6: 5 | F6: ✓ | G6: 5 | H6: ✓ | I6: =IF(OR(E6="",G6=""),"",G6-E6)
A7: =IF(Produits!$A$7="","",Produits!$A$7) | B7: =IF(Produits!$A$7="","",Produits!$B$7) | C7: =IF(Produits!$A$7="","",Produits!$C$7) | D7: 6 | E7: 10 | F7: ✓ | G7: 10 | H7: ✓ | I7: =IF(OR(E7="",G7=""),"",G7-E7)
A8: =IF(Produits!$A$8="","",Produits!$A$8) | B8: =IF(Produits!$A$8="","",Produits!$B$8) | C8: =IF(Produits!$A$8="","",Produits!$C$8) | D8: 1 | E8: 3 | F8: ✓ | G8: 3 | H8: ✓ | I8: =IF(OR(E8="",G8=""),"",G8-E8)
A9: =IF(Produits!$A$9="","",Produits!$A$9) | B9: =IF(Produits!$A$9="","",Produits!$B$9) | C9: =IF(Produits!$A$9="","",Produits!$C$9) | D9: 3 | E9: 5 | F9: ✓ | G9: 5 | H9: ✓ | I9: =IF(OR(E9="",G9=""),"",G9-E9)
A10: =IF(Produits!$A$10="","",Produits!$A$10) | B10: =IF(Produits!$A$10="","",Produits!$B$10) | C10: =IF(Produits!$A$10="","",Produits!$C$10) | D10: 4 | E10: 12 | F10: ✓ | G10: 12 | H10: ✓ | I10: =IF(OR(E10="",G10=""),"",G10-E10)
A11: =IF(Produits!$A$11="","",Produits!$A$11) | B11: =IF(Produits!$A$11="","",Produits!$B$11) | C11: =IF(Produits!$A$11="","",Produits!$C$11) | D11: 3 | E11: 6 | F11: ✓ | G11: 6 | H11: ✓ | I11: =IF(OR(E11="",G11=""),"",G11-E11)
A12: =IF(Produits!$A$12="","",Produits!$A$12) | B12: =IF(Produits!$A$12="","",Produits!$B$12) | C12: =IF(Produits!$A$12="","",Produits!$C$12) | D12: 40 | E12: 90 | F12: ✓ | G12: 90 | I12: =IF(OR(E12="",G12=""),"",G12-E12)
A13: =IF(Produits!$A$13="","",Produits!$A$13) | B13: =IF(Produits!$A$13="","",Produits!$B$13) | C13: =IF(Produits!$A$13="","",Produits!$C$13) | D13: 1.5 | E13: 3 | F13: ✓ | G13: 2 | I13: =IF(OR(E13="",G13=""),"",G13-E13)
A14: =IF(Produits!$A$14="","",Produits!$A$14) | B14: =IF(Produits!$A$14="","",Produits!$B$14) | C14: =IF(Produits!$A$14="","",Produits!$C$14) | D14: 2 | E14: 2 | F14: ✓ | G14: 2 | I14: =IF(OR(E14="",G14=""),"",G14-E14)
A15: =IF(Produits!$A$15="","",Produits!$A$15) | B15: =IF(Produits!$A$15="","",Produits!$B$15) | C15: =IF(Produits!$A$15="","",Produits!$C$15) | D15: 0.4 | E15: 1 | F15: ✓ | G15: 1 | I15: =IF(OR(E15="",G15=""),"",G15-E15)
A16: =IF(Produits!$A$16="","",Produits!$A$16) | B16: =IF(Produits!$A$16="","",Produits!$B$16) | C16: =IF(Produits!$A$16="","",Produits!$C$16) | D16: 6 | E16: 0 | G16: 0 | I16: =IF(OR(E16="",G16=""),"",G16-E16)
A17: =IF(Produits!$A$17="","",Produits!$A$17) | B17: =IF(Produits!$A$17="","",Produits!$B$17) | C17: =IF(Produits!$A$17="","",Produits!$C$17) | I17: =IF(OR(E17="",G17=""),"",G17-E17)
A18: =IF(Produits!$A$18="","",Produits!$A$18) | B18: =IF(Produits!$A$18="","",Produits!$B$18) | C18: =IF(Produits!$A$18="","",Produits!$C$18) | I18: =IF(OR(E18="",G18=""),"",G18-E18)
A19: =IF(Produits!$A$19="","",Produits!$A$19) | B19: =IF(Produits!$A$19="","",Produits!$B$19) | C19: =IF(Produits!$A$19="","",Produits!$C$19) | I19: =IF(OR(E19="",G19=""),"",G19-E19)
A20: =IF(Produits!$A$20="","",Produits!$A$20) | B20: =IF(Produits!$A$20="","",Produits!$B$20) | C20: =IF(Produits!$A$20="","",Produits!$C$20) | I20: =IF(OR(E20="",G20=""),"",G20-E20)
A21: =IF(Produits!$A$21="","",Produits!$A$21) | B21: =IF(Produits!$A$21="","",Produits!$B$21) | C21: =IF(Produits!$A$21="","",Produits!$C$21) | I21: =IF(OR(E21="",G21=""),"",G21-E21)
A22: =IF(Produits!$A$22="","",Produits!$A$22) | B22: =IF(Produits!$A$22="","",Produits!$B$22) | C22: =IF(Produits!$A$22="","",Produits!$C$22) | I22: =IF(OR(E22="",G22=""),"",G22-E22)
A23: =IF(Produits!$A$23="","",Produits!$A$23) | B23: =IF(Produits!$A$23="","",Produits!$B$23) | C23: =IF(Produits!$A$23="","",Produits!$C$23) | I23: =IF(OR(E23="",G23=""),"",G23-E23)
A24: =IF(Produits!$A$24="","",Produits!$A$24) | B24: =IF(Produits!$A$24="","",Produits!$B$24) | C24: =IF(Produits!$A$24="","",Produits!$C$24) | I24: =IF(OR(E24="",G24=""),"",G24-E24)
A25: =IF(Produits!$A$25="","",Produits!$A$25) | B25: =IF(Produits!$A$25="","",Produits!$B$25) | C25: =IF(Produits!$A$25="","",Produits!$C$25) | I25: =IF(OR(E25="",G25=""),"",G25-E25)
A26: =IF(Produits!$A$26="","",Produits!$A$26) | B26: =IF(Produits!$A$26="","",Produits!$B$26) | C26: =IF(Produits!$A$26="","",Produits!$C$26) | I26: =IF(OR(E26="",G26=""),"",G26-E26)
A27: =IF(Produits!$A$27="","",Produits!$A$27) | B27: =IF(Produits!$A$27="","",Produits!$B$27) | C27: =IF(Produits!$A$27="","",Produits!$C$27) | I27: =IF(OR(E27="",G27=""),"",G27-E27)
A28: =IF(Produits!$A$28="","",Produits!$A$28) | B28: =IF(Produits!$A$28="","",Produits!$B$28) | C28: =IF(Produits!$A$28="","",Produits!$C$28) | I28: =IF(OR(E28="",G28=""),"",G28-E28)
A29: =IF(Produits!$A$29="","",Produits!$A$29) | B29: =IF(Produits!$A$29="","",Produits!$B$29) | C29: =IF(Produits!$A$29="","",Produits!$C$29) | I29: =IF(OR(E29="",G29=""),"",G29-E29)
A30: =IF(Produits!$A$30="","",Produits!$A$30) | B30: =IF(Produits!$A$30="","",Produits!$B$30) | C30: =IF(Produits!$A$30="","",Produits!$C$30) | I30: =IF(OR(E30="",G30=""),"",G30-E30)
A31: =IF(Produits!$A$31="","",Produits!$A$31) | B31: =IF(Produits!$A$31="","",Produits!$B$31) | C31: =IF(Produits!$A$31="","",Produits!$C$31) | I31: =IF(OR(E31="",G31=""),"",G31-E31)
A32: =IF(Produits!$A$32="","",Produits!$A$32) | B32: =IF(Produits!$A$32="","",Produits!$B$32) | C32: =IF(Produits!$A$32="","",Produits!$C$32) | I32: =IF(OR(E32="",G32=""),"",G32-E32)
A33: =IF(Produits!$A$33="","",Produits!$A$33) | B33: =IF(Produits!$A$33="","",Produits!$B$33) | C33: =IF(Produits!$A$33="","",Produits!$C$33) | I33: =IF(OR(E33="",G33=""),"",G33-E33)
A34: =IF(Produits!$A$34="","",Produits!$A$34) | B34: =IF(Produits!$A$34="","",Produits!$B$34) | C34: =IF(Produits!$A$34="","",Produits!$C$34) | I34: =IF(OR(E34="",G34=""),"",G34-E34)
A35: =IF(Produits!$A$35="","",Produits!$A$35) | B35: =IF(Produits!$A$35="","",Produits!$B$35) | C35: =IF(Produits!$A$35="","",Produits!$C$35) | I35: =IF(OR(E35="",G35=""),"",G35-E35)
A36: =IF(Produits!$A$36="","",Produits!$A$36) | B36: =IF(Produits!$A$36="","",Produits!$B$36) | C36: =IF(Produits!$A$36="","",Produits!$C$36) | I36: =IF(OR(E36="",G36=""),"",G36-E36)
A37: =IF(Produits!$A$37="","",Produits!$A$37) | B37: =IF(Produits!$A$37="","",Produits!$B$37) | C37: =IF(Produits!$A$37="","",Produits!$C$37) | I37: =IF(OR(E37="",G37=""),"",G37-E37)
A38: =IF(Produits!$A$38="","",Produits!$A$38) | B38: =IF(Produits!$A$38="","",Produits!$B$38) | C38: =IF(Produits!$A$38="","",Produits!$C$38) | I38: =IF(OR(E38="",G38=""),"",G38-E38)
A39: =IF(Produits!$A$39="","",Produits!$A$39) | B39: =IF(Produits!$A$39="","",Produits!$B$39) | C39: =IF(Produits!$A$39="","",Produits!$C$39) | I39: =IF(OR(E39="",G39=""),"",G39-E39)
A40: =IF(Produits!$A$40="","",Produits!$A$40) | B40: =IF(Produits!$A$40="","",Produits!$B$40) | C40: =IF(Produits!$A$40="","",Produits!$C$40) | I40: =IF(OR(E40="",G40=""),"",G40-E40)
A41: =IF(Produits!$A$41="","",Produits!$A$41) | B41: =IF(Produits!$A$41="","",Produits!$B$41) | C41: =IF(Produits!$A$41="","",Produits!$C$41) | I41: =IF(OR(E41="",G41=""),"",G41-E41)
...

Sheet Semaine 2
A1: Semaine 2
A2: Coche ✓ au fur et à mesure — la ligne se barre quand c'est reçu
A4: Produit | B4: Fournisseur | C4: Unité | D4: Stock | E4: À commander | F4: Commandé ? | G4: Reçu | H4: Reçu ? | I4: Écart
A5: =IF(Produits!$A$5="","",Produits!$A$5) | B5: =IF(Produits!$A$5="","",Produits!$B$5) | C5: =IF(Produits!$A$5="","",Produits!$C$5) | D5: 5 | E5: 10 | F5: ✓ | G5: 10 | H5: ✓ | I5: =IF(OR(E5="",G5=""),"",G5-E5)
A6: =IF(Produits!$A$6="","",Produits!$A$6) | B6: =IF(Produits!$A$6="","",Produits!$B$6) | C6: =IF(Produits!$A$6="","",Produits!$C$6) | D6: 3 | E6: 3 | F6: ✓ | G6: 3 | H6: ✓ | I6: =IF(OR(E6="",G6=""),"",G6-E6)
A7: =IF(Produits!$A$7="","",Produits!$A$7) | B7: =IF(Produits!$A$7="","",Produits!$B$7) | C7: =IF(Produits!$A$7="","",Produits!$C$7) | D7: 7 | E7: 5 | F7: ✓ | G7: 5 | H7: ✓ | I7: =IF(OR(E7="",G7=""),"",G7-E7)
A8: =IF(Produits!$A$8="","",Produits!$A$8) | B8: =IF(Produits!$A$8="","",Produits!$B$8) | C8: =IF(Produits!$A$8="","",Produits!$C$8) | D8: 2 | E8: 0 | G8: 0 | I8: =IF(OR(E8="",G8=""),"",G8-E8)
A9: =IF(Produits!$A$9="","",Produits!$A$9) | B9: =IF(Produits!$A$9="","",Produits!$B$9) | C9: =IF(Produits!$A$9="","",Produits!$C$9) | D9: 4 | E9: 5 | F9: ✓ | G9: 5 | H9: ✓ | I9: =IF(OR(E9="",G9=""),"",G9-E9)
A10: =IF(Produits!$A$10="","",Produits!$A$10) | B10: =IF(Produits!$A$10="","",Produits!$B$10) | C10: =IF(Produits!$A$10="","",Produits!$C$10) | D10: 5 | E10: 10 | F10: ✓ | G10: 10 | H10: ✓ | I10: =IF(OR(E10="",G10=""),"",G10-E10)
A11: =IF(Produits!$A$11="","",Produits!$A$11) | B11: =IF(Produits!$A$11="","",Produits!$B$11) | C11: =IF(Produits!$A$11="","",Produits!$C$11) | D11: 4 | E11: 6 | F11: ✓ | G11: 6 | H11: ✓ | I11: =IF(OR(E11="",G11=""),"",G11-E11)
A12: =IF(Produits!$A$12="","",Produits!$A$12) | B12: =IF(Produits!$A$12="","",Produits!$B$12) | C12: =IF(Produits!$A$12="","",Produits!$C$12) | D12: 50 | E12: 60 | F12: ✓ | G12: 60 | H12: ✓ | I12: =IF(OR(E12="",G12=""),"",G12-E12)
A13: =IF(Produits!$A$13="","",Produits!$A$13) | B13: =IF(Produits!$A$13="","",Produits!$B$13) | C13: =IF(Produits!$A$13="","",Produits!$C$13) | D13: 2 | E13: 2 | F13: ✓ | G13: 2 | H13: ✓ | I13: =IF(OR(E13="",G13=""),"",G13-E13)
A14: =IF(Produits!$A$14="","",Produits!$A$14) | B14: =IF(Produits!$A$14="","",Produits!$B$14) | C14: =IF(Produits!$A$14="","",Produits!$C$14) | D14: 2 | E14: 2 | F14: ✓ | G14: 2 | H14: ✓ | I14: =IF(OR(E14="",G14=""),"",G14-E14)
A15: =IF(Produits!$A$15="","",Produits!$A$15) | B15: =IF(Produits!$A$15="","",Produits!$B$15) | C15: =IF(Produits!$A$15="","",Produits!$C$15) | D15: 0.6 | E15: 0 | G15: 0 | I15: =IF(OR(E15="",G15=""),"",G15-E15)
A16: =IF(Produits!$A$16="","",Produits!$A$16) | B16: =IF(Produits!$A$16="","",Produits!$B$16) | C16: =IF(Produits!$A$16="","",Produits!$C$16) | D16: 6 | E16: 0 | G16: 0 | I16: =IF(OR(E16="",G16=""),"",G16-E16)
A17: =IF(Produits!$A$17="","",Produits!$A$17) | B17: =IF(Produits!$A$17="","",Produits!$B$17) | C17: =IF(Produits!$A$17="","",Produits!$C$17) | I17: =IF(OR(E17="",G17=""),"",G17-E17)
A18: =IF(Produits!$A$18="","",Produits!$A$18) | B18: =IF(Produits!$A$18="","",Produits!$B$18) | C18: =IF(Produits!$A$18="","",Produits!$C$18) | I18: =IF(OR(E18="",G18=""),"",G18-E18)
A19: =IF(Produits!$A$19="","",Produits!$A$19) | B19: =IF(Produits!$A$19="","",Produits!$B$19) | C19: =IF(Produits!$A$19="","",Produits!$C$19) | I19: =IF(OR(E19="",G19=""),"",G19-E19)
A20: =IF(Produits!$A$20="","",Produits!$A$20) | B20: =IF(Produits!$A$20="","",Produits!$B$20) | C20: =IF(Produits!$A$20="","",Produits!$C$20) | I20: =IF(OR(E20="",G20=""),"",G20-E20)
A21: =IF(Produits!$A$21="","",Produits!$A$21) | B21: =IF(Produits!$A$21="","",Produits!$B$21) | C21: =IF(Produits!$A$21="","",Produits!$C$21) | I21: =IF(OR(E21="",G21=""),"",G21-E21)
A22: =IF(Produits!$A$22="","",Produits!$A$22) | B22: =IF(Produits!$A$22="","",Produits!$B$22) | C22: =IF(Produits!$A$22="","",Produits!$C$22) | I22: =IF(OR(E22="",G22=""),"",G22-E22)
A23: =IF(Produits!$A$23="","",Produits!$A$23) | B23: =IF(Produits!$A$23="","",Produits!$B$23) | C23: =IF(Produits!$A$23="","",Produits!$C$23) | I23: =IF(OR(E23="",G23=""),"",G23-E23)
A24: =IF(Produits!$A$24="","",Produits!$A$24) | B24: =IF(Produits!$A$24="","",Produits!$B$24) | C24: =IF(Produits!$A$24="","",Produits!$C$24) | I24: =IF(OR(E24="",G24=""),"",G24-E24)
A25: =IF(Produits!$A$25="","",Produits!$A$25) | B25: =IF(Produits!$A$25="","",Produits!$B$25) | C25: =IF(Produits!$A$25="","",Produits!$C$25) | I25: =IF(OR(E25="",G25=""),"",G25-E25)
A26: =IF(Produits!$A$26="","",Produits!$A$26) | B26: =IF(Produits!$A$26="","",Produits!$B$26) | C26: =IF(Produits!$A$26="","",Produits!$C$26) | I26: =IF(OR(E26="",G26=""),"",G26-E26)
A27: =IF(Produits!$A$27="","",Produits!$A$27) | B27: =IF(Produits!$A$27="","",Produits!$B$27) | C27: =IF(Produits!$A$27="","",Produits!$C$27) | I27: =IF(OR(E27="",G27=""),"",G27-E27)
A28: =IF(Produits!$A$28="","",Produits!$A$28) | B28: =IF(Produits!$A$28="","",Produits!$B$28) | C28: =IF(Produits!$A$28="","",Produits!$C$28) | I28: =IF(OR(E28="",G28=""),"",G28-E28)
A29: =IF(Produits!$A$29="","",Produits!$A$29) | B29: =IF(Produits!$A$29="","",Produits!$B$29) | C29: =IF(Produits!$A$29="","",Produits!$C$29) | I29: =IF(OR(E29="",G29=""),"",G29-E29)
A30: =IF(Produits!$A$30="","",Produits!$A$30) | B30: =IF(Produits!$A$30="","",Produits!$B$30) | C30: =IF(Produits!$A$30="","",Produits!$C$30) | I30: =IF(OR(E30="",G30=""),"",G30-E30)
A31: =IF(Produits!$A$31="","",Produits!$A$31) | B31: =IF(Produits!$A$31="","",Produits!$B$31) | C31: =IF(Produits!$A$31="","",Produits!$C$31) | I31: =IF(OR(E31="",G31=""),"",G31-E31)
A32: =IF(Produits!$A$32="","",Produits!$A$32) | B32: =IF(Produits!$A$32="","",Produits!$B$32) | C32: =IF(Produits!$A$32="","",Produits!$C$32) | I32: =IF(OR(E32="",G32=""),"",G32-E32)
A33: =IF(Produits!$A$33="","",Produits!$A$33) | B33: =IF(Produits!$A$33="","",Produits!$B$33) | C33: =IF(Produits!$A$33="","",Produits!$C$33) | I33: =IF(OR(E33="",G33=""),"",G33-E33)
A34: =IF(Produits!$A$34="","",Produits!$A$34) | B34: =IF(Produits!$A$34="","",Produits!$B$34) | C34: =IF(Produits!$A$34="","",Produits!$C$34) | I34: =IF(OR(E34="",G34=""),"",G34-E34)
A35: =IF(Produits!$A$35="","",Produits!$A$35) | B35: =IF(Produits!$A$35="","",Produits!$B$35) | C35: =IF(Produits!$A$35="","",Produits!$C$35) | I35: =IF(OR(E35="",G35=""),"",G35-E35)
A36: =IF(Produits!$A$36="","",Produits!$A$36) | B36: =IF(Produits!$A$36="","",Produits!$B$36) | C36: =IF(Produits!$A$36="","",Produits!$C$36) | I36: =IF(OR(E36="",G36=""),"",G36-E36)
A37: =IF(Produits!$A$37="","",Produits!$A$37) | B37: =IF(Produits!$A$37="","",Produits!$B$37) | C37: =IF(Produits!$A$37="","",Produits!$C$37) | I37: =IF(OR(E37="",G37=""),"",G37-E37)
A38: =IF(Produits!$A$38="","",Produits!$A$38) | B38: =IF(Produits!$A$38="","",Produits!$B$38) | C38: =IF(Produits!$A$38="","",Produits!$C$38) | I38: =IF(OR(E38="",G38=""),"",G38-E38)
A39: =IF(Produits!$A$39="","",Produits!$A$39) | B39: =IF(Produits!$A$39="","",Produits!$B$39) | C39: =IF(Produits!$A$39="","",Produits!$C$39) | I39: =IF(OR(E39="",G39=""),"",G39-E39)
A40: =IF(Produits!$A$40="","",Produits!$A$40) | B40: =IF(Produits!$A$40="","",Produits!$B$40) | C40: =IF(Produits!$A$40="","",Produits!$C$40) | I40: =IF(OR(E40="",G40=""),"",G40-E40)
A41: =IF(Produits!$A$41="","",Produits!$A$41) | B41: =IF(Produits!$A$41="","",Produits!$B$41) | C41: =IF(Produits!$A$41="","",Produits!$C$41) | I41: =IF(OR(E41="",G41=""),"",G41-E41)
...

Sheet Semaine 3
A1: Semaine 3
A2: Coche ✓ au fur et à mesure — la ligne se barre quand c'est reçu
A4: Produit | B4: Fournisseur | C4: Unité | D4: Stock | E4: À commander | F4: Commandé ? | G4: Reçu | H4: Reçu ? | I4: Écart
A5: =IF(Produits!$A$5="","",Produits!$A$5) | B5: =IF(Produits!$A$5="","",Produits!$B$5) | C5: =IF(Produits!$A$5="","",Produits!$C$5) | I5: =IF(OR(E5="",G5=""),"",G5-E5)
A6: =IF(Produits!$A$6="","",Produits!$A$6) | B6: =IF(Produits!$A$6="","",Produits!$B$6) | C6: =IF(Produits!$A$6="","",Produits!$C$6) | I6: =IF(OR(E6="",G6=""),"",G6-E6)
A7: =IF(Produits!$A$7="","",Produits!$A$7) | B7: =IF(Produits!$A$7="","",Produits!$B$7) | C7: =IF(Produits!$A$7="","",Produits!$C$7) | I7: =IF(OR(E7="",G7=""),"",G7-E7)
A8: =IF(Produits!$A$8="","",Produits!$A$8) | B8: =IF(Produits!$A$8="","",Produits!$B$8) | C8: =IF(Produits!$A$8="","",Produits!$C$8) | I8: =IF(OR(E8="",G8=""),"",G8-E8)
A9: =IF(Produits!$A$9="","",Produits!$A$9) | B9: =IF(Produits!$A$9="","",Produits!$B$9) | C9: =IF(Produits!$A$9="","",Produits!$C$9) | I9: =IF(OR(E9="",G9=""),"",G9-E9)
A10: =IF(Produits!$A$10="","",Produits!$A$10) | B10: =IF(Produits!$A$10="","",Produits!$B$10) | C10: =IF(Produits!$A$10="","",Produits!$C$10) | I10: =IF(OR(E10="",G10=""),"",G10-E10)
A11: =IF(Produits!$A$11="","",Produits!$A$11) | B11: =IF(Produits!$A$11="","",Produits!$B$11) | C11: =IF(Produits!$A$11="","",Produits!$C$11) | I11: =IF(OR(E11="",G11=""),"",G11-E11)
A12: =IF(Produits!$A$12="","",Produits!$A$12) | B12: =IF(Produits!$A$12="","",Produits!$B$12) | C12: =IF(Produits!$A$12="","",Produits!$C$12) | I12: =IF(OR(E12="",G12=""),"",G12-E12)
A13: =IF(Produits!$A$13="","",Produits!$A$13) | B13: =IF(Produits!$A$13="","",Produits!$B$13) | C13: =IF(Produits!$A$13="","",Produits!$C$13) | I13: =IF(OR(E13="",G13=""),"",G13-E13)
A14: =IF(Produits!$A$14="","",Produits!$A$14) | B14: =IF(Produits!$A$14="","",Produits!$B$14) | C14: =IF(Produits!$A$14="","",Produits!$C$14) | I14: =IF(OR(E14="",G14=""),"",G14-E14)
A15: =IF(Produits!$A$15="","",Produits!$A$15) | B15: =IF(Produits!$A$15="","",Produits!$B$15) | C15: =IF(Produits!$A$15="","",Produits!$C$15) | I15: =IF(OR(E15="",G15=""),"",G15-E15)
A16: =IF(Produits!$A$16="","",Produits!$A$16) | B16: =IF(Produits!$A$16="","",Produits!$B$16) | C16: =IF(Produits!$A$16="","",Produits!$C$16) | I16: =IF(OR(E16="",G16=""),"",G16-E16)
A17: =IF(Produits!$A$17="","",Produits!$A$17) | B17: =IF(Produits!$A$17="","",Produits!$B$17) | C17: =IF(Produits!$A$17="","",Produits!$C$17) | I17: =IF(OR(E17="",G17=""),"",G17-E17)
A18: =IF(Produits!$A$18="","",Produits!$A$18) | B18: =IF(Produits!$A$18="","",Produits!$B$18) | C18: =IF(Produits!$A$18="","",Produits!$C$18) | I18: =IF(OR(E18="",G18=""),"",G18-E18)
A19: =IF(Produits!$A$19="","",Produits!$A$19) | B19: =IF(Produits!$A$19="","",Produits!$B$19) | C19: =IF(Produits!$A$19="","",Produits!$C$19) | I19: =IF(OR(E19="",G19=""),"",G19-E19)
A20: =IF(Produits!$A$20="","",Produits!$A$20) | B20: =IF(Produits!$A$20="","",Produits!$B$20) | C20: =IF(Produits!$A$20="","",Produits!$C$20) | I20: =IF(OR(E20="",G20=""),"",G20-E20)
A21: =IF(Produits!$A$21="","",Produits!$A$21) | B21: =IF(Produits!$A$21="","",Produits!$B$21) | C21: =IF(Produits!$A$21="","",Produits!$C$21) | I21: =IF(OR(E21="",G21=""),"",G21-E21)
A22: =IF(Produits!$A$22="","",Produits!$A$22) | B22: =IF(Produits!$A$22="","",Produits!$B$22) | C22: =IF(Produits!$A$22="","",Produits!$C$22) | I22: =IF(OR(E22="",G22=""),"",G22-E22)
A23: =IF(Produits!$A$23="","",Produits!$A$23) | B23: =IF(Produits!$A$23="","",Produits!$B$23) | C23: =IF(Produits!$A$23="","",Produits!$C$23) | I23: =IF(OR(E23="",G23=""),"",G23-E23)
A24: =IF(Produits!$A$24="","",Produits!$A$24) | B24: =IF(Produits!$A$24="","",Produits!$B$24) | C24: =IF(Produits!$A$24="","",Produits!$C$24) | I24: =IF(OR(E24="",G24=""),"",G24-E24)
A25: =IF(Produits!$A$25="","",Produits!$A$25) | B25: =IF(Produits!$A$25="","",Produits!$B$25) | C25: =IF(Produits!$A$25="","",Produits!$C$25) | I25: =IF(OR(E25="",G25=""),"",G25-E25)
A26: =IF(Produits!$A$26="","",Produits!$A$26) | B26: =IF(Produits!$A$26="","",Produits!$B$26) | C26: =IF(Produits!$A$26="","",Produits!$C$26) | I26: =IF(OR(E26="",G26=""),"",G26-E26)
A27: =IF(Produits!$A$27="","",Produits!$A$27) | B27: =IF(Produits!$A$27="","",Produits!$B$27) | C27: =IF(Produits!$A$27="","",Produits!$C$27) | I27: =IF(OR(E27="",G27=""),"",G27-E27)
A28: =IF(Produits!$A$28="","",Produits!$A$28) | B28: =IF(Produits!$A$28="","",Produits!$B$28) | C28: =IF(Produits!$A$28="","",Produits!$C$28) | I28: =IF(OR(E28="",G28=""),"",G28-E28)
A29: =IF(Produits!$A$29="","",Produits!$A$29) | B29: =IF(Produits!$A$29="","",Produits!$B$29) | C29: =IF(Produits!$A$29="","",Produits!$C$29) | I29: =IF(OR(E29="",G29=""),"",G29-E29)
A30: =IF(Produits!$A$30="","",Produits!$A$30) | B30: =IF(Produits!$A$30="","",Produits!$B$30) | C30: =IF(Produits!$A$30="","",Produits!$C$30) | I30: =IF(OR(E30="",G30=""),"",G30-E30)
A31: =IF(Produits!$A$31="","",Produits!$A$31) | B31: =IF(Produits!$A$31="","",Produits!$B$31) | C31: =IF(Produits!$A$31="","",Produits!$C$31) | I31: =IF(OR(E31="",G31=""),"",G31-E31)
A32: =IF(Produits!$A$32="","",Produits!$A$32) | B32: =IF(Produits!$A$32="","",Produits!$B$32) | C32: =IF(Produits!$A$32="","",Produits!$C$32) | I32: =IF(OR(E32="",G32=""),"",G32-E32)
A33: =IF(Produits!$A$33="","",Produits!$A$33) | B33: =IF(Produits!$A$33="","",Produits!$B$33) | C33: =IF(Produits!$A$33="","",Produits!$C$33) | I33: =IF(OR(E33="",G33=""),"",G33-E33)
A34: =IF(Produits!$A$34="","",Produits!$A$34) | B34: =IF(Produits!$A$34="","",Produits!$B$34) | C34: =IF(Produits!$A$34="","",Produits!$C$34) | I34: =IF(OR(E34="",G34=""),"",G34-E34)
A35: =IF(Produits!$A$35="","",Produits!$A$35) | B35: =IF(Produits!$A$35="","",Produits!$B$35) | C35: =IF(Produits!$A$35="","",Produits!$C$35) | I35: =IF(OR(E35="",G35=""),"",G35-E35)
A36: =IF(Produits!$A$36="","",Produits!$A$36) | B36: =IF(Produits!$A$36="","",Produits!$B$36) | C36: =IF(Produits!$A$36="","",Produits!$C$36) | I36: =IF(OR(E36="",G36=""),"",G36-E36)
A37: =IF(Produits!$A$37="","",Produits!$A$37) | B37: =IF(Produits!$A$37="","",Produits!$B$37) | C37: =IF(Produits!$A$37="","",Produits!$C$37) | I37: =IF(OR(E37="",G37=""),"",G37-E37)
A38: =IF(Produits!$A$38="","",Produits!$A$38) | B38: =IF(Produits!$A$38="","",Produits!$B$38) | C38: =IF(Produits!$A$38="","",Produits!$C$38) | I38: =IF(OR(E38="",G38=""),"",G38-E38)
A39: =IF(Produits!$A$39="","",Produits!$A$39) | B39: =IF(Produits!$A$39="","",Produits!$B$39) | C39: =IF(Produits!$A$39="","",Produits!$C$39) | I39: =IF(OR(E39="",G39=""),"",G39-E39)
A40: =IF(Produits!$A$40="","",Produits!$A$40) | B40: =IF(Produits!$A$40="","",Produits!$B$40) | C40: =IF(Produits!$A$40="","",Produits!$C$40) | I40: =IF(OR(E40="",G40=""),"",G40-E40)
A41: =IF(Produits!$A$41="","",Produits!$A$41) | B41: =IF(Produits!$A$41="","",Produits!$B$41) | C41: =IF(Produits!$A$41="","",Produits!$C$41) | I41: =IF(OR(E41="",G41=""),"",G41-E41)
...

Sheet Semaine 4
A1: Semaine 4
A2: Coche ✓ au fur et à mesure — la ligne se barre quand c'est reçu
A4: Produit | B4: Fournisseur | C4: Unité | D4: Stock | E4: À commander | F4: Commandé ? | G4: Reçu | H4: Reçu ? | I4: Écart
A5: =IF(Produits!$A$5="","",Produits!$A$5) | B5: =IF(Produits!$A$5="","",Produits!$B$5) | C5: =IF(Produits!$A$5="","",Produits!$C$5) | I5: =IF(OR(E5="",G5=""),"",G5-E5)
A6: =IF(Produits!$A$6="","",Produits!$A$6) | B6: =IF(Produits!$A$6="","",Produits!$B$6) | C6: =IF(Produits!$A$6="","",Produits!$C$6) | I6: =IF(OR(E6="",G6=""),"",G6-E6)
A7: =IF(Produits!$A$7="","",Produits!$A$7) | B7: =IF(Produits!$A$7="","",Produits!$B$7) | C7: =IF(Produits!$A$7="","",Produits!$C$7) | I7: =IF(OR(E7="",G7=""),"",G7-E7)
A8: =IF(Produits!$A$8="","",Produits!$A$8) | B8: =IF(Produits!$A$8="","",Produits!$B$8) | C8: =IF(Produits!$A$8="","",Produits!$C$8) | I8: =IF(OR(E8="",G8=""),"",G8-E8)
A9: =IF(Produits!$A$9="","",Produits!$A$9) | B9: =IF(Produits!$A$9="","",Produits!$B$9) | C9: =IF(Produits!$A$9="","",Produits!$C$9) | I9: =IF(OR(E9="",G9=""),"",G9-E9)
A10: =IF(Produits!$A$10="","",Produits!$A$10) | B10: =IF(Produits!$A$10="","",Produits!$B$10) | C10: =IF(Produits!$A$10="","",Produits!$C$10) | I10: =IF(OR(E10="",G10=""),"",G10-E10)
A11: =IF(Produits!$A$11="","",Produits!$A$11) | B11: =IF(Produits!$A$11="","",Produits!$B$11) | C11: =IF(Produits!$A$11="","",Produits!$C$11) | I11: =IF(OR(E11="",G11=""),"",G11-E11)
A12: =IF(Produits!$A$12="","",Produits!$A$12) | B12: =IF(Produits!$A$12="","",Produits!$B$12) | C12: =IF(Produits!$A$12="","",Produits!$C$12) | I12: =IF(OR(E12="",G12=""),"",G12-E12)
A13: =IF(Produits!$A$13="","",Produits!$A$13) | B13: =IF(Produits!$A$13="","",Produits!$B$13) | C13: =IF(Produits!$A$13="","",Produits!$C$13) | I13: =IF(OR(E13="",G13=""),"",G13-E13)
A14: =IF(Produits!$A$14="","",Produits!$A$14) | B14: =IF(Produits!$A$14="","",Produits!$B$14) | C14: =IF(Produits!$A$14="","",Produits!$C$14) | I14: =IF(OR(E14="",G14=""),"",G14-E14)
A15: =IF(Produits!$A$15="","",Produits!$A$15) | B15: =IF(Produits!$A$15="","",Produits!$B$15) | C15: =IF(Produits!$A$15="","",Produits!$C$15) | I15: =IF(OR(E15="",G15=""),"",G15-E15)
A16: =IF(Produits!$A$16="","",Produits!$A$16) | B16: =IF(Produits!$A$16="","",Produits!$B$16) | C16: =IF(Produits!$A$16="","",Produits!$C$16) | I16: =IF(OR(E16="",G16=""),"",G16-E16)
A17: =IF(Produits!$A$17="","",Produits!$A$17) | B17: =IF(Produits!$A$17="","",Produits!$B$17) | C17: =IF(Produits!$A$17="","",Produits!$C$17) | I17: =IF(OR(E17="",G17=""),"",G17-E17)
A18: =IF(Produits!$A$18="","",Produits!$A$18) | B18: =IF(Produits!$A$18="","",Produits!$B$18) | C18: =IF(Produits!$A$18="","",Produits!$C$18) | I18: =IF(OR(E18="",G18=""),"",G18-E18)
A19: =IF(Produits!$A$19="","",Produits!$A$19) | B19: =IF(Produits!$A$19="","",Produits!$B$19) | C19: =IF(Produits!$A$19="","",Produits!$C$19) | I19: =IF(OR(E19="",G19=""),"",G19-E19)
A20: =IF(Produits!$A$20="","",Produits!$A$20) | B20: =IF(Produits!$A$20="","",Produits!$B$20) | C20: =IF(Produits!$A$20="","",Produits!$C$20) | I20: =IF(OR(E20="",G20=""),"",G20-E20)
A21: =IF(Produits!$A$21="","",Produits!$A$21) | B21: =IF(Produits!$A$21="","",Produits!$B$21) | C21: =IF(Produits!$A$21="","",Produits!$C$21) | I21: =IF(OR(E21="",G21=""),"",G21-E21)
A22: =IF(Produits!$A$22="","",Produits!$A$22) | B22: =IF(Produits!$A$22="","",Produits!$B$22) | C22: =IF(Produits!$A$22="","",Produits!$C$22) | I22: =IF(OR(E22="",G22=""),"",G22-E22)
A23: =IF(Produits!$A$23="","",Produits!$A$23) | B23: =IF(Produits!$A$23="","",Produits!$B$23) | C23: =IF(Produits!$A$23="","",Produits!$C$23) | I23: =IF(OR(E23="",G23=""),"",G23-E23)
A24: =IF(Produits!$A$24="","",Produits!$A$24) | B24: =IF(Produits!$A$24="","",Produits!$B$24) | C24: =IF(Produits!$A$24="","",Produits!$C$24) | I24: =IF(OR(E24="",G24=""),"",G24-E24)
A25: =IF(Produits!$A$25="","",Produits!$A$25) | B25: =IF(Produits!$A$25="","",Produits!$B$25) | C25: =IF(Produits!$A$25="","",Produits!$C$25) | I25: =IF(OR(E25="",G25=""),"",G25-E25)
A26: =IF(Produits!$A$26="","",Produits!$A$26) | B26: =IF(Produits!$A$26="","",Produits!$B$26) | C26: =IF(Produits!$A$26="","",Produits!$C$26) | I26: =IF(OR(E26="",G26=""),"",G26-E26)
A27: =IF(Produits!$A$27="","",Produits!$A$27) | B27: =IF(Produits!$A$27="","",Produits!$B$27) | C27: =IF(Produits!$A$27="","",Produits!$C$27) | I27: =IF(OR(E27="",G27=""),"",G27-E27)
A28: =IF(Produits!$A$28="","",Produits!$A$28) | B28: =IF(Produits!$A$28="","",Produits!$B$28) | C28: =IF(Produits!$A$28="","",Produits!$C$28) | I28: =IF(OR(E28="",G28=""),"",G28-E28)
A29: =IF(Produits!$A$29="","",Produits!$A$29) | B29: =IF(Produits!$A$29="","",Produits!$B$29) | C29: =IF(Produits!$A$29="","",Produits!$C$29) | I29: =IF(OR(E29="",G29=""),"",G29-E29)
A30: =IF(Produits!$A$30="","",Produits!$A$30) | B30: =IF(Produits!$A$30="","",Produits!$B$30) | C30: =IF(Produits!$A$30="","",Produits!$C$30) | I30: =IF(OR(E30="",G30=""),"",G30-E30)
A31: =IF(Produits!$A$31="","",Produits!$A$31) | B31: =IF(Produits!$A$31="","",Produits!$B$31) | C31: =IF(Produits!$A$31="","",Produits!$C$31) | I31: =IF(OR(E31="",G31=""),"",G31-E31)
A32: =IF(Produits!$A$32="","",Produits!$A$32) | B32: =IF(Produits!$A$32="","",Produits!$B$32) | C32: =IF(Produits!$A$32="","",Produits!$C$32) | I32: =IF(OR(E32="",G32=""),"",G32-E32)
A33: =IF(Produits!$A$33="","",Produits!$A$33) | B33: =IF(Produits!$A$33="","",Produits!$B$33) | C33: =IF(Produits!$A$33="","",Produits!$C$33) | I33: =IF(OR(E33="",G33=""),"",G33-E33)
A34: =IF(Produits!$A$34="","",Produits!$A$34) | B34: =IF(Produits!$A$34="","",Produits!$B$34) | C34: =IF(Produits!$A$34="","",Produits!$C$34) | I34: =IF(OR(E34="",G34=""),"",G34-E34)
A35: =IF(Produits!$A$35="","",Produits!$A$35) | B35: =IF(Produits!$A$35="","",Produits!$B$35) | C35: =IF(Produits!$A$35="","",Produits!$C$35) | I35: =IF(OR(E35="",G35=""),"",G35-E35)
A36: =IF(Produits!$A$36="","",Produits!$A$36) | B36: =IF(Produits!$A$36="","",Produits!$B$36) | C36: =IF(Produits!$A$36="","",Produits!$C$36) | I36: =IF(OR(E36="",G36=""),"",G36-E36)
A37: =IF(Produits!$A$37="","",Produits!$A$37) | B37: =IF(Produits!$A$37="","",Produits!$B$37) | C37: =IF(Produits!$A$37="","",Produits!$C$37) | I37: =IF(OR(E37="",G37=""),"",G37-E37)
A38: =IF(Produits!$A$38="","",Produits!$A$38) | B38: =IF(Produits!$A$38="","",Produits!$B$38) | C38: =IF(Produits!$A$38="","",Produits!$C$38) | I38: =IF(OR(E38="",G38=""),"",G38-E38)
A39: =IF(Produits!$A$39="","",Produits!$A$39) | B39: =IF(Produits!$A$39="","",Produits!$B$39) | C39: =IF(Produits!$A$39="","",Produits!$C$39) | I39: =IF(OR(E39="",G39=""),"",G39-E39)
A40: =IF(Produits!$A$40="","",Produits!$A$40) | B40: =IF(Produits!$A$40="","",Produits!$B$40) | C40: =IF(Produits!$A$40="","",Produits!$C$40) | I40: =IF(OR(E40="",G40=""),"",G40-E40)
A41: =IF(Produits!$A$41="","",Produits!$A$41) | B41: =IF(Produits!$A$41="","",Produits!$B$41) | C41: =IF(Produits!$A$41="","",Produits!$C$41) | I41: =IF(OR(E41="",G41=""),"",G41-E41)
...

Sheet Récap du mois
A1: Récap du mois
A2: Calculé à partir des 4 semaines — rien à remplir
A4: Produit | B4: Unité | C4: Total commandé | D4: Total reçu | E4: Manque | F4: Dernier stock
A5: =IF(Produits!$A$5="","",Produits!$A$5) | B5: =IF(Produits!$A$5="","",Produits!$C$5) | C5: =IF(COUNT('Semaine 1'!E5,'Semaine 2'!E5,'Semaine 3'!E5,'Semaine 4'!E5)=0,"",SUM('Semaine 1'!E5,'Semaine 2'!E5,'Semaine 3'!E5,'Semaine 4'!E5)) | D5: =IF(COUNT('Semaine 1'!G5,'Semaine 2'!G5,'Semaine 3'!G5,'Semaine 4'!G5)=0,"",SUM('Semaine 1'!G5,'Semaine 2'!G5,'Semaine 3'!G5,'Semaine 4'!G5)) | E5: =IF(OR(C5="",D5=""),"",D5-C5) | F5: =IF('Semaine 4'!D5<>"",'Semaine 4'!D5,IF('Semaine 3'!D5<>"",'Semaine 3'!D5,IF('Semaine 2'!D5<>"",'Semaine 2'!D5,IF('Semaine 1'!D5<>"",'Semaine 1'!D5,""))))
A6: =IF(Produits!$A$6="","",Produits!$A$6) | B6: =IF(Produits!$A$6="","",Produits!$C$6) | C6: =IF(COUNT('Semaine 1'!E6,'Semaine 2'!E6,'Semaine 3'!E6,'Semaine 4'!E6)=0,"",SUM('Semaine 1'!E6,'Semaine 2'!E6,'Semaine 3'!E6,'Semaine 4'!E6)) | D6: =IF(COUNT('Semaine 1'!G6,'Semaine 2'!G6,'Semaine 3'!G6,'Semaine 4'!G6)=0,"",SUM('Semaine 1'!G6,'Semaine 2'!G6,'Semaine 3'!G6,'Semaine 4'!G6)) | E6: =IF(OR(C6="",D6=""),"",D6-C6) | F6: =IF('Semaine 4'!D6<>"",'Semaine 4'!D6,IF('Semaine 3'!D6<>"",'Semaine 3'!D6,IF('Semaine 2'!D6<>"",'Semaine 2'!D6,IF('Semaine 1'!D6<>"",'Semaine 1'!D6,""))))
A7: =IF(Produits!$A$7="","",Produits!$A$7) | B7: =IF(Produits!$A$7="","",Produits!$C$7) | C7: =IF(COUNT('Semaine 1'!E7,'Semaine 2'!E7,'Semaine 3'!E7,'Semaine 4'!E7)=0,"",SUM('Semaine 1'!E7,'Semaine 2'!E7,'Semaine 3'!E7,'Semaine 4'!E7)) | D7: =IF(COUNT('Semaine 1'!G7,'Semaine 2'!G7,'Semaine 3'!G7,'Semaine 4'!G7)=0,"",SUM('Semaine 1'!G7,'Semaine 2'!G7,'Semaine 3'!G7,'Semaine 4'!G7)) | E7: =IF(OR(C7="",D7=""),"",D7-C7) | F7: =IF('Semaine 4'!D7<>"",'Semaine 4'!D7,IF('Semaine 3'!D7<>"",'Semaine 3'!D7,IF('Semaine 2'!D7<>"",'Semaine 2'!D7,IF('Semaine 1'!D7<>"",'Semaine 1'!D7,""))))
A8: =IF(Produits!$A$8="","",Produits!$A$8) | B8: =IF(Produits!$A$8="","",Produits!$C$8) | C8: =IF(COUNT('Semaine 1'!E8,'Semaine 2'!E8,'Semaine 3'!E8,'Semaine 4'!E8)=0,"",SUM('Semaine 1'!E8,'Semaine 2'!E8,'Semaine 3'!E8,'Semaine 4'!E8)) | D8: =IF(COUNT('Semaine 1'!G8,'Semaine 2'!G8,'Semaine 3'!G8,'Semaine 4'!G8)=0,"",SUM('Semaine 1'!G8,'Semaine 2'!G8,'Semaine 3'!G8,'Semaine 4'!G8)) | E8: =IF(OR(C8="",D8=""),"",D8-C8) | F8: =IF('Semaine 4'!D8<>"",'Semaine 4'!D8,IF('Semaine 3'!D8<>"",'Semaine 3'!D8,IF('Semaine 2'!D8<>"",'Semaine 2'!D8,IF('Semaine 1'!D8<>"",'Semaine 1'!D8,""))))
A9: =IF(Produits!$A$9="","",Produits!$A$9) | B9: =IF(Produits!$A$9="","",Produits!$C$9) | C9: =IF(COUNT('Semaine 1'!E9,'Semaine 2'!E9,'Semaine 3'!E9,'Semaine 4'!E9)=0,"",SUM('Semaine 1'!E9,'Semaine 2'!E9,'Semaine 3'!E9,'Semaine 4'!E9)) | D9: =IF(COUNT('Semaine 1'!G9,'Semaine 2'!G9,'Semaine 3'!G9,'Semaine 4'!G9)=0,"",SUM('Semaine 1'!G9,'Semaine 2'!G9,'Semaine 3'!G9,'Semaine 4'!G9)) | E9: =IF(OR(C9="",D9=""),"",D9-C9) | F9: =IF('Semaine 4'!D9<>"",'Semaine 4'!D9,IF('Semaine 3'!D9<>"",'Semaine 3'!D9,IF('Semaine 2'!D9<>"",'Semaine 2'!D9,IF('Semaine 1'!D9<>"",'Semaine 1'!D9,""))))
A10: =IF(Produits!$A$10="","",Produits!$A$10) | B10: =IF(Produits!$A$10="","",Produits!$C$10) | C10: =IF(COUNT('Semaine 1'!E10,'Semaine 2'!E10,'Semaine 3'!E10,'Semaine 4'!E10)=0,"",SUM('Semaine 1'!E10,'Semaine 2'!E10,'Semaine 3'!E10,'Semaine 4'!E10)) | D10: =IF(COUNT('Semaine 1'!G10,'Semaine 2'!G10,'Semaine 3'!G10,'Semaine 4'!G10)=0,"",SUM('Semaine 1'!G10,'Semaine 2'!G10,'Semaine 3'!G10,'Semaine 4'!G10)) | E10: =IF(OR(C10="",D10=""),"",D10-C10) | F10: =IF('Semaine 4'!D10<>"",'Semaine 4'!D10,IF('Semaine 3'!D10<>"",'Semaine 3'!D10,IF('Semaine 2'!D10<>"",'Semaine 2'!D10,IF('Semaine 1'!D10<>"",'Semaine 1'!D10,""))))
A11: =IF(Produits!$A$11="","",Produits!$A$11) | B11: =IF(Produits!$A$11="","",Produits!$C$11) | C11: =IF(COUNT('Semaine 1'!E11,'Semaine 2'!E11,'Semaine 3'!E11,'Semaine 4'!E11)=0,"",SUM('Semaine 1'!E11,'Semaine 2'!E11,'Semaine 3'!E11,'Semaine 4'!E11)) | D11: =IF(COUNT('Semaine 1'!G11,'Semaine 2'!G11,'Semaine 3'!G11,'Semaine 4'!G11)=0,"",SUM('Semaine 1'!G11,'Semaine 2'!G11,'Semaine 3'!G11,'Semaine 4'!G11)) | E11: =IF(OR(C11="",D11=""),"",D11-C11) | F11: =IF('Semaine 4'!D11<>"",'Semaine 4'!D11,IF('Semaine 3'!D11<>"",'Semaine 3'!D11,IF('Semaine 2'!D11<>"",'Semaine 2'!D11,IF('Semaine 1'!D11<>"",'Semaine 1'!D11,""))))
A12: =IF(Produits!$A$12="","",Produits!$A$12) | B12: =IF(Produits!$A$12="","",Produits!$C$12) | C12: =IF(COUNT('Semaine 1'!E12,'Semaine 2'!E12,'Semaine 3'!E12,'Semaine 4'!E12)=0,"",SUM('Semaine 1'!E12,'Semaine 2'!E12,'Semaine 3'!E12,'Semaine 4'!E12)) | D12: =IF(COUNT('Semaine 1'!G12,'Semaine 2'!G12,'Semaine 3'!G12,'Semaine 4'!G12)=0,"",SUM('Semaine 1'!G12,'Semaine 2'!G12,'Semaine 3'!G12,'Semaine 4'!G12)) | E12: =IF(OR(C12="",D12=""),"",D12-C12) | F12: =IF('Semaine 4'!D12<>"",'Semaine 4'!D12,IF('Semaine 3'!D12<>"",'Semaine 3'!D12,IF('Semaine 2'!D12<>"",'Semaine 2'!D12,IF('Semaine 1'!D12<>"",'Semaine 1'!D12,""))))
A13: =IF(Produits!$A$13="","",Produits!$A$13) | B13: =IF(Produits!$A$13="","",Produits!$C$13) | C13: =IF(COUNT('Semaine 1'!E13,'Semaine 2'!E13,'Semaine 3'!E13,'Semaine 4'!E13)=0,"",SUM('Semaine 1'!E13,'Semaine 2'!E13,'Semaine 3'!E13,'Semaine 4'!E13)) | D13: =IF(COUNT('Semaine 1'!G13,'Semaine 2'!G13,'Semaine 3'!G13,'Semaine 4'!G13)=0,"",SUM('Semaine 1'!G13,'Semaine 2'!G13,'Semaine 3'!G13,'Semaine 4'!G13)) | E13: =IF(OR(C13="",D13=""),"",D13-C13) | F13: =IF('Semaine 4'!D13<>"",'Semaine 4'!D13,IF('Semaine 3'!D13<>"",'Semaine 3'!D13,IF('Semaine 2'!D13<>"",'Semaine 2'!D13,IF('Semaine 1'!D13<>"",'Semaine 1'!D13,""))))
A14: =IF(Produits!$A$14="","",Produits!$A$14) | B14: =IF(Produits!$A$14="","",Produits!$C$14) | C14: =IF(COUNT('Semaine 1'!E14,'Semaine 2'!E14,'Semaine 3'!E14,'Semaine 4'!E14)=0,"",SUM('Semaine 1'!E14,'Semaine 2'!E14,'Semaine 3'!E14,'Semaine 4'!E14)) | D14: =IF(COUNT('Semaine 1'!G14,'Semaine 2'!G14,'Semaine 3'!G14,'Semaine 4'!G14)=0,"",SUM('Semaine 1'!G14,'Semaine 2'!G14,'Semaine 3'!G14,'Semaine 4'!G14)) | E14: =IF(OR(C14="",D14=""),"",D14-C14) | F14: =IF('Semaine 4'!D14<>"",'Semaine 4'!D14,IF('Semaine 3'!D14<>"",'Semaine 3'!D14,IF('Semaine 2'!D14<>"",'Semaine 2'!D14,IF('Semaine 1'!D14<>"",'Semaine 1'!D14,""))))
A15: =IF(Produits!$A$15="","",Produits!$A$15) | B15: =IF(Produits!$A$15="","",Produits!$C$15) | C15: =IF(COUNT('Semaine 1'!E15,'Semaine 2'!E15,'Semaine 3'!E15,'Semaine 4'!E15)=0,"",SUM('Semaine 1'!E15,'Semaine 2'!E15,'Semaine 3'!E15,'Semaine 4'!E15)) | D15: =IF(COUNT('Semaine 1'!G15,'Semaine 2'!G15,'Semaine 3'!G15,'Semaine 4'!G15)=0,"",SUM('Semaine 1'!G15,'Semaine 2'!G15,'Semaine 3'!G15,'Semaine 4'!G15)) | E15: =IF(OR(C15="",D15=""),"",D15-C15) | F15: =IF('Semaine 4'!D15<>"",'Semaine 4'!D15,IF('Semaine 3'!D15<>"",'Semaine 3'!D15,IF('Semaine 2'!D15<>"",'Semaine 2'!D15,IF('Semaine 1'!D15<>"",'Semaine 1'!D15,""))))
A16: =IF(Produits!$A$16="","",Produits!$A$16) | B16: =IF(Produits!$A$16="","",Produits!$C$16) | C16: =IF(COUNT('Semaine 1'!E16,'Semaine 2'!E16,'Semaine 3'!E16,'Semaine 4'!E16)=0,"",SUM('Semaine 1'!E16,'Semaine 2'!E16,'Semaine 3'!E16,'Semaine 4'!E16)) | D16: =IF(COUNT('Semaine 1'!G16,'Semaine 2'!G16,'Semaine 3'!G16,'Semaine 4'!G16)=0,"",SUM('Semaine 1'!G16,'Semaine 2'!G16,'Semaine 3'!G16,'Semaine 4'!G16)) | E16: =IF(OR(C16="",D16=""),"",D16-C16) | F16: =IF('Semaine 4'!D16<>"",'Semaine 4'!D16,IF('Semaine 3'!D16<>"",'Semaine 3'!D16,IF('Semaine 2'!D16<>"",'Semaine 2'!D16,IF('Semaine 1'!D16<>"",'Semaine 1'!D16,""))))
A17: =IF(Produits!$A$17="","",Produits!$A$17) | B17: =IF(Produits!$A$17="","",Produits!$C$17) | C17: =IF(COUNT('Semaine 1'!E17,'Semaine 2'!E17,'Semaine 3'!E17,'Semaine 4'!E17)=0,"",SUM('Semaine 1'!E17,'Semaine 2'!E17,'Semaine 3'!E17,'Semaine 4'!E17)) | D17: =IF(COUNT('Semaine 1'!G17,'Semaine 2'!G17,'Semaine 3'!G17,'Semaine 4'!G17)=0,"",SUM('Semaine 1'!G17,'Semaine 2'!G17,'Semaine 3'!G17,'Semaine 4'!G17)) | E17: =IF(OR(C17="",D17=""),"",D17-C17) | F17: =IF('Semaine 4'!D17<>"",'Semaine 4'!D17,IF('Semaine 3'!D17<>"",'Semaine 3'!D17,IF('Semaine 2'!D17<>"",'Semaine 2'!D17,IF('Semaine 1'!D17<>"",'Semaine 1'!D17,""))))
A18: =IF(Produits!$A$18="","",Produits!$A$18) | B18: =IF(Produits!$A$18="","",Produits!$C$18) | C18: =IF(COUNT('Semaine 1'!E18,'Semaine 2'!E18,'Semaine 3'!E18,'Semaine 4'!E18)=0,"",SUM('Semaine 1'!E18,'Semaine 2'!E18,'Semaine 3'!E18,'Semaine 4'!E18)) | D18: =IF(COUNT('Semaine 1'!G18,'Semaine 2'!G18,'Semaine 3'!G18,'Semaine 4'!G18)=0,"",SUM('Semaine 1'!G18,'Semaine 2'!G18,'Semaine 3'!G18,'Semaine 4'!G18)) | E18: =IF(OR(C18="",D18=""),"",D18-C18) | F18: =IF('Semaine 4'!D18<>"",'Semaine 4'!D18,IF('Semaine 3'!D18<>"",'Semaine 3'!D18,IF('Semaine 2'!D18<>"",'Semaine 2'!D18,IF('Semaine 1'!D18<>"",'Semaine 1'!D18,""))))
A19: =IF(Produits!$A$19="","",Produits!$A$19) | B19: =IF(Produits!$A$19="","",Produits!$C$19) | C19: =IF(COUNT('Semaine 1'!E19,'Semaine 2'!E19,'Semaine 3'!E19,'Semaine 4'!E19)=0,"",SUM('Semaine 1'!E19,'Semaine 2'!E19,'Semaine 3'!E19,'Semaine 4'!E19)) | D19: =IF(COUNT('Semaine 1'!G19,'Semaine 2'!G19,'Semaine 3'!G19,'Semaine 4'!G19)=0,"",SUM('Semaine 1'!G19,'Semaine 2'!G19,'Semaine 3'!G19,'Semaine 4'!G19)) | E19: =IF(OR(C19="",D19=""),"",D19-C19) | F19: =IF('Semaine 4'!D19<>"",'Semaine 4'!D19,IF('Semaine 3'!D19<>"",'Semaine 3'!D19,IF('Semaine 2'!D19<>"",'Semaine 2'!D19,IF('Semaine 1'!D19<>"",'Semaine 1'!D19,""))))
A20: =IF(Produits!$A$20="","",Produits!$A$20) | B20: =IF(Produits!$A$20="","",Produits!$C$20) | C20: =IF(COUNT('Semaine 1'!E20,'Semaine 2'!E20,'Semaine 3'!E20,'Semaine 4'!E20)=0,"",SUM('Semaine 1'!E20,'Semaine 2'!E20,'Semaine 3'!E20,'Semaine 4'!E20)) | D20: =IF(COUNT('Semaine 1'!G20,'Semaine 2'!G20,'Semaine 3'!G20,'Semaine 4'!G20)=0,"",SUM('Semaine 1'!G20,'Semaine 2'!G20,'Semaine 3'!G20,'Semaine 4'!G20)) | E20: =IF(OR(C20="",D20=""),"",D20-C20) | F20: =IF('Semaine 4'!D20<>"",'Semaine 4'!D20,IF('Semaine 3'!D20<>"",'Semaine 3'!D20,IF('Semaine 2'!D20<>"",'Semaine 2'!D20,IF('Semaine 1'!D20<>"",'Semaine 1'!D20,""))))
A21: =IF(Produits!$A$21="","",Produits!$A$21) | B21: =IF(Produits!$A$21="","",Produits!$C$21) | C21: =IF(COUNT('Semaine 1'!E21,'Semaine 2'!E21,'Semaine 3'!E21,'Semaine 4'!E21)=0,"",SUM('Semaine 1'!E21,'Semaine 2'!E21,'Semaine 3'!E21,'Semaine 4'!E21)) | D21: =IF(COUNT('Semaine 1'!G21,'Semaine 2'!G21,'Semaine 3'!G21,'Semaine 4'!G21)=0,"",SUM('Semaine 1'!G21,'Semaine 2'!G21,'Semaine 3'!G21,'Semaine 4'!G21)) | E21: =IF(OR(C21="",D21=""),"",D21-C21) | F21: =IF('Semaine 4'!D21<>"",'Semaine 4'!D21,IF('Semaine 3'!D21<>"",'Semaine 3'!D21,IF('Semaine 2'!D21<>"",'Semaine 2'!D21,IF('Semaine 1'!D21<>"",'Semaine 1'!D21,""))))
A22: =IF(Produits!$A$22="","",Produits!$A$22) | B22: =IF(Produits!$A$22="","",Produits!$C$22) | C22: =IF(COUNT('Semaine 1'!E22,'Semaine 2'!E22,'Semaine 3'!E22,'Semaine 4'!E22)=0,"",SUM('Semaine 1'!E22,'Semaine 2'!E22,'Semaine 3'!E22,'Semaine 4'!E22)) | D22: =IF(COUNT('Semaine 1'!G22,'Semaine 2'!G22,'Semaine 3'!G22,'Semaine 4'!G22)=0,"",SUM('Semaine 1'!G22,'Semaine 2'!G22,'Semaine 3'!G22,'Semaine 4'!G22)) | E22: =IF(OR(C22="",D22=""),"",D22-C22) | F22: =IF('Semaine 4'!D22<>"",'Semaine 4'!D22,IF('Semaine 3'!D22<>"",'Semaine 3'!D22,IF('Semaine 2'!D22<>"",'Semaine 2'!D22,IF('Semaine 1'!D22<>"",'Semaine 1'!D22,""))))
A23: =IF(Produits!$A$23="","",Produits!$A$23) | B23: =IF(Produits!$A$23="","",Produits!$C$23) | C23: =IF(COUNT('Semaine 1'!E23,'Semaine 2'!E23,'Semaine 3'!E23,'Semaine 4'!E23)=0,"",SUM('Semaine 1'!E23,'Semaine 2'!E23,'Semaine 3'!E23,'Semaine 4'!E23)) | D23: =IF(COUNT('Semaine 1'!G23,'Semaine 2'!G23,'Semaine 3'!G23,'Semaine 4'!G23)=0,"",SUM('Semaine 1'!G23,'Semaine 2'!G23,'Semaine 3'!G23,'Semaine 4'!G23)) | E23: =IF(OR(C23="",D23=""),"",D23-C23) | F23: =IF('Semaine 4'!D23<>"",'Semaine 4'!D23,IF('Semaine 3'!D23<>"",'Semaine 3'!D23,IF('Semaine 2'!D23<>"",'Semaine 2'!D23,IF('Semaine 1'!D23<>"",'Semaine 1'!D23,""))))
A24: =IF(Produits!$A$24="","",Produits!$A$24) | B24: =IF(Produits!$A$24="","",Produits!$C$24) | C24: =IF(COUNT('Semaine 1'!E24,'Semaine 2'!E24,'Semaine 3'!E24,'Semaine 4'!E24)=0,"",SUM('Semaine 1'!E24,'Semaine 2'!E24,'Semaine 3'!E24,'Semaine 4'!E24)) | D24: =IF(COUNT('Semaine 1'!G24,'Semaine 2'!G24,'Semaine 3'!G24,'Semaine 4'!G24)=0,"",SUM('Semaine 1'!G24,'Semaine 2'!G24,'Semaine 3'!G24,'Semaine 4'!G24)) | E24: =IF(OR(C24="",D24=""),"",D24-C24) | F24: =IF('Semaine 4'!D24<>"",'Semaine 4'!D24,IF('Semaine 3'!D24<>"",'Semaine 3'!D24,IF('Semaine 2'!D24<>"",'Semaine 2'!D24,IF('Semaine 1'!D24<>"",'Semaine 1'!D24,""))))
A25: =IF(Produits!$A$25="","",Produits!$A$25) | B25: =IF(Produits!$A$25="","",Produits!$C$25) | C25: =IF(COUNT('Semaine 1'!E25,'Semaine 2'!E25,'Semaine 3'!E25,'Semaine 4'!E25)=0,"",SUM('Semaine 1'!E25,'Semaine 2'!E25,'Semaine 3'!E25,'Semaine 4'!E25)) | D25: =IF(COUNT('Semaine 1'!G25,'Semaine 2'!G25,'Semaine 3'!G25,'Semaine 4'!G25)=0,"",SUM('Semaine 1'!G25,'Semaine 2'!G25,'Semaine 3'!G25,'Semaine 4'!G25)) | E25: =IF(OR(C25="",D25=""),"",D25-C25) | F25: =IF('Semaine 4'!D25<>"",'Semaine 4'!D25,IF('Semaine 3'!D25<>"",'Semaine 3'!D25,IF('Semaine 2'!D25<>"",'Semaine 2'!D25,IF('Semaine 1'!D25<>"",'Semaine 1'!D25,""))))
A26: =IF(Produits!$A$26="","",Produits!$A$26) | B26: =IF(Produits!$A$26="","",Produits!$C$26) | C26: =IF(COUNT('Semaine 1'!E26,'Semaine 2'!E26,'Semaine 3'!E26,'Semaine 4'!E26)=0,"",SUM('Semaine 1'!E26,'Semaine 2'!E26,'Semaine 3'!E26,'Semaine 4'!E26)) | D26: =IF(COUNT('Semaine 1'!G26,'Semaine 2'!G26,'Semaine 3'!G26,'Semaine 4'!G26)=0,"",SUM('Semaine 1'!G26,'Semaine 2'!G26,'Semaine 3'!G26,'Semaine 4'!G26)) | E26: =IF(OR(C26="",D26=""),"",D26-C26) | F26: =IF('Semaine 4'!D26<>"",'Semaine 4'!D26,IF('Semaine 3'!D26<>"",'Semaine 3'!D26,IF('Semaine 2'!D26<>"",'Semaine 2'!D26,IF('Semaine 1'!D26<>"",'Semaine 1'!D26,""))))
A27: =IF(Produits!$A$27="","",Produits!$A$27) | B27: =IF(Produits!$A$27="","",Produits!$C$27) | C27: =IF(COUNT('Semaine 1'!E27,'Semaine 2'!E27,'Semaine 3'!E27,'Semaine 4'!E27)=0,"",SUM('Semaine 1'!E27,'Semaine 2'!E27,'Semaine 3'!E27,'Semaine 4'!E27)) | D27: =IF(COUNT('Semaine 1'!G27,'Semaine 2'!G27,'Semaine 3'!G27,'Semaine 4'!G27)=0,"",SUM('Semaine 1'!G27,'Semaine 2'!G27,'Semaine 3'!G27,'Semaine 4'!G27)) | E27: =IF(OR(C27="",D27=""),"",D27-C27) | F27: =IF('Semaine 4'!D27<>"",'Semaine 4'!D27,IF('Semaine 3'!D27<>"",'Semaine 3'!D27,IF('Semaine 2'!D27<>"",'Semaine 2'!D27,IF('Semaine 1'!D27<>"",'Semaine 1'!D27,""))))
A28: =IF(Produits!$A$28="","",Produits!$A$28) | B28: =IF(Produits!$A$28="","",Produits!$C$28) | C28: =IF(COUNT('Semaine 1'!E28,'Semaine 2'!E28,'Semaine 3'!E28,'Semaine 4'!E28)=0,"",SUM('Semaine 1'!E28,'Semaine 2'!E28,'Semaine 3'!E28,'Semaine 4'!E28)) | D28: =IF(COUNT('Semaine 1'!G28,'Semaine 2'!G28,'Semaine 3'!G28,'Semaine 4'!G28)=0,"",SUM('Semaine 1'!G28,'Semaine 2'!G28,'Semaine 3'!G28,'Semaine 4'!G28)) | E28: =IF(OR(C28="",D28=""),"",D28-C28) | F28: =IF('Semaine 4'!D28<>"",'Semaine 4'!D28,IF('Semaine 3'!D28<>"",'Semaine 3'!D28,IF('Semaine 2'!D28<>"",'Semaine 2'!D28,IF('Semaine 1'!D28<>"",'Semaine 1'!D28,""))))
A29: =IF(Produits!$A$29="","",Produits!$A$29) | B29: =IF(Produits!$A$29="","",Produits!$C$29) | C29: =IF(COUNT('Semaine 1'!E29,'Semaine 2'!E29,'Semaine 3'!E29,'Semaine 4'!E29)=0,"",SUM('Semaine 1'!E29,'Semaine 2'!E29,'Semaine 3'!E29,'Semaine 4'!E29)) | D29: =IF(COUNT('Semaine 1'!G29,'Semaine 2'!G29,'Semaine 3'!G29,'Semaine 4'!G29)=0,"",SUM('Semaine 1'!G29,'Semaine 2'!G29,'Semaine 3'!G29,'Semaine 4'!G29)) | E29: =IF(OR(C29="",D29=""),"",D29-C29) | F29: =IF('Semaine 4'!D29<>"",'Semaine 4'!D29,IF('Semaine 3'!D29<>"",'Semaine 3'!D29,IF('Semaine 2'!D29<>"",'Semaine 2'!D29,IF('Semaine 1'!D29<>"",'Semaine 1'!D29,""))))
A30: =IF(Produits!$A$30="","",Produits!$A$30) | B30: =IF(Produits!$A$30="","",Produits!$C$30) | C30: =IF(COUNT('Semaine 1'!E30,'Semaine 2'!E30,'Semaine 3'!E30,'Semaine 4'!E30)=0,"",SUM('Semaine 1'!E30,'Semaine 2'!E30,'Semaine 3'!E30,'Semaine 4'!E30)) | D30: =IF(COUNT('Semaine 1'!G30,'Semaine 2'!G30,'Semaine 3'!G30,'Semaine 4'!G30)=0,"",SUM('Semaine 1'!G30,'Semaine 2'!G30,'Semaine 3'!G30,'Semaine 4'!G30)) | E30: =IF(OR(C30="",D30=""),"",D30-C30) | F30: =IF('Semaine 4'!D30<>"",'Semaine 4'!D30,IF('Semaine 3'!D30<>"",'Semaine 3'!D30,IF('Semaine 2'!D30<>"",'Semaine 2'!D30,IF('Semaine 1'!D30<>"",'Semaine 1'!D30,""))))
A31: =IF(Produits!$A$31="","",Produits!$A$31) | B31: =IF(Produits!$A$31="","",Produits!$C$31) | C31: =IF(COUNT('Semaine 1'!E31,'Semaine 2'!E31,'Semaine 3'!E31,'Semaine 4'!E31)=0,"",SUM('Semaine 1'!E31,'Semaine 2'!E31,'Semaine 3'!E31,'Semaine 4'!E31)) | D31: =IF(COUNT('Semaine 1'!G31,'Semaine 2'!G31,'Semaine 3'!G31,'Semaine 4'!G31)=0,"",SUM('Semaine 1'!G31,'Semaine 2'!G31,'Semaine 3'!G31,'Semaine 4'!G31)) | E31: =IF(OR(C31="",D31=""),"",D31-C31) | F31: =IF('Semaine 4'!D31<>"",'Semaine 4'!D31,IF('Semaine 3'!D31<>"",'Semaine 3'!D31,IF('Semaine 2'!D31<>"",'Semaine 2'!D31,IF('Semaine 1'!D31<>"",'Semaine 1'!D31,""))))
A32: =IF(Produits!$A$32="","",Produits!$A$32) | B32: =IF(Produits!$A$32="","",Produits!$C$32) | C32: =IF(COUNT('Semaine 1'!E32,'Semaine 2'!E32,'Semaine 3'!E32,'Semaine 4'!E32)=0,"",SUM('Semaine 1'!E32,'Semaine 2'!E32,'Semaine 3'!E32,'Semaine 4'!E32)) | D32: =IF(COUNT('Semaine 1'!G32,'Semaine 2'!G32,'Semaine 3'!G32,'Semaine 4'!G32)=0,"",SUM('Semaine 1'!G32,'Semaine 2'!G32,'Semaine 3'!G32,'Semaine 4'!G32)) | E32: =IF(OR(C32="",D32=""),"",D32-C32) | F32: =IF('Semaine 4'!D32<>"",'Semaine 4'!D32,IF('Semaine 3'!D32<>"",'Semaine 3'!D32,IF('Semaine 2'!D32<>"",'Semaine 2'!D32,IF('Semaine 1'!D32<>"",'Semaine 1'!D32,""))))
A33: =IF(Produits!$A$33="","",Produits!$A$33) | B33: =IF(Produits!$A$33="","",Produits!$C$33) | C33: =IF(COUNT('Semaine 1'!E33,'Semaine 2'!E33,'Semaine 3'!E33,'Semaine 4'!E33)=0,"",SUM('Semaine 1'!E33,'Semaine 2'!E33,'Semaine 3'!E33,'Semaine 4'!E33)) | D33: =IF(COUNT('Semaine 1'!G33,'Semaine 2'!G33,'Semaine 3'!G33,'Semaine 4'!G33)=0,"",SUM('Semaine 1'!G33,'Semaine 2'!G33,'Semaine 3'!G33,'Semaine 4'!G33)) | E33: =IF(OR(C33="",D33=""),"",D33-C33) | F33: =IF('Semaine 4'!D33<>"",'Semaine 4'!D33,IF('Semaine 3'!D33<>"",'Semaine 3'!D33,IF('Semaine 2'!D33<>"",'Semaine 2'!D33,IF('Semaine 1'!D33<>"",'Semaine 1'!D33,""))))
A34: =IF(Produits!$A$34="","",Produits!$A$34) | B34: =IF(Produits!$A$34="","",Produits!$C$34) | C34: =IF(COUNT('Semaine 1'!E34,'Semaine 2'!E34,'Semaine 3'!E34,'Semaine 4'!E34)=0,"",SUM('Semaine 1'!E34,'Semaine 2'!E34,'Semaine 3'!E34,'Semaine 4'!E34)) | D34: =IF(COUNT('Semaine 1'!G34,'Semaine 2'!G34,'Semaine 3'!G34,'Semaine 4'!G34)=0,"",SUM('Semaine 1'!G34,'Semaine 2'!G34,'Semaine 3'!G34,'Semaine 4'!G34)) | E34: =IF(OR(C34="",D34=""),"",D34-C34) | F34: =IF('Semaine 4'!D34<>"",'Semaine 4'!D34,IF('Semaine 3'!D34<>"",'Semaine 3'!D34,IF('Semaine 2'!D34<>"",'Semaine 2'!D34,IF('Semaine 1'!D34<>"",'Semaine 1'!D34,""))))
A35: =IF(Produits!$A$35="","",Produits!$A$35) | B35: =IF(Produits!$A$35="","",Produits!$C$35) | C35: =IF(COUNT('Semaine 1'!E35,'Semaine 2'!E35,'Semaine 3'!E35,'Semaine 4'!E35)=0,"",SUM('Semaine 1'!E35,'Semaine 2'!E35,'Semaine 3'!E35,'Semaine 4'!E35)) | D35: =IF(COUNT('Semaine 1'!G35,'Semaine 2'!G35,'Semaine 3'!G35,'Semaine 4'!G35)=0,"",SUM('Semaine 1'!G35,'Semaine 2'!G35,'Semaine 3'!G35,'Semaine 4'!G35)) | E35: =IF(OR(C35="",D35=""),"",D35-C35) | F35: =IF('Semaine 4'!D35<>"",'Semaine 4'!D35,IF('Semaine 3'!D35<>"",'Semaine 3'!D35,IF('Semaine 2'!D35<>"",'Semaine 2'!D35,IF('Semaine 1'!D35<>"",'Semaine 1'!D35,""))))
A36: =IF(Produits!$A$36="","",Produits!$A$36) | B36: =IF(Produits!$A$36="","",Produits!$C$36) | C36: =IF(COUNT('Semaine 1'!E36,'Semaine 2'!E36,'Semaine 3'!E36,'Semaine 4'!E36)=0,"",SUM('Semaine 1'!E36,'Semaine 2'!E36,'Semaine 3'!E36,'Semaine 4'!E36)) | D36: =IF(COUNT('Semaine 1'!G36,'Semaine 2'!G36,'Semaine 3'!G36,'Semaine 4'!G36)=0,"",SUM('Semaine 1'!G36,'Semaine 2'!G36,'Semaine 3'!G36,'Semaine 4'!G36)) | E36: =IF(OR(C36="",D36=""),"",D36-C36) | F36: =IF('Semaine 4'!D36<>"",'Semaine 4'!D36,IF('Semaine 3'!D36<>"",'Semaine 3'!D36,IF('Semaine 2'!D36<>"",'Semaine 2'!D36,IF('Semaine 1'!D36<>"",'Semaine 1'!D36,""))))
A37: =IF(Produits!$A$37="","",Produits!$A$37) | B37: =IF(Produits!$A$37="","",Produits!$C$37) | C37: =IF(COUNT('Semaine 1'!E37,'Semaine 2'!E37,'Semaine 3'!E37,'Semaine 4'!E37)=0,"",SUM('Semaine 1'!E37,'Semaine 2'!E37,'Semaine 3'!E37,'Semaine 4'!E37)) | D37: =IF(COUNT('Semaine 1'!G37,'Semaine 2'!G37,'Semaine 3'!G37,'Semaine 4'!G37)=0,"",SUM('Semaine 1'!G37,'Semaine 2'!G37,'Semaine 3'!G37,'Semaine 4'!G37)) | E37: =IF(OR(C37="",D37=""),"",D37-C37) | F37: =IF('Semaine 4'!D37<>"",'Semaine 4'!D37,IF('Semaine 3'!D37<>"",'Semaine 3'!D37,IF('Semaine 2'!D37<>"",'Semaine 2'!D37,IF('Semaine 1'!D37<>"",'Semaine 1'!D37,""))))
A38: =IF(Produits!$A$38="","",Produits!$A$38) | B38: =IF(Produits!$A$38="","",Produits!$C$38) | C38: =IF(COUNT('Semaine 1'!E38,'Semaine 2'!E38,'Semaine 3'!E38,'Semaine 4'!E38)=0,"",SUM('Semaine 1'!E38,'Semaine 2'!E38,'Semaine 3'!E38,'Semaine 4'!E38)) | D38: =IF(COUNT('Semaine 1'!G38,'Semaine 2'!G38,'Semaine 3'!G38,'Semaine 4'!G38)=0,"",SUM('Semaine 1'!G38,'Semaine 2'!G38,'Semaine 3'!G38,'Semaine 4'!G38)) | E38: =IF(OR(C38="",D38=""),"",D38-C38) | F38: =IF('Semaine 4'!D38<>"",'Semaine 4'!D38,IF('Semaine 3'!D38<>"",'Semaine 3'!D38,IF('Semaine 2'!D38<>"",'Semaine 2'!D38,IF('Semaine 1'!D38<>"",'Semaine 1'!D38,""))))
A39: =IF(Produits!$A$39="","",Produits!$A$39) | B39: =IF(Produits!$A$39="","",Produits!$C$39) | C39: =IF(COUNT('Semaine 1'!E39,'Semaine 2'!E39,'Semaine 3'!E39,'Semaine 4'!E39)=0,"",SUM('Semaine 1'!E39,'Semaine 2'!E39,'Semaine 3'!E39,'Semaine 4'!E39)) | D39: =IF(COUNT('Semaine 1'!G39,'Semaine 2'!G39,'Semaine 3'!G39,'Semaine 4'!G39)=0,"",SUM('Semaine 1'!G39,'Semaine 2'!G39,'Semaine 3'!G39,'Semaine 4'!G39)) | E39: =IF(OR(C39="",D39=""),"",D39-C39) | F39: =IF('Semaine 4'!D39<>"",'Semaine 4'!D39,IF('Semaine 3'!D39<>"",'Semaine 3'!D39,IF('Semaine 2'!D39<>"",'Semaine 2'!D39,IF('Semaine 1'!D39<>"",'Semaine 1'!D39,""))))
A40: =IF(Produits!$A$40="","",Produits!$A$40) | B40: =IF(Produits!$A$40="","",Produits!$C$40) | C40: =IF(COUNT('Semaine 1'!E40,'Semaine 2'!E40,'Semaine 3'!E40,'Semaine 4'!E40)=0,"",SUM('Semaine 1'!E40,'Semaine 2'!E40,'Semaine 3'!E40,'Semaine 4'!E40)) | D40: =IF(COUNT('Semaine 1'!G40,'Semaine 2'!G40,'Semaine 3'!G40,'Semaine 4'!G40)=0,"",SUM('Semaine 1'!G40,'Semaine 2'!G40,'Semaine 3'!G40,'Semaine 4'!G40)) | E40: =IF(OR(C40="",D40=""),"",D40-C40) | F40: =IF('Semaine 4'!D40<>"",'Semaine 4'!D40,IF('Semaine 3'!D40<>"",'Semaine 3'!D40,IF('Semaine 2'!D40<>"",'Semaine 2'!D40,IF('Semaine 1'!D40<>"",'Semaine 1'!D40,""))))
A41: =IF(Produits!$A$41="","",Produits!$A$41) | B41: =IF(Produits!$A$41="","",Produits!$C$41) | C41: =IF(COUNT('Semaine 1'!E41,'Semaine 2'!E41,'Semaine 3'!E41,'Semaine 4'!E41)=0,"",SUM('Semaine 1'!E41,'Semaine 2'!E41,'Semaine 3'!E41,'Semaine 4'!E41)) | D41: =IF(COUNT('Semaine 1'!G41,'Semaine 2'!G41,'Semaine 3'!G41,'Semaine 4'!G41)=0,"",SUM('Semaine 1'!G41,'Semaine 2'!G41,'Semaine 3'!G41,'Semaine 4'!G41)) | E41: =IF(OR(C41="",D41=""),"",D41-C41) | F41: =IF('Semaine 4'!D41<>"",'Semaine 4'!D41,IF('Semaine 3'!D41<>"",'Semaine 3'!D41,IF('Semaine 2'!D41<>"",'Semaine 2'!D41,IF('Semaine 1'!D41<>"",'Semaine 1'!D41,""))))
...
