Workbook

Sheet Mode d'emploi
A1: 16 · Les pertes
A2: Proposition de tableau de gestion des stocks — Excel et Google Sheets
A4: L'idée | B4: Le suivi du stock habituel, plus un carnet des pertes : produit périmé, préparation ratée, pot renversé, dégustation. À la fin du mois, tu vois ce qui part à la poubelle et pourquoi — c'est souvent ce qui explique qu'il te manque de la marchandise.
A6: Comment faire | B6: 1. Remplis l'onglet Produits une seule fois.
B7: 2. Chaque semaine : Stock, Commandé, Reçu dans l'onglet du mois.
B8: 3. Quand tu jettes ou perds quelque chose : une ligne dans « Pertes » (date, produit, quantité, raison).
B9: 4. « Bilan des pertes » : tape le mois et l'année, le total par produit et par raison s'affiche.
A11: Les onglets | B11: Produits — ta liste.
B12: Octobre 2026 — stock, commandé, reçu.
B13: Pertes — le carnet.
B14: Bilan des pertes — par produit et par raison.
A16: Couleurs | B16: Cases jaunes = à remplir. Cases blanches = calculées toutes seules, ne pas y toucher.
B17: Chiffres en bleu = exemple pour montrer le fonctionnement, à effacer.
B18: Rouge = il manque quelque chose (livraison incomplète, stock trop bas).
A20: Google Sheets | B20: Fichier > Importer > Importer ce fichier. Tout fonctionne pareil, y compris sur téléphone.

Sheet Produits
A1: Mes produits
A2: Une ligne par produit. Tout le reste du fichier se remplit à partir de cette liste.
A4: Produit | B4: Fournisseur | C4: Unité
A5: Farine T55 | B5: Metro | C5: kg
A6: Farine T45 | B6: Metro | C6: kg
A7: Sucre semoule | B7: Metro | C7: kg
A8: Sucre glace | B8: Metro | C8: kg
A9: Beurre doux | B9: Crèmerie | C9: kg
A10: Crème liquide 35% | B10: Crèmerie | C10: L
A11: Lait entier | B11: Crèmerie | C11: L
A12: Oeufs | B12: Crèmerie | C12: pièce
A13: Chocolat blanc | B13: Transgourmet | C13: kg
A14: Chocolat noir 70% | B14: Transgourmet | C14: kg
A15: Levure chimique | B15: Transgourmet | C15: kg
A16: Vanille (gousse) | B16: Transgourmet | C16: pièce

Sheet Octobre 2026
A1: Octobre 2026
A2: Stock = ce qu'il reste · Commandé = ce que tu demandes · Reçu = ce qui est arrivé
A4: Produit | B4: Fournisseur | C4: Unité | D4: Semaine 1 | G4: Semaine 2 | J4: Semaine 3 | M4: Semaine 4 | P4: Total du mois
D6: Stock | E6: Commandé | F6: Reçu | G6: Stock | H6: Commandé | I6: Reçu | J6: Stock | K6: Commandé | L6: Reçu | M6: Stock | N6: Commandé | O6: Reçu | P6: Commandé | Q6: Reçu | R6: Écart | S6: Dernier stock
A7: =IF(Produits!$A$5="","",Produits!$A$5) | B7: =IF(Produits!$A$5="","",Produits!$B$5) | C7: =IF(Produits!$A$5="","",Produits!$C$5) | D7: 8 | E7: 10 | F7: 7 | G7: 5 | H7: 10 | I7: 10 | P7: =IF(COUNT(E7,H7,K7,N7)=0,"",SUM(E7,H7,K7,N7)) | Q7: =IF(COUNT(F7,I7,L7,O7)=0,"",SUM(F7,I7,L7,O7)) | R7: =IF(OR(P7="",Q7=""),"",Q7-P7) | S7: =IF(M7<>"",M7,IF(J7<>"",J7,IF(G7<>"",G7,IF(D7<>"",D7,""))))
A8: =IF(Produits!$A$6="","",Produits!$A$6) | B8: =IF(Produits!$A$6="","",Produits!$B$6) | C8: =IF(Produits!$A$6="","",Produits!$C$6) | D8: 2 | E8: 5 | F8: 5 | G8: 3 | H8: 3 | I8: 3 | P8: =IF(COUNT(E8,H8,K8,N8)=0,"",SUM(E8,H8,K8,N8)) | Q8: =IF(COUNT(F8,I8,L8,O8)=0,"",SUM(F8,I8,L8,O8)) | R8: =IF(OR(P8="",Q8=""),"",Q8-P8) | S8: =IF(M8<>"",M8,IF(J8<>"",J8,IF(G8<>"",G8,IF(D8<>"",D8,""))))
A9: =IF(Produits!$A$7="","",Produits!$A$7) | B9: =IF(Produits!$A$7="","",Produits!$B$7) | C9: =IF(Produits!$A$7="","",Produits!$C$7) | D9: 6 | E9: 10 | F9: 10 | G9: 7 | H9: 5 | I9: 5 | P9: =IF(COUNT(E9,H9,K9,N9)=0,"",SUM(E9,H9,K9,N9)) | Q9: =IF(COUNT(F9,I9,L9,O9)=0,"",SUM(F9,I9,L9,O9)) | R9: =IF(OR(P9="",Q9=""),"",Q9-P9) | S9: =IF(M9<>"",M9,IF(J9<>"",J9,IF(G9<>"",G9,IF(D9<>"",D9,""))))
A10: =IF(Produits!$A$8="","",Produits!$A$8) | B10: =IF(Produits!$A$8="","",Produits!$B$8) | C10: =IF(Produits!$A$8="","",Produits!$C$8) | D10: 1 | E10: 3 | F10: 3 | G10: 2 | H10: 0 | I10: 0 | P10: =IF(COUNT(E10,H10,K10,N10)=0,"",SUM(E10,H10,K10,N10)) | Q10: =IF(COUNT(F10,I10,L10,O10)=0,"",SUM(F10,I10,L10,O10)) | R10: =IF(OR(P10="",Q10=""),"",Q10-P10) | S10: =IF(M10<>"",M10,IF(J10<>"",J10,IF(G10<>"",G10,IF(D10<>"",D10,""))))
A11: =IF(Produits!$A$9="","",Produits!$A$9) | B11: =IF(Produits!$A$9="","",Produits!$B$9) | C11: =IF(Produits!$A$9="","",Produits!$C$9) | D11: 3 | E11: 5 | F11: 5 | G11: 4 | H11: 5 | I11: 5 | P11: =IF(COUNT(E11,H11,K11,N11)=0,"",SUM(E11,H11,K11,N11)) | Q11: =IF(COUNT(F11,I11,L11,O11)=0,"",SUM(F11,I11,L11,O11)) | R11: =IF(OR(P11="",Q11=""),"",Q11-P11) | S11: =IF(M11<>"",M11,IF(J11<>"",J11,IF(G11<>"",G11,IF(D11<>"",D11,""))))
A12: =IF(Produits!$A$10="","",Produits!$A$10) | B12: =IF(Produits!$A$10="","",Produits!$B$10) | C12: =IF(Produits!$A$10="","",Produits!$C$10) | D12: 4 | E12: 12 | F12: 12 | G12: 5 | H12: 10 | I12: 10 | P12: =IF(COUNT(E12,H12,K12,N12)=0,"",SUM(E12,H12,K12,N12)) | Q12: =IF(COUNT(F12,I12,L12,O12)=0,"",SUM(F12,I12,L12,O12)) | R12: =IF(OR(P12="",Q12=""),"",Q12-P12) | S12: =IF(M12<>"",M12,IF(J12<>"",J12,IF(G12<>"",G12,IF(D12<>"",D12,""))))
A13: =IF(Produits!$A$11="","",Produits!$A$11) | B13: =IF(Produits!$A$11="","",Produits!$B$11) | C13: =IF(Produits!$A$11="","",Produits!$C$11) | D13: 3 | E13: 6 | F13: 6 | G13: 4 | H13: 6 | I13: 6 | P13: =IF(COUNT(E13,H13,K13,N13)=0,"",SUM(E13,H13,K13,N13)) | Q13: =IF(COUNT(F13,I13,L13,O13)=0,"",SUM(F13,I13,L13,O13)) | R13: =IF(OR(P13="",Q13=""),"",Q13-P13) | S13: =IF(M13<>"",M13,IF(J13<>"",J13,IF(G13<>"",G13,IF(D13<>"",D13,""))))
A14: =IF(Produits!$A$12="","",Produits!$A$12) | B14: =IF(Produits!$A$12="","",Produits!$B$12) | C14: =IF(Produits!$A$12="","",Produits!$C$12) | D14: 40 | E14: 90 | F14: 90 | G14: 50 | H14: 60 | I14: 60 | P14: =IF(COUNT(E14,H14,K14,N14)=0,"",SUM(E14,H14,K14,N14)) | Q14: =IF(COUNT(F14,I14,L14,O14)=0,"",SUM(F14,I14,L14,O14)) | R14: =IF(OR(P14="",Q14=""),"",Q14-P14) | S14: =IF(M14<>"",M14,IF(J14<>"",J14,IF(G14<>"",G14,IF(D14<>"",D14,""))))
A15: =IF(Produits!$A$13="","",Produits!$A$13) | B15: =IF(Produits!$A$13="","",Produits!$B$13) | C15: =IF(Produits!$A$13="","",Produits!$C$13) | D15: 1.5 | E15: 3 | F15: 2 | G15: 2 | H15: 2 | I15: 2 | P15: =IF(COUNT(E15,H15,K15,N15)=0,"",SUM(E15,H15,K15,N15)) | Q15: =IF(COUNT(F15,I15,L15,O15)=0,"",SUM(F15,I15,L15,O15)) | R15: =IF(OR(P15="",Q15=""),"",Q15-P15) | S15: =IF(M15<>"",M15,IF(J15<>"",J15,IF(G15<>"",G15,IF(D15<>"",D15,""))))
A16: =IF(Produits!$A$14="","",Produits!$A$14) | B16: =IF(Produits!$A$14="","",Produits!$B$14) | C16: =IF(Produits!$A$14="","",Produits!$C$14) | D16: 2 | E16: 2 | F16: 2 | G16: 2 | H16: 2 | I16: 2 | P16: =IF(COUNT(E16,H16,K16,N16)=0,"",SUM(E16,H16,K16,N16)) | Q16: =IF(COUNT(F16,I16,L16,O16)=0,"",SUM(F16,I16,L16,O16)) | R16: =IF(OR(P16="",Q16=""),"",Q16-P16) | S16: =IF(M16<>"",M16,IF(J16<>"",J16,IF(G16<>"",G16,IF(D16<>"",D16,""))))
A17: =IF(Produits!$A$15="","",Produits!$A$15) | B17: =IF(Produits!$A$15="","",Produits!$B$15) | C17: =IF(Produits!$A$15="","",Produits!$C$15) | D17: 0.4 | E17: 1 | F17: 1 | G17: 0.6 | H17: 0 | I17: 0 | P17: =IF(COUNT(E17,H17,K17,N17)=0,"",SUM(E17,H17,K17,N17)) | Q17: =IF(COUNT(F17,I17,L17,O17)=0,"",SUM(F17,I17,L17,O17)) | R17: =IF(OR(P17="",Q17=""),"",Q17-P17) | S17: =IF(M17<>"",M17,IF(J17<>"",J17,IF(G17<>"",G17,IF(D17<>"",D17,""))))
A18: =IF(Produits!$A$16="","",Produits!$A$16) | B18: =IF(Produits!$A$16="","",Produits!$B$16) | C18: =IF(Produits!$A$16="","",Produits!$C$16) | D18: 6 | E18: 0 | F18: 0 | G18: 6 | H18: 0 | I18: 0 | P18: =IF(COUNT(E18,H18,K18,N18)=0,"",SUM(E18,H18,K18,N18)) | Q18: =IF(COUNT(F18,I18,L18,O18)=0,"",SUM(F18,I18,L18,O18)) | R18: =IF(OR(P18="",Q18=""),"",Q18-P18) | S18: =IF(M18<>"",M18,IF(J18<>"",J18,IF(G18<>"",G18,IF(D18<>"",D18,""))))
A19: =IF(Produits!$A$17="","",Produits!$A$17) | B19: =IF(Produits!$A$17="","",Produits!$B$17) | C19: =IF(Produits!$A$17="","",Produits!$C$17) | P19: =IF(COUNT(E19,H19,K19,N19)=0,"",SUM(E19,H19,K19,N19)) | Q19: =IF(COUNT(F19,I19,L19,O19)=0,"",SUM(F19,I19,L19,O19)) | R19: =IF(OR(P19="",Q19=""),"",Q19-P19) | S19: =IF(M19<>"",M19,IF(J19<>"",J19,IF(G19<>"",G19,IF(D19<>"",D19,""))))
A20: =IF(Produits!$A$18="","",Produits!$A$18) | B20: =IF(Produits!$A$18="","",Produits!$B$18) | C20: =IF(Produits!$A$18="","",Produits!$C$18) | P20: =IF(COUNT(E20,H20,K20,N20)=0,"",SUM(E20,H20,K20,N20)) | Q20: =IF(COUNT(F20,I20,L20,O20)=0,"",SUM(F20,I20,L20,O20)) | R20: =IF(OR(P20="",Q20=""),"",Q20-P20) | S20: =IF(M20<>"",M20,IF(J20<>"",J20,IF(G20<>"",G20,IF(D20<>"",D20,""))))
A21: =IF(Produits!$A$19="","",Produits!$A$19) | B21: =IF(Produits!$A$19="","",Produits!$B$19) | C21: =IF(Produits!$A$19="","",Produits!$C$19) | P21: =IF(COUNT(E21,H21,K21,N21)=0,"",SUM(E21,H21,K21,N21)) | Q21: =IF(COUNT(F21,I21,L21,O21)=0,"",SUM(F21,I21,L21,O21)) | R21: =IF(OR(P21="",Q21=""),"",Q21-P21) | S21: =IF(M21<>"",M21,IF(J21<>"",J21,IF(G21<>"",G21,IF(D21<>"",D21,""))))
A22: =IF(Produits!$A$20="","",Produits!$A$20) | B22: =IF(Produits!$A$20="","",Produits!$B$20) | C22: =IF(Produits!$A$20="","",Produits!$C$20) | P22: =IF(COUNT(E22,H22,K22,N22)=0,"",SUM(E22,H22,K22,N22)) | Q22: =IF(COUNT(F22,I22,L22,O22)=0,"",SUM(F22,I22,L22,O22)) | R22: =IF(OR(P22="",Q22=""),"",Q22-P22) | S22: =IF(M22<>"",M22,IF(J22<>"",J22,IF(G22<>"",G22,IF(D22<>"",D22,""))))
A23: =IF(Produits!$A$21="","",Produits!$A$21) | B23: =IF(Produits!$A$21="","",Produits!$B$21) | C23: =IF(Produits!$A$21="","",Produits!$C$21) | P23: =IF(COUNT(E23,H23,K23,N23)=0,"",SUM(E23,H23,K23,N23)) | Q23: =IF(COUNT(F23,I23,L23,O23)=0,"",SUM(F23,I23,L23,O23)) | R23: =IF(OR(P23="",Q23=""),"",Q23-P23) | S23: =IF(M23<>"",M23,IF(J23<>"",J23,IF(G23<>"",G23,IF(D23<>"",D23,""))))
A24: =IF(Produits!$A$22="","",Produits!$A$22) | B24: =IF(Produits!$A$22="","",Produits!$B$22) | C24: =IF(Produits!$A$22="","",Produits!$C$22) | P24: =IF(COUNT(E24,H24,K24,N24)=0,"",SUM(E24,H24,K24,N24)) | Q24: =IF(COUNT(F24,I24,L24,O24)=0,"",SUM(F24,I24,L24,O24)) | R24: =IF(OR(P24="",Q24=""),"",Q24-P24) | S24: =IF(M24<>"",M24,IF(J24<>"",J24,IF(G24<>"",G24,IF(D24<>"",D24,""))))
A25: =IF(Produits!$A$23="","",Produits!$A$23) | B25: =IF(Produits!$A$23="","",Produits!$B$23) | C25: =IF(Produits!$A$23="","",Produits!$C$23) | P25: =IF(COUNT(E25,H25,K25,N25)=0,"",SUM(E25,H25,K25,N25)) | Q25: =IF(COUNT(F25,I25,L25,O25)=0,"",SUM(F25,I25,L25,O25)) | R25: =IF(OR(P25="",Q25=""),"",Q25-P25) | S25: =IF(M25<>"",M25,IF(J25<>"",J25,IF(G25<>"",G25,IF(D25<>"",D25,""))))
A26: =IF(Produits!$A$24="","",Produits!$A$24) | B26: =IF(Produits!$A$24="","",Produits!$B$24) | C26: =IF(Produits!$A$24="","",Produits!$C$24) | P26: =IF(COUNT(E26,H26,K26,N26)=0,"",SUM(E26,H26,K26,N26)) | Q26: =IF(COUNT(F26,I26,L26,O26)=0,"",SUM(F26,I26,L26,O26)) | R26: =IF(OR(P26="",Q26=""),"",Q26-P26) | S26: =IF(M26<>"",M26,IF(J26<>"",J26,IF(G26<>"",G26,IF(D26<>"",D26,""))))
A27: =IF(Produits!$A$25="","",Produits!$A$25) | B27: =IF(Produits!$A$25="","",Produits!$B$25) | C27: =IF(Produits!$A$25="","",Produits!$C$25) | P27: =IF(COUNT(E27,H27,K27,N27)=0,"",SUM(E27,H27,K27,N27)) | Q27: =IF(COUNT(F27,I27,L27,O27)=0,"",SUM(F27,I27,L27,O27)) | R27: =IF(OR(P27="",Q27=""),"",Q27-P27) | S27: =IF(M27<>"",M27,IF(J27<>"",J27,IF(G27<>"",G27,IF(D27<>"",D27,""))))
A28: =IF(Produits!$A$26="","",Produits!$A$26) | B28: =IF(Produits!$A$26="","",Produits!$B$26) | C28: =IF(Produits!$A$26="","",Produits!$C$26) | P28: =IF(COUNT(E28,H28,K28,N28)=0,"",SUM(E28,H28,K28,N28)) | Q28: =IF(COUNT(F28,I28,L28,O28)=0,"",SUM(F28,I28,L28,O28)) | R28: =IF(OR(P28="",Q28=""),"",Q28-P28) | S28: =IF(M28<>"",M28,IF(J28<>"",J28,IF(G28<>"",G28,IF(D28<>"",D28,""))))
A29: =IF(Produits!$A$27="","",Produits!$A$27) | B29: =IF(Produits!$A$27="","",Produits!$B$27) | C29: =IF(Produits!$A$27="","",Produits!$C$27) | P29: =IF(COUNT(E29,H29,K29,N29)=0,"",SUM(E29,H29,K29,N29)) | Q29: =IF(COUNT(F29,I29,L29,O29)=0,"",SUM(F29,I29,L29,O29)) | R29: =IF(OR(P29="",Q29=""),"",Q29-P29) | S29: =IF(M29<>"",M29,IF(J29<>"",J29,IF(G29<>"",G29,IF(D29<>"",D29,""))))
A30: =IF(Produits!$A$28="","",Produits!$A$28) | B30: =IF(Produits!$A$28="","",Produits!$B$28) | C30: =IF(Produits!$A$28="","",Produits!$C$28) | P30: =IF(COUNT(E30,H30,K30,N30)=0,"",SUM(E30,H30,K30,N30)) | Q30: =IF(COUNT(F30,I30,L30,O30)=0,"",SUM(F30,I30,L30,O30)) | R30: =IF(OR(P30="",Q30=""),"",Q30-P30) | S30: =IF(M30<>"",M30,IF(J30<>"",J30,IF(G30<>"",G30,IF(D30<>"",D30,""))))
A31: =IF(Produits!$A$29="","",Produits!$A$29) | B31: =IF(Produits!$A$29="","",Produits!$B$29) | C31: =IF(Produits!$A$29="","",Produits!$C$29) | P31: =IF(COUNT(E31,H31,K31,N31)=0,"",SUM(E31,H31,K31,N31)) | Q31: =IF(COUNT(F31,I31,L31,O31)=0,"",SUM(F31,I31,L31,O31)) | R31: =IF(OR(P31="",Q31=""),"",Q31-P31) | S31: =IF(M31<>"",M31,IF(J31<>"",J31,IF(G31<>"",G31,IF(D31<>"",D31,""))))
A32: =IF(Produits!$A$30="","",Produits!$A$30) | B32: =IF(Produits!$A$30="","",Produits!$B$30) | C32: =IF(Produits!$A$30="","",Produits!$C$30) | P32: =IF(COUNT(E32,H32,K32,N32)=0,"",SUM(E32,H32,K32,N32)) | Q32: =IF(COUNT(F32,I32,L32,O32)=0,"",SUM(F32,I32,L32,O32)) | R32: =IF(OR(P32="",Q32=""),"",Q32-P32) | S32: =IF(M32<>"",M32,IF(J32<>"",J32,IF(G32<>"",G32,IF(D32<>"",D32,""))))
A33: =IF(Produits!$A$31="","",Produits!$A$31) | B33: =IF(Produits!$A$31="","",Produits!$B$31) | C33: =IF(Produits!$A$31="","",Produits!$C$31) | P33: =IF(COUNT(E33,H33,K33,N33)=0,"",SUM(E33,H33,K33,N33)) | Q33: =IF(COUNT(F33,I33,L33,O33)=0,"",SUM(F33,I33,L33,O33)) | R33: =IF(OR(P33="",Q33=""),"",Q33-P33) | S33: =IF(M33<>"",M33,IF(J33<>"",J33,IF(G33<>"",G33,IF(D33<>"",D33,""))))
A34: =IF(Produits!$A$32="","",Produits!$A$32) | B34: =IF(Produits!$A$32="","",Produits!$B$32) | C34: =IF(Produits!$A$32="","",Produits!$C$32) | P34: =IF(COUNT(E34,H34,K34,N34)=0,"",SUM(E34,H34,K34,N34)) | Q34: =IF(COUNT(F34,I34,L34,O34)=0,"",SUM(F34,I34,L34,O34)) | R34: =IF(OR(P34="",Q34=""),"",Q34-P34) | S34: =IF(M34<>"",M34,IF(J34<>"",J34,IF(G34<>"",G34,IF(D34<>"",D34,""))))
A35: =IF(Produits!$A$33="","",Produits!$A$33) | B35: =IF(Produits!$A$33="","",Produits!$B$33) | C35: =IF(Produits!$A$33="","",Produits!$C$33) | P35: =IF(COUNT(E35,H35,K35,N35)=0,"",SUM(E35,H35,K35,N35)) | Q35: =IF(COUNT(F35,I35,L35,O35)=0,"",SUM(F35,I35,L35,O35)) | R35: =IF(OR(P35="",Q35=""),"",Q35-P35) | S35: =IF(M35<>"",M35,IF(J35<>"",J35,IF(G35<>"",G35,IF(D35<>"",D35,""))))
A36: =IF(Produits!$A$34="","",Produits!$A$34) | B36: =IF(Produits!$A$34="","",Produits!$B$34) | C36: =IF(Produits!$A$34="","",Produits!$C$34) | P36: =IF(COUNT(E36,H36,K36,N36)=0,"",SUM(E36,H36,K36,N36)) | Q36: =IF(COUNT(F36,I36,L36,O36)=0,"",SUM(F36,I36,L36,O36)) | R36: =IF(OR(P36="",Q36=""),"",Q36-P36) | S36: =IF(M36<>"",M36,IF(J36<>"",J36,IF(G36<>"",G36,IF(D36<>"",D36,""))))
A37: =IF(Produits!$A$35="","",Produits!$A$35) | B37: =IF(Produits!$A$35="","",Produits!$B$35) | C37: =IF(Produits!$A$35="","",Produits!$C$35) | P37: =IF(COUNT(E37,H37,K37,N37)=0,"",SUM(E37,H37,K37,N37)) | Q37: =IF(COUNT(F37,I37,L37,O37)=0,"",SUM(F37,I37,L37,O37)) | R37: =IF(OR(P37="",Q37=""),"",Q37-P37) | S37: =IF(M37<>"",M37,IF(J37<>"",J37,IF(G37<>"",G37,IF(D37<>"",D37,""))))
A38: =IF(Produits!$A$36="","",Produits!$A$36) | B38: =IF(Produits!$A$36="","",Produits!$B$36) | C38: =IF(Produits!$A$36="","",Produits!$C$36) | P38: =IF(COUNT(E38,H38,K38,N38)=0,"",SUM(E38,H38,K38,N38)) | Q38: =IF(COUNT(F38,I38,L38,O38)=0,"",SUM(F38,I38,L38,O38)) | R38: =IF(OR(P38="",Q38=""),"",Q38-P38) | S38: =IF(M38<>"",M38,IF(J38<>"",J38,IF(G38<>"",G38,IF(D38<>"",D38,""))))
A39: =IF(Produits!$A$37="","",Produits!$A$37) | B39: =IF(Produits!$A$37="","",Produits!$B$37) | C39: =IF(Produits!$A$37="","",Produits!$C$37) | P39: =IF(COUNT(E39,H39,K39,N39)=0,"",SUM(E39,H39,K39,N39)) | Q39: =IF(COUNT(F39,I39,L39,O39)=0,"",SUM(F39,I39,L39,O39)) | R39: =IF(OR(P39="",Q39=""),"",Q39-P39) | S39: =IF(M39<>"",M39,IF(J39<>"",J39,IF(G39<>"",G39,IF(D39<>"",D39,""))))
A40: =IF(Produits!$A$38="","",Produits!$A$38) | B40: =IF(Produits!$A$38="","",Produits!$B$38) | C40: =IF(Produits!$A$38="","",Produits!$C$38) | P40: =IF(COUNT(E40,H40,K40,N40)=0,"",SUM(E40,H40,K40,N40)) | Q40: =IF(COUNT(F40,I40,L40,O40)=0,"",SUM(F40,I40,L40,O40)) | R40: =IF(OR(P40="",Q40=""),"",Q40-P40) | S40: =IF(M40<>"",M40,IF(J40<>"",J40,IF(G40<>"",G40,IF(D40<>"",D40,""))))
A41: =IF(Produits!$A$39="","",Produits!$A$39) | B41: =IF(Produits!$A$39="","",Produits!$B$39) | C41: =IF(Produits!$A$39="","",Produits!$C$39) | P41: =IF(COUNT(E41,H41,K41,N41)=0,"",SUM(E41,H41,K41,N41)) | Q41: =IF(COUNT(F41,I41,L41,O41)=0,"",SUM(F41,I41,L41,O41)) | R41: =IF(OR(P41="",Q41=""),"",Q41-P41) | S41: =IF(M41<>"",M41,IF(J41<>"",J41,IF(G41<>"",G41,IF(D41<>"",D41,""))))
A42: =IF(Produits!$A$40="","",Produits!$A$40) | B42: =IF(Produits!$A$40="","",Produits!$B$40) | C42: =IF(Produits!$A$40="","",Produits!$C$40) | P42: =IF(COUNT(E42,H42,K42,N42)=0,"",SUM(E42,H42,K42,N42)) | Q42: =IF(COUNT(F42,I42,L42,O42)=0,"",SUM(F42,I42,L42,O42)) | R42: =IF(OR(P42="",Q42=""),"",Q42-P42) | S42: =IF(M42<>"",M42,IF(J42<>"",J42,IF(G42<>"",G42,IF(D42<>"",D42,""))))
...

Sheet Pertes
A1: Carnet des pertes
A2: Une ligne par perte
A4: Date | B4: Produit | C4: Quantité | D4: Unité | E4: Raison | F4: Note | G4: Mois | H4: Année
A5: =DATE(2026,10,3) | B5: Crème liquide 35% | C5: 1 | D5: =IF(B5="","",IFERROR(INDEX(Produits!$C$5:$C$44,MATCH(B5,Produits!$A$5:$A$44,0)),"")) | E5: Périmé | F5: Bouteille ouverte oubliée | G5: =IF(A5="","",MONTH(A5)) | H5: =IF(A5="","",YEAR(A5))
A6: =DATE(2026,10,6) | B6: Chocolat blanc | C6: 0.3 | D6: =IF(B6="","",IFERROR(INDEX(Produits!$C$5:$C$44,MATCH(B6,Produits!$A$5:$A$44,0)),"")) | E6: Raté | F6: Ganache tranchée | G6: =IF(A6="","",MONTH(A6)) | H6: =IF(A6="","",YEAR(A6))
A7: =DATE(2026,10,8) | B7: Oeufs | C7: 6 | D7: =IF(B7="","",IFERROR(INDEX(Produits!$C$5:$C$44,MATCH(B7,Produits!$A$5:$A$44,0)),"")) | E7: Cassé / renversé | F7: Plateau tombé | G7: =IF(A7="","",MONTH(A7)) | H7: =IF(A7="","",YEAR(A7))
A8: =DATE(2026,10,9) | B8: Beurre doux | C8: 0.2 | D8: =IF(B8="","",IFERROR(INDEX(Produits!$C$5:$C$44,MATCH(B8,Produits!$A$5:$A$44,0)),"")) | E8: Dégustation | F8: Essai nouvelle recette | G8: =IF(A8="","",MONTH(A8)) | H8: =IF(A8="","",YEAR(A8))
D9: =IF(B9="","",IFERROR(INDEX(Produits!$C$5:$C$44,MATCH(B9,Produits!$A$5:$A$44,0)),"")) | G9: =IF(A9="","",MONTH(A9)) | H9: =IF(A9="","",YEAR(A9))
D10: =IF(B10="","",IFERROR(INDEX(Produits!$C$5:$C$44,MATCH(B10,Produits!$A$5:$A$44,0)),"")) | G10: =IF(A10="","",MONTH(A10)) | H10: =IF(A10="","",YEAR(A10))
D11: =IF(B11="","",IFERROR(INDEX(Produits!$C$5:$C$44,MATCH(B11,Produits!$A$5:$A$44,0)),"")) | G11: =IF(A11="","",MONTH(A11)) | H11: =IF(A11="","",YEAR(A11))
D12: =IF(B12="","",IFERROR(INDEX(Produits!$C$5:$C$44,MATCH(B12,Produits!$A$5:$A$44,0)),"")) | G12: =IF(A12="","",MONTH(A12)) | H12: =IF(A12="","",YEAR(A12))
D13: =IF(B13="","",IFERROR(INDEX(Produits!$C$5:$C$44,MATCH(B13,Produits!$A$5:$A$44,0)),"")) | G13: =IF(A13="","",MONTH(A13)) | H13: =IF(A13="","",YEAR(A13))
D14: =IF(B14="","",IFERROR(INDEX(Produits!$C$5:$C$44,MATCH(B14,Produits!$A$5:$A$44,0)),"")) | G14: =IF(A14="","",MONTH(A14)) | H14: =IF(A14="","",YEAR(A14))
D15: =IF(B15="","",IFERROR(INDEX(Produits!$C$5:$C$44,MATCH(B15,Produits!$A$5:$A$44,0)),"")) | G15: =IF(A15="","",MONTH(A15)) | H15: =IF(A15="","",YEAR(A15))
D16: =IF(B16="","",IFERROR(INDEX(Produits!$C$5:$C$44,MATCH(B16,Produits!$A$5:$A$44,0)),"")) | G16: =IF(A16="","",MONTH(A16)) | H16: =IF(A16="","",YEAR(A16))
D17: =IF(B17="","",IFERROR(INDEX(Produits!$C$5:$C$44,MATCH(B17,Produits!$A$5:$A$44,0)),"")) | G17: =IF(A17="","",MONTH(A17)) | H17: =IF(A17="","",YEAR(A17))
D18: =IF(B18="","",IFERROR(INDEX(Produits!$C$5:$C$44,MATCH(B18,Produits!$A$5:$A$44,0)),"")) | G18: =IF(A18="","",MONTH(A18)) | H18: =IF(A18="","",YEAR(A18))
D19: =IF(B19="","",IFERROR(INDEX(Produits!$C$5:$C$44,MATCH(B19,Produits!$A$5:$A$44,0)),"")) | G19: =IF(A19="","",MONTH(A19)) | H19: =IF(A19="","",YEAR(A19))
D20: =IF(B20="","",IFERROR(INDEX(Produits!$C$5:$C$44,MATCH(B20,Produits!$A$5:$A$44,0)),"")) | G20: =IF(A20="","",MONTH(A20)) | H20: =IF(A20="","",YEAR(A20))
... D154: =IF(B154="","",IFERROR(INDEX(Produits!$C$5:$C$44,MATCH(B154,Produits!$A$5:$A$44,0)),"")) | G154: =IF(A154="","",MONTH(A154)) | H154: =IF(A154="","",YEAR(A154))

Sheet Bilan des pertes
A1: Bilan des pertes
A2: Tape le mois et l'année dans les cases jaunes
A3: Mois (1 à 12) | B3: 10 | C3: Année | D3: 2026
A5: Produit | B5: Unité | C5: Périmé | D5: Raté | E5: Cassé / renversé | F5: Dégustation | G5: Autre | H5: Total perdu
A6: =IF(Produits!$A$5="","",Produits!$A$5) | B6: =IF(Produits!$A$5="","",Produits!$C$5) | C6: =IF($A6="","",IF(SUMIFS(Pertes!$C$5:$C$154,Pertes!$B$5:$B$154,$A6,Pertes!$E$5:$E$154,"Périmé",Pertes!$G$5:$G$154,$B$3,Pertes!$H$5:$H$154,$D$3)=0,"",SUMIFS(Pertes!$C$5:$C$154,Pertes!$B$5:$B$154,$A6,Pertes!$E$5:$E$154,"Périmé",Pertes!$G$5:$G$154,$B$3,Pertes!$H$5:$H$154,$D$3))) | D6: =IF($A6="","",IF(SUMIFS(Pertes!$C$5:$C$154,Pertes!$B$5:$B$154,$A6,Pertes!$E$5:$E$154,"Raté",Pertes!$G$5:$G$154,$B$3,Pertes!$H$5:$H$154,$D$3)=0,"",SUMIFS(Pertes!$C$5:$C$154,Pertes!$B$5:$B$154,$A6,Pertes!$E$5:$E$154,"Raté",Pertes!$G$5:$G$154,$B$3,Pertes!$H$5:$H$154,$D$3))) | E6: =IF($A6="","",IF(SUMIFS(Pertes!$C$5:$C$154,Pertes!$B$5:$B$154,$A6,Pertes!$E$5:$E$154,"Cassé / renversé",Pertes!$G$5:$G$154,$B$3,Pertes!$H$5:$H$154,$D$3)=0,"",SUMIFS(Pertes!$C$5:$C$154,Pertes!$B$5:$B$154,$A6,Pertes!$E$5:$E$154,"Cassé / renversé",Pertes!$G$5:$G$154,$B$3,Pertes!$H$5:$H$154,$D$3))) | F6: =IF($A6="","",IF(SUMIFS(Pertes!$C$5:$C$154,Pertes!$B$5:$B$154,$A6,Pertes!$E$5:$E$154,"Dégustation",Pertes!$G$5:$G$154,$B$3,Pertes!$H$5:$H$154,$D$3)=0,"",SUMIFS(Pertes!$C$5:$C$154,Pertes!$B$5:$B$154,$A6,Pertes!$E$5:$E$154,"Dégustation",Pertes!$G$5:$G$154,$B$3,Pertes!$H$5:$H$154,$D$3))) | G6: =IF($A6="","",IF(SUMIFS(Pertes!$C$5:$C$154,Pertes!$B$5:$B$154,$A6,Pertes!$E$5:$E$154,"Autre",Pertes!$G$5:$G$154,$B$3,Pertes!$H$5:$H$154,$D$3)=0,"",SUMIFS(Pertes!$C$5:$C$154,Pertes!$B$5:$B$154,$A6,Pertes!$E$5:$E$154,"Autre",Pertes!$G$5:$G$154,$B$3,Pertes!$H$5:$H$154,$D$3))) | H6: =IF(COUNT(C6:G6)=0,"",SUM(C6:G6))
A7: =IF(Produits!$A$6="","",Produits!$A$6) | B7: =IF(Produits!$A$6="","",Produits!$C$6) | C7: =IF($A7="","",IF(SUMIFS(Pertes!$C$5:$C$154,Pertes!$B$5:$B$154,$A7,Pertes!$E$5:$E$154,"Périmé",Pertes!$G$5:$G$154,$B$3,Pertes!$H$5:$H$154,$D$3)=0,"",SUMIFS(Pertes!$C$5:$C$154,Pertes!$B$5:$B$154,$A7,Pertes!$E$5:$E$154,"Périmé",Pertes!$G$5:$G$154,$B$3,Pertes!$H$5:$H$154,$D$3))) | D7: =IF($A7="","",IF(SUMIFS(Pertes!$C$5:$C$154,Pertes!$B$5:$B$154,$A7,Pertes!$E$5:$E$154,"Raté",Pertes!$G$5:$G$154,$B$3,Pertes!$H$5:$H$154,$D$3)=0,"",SUMIFS(Pertes!$C$5:$C$154,Pertes!$B$5:$B$154,$A7,Pertes!$E$5:$E$154,"Raté",Pertes!$G$5:$G$154,$B$3,Pertes!$H$5:$H$154,$D$3))) | E7: =IF($A7="","",IF(SUMIFS(Pertes!$C$5:$C$154,Pertes!$B$5:$B$154,$A7,Pertes!$E$5:$E$154,"Cassé / renversé",Pertes!$G$5:$G$154,$B$3,Pertes!$H$5:$H$154,$D$3)=0,"",SUMIFS(Pertes!$C$5:$C$154,Pertes!$B$5:$B$154,$A7,Pertes!$E$5:$E$154,"Cassé / renversé",Pertes!$G$5:$G$154,$B$3,Pertes!$H$5:$H$154,$D$3))) | F7: =IF($A7="","",IF(SUMIFS(Pertes!$C$5:$C$154,Pertes!$B$5:$B$154,$A7,Pertes!$E$5:$E$154,"Dégustation",Pertes!$G$5:$G$154,$B$3,Pertes!$H$5:$H$154,$D$3)=0,"",SUMIFS(Pertes!$C$5:$C$154,Pertes!$B$5:$B$154,$A7,Pertes!$E$5:$E$154,"Dégustation",Pertes!$G$5:$G$154,$B$3,Pertes!$H$5:$H$154,$D$3))) | G7: =IF($A7="","",IF(SUMIFS(Pertes!$C$5:$C$154,Pertes!$B$5:$B$154,$A7,Pertes!$E$5:$E$154,"Autre",Pertes!$G$5:$G$154,$B$3,Pertes!$H$5:$H$154,$D$3)=0,"",SUMIFS(Pertes!$C$5:$C$154,Pertes!$B$5:$B$154,$A7,Pertes!$E$5:$E$154,"Autre",Pertes!$G$5:$G$154,$B$3,Pertes!$H$5:$H$154,$D$3))) | H7: =IF(COUNT(C7:G7)=0,"",SUM(C7:G7))
A8: =IF(Produits!$A$7="","",Produits!$A$7) | B8: =IF(Produits!$A$7="","",Produits!$C$7) | C8: =IF($A8="","",IF(SUMIFS(Pertes!$C$5:$C$154,Pertes!$B$5:$B$154,$A8,Pertes!$E$5:$E$154,"Périmé",Pertes!$G$5:$G$154,$B$3,Pertes!$H$5:$H$154,$D$3)=0,"",SUMIFS(Pertes!$C$5:$C$154,Pertes!$B$5:$B$154,$A8,Pertes!$E$5:$E$154,"Périmé",Pertes!$G$5:$G$154,$B$3,Pertes!$H$5:$H$154,$D$3))) | D8: =IF($A8="","",IF(SUMIFS(Pertes!$C$5:$C$154,Pertes!$B$5:$B$154,$A8,Pertes!$E$5:$E$154,"Raté",Pertes!$G$5:$G$154,$B$3,Pertes!$H$5:$H$154,$D$3)=0,"",SUMIFS(Pertes!$C$5:$C$154,Pertes!$B$5:$B$154,$A8,Pertes!$E$5:$E$154,"Raté",Pertes!$G$5:$G$154,$B$3,Pertes!$H$5:$H$154,$D$3))) | E8: =IF($A8="","",IF(SUMIFS(Pertes!$C$5:$C$154,Pertes!$B$5:$B$154,$A8,Pertes!$E$5:$E$154,"Cassé / renversé",Pertes!$G$5:$G$154,$B$3,Pertes!$H$5:$H$154,$D$3)=0,"",SUMIFS(Pertes!$C$5:$C$154,Pertes!$B$5:$B$154,$A8,Pertes!$E$5:$E$154,"Cassé / renversé",Pertes!$G$5:$G$154,$B$3,Pertes!$H$5:$H$154,$D$3))) | F8: =IF($A8="","",IF(SUMIFS(Pertes!$C$5:$C$154,Pertes!$B$5:$B$154,$A8,Pertes!$E$5:$E$154,"Dégustation",Pertes!$G$5:$G$154,$B$3,Pertes!$H$5:$H$154,$D$3)=0,"",SUMIFS(Pertes!$C$5:$C$154,Pertes!$B$5:$B$154,$A8,Pertes!$E$5:$E$154,"Dégustation",Pertes!$G$5:$G$154,$B$3,Pertes!$H$5:$H$154,$D$3))) | G8: =IF($A8="","",IF(SUMIFS(Pertes!$C$5:$C$154,Pertes!$B$5:$B$154,$A8,Pertes!$E$5:$E$154,"Autre",Pertes!$G$5:$G$154,$B$3,Pertes!$H$5:$H$154,$D$3)=0,"",SUMIFS(Pertes!$C$5:$C$154,Pertes!$B$5:$B$154,$A8,Pertes!$E$5:$E$154,"Autre",Pertes!$G$5:$G$154,$B$3,Pertes!$H$5:$H$154,$D$3))) | H8: =IF(COUNT(C8:G8)=0,"",SUM(C8:G8))
A9: =IF(Produits!$A$8="","",Produits!$A$8) | B9: =IF(Produits!$A$8="","",Produits!$C$8) | C9: =IF($A9="","",IF(SUMIFS(Pertes!$C$5:$C$154,Pertes!$B$5:$B$154,$A9,Pertes!$E$5:$E$154,"Périmé",Pertes!$G$5:$G$154,$B$3,Pertes!$H$5:$H$154,$D$3)=0,"",SUMIFS(Pertes!$C$5:$C$154,Pertes!$B$5:$B$154,$A9,Pertes!$E$5:$E$154,"Périmé",Pertes!$G$5:$G$154,$B$3,Pertes!$H$5:$H$154,$D$3))) | D9: =IF($A9="","",IF(SUMIFS(Pertes!$C$5:$C$154,Pertes!$B$5:$B$154,$A9,Pertes!$E$5:$E$154,"Raté",Pertes!$G$5:$G$154,$B$3,Pertes!$H$5:$H$154,$D$3)=0,"",SUMIFS(Pertes!$C$5:$C$154,Pertes!$B$5:$B$154,$A9,Pertes!$E$5:$E$154,"Raté",Pertes!$G$5:$G$154,$B$3,Pertes!$H$5:$H$154,$D$3))) | E9: =IF($A9="","",IF(SUMIFS(Pertes!$C$5:$C$154,Pertes!$B$5:$B$154,$A9,Pertes!$E$5:$E$154,"Cassé / renversé",Pertes!$G$5:$G$154,$B$3,Pertes!$H$5:$H$154,$D$3)=0,"",SUMIFS(Pertes!$C$5:$C$154,Pertes!$B$5:$B$154,$A9,Pertes!$E$5:$E$154,"Cassé / renversé",Pertes!$G$5:$G$154,$B$3,Pertes!$H$5:$H$154,$D$3))) | F9: =IF($A9="","",IF(SUMIFS(Pertes!$C$5:$C$154,Pertes!$B$5:$B$154,$A9,Pertes!$E$5:$E$154,"Dégustation",Pertes!$G$5:$G$154,$B$3,Pertes!$H$5:$H$154,$D$3)=0,"",SUMIFS(Pertes!$C$5:$C$154,Pertes!$B$5:$B$154,$A9,Pertes!$E$5:$E$154,"Dégustation",Pertes!$G$5:$G$154,$B$3,Pertes!$H$5:$H$154,$D$3))) | G9: =IF($A9="","",IF(SUMIFS(Pertes!$C$5:$C$154,Pertes!$B$5:$B$154,$A9,Pertes!$E$5:$E$154,"Autre",Pertes!$G$5:$G$154,$B$3,Pertes!$H$5:$H$154,$D$3)=0,"",SUMIFS(Pertes!$C$5:$C$154,Pertes!$B$5:$B$154,$A9,Pertes!$E$5:$E$154,"Autre",Pertes!$G$5:$G$154,$B$3,Pertes!$H$5:$H$154,$D$3))) | H9: =IF(COUNT(C9:G9)=0,"",SUM(C9:G9))
A10: =IF(Produits!$A$9="","",Produits!$A$9) | B10: =IF(Produits!$A$9="","",Produits!$C$9) | C10: =IF($A10="","",IF(SUMIFS(Pertes!$C$5:$C$154,Pertes!$B$5:$B$154,$A10,Pertes!$E$5:$E$154,"Périmé",Pertes!$G$5:$G$154,$B$3,Pertes!$H$5:$H$154,$D$3)=0,"",SUMIFS(Pertes!$C$5:$C$154,Pertes!$B$5:$B$154,$A10,Pertes!$E$5:$E$154,"Périmé",Pertes!$G$5:$G$154,$B$3,Pertes!$H$5:$H$154,$D$3))) | D10: =IF($A10="","",IF(SUMIFS(Pertes!$C$5:$C$154,Pertes!$B$5:$B$154,$A10,Pertes!$E$5:$E$154,"Raté",Pertes!$G$5:$G$154,$B$3,Pertes!$H$5:$H$154,$D$3)=0,"",SUMIFS(Pertes!$C$5:$C$154,Pertes!$B$5:$B$154,$A10,Pertes!$E$5:$E$154,"Raté",Pertes!$G$5:$G$154,$B$3,Pertes!$H$5:$H$154,$D$3))) | E10: =IF($A10="","",IF(SUMIFS(Pertes!$C$5:$C$154,Pertes!$B$5:$B$154,$A10,Pertes!$E$5:$E$154,"Cassé / renversé",Pertes!$G$5:$G$154,$B$3,Pertes!$H$5:$H$154,$D$3)=0,"",SUMIFS(Pertes!$C$5:$C$154,Pertes!$B$5:$B$154,$A10,Pertes!$E$5:$E$154,"Cassé / renversé",Pertes!$G$5:$G$154,$B$3,Pertes!$H$5:$H$154,$D$3))) | F10: =IF($A10="","",IF(SUMIFS(Pertes!$C$5:$C$154,Pertes!$B$5:$B$154,$A10,Pertes!$E$5:$E$154,"Dégustation",Pertes!$G$5:$G$154,$B$3,Pertes!$H$5:$H$154,$D$3)=0,"",SUMIFS(Pertes!$C$5:$C$154,Pertes!$B$5:$B$154,$A10,Pertes!$E$5:$E$154,"Dégustation",Pertes!$G$5:$G$154,$B$3,Pertes!$H$5:$H$154,$D$3))) | G10: =IF($A10="","",IF(SUMIFS(Pertes!$C$5:$C$154,Pertes!$B$5:$B$154,$A10,Pertes!$E$5:$E$154,"Autre",Pertes!$G$5:$G$154,$B$3,Pertes!$H$5:$H$154,$D$3)=0,"",SUMIFS(Pertes!$C$5:$C$154,Pertes!$B$5:$B$154,$A10,Pertes!$E$5:$E$154,"Autre",Pertes!$G$5:$G$154,$B$3,Pertes!$H$5:$H$154,$D$3))) | H10: =IF(COUNT(C10:G10)=0,"",SUM(C10:G10))
A11: =IF(Produits!$A$10="","",Produits!$A$10) | B11: =IF(Produits!$A$10="","",Produits!$C$10) | C11: =IF($A11="","",IF(SUMIFS(Pertes!$C$5:$C$154,Pertes!$B$5:$B$154,$A11,Pertes!$E$5:$E$154,"Périmé",Pertes!$G$5:$G$154,$B$3,Pertes!$H$5:$H$154,$D$3)=0,"",SUMIFS(Pertes!$C$5:$C$154,Pertes!$B$5:$B$154,$A11,Pertes!$E$5:$E$154,"Périmé",Pertes!$G$5:$G$154,$B$3,Pertes!$H$5:$H$154,$D$3))) | D11: =IF($A11="","",IF(SUMIFS(Pertes!$C$5:$C$154,Pertes!$B$5:$B$154,$A11,Pertes!$E$5:$E$154,"Raté",Pertes!$G$5:$G$154,$B$3,Pertes!$H$5:$H$154,$D$3)=0,"",SUMIFS(Pertes!$C$5:$C$154,Pertes!$B$5:$B$154,$A11,Pertes!$E$5:$E$154,"Raté",Pertes!$G$5:$G$154,$B$3,Pertes!$H$5:$H$154,$D$3))) | E11: =IF($A11="","",IF(SUMIFS(Pertes!$C$5:$C$154,Pertes!$B$5:$B$154,$A11,Pertes!$E$5:$E$154,"Cassé / renversé",Pertes!$G$5:$G$154,$B$3,Pertes!$H$5:$H$154,$D$3)=0,"",SUMIFS(Pertes!$C$5:$C$154,Pertes!$B$5:$B$154,$A11,Pertes!$E$5:$E$154,"Cassé / renversé",Pertes!$G$5:$G$154,$B$3,Pertes!$H$5:$H$154,$D$3))) | F11: =IF($A11="","",IF(SUMIFS(Pertes!$C$5:$C$154,Pertes!$B$5:$B$154,$A11,Pertes!$E$5:$E$154,"Dégustation",Pertes!$G$5:$G$154,$B$3,Pertes!$H$5:$H$154,$D$3)=0,"",SUMIFS(Pertes!$C$5:$C$154,Pertes!$B$5:$B$154,$A11,Pertes!$E$5:$E$154,"Dégustation",Pertes!$G$5:$G$154,$B$3,Pertes!$H$5:$H$154,$D$3))) | G11: =IF($A11="","",IF(SUMIFS(Pertes!$C$5:$C$154,Pertes!$B$5:$B$154,$A11,Pertes!$E$5:$E$154,"Autre",Pertes!$G$5:$G$154,$B$3,Pertes!$H$5:$H$154,$D$3)=0,"",SUMIFS(Pertes!$C$5:$C$154,Pertes!$B$5:$B$154,$A11,Pertes!$E$5:$E$154,"Autre",Pertes!$G$5:$G$154,$B$3,Pertes!$H$5:$H$154,$D$3))) | H11: =IF(COUNT(C11:G11)=0,"",SUM(C11:G11))
A12: =IF(Produits!$A$11="","",Produits!$A$11) | B12: =IF(Produits!$A$11="","",Produits!$C$11) | C12: =IF($A12="","",IF(SUMIFS(Pertes!$C$5:$C$154,Pertes!$B$5:$B$154,$A12,Pertes!$E$5:$E$154,"Périmé",Pertes!$G$5:$G$154,$B$3,Pertes!$H$5:$H$154,$D$3)=0,"",SUMIFS(Pertes!$C$5:$C$154,Pertes!$B$5:$B$154,$A12,Pertes!$E$5:$E$154,"Périmé",Pertes!$G$5:$G$154,$B$3,Pertes!$H$5:$H$154,$D$3))) | D12: =IF($A12="","",IF(SUMIFS(Pertes!$C$5:$C$154,Pertes!$B$5:$B$154,$A12,Pertes!$E$5:$E$154,"Raté",Pertes!$G$5:$G$154,$B$3,Pertes!$H$5:$H$154,$D$3)=0,"",SUMIFS(Pertes!$C$5:$C$154,Pertes!$B$5:$B$154,$A12,Pertes!$E$5:$E$154,"Raté",Pertes!$G$5:$G$154,$B$3,Pertes!$H$5:$H$154,$D$3))) | E12: =IF($A12="","",IF(SUMIFS(Pertes!$C$5:$C$154,Pertes!$B$5:$B$154,$A12,Pertes!$E$5:$E$154,"Cassé / renversé",Pertes!$G$5:$G$154,$B$3,Pertes!$H$5:$H$154,$D$3)=0,"",SUMIFS(Pertes!$C$5:$C$154,Pertes!$B$5:$B$154,$A12,Pertes!$E$5:$E$154,"Cassé / renversé",Pertes!$G$5:$G$154,$B$3,Pertes!$H$5:$H$154,$D$3))) | F12: =IF($A12="","",IF(SUMIFS(Pertes!$C$5:$C$154,Pertes!$B$5:$B$154,$A12,Pertes!$E$5:$E$154,"Dégustation",Pertes!$G$5:$G$154,$B$3,Pertes!$H$5:$H$154,$D$3)=0,"",SUMIFS(Pertes!$C$5:$C$154,Pertes!$B$5:$B$154,$A12,Pertes!$E$5:$E$154,"Dégustation",Pertes!$G$5:$G$154,$B$3,Pertes!$H$5:$H$154,$D$3))) | G12: =IF($A12="","",IF(SUMIFS(Pertes!$C$5:$C$154,Pertes!$B$5:$B$154,$A12,Pertes!$E$5:$E$154,"Autre",Pertes!$G$5:$G$154,$B$3,Pertes!$H$5:$H$154,$D$3)=0,"",SUMIFS(Pertes!$C$5:$C$154,Pertes!$B$5:$B$154,$A12,Pertes!$E$5:$E$154,"Autre",Pertes!$G$5:$G$154,$B$3,Pertes!$H$5:$H$154,$D$3))) | H12: =IF(COUNT(C12:G12)=0,"",SUM(C12:G12))
A13: =IF(Produits!$A$12="","",Produits!$A$12) | B13: =IF(Produits!$A$12="","",Produits!$C$12) | C13: =IF($A13="","",IF(SUMIFS(Pertes!$C$5:$C$154,Pertes!$B$5:$B$154,$A13,Pertes!$E$5:$E$154,"Périmé",Pertes!$G$5:$G$154,$B$3,Pertes!$H$5:$H$154,$D$3)=0,"",SUMIFS(Pertes!$C$5:$C$154,Pertes!$B$5:$B$154,$A13,Pertes!$E$5:$E$154,"Périmé",Pertes!$G$5:$G$154,$B$3,Pertes!$H$5:$H$154,$D$3))) | D13: =IF($A13="","",IF(SUMIFS(Pertes!$C$5:$C$154,Pertes!$B$5:$B$154,$A13,Pertes!$E$5:$E$154,"Raté",Pertes!$G$5:$G$154,$B$3,Pertes!$H$5:$H$154,$D$3)=0,"",SUMIFS(Pertes!$C$5:$C$154,Pertes!$B$5:$B$154,$A13,Pertes!$E$5:$E$154,"Raté",Pertes!$G$5:$G$154,$B$3,Pertes!$H$5:$H$154,$D$3))) | E13: =IF($A13="","",IF(SUMIFS(Pertes!$C$5:$C$154,Pertes!$B$5:$B$154,$A13,Pertes!$E$5:$E$154,"Cassé / renversé",Pertes!$G$5:$G$154,$B$3,Pertes!$H$5:$H$154,$D$3)=0,"",SUMIFS(Pertes!$C$5:$C$154,Pertes!$B$5:$B$154,$A13,Pertes!$E$5:$E$154,"Cassé / renversé",Pertes!$G$5:$G$154,$B$3,Pertes!$H$5:$H$154,$D$3))) | F13: =IF($A13="","",IF(SUMIFS(Pertes!$C$5:$C$154,Pertes!$B$5:$B$154,$A13,Pertes!$E$5:$E$154,"Dégustation",Pertes!$G$5:$G$154,$B$3,Pertes!$H$5:$H$154,$D$3)=0,"",SUMIFS(Pertes!$C$5:$C$154,Pertes!$B$5:$B$154,$A13,Pertes!$E$5:$E$154,"Dégustation",Pertes!$G$5:$G$154,$B$3,Pertes!$H$5:$H$154,$D$3))) | G13: =IF($A13="","",IF(SUMIFS(Pertes!$C$5:$C$154,Pertes!$B$5:$B$154,$A13,Pertes!$E$5:$E$154,"Autre",Pertes!$G$5:$G$154,$B$3,Pertes!$H$5:$H$154,$D$3)=0,"",SUMIFS(Pertes!$C$5:$C$154,Pertes!$B$5:$B$154,$A13,Pertes!$E$5:$E$154,"Autre",Pertes!$G$5:$G$154,$B$3,Pertes!$H$5:$H$154,$D$3))) | H13: =IF(COUNT(C13:G13)=0,"",SUM(C13:G13))
A14: =IF(Produits!$A$13="","",Produits!$A$13) | B14: =IF(Produits!$A$13="","",Produits!$C$13) | C14: =IF($A14="","",IF(SUMIFS(Pertes!$C$5:$C$154,Pertes!$B$5:$B$154,$A14,Pertes!$E$5:$E$154,"Périmé",Pertes!$G$5:$G$154,$B$3,Pertes!$H$5:$H$154,$D$3)=0,"",SUMIFS(Pertes!$C$5:$C$154,Pertes!$B$5:$B$154,$A14,Pertes!$E$5:$E$154,"Périmé",Pertes!$G$5:$G$154,$B$3,Pertes!$H$5:$H$154,$D$3))) | D14: =IF($A14="","",IF(SUMIFS(Pertes!$C$5:$C$154,Pertes!$B$5:$B$154,$A14,Pertes!$E$5:$E$154,"Raté",Pertes!$G$5:$G$154,$B$3,Pertes!$H$5:$H$154,$D$3)=0,"",SUMIFS(Pertes!$C$5:$C$154,Pertes!$B$5:$B$154,$A14,Pertes!$E$5:$E$154,"Raté",Pertes!$G$5:$G$154,$B$3,Pertes!$H$5:$H$154,$D$3))) | E14: =IF($A14="","",IF(SUMIFS(Pertes!$C$5:$C$154,Pertes!$B$5:$B$154,$A14,Pertes!$E$5:$E$154,"Cassé / renversé",Pertes!$G$5:$G$154,$B$3,Pertes!$H$5:$H$154,$D$3)=0,"",SUMIFS(Pertes!$C$5:$C$154,Pertes!$B$5:$B$154,$A14,Pertes!$E$5:$E$154,"Cassé / renversé",Pertes!$G$5:$G$154,$B$3,Pertes!$H$5:$H$154,$D$3))) | F14: =IF($A14="","",IF(SUMIFS(Pertes!$C$5:$C$154,Pertes!$B$5:$B$154,$A14,Pertes!$E$5:$E$154,"Dégustation",Pertes!$G$5:$G$154,$B$3,Pertes!$H$5:$H$154,$D$3)=0,"",SUMIFS(Pertes!$C$5:$C$154,Pertes!$B$5:$B$154,$A14,Pertes!$E$5:$E$154,"Dégustation",Pertes!$G$5:$G$154,$B$3,Pertes!$H$5:$H$154,$D$3))) | G14: =IF($A14="","",IF(SUMIFS(Pertes!$C$5:$C$154,Pertes!$B$5:$B$154,$A14,Pertes!$E$5:$E$154,"Autre",Pertes!$G$5:$G$154,$B$3,Pertes!$H$5:$H$154,$D$3)=0,"",SUMIFS(Pertes!$C$5:$C$154,Pertes!$B$5:$B$154,$A14,Pertes!$E$5:$E$154,"Autre",Pertes!$G$5:$G$154,$B$3,Pertes!$H$5:$H$154,$D$3))) | H14: =IF(COUNT(C14:G14)=0,"",SUM(C14:G14))
A15: =IF(Produits!$A$14="","",Produits!$A$14) | B15: =IF(Produits!$A$14="","",Produits!$C$14) | C15: =IF($A15="","",IF(SUMIFS(Pertes!$C$5:$C$154,Pertes!$B$5:$B$154,$A15,Pertes!$E$5:$E$154,"Périmé",Pertes!$G$5:$G$154,$B$3,Pertes!$H$5:$H$154,$D$3)=0,"",SUMIFS(Pertes!$C$5:$C$154,Pertes!$B$5:$B$154,$A15,Pertes!$E$5:$E$154,"Périmé",Pertes!$G$5:$G$154,$B$3,Pertes!$H$5:$H$154,$D$3))) | D15: =IF($A15="","",IF(SUMIFS(Pertes!$C$5:$C$154,Pertes!$B$5:$B$154,$A15,Pertes!$E$5:$E$154,"Raté",Pertes!$G$5:$G$154,$B$3,Pertes!$H$5:$H$154,$D$3)=0,"",SUMIFS(Pertes!$C$5:$C$154,Pertes!$B$5:$B$154,$A15,Pertes!$E$5:$E$154,"Raté",Pertes!$G$5:$G$154,$B$3,Pertes!$H$5:$H$154,$D$3))) | E15: =IF($A15="","",IF(SUMIFS(Pertes!$C$5:$C$154,Pertes!$B$5:$B$154,$A15,Pertes!$E$5:$E$154,"Cassé / renversé",Pertes!$G$5:$G$154,$B$3,Pertes!$H$5:$H$154,$D$3)=0,"",SUMIFS(Pertes!$C$5:$C$154,Pertes!$B$5:$B$154,$A15,Pertes!$E$5:$E$154,"Cassé / renversé",Pertes!$G$5:$G$154,$B$3,Pertes!$H$5:$H$154,$D$3))) | F15: =IF($A15="","",IF(SUMIFS(Pertes!$C$5:$C$154,Pertes!$B$5:$B$154,$A15,Pertes!$E$5:$E$154,"Dégustation",Pertes!$G$5:$G$154,$B$3,Pertes!$H$5:$H$154,$D$3)=0,"",SUMIFS(Pertes!$C$5:$C$154,Pertes!$B$5:$B$154,$A15,Pertes!$E$5:$E$154,"Dégustation",Pertes!$G$5:$G$154,$B$3,Pertes!$H$5:$H$154,$D$3))) | G15: =IF($A15="","",IF(SUMIFS(Pertes!$C$5:$C$154,Pertes!$B$5:$B$154,$A15,Pertes!$E$5:$E$154,"Autre",Pertes!$G$5:$G$154,$B$3,Pertes!$H$5:$H$154,$D$3)=0,"",SUMIFS(Pertes!$C$5:$C$154,Pertes!$B$5:$B$154,$A15,Pertes!$E$5:$E$154,"Autre",Pertes!$G$5:$G$154,$B$3,Pertes!$H$5:$H$154,$D$3))) | H15: =IF(COUNT(C15:G15)=0,"",SUM(C15:G15))
A16: =IF(Produits!$A$15="","",Produits!$A$15) | B16: =IF(Produits!$A$15="","",Produits!$C$15) | C16: =IF($A16="","",IF(SUMIFS(Pertes!$C$5:$C$154,Pertes!$B$5:$B$154,$A16,Pertes!$E$5:$E$154,"Périmé",Pertes!$G$5:$G$154,$B$3,Pertes!$H$5:$H$154,$D$3)=0,"",SUMIFS(Pertes!$C$5:$C$154,Pertes!$B$5:$B$154,$A16,Pertes!$E$5:$E$154,"Périmé",Pertes!$G$5:$G$154,$B$3,Pertes!$H$5:$H$154,$D$3))) | D16: =IF($A16="","",IF(SUMIFS(Pertes!$C$5:$C$154,Pertes!$B$5:$B$154,$A16,Pertes!$E$5:$E$154,"Raté",Pertes!$G$5:$G$154,$B$3,Pertes!$H$5:$H$154,$D$3)=0,"",SUMIFS(Pertes!$C$5:$C$154,Pertes!$B$5:$B$154,$A16,Pertes!$E$5:$E$154,"Raté",Pertes!$G$5:$G$154,$B$3,Pertes!$H$5:$H$154,$D$3))) | E16: =IF($A16="","",IF(SUMIFS(Pertes!$C$5:$C$154,Pertes!$B$5:$B$154,$A16,Pertes!$E$5:$E$154,"Cassé / renversé",Pertes!$G$5:$G$154,$B$3,Pertes!$H$5:$H$154,$D$3)=0,"",SUMIFS(Pertes!$C$5:$C$154,Pertes!$B$5:$B$154,$A16,Pertes!$E$5:$E$154,"Cassé / renversé",Pertes!$G$5:$G$154,$B$3,Pertes!$H$5:$H$154,$D$3))) | F16: =IF($A16="","",IF(SUMIFS(Pertes!$C$5:$C$154,Pertes!$B$5:$B$154,$A16,Pertes!$E$5:$E$154,"Dégustation",Pertes!$G$5:$G$154,$B$3,Pertes!$H$5:$H$154,$D$3)=0,"",SUMIFS(Pertes!$C$5:$C$154,Pertes!$B$5:$B$154,$A16,Pertes!$E$5:$E$154,"Dégustation",Pertes!$G$5:$G$154,$B$3,Pertes!$H$5:$H$154,$D$3))) | G16: =IF($A16="","",IF(SUMIFS(Pertes!$C$5:$C$154,Pertes!$B$5:$B$154,$A16,Pertes!$E$5:$E$154,"Autre",Pertes!$G$5:$G$154,$B$3,Pertes!$H$5:$H$154,$D$3)=0,"",SUMIFS(Pertes!$C$5:$C$154,Pertes!$B$5:$B$154,$A16,Pertes!$E$5:$E$154,"Autre",Pertes!$G$5:$G$154,$B$3,Pertes!$H$5:$H$154,$D$3))) | H16: =IF(COUNT(C16:G16)=0,"",SUM(C16:G16))
A17: =IF(Produits!$A$16="","",Produits!$A$16) | B17: =IF(Produits!$A$16="","",Produits!$C$16) | C17: =IF($A17="","",IF(SUMIFS(Pertes!$C$5:$C$154,Pertes!$B$5:$B$154,$A17,Pertes!$E$5:$E$154,"Périmé",Pertes!$G$5:$G$154,$B$3,Pertes!$H$5:$H$154,$D$3)=0,"",SUMIFS(Pertes!$C$5:$C$154,Pertes!$B$5:$B$154,$A17,Pertes!$E$5:$E$154,"Périmé",Pertes!$G$5:$G$154,$B$3,Pertes!$H$5:$H$154,$D$3))) | D17: =IF($A17="","",IF(SUMIFS(Pertes!$C$5:$C$154,Pertes!$B$5:$B$154,$A17,Pertes!$E$5:$E$154,"Raté",Pertes!$G$5:$G$154,$B$3,Pertes!$H$5:$H$154,$D$3)=0,"",SUMIFS(Pertes!$C$5:$C$154,Pertes!$B$5:$B$154,$A17,Pertes!$E$5:$E$154,"Raté",Pertes!$G$5:$G$154,$B$3,Pertes!$H$5:$H$154,$D$3))) | E17: =IF($A17="","",IF(SUMIFS(Pertes!$C$5:$C$154,Pertes!$B$5:$B$154,$A17,Pertes!$E$5:$E$154,"Cassé / renversé",Pertes!$G$5:$G$154,$B$3,Pertes!$H$5:$H$154,$D$3)=0,"",SUMIFS(Pertes!$C$5:$C$154,Pertes!$B$5:$B$154,$A17,Pertes!$E$5:$E$154,"Cassé / renversé",Pertes!$G$5:$G$154,$B$3,Pertes!$H$5:$H$154,$D$3))) | F17: =IF($A17="","",IF(SUMIFS(Pertes!$C$5:$C$154,Pertes!$B$5:$B$154,$A17,Pertes!$E$5:$E$154,"Dégustation",Pertes!$G$5:$G$154,$B$3,Pertes!$H$5:$H$154,$D$3)=0,"",SUMIFS(Pertes!$C$5:$C$154,Pertes!$B$5:$B$154,$A17,Pertes!$E$5:$E$154,"Dégustation",Pertes!$G$5:$G$154,$B$3,Pertes!$H$5:$H$154,$D$3))) | G17: =IF($A17="","",IF(SUMIFS(Pertes!$C$5:$C$154,Pertes!$B$5:$B$154,$A17,Pertes!$E$5:$E$154,"Autre",Pertes!$G$5:$G$154,$B$3,Pertes!$H$5:$H$154,$D$3)=0,"",SUMIFS(Pertes!$C$5:$C$154,Pertes!$B$5:$B$154,$A17,Pertes!$E$5:$E$154,"Autre",Pertes!$G$5:$G$154,$B$3,Pertes!$H$5:$H$154,$D$3))) | H17: =IF(COUNT(C17:G17)=0,"",SUM(C17:G17))
A18: =IF(Produits!$A$17="","",Produits!$A$17) | B18: =IF(Produits!$A$17="","",Produits!$C$17) | C18: =IF($A18="","",IF(SUMIFS(Pertes!$C$5:$C$154,Pertes!$B$5:$B$154,$A18,Pertes!$E$5:$E$154,"Périmé",Pertes!$G$5:$G$154,$B$3,Pertes!$H$5:$H$154,$D$3)=0,"",SUMIFS(Pertes!$C$5:$C$154,Pertes!$B$5:$B$154,$A18,Pertes!$E$5:$E$154,"Périmé",Pertes!$G$5:$G$154,$B$3,Pertes!$H$5:$H$154,$D$3))) | D18: =IF($A18="","",IF(SUMIFS(Pertes!$C$5:$C$154,Pertes!$B$5:$B$154,$A18,Pertes!$E$5:$E$154,"Raté",Pertes!$G$5:$G$154,$B$3,Pertes!$H$5:$H$154,$D$3)=0,"",SUMIFS(Pertes!$C$5:$C$154,Pertes!$B$5:$B$154,$A18,Pertes!$E$5:$E$154,"Raté",Pertes!$G$5:$G$154,$B$3,Pertes!$H$5:$H$154,$D$3))) | E18: =IF($A18="","",IF(SUMIFS(Pertes!$C$5:$C$154,Pertes!$B$5:$B$154,$A18,Pertes!$E$5:$E$154,"Cassé / renversé",Pertes!$G$5:$G$154,$B$3,Pertes!$H$5:$H$154,$D$3)=0,"",SUMIFS(Pertes!$C$5:$C$154,Pertes!$B$5:$B$154,$A18,Pertes!$E$5:$E$154,"Cassé / renversé",Pertes!$G$5:$G$154,$B$3,Pertes!$H$5:$H$154,$D$3))) | F18: =IF($A18="","",IF(SUMIFS(Pertes!$C$5:$C$154,Pertes!$B$5:$B$154,$A18,Pertes!$E$5:$E$154,"Dégustation",Pertes!$G$5:$G$154,$B$3,Pertes!$H$5:$H$154,$D$3)=0,"",SUMIFS(Pertes!$C$5:$C$154,Pertes!$B$5:$B$154,$A18,Pertes!$E$5:$E$154,"Dégustation",Pertes!$G$5:$G$154,$B$3,Pertes!$H$5:$H$154,$D$3))) | G18: =IF($A18="","",IF(SUMIFS(Pertes!$C$5:$C$154,Pertes!$B$5:$B$154,$A18,Pertes!$E$5:$E$154,"Autre",Pertes!$G$5:$G$154,$B$3,Pertes!$H$5:$H$154,$D$3)=0,"",SUMIFS(Pertes!$C$5:$C$154,Pertes!$B$5:$B$154,$A18,Pertes!$E$5:$E$154,"Autre",Pertes!$G$5:$G$154,$B$3,Pertes!$H$5:$H$154,$D$3))) | H18: =IF(COUNT(C18:G18)=0,"",SUM(C18:G18))
A19: =IF(Produits!$A$18="","",Produits!$A$18) | B19: =IF(Produits!$A$18="","",Produits!$C$18) | C19: =IF($A19="","",IF(SUMIFS(Pertes!$C$5:$C$154,Pertes!$B$5:$B$154,$A19,Pertes!$E$5:$E$154,"Périmé",Pertes!$G$5:$G$154,$B$3,Pertes!$H$5:$H$154,$D$3)=0,"",SUMIFS(Pertes!$C$5:$C$154,Pertes!$B$5:$B$154,$A19,Pertes!$E$5:$E$154,"Périmé",Pertes!$G$5:$G$154,$B$3,Pertes!$H$5:$H$154,$D$3))) | D19: =IF($A19="","",IF(SUMIFS(Pertes!$C$5:$C$154,Pertes!$B$5:$B$154,$A19,Pertes!$E$5:$E$154,"Raté",Pertes!$G$5:$G$154,$B$3,Pertes!$H$5:$H$154,$D$3)=0,"",SUMIFS(Pertes!$C$5:$C$154,Pertes!$B$5:$B$154,$A19,Pertes!$E$5:$E$154,"Raté",Pertes!$G$5:$G$154,$B$3,Pertes!$H$5:$H$154,$D$3))) | E19: =IF($A19="","",IF(SUMIFS(Pertes!$C$5:$C$154,Pertes!$B$5:$B$154,$A19,Pertes!$E$5:$E$154,"Cassé / renversé",Pertes!$G$5:$G$154,$B$3,Pertes!$H$5:$H$154,$D$3)=0,"",SUMIFS(Pertes!$C$5:$C$154,Pertes!$B$5:$B$154,$A19,Pertes!$E$5:$E$154,"Cassé / renversé",Pertes!$G$5:$G$154,$B$3,Pertes!$H$5:$H$154,$D$3))) | F19: =IF($A19="","",IF(SUMIFS(Pertes!$C$5:$C$154,Pertes!$B$5:$B$154,$A19,Pertes!$E$5:$E$154,"Dégustation",Pertes!$G$5:$G$154,$B$3,Pertes!$H$5:$H$154,$D$3)=0,"",SUMIFS(Pertes!$C$5:$C$154,Pertes!$B$5:$B$154,$A19,Pertes!$E$5:$E$154,"Dégustation",Pertes!$G$5:$G$154,$B$3,Pertes!$H$5:$H$154,$D$3))) | G19: =IF($A19="","",IF(SUMIFS(Pertes!$C$5:$C$154,Pertes!$B$5:$B$154,$A19,Pertes!$E$5:$E$154,"Autre",Pertes!$G$5:$G$154,$B$3,Pertes!$H$5:$H$154,$D$3)=0,"",SUMIFS(Pertes!$C$5:$C$154,Pertes!$B$5:$B$154,$A19,Pertes!$E$5:$E$154,"Autre",Pertes!$G$5:$G$154,$B$3,Pertes!$H$5:$H$154,$D$3))) | H19: =IF(COUNT(C19:G19)=0,"",SUM(C19:G19))
A20: =IF(Produits!$A$19="","",Produits!$A$19) | B20: =IF(Produits!$A$19="","",Produits!$C$19) | C20: =IF($A20="","",IF(SUMIFS(Pertes!$C$5:$C$154,Pertes!$B$5:$B$154,$A20,Pertes!$E$5:$E$154,"Périmé",Pertes!$G$5:$G$154,$B$3,Pertes!$H$5:$H$154,$D$3)=0,"",SUMIFS(Pertes!$C$5:$C$154,Pertes!$B$5:$B$154,$A20,Pertes!$E$5:$E$154,"Périmé",Pertes!$G$5:$G$154,$B$3,Pertes!$H$5:$H$154,$D$3))) | D20: =IF($A20="","",IF(SUMIFS(Pertes!$C$5:$C$154,Pertes!$B$5:$B$154,$A20,Pertes!$E$5:$E$154,"Raté",Pertes!$G$5:$G$154,$B$3,Pertes!$H$5:$H$154,$D$3)=0,"",SUMIFS(Pertes!$C$5:$C$154,Pertes!$B$5:$B$154,$A20,Pertes!$E$5:$E$154,"Raté",Pertes!$G$5:$G$154,$B$3,Pertes!$H$5:$H$154,$D$3))) | E20: =IF($A20="","",IF(SUMIFS(Pertes!$C$5:$C$154,Pertes!$B$5:$B$154,$A20,Pertes!$E$5:$E$154,"Cassé / renversé",Pertes!$G$5:$G$154,$B$3,Pertes!$H$5:$H$154,$D$3)=0,"",SUMIFS(Pertes!$C$5:$C$154,Pertes!$B$5:$B$154,$A20,Pertes!$E$5:$E$154,"Cassé / renversé",Pertes!$G$5:$G$154,$B$3,Pertes!$H$5:$H$154,$D$3))) | F20: =IF($A20="","",IF(SUMIFS(Pertes!$C$5:$C$154,Pertes!$B$5:$B$154,$A20,Pertes!$E$5:$E$154,"Dégustation",Pertes!$G$5:$G$154,$B$3,Pertes!$H$5:$H$154,$D$3)=0,"",SUMIFS(Pertes!$C$5:$C$154,Pertes!$B$5:$B$154,$A20,Pertes!$E$5:$E$154,"Dégustation",Pertes!$G$5:$G$154,$B$3,Pertes!$H$5:$H$154,$D$3))) | G20: =IF($A20="","",IF(SUMIFS(Pertes!$C$5:$C$154,Pertes!$B$5:$B$154,$A20,Pertes!$E$5:$E$154,"Autre",Pertes!$G$5:$G$154,$B$3,Pertes!$H$5:$H$154,$D$3)=0,"",SUMIFS(Pertes!$C$5:$C$154,Pertes!$B$5:$B$154,$A20,Pertes!$E$5:$E$154,"Autre",Pertes!$G$5:$G$154,$B$3,Pertes!$H$5:$H$154,$D$3))) | H20: =IF(COUNT(C20:G20)=0,"",SUM(C20:G20))
A21: =IF(Produits!$A$20="","",Produits!$A$20) | B21: =IF(Produits!$A$20="","",Produits!$C$20) | C21: =IF($A21="","",IF(SUMIFS(Pertes!$C$5:$C$154,Pertes!$B$5:$B$154,$A21,Pertes!$E$5:$E$154,"Périmé",Pertes!$G$5:$G$154,$B$3,Pertes!$H$5:$H$154,$D$3)=0,"",SUMIFS(Pertes!$C$5:$C$154,Pertes!$B$5:$B$154,$A21,Pertes!$E$5:$E$154,"Périmé",Pertes!$G$5:$G$154,$B$3,Pertes!$H$5:$H$154,$D$3))) | D21: =IF($A21="","",IF(SUMIFS(Pertes!$C$5:$C$154,Pertes!$B$5:$B$154,$A21,Pertes!$E$5:$E$154,"Raté",Pertes!$G$5:$G$154,$B$3,Pertes!$H$5:$H$154,$D$3)=0,"",SUMIFS(Pertes!$C$5:$C$154,Pertes!$B$5:$B$154,$A21,Pertes!$E$5:$E$154,"Raté",Pertes!$G$5:$G$154,$B$3,Pertes!$H$5:$H$154,$D$3))) | E21: =IF($A21="","",IF(SUMIFS(Pertes!$C$5:$C$154,Pertes!$B$5:$B$154,$A21,Pertes!$E$5:$E$154,"Cassé / renversé",Pertes!$G$5:$G$154,$B$3,Pertes!$H$5:$H$154,$D$3)=0,"",SUMIFS(Pertes!$C$5:$C$154,Pertes!$B$5:$B$154,$A21,Pertes!$E$5:$E$154,"Cassé / renversé",Pertes!$G$5:$G$154,$B$3,Pertes!$H$5:$H$154,$D$3))) | F21: =IF($A21="","",IF(SUMIFS(Pertes!$C$5:$C$154,Pertes!$B$5:$B$154,$A21,Pertes!$E$5:$E$154,"Dégustation",Pertes!$G$5:$G$154,$B$3,Pertes!$H$5:$H$154,$D$3)=0,"",SUMIFS(Pertes!$C$5:$C$154,Pertes!$B$5:$B$154,$A21,Pertes!$E$5:$E$154,"Dégustation",Pertes!$G$5:$G$154,$B$3,Pertes!$H$5:$H$154,$D$3))) | G21: =IF($A21="","",IF(SUMIFS(Pertes!$C$5:$C$154,Pertes!$B$5:$B$154,$A21,Pertes!$E$5:$E$154,"Autre",Pertes!$G$5:$G$154,$B$3,Pertes!$H$5:$H$154,$D$3)=0,"",SUMIFS(Pertes!$C$5:$C$154,Pertes!$B$5:$B$154,$A21,Pertes!$E$5:$E$154,"Autre",Pertes!$G$5:$G$154,$B$3,Pertes!$H$5:$H$154,$D$3))) | H21: =IF(COUNT(C21:G21)=0,"",SUM(C21:G21))
A22: =IF(Produits!$A$21="","",Produits!$A$21) | B22: =IF(Produits!$A$21="","",Produits!$C$21) | C22: =IF($A22="","",IF(SUMIFS(Pertes!$C$5:$C$154,Pertes!$B$5:$B$154,$A22,Pertes!$E$5:$E$154,"Périmé",Pertes!$G$5:$G$154,$B$3,Pertes!$H$5:$H$154,$D$3)=0,"",SUMIFS(Pertes!$C$5:$C$154,Pertes!$B$5:$B$154,$A22,Pertes!$E$5:$E$154,"Périmé",Pertes!$G$5:$G$154,$B$3,Pertes!$H$5:$H$154,$D$3))) | D22: =IF($A22="","",IF(SUMIFS(Pertes!$C$5:$C$154,Pertes!$B$5:$B$154,$A22,Pertes!$E$5:$E$154,"Raté",Pertes!$G$5:$G$154,$B$3,Pertes!$H$5:$H$154,$D$3)=0,"",SUMIFS(Pertes!$C$5:$C$154,Pertes!$B$5:$B$154,$A22,Pertes!$E$5:$E$154,"Raté",Pertes!$G$5:$G$154,$B$3,Pertes!$H$5:$H$154,$D$3))) | E22: =IF($A22="","",IF(SUMIFS(Pertes!$C$5:$C$154,Pertes!$B$5:$B$154,$A22,Pertes!$E$5:$E$154,"Cassé / renversé",Pertes!$G$5:$G$154,$B$3,Pertes!$H$5:$H$154,$D$3)=0,"",SUMIFS(Pertes!$C$5:$C$154,Pertes!$B$5:$B$154,$A22,Pertes!$E$5:$E$154,"Cassé / renversé",Pertes!$G$5:$G$154,$B$3,Pertes!$H$5:$H$154,$D$3))) | F22: =IF($A22="","",IF(SUMIFS(Pertes!$C$5:$C$154,Pertes!$B$5:$B$154,$A22,Pertes!$E$5:$E$154,"Dégustation",Pertes!$G$5:$G$154,$B$3,Pertes!$H$5:$H$154,$D$3)=0,"",SUMIFS(Pertes!$C$5:$C$154,Pertes!$B$5:$B$154,$A22,Pertes!$E$5:$E$154,"Dégustation",Pertes!$G$5:$G$154,$B$3,Pertes!$H$5:$H$154,$D$3))) | G22: =IF($A22="","",IF(SUMIFS(Pertes!$C$5:$C$154,Pertes!$B$5:$B$154,$A22,Pertes!$E$5:$E$154,"Autre",Pertes!$G$5:$G$154,$B$3,Pertes!$H$5:$H$154,$D$3)=0,"",SUMIFS(Pertes!$C$5:$C$154,Pertes!$B$5:$B$154,$A22,Pertes!$E$5:$E$154,"Autre",Pertes!$G$5:$G$154,$B$3,Pertes!$H$5:$H$154,$D$3))) | H22: =IF(COUNT(C22:G22)=0,"",SUM(C22:G22))
A23: =IF(Produits!$A$22="","",Produits!$A$22) | B23: =IF(Produits!$A$22="","",Produits!$C$22) | C23: =IF($A23="","",IF(SUMIFS(Pertes!$C$5:$C$154,Pertes!$B$5:$B$154,$A23,Pertes!$E$5:$E$154,"Périmé",Pertes!$G$5:$G$154,$B$3,Pertes!$H$5:$H$154,$D$3)=0,"",SUMIFS(Pertes!$C$5:$C$154,Pertes!$B$5:$B$154,$A23,Pertes!$E$5:$E$154,"Périmé",Pertes!$G$5:$G$154,$B$3,Pertes!$H$5:$H$154,$D$3))) | D23: =IF($A23="","",IF(SUMIFS(Pertes!$C$5:$C$154,Pertes!$B$5:$B$154,$A23,Pertes!$E$5:$E$154,"Raté",Pertes!$G$5:$G$154,$B$3,Pertes!$H$5:$H$154,$D$3)=0,"",SUMIFS(Pertes!$C$5:$C$154,Pertes!$B$5:$B$154,$A23,Pertes!$E$5:$E$154,"Raté",Pertes!$G$5:$G$154,$B$3,Pertes!$H$5:$H$154,$D$3))) | E23: =IF($A23="","",IF(SUMIFS(Pertes!$C$5:$C$154,Pertes!$B$5:$B$154,$A23,Pertes!$E$5:$E$154,"Cassé / renversé",Pertes!$G$5:$G$154,$B$3,Pertes!$H$5:$H$154,$D$3)=0,"",SUMIFS(Pertes!$C$5:$C$154,Pertes!$B$5:$B$154,$A23,Pertes!$E$5:$E$154,"Cassé / renversé",Pertes!$G$5:$G$154,$B$3,Pertes!$H$5:$H$154,$D$3))) | F23: =IF($A23="","",IF(SUMIFS(Pertes!$C$5:$C$154,Pertes!$B$5:$B$154,$A23,Pertes!$E$5:$E$154,"Dégustation",Pertes!$G$5:$G$154,$B$3,Pertes!$H$5:$H$154,$D$3)=0,"",SUMIFS(Pertes!$C$5:$C$154,Pertes!$B$5:$B$154,$A23,Pertes!$E$5:$E$154,"Dégustation",Pertes!$G$5:$G$154,$B$3,Pertes!$H$5:$H$154,$D$3))) | G23: =IF($A23="","",IF(SUMIFS(Pertes!$C$5:$C$154,Pertes!$B$5:$B$154,$A23,Pertes!$E$5:$E$154,"Autre",Pertes!$G$5:$G$154,$B$3,Pertes!$H$5:$H$154,$D$3)=0,"",SUMIFS(Pertes!$C$5:$C$154,Pertes!$B$5:$B$154,$A23,Pertes!$E$5:$E$154,"Autre",Pertes!$G$5:$G$154,$B$3,Pertes!$H$5:$H$154,$D$3))) | H23: =IF(COUNT(C23:G23)=0,"",SUM(C23:G23))
A24: =IF(Produits!$A$23="","",Produits!$A$23) | B24: =IF(Produits!$A$23="","",Produits!$C$23) | C24: =IF($A24="","",IF(SUMIFS(Pertes!$C$5:$C$154,Pertes!$B$5:$B$154,$A24,Pertes!$E$5:$E$154,"Périmé",Pertes!$G$5:$G$154,$B$3,Pertes!$H$5:$H$154,$D$3)=0,"",SUMIFS(Pertes!$C$5:$C$154,Pertes!$B$5:$B$154,$A24,Pertes!$E$5:$E$154,"Périmé",Pertes!$G$5:$G$154,$B$3,Pertes!$H$5:$H$154,$D$3))) | D24: =IF($A24="","",IF(SUMIFS(Pertes!$C$5:$C$154,Pertes!$B$5:$B$154,$A24,Pertes!$E$5:$E$154,"Raté",Pertes!$G$5:$G$154,$B$3,Pertes!$H$5:$H$154,$D$3)=0,"",SUMIFS(Pertes!$C$5:$C$154,Pertes!$B$5:$B$154,$A24,Pertes!$E$5:$E$154,"Raté",Pertes!$G$5:$G$154,$B$3,Pertes!$H$5:$H$154,$D$3))) | E24: =IF($A24="","",IF(SUMIFS(Pertes!$C$5:$C$154,Pertes!$B$5:$B$154,$A24,Pertes!$E$5:$E$154,"Cassé / renversé",Pertes!$G$5:$G$154,$B$3,Pertes!$H$5:$H$154,$D$3)=0,"",SUMIFS(Pertes!$C$5:$C$154,Pertes!$B$5:$B$154,$A24,Pertes!$E$5:$E$154,"Cassé / renversé",Pertes!$G$5:$G$154,$B$3,Pertes!$H$5:$H$154,$D$3))) | F24: =IF($A24="","",IF(SUMIFS(Pertes!$C$5:$C$154,Pertes!$B$5:$B$154,$A24,Pertes!$E$5:$E$154,"Dégustation",Pertes!$G$5:$G$154,$B$3,Pertes!$H$5:$H$154,$D$3)=0,"",SUMIFS(Pertes!$C$5:$C$154,Pertes!$B$5:$B$154,$A24,Pertes!$E$5:$E$154,"Dégustation",Pertes!$G$5:$G$154,$B$3,Pertes!$H$5:$H$154,$D$3))) | G24: =IF($A24="","",IF(SUMIFS(Pertes!$C$5:$C$154,Pertes!$B$5:$B$154,$A24,Pertes!$E$5:$E$154,"Autre",Pertes!$G$5:$G$154,$B$3,Pertes!$H$5:$H$154,$D$3)=0,"",SUMIFS(Pertes!$C$5:$C$154,Pertes!$B$5:$B$154,$A24,Pertes!$E$5:$E$154,"Autre",Pertes!$G$5:$G$154,$B$3,Pertes!$H$5:$H$154,$D$3))) | H24: =IF(COUNT(C24:G24)=0,"",SUM(C24:G24))
A25: =IF(Produits!$A$24="","",Produits!$A$24) | B25: =IF(Produits!$A$24="","",Produits!$C$24) | C25: =IF($A25="","",IF(SUMIFS(Pertes!$C$5:$C$154,Pertes!$B$5:$B$154,$A25,Pertes!$E$5:$E$154,"Périmé",Pertes!$G$5:$G$154,$B$3,Pertes!$H$5:$H$154,$D$3)=0,"",SUMIFS(Pertes!$C$5:$C$154,Pertes!$B$5:$B$154,$A25,Pertes!$E$5:$E$154,"Périmé",Pertes!$G$5:$G$154,$B$3,Pertes!$H$5:$H$154,$D$3))) | D25: =IF($A25="","",IF(SUMIFS(Pertes!$C$5:$C$154,Pertes!$B$5:$B$154,$A25,Pertes!$E$5:$E$154,"Raté",Pertes!$G$5:$G$154,$B$3,Pertes!$H$5:$H$154,$D$3)=0,"",SUMIFS(Pertes!$C$5:$C$154,Pertes!$B$5:$B$154,$A25,Pertes!$E$5:$E$154,"Raté",Pertes!$G$5:$G$154,$B$3,Pertes!$H$5:$H$154,$D$3))) | E25: =IF($A25="","",IF(SUMIFS(Pertes!$C$5:$C$154,Pertes!$B$5:$B$154,$A25,Pertes!$E$5:$E$154,"Cassé / renversé",Pertes!$G$5:$G$154,$B$3,Pertes!$H$5:$H$154,$D$3)=0,"",SUMIFS(Pertes!$C$5:$C$154,Pertes!$B$5:$B$154,$A25,Pertes!$E$5:$E$154,"Cassé / renversé",Pertes!$G$5:$G$154,$B$3,Pertes!$H$5:$H$154,$D$3))) | F25: =IF($A25="","",IF(SUMIFS(Pertes!$C$5:$C$154,Pertes!$B$5:$B$154,$A25,Pertes!$E$5:$E$154,"Dégustation",Pertes!$G$5:$G$154,$B$3,Pertes!$H$5:$H$154,$D$3)=0,"",SUMIFS(Pertes!$C$5:$C$154,Pertes!$B$5:$B$154,$A25,Pertes!$E$5:$E$154,"Dégustation",Pertes!$G$5:$G$154,$B$3,Pertes!$H$5:$H$154,$D$3))) | G25: =IF($A25="","",IF(SUMIFS(Pertes!$C$5:$C$154,Pertes!$B$5:$B$154,$A25,Pertes!$E$5:$E$154,"Autre",Pertes!$G$5:$G$154,$B$3,Pertes!$H$5:$H$154,$D$3)=0,"",SUMIFS(Pertes!$C$5:$C$154,Pertes!$B$5:$B$154,$A25,Pertes!$E$5:$E$154,"Autre",Pertes!$G$5:$G$154,$B$3,Pertes!$H$5:$H$154,$D$3))) | H25: =IF(COUNT(C25:G25)=0,"",SUM(C25:G25))
A26: =IF(Produits!$A$25="","",Produits!$A$25) | B26: =IF(Produits!$A$25="","",Produits!$C$25) | C26: =IF($A26="","",IF(SUMIFS(Pertes!$C$5:$C$154,Pertes!$B$5:$B$154,$A26,Pertes!$E$5:$E$154,"Périmé",Pertes!$G$5:$G$154,$B$3,Pertes!$H$5:$H$154,$D$3)=0,"",SUMIFS(Pertes!$C$5:$C$154,Pertes!$B$5:$B$154,$A26,Pertes!$E$5:$E$154,"Périmé",Pertes!$G$5:$G$154,$B$3,Pertes!$H$5:$H$154,$D$3))) | D26: =IF($A26="","",IF(SUMIFS(Pertes!$C$5:$C$154,Pertes!$B$5:$B$154,$A26,Pertes!$E$5:$E$154,"Raté",Pertes!$G$5:$G$154,$B$3,Pertes!$H$5:$H$154,$D$3)=0,"",SUMIFS(Pertes!$C$5:$C$154,Pertes!$B$5:$B$154,$A26,Pertes!$E$5:$E$154,"Raté",Pertes!$G$5:$G$154,$B$3,Pertes!$H$5:$H$154,$D$3))) | E26: =IF($A26="","",IF(SUMIFS(Pertes!$C$5:$C$154,Pertes!$B$5:$B$154,$A26,Pertes!$E$5:$E$154,"Cassé / renversé",Pertes!$G$5:$G$154,$B$3,Pertes!$H$5:$H$154,$D$3)=0,"",SUMIFS(Pertes!$C$5:$C$154,Pertes!$B$5:$B$154,$A26,Pertes!$E$5:$E$154,"Cassé / renversé",Pertes!$G$5:$G$154,$B$3,Pertes!$H$5:$H$154,$D$3))) | F26: =IF($A26="","",IF(SUMIFS(Pertes!$C$5:$C$154,Pertes!$B$5:$B$154,$A26,Pertes!$E$5:$E$154,"Dégustation",Pertes!$G$5:$G$154,$B$3,Pertes!$H$5:$H$154,$D$3)=0,"",SUMIFS(Pertes!$C$5:$C$154,Pertes!$B$5:$B$154,$A26,Pertes!$E$5:$E$154,"Dégustation",Pertes!$G$5:$G$154,$B$3,Pertes!$H$5:$H$154,$D$3))) | G26: =IF($A26="","",IF(SUMIFS(Pertes!$C$5:$C$154,Pertes!$B$5:$B$154,$A26,Pertes!$E$5:$E$154,"Autre",Pertes!$G$5:$G$154,$B$3,Pertes!$H$5:$H$154,$D$3)=0,"",SUMIFS(Pertes!$C$5:$C$154,Pertes!$B$5:$B$154,$A26,Pertes!$E$5:$E$154,"Autre",Pertes!$G$5:$G$154,$B$3,Pertes!$H$5:$H$154,$D$3))) | H26: =IF(COUNT(C26:G26)=0,"",SUM(C26:G26))
A27: =IF(Produits!$A$26="","",Produits!$A$26) | B27: =IF(Produits!$A$26="","",Produits!$C$26) | C27: =IF($A27="","",IF(SUMIFS(Pertes!$C$5:$C$154,Pertes!$B$5:$B$154,$A27,Pertes!$E$5:$E$154,"Périmé",Pertes!$G$5:$G$154,$B$3,Pertes!$H$5:$H$154,$D$3)=0,"",SUMIFS(Pertes!$C$5:$C$154,Pertes!$B$5:$B$154,$A27,Pertes!$E$5:$E$154,"Périmé",Pertes!$G$5:$G$154,$B$3,Pertes!$H$5:$H$154,$D$3))) | D27: =IF($A27="","",IF(SUMIFS(Pertes!$C$5:$C$154,Pertes!$B$5:$B$154,$A27,Pertes!$E$5:$E$154,"Raté",Pertes!$G$5:$G$154,$B$3,Pertes!$H$5:$H$154,$D$3)=0,"",SUMIFS(Pertes!$C$5:$C$154,Pertes!$B$5:$B$154,$A27,Pertes!$E$5:$E$154,"Raté",Pertes!$G$5:$G$154,$B$3,Pertes!$H$5:$H$154,$D$3))) | E27: =IF($A27="","",IF(SUMIFS(Pertes!$C$5:$C$154,Pertes!$B$5:$B$154,$A27,Pertes!$E$5:$E$154,"Cassé / renversé",Pertes!$G$5:$G$154,$B$3,Pertes!$H$5:$H$154,$D$3)=0,"",SUMIFS(Pertes!$C$5:$C$154,Pertes!$B$5:$B$154,$A27,Pertes!$E$5:$E$154,"Cassé / renversé",Pertes!$G$5:$G$154,$B$3,Pertes!$H$5:$H$154,$D$3))) | F27: =IF($A27="","",IF(SUMIFS(Pertes!$C$5:$C$154,Pertes!$B$5:$B$154,$A27,Pertes!$E$5:$E$154,"Dégustation",Pertes!$G$5:$G$154,$B$3,Pertes!$H$5:$H$154,$D$3)=0,"",SUMIFS(Pertes!$C$5:$C$154,Pertes!$B$5:$B$154,$A27,Pertes!$E$5:$E$154,"Dégustation",Pertes!$G$5:$G$154,$B$3,Pertes!$H$5:$H$154,$D$3))) | G27: =IF($A27="","",IF(SUMIFS(Pertes!$C$5:$C$154,Pertes!$B$5:$B$154,$A27,Pertes!$E$5:$E$154,"Autre",Pertes!$G$5:$G$154,$B$3,Pertes!$H$5:$H$154,$D$3)=0,"",SUMIFS(Pertes!$C$5:$C$154,Pertes!$B$5:$B$154,$A27,Pertes!$E$5:$E$154,"Autre",Pertes!$G$5:$G$154,$B$3,Pertes!$H$5:$H$154,$D$3))) | H27: =IF(COUNT(C27:G27)=0,"",SUM(C27:G27))
A28: =IF(Produits!$A$27="","",Produits!$A$27) | B28: =IF(Produits!$A$27="","",Produits!$C$27) | C28: =IF($A28="","",IF(SUMIFS(Pertes!$C$5:$C$154,Pertes!$B$5:$B$154,$A28,Pertes!$E$5:$E$154,"Périmé",Pertes!$G$5:$G$154,$B$3,Pertes!$H$5:$H$154,$D$3)=0,"",SUMIFS(Pertes!$C$5:$C$154,Pertes!$B$5:$B$154,$A28,Pertes!$E$5:$E$154,"Périmé",Pertes!$G$5:$G$154,$B$3,Pertes!$H$5:$H$154,$D$3))) | D28: =IF($A28="","",IF(SUMIFS(Pertes!$C$5:$C$154,Pertes!$B$5:$B$154,$A28,Pertes!$E$5:$E$154,"Raté",Pertes!$G$5:$G$154,$B$3,Pertes!$H$5:$H$154,$D$3)=0,"",SUMIFS(Pertes!$C$5:$C$154,Pertes!$B$5:$B$154,$A28,Pertes!$E$5:$E$154,"Raté",Pertes!$G$5:$G$154,$B$3,Pertes!$H$5:$H$154,$D$3))) | E28: =IF($A28="","",IF(SUMIFS(Pertes!$C$5:$C$154,Pertes!$B$5:$B$154,$A28,Pertes!$E$5:$E$154,"Cassé / renversé",Pertes!$G$5:$G$154,$B$3,Pertes!$H$5:$H$154,$D$3)=0,"",SUMIFS(Pertes!$C$5:$C$154,Pertes!$B$5:$B$154,$A28,Pertes!$E$5:$E$154,"Cassé / renversé",Pertes!$G$5:$G$154,$B$3,Pertes!$H$5:$H$154,$D$3))) | F28: =IF($A28="","",IF(SUMIFS(Pertes!$C$5:$C$154,Pertes!$B$5:$B$154,$A28,Pertes!$E$5:$E$154,"Dégustation",Pertes!$G$5:$G$154,$B$3,Pertes!$H$5:$H$154,$D$3)=0,"",SUMIFS(Pertes!$C$5:$C$154,Pertes!$B$5:$B$154,$A28,Pertes!$E$5:$E$154,"Dégustation",Pertes!$G$5:$G$154,$B$3,Pertes!$H$5:$H$154,$D$3))) | G28: =IF($A28="","",IF(SUMIFS(Pertes!$C$5:$C$154,Pertes!$B$5:$B$154,$A28,Pertes!$E$5:$E$154,"Autre",Pertes!$G$5:$G$154,$B$3,Pertes!$H$5:$H$154,$D$3)=0,"",SUMIFS(Pertes!$C$5:$C$154,Pertes!$B$5:$B$154,$A28,Pertes!$E$5:$E$154,"Autre",Pertes!$G$5:$G$154,$B$3,Pertes!$H$5:$H$154,$D$3))) | H28: =IF(COUNT(C28:G28)=0,"",SUM(C28:G28))
A29: =IF(Produits!$A$28="","",Produits!$A$28) | B29: =IF(Produits!$A$28="","",Produits!$C$28) | C29: =IF($A29="","",IF(SUMIFS(Pertes!$C$5:$C$154,Pertes!$B$5:$B$154,$A29,Pertes!$E$5:$E$154,"Périmé",Pertes!$G$5:$G$154,$B$3,Pertes!$H$5:$H$154,$D$3)=0,"",SUMIFS(Pertes!$C$5:$C$154,Pertes!$B$5:$B$154,$A29,Pertes!$E$5:$E$154,"Périmé",Pertes!$G$5:$G$154,$B$3,Pertes!$H$5:$H$154,$D$3))) | D29: =IF($A29="","",IF(SUMIFS(Pertes!$C$5:$C$154,Pertes!$B$5:$B$154,$A29,Pertes!$E$5:$E$154,"Raté",Pertes!$G$5:$G$154,$B$3,Pertes!$H$5:$H$154,$D$3)=0,"",SUMIFS(Pertes!$C$5:$C$154,Pertes!$B$5:$B$154,$A29,Pertes!$E$5:$E$154,"Raté",Pertes!$G$5:$G$154,$B$3,Pertes!$H$5:$H$154,$D$3))) | E29: =IF($A29="","",IF(SUMIFS(Pertes!$C$5:$C$154,Pertes!$B$5:$B$154,$A29,Pertes!$E$5:$E$154,"Cassé / renversé",Pertes!$G$5:$G$154,$B$3,Pertes!$H$5:$H$154,$D$3)=0,"",SUMIFS(Pertes!$C$5:$C$154,Pertes!$B$5:$B$154,$A29,Pertes!$E$5:$E$154,"Cassé / renversé",Pertes!$G$5:$G$154,$B$3,Pertes!$H$5:$H$154,$D$3))) | F29: =IF($A29="","",IF(SUMIFS(Pertes!$C$5:$C$154,Pertes!$B$5:$B$154,$A29,Pertes!$E$5:$E$154,"Dégustation",Pertes!$G$5:$G$154,$B$3,Pertes!$H$5:$H$154,$D$3)=0,"",SUMIFS(Pertes!$C$5:$C$154,Pertes!$B$5:$B$154,$A29,Pertes!$E$5:$E$154,"Dégustation",Pertes!$G$5:$G$154,$B$3,Pertes!$H$5:$H$154,$D$3))) | G29: =IF($A29="","",IF(SUMIFS(Pertes!$C$5:$C$154,Pertes!$B$5:$B$154,$A29,Pertes!$E$5:$E$154,"Autre",Pertes!$G$5:$G$154,$B$3,Pertes!$H$5:$H$154,$D$3)=0,"",SUMIFS(Pertes!$C$5:$C$154,Pertes!$B$5:$B$154,$A29,Pertes!$E$5:$E$154,"Autre",Pertes!$G$5:$G$154,$B$3,Pertes!$H$5:$H$154,$D$3))) | H29: =IF(COUNT(C29:G29)=0,"",SUM(C29:G29))
A30: =IF(Produits!$A$29="","",Produits!$A$29) | B30: =IF(Produits!$A$29="","",Produits!$C$29) | C30: =IF($A30="","",IF(SUMIFS(Pertes!$C$5:$C$154,Pertes!$B$5:$B$154,$A30,Pertes!$E$5:$E$154,"Périmé",Pertes!$G$5:$G$154,$B$3,Pertes!$H$5:$H$154,$D$3)=0,"",SUMIFS(Pertes!$C$5:$C$154,Pertes!$B$5:$B$154,$A30,Pertes!$E$5:$E$154,"Périmé",Pertes!$G$5:$G$154,$B$3,Pertes!$H$5:$H$154,$D$3))) | D30: =IF($A30="","",IF(SUMIFS(Pertes!$C$5:$C$154,Pertes!$B$5:$B$154,$A30,Pertes!$E$5:$E$154,"Raté",Pertes!$G$5:$G$154,$B$3,Pertes!$H$5:$H$154,$D$3)=0,"",SUMIFS(Pertes!$C$5:$C$154,Pertes!$B$5:$B$154,$A30,Pertes!$E$5:$E$154,"Raté",Pertes!$G$5:$G$154,$B$3,Pertes!$H$5:$H$154,$D$3))) | E30: =IF($A30="","",IF(SUMIFS(Pertes!$C$5:$C$154,Pertes!$B$5:$B$154,$A30,Pertes!$E$5:$E$154,"Cassé / renversé",Pertes!$G$5:$G$154,$B$3,Pertes!$H$5:$H$154,$D$3)=0,"",SUMIFS(Pertes!$C$5:$C$154,Pertes!$B$5:$B$154,$A30,Pertes!$E$5:$E$154,"Cassé / renversé",Pertes!$G$5:$G$154,$B$3,Pertes!$H$5:$H$154,$D$3))) | F30: =IF($A30="","",IF(SUMIFS(Pertes!$C$5:$C$154,Pertes!$B$5:$B$154,$A30,Pertes!$E$5:$E$154,"Dégustation",Pertes!$G$5:$G$154,$B$3,Pertes!$H$5:$H$154,$D$3)=0,"",SUMIFS(Pertes!$C$5:$C$154,Pertes!$B$5:$B$154,$A30,Pertes!$E$5:$E$154,"Dégustation",Pertes!$G$5:$G$154,$B$3,Pertes!$H$5:$H$154,$D$3))) | G30: =IF($A30="","",IF(SUMIFS(Pertes!$C$5:$C$154,Pertes!$B$5:$B$154,$A30,Pertes!$E$5:$E$154,"Autre",Pertes!$G$5:$G$154,$B$3,Pertes!$H$5:$H$154,$D$3)=0,"",SUMIFS(Pertes!$C$5:$C$154,Pertes!$B$5:$B$154,$A30,Pertes!$E$5:$E$154,"Autre",Pertes!$G$5:$G$154,$B$3,Pertes!$H$5:$H$154,$D$3))) | H30: =IF(COUNT(C30:G30)=0,"",SUM(C30:G30))
