Workbook

Sheet Mode d'emploi
A1: Suivi des stocks — version pour Lele (v1)
A2: Proposition de tableau de gestion des stocks — Excel et Google Sheets
A4: L'idée | B4: Ton suivi sur l'année, avec tout ce que tu as demandé : les produits rangés par zone (réserve sèche, chambre froide positive, chambre froide négative, ménager), la date de commande chaque semaine, le tableau de bord avec les tendances, et le registre de réception qui remplace ton cahier.
A6: Comment faire | B6: 1. Onglet Produits : écris chaque produit dans sa zone, avec son fournisseur habituel, l'unité, le stock minimum et le prix unitaire (une seule fois — à changer seulement si le tarif change).
B7: 2. Chaque semaine, dans l'onglet du mois : la date de commande, le stock compté, ce que tu commandes, puis ce que tu reçois à la livraison. Rouge = reçu moins que commandé, orange = sous le minimum.
B8: 3. À chaque livraison : une ligne par produit dans Réceptions (date, produit, fournisseur, quantité, n° de lot, DLC). Le fournisseur peut être différent de l'habituel.
B9: 4. Tableau de bord : choisis le mois, tout se calcule. Année 2026 : le récap mois par mois.
B10: 5. Les chiffres en bleu sont des exemples : efface-les avant de commencer.
A12: Les onglets | B12: Tableau de bord — dépenses, livraisons incomplètes, produits sous le minimum, tendances, top 10.
B13: Produits — ta liste par zone, avec minimum et prix.
B14: Fournisseurs — carnet d'adresses.
B15: Janvier à Décembre — la saisie de chaque semaine.
B16: Année 2026 — reçu, dépenses et stock de fin de mois.
B17: Réceptions — le registre qui remplace le cahier.
A19: Couleurs | B19: Cases jaunes = à remplir. Cases blanches = calculées toutes seules, ne pas y toucher.
B20: Chiffres en bleu = exemple pour montrer le fonctionnement, à effacer.
B21: Rouge = il manque quelque chose (livraison incomplète, stock trop bas).
A23: Google Sheets | B23: Fichier > Importer > Importer ce fichier. Tout fonctionne pareil, y compris sur téléphone.

Sheet Tableau de bord
A1: Tableau de bord
A2: Choisis le mois dans la case jaune — tout se recalcule. Rien d'autre à remplir ici.
A3: Mois : | B3: Octobre | Z3: =MATCH($B$3,$Z$5:$Z$16,0)
AA4: Produit | AB4: S1 | AC4: S2 | AD4: S3 | AE4: S4 | AF4: Commandé | AG4: Reçu | AH4: Écart | AI4: Dernier | AJ4: Mini | AK4: Dépense | AL4: SousMini | AM4: Tri
A5: Dépensé ce mois | C5: Reçu incomplet | E5: Sous le minimum | G5: Produits suivis | Z5: Janvier | AA5: =IF(Produits!$A$6="","",Produits!$A$6) | AB5: =IF(ISNUMBER(CHOOSE($Z$3,'Janvier'!E7,'Février'!E7,'Mars'!E7,'Avril'!E7,'Mai'!E7,'Juin'!E7,'Juillet'!E7,'Août'!E7,'Septembre'!E7,'Octobre'!E7,'Novembre'!E7,'Décembre'!E7)),CHOOSE($Z$3,'Janvier'!E7,'Février'!E7,'Mars'!E7,'Avril'!E7,'Mai'!E7,'Juin'!E7,'Juillet'!E7,'Août'!E7,'Septembre'!E7,'Octobre'!E7,'Novembre'!E7,'Décembre'!E7),"") | AC5: =IF(ISNUMBER(CHOOSE($Z$3,'Janvier'!I7,'Février'!I7,'Mars'!I7,'Avril'!I7,'Mai'!I7,'Juin'!I7,'Juillet'!I7,'Août'!I7,'Septembre'!I7,'Octobre'!I7,'Novembre'!I7,'Décembre'!I7)),CHOOSE($Z$3,'Janvier'!I7,'Février'!I7,'Mars'!I7,'Avril'!I7,'Mai'!I7,'Juin'!I7,'Juillet'!I7,'Août'!I7,'Septembre'!I7,'Octobre'!I7,'Novembre'!I7,'Décembre'!I7),"") | AD5: =IF(ISNUMBER(CHOOSE($Z$3,'Janvier'!M7,'Février'!M7,'Mars'!M7,'Avril'!M7,'Mai'!M7,'Juin'!M7,'Juillet'!M7,'Août'!M7,'Septembre'!M7,'Octobre'!M7,'Novembre'!M7,'Décembre'!M7)),CHOOSE($Z$3,'Janvier'!M7,'Février'!M7,'Mars'!M7,'Avril'!M7,'Mai'!M7,'Juin'!M7,'Juillet'!M7,'Août'!M7,'Septembre'!M7,'Octobre'!M7,'Novembre'!M7,'Décembre'!M7),"") | AE5: =IF(ISNUMBER(CHOOSE($Z$3,'Janvier'!Q7,'Février'!Q7,'Mars'!Q7,'Avril'!Q7,'Mai'!Q7,'Juin'!Q7,'Juillet'!Q7,'Août'!Q7,'Septembre'!Q7,'Octobre'!Q7,'Novembre'!Q7,'Décembre'!Q7)),CHOOSE($Z$3,'Janvier'!Q7,'Février'!Q7,'Mars'!Q7,'Avril'!Q7,'Mai'!Q7,'Juin'!Q7,'Juillet'!Q7,'Août'!Q7,'Septembre'!Q7,'Octobre'!Q7,'Novembre'!Q7,'Décembre'!Q7),"") | AF5: =IF(ISNUMBER(CHOOSE($Z$3,'Janvier'!T7,'Février'!T7,'Mars'!T7,'Avril'!T7,'Mai'!T7,'Juin'!T7,'Juillet'!T7,'Août'!T7,'Septembre'!T7,'Octobre'!T7,'Novembre'!T7,'Décembre'!T7)),CHOOSE($Z$3,'Janvier'!T7,'Février'!T7,'Mars'!T7,'Avril'!T7,'Mai'!T7,'Juin'!T7,'Juillet'!T7,'Août'!T7,'Septembre'!T7,'Octobre'!T7,'Novembre'!T7,'Décembre'!T7),"") | AG5: =IF(ISNUMBER(CHOOSE($Z$3,'Janvier'!U7,'Février'!U7,'Mars'!U7,'Avril'!U7,'Mai'!U7,'Juin'!U7,'Juillet'!U7,'Août'!U7,'Septembre'!U7,'Octobre'!U7,'Novembre'!U7,'Décembre'!U7)),CHOOSE($Z$3,'Janvier'!U7,'Février'!U7,'Mars'!U7,'Avril'!U7,'Mai'!U7,'Juin'!U7,'Juillet'!U7,'Août'!U7,'Septembre'!U7,'Octobre'!U7,'Novembre'!U7,'Décembre'!U7),"") | AH5: =IF(ISNUMBER(CHOOSE($Z$3,'Janvier'!V7,'Février'!V7,'Mars'!V7,'Avril'!V7,'Mai'!V7,'Juin'!V7,'Juillet'!V7,'Août'!V7,'Septembre'!V7,'Octobre'!V7,'Novembre'!V7,'Décembre'!V7)),CHOOSE($Z$3,'Janvier'!V7,'Février'!V7,'Mars'!V7,'Avril'!V7,'Mai'!V7,'Juin'!V7,'Juillet'!V7,'Août'!V7,'Septembre'!V7,'Octobre'!V7,'Novembre'!V7,'Décembre'!V7),"") | AI5: =IF(ISNUMBER(CHOOSE($Z$3,'Janvier'!W7,'Février'!W7,'Mars'!W7,'Avril'!W7,'Mai'!W7,'Juin'!W7,'Juillet'!W7,'Août'!W7,'Septembre'!W7,'Octobre'!W7,'Novembre'!W7,'Décembre'!W7)),CHOOSE($Z$3,'Janvier'!W7,'Février'!W7,'Mars'!W7,'Avril'!W7,'Mai'!W7,'Juin'!W7,'Juillet'!W7,'Août'!W7,'Septembre'!W7,'Octobre'!W7,'Novembre'!W7,'Décembre'!W7),"") | AJ5: =IF(Produits!$A$6="","",Produits!$D$6) | AK5: =IF(ISNUMBER(CHOOSE($Z$3,'Janvier'!X7,'Février'!X7,'Mars'!X7,'Avril'!X7,'Mai'!X7,'Juin'!X7,'Juillet'!X7,'Août'!X7,'Septembre'!X7,'Octobre'!X7,'Novembre'!X7,'Décembre'!X7)),CHOOSE($Z$3,'Janvier'!X7,'Février'!X7,'Mars'!X7,'Avril'!X7,'Mai'!X7,'Juin'!X7,'Juillet'!X7,'Août'!X7,'Septembre'!X7,'Octobre'!X7,'Novembre'!X7,'Décembre'!X7),"") | AL5: =IF(AND(ISNUMBER(AI5),ISNUMBER(AJ5)),IF(AI5<=AJ5,1,0),0) | AM5: =IF(OR(AA5="",AK5=""),-1,AK5+ROW()/1000000)
A6: =SUM(AK5:AK64) | C6: =COUNTIF(AH5:AH64,"<0") | E6: =SUM(AL5:AL64) | G6: =COUNTA(Produits!A6:A20)+COUNTA(Produits!A22:A36)+COUNTA(Produits!A38:A52)+COUNTA(Produits!A54:A68) | Z6: Février | AA6: =IF(Produits!$A$7="","",Produits!$A$7) | AB6: =IF(ISNUMBER(CHOOSE($Z$3,'Janvier'!E8,'Février'!E8,'Mars'!E8,'Avril'!E8,'Mai'!E8,'Juin'!E8,'Juillet'!E8,'Août'!E8,'Septembre'!E8,'Octobre'!E8,'Novembre'!E8,'Décembre'!E8)),CHOOSE($Z$3,'Janvier'!E8,'Février'!E8,'Mars'!E8,'Avril'!E8,'Mai'!E8,'Juin'!E8,'Juillet'!E8,'Août'!E8,'Septembre'!E8,'Octobre'!E8,'Novembre'!E8,'Décembre'!E8),"") | AC6: =IF(ISNUMBER(CHOOSE($Z$3,'Janvier'!I8,'Février'!I8,'Mars'!I8,'Avril'!I8,'Mai'!I8,'Juin'!I8,'Juillet'!I8,'Août'!I8,'Septembre'!I8,'Octobre'!I8,'Novembre'!I8,'Décembre'!I8)),CHOOSE($Z$3,'Janvier'!I8,'Février'!I8,'Mars'!I8,'Avril'!I8,'Mai'!I8,'Juin'!I8,'Juillet'!I8,'Août'!I8,'Septembre'!I8,'Octobre'!I8,'Novembre'!I8,'Décembre'!I8),"") | AD6: =IF(ISNUMBER(CHOOSE($Z$3,'Janvier'!M8,'Février'!M8,'Mars'!M8,'Avril'!M8,'Mai'!M8,'Juin'!M8,'Juillet'!M8,'Août'!M8,'Septembre'!M8,'Octobre'!M8,'Novembre'!M8,'Décembre'!M8)),CHOOSE($Z$3,'Janvier'!M8,'Février'!M8,'Mars'!M8,'Avril'!M8,'Mai'!M8,'Juin'!M8,'Juillet'!M8,'Août'!M8,'Septembre'!M8,'Octobre'!M8,'Novembre'!M8,'Décembre'!M8),"") | AE6: =IF(ISNUMBER(CHOOSE($Z$3,'Janvier'!Q8,'Février'!Q8,'Mars'!Q8,'Avril'!Q8,'Mai'!Q8,'Juin'!Q8,'Juillet'!Q8,'Août'!Q8,'Septembre'!Q8,'Octobre'!Q8,'Novembre'!Q8,'Décembre'!Q8)),CHOOSE($Z$3,'Janvier'!Q8,'Février'!Q8,'Mars'!Q8,'Avril'!Q8,'Mai'!Q8,'Juin'!Q8,'Juillet'!Q8,'Août'!Q8,'Septembre'!Q8,'Octobre'!Q8,'Novembre'!Q8,'Décembre'!Q8),"") | AF6: =IF(ISNUMBER(CHOOSE($Z$3,'Janvier'!T8,'Février'!T8,'Mars'!T8,'Avril'!T8,'Mai'!T8,'Juin'!T8,'Juillet'!T8,'Août'!T8,'Septembre'!T8,'Octobre'!T8,'Novembre'!T8,'Décembre'!T8)),CHOOSE($Z$3,'Janvier'!T8,'Février'!T8,'Mars'!T8,'Avril'!T8,'Mai'!T8,'Juin'!T8,'Juillet'!T8,'Août'!T8,'Septembre'!T8,'Octobre'!T8,'Novembre'!T8,'Décembre'!T8),"") | AG6: =IF(ISNUMBER(CHOOSE($Z$3,'Janvier'!U8,'Février'!U8,'Mars'!U8,'Avril'!U8,'Mai'!U8,'Juin'!U8,'Juillet'!U8,'Août'!U8,'Septembre'!U8,'Octobre'!U8,'Novembre'!U8,'Décembre'!U8)),CHOOSE($Z$3,'Janvier'!U8,'Février'!U8,'Mars'!U8,'Avril'!U8,'Mai'!U8,'Juin'!U8,'Juillet'!U8,'Août'!U8,'Septembre'!U8,'Octobre'!U8,'Novembre'!U8,'Décembre'!U8),"") | AH6: =IF(ISNUMBER(CHOOSE($Z$3,'Janvier'!V8,'Février'!V8,'Mars'!V8,'Avril'!V8,'Mai'!V8,'Juin'!V8,'Juillet'!V8,'Août'!V8,'Septembre'!V8,'Octobre'!V8,'Novembre'!V8,'Décembre'!V8)),CHOOSE($Z$3,'Janvier'!V8,'Février'!V8,'Mars'!V8,'Avril'!V8,'Mai'!V8,'Juin'!V8,'Juillet'!V8,'Août'!V8,'Septembre'!V8,'Octobre'!V8,'Novembre'!V8,'Décembre'!V8),"") | AI6: =IF(ISNUMBER(CHOOSE($Z$3,'Janvier'!W8,'Février'!W8,'Mars'!W8,'Avril'!W8,'Mai'!W8,'Juin'!W8,'Juillet'!W8,'Août'!W8,'Septembre'!W8,'Octobre'!W8,'Novembre'!W8,'Décembre'!W8)),CHOOSE($Z$3,'Janvier'!W8,'Février'!W8,'Mars'!W8,'Avril'!W8,'Mai'!W8,'Juin'!W8,'Juillet'!W8,'Août'!W8,'Septembre'!W8,'Octobre'!W8,'Novembre'!W8,'Décembre'!W8),"") | AJ6: =IF(Produits!$A$7="","",Produits!$D$7) | AK6: =IF(ISNUMBER(CHOOSE($Z$3,'Janvier'!X8,'Février'!X8,'Mars'!X8,'Avril'!X8,'Mai'!X8,'Juin'!X8,'Juillet'!X8,'Août'!X8,'Septembre'!X8,'Octobre'!X8,'Novembre'!X8,'Décembre'!X8)),CHOOSE($Z$3,'Janvier'!X8,'Février'!X8,'Mars'!X8,'Avril'!X8,'Mai'!X8,'Juin'!X8,'Juillet'!X8,'Août'!X8,'Septembre'!X8,'Octobre'!X8,'Novembre'!X8,'Décembre'!X8),"") | AL6: =IF(AND(ISNUMBER(AI6),ISNUMBER(AJ6)),IF(AI6<=AJ6,1,0),0) | AM6: =IF(OR(AA6="",AK6=""),-1,AK6+ROW()/1000000)
Z7: Mars | AA7: =IF(Produits!$A$8="","",Produits!$A$8) | AB7: =IF(ISNUMBER(CHOOSE($Z$3,'Janvier'!E9,'Février'!E9,'Mars'!E9,'Avril'!E9,'Mai'!E9,'Juin'!E9,'Juillet'!E9,'Août'!E9,'Septembre'!E9,'Octobre'!E9,'Novembre'!E9,'Décembre'!E9)),CHOOSE($Z$3,'Janvier'!E9,'Février'!E9,'Mars'!E9,'Avril'!E9,'Mai'!E9,'Juin'!E9,'Juillet'!E9,'Août'!E9,'Septembre'!E9,'Octobre'!E9,'Novembre'!E9,'Décembre'!E9),"") | AC7: =IF(ISNUMBER(CHOOSE($Z$3,'Janvier'!I9,'Février'!I9,'Mars'!I9,'Avril'!I9,'Mai'!I9,'Juin'!I9,'Juillet'!I9,'Août'!I9,'Septembre'!I9,'Octobre'!I9,'Novembre'!I9,'Décembre'!I9)),CHOOSE($Z$3,'Janvier'!I9,'Février'!I9,'Mars'!I9,'Avril'!I9,'Mai'!I9,'Juin'!I9,'Juillet'!I9,'Août'!I9,'Septembre'!I9,'Octobre'!I9,'Novembre'!I9,'Décembre'!I9),"") | AD7: =IF(ISNUMBER(CHOOSE($Z$3,'Janvier'!M9,'Février'!M9,'Mars'!M9,'Avril'!M9,'Mai'!M9,'Juin'!M9,'Juillet'!M9,'Août'!M9,'Septembre'!M9,'Octobre'!M9,'Novembre'!M9,'Décembre'!M9)),CHOOSE($Z$3,'Janvier'!M9,'Février'!M9,'Mars'!M9,'Avril'!M9,'Mai'!M9,'Juin'!M9,'Juillet'!M9,'Août'!M9,'Septembre'!M9,'Octobre'!M9,'Novembre'!M9,'Décembre'!M9),"") | AE7: =IF(ISNUMBER(CHOOSE($Z$3,'Janvier'!Q9,'Février'!Q9,'Mars'!Q9,'Avril'!Q9,'Mai'!Q9,'Juin'!Q9,'Juillet'!Q9,'Août'!Q9,'Septembre'!Q9,'Octobre'!Q9,'Novembre'!Q9,'Décembre'!Q9)),CHOOSE($Z$3,'Janvier'!Q9,'Février'!Q9,'Mars'!Q9,'Avril'!Q9,'Mai'!Q9,'Juin'!Q9,'Juillet'!Q9,'Août'!Q9,'Septembre'!Q9,'Octobre'!Q9,'Novembre'!Q9,'Décembre'!Q9),"") | AF7: =IF(ISNUMBER(CHOOSE($Z$3,'Janvier'!T9,'Février'!T9,'Mars'!T9,'Avril'!T9,'Mai'!T9,'Juin'!T9,'Juillet'!T9,'Août'!T9,'Septembre'!T9,'Octobre'!T9,'Novembre'!T9,'Décembre'!T9)),CHOOSE($Z$3,'Janvier'!T9,'Février'!T9,'Mars'!T9,'Avril'!T9,'Mai'!T9,'Juin'!T9,'Juillet'!T9,'Août'!T9,'Septembre'!T9,'Octobre'!T9,'Novembre'!T9,'Décembre'!T9),"") | AG7: =IF(ISNUMBER(CHOOSE($Z$3,'Janvier'!U9,'Février'!U9,'Mars'!U9,'Avril'!U9,'Mai'!U9,'Juin'!U9,'Juillet'!U9,'Août'!U9,'Septembre'!U9,'Octobre'!U9,'Novembre'!U9,'Décembre'!U9)),CHOOSE($Z$3,'Janvier'!U9,'Février'!U9,'Mars'!U9,'Avril'!U9,'Mai'!U9,'Juin'!U9,'Juillet'!U9,'Août'!U9,'Septembre'!U9,'Octobre'!U9,'Novembre'!U9,'Décembre'!U9),"") | AH7: =IF(ISNUMBER(CHOOSE($Z$3,'Janvier'!V9,'Février'!V9,'Mars'!V9,'Avril'!V9,'Mai'!V9,'Juin'!V9,'Juillet'!V9,'Août'!V9,'Septembre'!V9,'Octobre'!V9,'Novembre'!V9,'Décembre'!V9)),CHOOSE($Z$3,'Janvier'!V9,'Février'!V9,'Mars'!V9,'Avril'!V9,'Mai'!V9,'Juin'!V9,'Juillet'!V9,'Août'!V9,'Septembre'!V9,'Octobre'!V9,'Novembre'!V9,'Décembre'!V9),"") | AI7: =IF(ISNUMBER(CHOOSE($Z$3,'Janvier'!W9,'Février'!W9,'Mars'!W9,'Avril'!W9,'Mai'!W9,'Juin'!W9,'Juillet'!W9,'Août'!W9,'Septembre'!W9,'Octobre'!W9,'Novembre'!W9,'Décembre'!W9)),CHOOSE($Z$3,'Janvier'!W9,'Février'!W9,'Mars'!W9,'Avril'!W9,'Mai'!W9,'Juin'!W9,'Juillet'!W9,'Août'!W9,'Septembre'!W9,'Octobre'!W9,'Novembre'!W9,'Décembre'!W9),"") | AJ7: =IF(Produits!$A$8="","",Produits!$D$8) | AK7: =IF(ISNUMBER(CHOOSE($Z$3,'Janvier'!X9,'Février'!X9,'Mars'!X9,'Avril'!X9,'Mai'!X9,'Juin'!X9,'Juillet'!X9,'Août'!X9,'Septembre'!X9,'Octobre'!X9,'Novembre'!X9,'Décembre'!X9)),CHOOSE($Z$3,'Janvier'!X9,'Février'!X9,'Mars'!X9,'Avril'!X9,'Mai'!X9,'Juin'!X9,'Juillet'!X9,'Août'!X9,'Septembre'!X9,'Octobre'!X9,'Novembre'!X9,'Décembre'!X9),"") | AL7: =IF(AND(ISNUMBER(AI7),ISNUMBER(AJ7)),IF(AI7<=AJ7,1,0),0) | AM7: =IF(OR(AA7="",AK7=""),-1,AK7+ROW()/1000000)
Z8: Avril | AA8: =IF(Produits!$A$9="","",Produits!$A$9) | AB8: =IF(ISNUMBER(CHOOSE($Z$3,'Janvier'!E10,'Février'!E10,'Mars'!E10,'Avril'!E10,'Mai'!E10,'Juin'!E10,'Juillet'!E10,'Août'!E10,'Septembre'!E10,'Octobre'!E10,'Novembre'!E10,'Décembre'!E10)),CHOOSE($Z$3,'Janvier'!E10,'Février'!E10,'Mars'!E10,'Avril'!E10,'Mai'!E10,'Juin'!E10,'Juillet'!E10,'Août'!E10,'Septembre'!E10,'Octobre'!E10,'Novembre'!E10,'Décembre'!E10),"") | AC8: =IF(ISNUMBER(CHOOSE($Z$3,'Janvier'!I10,'Février'!I10,'Mars'!I10,'Avril'!I10,'Mai'!I10,'Juin'!I10,'Juillet'!I10,'Août'!I10,'Septembre'!I10,'Octobre'!I10,'Novembre'!I10,'Décembre'!I10)),CHOOSE($Z$3,'Janvier'!I10,'Février'!I10,'Mars'!I10,'Avril'!I10,'Mai'!I10,'Juin'!I10,'Juillet'!I10,'Août'!I10,'Septembre'!I10,'Octobre'!I10,'Novembre'!I10,'Décembre'!I10),"") | AD8: =IF(ISNUMBER(CHOOSE($Z$3,'Janvier'!M10,'Février'!M10,'Mars'!M10,'Avril'!M10,'Mai'!M10,'Juin'!M10,'Juillet'!M10,'Août'!M10,'Septembre'!M10,'Octobre'!M10,'Novembre'!M10,'Décembre'!M10)),CHOOSE($Z$3,'Janvier'!M10,'Février'!M10,'Mars'!M10,'Avril'!M10,'Mai'!M10,'Juin'!M10,'Juillet'!M10,'Août'!M10,'Septembre'!M10,'Octobre'!M10,'Novembre'!M10,'Décembre'!M10),"") | AE8: =IF(ISNUMBER(CHOOSE($Z$3,'Janvier'!Q10,'Février'!Q10,'Mars'!Q10,'Avril'!Q10,'Mai'!Q10,'Juin'!Q10,'Juillet'!Q10,'Août'!Q10,'Septembre'!Q10,'Octobre'!Q10,'Novembre'!Q10,'Décembre'!Q10)),CHOOSE($Z$3,'Janvier'!Q10,'Février'!Q10,'Mars'!Q10,'Avril'!Q10,'Mai'!Q10,'Juin'!Q10,'Juillet'!Q10,'Août'!Q10,'Septembre'!Q10,'Octobre'!Q10,'Novembre'!Q10,'Décembre'!Q10),"") | AF8: =IF(ISNUMBER(CHOOSE($Z$3,'Janvier'!T10,'Février'!T10,'Mars'!T10,'Avril'!T10,'Mai'!T10,'Juin'!T10,'Juillet'!T10,'Août'!T10,'Septembre'!T10,'Octobre'!T10,'Novembre'!T10,'Décembre'!T10)),CHOOSE($Z$3,'Janvier'!T10,'Février'!T10,'Mars'!T10,'Avril'!T10,'Mai'!T10,'Juin'!T10,'Juillet'!T10,'Août'!T10,'Septembre'!T10,'Octobre'!T10,'Novembre'!T10,'Décembre'!T10),"") | AG8: =IF(ISNUMBER(CHOOSE($Z$3,'Janvier'!U10,'Février'!U10,'Mars'!U10,'Avril'!U10,'Mai'!U10,'Juin'!U10,'Juillet'!U10,'Août'!U10,'Septembre'!U10,'Octobre'!U10,'Novembre'!U10,'Décembre'!U10)),CHOOSE($Z$3,'Janvier'!U10,'Février'!U10,'Mars'!U10,'Avril'!U10,'Mai'!U10,'Juin'!U10,'Juillet'!U10,'Août'!U10,'Septembre'!U10,'Octobre'!U10,'Novembre'!U10,'Décembre'!U10),"") | AH8: =IF(ISNUMBER(CHOOSE($Z$3,'Janvier'!V10,'Février'!V10,'Mars'!V10,'Avril'!V10,'Mai'!V10,'Juin'!V10,'Juillet'!V10,'Août'!V10,'Septembre'!V10,'Octobre'!V10,'Novembre'!V10,'Décembre'!V10)),CHOOSE($Z$3,'Janvier'!V10,'Février'!V10,'Mars'!V10,'Avril'!V10,'Mai'!V10,'Juin'!V10,'Juillet'!V10,'Août'!V10,'Septembre'!V10,'Octobre'!V10,'Novembre'!V10,'Décembre'!V10),"") | AI8: =IF(ISNUMBER(CHOOSE($Z$3,'Janvier'!W10,'Février'!W10,'Mars'!W10,'Avril'!W10,'Mai'!W10,'Juin'!W10,'Juillet'!W10,'Août'!W10,'Septembre'!W10,'Octobre'!W10,'Novembre'!W10,'Décembre'!W10)),CHOOSE($Z$3,'Janvier'!W10,'Février'!W10,'Mars'!W10,'Avril'!W10,'Mai'!W10,'Juin'!W10,'Juillet'!W10,'Août'!W10,'Septembre'!W10,'Octobre'!W10,'Novembre'!W10,'Décembre'!W10),"") | AJ8: =IF(Produits!$A$9="","",Produits!$D$9) | AK8: =IF(ISNUMBER(CHOOSE($Z$3,'Janvier'!X10,'Février'!X10,'Mars'!X10,'Avril'!X10,'Mai'!X10,'Juin'!X10,'Juillet'!X10,'Août'!X10,'Septembre'!X10,'Octobre'!X10,'Novembre'!X10,'Décembre'!X10)),CHOOSE($Z$3,'Janvier'!X10,'Février'!X10,'Mars'!X10,'Avril'!X10,'Mai'!X10,'Juin'!X10,'Juillet'!X10,'Août'!X10,'Septembre'!X10,'Octobre'!X10,'Novembre'!X10,'Décembre'!X10),"") | AL8: =IF(AND(ISNUMBER(AI8),ISNUMBER(AJ8)),IF(AI8<=AJ8,1,0),0) | AM8: =IF(OR(AA8="",AK8=""),-1,AK8+ROW()/1000000)
Z9: Mai | AA9: =IF(Produits!$A$10="","",Produits!$A$10) | AB9: =IF(ISNUMBER(CHOOSE($Z$3,'Janvier'!E11,'Février'!E11,'Mars'!E11,'Avril'!E11,'Mai'!E11,'Juin'!E11,'Juillet'!E11,'Août'!E11,'Septembre'!E11,'Octobre'!E11,'Novembre'!E11,'Décembre'!E11)),CHOOSE($Z$3,'Janvier'!E11,'Février'!E11,'Mars'!E11,'Avril'!E11,'Mai'!E11,'Juin'!E11,'Juillet'!E11,'Août'!E11,'Septembre'!E11,'Octobre'!E11,'Novembre'!E11,'Décembre'!E11),"") | AC9: =IF(ISNUMBER(CHOOSE($Z$3,'Janvier'!I11,'Février'!I11,'Mars'!I11,'Avril'!I11,'Mai'!I11,'Juin'!I11,'Juillet'!I11,'Août'!I11,'Septembre'!I11,'Octobre'!I11,'Novembre'!I11,'Décembre'!I11)),CHOOSE($Z$3,'Janvier'!I11,'Février'!I11,'Mars'!I11,'Avril'!I11,'Mai'!I11,'Juin'!I11,'Juillet'!I11,'Août'!I11,'Septembre'!I11,'Octobre'!I11,'Novembre'!I11,'Décembre'!I11),"") | AD9: =IF(ISNUMBER(CHOOSE($Z$3,'Janvier'!M11,'Février'!M11,'Mars'!M11,'Avril'!M11,'Mai'!M11,'Juin'!M11,'Juillet'!M11,'Août'!M11,'Septembre'!M11,'Octobre'!M11,'Novembre'!M11,'Décembre'!M11)),CHOOSE($Z$3,'Janvier'!M11,'Février'!M11,'Mars'!M11,'Avril'!M11,'Mai'!M11,'Juin'!M11,'Juillet'!M11,'Août'!M11,'Septembre'!M11,'Octobre'!M11,'Novembre'!M11,'Décembre'!M11),"") | AE9: =IF(ISNUMBER(CHOOSE($Z$3,'Janvier'!Q11,'Février'!Q11,'Mars'!Q11,'Avril'!Q11,'Mai'!Q11,'Juin'!Q11,'Juillet'!Q11,'Août'!Q11,'Septembre'!Q11,'Octobre'!Q11,'Novembre'!Q11,'Décembre'!Q11)),CHOOSE($Z$3,'Janvier'!Q11,'Février'!Q11,'Mars'!Q11,'Avril'!Q11,'Mai'!Q11,'Juin'!Q11,'Juillet'!Q11,'Août'!Q11,'Septembre'!Q11,'Octobre'!Q11,'Novembre'!Q11,'Décembre'!Q11),"") | AF9: =IF(ISNUMBER(CHOOSE($Z$3,'Janvier'!T11,'Février'!T11,'Mars'!T11,'Avril'!T11,'Mai'!T11,'Juin'!T11,'Juillet'!T11,'Août'!T11,'Septembre'!T11,'Octobre'!T11,'Novembre'!T11,'Décembre'!T11)),CHOOSE($Z$3,'Janvier'!T11,'Février'!T11,'Mars'!T11,'Avril'!T11,'Mai'!T11,'Juin'!T11,'Juillet'!T11,'Août'!T11,'Septembre'!T11,'Octobre'!T11,'Novembre'!T11,'Décembre'!T11),"") | AG9: =IF(ISNUMBER(CHOOSE($Z$3,'Janvier'!U11,'Février'!U11,'Mars'!U11,'Avril'!U11,'Mai'!U11,'Juin'!U11,'Juillet'!U11,'Août'!U11,'Septembre'!U11,'Octobre'!U11,'Novembre'!U11,'Décembre'!U11)),CHOOSE($Z$3,'Janvier'!U11,'Février'!U11,'Mars'!U11,'Avril'!U11,'Mai'!U11,'Juin'!U11,'Juillet'!U11,'Août'!U11,'Septembre'!U11,'Octobre'!U11,'Novembre'!U11,'Décembre'!U11),"") | AH9: =IF(ISNUMBER(CHOOSE($Z$3,'Janvier'!V11,'Février'!V11,'Mars'!V11,'Avril'!V11,'Mai'!V11,'Juin'!V11,'Juillet'!V11,'Août'!V11,'Septembre'!V11,'Octobre'!V11,'Novembre'!V11,'Décembre'!V11)),CHOOSE($Z$3,'Janvier'!V11,'Février'!V11,'Mars'!V11,'Avril'!V11,'Mai'!V11,'Juin'!V11,'Juillet'!V11,'Août'!V11,'Septembre'!V11,'Octobre'!V11,'Novembre'!V11,'Décembre'!V11),"") | AI9: =IF(ISNUMBER(CHOOSE($Z$3,'Janvier'!W11,'Février'!W11,'Mars'!W11,'Avril'!W11,'Mai'!W11,'Juin'!W11,'Juillet'!W11,'Août'!W11,'Septembre'!W11,'Octobre'!W11,'Novembre'!W11,'Décembre'!W11)),CHOOSE($Z$3,'Janvier'!W11,'Février'!W11,'Mars'!W11,'Avril'!W11,'Mai'!W11,'Juin'!W11,'Juillet'!W11,'Août'!W11,'Septembre'!W11,'Octobre'!W11,'Novembre'!W11,'Décembre'!W11),"") | AJ9: =IF(Produits!$A$10="","",Produits!$D$10) | AK9: =IF(ISNUMBER(CHOOSE($Z$3,'Janvier'!X11,'Février'!X11,'Mars'!X11,'Avril'!X11,'Mai'!X11,'Juin'!X11,'Juillet'!X11,'Août'!X11,'Septembre'!X11,'Octobre'!X11,'Novembre'!X11,'Décembre'!X11)),CHOOSE($Z$3,'Janvier'!X11,'Février'!X11,'Mars'!X11,'Avril'!X11,'Mai'!X11,'Juin'!X11,'Juillet'!X11,'Août'!X11,'Septembre'!X11,'Octobre'!X11,'Novembre'!X11,'Décembre'!X11),"") | AL9: =IF(AND(ISNUMBER(AI9),ISNUMBER(AJ9)),IF(AI9<=AJ9,1,0),0) | AM9: =IF(OR(AA9="",AK9=""),-1,AK9+ROW()/1000000)
A10: Top 10 des dépenses du mois | Z10: Juin | AA10: =IF(Produits!$A$11="","",Produits!$A$11) | AB10: =IF(ISNUMBER(CHOOSE($Z$3,'Janvier'!E12,'Février'!E12,'Mars'!E12,'Avril'!E12,'Mai'!E12,'Juin'!E12,'Juillet'!E12,'Août'!E12,'Septembre'!E12,'Octobre'!E12,'Novembre'!E12,'Décembre'!E12)),CHOOSE($Z$3,'Janvier'!E12,'Février'!E12,'Mars'!E12,'Avril'!E12,'Mai'!E12,'Juin'!E12,'Juillet'!E12,'Août'!E12,'Septembre'!E12,'Octobre'!E12,'Novembre'!E12,'Décembre'!E12),"") | AC10: =IF(ISNUMBER(CHOOSE($Z$3,'Janvier'!I12,'Février'!I12,'Mars'!I12,'Avril'!I12,'Mai'!I12,'Juin'!I12,'Juillet'!I12,'Août'!I12,'Septembre'!I12,'Octobre'!I12,'Novembre'!I12,'Décembre'!I12)),CHOOSE($Z$3,'Janvier'!I12,'Février'!I12,'Mars'!I12,'Avril'!I12,'Mai'!I12,'Juin'!I12,'Juillet'!I12,'Août'!I12,'Septembre'!I12,'Octobre'!I12,'Novembre'!I12,'Décembre'!I12),"") | AD10: =IF(ISNUMBER(CHOOSE($Z$3,'Janvier'!M12,'Février'!M12,'Mars'!M12,'Avril'!M12,'Mai'!M12,'Juin'!M12,'Juillet'!M12,'Août'!M12,'Septembre'!M12,'Octobre'!M12,'Novembre'!M12,'Décembre'!M12)),CHOOSE($Z$3,'Janvier'!M12,'Février'!M12,'Mars'!M12,'Avril'!M12,'Mai'!M12,'Juin'!M12,'Juillet'!M12,'Août'!M12,'Septembre'!M12,'Octobre'!M12,'Novembre'!M12,'Décembre'!M12),"") | AE10: =IF(ISNUMBER(CHOOSE($Z$3,'Janvier'!Q12,'Février'!Q12,'Mars'!Q12,'Avril'!Q12,'Mai'!Q12,'Juin'!Q12,'Juillet'!Q12,'Août'!Q12,'Septembre'!Q12,'Octobre'!Q12,'Novembre'!Q12,'Décembre'!Q12)),CHOOSE($Z$3,'Janvier'!Q12,'Février'!Q12,'Mars'!Q12,'Avril'!Q12,'Mai'!Q12,'Juin'!Q12,'Juillet'!Q12,'Août'!Q12,'Septembre'!Q12,'Octobre'!Q12,'Novembre'!Q12,'Décembre'!Q12),"") | AF10: =IF(ISNUMBER(CHOOSE($Z$3,'Janvier'!T12,'Février'!T12,'Mars'!T12,'Avril'!T12,'Mai'!T12,'Juin'!T12,'Juillet'!T12,'Août'!T12,'Septembre'!T12,'Octobre'!T12,'Novembre'!T12,'Décembre'!T12)),CHOOSE($Z$3,'Janvier'!T12,'Février'!T12,'Mars'!T12,'Avril'!T12,'Mai'!T12,'Juin'!T12,'Juillet'!T12,'Août'!T12,'Septembre'!T12,'Octobre'!T12,'Novembre'!T12,'Décembre'!T12),"") | AG10: =IF(ISNUMBER(CHOOSE($Z$3,'Janvier'!U12,'Février'!U12,'Mars'!U12,'Avril'!U12,'Mai'!U12,'Juin'!U12,'Juillet'!U12,'Août'!U12,'Septembre'!U12,'Octobre'!U12,'Novembre'!U12,'Décembre'!U12)),CHOOSE($Z$3,'Janvier'!U12,'Février'!U12,'Mars'!U12,'Avril'!U12,'Mai'!U12,'Juin'!U12,'Juillet'!U12,'Août'!U12,'Septembre'!U12,'Octobre'!U12,'Novembre'!U12,'Décembre'!U12),"") | AH10: =IF(ISNUMBER(CHOOSE($Z$3,'Janvier'!V12,'Février'!V12,'Mars'!V12,'Avril'!V12,'Mai'!V12,'Juin'!V12,'Juillet'!V12,'Août'!V12,'Septembre'!V12,'Octobre'!V12,'Novembre'!V12,'Décembre'!V12)),CHOOSE($Z$3,'Janvier'!V12,'Février'!V12,'Mars'!V12,'Avril'!V12,'Mai'!V12,'Juin'!V12,'Juillet'!V12,'Août'!V12,'Septembre'!V12,'Octobre'!V12,'Novembre'!V12,'Décembre'!V12),"") | AI10: =IF(ISNUMBER(CHOOSE($Z$3,'Janvier'!W12,'Février'!W12,'Mars'!W12,'Avril'!W12,'Mai'!W12,'Juin'!W12,'Juillet'!W12,'Août'!W12,'Septembre'!W12,'Octobre'!W12,'Novembre'!W12,'Décembre'!W12)),CHOOSE($Z$3,'Janvier'!W12,'Février'!W12,'Mars'!W12,'Avril'!W12,'Mai'!W12,'Juin'!W12,'Juillet'!W12,'Août'!W12,'Septembre'!W12,'Octobre'!W12,'Novembre'!W12,'Décembre'!W12),"") | AJ10: =IF(Produits!$A$11="","",Produits!$D$11) | AK10: =IF(ISNUMBER(CHOOSE($Z$3,'Janvier'!X12,'Février'!X12,'Mars'!X12,'Avril'!X12,'Mai'!X12,'Juin'!X12,'Juillet'!X12,'Août'!X12,'Septembre'!X12,'Octobre'!X12,'Novembre'!X12,'Décembre'!X12)),CHOOSE($Z$3,'Janvier'!X12,'Février'!X12,'Mars'!X12,'Avril'!X12,'Mai'!X12,'Juin'!X12,'Juillet'!X12,'Août'!X12,'Septembre'!X12,'Octobre'!X12,'Novembre'!X12,'Décembre'!X12),"") | AL10: =IF(AND(ISNUMBER(AI10),ISNUMBER(AJ10)),IF(AI10<=AJ10,1,0),0) | AM10: =IF(OR(AA10="",AK10=""),-1,AK10+ROW()/1000000)
A11: Rang | B11: Produit | D11: Reçu | E11: Dépense (€) | Z11: Juillet | AA11: =IF(Produits!$A$12="","",Produits!$A$12) | AB11: =IF(ISNUMBER(CHOOSE($Z$3,'Janvier'!E13,'Février'!E13,'Mars'!E13,'Avril'!E13,'Mai'!E13,'Juin'!E13,'Juillet'!E13,'Août'!E13,'Septembre'!E13,'Octobre'!E13,'Novembre'!E13,'Décembre'!E13)),CHOOSE($Z$3,'Janvier'!E13,'Février'!E13,'Mars'!E13,'Avril'!E13,'Mai'!E13,'Juin'!E13,'Juillet'!E13,'Août'!E13,'Septembre'!E13,'Octobre'!E13,'Novembre'!E13,'Décembre'!E13),"") | AC11: =IF(ISNUMBER(CHOOSE($Z$3,'Janvier'!I13,'Février'!I13,'Mars'!I13,'Avril'!I13,'Mai'!I13,'Juin'!I13,'Juillet'!I13,'Août'!I13,'Septembre'!I13,'Octobre'!I13,'Novembre'!I13,'Décembre'!I13)),CHOOSE($Z$3,'Janvier'!I13,'Février'!I13,'Mars'!I13,'Avril'!I13,'Mai'!I13,'Juin'!I13,'Juillet'!I13,'Août'!I13,'Septembre'!I13,'Octobre'!I13,'Novembre'!I13,'Décembre'!I13),"") | AD11: =IF(ISNUMBER(CHOOSE($Z$3,'Janvier'!M13,'Février'!M13,'Mars'!M13,'Avril'!M13,'Mai'!M13,'Juin'!M13,'Juillet'!M13,'Août'!M13,'Septembre'!M13,'Octobre'!M13,'Novembre'!M13,'Décembre'!M13)),CHOOSE($Z$3,'Janvier'!M13,'Février'!M13,'Mars'!M13,'Avril'!M13,'Mai'!M13,'Juin'!M13,'Juillet'!M13,'Août'!M13,'Septembre'!M13,'Octobre'!M13,'Novembre'!M13,'Décembre'!M13),"") | AE11: =IF(ISNUMBER(CHOOSE($Z$3,'Janvier'!Q13,'Février'!Q13,'Mars'!Q13,'Avril'!Q13,'Mai'!Q13,'Juin'!Q13,'Juillet'!Q13,'Août'!Q13,'Septembre'!Q13,'Octobre'!Q13,'Novembre'!Q13,'Décembre'!Q13)),CHOOSE($Z$3,'Janvier'!Q13,'Février'!Q13,'Mars'!Q13,'Avril'!Q13,'Mai'!Q13,'Juin'!Q13,'Juillet'!Q13,'Août'!Q13,'Septembre'!Q13,'Octobre'!Q13,'Novembre'!Q13,'Décembre'!Q13),"") | AF11: =IF(ISNUMBER(CHOOSE($Z$3,'Janvier'!T13,'Février'!T13,'Mars'!T13,'Avril'!T13,'Mai'!T13,'Juin'!T13,'Juillet'!T13,'Août'!T13,'Septembre'!T13,'Octobre'!T13,'Novembre'!T13,'Décembre'!T13)),CHOOSE($Z$3,'Janvier'!T13,'Février'!T13,'Mars'!T13,'Avril'!T13,'Mai'!T13,'Juin'!T13,'Juillet'!T13,'Août'!T13,'Septembre'!T13,'Octobre'!T13,'Novembre'!T13,'Décembre'!T13),"") | AG11: =IF(ISNUMBER(CHOOSE($Z$3,'Janvier'!U13,'Février'!U13,'Mars'!U13,'Avril'!U13,'Mai'!U13,'Juin'!U13,'Juillet'!U13,'Août'!U13,'Septembre'!U13,'Octobre'!U13,'Novembre'!U13,'Décembre'!U13)),CHOOSE($Z$3,'Janvier'!U13,'Février'!U13,'Mars'!U13,'Avril'!U13,'Mai'!U13,'Juin'!U13,'Juillet'!U13,'Août'!U13,'Septembre'!U13,'Octobre'!U13,'Novembre'!U13,'Décembre'!U13),"") | AH11: =IF(ISNUMBER(CHOOSE($Z$3,'Janvier'!V13,'Février'!V13,'Mars'!V13,'Avril'!V13,'Mai'!V13,'Juin'!V13,'Juillet'!V13,'Août'!V13,'Septembre'!V13,'Octobre'!V13,'Novembre'!V13,'Décembre'!V13)),CHOOSE($Z$3,'Janvier'!V13,'Février'!V13,'Mars'!V13,'Avril'!V13,'Mai'!V13,'Juin'!V13,'Juillet'!V13,'Août'!V13,'Septembre'!V13,'Octobre'!V13,'Novembre'!V13,'Décembre'!V13),"") | AI11: =IF(ISNUMBER(CHOOSE($Z$3,'Janvier'!W13,'Février'!W13,'Mars'!W13,'Avril'!W13,'Mai'!W13,'Juin'!W13,'Juillet'!W13,'Août'!W13,'Septembre'!W13,'Octobre'!W13,'Novembre'!W13,'Décembre'!W13)),CHOOSE($Z$3,'Janvier'!W13,'Février'!W13,'Mars'!W13,'Avril'!W13,'Mai'!W13,'Juin'!W13,'Juillet'!W13,'Août'!W13,'Septembre'!W13,'Octobre'!W13,'Novembre'!W13,'Décembre'!W13),"") | AJ11: =IF(Produits!$A$12="","",Produits!$D$12) | AK11: =IF(ISNUMBER(CHOOSE($Z$3,'Janvier'!X13,'Février'!X13,'Mars'!X13,'Avril'!X13,'Mai'!X13,'Juin'!X13,'Juillet'!X13,'Août'!X13,'Septembre'!X13,'Octobre'!X13,'Novembre'!X13,'Décembre'!X13)),CHOOSE($Z$3,'Janvier'!X13,'Février'!X13,'Mars'!X13,'Avril'!X13,'Mai'!X13,'Juin'!X13,'Juillet'!X13,'Août'!X13,'Septembre'!X13,'Octobre'!X13,'Novembre'!X13,'Décembre'!X13),"") | AL11: =IF(AND(ISNUMBER(AI11),ISNUMBER(AJ11)),IF(AI11<=AJ11,1,0),0) | AM11: =IF(OR(AA11="",AK11=""),-1,AK11+ROW()/1000000)
A12: 1 | B12: =IF(LARGE($AM$5:$AM$64,1)<=0,"",INDEX($AA$5:$AA$64,MATCH(LARGE($AM$5:$AM$64,1),$AM$5:$AM$64,0))) | D12: =IF(B12="","",INDEX($AG$5:$AG$64,MATCH(LARGE($AM$5:$AM$64,1),$AM$5:$AM$64,0))) | E12: =IF(B12="","",INDEX($AK$5:$AK$64,MATCH(LARGE($AM$5:$AM$64,1),$AM$5:$AM$64,0))) | Z12: Août | AA12: =IF(Produits!$A$13="","",Produits!$A$13) | AB12: =IF(ISNUMBER(CHOOSE($Z$3,'Janvier'!E14,'Février'!E14,'Mars'!E14,'Avril'!E14,'Mai'!E14,'Juin'!E14,'Juillet'!E14,'Août'!E14,'Septembre'!E14,'Octobre'!E14,'Novembre'!E14,'Décembre'!E14)),CHOOSE($Z$3,'Janvier'!E14,'Février'!E14,'Mars'!E14,'Avril'!E14,'Mai'!E14,'Juin'!E14,'Juillet'!E14,'Août'!E14,'Septembre'!E14,'Octobre'!E14,'Novembre'!E14,'Décembre'!E14),"") | AC12: =IF(ISNUMBER(CHOOSE($Z$3,'Janvier'!I14,'Février'!I14,'Mars'!I14,'Avril'!I14,'Mai'!I14,'Juin'!I14,'Juillet'!I14,'Août'!I14,'Septembre'!I14,'Octobre'!I14,'Novembre'!I14,'Décembre'!I14)),CHOOSE($Z$3,'Janvier'!I14,'Février'!I14,'Mars'!I14,'Avril'!I14,'Mai'!I14,'Juin'!I14,'Juillet'!I14,'Août'!I14,'Septembre'!I14,'Octobre'!I14,'Novembre'!I14,'Décembre'!I14),"") | AD12: =IF(ISNUMBER(CHOOSE($Z$3,'Janvier'!M14,'Février'!M14,'Mars'!M14,'Avril'!M14,'Mai'!M14,'Juin'!M14,'Juillet'!M14,'Août'!M14,'Septembre'!M14,'Octobre'!M14,'Novembre'!M14,'Décembre'!M14)),CHOOSE($Z$3,'Janvier'!M14,'Février'!M14,'Mars'!M14,'Avril'!M14,'Mai'!M14,'Juin'!M14,'Juillet'!M14,'Août'!M14,'Septembre'!M14,'Octobre'!M14,'Novembre'!M14,'Décembre'!M14),"") | AE12: =IF(ISNUMBER(CHOOSE($Z$3,'Janvier'!Q14,'Février'!Q14,'Mars'!Q14,'Avril'!Q14,'Mai'!Q14,'Juin'!Q14,'Juillet'!Q14,'Août'!Q14,'Septembre'!Q14,'Octobre'!Q14,'Novembre'!Q14,'Décembre'!Q14)),CHOOSE($Z$3,'Janvier'!Q14,'Février'!Q14,'Mars'!Q14,'Avril'!Q14,'Mai'!Q14,'Juin'!Q14,'Juillet'!Q14,'Août'!Q14,'Septembre'!Q14,'Octobre'!Q14,'Novembre'!Q14,'Décembre'!Q14),"") | AF12: =IF(ISNUMBER(CHOOSE($Z$3,'Janvier'!T14,'Février'!T14,'Mars'!T14,'Avril'!T14,'Mai'!T14,'Juin'!T14,'Juillet'!T14,'Août'!T14,'Septembre'!T14,'Octobre'!T14,'Novembre'!T14,'Décembre'!T14)),CHOOSE($Z$3,'Janvier'!T14,'Février'!T14,'Mars'!T14,'Avril'!T14,'Mai'!T14,'Juin'!T14,'Juillet'!T14,'Août'!T14,'Septembre'!T14,'Octobre'!T14,'Novembre'!T14,'Décembre'!T14),"") | AG12: =IF(ISNUMBER(CHOOSE($Z$3,'Janvier'!U14,'Février'!U14,'Mars'!U14,'Avril'!U14,'Mai'!U14,'Juin'!U14,'Juillet'!U14,'Août'!U14,'Septembre'!U14,'Octobre'!U14,'Novembre'!U14,'Décembre'!U14)),CHOOSE($Z$3,'Janvier'!U14,'Février'!U14,'Mars'!U14,'Avril'!U14,'Mai'!U14,'Juin'!U14,'Juillet'!U14,'Août'!U14,'Septembre'!U14,'Octobre'!U14,'Novembre'!U14,'Décembre'!U14),"") | AH12: =IF(ISNUMBER(CHOOSE($Z$3,'Janvier'!V14,'Février'!V14,'Mars'!V14,'Avril'!V14,'Mai'!V14,'Juin'!V14,'Juillet'!V14,'Août'!V14,'Septembre'!V14,'Octobre'!V14,'Novembre'!V14,'Décembre'!V14)),CHOOSE($Z$3,'Janvier'!V14,'Février'!V14,'Mars'!V14,'Avril'!V14,'Mai'!V14,'Juin'!V14,'Juillet'!V14,'Août'!V14,'Septembre'!V14,'Octobre'!V14,'Novembre'!V14,'Décembre'!V14),"") | AI12: =IF(ISNUMBER(CHOOSE($Z$3,'Janvier'!W14,'Février'!W14,'Mars'!W14,'Avril'!W14,'Mai'!W14,'Juin'!W14,'Juillet'!W14,'Août'!W14,'Septembre'!W14,'Octobre'!W14,'Novembre'!W14,'Décembre'!W14)),CHOOSE($Z$3,'Janvier'!W14,'Février'!W14,'Mars'!W14,'Avril'!W14,'Mai'!W14,'Juin'!W14,'Juillet'!W14,'Août'!W14,'Septembre'!W14,'Octobre'!W14,'Novembre'!W14,'Décembre'!W14),"") | AJ12: =IF(Produits!$A$13="","",Produits!$D$13) | AK12: =IF(ISNUMBER(CHOOSE($Z$3,'Janvier'!X14,'Février'!X14,'Mars'!X14,'Avril'!X14,'Mai'!X14,'Juin'!X14,'Juillet'!X14,'Août'!X14,'Septembre'!X14,'Octobre'!X14,'Novembre'!X14,'Décembre'!X14)),CHOOSE($Z$3,'Janvier'!X14,'Février'!X14,'Mars'!X14,'Avril'!X14,'Mai'!X14,'Juin'!X14,'Juillet'!X14,'Août'!X14,'Septembre'!X14,'Octobre'!X14,'Novembre'!X14,'Décembre'!X14),"") | AL12: =IF(AND(ISNUMBER(AI12),ISNUMBER(AJ12)),IF(AI12<=AJ12,1,0),0) | AM12: =IF(OR(AA12="",AK12=""),-1,AK12+ROW()/1000000)
A13: 2 | B13: =IF(LARGE($AM$5:$AM$64,2)<=0,"",INDEX($AA$5:$AA$64,MATCH(LARGE($AM$5:$AM$64,2),$AM$5:$AM$64,0))) | D13: =IF(B13="","",INDEX($AG$5:$AG$64,MATCH(LARGE($AM$5:$AM$64,2),$AM$5:$AM$64,0))) | E13: =IF(B13="","",INDEX($AK$5:$AK$64,MATCH(LARGE($AM$5:$AM$64,2),$AM$5:$AM$64,0))) | Z13: Septembre | AA13: =IF(Produits!$A$14="","",Produits!$A$14) | AB13: =IF(ISNUMBER(CHOOSE($Z$3,'Janvier'!E15,'Février'!E15,'Mars'!E15,'Avril'!E15,'Mai'!E15,'Juin'!E15,'Juillet'!E15,'Août'!E15,'Septembre'!E15,'Octobre'!E15,'Novembre'!E15,'Décembre'!E15)),CHOOSE($Z$3,'Janvier'!E15,'Février'!E15,'Mars'!E15,'Avril'!E15,'Mai'!E15,'Juin'!E15,'Juillet'!E15,'Août'!E15,'Septembre'!E15,'Octobre'!E15,'Novembre'!E15,'Décembre'!E15),"") | AC13: =IF(ISNUMBER(CHOOSE($Z$3,'Janvier'!I15,'Février'!I15,'Mars'!I15,'Avril'!I15,'Mai'!I15,'Juin'!I15,'Juillet'!I15,'Août'!I15,'Septembre'!I15,'Octobre'!I15,'Novembre'!I15,'Décembre'!I15)),CHOOSE($Z$3,'Janvier'!I15,'Février'!I15,'Mars'!I15,'Avril'!I15,'Mai'!I15,'Juin'!I15,'Juillet'!I15,'Août'!I15,'Septembre'!I15,'Octobre'!I15,'Novembre'!I15,'Décembre'!I15),"") | AD13: =IF(ISNUMBER(CHOOSE($Z$3,'Janvier'!M15,'Février'!M15,'Mars'!M15,'Avril'!M15,'Mai'!M15,'Juin'!M15,'Juillet'!M15,'Août'!M15,'Septembre'!M15,'Octobre'!M15,'Novembre'!M15,'Décembre'!M15)),CHOOSE($Z$3,'Janvier'!M15,'Février'!M15,'Mars'!M15,'Avril'!M15,'Mai'!M15,'Juin'!M15,'Juillet'!M15,'Août'!M15,'Septembre'!M15,'Octobre'!M15,'Novembre'!M15,'Décembre'!M15),"") | AE13: =IF(ISNUMBER(CHOOSE($Z$3,'Janvier'!Q15,'Février'!Q15,'Mars'!Q15,'Avril'!Q15,'Mai'!Q15,'Juin'!Q15,'Juillet'!Q15,'Août'!Q15,'Septembre'!Q15,'Octobre'!Q15,'Novembre'!Q15,'Décembre'!Q15)),CHOOSE($Z$3,'Janvier'!Q15,'Février'!Q15,'Mars'!Q15,'Avril'!Q15,'Mai'!Q15,'Juin'!Q15,'Juillet'!Q15,'Août'!Q15,'Septembre'!Q15,'Octobre'!Q15,'Novembre'!Q15,'Décembre'!Q15),"") | AF13: =IF(ISNUMBER(CHOOSE($Z$3,'Janvier'!T15,'Février'!T15,'Mars'!T15,'Avril'!T15,'Mai'!T15,'Juin'!T15,'Juillet'!T15,'Août'!T15,'Septembre'!T15,'Octobre'!T15,'Novembre'!T15,'Décembre'!T15)),CHOOSE($Z$3,'Janvier'!T15,'Février'!T15,'Mars'!T15,'Avril'!T15,'Mai'!T15,'Juin'!T15,'Juillet'!T15,'Août'!T15,'Septembre'!T15,'Octobre'!T15,'Novembre'!T15,'Décembre'!T15),"") | AG13: =IF(ISNUMBER(CHOOSE($Z$3,'Janvier'!U15,'Février'!U15,'Mars'!U15,'Avril'!U15,'Mai'!U15,'Juin'!U15,'Juillet'!U15,'Août'!U15,'Septembre'!U15,'Octobre'!U15,'Novembre'!U15,'Décembre'!U15)),CHOOSE($Z$3,'Janvier'!U15,'Février'!U15,'Mars'!U15,'Avril'!U15,'Mai'!U15,'Juin'!U15,'Juillet'!U15,'Août'!U15,'Septembre'!U15,'Octobre'!U15,'Novembre'!U15,'Décembre'!U15),"") | AH13: =IF(ISNUMBER(CHOOSE($Z$3,'Janvier'!V15,'Février'!V15,'Mars'!V15,'Avril'!V15,'Mai'!V15,'Juin'!V15,'Juillet'!V15,'Août'!V15,'Septembre'!V15,'Octobre'!V15,'Novembre'!V15,'Décembre'!V15)),CHOOSE($Z$3,'Janvier'!V15,'Février'!V15,'Mars'!V15,'Avril'!V15,'Mai'!V15,'Juin'!V15,'Juillet'!V15,'Août'!V15,'Septembre'!V15,'Octobre'!V15,'Novembre'!V15,'Décembre'!V15),"") | AI13: =IF(ISNUMBER(CHOOSE($Z$3,'Janvier'!W15,'Février'!W15,'Mars'!W15,'Avril'!W15,'Mai'!W15,'Juin'!W15,'Juillet'!W15,'Août'!W15,'Septembre'!W15,'Octobre'!W15,'Novembre'!W15,'Décembre'!W15)),CHOOSE($Z$3,'Janvier'!W15,'Février'!W15,'Mars'!W15,'Avril'!W15,'Mai'!W15,'Juin'!W15,'Juillet'!W15,'Août'!W15,'Septembre'!W15,'Octobre'!W15,'Novembre'!W15,'Décembre'!W15),"") | AJ13: =IF(Produits!$A$14="","",Produits!$D$14) | AK13: =IF(ISNUMBER(CHOOSE($Z$3,'Janvier'!X15,'Février'!X15,'Mars'!X15,'Avril'!X15,'Mai'!X15,'Juin'!X15,'Juillet'!X15,'Août'!X15,'Septembre'!X15,'Octobre'!X15,'Novembre'!X15,'Décembre'!X15)),CHOOSE($Z$3,'Janvier'!X15,'Février'!X15,'Mars'!X15,'Avril'!X15,'Mai'!X15,'Juin'!X15,'Juillet'!X15,'Août'!X15,'Septembre'!X15,'Octobre'!X15,'Novembre'!X15,'Décembre'!X15),"") | AL13: =IF(AND(ISNUMBER(AI13),ISNUMBER(AJ13)),IF(AI13<=AJ13,1,0),0) | AM13: =IF(OR(AA13="",AK13=""),-1,AK13+ROW()/1000000)
A14: 3 | B14: =IF(LARGE($AM$5:$AM$64,3)<=0,"",INDEX($AA$5:$AA$64,MATCH(LARGE($AM$5:$AM$64,3),$AM$5:$AM$64,0))) | D14: =IF(B14="","",INDEX($AG$5:$AG$64,MATCH(LARGE($AM$5:$AM$64,3),$AM$5:$AM$64,0))) | E14: =IF(B14="","",INDEX($AK$5:$AK$64,MATCH(LARGE($AM$5:$AM$64,3),$AM$5:$AM$64,0))) | Z14: Octobre | AA14: =IF(Produits!$A$15="","",Produits!$A$15) | AB14: =IF(ISNUMBER(CHOOSE($Z$3,'Janvier'!E16,'Février'!E16,'Mars'!E16,'Avril'!E16,'Mai'!E16,'Juin'!E16,'Juillet'!E16,'Août'!E16,'Septembre'!E16,'Octobre'!E16,'Novembre'!E16,'Décembre'!E16)),CHOOSE($Z$3,'Janvier'!E16,'Février'!E16,'Mars'!E16,'Avril'!E16,'Mai'!E16,'Juin'!E16,'Juillet'!E16,'Août'!E16,'Septembre'!E16,'Octobre'!E16,'Novembre'!E16,'Décembre'!E16),"") | AC14: =IF(ISNUMBER(CHOOSE($Z$3,'Janvier'!I16,'Février'!I16,'Mars'!I16,'Avril'!I16,'Mai'!I16,'Juin'!I16,'Juillet'!I16,'Août'!I16,'Septembre'!I16,'Octobre'!I16,'Novembre'!I16,'Décembre'!I16)),CHOOSE($Z$3,'Janvier'!I16,'Février'!I16,'Mars'!I16,'Avril'!I16,'Mai'!I16,'Juin'!I16,'Juillet'!I16,'Août'!I16,'Septembre'!I16,'Octobre'!I16,'Novembre'!I16,'Décembre'!I16),"") | AD14: =IF(ISNUMBER(CHOOSE($Z$3,'Janvier'!M16,'Février'!M16,'Mars'!M16,'Avril'!M16,'Mai'!M16,'Juin'!M16,'Juillet'!M16,'Août'!M16,'Septembre'!M16,'Octobre'!M16,'Novembre'!M16,'Décembre'!M16)),CHOOSE($Z$3,'Janvier'!M16,'Février'!M16,'Mars'!M16,'Avril'!M16,'Mai'!M16,'Juin'!M16,'Juillet'!M16,'Août'!M16,'Septembre'!M16,'Octobre'!M16,'Novembre'!M16,'Décembre'!M16),"") | AE14: =IF(ISNUMBER(CHOOSE($Z$3,'Janvier'!Q16,'Février'!Q16,'Mars'!Q16,'Avril'!Q16,'Mai'!Q16,'Juin'!Q16,'Juillet'!Q16,'Août'!Q16,'Septembre'!Q16,'Octobre'!Q16,'Novembre'!Q16,'Décembre'!Q16)),CHOOSE($Z$3,'Janvier'!Q16,'Février'!Q16,'Mars'!Q16,'Avril'!Q16,'Mai'!Q16,'Juin'!Q16,'Juillet'!Q16,'Août'!Q16,'Septembre'!Q16,'Octobre'!Q16,'Novembre'!Q16,'Décembre'!Q16),"") | AF14: =IF(ISNUMBER(CHOOSE($Z$3,'Janvier'!T16,'Février'!T16,'Mars'!T16,'Avril'!T16,'Mai'!T16,'Juin'!T16,'Juillet'!T16,'Août'!T16,'Septembre'!T16,'Octobre'!T16,'Novembre'!T16,'Décembre'!T16)),CHOOSE($Z$3,'Janvier'!T16,'Février'!T16,'Mars'!T16,'Avril'!T16,'Mai'!T16,'Juin'!T16,'Juillet'!T16,'Août'!T16,'Septembre'!T16,'Octobre'!T16,'Novembre'!T16,'Décembre'!T16),"") | AG14: =IF(ISNUMBER(CHOOSE($Z$3,'Janvier'!U16,'Février'!U16,'Mars'!U16,'Avril'!U16,'Mai'!U16,'Juin'!U16,'Juillet'!U16,'Août'!U16,'Septembre'!U16,'Octobre'!U16,'Novembre'!U16,'Décembre'!U16)),CHOOSE($Z$3,'Janvier'!U16,'Février'!U16,'Mars'!U16,'Avril'!U16,'Mai'!U16,'Juin'!U16,'Juillet'!U16,'Août'!U16,'Septembre'!U16,'Octobre'!U16,'Novembre'!U16,'Décembre'!U16),"") | AH14: =IF(ISNUMBER(CHOOSE($Z$3,'Janvier'!V16,'Février'!V16,'Mars'!V16,'Avril'!V16,'Mai'!V16,'Juin'!V16,'Juillet'!V16,'Août'!V16,'Septembre'!V16,'Octobre'!V16,'Novembre'!V16,'Décembre'!V16)),CHOOSE($Z$3,'Janvier'!V16,'Février'!V16,'Mars'!V16,'Avril'!V16,'Mai'!V16,'Juin'!V16,'Juillet'!V16,'Août'!V16,'Septembre'!V16,'Octobre'!V16,'Novembre'!V16,'Décembre'!V16),"") | AI14: =IF(ISNUMBER(CHOOSE($Z$3,'Janvier'!W16,'Février'!W16,'Mars'!W16,'Avril'!W16,'Mai'!W16,'Juin'!W16,'Juillet'!W16,'Août'!W16,'Septembre'!W16,'Octobre'!W16,'Novembre'!W16,'Décembre'!W16)),CHOOSE($Z$3,'Janvier'!W16,'Février'!W16,'Mars'!W16,'Avril'!W16,'Mai'!W16,'Juin'!W16,'Juillet'!W16,'Août'!W16,'Septembre'!W16,'Octobre'!W16,'Novembre'!W16,'Décembre'!W16),"") | AJ14: =IF(Produits!$A$15="","",Produits!$D$15) | AK14: =IF(ISNUMBER(CHOOSE($Z$3,'Janvier'!X16,'Février'!X16,'Mars'!X16,'Avril'!X16,'Mai'!X16,'Juin'!X16,'Juillet'!X16,'Août'!X16,'Septembre'!X16,'Octobre'!X16,'Novembre'!X16,'Décembre'!X16)),CHOOSE($Z$3,'Janvier'!X16,'Février'!X16,'Mars'!X16,'Avril'!X16,'Mai'!X16,'Juin'!X16,'Juillet'!X16,'Août'!X16,'Septembre'!X16,'Octobre'!X16,'Novembre'!X16,'Décembre'!X16),"") | AL14: =IF(AND(ISNUMBER(AI14),ISNUMBER(AJ14)),IF(AI14<=AJ14,1,0),0) | AM14: =IF(OR(AA14="",AK14=""),-1,AK14+ROW()/1000000)
A15: 4 | B15: =IF(LARGE($AM$5:$AM$64,4)<=0,"",INDEX($AA$5:$AA$64,MATCH(LARGE($AM$5:$AM$64,4),$AM$5:$AM$64,0))) | D15: =IF(B15="","",INDEX($AG$5:$AG$64,MATCH(LARGE($AM$5:$AM$64,4),$AM$5:$AM$64,0))) | E15: =IF(B15="","",INDEX($AK$5:$AK$64,MATCH(LARGE($AM$5:$AM$64,4),$AM$5:$AM$64,0))) | Z15: Novembre | AA15: =IF(Produits!$A$16="","",Produits!$A$16) | AB15: =IF(ISNUMBER(CHOOSE($Z$3,'Janvier'!E17,'Février'!E17,'Mars'!E17,'Avril'!E17,'Mai'!E17,'Juin'!E17,'Juillet'!E17,'Août'!E17,'Septembre'!E17,'Octobre'!E17,'Novembre'!E17,'Décembre'!E17)),CHOOSE($Z$3,'Janvier'!E17,'Février'!E17,'Mars'!E17,'Avril'!E17,'Mai'!E17,'Juin'!E17,'Juillet'!E17,'Août'!E17,'Septembre'!E17,'Octobre'!E17,'Novembre'!E17,'Décembre'!E17),"") | AC15: =IF(ISNUMBER(CHOOSE($Z$3,'Janvier'!I17,'Février'!I17,'Mars'!I17,'Avril'!I17,'Mai'!I17,'Juin'!I17,'Juillet'!I17,'Août'!I17,'Septembre'!I17,'Octobre'!I17,'Novembre'!I17,'Décembre'!I17)),CHOOSE($Z$3,'Janvier'!I17,'Février'!I17,'Mars'!I17,'Avril'!I17,'Mai'!I17,'Juin'!I17,'Juillet'!I17,'Août'!I17,'Septembre'!I17,'Octobre'!I17,'Novembre'!I17,'Décembre'!I17),"") | AD15: =IF(ISNUMBER(CHOOSE($Z$3,'Janvier'!M17,'Février'!M17,'Mars'!M17,'Avril'!M17,'Mai'!M17,'Juin'!M17,'Juillet'!M17,'Août'!M17,'Septembre'!M17,'Octobre'!M17,'Novembre'!M17,'Décembre'!M17)),CHOOSE($Z$3,'Janvier'!M17,'Février'!M17,'Mars'!M17,'Avril'!M17,'Mai'!M17,'Juin'!M17,'Juillet'!M17,'Août'!M17,'Septembre'!M17,'Octobre'!M17,'Novembre'!M17,'Décembre'!M17),"") | AE15: =IF(ISNUMBER(CHOOSE($Z$3,'Janvier'!Q17,'Février'!Q17,'Mars'!Q17,'Avril'!Q17,'Mai'!Q17,'Juin'!Q17,'Juillet'!Q17,'Août'!Q17,'Septembre'!Q17,'Octobre'!Q17,'Novembre'!Q17,'Décembre'!Q17)),CHOOSE($Z$3,'Janvier'!Q17,'Février'!Q17,'Mars'!Q17,'Avril'!Q17,'Mai'!Q17,'Juin'!Q17,'Juillet'!Q17,'Août'!Q17,'Septembre'!Q17,'Octobre'!Q17,'Novembre'!Q17,'Décembre'!Q17),"") | AF15: =IF(ISNUMBER(CHOOSE($Z$3,'Janvier'!T17,'Février'!T17,'Mars'!T17,'Avril'!T17,'Mai'!T17,'Juin'!T17,'Juillet'!T17,'Août'!T17,'Septembre'!T17,'Octobre'!T17,'Novembre'!T17,'Décembre'!T17)),CHOOSE($Z$3,'Janvier'!T17,'Février'!T17,'Mars'!T17,'Avril'!T17,'Mai'!T17,'Juin'!T17,'Juillet'!T17,'Août'!T17,'Septembre'!T17,'Octobre'!T17,'Novembre'!T17,'Décembre'!T17),"") | AG15: =IF(ISNUMBER(CHOOSE($Z$3,'Janvier'!U17,'Février'!U17,'Mars'!U17,'Avril'!U17,'Mai'!U17,'Juin'!U17,'Juillet'!U17,'Août'!U17,'Septembre'!U17,'Octobre'!U17,'Novembre'!U17,'Décembre'!U17)),CHOOSE($Z$3,'Janvier'!U17,'Février'!U17,'Mars'!U17,'Avril'!U17,'Mai'!U17,'Juin'!U17,'Juillet'!U17,'Août'!U17,'Septembre'!U17,'Octobre'!U17,'Novembre'!U17,'Décembre'!U17),"") | AH15: =IF(ISNUMBER(CHOOSE($Z$3,'Janvier'!V17,'Février'!V17,'Mars'!V17,'Avril'!V17,'Mai'!V17,'Juin'!V17,'Juillet'!V17,'Août'!V17,'Septembre'!V17,'Octobre'!V17,'Novembre'!V17,'Décembre'!V17)),CHOOSE($Z$3,'Janvier'!V17,'Février'!V17,'Mars'!V17,'Avril'!V17,'Mai'!V17,'Juin'!V17,'Juillet'!V17,'Août'!V17,'Septembre'!V17,'Octobre'!V17,'Novembre'!V17,'Décembre'!V17),"") | AI15: =IF(ISNUMBER(CHOOSE($Z$3,'Janvier'!W17,'Février'!W17,'Mars'!W17,'Avril'!W17,'Mai'!W17,'Juin'!W17,'Juillet'!W17,'Août'!W17,'Septembre'!W17,'Octobre'!W17,'Novembre'!W17,'Décembre'!W17)),CHOOSE($Z$3,'Janvier'!W17,'Février'!W17,'Mars'!W17,'Avril'!W17,'Mai'!W17,'Juin'!W17,'Juillet'!W17,'Août'!W17,'Septembre'!W17,'Octobre'!W17,'Novembre'!W17,'Décembre'!W17),"") | AJ15: =IF(Produits!$A$16="","",Produits!$D$16) | AK15: =IF(ISNUMBER(CHOOSE($Z$3,'Janvier'!X17,'Février'!X17,'Mars'!X17,'Avril'!X17,'Mai'!X17,'Juin'!X17,'Juillet'!X17,'Août'!X17,'Septembre'!X17,'Octobre'!X17,'Novembre'!X17,'Décembre'!X17)),CHOOSE($Z$3,'Janvier'!X17,'Février'!X17,'Mars'!X17,'Avril'!X17,'Mai'!X17,'Juin'!X17,'Juillet'!X17,'Août'!X17,'Septembre'!X17,'Octobre'!X17,'Novembre'!X17,'Décembre'!X17),"") | AL15: =IF(AND(ISNUMBER(AI15),ISNUMBER(AJ15)),IF(AI15<=AJ15,1,0),0) | AM15: =IF(OR(AA15="",AK15=""),-1,AK15+ROW()/1000000)
A16: 5 | B16: =IF(LARGE($AM$5:$AM$64,5)<=0,"",INDEX($AA$5:$AA$64,MATCH(LARGE($AM$5:$AM$64,5),$AM$5:$AM$64,0))) | D16: =IF(B16="","",INDEX($AG$5:$AG$64,MATCH(LARGE($AM$5:$AM$64,5),$AM$5:$AM$64,0))) | E16: =IF(B16="","",INDEX($AK$5:$AK$64,MATCH(LARGE($AM$5:$AM$64,5),$AM$5:$AM$64,0))) | Z16: Décembre | AA16: =IF(Produits!$A$17="","",Produits!$A$17) | AB16: =IF(ISNUMBER(CHOOSE($Z$3,'Janvier'!E18,'Février'!E18,'Mars'!E18,'Avril'!E18,'Mai'!E18,'Juin'!E18,'Juillet'!E18,'Août'!E18,'Septembre'!E18,'Octobre'!E18,'Novembre'!E18,'Décembre'!E18)),CHOOSE($Z$3,'Janvier'!E18,'Février'!E18,'Mars'!E18,'Avril'!E18,'Mai'!E18,'Juin'!E18,'Juillet'!E18,'Août'!E18,'Septembre'!E18,'Octobre'!E18,'Novembre'!E18,'Décembre'!E18),"") | AC16: =IF(ISNUMBER(CHOOSE($Z$3,'Janvier'!I18,'Février'!I18,'Mars'!I18,'Avril'!I18,'Mai'!I18,'Juin'!I18,'Juillet'!I18,'Août'!I18,'Septembre'!I18,'Octobre'!I18,'Novembre'!I18,'Décembre'!I18)),CHOOSE($Z$3,'Janvier'!I18,'Février'!I18,'Mars'!I18,'Avril'!I18,'Mai'!I18,'Juin'!I18,'Juillet'!I18,'Août'!I18,'Septembre'!I18,'Octobre'!I18,'Novembre'!I18,'Décembre'!I18),"") | AD16: =IF(ISNUMBER(CHOOSE($Z$3,'Janvier'!M18,'Février'!M18,'Mars'!M18,'Avril'!M18,'Mai'!M18,'Juin'!M18,'Juillet'!M18,'Août'!M18,'Septembre'!M18,'Octobre'!M18,'Novembre'!M18,'Décembre'!M18)),CHOOSE($Z$3,'Janvier'!M18,'Février'!M18,'Mars'!M18,'Avril'!M18,'Mai'!M18,'Juin'!M18,'Juillet'!M18,'Août'!M18,'Septembre'!M18,'Octobre'!M18,'Novembre'!M18,'Décembre'!M18),"") | AE16: =IF(ISNUMBER(CHOOSE($Z$3,'Janvier'!Q18,'Février'!Q18,'Mars'!Q18,'Avril'!Q18,'Mai'!Q18,'Juin'!Q18,'Juillet'!Q18,'Août'!Q18,'Septembre'!Q18,'Octobre'!Q18,'Novembre'!Q18,'Décembre'!Q18)),CHOOSE($Z$3,'Janvier'!Q18,'Février'!Q18,'Mars'!Q18,'Avril'!Q18,'Mai'!Q18,'Juin'!Q18,'Juillet'!Q18,'Août'!Q18,'Septembre'!Q18,'Octobre'!Q18,'Novembre'!Q18,'Décembre'!Q18),"") | AF16: =IF(ISNUMBER(CHOOSE($Z$3,'Janvier'!T18,'Février'!T18,'Mars'!T18,'Avril'!T18,'Mai'!T18,'Juin'!T18,'Juillet'!T18,'Août'!T18,'Septembre'!T18,'Octobre'!T18,'Novembre'!T18,'Décembre'!T18)),CHOOSE($Z$3,'Janvier'!T18,'Février'!T18,'Mars'!T18,'Avril'!T18,'Mai'!T18,'Juin'!T18,'Juillet'!T18,'Août'!T18,'Septembre'!T18,'Octobre'!T18,'Novembre'!T18,'Décembre'!T18),"") | AG16: =IF(ISNUMBER(CHOOSE($Z$3,'Janvier'!U18,'Février'!U18,'Mars'!U18,'Avril'!U18,'Mai'!U18,'Juin'!U18,'Juillet'!U18,'Août'!U18,'Septembre'!U18,'Octobre'!U18,'Novembre'!U18,'Décembre'!U18)),CHOOSE($Z$3,'Janvier'!U18,'Février'!U18,'Mars'!U18,'Avril'!U18,'Mai'!U18,'Juin'!U18,'Juillet'!U18,'Août'!U18,'Septembre'!U18,'Octobre'!U18,'Novembre'!U18,'Décembre'!U18),"") | AH16: =IF(ISNUMBER(CHOOSE($Z$3,'Janvier'!V18,'Février'!V18,'Mars'!V18,'Avril'!V18,'Mai'!V18,'Juin'!V18,'Juillet'!V18,'Août'!V18,'Septembre'!V18,'Octobre'!V18,'Novembre'!V18,'Décembre'!V18)),CHOOSE($Z$3,'Janvier'!V18,'Février'!V18,'Mars'!V18,'Avril'!V18,'Mai'!V18,'Juin'!V18,'Juillet'!V18,'Août'!V18,'Septembre'!V18,'Octobre'!V18,'Novembre'!V18,'Décembre'!V18),"") | AI16: =IF(ISNUMBER(CHOOSE($Z$3,'Janvier'!W18,'Février'!W18,'Mars'!W18,'Avril'!W18,'Mai'!W18,'Juin'!W18,'Juillet'!W18,'Août'!W18,'Septembre'!W18,'Octobre'!W18,'Novembre'!W18,'Décembre'!W18)),CHOOSE($Z$3,'Janvier'!W18,'Février'!W18,'Mars'!W18,'Avril'!W18,'Mai'!W18,'Juin'!W18,'Juillet'!W18,'Août'!W18,'Septembre'!W18,'Octobre'!W18,'Novembre'!W18,'Décembre'!W18),"") | AJ16: =IF(Produits!$A$17="","",Produits!$D$17) | AK16: =IF(ISNUMBER(CHOOSE($Z$3,'Janvier'!X18,'Février'!X18,'Mars'!X18,'Avril'!X18,'Mai'!X18,'Juin'!X18,'Juillet'!X18,'Août'!X18,'Septembre'!X18,'Octobre'!X18,'Novembre'!X18,'Décembre'!X18)),CHOOSE($Z$3,'Janvier'!X18,'Février'!X18,'Mars'!X18,'Avril'!X18,'Mai'!X18,'Juin'!X18,'Juillet'!X18,'Août'!X18,'Septembre'!X18,'Octobre'!X18,'Novembre'!X18,'Décembre'!X18),"") | AL16: =IF(AND(ISNUMBER(AI16),ISNUMBER(AJ16)),IF(AI16<=AJ16,1,0),0) | AM16: =IF(OR(AA16="",AK16=""),-1,AK16+ROW()/1000000)
A17: 6 | B17: =IF(LARGE($AM$5:$AM$64,6)<=0,"",INDEX($AA$5:$AA$64,MATCH(LARGE($AM$5:$AM$64,6),$AM$5:$AM$64,0))) | D17: =IF(B17="","",INDEX($AG$5:$AG$64,MATCH(LARGE($AM$5:$AM$64,6),$AM$5:$AM$64,0))) | E17: =IF(B17="","",INDEX($AK$5:$AK$64,MATCH(LARGE($AM$5:$AM$64,6),$AM$5:$AM$64,0))) | AA17: =IF(Produits!$A$18="","",Produits!$A$18) | AB17: =IF(ISNUMBER(CHOOSE($Z$3,'Janvier'!E19,'Février'!E19,'Mars'!E19,'Avril'!E19,'Mai'!E19,'Juin'!E19,'Juillet'!E19,'Août'!E19,'Septembre'!E19,'Octobre'!E19,'Novembre'!E19,'Décembre'!E19)),CHOOSE($Z$3,'Janvier'!E19,'Février'!E19,'Mars'!E19,'Avril'!E19,'Mai'!E19,'Juin'!E19,'Juillet'!E19,'Août'!E19,'Septembre'!E19,'Octobre'!E19,'Novembre'!E19,'Décembre'!E19),"") | AC17: =IF(ISNUMBER(CHOOSE($Z$3,'Janvier'!I19,'Février'!I19,'Mars'!I19,'Avril'!I19,'Mai'!I19,'Juin'!I19,'Juillet'!I19,'Août'!I19,'Septembre'!I19,'Octobre'!I19,'Novembre'!I19,'Décembre'!I19)),CHOOSE($Z$3,'Janvier'!I19,'Février'!I19,'Mars'!I19,'Avril'!I19,'Mai'!I19,'Juin'!I19,'Juillet'!I19,'Août'!I19,'Septembre'!I19,'Octobre'!I19,'Novembre'!I19,'Décembre'!I19),"") | AD17: =IF(ISNUMBER(CHOOSE($Z$3,'Janvier'!M19,'Février'!M19,'Mars'!M19,'Avril'!M19,'Mai'!M19,'Juin'!M19,'Juillet'!M19,'Août'!M19,'Septembre'!M19,'Octobre'!M19,'Novembre'!M19,'Décembre'!M19)),CHOOSE($Z$3,'Janvier'!M19,'Février'!M19,'Mars'!M19,'Avril'!M19,'Mai'!M19,'Juin'!M19,'Juillet'!M19,'Août'!M19,'Septembre'!M19,'Octobre'!M19,'Novembre'!M19,'Décembre'!M19),"") | AE17: =IF(ISNUMBER(CHOOSE($Z$3,'Janvier'!Q19,'Février'!Q19,'Mars'!Q19,'Avril'!Q19,'Mai'!Q19,'Juin'!Q19,'Juillet'!Q19,'Août'!Q19,'Septembre'!Q19,'Octobre'!Q19,'Novembre'!Q19,'Décembre'!Q19)),CHOOSE($Z$3,'Janvier'!Q19,'Février'!Q19,'Mars'!Q19,'Avril'!Q19,'Mai'!Q19,'Juin'!Q19,'Juillet'!Q19,'Août'!Q19,'Septembre'!Q19,'Octobre'!Q19,'Novembre'!Q19,'Décembre'!Q19),"") | AF17: =IF(ISNUMBER(CHOOSE($Z$3,'Janvier'!T19,'Février'!T19,'Mars'!T19,'Avril'!T19,'Mai'!T19,'Juin'!T19,'Juillet'!T19,'Août'!T19,'Septembre'!T19,'Octobre'!T19,'Novembre'!T19,'Décembre'!T19)),CHOOSE($Z$3,'Janvier'!T19,'Février'!T19,'Mars'!T19,'Avril'!T19,'Mai'!T19,'Juin'!T19,'Juillet'!T19,'Août'!T19,'Septembre'!T19,'Octobre'!T19,'Novembre'!T19,'Décembre'!T19),"") | AG17: =IF(ISNUMBER(CHOOSE($Z$3,'Janvier'!U19,'Février'!U19,'Mars'!U19,'Avril'!U19,'Mai'!U19,'Juin'!U19,'Juillet'!U19,'Août'!U19,'Septembre'!U19,'Octobre'!U19,'Novembre'!U19,'Décembre'!U19)),CHOOSE($Z$3,'Janvier'!U19,'Février'!U19,'Mars'!U19,'Avril'!U19,'Mai'!U19,'Juin'!U19,'Juillet'!U19,'Août'!U19,'Septembre'!U19,'Octobre'!U19,'Novembre'!U19,'Décembre'!U19),"") | AH17: =IF(ISNUMBER(CHOOSE($Z$3,'Janvier'!V19,'Février'!V19,'Mars'!V19,'Avril'!V19,'Mai'!V19,'Juin'!V19,'Juillet'!V19,'Août'!V19,'Septembre'!V19,'Octobre'!V19,'Novembre'!V19,'Décembre'!V19)),CHOOSE($Z$3,'Janvier'!V19,'Février'!V19,'Mars'!V19,'Avril'!V19,'Mai'!V19,'Juin'!V19,'Juillet'!V19,'Août'!V19,'Septembre'!V19,'Octobre'!V19,'Novembre'!V19,'Décembre'!V19),"") | AI17: =IF(ISNUMBER(CHOOSE($Z$3,'Janvier'!W19,'Février'!W19,'Mars'!W19,'Avril'!W19,'Mai'!W19,'Juin'!W19,'Juillet'!W19,'Août'!W19,'Septembre'!W19,'Octobre'!W19,'Novembre'!W19,'Décembre'!W19)),CHOOSE($Z$3,'Janvier'!W19,'Février'!W19,'Mars'!W19,'Avril'!W19,'Mai'!W19,'Juin'!W19,'Juillet'!W19,'Août'!W19,'Septembre'!W19,'Octobre'!W19,'Novembre'!W19,'Décembre'!W19),"") | AJ17: =IF(Produits!$A$18="","",Produits!$D$18) | AK17: =IF(ISNUMBER(CHOOSE($Z$3,'Janvier'!X19,'Février'!X19,'Mars'!X19,'Avril'!X19,'Mai'!X19,'Juin'!X19,'Juillet'!X19,'Août'!X19,'Septembre'!X19,'Octobre'!X19,'Novembre'!X19,'Décembre'!X19)),CHOOSE($Z$3,'Janvier'!X19,'Février'!X19,'Mars'!X19,'Avril'!X19,'Mai'!X19,'Juin'!X19,'Juillet'!X19,'Août'!X19,'Septembre'!X19,'Octobre'!X19,'Novembre'!X19,'Décembre'!X19),"") | AL17: =IF(AND(ISNUMBER(AI17),ISNUMBER(AJ17)),IF(AI17<=AJ17,1,0),0) | AM17: =IF(OR(AA17="",AK17=""),-1,AK17+ROW()/1000000)
A18: 7 | B18: =IF(LARGE($AM$5:$AM$64,7)<=0,"",INDEX($AA$5:$AA$64,MATCH(LARGE($AM$5:$AM$64,7),$AM$5:$AM$64,0))) | D18: =IF(B18="","",INDEX($AG$5:$AG$64,MATCH(LARGE($AM$5:$AM$64,7),$AM$5:$AM$64,0))) | E18: =IF(B18="","",INDEX($AK$5:$AK$64,MATCH(LARGE($AM$5:$AM$64,7),$AM$5:$AM$64,0))) | AA18: =IF(Produits!$A$19="","",Produits!$A$19) | AB18: =IF(ISNUMBER(CHOOSE($Z$3,'Janvier'!E20,'Février'!E20,'Mars'!E20,'Avril'!E20,'Mai'!E20,'Juin'!E20,'Juillet'!E20,'Août'!E20,'Septembre'!E20,'Octobre'!E20,'Novembre'!E20,'Décembre'!E20)),CHOOSE($Z$3,'Janvier'!E20,'Février'!E20,'Mars'!E20,'Avril'!E20,'Mai'!E20,'Juin'!E20,'Juillet'!E20,'Août'!E20,'Septembre'!E20,'Octobre'!E20,'Novembre'!E20,'Décembre'!E20),"") | AC18: =IF(ISNUMBER(CHOOSE($Z$3,'Janvier'!I20,'Février'!I20,'Mars'!I20,'Avril'!I20,'Mai'!I20,'Juin'!I20,'Juillet'!I20,'Août'!I20,'Septembre'!I20,'Octobre'!I20,'Novembre'!I20,'Décembre'!I20)),CHOOSE($Z$3,'Janvier'!I20,'Février'!I20,'Mars'!I20,'Avril'!I20,'Mai'!I20,'Juin'!I20,'Juillet'!I20,'Août'!I20,'Septembre'!I20,'Octobre'!I20,'Novembre'!I20,'Décembre'!I20),"") | AD18: =IF(ISNUMBER(CHOOSE($Z$3,'Janvier'!M20,'Février'!M20,'Mars'!M20,'Avril'!M20,'Mai'!M20,'Juin'!M20,'Juillet'!M20,'Août'!M20,'Septembre'!M20,'Octobre'!M20,'Novembre'!M20,'Décembre'!M20)),CHOOSE($Z$3,'Janvier'!M20,'Février'!M20,'Mars'!M20,'Avril'!M20,'Mai'!M20,'Juin'!M20,'Juillet'!M20,'Août'!M20,'Septembre'!M20,'Octobre'!M20,'Novembre'!M20,'Décembre'!M20),"") | AE18: =IF(ISNUMBER(CHOOSE($Z$3,'Janvier'!Q20,'Février'!Q20,'Mars'!Q20,'Avril'!Q20,'Mai'!Q20,'Juin'!Q20,'Juillet'!Q20,'Août'!Q20,'Septembre'!Q20,'Octobre'!Q20,'Novembre'!Q20,'Décembre'!Q20)),CHOOSE($Z$3,'Janvier'!Q20,'Février'!Q20,'Mars'!Q20,'Avril'!Q20,'Mai'!Q20,'Juin'!Q20,'Juillet'!Q20,'Août'!Q20,'Septembre'!Q20,'Octobre'!Q20,'Novembre'!Q20,'Décembre'!Q20),"") | AF18: =IF(ISNUMBER(CHOOSE($Z$3,'Janvier'!T20,'Février'!T20,'Mars'!T20,'Avril'!T20,'Mai'!T20,'Juin'!T20,'Juillet'!T20,'Août'!T20,'Septembre'!T20,'Octobre'!T20,'Novembre'!T20,'Décembre'!T20)),CHOOSE($Z$3,'Janvier'!T20,'Février'!T20,'Mars'!T20,'Avril'!T20,'Mai'!T20,'Juin'!T20,'Juillet'!T20,'Août'!T20,'Septembre'!T20,'Octobre'!T20,'Novembre'!T20,'Décembre'!T20),"") | AG18: =IF(ISNUMBER(CHOOSE($Z$3,'Janvier'!U20,'Février'!U20,'Mars'!U20,'Avril'!U20,'Mai'!U20,'Juin'!U20,'Juillet'!U20,'Août'!U20,'Septembre'!U20,'Octobre'!U20,'Novembre'!U20,'Décembre'!U20)),CHOOSE($Z$3,'Janvier'!U20,'Février'!U20,'Mars'!U20,'Avril'!U20,'Mai'!U20,'Juin'!U20,'Juillet'!U20,'Août'!U20,'Septembre'!U20,'Octobre'!U20,'Novembre'!U20,'Décembre'!U20),"") | AH18: =IF(ISNUMBER(CHOOSE($Z$3,'Janvier'!V20,'Février'!V20,'Mars'!V20,'Avril'!V20,'Mai'!V20,'Juin'!V20,'Juillet'!V20,'Août'!V20,'Septembre'!V20,'Octobre'!V20,'Novembre'!V20,'Décembre'!V20)),CHOOSE($Z$3,'Janvier'!V20,'Février'!V20,'Mars'!V20,'Avril'!V20,'Mai'!V20,'Juin'!V20,'Juillet'!V20,'Août'!V20,'Septembre'!V20,'Octobre'!V20,'Novembre'!V20,'Décembre'!V20),"") | AI18: =IF(ISNUMBER(CHOOSE($Z$3,'Janvier'!W20,'Février'!W20,'Mars'!W20,'Avril'!W20,'Mai'!W20,'Juin'!W20,'Juillet'!W20,'Août'!W20,'Septembre'!W20,'Octobre'!W20,'Novembre'!W20,'Décembre'!W20)),CHOOSE($Z$3,'Janvier'!W20,'Février'!W20,'Mars'!W20,'Avril'!W20,'Mai'!W20,'Juin'!W20,'Juillet'!W20,'Août'!W20,'Septembre'!W20,'Octobre'!W20,'Novembre'!W20,'Décembre'!W20),"") | AJ18: =IF(Produits!$A$19="","",Produits!$D$19) | AK18: =IF(ISNUMBER(CHOOSE($Z$3,'Janvier'!X20,'Février'!X20,'Mars'!X20,'Avril'!X20,'Mai'!X20,'Juin'!X20,'Juillet'!X20,'Août'!X20,'Septembre'!X20,'Octobre'!X20,'Novembre'!X20,'Décembre'!X20)),CHOOSE($Z$3,'Janvier'!X20,'Février'!X20,'Mars'!X20,'Avril'!X20,'Mai'!X20,'Juin'!X20,'Juillet'!X20,'Août'!X20,'Septembre'!X20,'Octobre'!X20,'Novembre'!X20,'Décembre'!X20),"") | AL18: =IF(AND(ISNUMBER(AI18),ISNUMBER(AJ18)),IF(AI18<=AJ18,1,0),0) | AM18: =IF(OR(AA18="",AK18=""),-1,AK18+ROW()/1000000)
A19: 8 | B19: =IF(LARGE($AM$5:$AM$64,8)<=0,"",INDEX($AA$5:$AA$64,MATCH(LARGE($AM$5:$AM$64,8),$AM$5:$AM$64,0))) | D19: =IF(B19="","",INDEX($AG$5:$AG$64,MATCH(LARGE($AM$5:$AM$64,8),$AM$5:$AM$64,0))) | E19: =IF(B19="","",INDEX($AK$5:$AK$64,MATCH(LARGE($AM$5:$AM$64,8),$AM$5:$AM$64,0))) | AA19: =IF(Produits!$A$20="","",Produits!$A$20) | AB19: =IF(ISNUMBER(CHOOSE($Z$3,'Janvier'!E21,'Février'!E21,'Mars'!E21,'Avril'!E21,'Mai'!E21,'Juin'!E21,'Juillet'!E21,'Août'!E21,'Septembre'!E21,'Octobre'!E21,'Novembre'!E21,'Décembre'!E21)),CHOOSE($Z$3,'Janvier'!E21,'Février'!E21,'Mars'!E21,'Avril'!E21,'Mai'!E21,'Juin'!E21,'Juillet'!E21,'Août'!E21,'Septembre'!E21,'Octobre'!E21,'Novembre'!E21,'Décembre'!E21),"") | AC19: =IF(ISNUMBER(CHOOSE($Z$3,'Janvier'!I21,'Février'!I21,'Mars'!I21,'Avril'!I21,'Mai'!I21,'Juin'!I21,'Juillet'!I21,'Août'!I21,'Septembre'!I21,'Octobre'!I21,'Novembre'!I21,'Décembre'!I21)),CHOOSE($Z$3,'Janvier'!I21,'Février'!I21,'Mars'!I21,'Avril'!I21,'Mai'!I21,'Juin'!I21,'Juillet'!I21,'Août'!I21,'Septembre'!I21,'Octobre'!I21,'Novembre'!I21,'Décembre'!I21),"") | AD19: =IF(ISNUMBER(CHOOSE($Z$3,'Janvier'!M21,'Février'!M21,'Mars'!M21,'Avril'!M21,'Mai'!M21,'Juin'!M21,'Juillet'!M21,'Août'!M21,'Septembre'!M21,'Octobre'!M21,'Novembre'!M21,'Décembre'!M21)),CHOOSE($Z$3,'Janvier'!M21,'Février'!M21,'Mars'!M21,'Avril'!M21,'Mai'!M21,'Juin'!M21,'Juillet'!M21,'Août'!M21,'Septembre'!M21,'Octobre'!M21,'Novembre'!M21,'Décembre'!M21),"") | AE19: =IF(ISNUMBER(CHOOSE($Z$3,'Janvier'!Q21,'Février'!Q21,'Mars'!Q21,'Avril'!Q21,'Mai'!Q21,'Juin'!Q21,'Juillet'!Q21,'Août'!Q21,'Septembre'!Q21,'Octobre'!Q21,'Novembre'!Q21,'Décembre'!Q21)),CHOOSE($Z$3,'Janvier'!Q21,'Février'!Q21,'Mars'!Q21,'Avril'!Q21,'Mai'!Q21,'Juin'!Q21,'Juillet'!Q21,'Août'!Q21,'Septembre'!Q21,'Octobre'!Q21,'Novembre'!Q21,'Décembre'!Q21),"") | AF19: =IF(ISNUMBER(CHOOSE($Z$3,'Janvier'!T21,'Février'!T21,'Mars'!T21,'Avril'!T21,'Mai'!T21,'Juin'!T21,'Juillet'!T21,'Août'!T21,'Septembre'!T21,'Octobre'!T21,'Novembre'!T21,'Décembre'!T21)),CHOOSE($Z$3,'Janvier'!T21,'Février'!T21,'Mars'!T21,'Avril'!T21,'Mai'!T21,'Juin'!T21,'Juillet'!T21,'Août'!T21,'Septembre'!T21,'Octobre'!T21,'Novembre'!T21,'Décembre'!T21),"") | AG19: =IF(ISNUMBER(CHOOSE($Z$3,'Janvier'!U21,'Février'!U21,'Mars'!U21,'Avril'!U21,'Mai'!U21,'Juin'!U21,'Juillet'!U21,'Août'!U21,'Septembre'!U21,'Octobre'!U21,'Novembre'!U21,'Décembre'!U21)),CHOOSE($Z$3,'Janvier'!U21,'Février'!U21,'Mars'!U21,'Avril'!U21,'Mai'!U21,'Juin'!U21,'Juillet'!U21,'Août'!U21,'Septembre'!U21,'Octobre'!U21,'Novembre'!U21,'Décembre'!U21),"") | AH19: =IF(ISNUMBER(CHOOSE($Z$3,'Janvier'!V21,'Février'!V21,'Mars'!V21,'Avril'!V21,'Mai'!V21,'Juin'!V21,'Juillet'!V21,'Août'!V21,'Septembre'!V21,'Octobre'!V21,'Novembre'!V21,'Décembre'!V21)),CHOOSE($Z$3,'Janvier'!V21,'Février'!V21,'Mars'!V21,'Avril'!V21,'Mai'!V21,'Juin'!V21,'Juillet'!V21,'Août'!V21,'Septembre'!V21,'Octobre'!V21,'Novembre'!V21,'Décembre'!V21),"") | AI19: =IF(ISNUMBER(CHOOSE($Z$3,'Janvier'!W21,'Février'!W21,'Mars'!W21,'Avril'!W21,'Mai'!W21,'Juin'!W21,'Juillet'!W21,'Août'!W21,'Septembre'!W21,'Octobre'!W21,'Novembre'!W21,'Décembre'!W21)),CHOOSE($Z$3,'Janvier'!W21,'Février'!W21,'Mars'!W21,'Avril'!W21,'Mai'!W21,'Juin'!W21,'Juillet'!W21,'Août'!W21,'Septembre'!W21,'Octobre'!W21,'Novembre'!W21,'Décembre'!W21),"") | AJ19: =IF(Produits!$A$20="","",Produits!$D$20) | AK19: =IF(ISNUMBER(CHOOSE($Z$3,'Janvier'!X21,'Février'!X21,'Mars'!X21,'Avril'!X21,'Mai'!X21,'Juin'!X21,'Juillet'!X21,'Août'!X21,'Septembre'!X21,'Octobre'!X21,'Novembre'!X21,'Décembre'!X21)),CHOOSE($Z$3,'Janvier'!X21,'Février'!X21,'Mars'!X21,'Avril'!X21,'Mai'!X21,'Juin'!X21,'Juillet'!X21,'Août'!X21,'Septembre'!X21,'Octobre'!X21,'Novembre'!X21,'Décembre'!X21),"") | AL19: =IF(AND(ISNUMBER(AI19),ISNUMBER(AJ19)),IF(AI19<=AJ19,1,0),0) | AM19: =IF(OR(AA19="",AK19=""),-1,AK19+ROW()/1000000)
