Workbook

Sheet Mode d'emploi
A1: 3 · Le journal
A2: Proposition de tableau de gestion des stocks — Excel et Google Sheets
A4: L'idée | B4: Au lieu d'un grand tableau, tu ajoutes simplement une ligne à chaque fois : la date, le produit (choisi dans une liste), et les quantités. Le fichier range tout et fait les totaux du mois tout seul. Le plus simple à remplir sur téléphone.
A6: Comment faire | B6: 1. Remplis l'onglet Produits une seule fois.
B7: 2. Onglet Saisies : une nouvelle ligne = une date + un produit. Choisis le produit dans la liste déroulante.
B8: 3. Tu peux remplir Stock et Commandé le vendredi, puis compléter Reçu sur la même ligne à la livraison.
B9: 4. Onglet Synthèse : tape le mois et l'année en haut, tous les totaux s'affichent. Rien à dupliquer, un seul fichier pour toute l'année.
A11: Les onglets | B11: Produits — ta liste.
B12: Saisies — le journal, une ligne par produit et par comptage.
B13: Synthèse — choisis un mois, tout est calculé.
A15: Couleurs | B15: Cases jaunes = à remplir. Cases blanches = calculées toutes seules, ne pas y toucher.
B16: Chiffres en bleu = exemple pour montrer le fonctionnement, à effacer.
B17: Rouge = il manque quelque chose (livraison incomplète, stock trop bas).
A19: Google Sheets | B19: Fichier > Importer > Importer ce fichier. Tout fonctionne pareil, y compris sur téléphone.

Sheet Produits
A1: Mes produits
A2: Une ligne par produit. Tout le reste du fichier se remplit à partir de cette liste.
A4: Produit | B4: Fournisseur | C4: Unité
A5: Farine T55 | B5: Metro | C5: kg
A6: Farine T45 | B6: Metro | C6: kg
A7: Sucre semoule | B7: Metro | C7: kg
A8: Sucre glace | B8: Metro | C8: kg
A9: Beurre doux | B9: Crèmerie | C9: kg
A10: Crème liquide 35% | B10: Crèmerie | C10: L
A11: Lait entier | B11: Crèmerie | C11: L
A12: Oeufs | B12: Crèmerie | C12: pièce
A13: Chocolat blanc | B13: Transgourmet | C13: kg
A14: Chocolat noir 70% | B14: Transgourmet | C14: kg
A15: Levure chimique | B15: Transgourmet | C15: kg
A16: Vanille (gousse) | B16: Transgourmet | C16: pièce

Sheet Synthèse
A1: Synthèse du mois
A2: Tape le mois et l'année dans les cases jaunes : tout le tableau se recalcule.
A3: Mois (1 à 12) | B3: 10 | C3: Année | D3: 2026
A5: Produit | B5: Unité | C5: Commandé S1 | D5: Commandé S2 | E5: Commandé S3 | F5: Commandé S4 | G5: Total commandé | H5: Total reçu | I5: Manque | J5: Dernier stock | K5: Compté le
A6: =IF(Produits!$A$5="","",Produits!$A$5) | B6: =IF(Produits!$A$5="","",Produits!$C$5) | C6: =IF($A6="","",IF(COUNTIFS(Saisies!$B$5:$B$304,$A6,Saisies!$J$5:$J$304,$B$3,Saisies!$K$5:$K$304,$D$3,Saisies!$I$5:$I$304,"S1",Saisies!$F$5:$F$304,">=0")=0,"",SUMIFS(Saisies!$F$5:$F$304,Saisies!$B$5:$B$304,$A6,Saisies!$J$5:$J$304,$B$3,Saisies!$K$5:$K$304,$D$3,Saisies!$I$5:$I$304,"S1"))) | D6: =IF($A6="","",IF(COUNTIFS(Saisies!$B$5:$B$304,$A6,Saisies!$J$5:$J$304,$B$3,Saisies!$K$5:$K$304,$D$3,Saisies!$I$5:$I$304,"S2",Saisies!$F$5:$F$304,">=0")=0,"",SUMIFS(Saisies!$F$5:$F$304,Saisies!$B$5:$B$304,$A6,Saisies!$J$5:$J$304,$B$3,Saisies!$K$5:$K$304,$D$3,Saisies!$I$5:$I$304,"S2"))) | E6: =IF($A6="","",IF(COUNTIFS(Saisies!$B$5:$B$304,$A6,Saisies!$J$5:$J$304,$B$3,Saisies!$K$5:$K$304,$D$3,Saisies!$I$5:$I$304,"S3",Saisies!$F$5:$F$304,">=0")=0,"",SUMIFS(Saisies!$F$5:$F$304,Saisies!$B$5:$B$304,$A6,Saisies!$J$5:$J$304,$B$3,Saisies!$K$5:$K$304,$D$3,Saisies!$I$5:$I$304,"S3"))) | F6: =IF($A6="","",IF(COUNTIFS(Saisies!$B$5:$B$304,$A6,Saisies!$J$5:$J$304,$B$3,Saisies!$K$5:$K$304,$D$3,Saisies!$I$5:$I$304,"S4",Saisies!$F$5:$F$304,">=0")=0,"",SUMIFS(Saisies!$F$5:$F$304,Saisies!$B$5:$B$304,$A6,Saisies!$J$5:$J$304,$B$3,Saisies!$K$5:$K$304,$D$3,Saisies!$I$5:$I$304,"S4"))) | G6: =IF($A6="","",IF(COUNTIFS(Saisies!$B$5:$B$304,$A6,Saisies!$J$5:$J$304,$B$3,Saisies!$K$5:$K$304,$D$3,Saisies!$F$5:$F$304,">=0")=0,"",SUMIFS(Saisies!$F$5:$F$304,Saisies!$B$5:$B$304,$A6,Saisies!$J$5:$J$304,$B$3,Saisies!$K$5:$K$304,$D$3))) | H6: =IF($A6="","",IF(COUNTIFS(Saisies!$B$5:$B$304,$A6,Saisies!$J$5:$J$304,$B$3,Saisies!$K$5:$K$304,$D$3,Saisies!$G$5:$G$304,">=0")=0,"",SUMIFS(Saisies!$G$5:$G$304,Saisies!$B$5:$B$304,$A6,Saisies!$J$5:$J$304,$B$3,Saisies!$K$5:$K$304,$D$3))) | I6: =IF(OR(G6="",H6=""),"",H6-G6) | J6: =IF(K6="","",SUMIFS(Saisies!$E$5:$E$304,Saisies!$B$5:$B$304,$A6,Saisies!$A$5:$A$304,K6)) | K6: =IF($A6="","",IF(COUNTIFS(Saisies!$B$5:$B$304,$A6,Saisies!$J$5:$J$304,$B$3,Saisies!$K$5:$K$304,$D$3,Saisies!$E$5:$E$304,">=0")=0,"",_xlfn.MAXIFS(Saisies!$A$5:$A$304,Saisies!$B$5:$B$304,$A6,Saisies!$J$5:$J$304,$B$3,Saisies!$K$5:$K$304,$D$3,Saisies!$E$5:$E$304,">=0")))
A7: =IF(Produits!$A$6="","",Produits!$A$6) | B7: =IF(Produits!$A$6="","",Produits!$C$6) | C7: =IF($A7="","",IF(COUNTIFS(Saisies!$B$5:$B$304,$A7,Saisies!$J$5:$J$304,$B$3,Saisies!$K$5:$K$304,$D$3,Saisies!$I$5:$I$304,"S1",Saisies!$F$5:$F$304,">=0")=0,"",SUMIFS(Saisies!$F$5:$F$304,Saisies!$B$5:$B$304,$A7,Saisies!$J$5:$J$304,$B$3,Saisies!$K$5:$K$304,$D$3,Saisies!$I$5:$I$304,"S1"))) | D7: =IF($A7="","",IF(COUNTIFS(Saisies!$B$5:$B$304,$A7,Saisies!$J$5:$J$304,$B$3,Saisies!$K$5:$K$304,$D$3,Saisies!$I$5:$I$304,"S2",Saisies!$F$5:$F$304,">=0")=0,"",SUMIFS(Saisies!$F$5:$F$304,Saisies!$B$5:$B$304,$A7,Saisies!$J$5:$J$304,$B$3,Saisies!$K$5:$K$304,$D$3,Saisies!$I$5:$I$304,"S2"))) | E7: =IF($A7="","",IF(COUNTIFS(Saisies!$B$5:$B$304,$A7,Saisies!$J$5:$J$304,$B$3,Saisies!$K$5:$K$304,$D$3,Saisies!$I$5:$I$304,"S3",Saisies!$F$5:$F$304,">=0")=0,"",SUMIFS(Saisies!$F$5:$F$304,Saisies!$B$5:$B$304,$A7,Saisies!$J$5:$J$304,$B$3,Saisies!$K$5:$K$304,$D$3,Saisies!$I$5:$I$304,"S3"))) | F7: =IF($A7="","",IF(COUNTIFS(Saisies!$B$5:$B$304,$A7,Saisies!$J$5:$J$304,$B$3,Saisies!$K$5:$K$304,$D$3,Saisies!$I$5:$I$304,"S4",Saisies!$F$5:$F$304,">=0")=0,"",SUMIFS(Saisies!$F$5:$F$304,Saisies!$B$5:$B$304,$A7,Saisies!$J$5:$J$304,$B$3,Saisies!$K$5:$K$304,$D$3,Saisies!$I$5:$I$304,"S4"))) | G7: =IF($A7="","",IF(COUNTIFS(Saisies!$B$5:$B$304,$A7,Saisies!$J$5:$J$304,$B$3,Saisies!$K$5:$K$304,$D$3,Saisies!$F$5:$F$304,">=0")=0,"",SUMIFS(Saisies!$F$5:$F$304,Saisies!$B$5:$B$304,$A7,Saisies!$J$5:$J$304,$B$3,Saisies!$K$5:$K$304,$D$3))) | H7: =IF($A7="","",IF(COUNTIFS(Saisies!$B$5:$B$304,$A7,Saisies!$J$5:$J$304,$B$3,Saisies!$K$5:$K$304,$D$3,Saisies!$G$5:$G$304,">=0")=0,"",SUMIFS(Saisies!$G$5:$G$304,Saisies!$B$5:$B$304,$A7,Saisies!$J$5:$J$304,$B$3,Saisies!$K$5:$K$304,$D$3))) | I7: =IF(OR(G7="",H7=""),"",H7-G7) | J7: =IF(K7="","",SUMIFS(Saisies!$E$5:$E$304,Saisies!$B$5:$B$304,$A7,Saisies!$A$5:$A$304,K7)) | K7: =IF($A7="","",IF(COUNTIFS(Saisies!$B$5:$B$304,$A7,Saisies!$J$5:$J$304,$B$3,Saisies!$K$5:$K$304,$D$3,Saisies!$E$5:$E$304,">=0")=0,"",_xlfn.MAXIFS(Saisies!$A$5:$A$304,Saisies!$B$5:$B$304,$A7,Saisies!$J$5:$J$304,$B$3,Saisies!$K$5:$K$304,$D$3,Saisies!$E$5:$E$304,">=0")))
A8: =IF(Produits!$A$7="","",Produits!$A$7) | B8: =IF(Produits!$A$7="","",Produits!$C$7) | C8: =IF($A8="","",IF(COUNTIFS(Saisies!$B$5:$B$304,$A8,Saisies!$J$5:$J$304,$B$3,Saisies!$K$5:$K$304,$D$3,Saisies!$I$5:$I$304,"S1",Saisies!$F$5:$F$304,">=0")=0,"",SUMIFS(Saisies!$F$5:$F$304,Saisies!$B$5:$B$304,$A8,Saisies!$J$5:$J$304,$B$3,Saisies!$K$5:$K$304,$D$3,Saisies!$I$5:$I$304,"S1"))) | D8: =IF($A8="","",IF(COUNTIFS(Saisies!$B$5:$B$304,$A8,Saisies!$J$5:$J$304,$B$3,Saisies!$K$5:$K$304,$D$3,Saisies!$I$5:$I$304,"S2",Saisies!$F$5:$F$304,">=0")=0,"",SUMIFS(Saisies!$F$5:$F$304,Saisies!$B$5:$B$304,$A8,Saisies!$J$5:$J$304,$B$3,Saisies!$K$5:$K$304,$D$3,Saisies!$I$5:$I$304,"S2"))) | E8: =IF($A8="","",IF(COUNTIFS(Saisies!$B$5:$B$304,$A8,Saisies!$J$5:$J$304,$B$3,Saisies!$K$5:$K$304,$D$3,Saisies!$I$5:$I$304,"S3",Saisies!$F$5:$F$304,">=0")=0,"",SUMIFS(Saisies!$F$5:$F$304,Saisies!$B$5:$B$304,$A8,Saisies!$J$5:$J$304,$B$3,Saisies!$K$5:$K$304,$D$3,Saisies!$I$5:$I$304,"S3"))) | F8: =IF($A8="","",IF(COUNTIFS(Saisies!$B$5:$B$304,$A8,Saisies!$J$5:$J$304,$B$3,Saisies!$K$5:$K$304,$D$3,Saisies!$I$5:$I$304,"S4",Saisies!$F$5:$F$304,">=0")=0,"",SUMIFS(Saisies!$F$5:$F$304,Saisies!$B$5:$B$304,$A8,Saisies!$J$5:$J$304,$B$3,Saisies!$K$5:$K$304,$D$3,Saisies!$I$5:$I$304,"S4"))) | G8: =IF($A8="","",IF(COUNTIFS(Saisies!$B$5:$B$304,$A8,Saisies!$J$5:$J$304,$B$3,Saisies!$K$5:$K$304,$D$3,Saisies!$F$5:$F$304,">=0")=0,"",SUMIFS(Saisies!$F$5:$F$304,Saisies!$B$5:$B$304,$A8,Saisies!$J$5:$J$304,$B$3,Saisies!$K$5:$K$304,$D$3))) | H8: =IF($A8="","",IF(COUNTIFS(Saisies!$B$5:$B$304,$A8,Saisies!$J$5:$J$304,$B$3,Saisies!$K$5:$K$304,$D$3,Saisies!$G$5:$G$304,">=0")=0,"",SUMIFS(Saisies!$G$5:$G$304,Saisies!$B$5:$B$304,$A8,Saisies!$J$5:$J$304,$B$3,Saisies!$K$5:$K$304,$D$3))) | I8: =IF(OR(G8="",H8=""),"",H8-G8) | J8: =IF(K8="","",SUMIFS(Saisies!$E$5:$E$304,Saisies!$B$5:$B$304,$A8,Saisies!$A$5:$A$304,K8)) | K8: =IF($A8="","",IF(COUNTIFS(Saisies!$B$5:$B$304,$A8,Saisies!$J$5:$J$304,$B$3,Saisies!$K$5:$K$304,$D$3,Saisies!$E$5:$E$304,">=0")=0,"",_xlfn.MAXIFS(Saisies!$A$5:$A$304,Saisies!$B$5:$B$304,$A8,Saisies!$J$5:$J$304,$B$3,Saisies!$K$5:$K$304,$D$3,Saisies!$E$5:$E$304,">=0")))
A9: =IF(Produits!$A$8="","",Produits!$A$8) | B9: =IF(Produits!$A$8="","",Produits!$C$8) | C9: =IF($A9="","",IF(COUNTIFS(Saisies!$B$5:$B$304,$A9,Saisies!$J$5:$J$304,$B$3,Saisies!$K$5:$K$304,$D$3,Saisies!$I$5:$I$304,"S1",Saisies!$F$5:$F$304,">=0")=0,"",SUMIFS(Saisies!$F$5:$F$304,Saisies!$B$5:$B$304,$A9,Saisies!$J$5:$J$304,$B$3,Saisies!$K$5:$K$304,$D$3,Saisies!$I$5:$I$304,"S1"))) | D9: =IF($A9="","",IF(COUNTIFS(Saisies!$B$5:$B$304,$A9,Saisies!$J$5:$J$304,$B$3,Saisies!$K$5:$K$304,$D$3,Saisies!$I$5:$I$304,"S2",Saisies!$F$5:$F$304,">=0")=0,"",SUMIFS(Saisies!$F$5:$F$304,Saisies!$B$5:$B$304,$A9,Saisies!$J$5:$J$304,$B$3,Saisies!$K$5:$K$304,$D$3,Saisies!$I$5:$I$304,"S2"))) | E9: =IF($A9="","",IF(COUNTIFS(Saisies!$B$5:$B$304,$A9,Saisies!$J$5:$J$304,$B$3,Saisies!$K$5:$K$304,$D$3,Saisies!$I$5:$I$304,"S3",Saisies!$F$5:$F$304,">=0")=0,"",SUMIFS(Saisies!$F$5:$F$304,Saisies!$B$5:$B$304,$A9,Saisies!$J$5:$J$304,$B$3,Saisies!$K$5:$K$304,$D$3,Saisies!$I$5:$I$304,"S3"))) | F9: =IF($A9="","",IF(COUNTIFS(Saisies!$B$5:$B$304,$A9,Saisies!$J$5:$J$304,$B$3,Saisies!$K$5:$K$304,$D$3,Saisies!$I$5:$I$304,"S4",Saisies!$F$5:$F$304,">=0")=0,"",SUMIFS(Saisies!$F$5:$F$304,Saisies!$B$5:$B$304,$A9,Saisies!$J$5:$J$304,$B$3,Saisies!$K$5:$K$304,$D$3,Saisies!$I$5:$I$304,"S4"))) | G9: =IF($A9="","",IF(COUNTIFS(Saisies!$B$5:$B$304,$A9,Saisies!$J$5:$J$304,$B$3,Saisies!$K$5:$K$304,$D$3,Saisies!$F$5:$F$304,">=0")=0,"",SUMIFS(Saisies!$F$5:$F$304,Saisies!$B$5:$B$304,$A9,Saisies!$J$5:$J$304,$B$3,Saisies!$K$5:$K$304,$D$3))) | H9: =IF($A9="","",IF(COUNTIFS(Saisies!$B$5:$B$304,$A9,Saisies!$J$5:$J$304,$B$3,Saisies!$K$5:$K$304,$D$3,Saisies!$G$5:$G$304,">=0")=0,"",SUMIFS(Saisies!$G$5:$G$304,Saisies!$B$5:$B$304,$A9,Saisies!$J$5:$J$304,$B$3,Saisies!$K$5:$K$304,$D$3))) | I9: =IF(OR(G9="",H9=""),"",H9-G9) | J9: =IF(K9="","",SUMIFS(Saisies!$E$5:$E$304,Saisies!$B$5:$B$304,$A9,Saisies!$A$5:$A$304,K9)) | K9: =IF($A9="","",IF(COUNTIFS(Saisies!$B$5:$B$304,$A9,Saisies!$J$5:$J$304,$B$3,Saisies!$K$5:$K$304,$D$3,Saisies!$E$5:$E$304,">=0")=0,"",_xlfn.MAXIFS(Saisies!$A$5:$A$304,Saisies!$B$5:$B$304,$A9,Saisies!$J$5:$J$304,$B$3,Saisies!$K$5:$K$304,$D$3,Saisies!$E$5:$E$304,">=0")))
A10: =IF(Produits!$A$9="","",Produits!$A$9) | B10: =IF(Produits!$A$9="","",Produits!$C$9) | C10: =IF($A10="","",IF(COUNTIFS(Saisies!$B$5:$B$304,$A10,Saisies!$J$5:$J$304,$B$3,Saisies!$K$5:$K$304,$D$3,Saisies!$I$5:$I$304,"S1",Saisies!$F$5:$F$304,">=0")=0,"",SUMIFS(Saisies!$F$5:$F$304,Saisies!$B$5:$B$304,$A10,Saisies!$J$5:$J$304,$B$3,Saisies!$K$5:$K$304,$D$3,Saisies!$I$5:$I$304,"S1"))) | D10: =IF($A10="","",IF(COUNTIFS(Saisies!$B$5:$B$304,$A10,Saisies!$J$5:$J$304,$B$3,Saisies!$K$5:$K$304,$D$3,Saisies!$I$5:$I$304,"S2",Saisies!$F$5:$F$304,">=0")=0,"",SUMIFS(Saisies!$F$5:$F$304,Saisies!$B$5:$B$304,$A10,Saisies!$J$5:$J$304,$B$3,Saisies!$K$5:$K$304,$D$3,Saisies!$I$5:$I$304,"S2"))) | E10: =IF($A10="","",IF(COUNTIFS(Saisies!$B$5:$B$304,$A10,Saisies!$J$5:$J$304,$B$3,Saisies!$K$5:$K$304,$D$3,Saisies!$I$5:$I$304,"S3",Saisies!$F$5:$F$304,">=0")=0,"",SUMIFS(Saisies!$F$5:$F$304,Saisies!$B$5:$B$304,$A10,Saisies!$J$5:$J$304,$B$3,Saisies!$K$5:$K$304,$D$3,Saisies!$I$5:$I$304,"S3"))) | F10: =IF($A10="","",IF(COUNTIFS(Saisies!$B$5:$B$304,$A10,Saisies!$J$5:$J$304,$B$3,Saisies!$K$5:$K$304,$D$3,Saisies!$I$5:$I$304,"S4",Saisies!$F$5:$F$304,">=0")=0,"",SUMIFS(Saisies!$F$5:$F$304,Saisies!$B$5:$B$304,$A10,Saisies!$J$5:$J$304,$B$3,Saisies!$K$5:$K$304,$D$3,Saisies!$I$5:$I$304,"S4"))) | G10: =IF($A10="","",IF(COUNTIFS(Saisies!$B$5:$B$304,$A10,Saisies!$J$5:$J$304,$B$3,Saisies!$K$5:$K$304,$D$3,Saisies!$F$5:$F$304,">=0")=0,"",SUMIFS(Saisies!$F$5:$F$304,Saisies!$B$5:$B$304,$A10,Saisies!$J$5:$J$304,$B$3,Saisies!$K$5:$K$304,$D$3))) | H10: =IF($A10="","",IF(COUNTIFS(Saisies!$B$5:$B$304,$A10,Saisies!$J$5:$J$304,$B$3,Saisies!$K$5:$K$304,$D$3,Saisies!$G$5:$G$304,">=0")=0,"",SUMIFS(Saisies!$G$5:$G$304,Saisies!$B$5:$B$304,$A10,Saisies!$J$5:$J$304,$B$3,Saisies!$K$5:$K$304,$D$3))) | I10: =IF(OR(G10="",H10=""),"",H10-G10) | J10: =IF(K10="","",SUMIFS(Saisies!$E$5:$E$304,Saisies!$B$5:$B$304,$A10,Saisies!$A$5:$A$304,K10)) | K10: =IF($A10="","",IF(COUNTIFS(Saisies!$B$5:$B$304,$A10,Saisies!$J$5:$J$304,$B$3,Saisies!$K$5:$K$304,$D$3,Saisies!$E$5:$E$304,">=0")=0,"",_xlfn.MAXIFS(Saisies!$A$5:$A$304,Saisies!$B$5:$B$304,$A10,Saisies!$J$5:$J$304,$B$3,Saisies!$K$5:$K$304,$D$3,Saisies!$E$5:$E$304,">=0")))
A11: =IF(Produits!$A$10="","",Produits!$A$10) | B11: =IF(Produits!$A$10="","",Produits!$C$10) | C11: =IF($A11="","",IF(COUNTIFS(Saisies!$B$5:$B$304,$A11,Saisies!$J$5:$J$304,$B$3,Saisies!$K$5:$K$304,$D$3,Saisies!$I$5:$I$304,"S1",Saisies!$F$5:$F$304,">=0")=0,"",SUMIFS(Saisies!$F$5:$F$304,Saisies!$B$5:$B$304,$A11,Saisies!$J$5:$J$304,$B$3,Saisies!$K$5:$K$304,$D$3,Saisies!$I$5:$I$304,"S1"))) | D11: =IF($A11="","",IF(COUNTIFS(Saisies!$B$5:$B$304,$A11,Saisies!$J$5:$J$304,$B$3,Saisies!$K$5:$K$304,$D$3,Saisies!$I$5:$I$304,"S2",Saisies!$F$5:$F$304,">=0")=0,"",SUMIFS(Saisies!$F$5:$F$304,Saisies!$B$5:$B$304,$A11,Saisies!$J$5:$J$304,$B$3,Saisies!$K$5:$K$304,$D$3,Saisies!$I$5:$I$304,"S2"))) | E11: =IF($A11="","",IF(COUNTIFS(Saisies!$B$5:$B$304,$A11,Saisies!$J$5:$J$304,$B$3,Saisies!$K$5:$K$304,$D$3,Saisies!$I$5:$I$304,"S3",Saisies!$F$5:$F$304,">=0")=0,"",SUMIFS(Saisies!$F$5:$F$304,Saisies!$B$5:$B$304,$A11,Saisies!$J$5:$J$304,$B$3,Saisies!$K$5:$K$304,$D$3,Saisies!$I$5:$I$304,"S3"))) | F11: =IF($A11="","",IF(COUNTIFS(Saisies!$B$5:$B$304,$A11,Saisies!$J$5:$J$304,$B$3,Saisies!$K$5:$K$304,$D$3,Saisies!$I$5:$I$304,"S4",Saisies!$F$5:$F$304,">=0")=0,"",SUMIFS(Saisies!$F$5:$F$304,Saisies!$B$5:$B$304,$A11,Saisies!$J$5:$J$304,$B$3,Saisies!$K$5:$K$304,$D$3,Saisies!$I$5:$I$304,"S4"))) | G11: =IF($A11="","",IF(COUNTIFS(Saisies!$B$5:$B$304,$A11,Saisies!$J$5:$J$304,$B$3,Saisies!$K$5:$K$304,$D$3,Saisies!$F$5:$F$304,">=0")=0,"",SUMIFS(Saisies!$F$5:$F$304,Saisies!$B$5:$B$304,$A11,Saisies!$J$5:$J$304,$B$3,Saisies!$K$5:$K$304,$D$3))) | H11: =IF($A11="","",IF(COUNTIFS(Saisies!$B$5:$B$304,$A11,Saisies!$J$5:$J$304,$B$3,Saisies!$K$5:$K$304,$D$3,Saisies!$G$5:$G$304,">=0")=0,"",SUMIFS(Saisies!$G$5:$G$304,Saisies!$B$5:$B$304,$A11,Saisies!$J$5:$J$304,$B$3,Saisies!$K$5:$K$304,$D$3))) | I11: =IF(OR(G11="",H11=""),"",H11-G11) | J11: =IF(K11="","",SUMIFS(Saisies!$E$5:$E$304,Saisies!$B$5:$B$304,$A11,Saisies!$A$5:$A$304,K11)) | K11: =IF($A11="","",IF(COUNTIFS(Saisies!$B$5:$B$304,$A11,Saisies!$J$5:$J$304,$B$3,Saisies!$K$5:$K$304,$D$3,Saisies!$E$5:$E$304,">=0")=0,"",_xlfn.MAXIFS(Saisies!$A$5:$A$304,Saisies!$B$5:$B$304,$A11,Saisies!$J$5:$J$304,$B$3,Saisies!$K$5:$K$304,$D$3,Saisies!$E$5:$E$304,">=0")))
A12: =IF(Produits!$A$11="","",Produits!$A$11) | B12: =IF(Produits!$A$11="","",Produits!$C$11) | C12: =IF($A12="","",IF(COUNTIFS(Saisies!$B$5:$B$304,$A12,Saisies!$J$5:$J$304,$B$3,Saisies!$K$5:$K$304,$D$3,Saisies!$I$5:$I$304,"S1",Saisies!$F$5:$F$304,">=0")=0,"",SUMIFS(Saisies!$F$5:$F$304,Saisies!$B$5:$B$304,$A12,Saisies!$J$5:$J$304,$B$3,Saisies!$K$5:$K$304,$D$3,Saisies!$I$5:$I$304,"S1"))) | D12: =IF($A12="","",IF(COUNTIFS(Saisies!$B$5:$B$304,$A12,Saisies!$J$5:$J$304,$B$3,Saisies!$K$5:$K$304,$D$3,Saisies!$I$5:$I$304,"S2",Saisies!$F$5:$F$304,">=0")=0,"",SUMIFS(Saisies!$F$5:$F$304,Saisies!$B$5:$B$304,$A12,Saisies!$J$5:$J$304,$B$3,Saisies!$K$5:$K$304,$D$3,Saisies!$I$5:$I$304,"S2"))) | E12: =IF($A12="","",IF(COUNTIFS(Saisies!$B$5:$B$304,$A12,Saisies!$J$5:$J$304,$B$3,Saisies!$K$5:$K$304,$D$3,Saisies!$I$5:$I$304,"S3",Saisies!$F$5:$F$304,">=0")=0,"",SUMIFS(Saisies!$F$5:$F$304,Saisies!$B$5:$B$304,$A12,Saisies!$J$5:$J$304,$B$3,Saisies!$K$5:$K$304,$D$3,Saisies!$I$5:$I$304,"S3"))) | F12: =IF($A12="","",IF(COUNTIFS(Saisies!$B$5:$B$304,$A12,Saisies!$J$5:$J$304,$B$3,Saisies!$K$5:$K$304,$D$3,Saisies!$I$5:$I$304,"S4",Saisies!$F$5:$F$304,">=0")=0,"",SUMIFS(Saisies!$F$5:$F$304,Saisies!$B$5:$B$304,$A12,Saisies!$J$5:$J$304,$B$3,Saisies!$K$5:$K$304,$D$3,Saisies!$I$5:$I$304,"S4"))) | G12: =IF($A12="","",IF(COUNTIFS(Saisies!$B$5:$B$304,$A12,Saisies!$J$5:$J$304,$B$3,Saisies!$K$5:$K$304,$D$3,Saisies!$F$5:$F$304,">=0")=0,"",SUMIFS(Saisies!$F$5:$F$304,Saisies!$B$5:$B$304,$A12,Saisies!$J$5:$J$304,$B$3,Saisies!$K$5:$K$304,$D$3))) | H12: =IF($A12="","",IF(COUNTIFS(Saisies!$B$5:$B$304,$A12,Saisies!$J$5:$J$304,$B$3,Saisies!$K$5:$K$304,$D$3,Saisies!$G$5:$G$304,">=0")=0,"",SUMIFS(Saisies!$G$5:$G$304,Saisies!$B$5:$B$304,$A12,Saisies!$J$5:$J$304,$B$3,Saisies!$K$5:$K$304,$D$3))) | I12: =IF(OR(G12="",H12=""),"",H12-G12) | J12: =IF(K12="","",SUMIFS(Saisies!$E$5:$E$304,Saisies!$B$5:$B$304,$A12,Saisies!$A$5:$A$304,K12)) | K12: =IF($A12="","",IF(COUNTIFS(Saisies!$B$5:$B$304,$A12,Saisies!$J$5:$J$304,$B$3,Saisies!$K$5:$K$304,$D$3,Saisies!$E$5:$E$304,">=0")=0,"",_xlfn.MAXIFS(Saisies!$A$5:$A$304,Saisies!$B$5:$B$304,$A12,Saisies!$J$5:$J$304,$B$3,Saisies!$K$5:$K$304,$D$3,Saisies!$E$5:$E$304,">=0")))
A13: =IF(Produits!$A$12="","",Produits!$A$12) | B13: =IF(Produits!$A$12="","",Produits!$C$12) | C13: =IF($A13="","",IF(COUNTIFS(Saisies!$B$5:$B$304,$A13,Saisies!$J$5:$J$304,$B$3,Saisies!$K$5:$K$304,$D$3,Saisies!$I$5:$I$304,"S1",Saisies!$F$5:$F$304,">=0")=0,"",SUMIFS(Saisies!$F$5:$F$304,Saisies!$B$5:$B$304,$A13,Saisies!$J$5:$J$304,$B$3,Saisies!$K$5:$K$304,$D$3,Saisies!$I$5:$I$304,"S1"))) | D13: =IF($A13="","",IF(COUNTIFS(Saisies!$B$5:$B$304,$A13,Saisies!$J$5:$J$304,$B$3,Saisies!$K$5:$K$304,$D$3,Saisies!$I$5:$I$304,"S2",Saisies!$F$5:$F$304,">=0")=0,"",SUMIFS(Saisies!$F$5:$F$304,Saisies!$B$5:$B$304,$A13,Saisies!$J$5:$J$304,$B$3,Saisies!$K$5:$K$304,$D$3,Saisies!$I$5:$I$304,"S2"))) | E13: =IF($A13="","",IF(COUNTIFS(Saisies!$B$5:$B$304,$A13,Saisies!$J$5:$J$304,$B$3,Saisies!$K$5:$K$304,$D$3,Saisies!$I$5:$I$304,"S3",Saisies!$F$5:$F$304,">=0")=0,"",SUMIFS(Saisies!$F$5:$F$304,Saisies!$B$5:$B$304,$A13,Saisies!$J$5:$J$304,$B$3,Saisies!$K$5:$K$304,$D$3,Saisies!$I$5:$I$304,"S3"))) | F13: =IF($A13="","",IF(COUNTIFS(Saisies!$B$5:$B$304,$A13,Saisies!$J$5:$J$304,$B$3,Saisies!$K$5:$K$304,$D$3,Saisies!$I$5:$I$304,"S4",Saisies!$F$5:$F$304,">=0")=0,"",SUMIFS(Saisies!$F$5:$F$304,Saisies!$B$5:$B$304,$A13,Saisies!$J$5:$J$304,$B$3,Saisies!$K$5:$K$304,$D$3,Saisies!$I$5:$I$304,"S4"))) | G13: =IF($A13="","",IF(COUNTIFS(Saisies!$B$5:$B$304,$A13,Saisies!$J$5:$J$304,$B$3,Saisies!$K$5:$K$304,$D$3,Saisies!$F$5:$F$304,">=0")=0,"",SUMIFS(Saisies!$F$5:$F$304,Saisies!$B$5:$B$304,$A13,Saisies!$J$5:$J$304,$B$3,Saisies!$K$5:$K$304,$D$3))) | H13: =IF($A13="","",IF(COUNTIFS(Saisies!$B$5:$B$304,$A13,Saisies!$J$5:$J$304,$B$3,Saisies!$K$5:$K$304,$D$3,Saisies!$G$5:$G$304,">=0")=0,"",SUMIFS(Saisies!$G$5:$G$304,Saisies!$B$5:$B$304,$A13,Saisies!$J$5:$J$304,$B$3,Saisies!$K$5:$K$304,$D$3))) | I13: =IF(OR(G13="",H13=""),"",H13-G13) | J13: =IF(K13="","",SUMIFS(Saisies!$E$5:$E$304,Saisies!$B$5:$B$304,$A13,Saisies!$A$5:$A$304,K13)) | K13: =IF($A13="","",IF(COUNTIFS(Saisies!$B$5:$B$304,$A13,Saisies!$J$5:$J$304,$B$3,Saisies!$K$5:$K$304,$D$3,Saisies!$E$5:$E$304,">=0")=0,"",_xlfn.MAXIFS(Saisies!$A$5:$A$304,Saisies!$B$5:$B$304,$A13,Saisies!$J$5:$J$304,$B$3,Saisies!$K$5:$K$304,$D$3,Saisies!$E$5:$E$304,">=0")))
A14: =IF(Produits!$A$13="","",Produits!$A$13) | B14: =IF(Produits!$A$13="","",Produits!$C$13) | C14: =IF($A14="","",IF(COUNTIFS(Saisies!$B$5:$B$304,$A14,Saisies!$J$5:$J$304,$B$3,Saisies!$K$5:$K$304,$D$3,Saisies!$I$5:$I$304,"S1",Saisies!$F$5:$F$304,">=0")=0,"",SUMIFS(Saisies!$F$5:$F$304,Saisies!$B$5:$B$304,$A14,Saisies!$J$5:$J$304,$B$3,Saisies!$K$5:$K$304,$D$3,Saisies!$I$5:$I$304,"S1"))) | D14: =IF($A14="","",IF(COUNTIFS(Saisies!$B$5:$B$304,$A14,Saisies!$J$5:$J$304,$B$3,Saisies!$K$5:$K$304,$D$3,Saisies!$I$5:$I$304,"S2",Saisies!$F$5:$F$304,">=0")=0,"",SUMIFS(Saisies!$F$5:$F$304,Saisies!$B$5:$B$304,$A14,Saisies!$J$5:$J$304,$B$3,Saisies!$K$5:$K$304,$D$3,Saisies!$I$5:$I$304,"S2"))) | E14: =IF($A14="","",IF(COUNTIFS(Saisies!$B$5:$B$304,$A14,Saisies!$J$5:$J$304,$B$3,Saisies!$K$5:$K$304,$D$3,Saisies!$I$5:$I$304,"S3",Saisies!$F$5:$F$304,">=0")=0,"",SUMIFS(Saisies!$F$5:$F$304,Saisies!$B$5:$B$304,$A14,Saisies!$J$5:$J$304,$B$3,Saisies!$K$5:$K$304,$D$3,Saisies!$I$5:$I$304,"S3"))) | F14: =IF($A14="","",IF(COUNTIFS(Saisies!$B$5:$B$304,$A14,Saisies!$J$5:$J$304,$B$3,Saisies!$K$5:$K$304,$D$3,Saisies!$I$5:$I$304,"S4",Saisies!$F$5:$F$304,">=0")=0,"",SUMIFS(Saisies!$F$5:$F$304,Saisies!$B$5:$B$304,$A14,Saisies!$J$5:$J$304,$B$3,Saisies!$K$5:$K$304,$D$3,Saisies!$I$5:$I$304,"S4"))) | G14: =IF($A14="","",IF(COUNTIFS(Saisies!$B$5:$B$304,$A14,Saisies!$J$5:$J$304,$B$3,Saisies!$K$5:$K$304,$D$3,Saisies!$F$5:$F$304,">=0")=0,"",SUMIFS(Saisies!$F$5:$F$304,Saisies!$B$5:$B$304,$A14,Saisies!$J$5:$J$304,$B$3,Saisies!$K$5:$K$304,$D$3))) | H14: =IF($A14="","",IF(COUNTIFS(Saisies!$B$5:$B$304,$A14,Saisies!$J$5:$J$304,$B$3,Saisies!$K$5:$K$304,$D$3,Saisies!$G$5:$G$304,">=0")=0,"",SUMIFS(Saisies!$G$5:$G$304,Saisies!$B$5:$B$304,$A14,Saisies!$J$5:$J$304,$B$3,Saisies!$K$5:$K$304,$D$3))) | I14: =IF(OR(G14="",H14=""),"",H14-G14) | J14: =IF(K14="","",SUMIFS(Saisies!$E$5:$E$304,Saisies!$B$5:$B$304,$A14,Saisies!$A$5:$A$304,K14)) | K14: =IF($A14="","",IF(COUNTIFS(Saisies!$B$5:$B$304,$A14,Saisies!$J$5:$J$304,$B$3,Saisies!$K$5:$K$304,$D$3,Saisies!$E$5:$E$304,">=0")=0,"",_xlfn.MAXIFS(Saisies!$A$5:$A$304,Saisies!$B$5:$B$304,$A14,Saisies!$J$5:$J$304,$B$3,Saisies!$K$5:$K$304,$D$3,Saisies!$E$5:$E$304,">=0")))
A15: =IF(Produits!$A$14="","",Produits!$A$14) | B15: =IF(Produits!$A$14="","",Produits!$C$14) | C15: =IF($A15="","",IF(COUNTIFS(Saisies!$B$5:$B$304,$A15,Saisies!$J$5:$J$304,$B$3,Saisies!$K$5:$K$304,$D$3,Saisies!$I$5:$I$304,"S1",Saisies!$F$5:$F$304,">=0")=0,"",SUMIFS(Saisies!$F$5:$F$304,Saisies!$B$5:$B$304,$A15,Saisies!$J$5:$J$304,$B$3,Saisies!$K$5:$K$304,$D$3,Saisies!$I$5:$I$304,"S1"))) | D15: =IF($A15="","",IF(COUNTIFS(Saisies!$B$5:$B$304,$A15,Saisies!$J$5:$J$304,$B$3,Saisies!$K$5:$K$304,$D$3,Saisies!$I$5:$I$304,"S2",Saisies!$F$5:$F$304,">=0")=0,"",SUMIFS(Saisies!$F$5:$F$304,Saisies!$B$5:$B$304,$A15,Saisies!$J$5:$J$304,$B$3,Saisies!$K$5:$K$304,$D$3,Saisies!$I$5:$I$304,"S2"))) | E15: =IF($A15="","",IF(COUNTIFS(Saisies!$B$5:$B$304,$A15,Saisies!$J$5:$J$304,$B$3,Saisies!$K$5:$K$304,$D$3,Saisies!$I$5:$I$304,"S3",Saisies!$F$5:$F$304,">=0")=0,"",SUMIFS(Saisies!$F$5:$F$304,Saisies!$B$5:$B$304,$A15,Saisies!$J$5:$J$304,$B$3,Saisies!$K$5:$K$304,$D$3,Saisies!$I$5:$I$304,"S3"))) | F15: =IF($A15="","",IF(COUNTIFS(Saisies!$B$5:$B$304,$A15,Saisies!$J$5:$J$304,$B$3,Saisies!$K$5:$K$304,$D$3,Saisies!$I$5:$I$304,"S4",Saisies!$F$5:$F$304,">=0")=0,"",SUMIFS(Saisies!$F$5:$F$304,Saisies!$B$5:$B$304,$A15,Saisies!$J$5:$J$304,$B$3,Saisies!$K$5:$K$304,$D$3,Saisies!$I$5:$I$304,"S4"))) | G15: =IF($A15="","",IF(COUNTIFS(Saisies!$B$5:$B$304,$A15,Saisies!$J$5:$J$304,$B$3,Saisies!$K$5:$K$304,$D$3,Saisies!$F$5:$F$304,">=0")=0,"",SUMIFS(Saisies!$F$5:$F$304,Saisies!$B$5:$B$304,$A15,Saisies!$J$5:$J$304,$B$3,Saisies!$K$5:$K$304,$D$3))) | H15: =IF($A15="","",IF(COUNTIFS(Saisies!$B$5:$B$304,$A15,Saisies!$J$5:$J$304,$B$3,Saisies!$K$5:$K$304,$D$3,Saisies!$G$5:$G$304,">=0")=0,"",SUMIFS(Saisies!$G$5:$G$304,Saisies!$B$5:$B$304,$A15,Saisies!$J$5:$J$304,$B$3,Saisies!$K$5:$K$304,$D$3))) | I15: =IF(OR(G15="",H15=""),"",H15-G15) | J15: =IF(K15="","",SUMIFS(Saisies!$E$5:$E$304,Saisies!$B$5:$B$304,$A15,Saisies!$A$5:$A$304,K15)) | K15: =IF($A15="","",IF(COUNTIFS(Saisies!$B$5:$B$304,$A15,Saisies!$J$5:$J$304,$B$3,Saisies!$K$5:$K$304,$D$3,Saisies!$E$5:$E$304,">=0")=0,"",_xlfn.MAXIFS(Saisies!$A$5:$A$304,Saisies!$B$5:$B$304,$A15,Saisies!$J$5:$J$304,$B$3,Saisies!$K$5:$K$304,$D$3,Saisies!$E$5:$E$304,">=0")))
A16: =IF(Produits!$A$15="","",Produits!$A$15) | B16: =IF(Produits!$A$15="","",Produits!$C$15) | C16: =IF($A16="","",IF(COUNTIFS(Saisies!$B$5:$B$304,$A16,Saisies!$J$5:$J$304,$B$3,Saisies!$K$5:$K$304,$D$3,Saisies!$I$5:$I$304,"S1",Saisies!$F$5:$F$304,">=0")=0,"",SUMIFS(Saisies!$F$5:$F$304,Saisies!$B$5:$B$304,$A16,Saisies!$J$5:$J$304,$B$3,Saisies!$K$5:$K$304,$D$3,Saisies!$I$5:$I$304,"S1"))) | D16: =IF($A16="","",IF(COUNTIFS(Saisies!$B$5:$B$304,$A16,Saisies!$J$5:$J$304,$B$3,Saisies!$K$5:$K$304,$D$3,Saisies!$I$5:$I$304,"S2",Saisies!$F$5:$F$304,">=0")=0,"",SUMIFS(Saisies!$F$5:$F$304,Saisies!$B$5:$B$304,$A16,Saisies!$J$5:$J$304,$B$3,Saisies!$K$5:$K$304,$D$3,Saisies!$I$5:$I$304,"S2"))) | E16: =IF($A16="","",IF(COUNTIFS(Saisies!$B$5:$B$304,$A16,Saisies!$J$5:$J$304,$B$3,Saisies!$K$5:$K$304,$D$3,Saisies!$I$5:$I$304,"S3",Saisies!$F$5:$F$304,">=0")=0,"",SUMIFS(Saisies!$F$5:$F$304,Saisies!$B$5:$B$304,$A16,Saisies!$J$5:$J$304,$B$3,Saisies!$K$5:$K$304,$D$3,Saisies!$I$5:$I$304,"S3"))) | F16: =IF($A16="","",IF(COUNTIFS(Saisies!$B$5:$B$304,$A16,Saisies!$J$5:$J$304,$B$3,Saisies!$K$5:$K$304,$D$3,Saisies!$I$5:$I$304,"S4",Saisies!$F$5:$F$304,">=0")=0,"",SUMIFS(Saisies!$F$5:$F$304,Saisies!$B$5:$B$304,$A16,Saisies!$J$5:$J$304,$B$3,Saisies!$K$5:$K$304,$D$3,Saisies!$I$5:$I$304,"S4"))) | G16: =IF($A16="","",IF(COUNTIFS(Saisies!$B$5:$B$304,$A16,Saisies!$J$5:$J$304,$B$3,Saisies!$K$5:$K$304,$D$3,Saisies!$F$5:$F$304,">=0")=0,"",SUMIFS(Saisies!$F$5:$F$304,Saisies!$B$5:$B$304,$A16,Saisies!$J$5:$J$304,$B$3,Saisies!$K$5:$K$304,$D$3))) | H16: =IF($A16="","",IF(COUNTIFS(Saisies!$B$5:$B$304,$A16,Saisies!$J$5:$J$304,$B$3,Saisies!$K$5:$K$304,$D$3,Saisies!$G$5:$G$304,">=0")=0,"",SUMIFS(Saisies!$G$5:$G$304,Saisies!$B$5:$B$304,$A16,Saisies!$J$5:$J$304,$B$3,Saisies!$K$5:$K$304,$D$3))) | I16: =IF(OR(G16="",H16=""),"",H16-G16) | J16: =IF(K16="","",SUMIFS(Saisies!$E$5:$E$304,Saisies!$B$5:$B$304,$A16,Saisies!$A$5:$A$304,K16)) | K16: =IF($A16="","",IF(COUNTIFS(Saisies!$B$5:$B$304,$A16,Saisies!$J$5:$J$304,$B$3,Saisies!$K$5:$K$304,$D$3,Saisies!$E$5:$E$304,">=0")=0,"",_xlfn.MAXIFS(Saisies!$A$5:$A$304,Saisies!$B$5:$B$304,$A16,Saisies!$J$5:$J$304,$B$3,Saisies!$K$5:$K$304,$D$3,Saisies!$E$5:$E$304,">=0")))
A17: =IF(Produits!$A$16="","",Produits!$A$16) | B17: =IF(Produits!$A$16="","",Produits!$C$16) | C17: =IF($A17="","",IF(COUNTIFS(Saisies!$B$5:$B$304,$A17,Saisies!$J$5:$J$304,$B$3,Saisies!$K$5:$K$304,$D$3,Saisies!$I$5:$I$304,"S1",Saisies!$F$5:$F$304,">=0")=0,"",SUMIFS(Saisies!$F$5:$F$304,Saisies!$B$5:$B$304,$A17,Saisies!$J$5:$J$304,$B$3,Saisies!$K$5:$K$304,$D$3,Saisies!$I$5:$I$304,"S1"))) | D17: =IF($A17="","",IF(COUNTIFS(Saisies!$B$5:$B$304,$A17,Saisies!$J$5:$J$304,$B$3,Saisies!$K$5:$K$304,$D$3,Saisies!$I$5:$I$304,"S2",Saisies!$F$5:$F$304,">=0")=0,"",SUMIFS(Saisies!$F$5:$F$304,Saisies!$B$5:$B$304,$A17,Saisies!$J$5:$J$304,$B$3,Saisies!$K$5:$K$304,$D$3,Saisies!$I$5:$I$304,"S2"))) | E17: =IF($A17="","",IF(COUNTIFS(Saisies!$B$5:$B$304,$A17,Saisies!$J$5:$J$304,$B$3,Saisies!$K$5:$K$304,$D$3,Saisies!$I$5:$I$304,"S3",Saisies!$F$5:$F$304,">=0")=0,"",SUMIFS(Saisies!$F$5:$F$304,Saisies!$B$5:$B$304,$A17,Saisies!$J$5:$J$304,$B$3,Saisies!$K$5:$K$304,$D$3,Saisies!$I$5:$I$304,"S3"))) | F17: =IF($A17="","",IF(COUNTIFS(Saisies!$B$5:$B$304,$A17,Saisies!$J$5:$J$304,$B$3,Saisies!$K$5:$K$304,$D$3,Saisies!$I$5:$I$304,"S4",Saisies!$F$5:$F$304,">=0")=0,"",SUMIFS(Saisies!$F$5:$F$304,Saisies!$B$5:$B$304,$A17,Saisies!$J$5:$J$304,$B$3,Saisies!$K$5:$K$304,$D$3,Saisies!$I$5:$I$304,"S4"))) | G17: =IF($A17="","",IF(COUNTIFS(Saisies!$B$5:$B$304,$A17,Saisies!$J$5:$J$304,$B$3,Saisies!$K$5:$K$304,$D$3,Saisies!$F$5:$F$304,">=0")=0,"",SUMIFS(Saisies!$F$5:$F$304,Saisies!$B$5:$B$304,$A17,Saisies!$J$5:$J$304,$B$3,Saisies!$K$5:$K$304,$D$3))) | H17: =IF($A17="","",IF(COUNTIFS(Saisies!$B$5:$B$304,$A17,Saisies!$J$5:$J$304,$B$3,Saisies!$K$5:$K$304,$D$3,Saisies!$G$5:$G$304,">=0")=0,"",SUMIFS(Saisies!$G$5:$G$304,Saisies!$B$5:$B$304,$A17,Saisies!$J$5:$J$304,$B$3,Saisies!$K$5:$K$304,$D$3))) | I17: =IF(OR(G17="",H17=""),"",H17-G17) | J17: =IF(K17="","",SUMIFS(Saisies!$E$5:$E$304,Saisies!$B$5:$B$304,$A17,Saisies!$A$5:$A$304,K17)) | K17: =IF($A17="","",IF(COUNTIFS(Saisies!$B$5:$B$304,$A17,Saisies!$J$5:$J$304,$B$3,Saisies!$K$5:$K$304,$D$3,Saisies!$E$5:$E$304,">=0")=0,"",_xlfn.MAXIFS(Saisies!$A$5:$A$304,Saisies!$B$5:$B$304,$A17,Saisies!$J$5:$J$304,$B$3,Saisies!$K$5:$K$304,$D$3,Saisies!$E$5:$E$304,">=0")))
A18: =IF(Produits!$A$17="","",Produits!$A$17) | B18: =IF(Produits!$A$17="","",Produits!$C$17) | C18: =IF($A18="","",IF(COUNTIFS(Saisies!$B$5:$B$304,$A18,Saisies!$J$5:$J$304,$B$3,Saisies!$K$5:$K$304,$D$3,Saisies!$I$5:$I$304,"S1",Saisies!$F$5:$F$304,">=0")=0,"",SUMIFS(Saisies!$F$5:$F$304,Saisies!$B$5:$B$304,$A18,Saisies!$J$5:$J$304,$B$3,Saisies!$K$5:$K$304,$D$3,Saisies!$I$5:$I$304,"S1"))) | D18: =IF($A18="","",IF(COUNTIFS(Saisies!$B$5:$B$304,$A18,Saisies!$J$5:$J$304,$B$3,Saisies!$K$5:$K$304,$D$3,Saisies!$I$5:$I$304,"S2",Saisies!$F$5:$F$304,">=0")=0,"",SUMIFS(Saisies!$F$5:$F$304,Saisies!$B$5:$B$304,$A18,Saisies!$J$5:$J$304,$B$3,Saisies!$K$5:$K$304,$D$3,Saisies!$I$5:$I$304,"S2"))) | E18: =IF($A18="","",IF(COUNTIFS(Saisies!$B$5:$B$304,$A18,Saisies!$J$5:$J$304,$B$3,Saisies!$K$5:$K$304,$D$3,Saisies!$I$5:$I$304,"S3",Saisies!$F$5:$F$304,">=0")=0,"",SUMIFS(Saisies!$F$5:$F$304,Saisies!$B$5:$B$304,$A18,Saisies!$J$5:$J$304,$B$3,Saisies!$K$5:$K$304,$D$3,Saisies!$I$5:$I$304,"S3"))) | F18: =IF($A18="","",IF(COUNTIFS(Saisies!$B$5:$B$304,$A18,Saisies!$J$5:$J$304,$B$3,Saisies!$K$5:$K$304,$D$3,Saisies!$I$5:$I$304,"S4",Saisies!$F$5:$F$304,">=0")=0,"",SUMIFS(Saisies!$F$5:$F$304,Saisies!$B$5:$B$304,$A18,Saisies!$J$5:$J$304,$B$3,Saisies!$K$5:$K$304,$D$3,Saisies!$I$5:$I$304,"S4"))) | G18: =IF($A18="","",IF(COUNTIFS(Saisies!$B$5:$B$304,$A18,Saisies!$J$5:$J$304,$B$3,Saisies!$K$5:$K$304,$D$3,Saisies!$F$5:$F$304,">=0")=0,"",SUMIFS(Saisies!$F$5:$F$304,Saisies!$B$5:$B$304,$A18,Saisies!$J$5:$J$304,$B$3,Saisies!$K$5:$K$304,$D$3))) | H18: =IF($A18="","",IF(COUNTIFS(Saisies!$B$5:$B$304,$A18,Saisies!$J$5:$J$304,$B$3,Saisies!$K$5:$K$304,$D$3,Saisies!$G$5:$G$304,">=0")=0,"",SUMIFS(Saisies!$G$5:$G$304,Saisies!$B$5:$B$304,$A18,Saisies!$J$5:$J$304,$B$3,Saisies!$K$5:$K$304,$D$3))) | I18: =IF(OR(G18="",H18=""),"",H18-G18) | J18: =IF(K18="","",SUMIFS(Saisies!$E$5:$E$304,Saisies!$B$5:$B$304,$A18,Saisies!$A$5:$A$304,K18)) | K18: =IF($A18="","",IF(COUNTIFS(Saisies!$B$5:$B$304,$A18,Saisies!$J$5:$J$304,$B$3,Saisies!$K$5:$K$304,$D$3,Saisies!$E$5:$E$304,">=0")=0,"",_xlfn.MAXIFS(Saisies!$A$5:$A$304,Saisies!$B$5:$B$304,$A18,Saisies!$J$5:$J$304,$B$3,Saisies!$K$5:$K$304,$D$3,Saisies!$E$5:$E$304,">=0")))
A19: =IF(Produits!$A$18="","",Produits!$A$18) | B19: =IF(Produits!$A$18="","",Produits!$C$18) | C19: =IF($A19="","",IF(COUNTIFS(Saisies!$B$5:$B$304,$A19,Saisies!$J$5:$J$304,$B$3,Saisies!$K$5:$K$304,$D$3,Saisies!$I$5:$I$304,"S1",Saisies!$F$5:$F$304,">=0")=0,"",SUMIFS(Saisies!$F$5:$F$304,Saisies!$B$5:$B$304,$A19,Saisies!$J$5:$J$304,$B$3,Saisies!$K$5:$K$304,$D$3,Saisies!$I$5:$I$304,"S1"))) | D19: =IF($A19="","",IF(COUNTIFS(Saisies!$B$5:$B$304,$A19,Saisies!$J$5:$J$304,$B$3,Saisies!$K$5:$K$304,$D$3,Saisies!$I$5:$I$304,"S2",Saisies!$F$5:$F$304,">=0")=0,"",SUMIFS(Saisies!$F$5:$F$304,Saisies!$B$5:$B$304,$A19,Saisies!$J$5:$J$304,$B$3,Saisies!$K$5:$K$304,$D$3,Saisies!$I$5:$I$304,"S2"))) | E19: =IF($A19="","",IF(COUNTIFS(Saisies!$B$5:$B$304,$A19,Saisies!$J$5:$J$304,$B$3,Saisies!$K$5:$K$304,$D$3,Saisies!$I$5:$I$304,"S3",Saisies!$F$5:$F$304,">=0")=0,"",SUMIFS(Saisies!$F$5:$F$304,Saisies!$B$5:$B$304,$A19,Saisies!$J$5:$J$304,$B$3,Saisies!$K$5:$K$304,$D$3,Saisies!$I$5:$I$304,"S3"))) | F19: =IF($A19="","",IF(COUNTIFS(Saisies!$B$5:$B$304,$A19,Saisies!$J$5:$J$304,$B$3,Saisies!$K$5:$K$304,$D$3,Saisies!$I$5:$I$304,"S4",Saisies!$F$5:$F$304,">=0")=0,"",SUMIFS(Saisies!$F$5:$F$304,Saisies!$B$5:$B$304,$A19,Saisies!$J$5:$J$304,$B$3,Saisies!$K$5:$K$304,$D$3,Saisies!$I$5:$I$304,"S4"))) | G19: =IF($A19="","",IF(COUNTIFS(Saisies!$B$5:$B$304,$A19,Saisies!$J$5:$J$304,$B$3,Saisies!$K$5:$K$304,$D$3,Saisies!$F$5:$F$304,">=0")=0,"",SUMIFS(Saisies!$F$5:$F$304,Saisies!$B$5:$B$304,$A19,Saisies!$J$5:$J$304,$B$3,Saisies!$K$5:$K$304,$D$3))) | H19: =IF($A19="","",IF(COUNTIFS(Saisies!$B$5:$B$304,$A19,Saisies!$J$5:$J$304,$B$3,Saisies!$K$5:$K$304,$D$3,Saisies!$G$5:$G$304,">=0")=0,"",SUMIFS(Saisies!$G$5:$G$304,Saisies!$B$5:$B$304,$A19,Saisies!$J$5:$J$304,$B$3,Saisies!$K$5:$K$304,$D$3))) | I19: =IF(OR(G19="",H19=""),"",H19-G19) | J19: =IF(K19="","",SUMIFS(Saisies!$E$5:$E$304,Saisies!$B$5:$B$304,$A19,Saisies!$A$5:$A$304,K19)) | K19: =IF($A19="","",IF(COUNTIFS(Saisies!$B$5:$B$304,$A19,Saisies!$J$5:$J$304,$B$3,Saisies!$K$5:$K$304,$D$3,Saisies!$E$5:$E$304,">=0")=0,"",_xlfn.MAXIFS(Saisies!$A$5:$A$304,Saisies!$B$5:$B$304,$A19,Saisies!$J$5:$J$304,$B$3,Saisies!$K$5:$K$304,$D$3,Saisies!$E$5:$E$304,">=0")))
A20: =IF(Produits!$A$19="","",Produits!$A$19) | B20: =IF(Produits!$A$19="","",Produits!$C$19) | C20: =IF($A20="","",IF(COUNTIFS(Saisies!$B$5:$B$304,$A20,Saisies!$J$5:$J$304,$B$3,Saisies!$K$5:$K$304,$D$3,Saisies!$I$5:$I$304,"S1",Saisies!$F$5:$F$304,">=0")=0,"",SUMIFS(Saisies!$F$5:$F$304,Saisies!$B$5:$B$304,$A20,Saisies!$J$5:$J$304,$B$3,Saisies!$K$5:$K$304,$D$3,Saisies!$I$5:$I$304,"S1"))) | D20: =IF($A20="","",IF(COUNTIFS(Saisies!$B$5:$B$304,$A20,Saisies!$J$5:$J$304,$B$3,Saisies!$K$5:$K$304,$D$3,Saisies!$I$5:$I$304,"S2",Saisies!$F$5:$F$304,">=0")=0,"",SUMIFS(Saisies!$F$5:$F$304,Saisies!$B$5:$B$304,$A20,Saisies!$J$5:$J$304,$B$3,Saisies!$K$5:$K$304,$D$3,Saisies!$I$5:$I$304,"S2"))) | E20: =IF($A20="","",IF(COUNTIFS(Saisies!$B$5:$B$304,$A20,Saisies!$J$5:$J$304,$B$3,Saisies!$K$5:$K$304,$D$3,Saisies!$I$5:$I$304,"S3",Saisies!$F$5:$F$304,">=0")=0,"",SUMIFS(Saisies!$F$5:$F$304,Saisies!$B$5:$B$304,$A20,Saisies!$J$5:$J$304,$B$3,Saisies!$K$5:$K$304,$D$3,Saisies!$I$5:$I$304,"S3"))) | F20: =IF($A20="","",IF(COUNTIFS(Saisies!$B$5:$B$304,$A20,Saisies!$J$5:$J$304,$B$3,Saisies!$K$5:$K$304,$D$3,Saisies!$I$5:$I$304,"S4",Saisies!$F$5:$F$304,">=0")=0,"",SUMIFS(Saisies!$F$5:$F$304,Saisies!$B$5:$B$304,$A20,Saisies!$J$5:$J$304,$B$3,Saisies!$K$5:$K$304,$D$3,Saisies!$I$5:$I$304,"S4"))) | G20: =IF($A20="","",IF(COUNTIFS(Saisies!$B$5:$B$304,$A20,Saisies!$J$5:$J$304,$B$3,Saisies!$K$5:$K$304,$D$3,Saisies!$F$5:$F$304,">=0")=0,"",SUMIFS(Saisies!$F$5:$F$304,Saisies!$B$5:$B$304,$A20,Saisies!$J$5:$J$304,$B$3,Saisies!$K$5:$K$304,$D$3))) | H20: =IF($A20="","",IF(COUNTIFS(Saisies!$B$5:$B$304,$A20,Saisies!$J$5:$J$304,$B$3,Saisies!$K$5:$K$304,$D$3,Saisies!$G$5:$G$304,">=0")=0,"",SUMIFS(Saisies!$G$5:$G$304,Saisies!$B$5:$B$304,$A20,Saisies!$J$5:$J$304,$B$3,Saisies!$K$5:$K$304,$D$3))) | I20: =IF(OR(G20="",H20=""),"",H20-G20) | J20: =IF(K20="","",SUMIFS(Saisies!$E$5:$E$304,Saisies!$B$5:$B$304,$A20,Saisies!$A$5:$A$304,K20)) | K20: =IF($A20="","",IF(COUNTIFS(Saisies!$B$5:$B$304,$A20,Saisies!$J$5:$J$304,$B$3,Saisies!$K$5:$K$304,$D$3,Saisies!$E$5:$E$304,">=0")=0,"",_xlfn.MAXIFS(Saisies!$A$5:$A$304,Saisies!$B$5:$B$304,$A20,Saisies!$J$5:$J$304,$B$3,Saisies!$K$5:$K$304,$D$3,Saisies!$E$5:$E$304,">=0")))
A21: =IF(Produits!$A$20="","",Produits!$A$20) | B21: =IF(Produits!$A$20="","",Produits!$C$20) | C21: =IF($A21="","",IF(COUNTIFS(Saisies!$B$5:$B$304,$A21,Saisies!$J$5:$J$304,$B$3,Saisies!$K$5:$K$304,$D$3,Saisies!$I$5:$I$304,"S1",Saisies!$F$5:$F$304,">=0")=0,"",SUMIFS(Saisies!$F$5:$F$304,Saisies!$B$5:$B$304,$A21,Saisies!$J$5:$J$304,$B$3,Saisies!$K$5:$K$304,$D$3,Saisies!$I$5:$I$304,"S1"))) | D21: =IF($A21="","",IF(COUNTIFS(Saisies!$B$5:$B$304,$A21,Saisies!$J$5:$J$304,$B$3,Saisies!$K$5:$K$304,$D$3,Saisies!$I$5:$I$304,"S2",Saisies!$F$5:$F$304,">=0")=0,"",SUMIFS(Saisies!$F$5:$F$304,Saisies!$B$5:$B$304,$A21,Saisies!$J$5:$J$304,$B$3,Saisies!$K$5:$K$304,$D$3,Saisies!$I$5:$I$304,"S2"))) | E21: =IF($A21="","",IF(COUNTIFS(Saisies!$B$5:$B$304,$A21,Saisies!$J$5:$J$304,$B$3,Saisies!$K$5:$K$304,$D$3,Saisies!$I$5:$I$304,"S3",Saisies!$F$5:$F$304,">=0")=0,"",SUMIFS(Saisies!$F$5:$F$304,Saisies!$B$5:$B$304,$A21,Saisies!$J$5:$J$304,$B$3,Saisies!$K$5:$K$304,$D$3,Saisies!$I$5:$I$304,"S3"))) | F21: =IF($A21="","",IF(COUNTIFS(Saisies!$B$5:$B$304,$A21,Saisies!$J$5:$J$304,$B$3,Saisies!$K$5:$K$304,$D$3,Saisies!$I$5:$I$304,"S4",Saisies!$F$5:$F$304,">=0")=0,"",SUMIFS(Saisies!$F$5:$F$304,Saisies!$B$5:$B$304,$A21,Saisies!$J$5:$J$304,$B$3,Saisies!$K$5:$K$304,$D$3,Saisies!$I$5:$I$304,"S4"))) | G21: =IF($A21="","",IF(COUNTIFS(Saisies!$B$5:$B$304,$A21,Saisies!$J$5:$J$304,$B$3,Saisies!$K$5:$K$304,$D$3,Saisies!$F$5:$F$304,">=0")=0,"",SUMIFS(Saisies!$F$5:$F$304,Saisies!$B$5:$B$304,$A21,Saisies!$J$5:$J$304,$B$3,Saisies!$K$5:$K$304,$D$3))) | H21: =IF($A21="","",IF(COUNTIFS(Saisies!$B$5:$B$304,$A21,Saisies!$J$5:$J$304,$B$3,Saisies!$K$5:$K$304,$D$3,Saisies!$G$5:$G$304,">=0")=0,"",SUMIFS(Saisies!$G$5:$G$304,Saisies!$B$5:$B$304,$A21,Saisies!$J$5:$J$304,$B$3,Saisies!$K$5:$K$304,$D$3))) | I21: =IF(OR(G21="",H21=""),"",H21-G21) | J21: =IF(K21="","",SUMIFS(Saisies!$E$5:$E$304,Saisies!$B$5:$B$304,$A21,Saisies!$A$5:$A$304,K21)) | K21: =IF($A21="","",IF(COUNTIFS(Saisies!$B$5:$B$304,$A21,Saisies!$J$5:$J$304,$B$3,Saisies!$K$5:$K$304,$D$3,Saisies!$E$5:$E$304,">=0")=0,"",_xlfn.MAXIFS(Saisies!$A$5:$A$304,Saisies!$B$5:$B$304,$A21,Saisies!$J$5:$J$304,$B$3,Saisies!$K$5:$K$304,$D$3,Saisies!$E$5:$E$304,">=0")))
A22: =IF(Produits!$A$21="","",Produits!$A$21) | B22: =IF(Produits!$A$21="","",Produits!$C$21) | C22: =IF($A22="","",IF(COUNTIFS(Saisies!$B$5:$B$304,$A22,Saisies!$J$5:$J$304,$B$3,Saisies!$K$5:$K$304,$D$3,Saisies!$I$5:$I$304,"S1",Saisies!$F$5:$F$304,">=0")=0,"",SUMIFS(Saisies!$F$5:$F$304,Saisies!$B$5:$B$304,$A22,Saisies!$J$5:$J$304,$B$3,Saisies!$K$5:$K$304,$D$3,Saisies!$I$5:$I$304,"S1"))) | D22: =IF($A22="","",IF(COUNTIFS(Saisies!$B$5:$B$304,$A22,Saisies!$J$5:$J$304,$B$3,Saisies!$K$5:$K$304,$D$3,Saisies!$I$5:$I$304,"S2",Saisies!$F$5:$F$304,">=0")=0,"",SUMIFS(Saisies!$F$5:$F$304,Saisies!$B$5:$B$304,$A22,Saisies!$J$5:$J$304,$B$3,Saisies!$K$5:$K$304,$D$3,Saisies!$I$5:$I$304,"S2"))) | E22: =IF($A22="","",IF(COUNTIFS(Saisies!$B$5:$B$304,$A22,Saisies!$J$5:$J$304,$B$3,Saisies!$K$5:$K$304,$D$3,Saisies!$I$5:$I$304,"S3",Saisies!$F$5:$F$304,">=0")=0,"",SUMIFS(Saisies!$F$5:$F$304,Saisies!$B$5:$B$304,$A22,Saisies!$J$5:$J$304,$B$3,Saisies!$K$5:$K$304,$D$3,Saisies!$I$5:$I$304,"S3"))) | F22: =IF($A22="","",IF(COUNTIFS(Saisies!$B$5:$B$304,$A22,Saisies!$J$5:$J$304,$B$3,Saisies!$K$5:$K$304,$D$3,Saisies!$I$5:$I$304,"S4",Saisies!$F$5:$F$304,">=0")=0,"",SUMIFS(Saisies!$F$5:$F$304,Saisies!$B$5:$B$304,$A22,Saisies!$J$5:$J$304,$B$3,Saisies!$K$5:$K$304,$D$3,Saisies!$I$5:$I$304,"S4"))) | G22: =IF($A22="","",IF(COUNTIFS(Saisies!$B$5:$B$304,$A22,Saisies!$J$5:$J$304,$B$3,Saisies!$K$5:$K$304,$D$3,Saisies!$F$5:$F$304,">=0")=0,"",SUMIFS(Saisies!$F$5:$F$304,Saisies!$B$5:$B$304,$A22,Saisies!$J$5:$J$304,$B$3,Saisies!$K$5:$K$304,$D$3))) | H22: =IF($A22="","",IF(COUNTIFS(Saisies!$B$5:$B$304,$A22,Saisies!$J$5:$J$304,$B$3,Saisies!$K$5:$K$304,$D$3,Saisies!$G$5:$G$304,">=0")=0,"",SUMIFS(Saisies!$G$5:$G$304,Saisies!$B$5:$B$304,$A22,Saisies!$J$5:$J$304,$B$3,Saisies!$K$5:$K$304,$D$3))) | I22: =IF(OR(G22="",H22=""),"",H22-G22) | J22: =IF(K22="","",SUMIFS(Saisies!$E$5:$E$304,Saisies!$B$5:$B$304,$A22,Saisies!$A$5:$A$304,K22)) | K22: =IF($A22="","",IF(COUNTIFS(Saisies!$B$5:$B$304,$A22,Saisies!$J$5:$J$304,$B$3,Saisies!$K$5:$K$304,$D$3,Saisies!$E$5:$E$304,">=0")=0,"",_xlfn.MAXIFS(Saisies!$A$5:$A$304,Saisies!$B$5:$B$304,$A22,Saisies!$J$5:$J$304,$B$3,Saisies!$K$5:$K$304,$D$3,Saisies!$E$5:$E$304,">=0")))
A23: =IF(Produits!$A$22="","",Produits!$A$22) | B23: =IF(Produits!$A$22="","",Produits!$C$22) | C23: =IF($A23="","",IF(COUNTIFS(Saisies!$B$5:$B$304,$A23,Saisies!$J$5:$J$304,$B$3,Saisies!$K$5:$K$304,$D$3,Saisies!$I$5:$I$304,"S1",Saisies!$F$5:$F$304,">=0")=0,"",SUMIFS(Saisies!$F$5:$F$304,Saisies!$B$5:$B$304,$A23,Saisies!$J$5:$J$304,$B$3,Saisies!$K$5:$K$304,$D$3,Saisies!$I$5:$I$304,"S1"))) | D23: =IF($A23="","",IF(COUNTIFS(Saisies!$B$5:$B$304,$A23,Saisies!$J$5:$J$304,$B$3,Saisies!$K$5:$K$304,$D$3,Saisies!$I$5:$I$304,"S2",Saisies!$F$5:$F$304,">=0")=0,"",SUMIFS(Saisies!$F$5:$F$304,Saisies!$B$5:$B$304,$A23,Saisies!$J$5:$J$304,$B$3,Saisies!$K$5:$K$304,$D$3,Saisies!$I$5:$I$304,"S2"))) | E23: =IF($A23="","",IF(COUNTIFS(Saisies!$B$5:$B$304,$A23,Saisies!$J$5:$J$304,$B$3,Saisies!$K$5:$K$304,$D$3,Saisies!$I$5:$I$304,"S3",Saisies!$F$5:$F$304,">=0")=0,"",SUMIFS(Saisies!$F$5:$F$304,Saisies!$B$5:$B$304,$A23,Saisies!$J$5:$J$304,$B$3,Saisies!$K$5:$K$304,$D$3,Saisies!$I$5:$I$304,"S3"))) | F23: =IF($A23="","",IF(COUNTIFS(Saisies!$B$5:$B$304,$A23,Saisies!$J$5:$J$304,$B$3,Saisies!$K$5:$K$304,$D$3,Saisies!$I$5:$I$304,"S4",Saisies!$F$5:$F$304,">=0")=0,"",SUMIFS(Saisies!$F$5:$F$304,Saisies!$B$5:$B$304,$A23,Saisies!$J$5:$J$304,$B$3,Saisies!$K$5:$K$304,$D$3,Saisies!$I$5:$I$304,"S4"))) | G23: =IF($A23="","",IF(COUNTIFS(Saisies!$B$5:$B$304,$A23,Saisies!$J$5:$J$304,$B$3,Saisies!$K$5:$K$304,$D$3,Saisies!$F$5:$F$304,">=0")=0,"",SUMIFS(Saisies!$F$5:$F$304,Saisies!$B$5:$B$304,$A23,Saisies!$J$5:$J$304,$B$3,Saisies!$K$5:$K$304,$D$3))) | H23: =IF($A23="","",IF(COUNTIFS(Saisies!$B$5:$B$304,$A23,Saisies!$J$5:$J$304,$B$3,Saisies!$K$5:$K$304,$D$3,Saisies!$G$5:$G$304,">=0")=0,"",SUMIFS(Saisies!$G$5:$G$304,Saisies!$B$5:$B$304,$A23,Saisies!$J$5:$J$304,$B$3,Saisies!$K$5:$K$304,$D$3))) | I23: =IF(OR(G23="",H23=""),"",H23-G23) | J23: =IF(K23="","",SUMIFS(Saisies!$E$5:$E$304,Saisies!$B$5:$B$304,$A23,Saisies!$A$5:$A$304,K23)) | K23: =IF($A23="","",IF(COUNTIFS(Saisies!$B$5:$B$304,$A23,Saisies!$J$5:$J$304,$B$3,Saisies!$K$5:$K$304,$D$3,Saisies!$E$5:$E$304,">=0")=0,"",_xlfn.MAXIFS(Saisies!$A$5:$A$304,Saisies!$B$5:$B$304,$A23,Saisies!$J$5:$J$304,$B$3,Saisies!$K$5:$K$304,$D$3,Saisies!$E$5:$E$304,">=0")))
A24: =IF(Produits!$A$23="","",Produits!$A$23) | B24: =IF(Produits!$A$23="","",Produits!$C$23) | C24: =IF($A24="","",IF(COUNTIFS(Saisies!$B$5:$B$304,$A24,Saisies!$J$5:$J$304,$B$3,Saisies!$K$5:$K$304,$D$3,Saisies!$I$5:$I$304,"S1",Saisies!$F$5:$F$304,">=0")=0,"",SUMIFS(Saisies!$F$5:$F$304,Saisies!$B$5:$B$304,$A24,Saisies!$J$5:$J$304,$B$3,Saisies!$K$5:$K$304,$D$3,Saisies!$I$5:$I$304,"S1"))) | D24: =IF($A24="","",IF(COUNTIFS(Saisies!$B$5:$B$304,$A24,Saisies!$J$5:$J$304,$B$3,Saisies!$K$5:$K$304,$D$3,Saisies!$I$5:$I$304,"S2",Saisies!$F$5:$F$304,">=0")=0,"",SUMIFS(Saisies!$F$5:$F$304,Saisies!$B$5:$B$304,$A24,Saisies!$J$5:$J$304,$B$3,Saisies!$K$5:$K$304,$D$3,Saisies!$I$5:$I$304,"S2"))) | E24: =IF($A24="","",IF(COUNTIFS(Saisies!$B$5:$B$304,$A24,Saisies!$J$5:$J$304,$B$3,Saisies!$K$5:$K$304,$D$3,Saisies!$I$5:$I$304,"S3",Saisies!$F$5:$F$304,">=0")=0,"",SUMIFS(Saisies!$F$5:$F$304,Saisies!$B$5:$B$304,$A24,Saisies!$J$5:$J$304,$B$3,Saisies!$K$5:$K$304,$D$3,Saisies!$I$5:$I$304,"S3"))) | F24: =IF($A24="","",IF(COUNTIFS(Saisies!$B$5:$B$304,$A24,Saisies!$J$5:$J$304,$B$3,Saisies!$K$5:$K$304,$D$3,Saisies!$I$5:$I$304,"S4",Saisies!$F$5:$F$304,">=0")=0,"",SUMIFS(Saisies!$F$5:$F$304,Saisies!$B$5:$B$304,$A24,Saisies!$J$5:$J$304,$B$3,Saisies!$K$5:$K$304,$D$3,Saisies!$I$5:$I$304,"S4"))) | G24: =IF($A24="","",IF(COUNTIFS(Saisies!$B$5:$B$304,$A24,Saisies!$J$5:$J$304,$B$3,Saisies!$K$5:$K$304,$D$3,Saisies!$F$5:$F$304,">=0")=0,"",SUMIFS(Saisies!$F$5:$F$304,Saisies!$B$5:$B$304,$A24,Saisies!$J$5:$J$304,$B$3,Saisies!$K$5:$K$304,$D$3))) | H24: =IF($A24="","",IF(COUNTIFS(Saisies!$B$5:$B$304,$A24,Saisies!$J$5:$J$304,$B$3,Saisies!$K$5:$K$304,$D$3,Saisies!$G$5:$G$304,">=0")=0,"",SUMIFS(Saisies!$G$5:$G$304,Saisies!$B$5:$B$304,$A24,Saisies!$J$5:$J$304,$B$3,Saisies!$K$5:$K$304,$D$3))) | I24: =IF(OR(G24="",H24=""),"",H24-G24) | J24: =IF(K24="","",SUMIFS(Saisies!$E$5:$E$304,Saisies!$B$5:$B$304,$A24,Saisies!$A$5:$A$304,K24)) | K24: =IF($A24="","",IF(COUNTIFS(Saisies!$B$5:$B$304,$A24,Saisies!$J$5:$J$304,$B$3,Saisies!$K$5:$K$304,$D$3,Saisies!$E$5:$E$304,">=0")=0,"",_xlfn.MAXIFS(Saisies!$A$5:$A$304,Saisies!$B$5:$B$304,$A24,Saisies!$J$5:$J$304,$B$3,Saisies!$K$5:$K$304,$D$3,Saisies!$E$5:$E$304,">=0")))
A25: =IF(Produits!$A$24="","",Produits!$A$24) | B25: =IF(Produits!$A$24="","",Produits!$C$24) | C25: =IF($A25="","",IF(COUNTIFS(Saisies!$B$5:$B$304,$A25,Saisies!$J$5:$J$304,$B$3,Saisies!$K$5:$K$304,$D$3,Saisies!$I$5:$I$304,"S1",Saisies!$F$5:$F$304,">=0")=0,"",SUMIFS(Saisies!$F$5:$F$304,Saisies!$B$5:$B$304,$A25,Saisies!$J$5:$J$304,$B$3,Saisies!$K$5:$K$304,$D$3,Saisies!$I$5:$I$304,"S1"))) | D25: =IF($A25="","",IF(COUNTIFS(Saisies!$B$5:$B$304,$A25,Saisies!$J$5:$J$304,$B$3,Saisies!$K$5:$K$304,$D$3,Saisies!$I$5:$I$304,"S2",Saisies!$F$5:$F$304,">=0")=0,"",SUMIFS(Saisies!$F$5:$F$304,Saisies!$B$5:$B$304,$A25,Saisies!$J$5:$J$304,$B$3,Saisies!$K$5:$K$304,$D$3,Saisies!$I$5:$I$304,"S2"))) | E25: =IF($A25="","",IF(COUNTIFS(Saisies!$B$5:$B$304,$A25,Saisies!$J$5:$J$304,$B$3,Saisies!$K$5:$K$304,$D$3,Saisies!$I$5:$I$304,"S3",Saisies!$F$5:$F$304,">=0")=0,"",SUMIFS(Saisies!$F$5:$F$304,Saisies!$B$5:$B$304,$A25,Saisies!$J$5:$J$304,$B$3,Saisies!$K$5:$K$304,$D$3,Saisies!$I$5:$I$304,"S3"))) | F25: =IF($A25="","",IF(COUNTIFS(Saisies!$B$5:$B$304,$A25,Saisies!$J$5:$J$304,$B$3,Saisies!$K$5:$K$304,$D$3,Saisies!$I$5:$I$304,"S4",Saisies!$F$5:$F$304,">=0")=0,"",SUMIFS(Saisies!$F$5:$F$304,Saisies!$B$5:$B$304,$A25,Saisies!$J$5:$J$304,$B$3,Saisies!$K$5:$K$304,$D$3,Saisies!$I$5:$I$304,"S4"))) | G25: =IF($A25="","",IF(COUNTIFS(Saisies!$B$5:$B$304,$A25,Saisies!$J$5:$J$304,$B$3,Saisies!$K$5:$K$304,$D$3,Saisies!$F$5:$F$304,">=0")=0,"",SUMIFS(Saisies!$F$5:$F$304,Saisies!$B$5:$B$304,$A25,Saisies!$J$5:$J$304,$B$3,Saisies!$K$5:$K$304,$D$3))) | H25: =IF($A25="","",IF(COUNTIFS(Saisies!$B$5:$B$304,$A25,Saisies!$J$5:$J$304,$B$3,Saisies!$K$5:$K$304,$D$3,Saisies!$G$5:$G$304,">=0")=0,"",SUMIFS(Saisies!$G$5:$G$304,Saisies!$B$5:$B$304,$A25,Saisies!$J$5:$J$304,$B$3,Saisies!$K$5:$K$304,$D$3))) | I25: =IF(OR(G25="",H25=""),"",H25-G25) | J25: =IF(K25="","",SUMIFS(Saisies!$E$5:$E$304,Saisies!$B$5:$B$304,$A25,Saisies!$A$5:$A$304,K25)) | K25: =IF($A25="","",IF(COUNTIFS(Saisies!$B$5:$B$304,$A25,Saisies!$J$5:$J$304,$B$3,Saisies!$K$5:$K$304,$D$3,Saisies!$E$5:$E$304,">=0")=0,"",_xlfn.MAXIFS(Saisies!$A$5:$A$304,Saisies!$B$5:$B$304,$A25,Saisies!$J$5:$J$304,$B$3,Saisies!$K$5:$K$304,$D$3,Saisies!$E$5:$E$304,">=0")))
A26: =IF(Produits!$A$25="","",Produits!$A$25) | B26: =IF(Produits!$A$25="","",Produits!$C$25) | C26: =IF($A26="","",IF(COUNTIFS(Saisies!$B$5:$B$304,$A26,Saisies!$J$5:$J$304,$B$3,Saisies!$K$5:$K$304,$D$3,Saisies!$I$5:$I$304,"S1",Saisies!$F$5:$F$304,">=0")=0,"",SUMIFS(Saisies!$F$5:$F$304,Saisies!$B$5:$B$304,$A26,Saisies!$J$5:$J$304,$B$3,Saisies!$K$5:$K$304,$D$3,Saisies!$I$5:$I$304,"S1"))) | D26: =IF($A26="","",IF(COUNTIFS(Saisies!$B$5:$B$304,$A26,Saisies!$J$5:$J$304,$B$3,Saisies!$K$5:$K$304,$D$3,Saisies!$I$5:$I$304,"S2",Saisies!$F$5:$F$304,">=0")=0,"",SUMIFS(Saisies!$F$5:$F$304,Saisies!$B$5:$B$304,$A26,Saisies!$J$5:$J$304,$B$3,Saisies!$K$5:$K$304,$D$3,Saisies!$I$5:$I$304,"S2"))) | E26: =IF($A26="","",IF(COUNTIFS(Saisies!$B$5:$B$304,$A26,Saisies!$J$5:$J$304,$B$3,Saisies!$K$5:$K$304,$D$3,Saisies!$I$5:$I$304,"S3",Saisies!$F$5:$F$304,">=0")=0,"",SUMIFS(Saisies!$F$5:$F$304,Saisies!$B$5:$B$304,$A26,Saisies!$J$5:$J$304,$B$3,Saisies!$K$5:$K$304,$D$3,Saisies!$I$5:$I$304,"S3"))) | F26: =IF($A26="","",IF(COUNTIFS(Saisies!$B$5:$B$304,$A26,Saisies!$J$5:$J$304,$B$3,Saisies!$K$5:$K$304,$D$3,Saisies!$I$5:$I$304,"S4",Saisies!$F$5:$F$304,">=0")=0,"",SUMIFS(Saisies!$F$5:$F$304,Saisies!$B$5:$B$304,$A26,Saisies!$J$5:$J$304,$B$3,Saisies!$K$5:$K$304,$D$3,Saisies!$I$5:$I$304,"S4"))) | G26: =IF($A26="","",IF(COUNTIFS(Saisies!$B$5:$B$304,$A26,Saisies!$J$5:$J$304,$B$3,Saisies!$K$5:$K$304,$D$3,Saisies!$F$5:$F$304,">=0")=0,"",SUMIFS(Saisies!$F$5:$F$304,Saisies!$B$5:$B$304,$A26,Saisies!$J$5:$J$304,$B$3,Saisies!$K$5:$K$304,$D$3))) | H26: =IF($A26="","",IF(COUNTIFS(Saisies!$B$5:$B$304,$A26,Saisies!$J$5:$J$304,$B$3,Saisies!$K$5:$K$304,$D$3,Saisies!$G$5:$G$304,">=0")=0,"",SUMIFS(Saisies!$G$5:$G$304,Saisies!$B$5:$B$304,$A26,Saisies!$J$5:$J$304,$B$3,Saisies!$K$5:$K$304,$D$3))) | I26: =IF(OR(G26="",H26=""),"",H26-G26) | J26: =IF(K26="","",SUMIFS(Saisies!$E$5:$E$304,Saisies!$B$5:$B$304,$A26,Saisies!$A$5:$A$304,K26)) | K26: =IF($A26="","",IF(COUNTIFS(Saisies!$B$5:$B$304,$A26,Saisies!$J$5:$J$304,$B$3,Saisies!$K$5:$K$304,$D$3,Saisies!$E$5:$E$304,">=0")=0,"",_xlfn.MAXIFS(Saisies!$A$5:$A$304,Saisies!$B$5:$B$304,$A26,Saisies!$J$5:$J$304,$B$3,Saisies!$K$5:$K$304,$D$3,Saisies!$E$5:$E$304,">=0")))
A27: =IF(Produits!$A$26="","",Produits!$A$26) | B27: =IF(Produits!$A$26="","",Produits!$C$26) | C27: =IF($A27="","",IF(COUNTIFS(Saisies!$B$5:$B$304,$A27,Saisies!$J$5:$J$304,$B$3,Saisies!$K$5:$K$304,$D$3,Saisies!$I$5:$I$304,"S1",Saisies!$F$5:$F$304,">=0")=0,"",SUMIFS(Saisies!$F$5:$F$304,Saisies!$B$5:$B$304,$A27,Saisies!$J$5:$J$304,$B$3,Saisies!$K$5:$K$304,$D$3,Saisies!$I$5:$I$304,"S1"))) | D27: =IF($A27="","",IF(COUNTIFS(Saisies!$B$5:$B$304,$A27,Saisies!$J$5:$J$304,$B$3,Saisies!$K$5:$K$304,$D$3,Saisies!$I$5:$I$304,"S2",Saisies!$F$5:$F$304,">=0")=0,"",SUMIFS(Saisies!$F$5:$F$304,Saisies!$B$5:$B$304,$A27,Saisies!$J$5:$J$304,$B$3,Saisies!$K$5:$K$304,$D$3,Saisies!$I$5:$I$304,"S2"))) | E27: =IF($A27="","",IF(COUNTIFS(Saisies!$B$5:$B$304,$A27,Saisies!$J$5:$J$304,$B$3,Saisies!$K$5:$K$304,$D$3,Saisies!$I$5:$I$304,"S3",Saisies!$F$5:$F$304,">=0")=0,"",SUMIFS(Saisies!$F$5:$F$304,Saisies!$B$5:$B$304,$A27,Saisies!$J$5:$J$304,$B$3,Saisies!$K$5:$K$304,$D$3,Saisies!$I$5:$I$304,"S3"))) | F27: =IF($A27="","",IF(COUNTIFS(Saisies!$B$5:$B$304,$A27,Saisies!$J$5:$J$304,$B$3,Saisies!$K$5:$K$304,$D$3,Saisies!$I$5:$I$304,"S4",Saisies!$F$5:$F$304,">=0")=0,"",SUMIFS(Saisies!$F$5:$F$304,Saisies!$B$5:$B$304,$A27,Saisies!$J$5:$J$304,$B$3,Saisies!$K$5:$K$304,$D$3,Saisies!$I$5:$I$304,"S4"))) | G27: =IF($A27="","",IF(COUNTIFS(Saisies!$B$5:$B$304,$A27,Saisies!$J$5:$J$304,$B$3,Saisies!$K$5:$K$304,$D$3,Saisies!$F$5:$F$304,">=0")=0,"",SUMIFS(Saisies!$F$5:$F$304,Saisies!$B$5:$B$304,$A27,Saisies!$J$5:$J$304,$B$3,Saisies!$K$5:$K$304,$D$3))) | H27: =IF($A27="","",IF(COUNTIFS(Saisies!$B$5:$B$304,$A27,Saisies!$J$5:$J$304,$B$3,Saisies!$K$5:$K$304,$D$3,Saisies!$G$5:$G$304,">=0")=0,"",SUMIFS(Saisies!$G$5:$G$304,Saisies!$B$5:$B$304,$A27,Saisies!$J$5:$J$304,$B$3,Saisies!$K$5:$K$304,$D$3))) | I27: =IF(OR(G27="",H27=""),"",H27-G27) | J27: =IF(K27="","",SUMIFS(Saisies!$E$5:$E$304,Saisies!$B$5:$B$304,$A27,Saisies!$A$5:$A$304,K27)) | K27: =IF($A27="","",IF(COUNTIFS(Saisies!$B$5:$B$304,$A27,Saisies!$J$5:$J$304,$B$3,Saisies!$K$5:$K$304,$D$3,Saisies!$E$5:$E$304,">=0")=0,"",_xlfn.MAXIFS(Saisies!$A$5:$A$304,Saisies!$B$5:$B$304,$A27,Saisies!$J$5:$J$304,$B$3,Saisies!$K$5:$K$304,$D$3,Saisies!$E$5:$E$304,">=0")))
A28: =IF(Produits!$A$27="","",Produits!$A$27) | B28: =IF(Produits!$A$27="","",Produits!$C$27) | C28: =IF($A28="","",IF(COUNTIFS(Saisies!$B$5:$B$304,$A28,Saisies!$J$5:$J$304,$B$3,Saisies!$K$5:$K$304,$D$3,Saisies!$I$5:$I$304,"S1",Saisies!$F$5:$F$304,">=0")=0,"",SUMIFS(Saisies!$F$5:$F$304,Saisies!$B$5:$B$304,$A28,Saisies!$J$5:$J$304,$B$3,Saisies!$K$5:$K$304,$D$3,Saisies!$I$5:$I$304,"S1"))) | D28: =IF($A28="","",IF(COUNTIFS(Saisies!$B$5:$B$304,$A28,Saisies!$J$5:$J$304,$B$3,Saisies!$K$5:$K$304,$D$3,Saisies!$I$5:$I$304,"S2",Saisies!$F$5:$F$304,">=0")=0,"",SUMIFS(Saisies!$F$5:$F$304,Saisies!$B$5:$B$304,$A28,Saisies!$J$5:$J$304,$B$3,Saisies!$K$5:$K$304,$D$3,Saisies!$I$5:$I$304,"S2"))) | E28: =IF($A28="","",IF(COUNTIFS(Saisies!$B$5:$B$304,$A28,Saisies!$J$5:$J$304,$B$3,Saisies!$K$5:$K$304,$D$3,Saisies!$I$5:$I$304,"S3",Saisies!$F$5:$F$304,">=0")=0,"",SUMIFS(Saisies!$F$5:$F$304,Saisies!$B$5:$B$304,$A28,Saisies!$J$5:$J$304,$B$3,Saisies!$K$5:$K$304,$D$3,Saisies!$I$5:$I$304,"S3"))) | F28: =IF($A28="","",IF(COUNTIFS(Saisies!$B$5:$B$304,$A28,Saisies!$J$5:$J$304,$B$3,Saisies!$K$5:$K$304,$D$3,Saisies!$I$5:$I$304,"S4",Saisies!$F$5:$F$304,">=0")=0,"",SUMIFS(Saisies!$F$5:$F$304,Saisies!$B$5:$B$304,$A28,Saisies!$J$5:$J$304,$B$3,Saisies!$K$5:$K$304,$D$3,Saisies!$I$5:$I$304,"S4"))) | G28: =IF($A28="","",IF(COUNTIFS(Saisies!$B$5:$B$304,$A28,Saisies!$J$5:$J$304,$B$3,Saisies!$K$5:$K$304,$D$3,Saisies!$F$5:$F$304,">=0")=0,"",SUMIFS(Saisies!$F$5:$F$304,Saisies!$B$5:$B$304,$A28,Saisies!$J$5:$J$304,$B$3,Saisies!$K$5:$K$304,$D$3))) | H28: =IF($A28="","",IF(COUNTIFS(Saisies!$B$5:$B$304,$A28,Saisies!$J$5:$J$304,$B$3,Saisies!$K$5:$K$304,$D$3,Saisies!$G$5:$G$304,">=0")=0,"",SUMIFS(Saisies!$G$5:$G$304,Saisies!$B$5:$B$304,$A28,Saisies!$J$5:$J$304,$B$3,Saisies!$K$5:$K$304,$D$3))) | I28: =IF(OR(G28="",H28=""),"",H28-G28) | J28: =IF(K28="","",SUMIFS(Saisies!$E$5:$E$304,Saisies!$B$5:$B$304,$A28,Saisies!$A$5:$A$304,K28)) | K28: =IF($A28="","",IF(COUNTIFS(Saisies!$B$5:$B$304,$A28,Saisies!$J$5:$J$304,$B$3,Saisies!$K$5:$K$304,$D$3,Saisies!$E$5:$E$304,">=0")=0,"",_xlfn.MAXIFS(Saisies!$A$5:$A$304,Saisies!$B$5:$B$304,$A28,Saisies!$J$5:$J$304,$B$3,Saisies!$K$5:$K$304,$D$3,Saisies!$E$5:$E$304,">=0")))
A29: =IF(Produits!$A$28="","",Produits!$A$28) | B29: =IF(Produits!$A$28="","",Produits!$C$28) | C29: =IF($A29="","",IF(COUNTIFS(Saisies!$B$5:$B$304,$A29,Saisies!$J$5:$J$304,$B$3,Saisies!$K$5:$K$304,$D$3,Saisies!$I$5:$I$304,"S1",Saisies!$F$5:$F$304,">=0")=0,"",SUMIFS(Saisies!$F$5:$F$304,Saisies!$B$5:$B$304,$A29,Saisies!$J$5:$J$304,$B$3,Saisies!$K$5:$K$304,$D$3,Saisies!$I$5:$I$304,"S1"))) | D29: =IF($A29="","",IF(COUNTIFS(Saisies!$B$5:$B$304,$A29,Saisies!$J$5:$J$304,$B$3,Saisies!$K$5:$K$304,$D$3,Saisies!$I$5:$I$304,"S2",Saisies!$F$5:$F$304,">=0")=0,"",SUMIFS(Saisies!$F$5:$F$304,Saisies!$B$5:$B$304,$A29,Saisies!$J$5:$J$304,$B$3,Saisies!$K$5:$K$304,$D$3,Saisies!$I$5:$I$304,"S2"))) | E29: =IF($A29="","",IF(COUNTIFS(Saisies!$B$5:$B$304,$A29,Saisies!$J$5:$J$304,$B$3,Saisies!$K$5:$K$304,$D$3,Saisies!$I$5:$I$304,"S3",Saisies!$F$5:$F$304,">=0")=0,"",SUMIFS(Saisies!$F$5:$F$304,Saisies!$B$5:$B$304,$A29,Saisies!$J$5:$J$304,$B$3,Saisies!$K$5:$K$304,$D$3,Saisies!$I$5:$I$304,"S3"))) | F29: =IF($A29="","",IF(COUNTIFS(Saisies!$B$5:$B$304,$A29,Saisies!$J$5:$J$304,$B$3,Saisies!$K$5:$K$304,$D$3,Saisies!$I$5:$I$304,"S4",Saisies!$F$5:$F$304,">=0")=0,"",SUMIFS(Saisies!$F$5:$F$304,Saisies!$B$5:$B$304,$A29,Saisies!$J$5:$J$304,$B$3,Saisies!$K$5:$K$304,$D$3,Saisies!$I$5:$I$304,"S4"))) | G29: =IF($A29="","",IF(COUNTIFS(Saisies!$B$5:$B$304,$A29,Saisies!$J$5:$J$304,$B$3,Saisies!$K$5:$K$304,$D$3,Saisies!$F$5:$F$304,">=0")=0,"",SUMIFS(Saisies!$F$5:$F$304,Saisies!$B$5:$B$304,$A29,Saisies!$J$5:$J$304,$B$3,Saisies!$K$5:$K$304,$D$3))) | H29: =IF($A29="","",IF(COUNTIFS(Saisies!$B$5:$B$304,$A29,Saisies!$J$5:$J$304,$B$3,Saisies!$K$5:$K$304,$D$3,Saisies!$G$5:$G$304,">=0")=0,"",SUMIFS(Saisies!$G$5:$G$304,Saisies!$B$5:$B$304,$A29,Saisies!$J$5:$J$304,$B$3,Saisies!$K$5:$K$304,$D$3))) | I29: =IF(OR(G29="",H29=""),"",H29-G29) | J29: =IF(K29="","",SUMIFS(Saisies!$E$5:$E$304,Saisies!$B$5:$B$304,$A29,Saisies!$A$5:$A$304,K29)) | K29: =IF($A29="","",IF(COUNTIFS(Saisies!$B$5:$B$304,$A29,Saisies!$J$5:$J$304,$B$3,Saisies!$K$5:$K$304,$D$3,Saisies!$E$5:$E$304,">=0")=0,"",_xlfn.MAXIFS(Saisies!$A$5:$A$304,Saisies!$B$5:$B$304,$A29,Saisies!$J$5:$J$304,$B$3,Saisies!$K$5:$K$304,$D$3,Saisies!$E$5:$E$304,">=0")))
A30: =IF(Produits!$A$29="","",Produits!$A$29) | B30: =IF(Produits!$A$29="","",Produits!$C$29) | C30: =IF($A30="","",IF(COUNTIFS(Saisies!$B$5:$B$304,$A30,Saisies!$J$5:$J$304,$B$3,Saisies!$K$5:$K$304,$D$3,Saisies!$I$5:$I$304,"S1",Saisies!$F$5:$F$304,">=0")=0,"",SUMIFS(Saisies!$F$5:$F$304,Saisies!$B$5:$B$304,$A30,Saisies!$J$5:$J$304,$B$3,Saisies!$K$5:$K$304,$D$3,Saisies!$I$5:$I$304,"S1"))) | D30: =IF($A30="","",IF(COUNTIFS(Saisies!$B$5:$B$304,$A30,Saisies!$J$5:$J$304,$B$3,Saisies!$K$5:$K$304,$D$3,Saisies!$I$5:$I$304,"S2",Saisies!$F$5:$F$304,">=0")=0,"",SUMIFS(Saisies!$F$5:$F$304,Saisies!$B$5:$B$304,$A30,Saisies!$J$5:$J$304,$B$3,Saisies!$K$5:$K$304,$D$3,Saisies!$I$5:$I$304,"S2"))) | E30: =IF($A30="","",IF(COUNTIFS(Saisies!$B$5:$B$304,$A30,Saisies!$J$5:$J$304,$B$3,Saisies!$K$5:$K$304,$D$3,Saisies!$I$5:$I$304,"S3",Saisies!$F$5:$F$304,">=0")=0,"",SUMIFS(Saisies!$F$5:$F$304,Saisies!$B$5:$B$304,$A30,Saisies!$J$5:$J$304,$B$3,Saisies!$K$5:$K$304,$D$3,Saisies!$I$5:$I$304,"S3"))) | F30: =IF($A30="","",IF(COUNTIFS(Saisies!$B$5:$B$304,$A30,Saisies!$J$5:$J$304,$B$3,Saisies!$K$5:$K$304,$D$3,Saisies!$I$5:$I$304,"S4",Saisies!$F$5:$F$304,">=0")=0,"",SUMIFS(Saisies!$F$5:$F$304,Saisies!$B$5:$B$304,$A30,Saisies!$J$5:$J$304,$B$3,Saisies!$K$5:$K$304,$D$3,Saisies!$I$5:$I$304,"S4"))) | G30: =IF($A30="","",IF(COUNTIFS(Saisies!$B$5:$B$304,$A30,Saisies!$J$5:$J$304,$B$3,Saisies!$K$5:$K$304,$D$3,Saisies!$F$5:$F$304,">=0")=0,"",SUMIFS(Saisies!$F$5:$F$304,Saisies!$B$5:$B$304,$A30,Saisies!$J$5:$J$304,$B$3,Saisies!$K$5:$K$304,$D$3))) | H30: =IF($A30="","",IF(COUNTIFS(Saisies!$B$5:$B$304,$A30,Saisies!$J$5:$J$304,$B$3,Saisies!$K$5:$K$304,$D$3,Saisies!$G$5:$G$304,">=0")=0,"",SUMIFS(Saisies!$G$5:$G$304,Saisies!$B$5:$B$304,$A30,Saisies!$J$5:$J$304,$B$3,Saisies!$K$5:$K$304,$D$3))) | I30: =IF(OR(G30="",H30=""),"",H30-G30) | J30: =IF(K30="","",SUMIFS(Saisies!$E$5:$E$304,Saisies!$B$5:$B$304,$A30,Saisies!$A$5:$A$304,K30)) | K30: =IF($A30="","",IF(COUNTIFS(Saisies!$B$5:$B$304,$A30,Saisies!$J$5:$J$304,$B$3,Saisies!$K$5:$K$304,$D$3,Saisies!$E$5:$E$304,">=0")=0,"",_xlfn.MAXIFS(Saisies!$A$5:$A$304,Saisies!$B$5:$B$304,$A30,Saisies!$J$5:$J$304,$B$3,Saisies!$K$5:$K$304,$D$3,Saisies!$E$5:$E$304,">=0")))
A31: =IF(Produits!$A$30="","",Produits!$A$30) | B31: =IF(Produits!$A$30="","",Produits!$C$30) | C31: =IF($A31="","",IF(COUNTIFS(Saisies!$B$5:$B$304,$A31,Saisies!$J$5:$J$304,$B$3,Saisies!$K$5:$K$304,$D$3,Saisies!$I$5:$I$304,"S1",Saisies!$F$5:$F$304,">=0")=0,"",SUMIFS(Saisies!$F$5:$F$304,Saisies!$B$5:$B$304,$A31,Saisies!$J$5:$J$304,$B$3,Saisies!$K$5:$K$304,$D$3,Saisies!$I$5:$I$304,"S1"))) | D31: =IF($A31="","",IF(COUNTIFS(Saisies!$B$5:$B$304,$A31,Saisies!$J$5:$J$304,$B$3,Saisies!$K$5:$K$304,$D$3,Saisies!$I$5:$I$304,"S2",Saisies!$F$5:$F$304,">=0")=0,"",SUMIFS(Saisies!$F$5:$F$304,Saisies!$B$5:$B$304,$A31,Saisies!$J$5:$J$304,$B$3,Saisies!$K$5:$K$304,$D$3,Saisies!$I$5:$I$304,"S2"))) | E31: =IF($A31="","",IF(COUNTIFS(Saisies!$B$5:$B$304,$A31,Saisies!$J$5:$J$304,$B$3,Saisies!$K$5:$K$304,$D$3,Saisies!$I$5:$I$304,"S3",Saisies!$F$5:$F$304,">=0")=0,"",SUMIFS(Saisies!$F$5:$F$304,Saisies!$B$5:$B$304,$A31,Saisies!$J$5:$J$304,$B$3,Saisies!$K$5:$K$304,$D$3,Saisies!$I$5:$I$304,"S3"))) | F31: =IF($A31="","",IF(COUNTIFS(Saisies!$B$5:$B$304,$A31,Saisies!$J$5:$J$304,$B$3,Saisies!$K$5:$K$304,$D$3,Saisies!$I$5:$I$304,"S4",Saisies!$F$5:$F$304,">=0")=0,"",SUMIFS(Saisies!$F$5:$F$304,Saisies!$B$5:$B$304,$A31,Saisies!$J$5:$J$304,$B$3,Saisies!$K$5:$K$304,$D$3,Saisies!$I$5:$I$304,"S4"))) | G31: =IF($A31="","",IF(COUNTIFS(Saisies!$B$5:$B$304,$A31,Saisies!$J$5:$J$304,$B$3,Saisies!$K$5:$K$304,$D$3,Saisies!$F$5:$F$304,">=0")=0,"",SUMIFS(Saisies!$F$5:$F$304,Saisies!$B$5:$B$304,$A31,Saisies!$J$5:$J$304,$B$3,Saisies!$K$5:$K$304,$D$3))) | H31: =IF($A31="","",IF(COUNTIFS(Saisies!$B$5:$B$304,$A31,Saisies!$J$5:$J$304,$B$3,Saisies!$K$5:$K$304,$D$3,Saisies!$G$5:$G$304,">=0")=0,"",SUMIFS(Saisies!$G$5:$G$304,Saisies!$B$5:$B$304,$A31,Saisies!$J$5:$J$304,$B$3,Saisies!$K$5:$K$304,$D$3))) | I31: =IF(OR(G31="",H31=""),"",H31-G31) | J31: =IF(K31="","",SUMIFS(Saisies!$E$5:$E$304,Saisies!$B$5:$B$304,$A31,Saisies!$A$5:$A$304,K31)) | K31: =IF($A31="","",IF(COUNTIFS(Saisies!$B$5:$B$304,$A31,Saisies!$J$5:$J$304,$B$3,Saisies!$K$5:$K$304,$D$3,Saisies!$E$5:$E$304,">=0")=0,"",_xlfn.MAXIFS(Saisies!$A$5:$A$304,Saisies!$B$5:$B$304,$A31,Saisies!$J$5:$J$304,$B$3,Saisies!$K$5:$K$304,$D$3,Saisies!$E$5:$E$304,">=0")))
