Workbook

Sheet Mode d'emploi
A1: 6 · Contrôle des livraisons
A2: Proposition de tableau de gestion des stocks — Excel et Google Sheets
A4: L'idée | B4: Met l'accent sur ce que tu reçois vraiment. Pour chaque produit, le fichier compare commandé et reçu et affiche OK, MANQUE ou EN TROP. Un onglet Réclamations garde la trace des appels au fournisseur.
A6: Comment faire | B6: 1. Remplis l'onglet Produits une seule fois.
B7: 2. Chaque semaine : Stock, Commandé, puis Reçu à la livraison. Le Statut s'affiche tout seul.
B8: 3. En cas de MANQUE : ajoute une ligne dans Réclamations (date, produit, ce que tu as fait).
B9: 4. Nouveau mois : duplique l'onglet du mois.
A11: Les onglets | B11: Produits — ta liste.
B12: Octobre 2026 — stock, commandé, reçu, statut par semaine.
B13: Réclamations — suivi des livraisons incomplètes.
A15: Couleurs | B15: Cases jaunes = à remplir. Cases blanches = calculées toutes seules, ne pas y toucher.
B16: Chiffres en bleu = exemple pour montrer le fonctionnement, à effacer.
B17: Rouge = il manque quelque chose (livraison incomplète, stock trop bas).
A19: Google Sheets | B19: Fichier > Importer > Importer ce fichier. Tout fonctionne pareil, y compris sur téléphone.

Sheet Produits
A1: Mes produits
A2: Une ligne par produit. Tout le reste du fichier se remplit à partir de cette liste.
A4: Produit | B4: Fournisseur | C4: Unité
A5: Farine T55 | B5: Metro | C5: kg
A6: Farine T45 | B6: Metro | C6: kg
A7: Sucre semoule | B7: Metro | C7: kg
A8: Sucre glace | B8: Metro | C8: kg
A9: Beurre doux | B9: Crèmerie | C9: kg
A10: Crème liquide 35% | B10: Crèmerie | C10: L
A11: Lait entier | B11: Crèmerie | C11: L
A12: Oeufs | B12: Crèmerie | C12: pièce
A13: Chocolat blanc | B13: Transgourmet | C13: kg
A14: Chocolat noir 70% | B14: Transgourmet | C14: kg
A15: Levure chimique | B15: Transgourmet | C15: kg
A16: Vanille (gousse) | B16: Transgourmet | C16: pièce

Sheet Octobre 2026
A1: Octobre 2026
A2: Statut : OK = tout reçu · MANQUE = moins que commandé · EN TROP = plus que commandé
A4: Produit | B4: Fournisseur | C4: Unité | D4: Semaine 1 | I4: Semaine 2 | N4: Semaine 3 | S4: Semaine 4 | X4: Total du mois
D6: Stock | E6: Commandé | F6: Reçu | G6: Écart | H6: Statut | I6: Stock | J6: Commandé | K6: Reçu | L6: Écart | M6: Statut | N6: Stock | O6: Commandé | P6: Reçu | Q6: Écart | R6: Statut | S6: Stock | T6: Commandé | U6: Reçu | V6: Écart | W6: Statut | X6: Livraisons incomplètes
A7: =IF(Produits!$A$5="","",Produits!$A$5) | B7: =IF(Produits!$A$5="","",Produits!$B$5) | C7: =IF(Produits!$A$5="","",Produits!$C$5) | D7: 8 | E7: 10 | F7: 7 | G7: =IF(OR(E7="",F7=""),"",F7-E7) | H7: =IF(OR(E7="",F7="",N(E7)=0),"",IF(F7<E7,"MANQUE",IF(F7>E7,"EN TROP","OK"))) | I7: 5 | J7: 10 | K7: 10 | L7: =IF(OR(J7="",K7=""),"",K7-J7) | M7: =IF(OR(J7="",K7="",N(J7)=0),"",IF(K7<J7,"MANQUE",IF(K7>J7,"EN TROP","OK"))) | Q7: =IF(OR(O7="",P7=""),"",P7-O7) | R7: =IF(OR(O7="",P7="",N(O7)=0),"",IF(P7<O7,"MANQUE",IF(P7>O7,"EN TROP","OK"))) | V7: =IF(OR(T7="",U7=""),"",U7-T7) | W7: =IF(OR(T7="",U7="",N(T7)=0),"",IF(U7<T7,"MANQUE",IF(U7>T7,"EN TROP","OK"))) | X7: =IF(A7="","",COUNTIF(H7:W7,"MANQUE"))
A8: =IF(Produits!$A$6="","",Produits!$A$6) | B8: =IF(Produits!$A$6="","",Produits!$B$6) | C8: =IF(Produits!$A$6="","",Produits!$C$6) | D8: 2 | E8: 5 | F8: 5 | G8: =IF(OR(E8="",F8=""),"",F8-E8) | H8: =IF(OR(E8="",F8="",N(E8)=0),"",IF(F8<E8,"MANQUE",IF(F8>E8,"EN TROP","OK"))) | I8: 3 | J8: 3 | K8: 3 | L8: =IF(OR(J8="",K8=""),"",K8-J8) | M8: =IF(OR(J8="",K8="",N(J8)=0),"",IF(K8<J8,"MANQUE",IF(K8>J8,"EN TROP","OK"))) | Q8: =IF(OR(O8="",P8=""),"",P8-O8) | R8: =IF(OR(O8="",P8="",N(O8)=0),"",IF(P8<O8,"MANQUE",IF(P8>O8,"EN TROP","OK"))) | V8: =IF(OR(T8="",U8=""),"",U8-T8) | W8: =IF(OR(T8="",U8="",N(T8)=0),"",IF(U8<T8,"MANQUE",IF(U8>T8,"EN TROP","OK"))) | X8: =IF(A8="","",COUNTIF(H8:W8,"MANQUE"))
A9: =IF(Produits!$A$7="","",Produits!$A$7) | B9: =IF(Produits!$A$7="","",Produits!$B$7) | C9: =IF(Produits!$A$7="","",Produits!$C$7) | D9: 6 | E9: 10 | F9: 10 | G9: =IF(OR(E9="",F9=""),"",F9-E9) | H9: =IF(OR(E9="",F9="",N(E9)=0),"",IF(F9<E9,"MANQUE",IF(F9>E9,"EN TROP","OK"))) | I9: 7 | J9: 5 | K9: 5 | L9: =IF(OR(J9="",K9=""),"",K9-J9) | M9: =IF(OR(J9="",K9="",N(J9)=0),"",IF(K9<J9,"MANQUE",IF(K9>J9,"EN TROP","OK"))) | Q9: =IF(OR(O9="",P9=""),"",P9-O9) | R9: =IF(OR(O9="",P9="",N(O9)=0),"",IF(P9<O9,"MANQUE",IF(P9>O9,"EN TROP","OK"))) | V9: =IF(OR(T9="",U9=""),"",U9-T9) | W9: =IF(OR(T9="",U9="",N(T9)=0),"",IF(U9<T9,"MANQUE",IF(U9>T9,"EN TROP","OK"))) | X9: =IF(A9="","",COUNTIF(H9:W9,"MANQUE"))
A10: =IF(Produits!$A$8="","",Produits!$A$8) | B10: =IF(Produits!$A$8="","",Produits!$B$8) | C10: =IF(Produits!$A$8="","",Produits!$C$8) | D10: 1 | E10: 3 | F10: 3 | G10: =IF(OR(E10="",F10=""),"",F10-E10) | H10: =IF(OR(E10="",F10="",N(E10)=0),"",IF(F10<E10,"MANQUE",IF(F10>E10,"EN TROP","OK"))) | I10: 2 | J10: 0 | K10: 0 | L10: =IF(OR(J10="",K10=""),"",K10-J10) | M10: =IF(OR(J10="",K10="",N(J10)=0),"",IF(K10<J10,"MANQUE",IF(K10>J10,"EN TROP","OK"))) | Q10: =IF(OR(O10="",P10=""),"",P10-O10) | R10: =IF(OR(O10="",P10="",N(O10)=0),"",IF(P10<O10,"MANQUE",IF(P10>O10,"EN TROP","OK"))) | V10: =IF(OR(T10="",U10=""),"",U10-T10) | W10: =IF(OR(T10="",U10="",N(T10)=0),"",IF(U10<T10,"MANQUE",IF(U10>T10,"EN TROP","OK"))) | X10: =IF(A10="","",COUNTIF(H10:W10,"MANQUE"))
A11: =IF(Produits!$A$9="","",Produits!$A$9) | B11: =IF(Produits!$A$9="","",Produits!$B$9) | C11: =IF(Produits!$A$9="","",Produits!$C$9) | D11: 3 | E11: 5 | F11: 5 | G11: =IF(OR(E11="",F11=""),"",F11-E11) | H11: =IF(OR(E11="",F11="",N(E11)=0),"",IF(F11<E11,"MANQUE",IF(F11>E11,"EN TROP","OK"))) | I11: 4 | J11: 5 | K11: 5 | L11: =IF(OR(J11="",K11=""),"",K11-J11) | M11: =IF(OR(J11="",K11="",N(J11)=0),"",IF(K11<J11,"MANQUE",IF(K11>J11,"EN TROP","OK"))) | Q11: =IF(OR(O11="",P11=""),"",P11-O11) | R11: =IF(OR(O11="",P11="",N(O11)=0),"",IF(P11<O11,"MANQUE",IF(P11>O11,"EN TROP","OK"))) | V11: =IF(OR(T11="",U11=""),"",U11-T11) | W11: =IF(OR(T11="",U11="",N(T11)=0),"",IF(U11<T11,"MANQUE",IF(U11>T11,"EN TROP","OK"))) | X11: =IF(A11="","",COUNTIF(H11:W11,"MANQUE"))
A12: =IF(Produits!$A$10="","",Produits!$A$10) | B12: =IF(Produits!$A$10="","",Produits!$B$10) | C12: =IF(Produits!$A$10="","",Produits!$C$10) | D12: 4 | E12: 12 | F12: 12 | G12: =IF(OR(E12="",F12=""),"",F12-E12) | H12: =IF(OR(E12="",F12="",N(E12)=0),"",IF(F12<E12,"MANQUE",IF(F12>E12,"EN TROP","OK"))) | I12: 5 | J12: 10 | K12: 10 | L12: =IF(OR(J12="",K12=""),"",K12-J12) | M12: =IF(OR(J12="",K12="",N(J12)=0),"",IF(K12<J12,"MANQUE",IF(K12>J12,"EN TROP","OK"))) | Q12: =IF(OR(O12="",P12=""),"",P12-O12) | R12: =IF(OR(O12="",P12="",N(O12)=0),"",IF(P12<O12,"MANQUE",IF(P12>O12,"EN TROP","OK"))) | V12: =IF(OR(T12="",U12=""),"",U12-T12) | W12: =IF(OR(T12="",U12="",N(T12)=0),"",IF(U12<T12,"MANQUE",IF(U12>T12,"EN TROP","OK"))) | X12: =IF(A12="","",COUNTIF(H12:W12,"MANQUE"))
A13: =IF(Produits!$A$11="","",Produits!$A$11) | B13: =IF(Produits!$A$11="","",Produits!$B$11) | C13: =IF(Produits!$A$11="","",Produits!$C$11) | D13: 3 | E13: 6 | F13: 6 | G13: =IF(OR(E13="",F13=""),"",F13-E13) | H13: =IF(OR(E13="",F13="",N(E13)=0),"",IF(F13<E13,"MANQUE",IF(F13>E13,"EN TROP","OK"))) | I13: 4 | J13: 6 | K13: 6 | L13: =IF(OR(J13="",K13=""),"",K13-J13) | M13: =IF(OR(J13="",K13="",N(J13)=0),"",IF(K13<J13,"MANQUE",IF(K13>J13,"EN TROP","OK"))) | Q13: =IF(OR(O13="",P13=""),"",P13-O13) | R13: =IF(OR(O13="",P13="",N(O13)=0),"",IF(P13<O13,"MANQUE",IF(P13>O13,"EN TROP","OK"))) | V13: =IF(OR(T13="",U13=""),"",U13-T13) | W13: =IF(OR(T13="",U13="",N(T13)=0),"",IF(U13<T13,"MANQUE",IF(U13>T13,"EN TROP","OK"))) | X13: =IF(A13="","",COUNTIF(H13:W13,"MANQUE"))
A14: =IF(Produits!$A$12="","",Produits!$A$12) | B14: =IF(Produits!$A$12="","",Produits!$B$12) | C14: =IF(Produits!$A$12="","",Produits!$C$12) | D14: 40 | E14: 90 | F14: 90 | G14: =IF(OR(E14="",F14=""),"",F14-E14) | H14: =IF(OR(E14="",F14="",N(E14)=0),"",IF(F14<E14,"MANQUE",IF(F14>E14,"EN TROP","OK"))) | I14: 50 | J14: 60 | K14: 60 | L14: =IF(OR(J14="",K14=""),"",K14-J14) | M14: =IF(OR(J14="",K14="",N(J14)=0),"",IF(K14<J14,"MANQUE",IF(K14>J14,"EN TROP","OK"))) | Q14: =IF(OR(O14="",P14=""),"",P14-O14) | R14: =IF(OR(O14="",P14="",N(O14)=0),"",IF(P14<O14,"MANQUE",IF(P14>O14,"EN TROP","OK"))) | V14: =IF(OR(T14="",U14=""),"",U14-T14) | W14: =IF(OR(T14="",U14="",N(T14)=0),"",IF(U14<T14,"MANQUE",IF(U14>T14,"EN TROP","OK"))) | X14: =IF(A14="","",COUNTIF(H14:W14,"MANQUE"))
A15: =IF(Produits!$A$13="","",Produits!$A$13) | B15: =IF(Produits!$A$13="","",Produits!$B$13) | C15: =IF(Produits!$A$13="","",Produits!$C$13) | D15: 1.5 | E15: 3 | F15: 2 | G15: =IF(OR(E15="",F15=""),"",F15-E15) | H15: =IF(OR(E15="",F15="",N(E15)=0),"",IF(F15<E15,"MANQUE",IF(F15>E15,"EN TROP","OK"))) | I15: 2 | J15: 2 | K15: 2 | L15: =IF(OR(J15="",K15=""),"",K15-J15) | M15: =IF(OR(J15="",K15="",N(J15)=0),"",IF(K15<J15,"MANQUE",IF(K15>J15,"EN TROP","OK"))) | Q15: =IF(OR(O15="",P15=""),"",P15-O15) | R15: =IF(OR(O15="",P15="",N(O15)=0),"",IF(P15<O15,"MANQUE",IF(P15>O15,"EN TROP","OK"))) | V15: =IF(OR(T15="",U15=""),"",U15-T15) | W15: =IF(OR(T15="",U15="",N(T15)=0),"",IF(U15<T15,"MANQUE",IF(U15>T15,"EN TROP","OK"))) | X15: =IF(A15="","",COUNTIF(H15:W15,"MANQUE"))
A16: =IF(Produits!$A$14="","",Produits!$A$14) | B16: =IF(Produits!$A$14="","",Produits!$B$14) | C16: =IF(Produits!$A$14="","",Produits!$C$14) | D16: 2 | E16: 2 | F16: 2 | G16: =IF(OR(E16="",F16=""),"",F16-E16) | H16: =IF(OR(E16="",F16="",N(E16)=0),"",IF(F16<E16,"MANQUE",IF(F16>E16,"EN TROP","OK"))) | I16: 2 | J16: 2 | K16: 2 | L16: =IF(OR(J16="",K16=""),"",K16-J16) | M16: =IF(OR(J16="",K16="",N(J16)=0),"",IF(K16<J16,"MANQUE",IF(K16>J16,"EN TROP","OK"))) | Q16: =IF(OR(O16="",P16=""),"",P16-O16) | R16: =IF(OR(O16="",P16="",N(O16)=0),"",IF(P16<O16,"MANQUE",IF(P16>O16,"EN TROP","OK"))) | V16: =IF(OR(T16="",U16=""),"",U16-T16) | W16: =IF(OR(T16="",U16="",N(T16)=0),"",IF(U16<T16,"MANQUE",IF(U16>T16,"EN TROP","OK"))) | X16: =IF(A16="","",COUNTIF(H16:W16,"MANQUE"))
A17: =IF(Produits!$A$15="","",Produits!$A$15) | B17: =IF(Produits!$A$15="","",Produits!$B$15) | C17: =IF(Produits!$A$15="","",Produits!$C$15) | D17: 0.4 | E17: 1 | F17: 1 | G17: =IF(OR(E17="",F17=""),"",F17-E17) | H17: =IF(OR(E17="",F17="",N(E17)=0),"",IF(F17<E17,"MANQUE",IF(F17>E17,"EN TROP","OK"))) | I17: 0.6 | J17: 0 | K17: 0 | L17: =IF(OR(J17="",K17=""),"",K17-J17) | M17: =IF(OR(J17="",K17="",N(J17)=0),"",IF(K17<J17,"MANQUE",IF(K17>J17,"EN TROP","OK"))) | Q17: =IF(OR(O17="",P17=""),"",P17-O17) | R17: =IF(OR(O17="",P17="",N(O17)=0),"",IF(P17<O17,"MANQUE",IF(P17>O17,"EN TROP","OK"))) | V17: =IF(OR(T17="",U17=""),"",U17-T17) | W17: =IF(OR(T17="",U17="",N(T17)=0),"",IF(U17<T17,"MANQUE",IF(U17>T17,"EN TROP","OK"))) | X17: =IF(A17="","",COUNTIF(H17:W17,"MANQUE"))
A18: =IF(Produits!$A$16="","",Produits!$A$16) | B18: =IF(Produits!$A$16="","",Produits!$B$16) | C18: =IF(Produits!$A$16="","",Produits!$C$16) | D18: 6 | E18: 0 | F18: 0 | G18: =IF(OR(E18="",F18=""),"",F18-E18) | H18: =IF(OR(E18="",F18="",N(E18)=0),"",IF(F18<E18,"MANQUE",IF(F18>E18,"EN TROP","OK"))) | I18: 6 | J18: 0 | K18: 0 | L18: =IF(OR(J18="",K18=""),"",K18-J18) | M18: =IF(OR(J18="",K18="",N(J18)=0),"",IF(K18<J18,"MANQUE",IF(K18>J18,"EN TROP","OK"))) | Q18: =IF(OR(O18="",P18=""),"",P18-O18) | R18: =IF(OR(O18="",P18="",N(O18)=0),"",IF(P18<O18,"MANQUE",IF(P18>O18,"EN TROP","OK"))) | V18: =IF(OR(T18="",U18=""),"",U18-T18) | W18: =IF(OR(T18="",U18="",N(T18)=0),"",IF(U18<T18,"MANQUE",IF(U18>T18,"EN TROP","OK"))) | X18: =IF(A18="","",COUNTIF(H18:W18,"MANQUE"))
A19: =IF(Produits!$A$17="","",Produits!$A$17) | B19: =IF(Produits!$A$17="","",Produits!$B$17) | C19: =IF(Produits!$A$17="","",Produits!$C$17) | G19: =IF(OR(E19="",F19=""),"",F19-E19) | H19: =IF(OR(E19="",F19="",N(E19)=0),"",IF(F19<E19,"MANQUE",IF(F19>E19,"EN TROP","OK"))) | L19: =IF(OR(J19="",K19=""),"",K19-J19) | M19: =IF(OR(J19="",K19="",N(J19)=0),"",IF(K19<J19,"MANQUE",IF(K19>J19,"EN TROP","OK"))) | Q19: =IF(OR(O19="",P19=""),"",P19-O19) | R19: =IF(OR(O19="",P19="",N(O19)=0),"",IF(P19<O19,"MANQUE",IF(P19>O19,"EN TROP","OK"))) | V19: =IF(OR(T19="",U19=""),"",U19-T19) | W19: =IF(OR(T19="",U19="",N(T19)=0),"",IF(U19<T19,"MANQUE",IF(U19>T19,"EN TROP","OK"))) | X19: =IF(A19="","",COUNTIF(H19:W19,"MANQUE"))
A20: =IF(Produits!$A$18="","",Produits!$A$18) | B20: =IF(Produits!$A$18="","",Produits!$B$18) | C20: =IF(Produits!$A$18="","",Produits!$C$18) | G20: =IF(OR(E20="",F20=""),"",F20-E20) | H20: =IF(OR(E20="",F20="",N(E20)=0),"",IF(F20<E20,"MANQUE",IF(F20>E20,"EN TROP","OK"))) | L20: =IF(OR(J20="",K20=""),"",K20-J20) | M20: =IF(OR(J20="",K20="",N(J20)=0),"",IF(K20<J20,"MANQUE",IF(K20>J20,"EN TROP","OK"))) | Q20: =IF(OR(O20="",P20=""),"",P20-O20) | R20: =IF(OR(O20="",P20="",N(O20)=0),"",IF(P20<O20,"MANQUE",IF(P20>O20,"EN TROP","OK"))) | V20: =IF(OR(T20="",U20=""),"",U20-T20) | W20: =IF(OR(T20="",U20="",N(T20)=0),"",IF(U20<T20,"MANQUE",IF(U20>T20,"EN TROP","OK"))) | X20: =IF(A20="","",COUNTIF(H20:W20,"MANQUE"))
A21: =IF(Produits!$A$19="","",Produits!$A$19) | B21: =IF(Produits!$A$19="","",Produits!$B$19) | C21: =IF(Produits!$A$19="","",Produits!$C$19) | G21: =IF(OR(E21="",F21=""),"",F21-E21) | H21: =IF(OR(E21="",F21="",N(E21)=0),"",IF(F21<E21,"MANQUE",IF(F21>E21,"EN TROP","OK"))) | L21: =IF(OR(J21="",K21=""),"",K21-J21) | M21: =IF(OR(J21="",K21="",N(J21)=0),"",IF(K21<J21,"MANQUE",IF(K21>J21,"EN TROP","OK"))) | Q21: =IF(OR(O21="",P21=""),"",P21-O21) | R21: =IF(OR(O21="",P21="",N(O21)=0),"",IF(P21<O21,"MANQUE",IF(P21>O21,"EN TROP","OK"))) | V21: =IF(OR(T21="",U21=""),"",U21-T21) | W21: =IF(OR(T21="",U21="",N(T21)=0),"",IF(U21<T21,"MANQUE",IF(U21>T21,"EN TROP","OK"))) | X21: =IF(A21="","",COUNTIF(H21:W21,"MANQUE"))
A22: =IF(Produits!$A$20="","",Produits!$A$20) | B22: =IF(Produits!$A$20="","",Produits!$B$20) | C22: =IF(Produits!$A$20="","",Produits!$C$20) | G22: =IF(OR(E22="",F22=""),"",F22-E22) | H22: =IF(OR(E22="",F22="",N(E22)=0),"",IF(F22<E22,"MANQUE",IF(F22>E22,"EN TROP","OK"))) | L22: =IF(OR(J22="",K22=""),"",K22-J22) | M22: =IF(OR(J22="",K22="",N(J22)=0),"",IF(K22<J22,"MANQUE",IF(K22>J22,"EN TROP","OK"))) | Q22: =IF(OR(O22="",P22=""),"",P22-O22) | R22: =IF(OR(O22="",P22="",N(O22)=0),"",IF(P22<O22,"MANQUE",IF(P22>O22,"EN TROP","OK"))) | V22: =IF(OR(T22="",U22=""),"",U22-T22) | W22: =IF(OR(T22="",U22="",N(T22)=0),"",IF(U22<T22,"MANQUE",IF(U22>T22,"EN TROP","OK"))) | X22: =IF(A22="","",COUNTIF(H22:W22,"MANQUE"))
A23: =IF(Produits!$A$21="","",Produits!$A$21) | B23: =IF(Produits!$A$21="","",Produits!$B$21) | C23: =IF(Produits!$A$21="","",Produits!$C$21) | G23: =IF(OR(E23="",F23=""),"",F23-E23) | H23: =IF(OR(E23="",F23="",N(E23)=0),"",IF(F23<E23,"MANQUE",IF(F23>E23,"EN TROP","OK"))) | L23: =IF(OR(J23="",K23=""),"",K23-J23) | M23: =IF(OR(J23="",K23="",N(J23)=0),"",IF(K23<J23,"MANQUE",IF(K23>J23,"EN TROP","OK"))) | Q23: =IF(OR(O23="",P23=""),"",P23-O23) | R23: =IF(OR(O23="",P23="",N(O23)=0),"",IF(P23<O23,"MANQUE",IF(P23>O23,"EN TROP","OK"))) | V23: =IF(OR(T23="",U23=""),"",U23-T23) | W23: =IF(OR(T23="",U23="",N(T23)=0),"",IF(U23<T23,"MANQUE",IF(U23>T23,"EN TROP","OK"))) | X23: =IF(A23="","",COUNTIF(H23:W23,"MANQUE"))
A24: =IF(Produits!$A$22="","",Produits!$A$22) | B24: =IF(Produits!$A$22="","",Produits!$B$22) | C24: =IF(Produits!$A$22="","",Produits!$C$22) | G24: =IF(OR(E24="",F24=""),"",F24-E24) | H24: =IF(OR(E24="",F24="",N(E24)=0),"",IF(F24<E24,"MANQUE",IF(F24>E24,"EN TROP","OK"))) | L24: =IF(OR(J24="",K24=""),"",K24-J24) | M24: =IF(OR(J24="",K24="",N(J24)=0),"",IF(K24<J24,"MANQUE",IF(K24>J24,"EN TROP","OK"))) | Q24: =IF(OR(O24="",P24=""),"",P24-O24) | R24: =IF(OR(O24="",P24="",N(O24)=0),"",IF(P24<O24,"MANQUE",IF(P24>O24,"EN TROP","OK"))) | V24: =IF(OR(T24="",U24=""),"",U24-T24) | W24: =IF(OR(T24="",U24="",N(T24)=0),"",IF(U24<T24,"MANQUE",IF(U24>T24,"EN TROP","OK"))) | X24: =IF(A24="","",COUNTIF(H24:W24,"MANQUE"))
A25: =IF(Produits!$A$23="","",Produits!$A$23) | B25: =IF(Produits!$A$23="","",Produits!$B$23) | C25: =IF(Produits!$A$23="","",Produits!$C$23) | G25: =IF(OR(E25="",F25=""),"",F25-E25) | H25: =IF(OR(E25="",F25="",N(E25)=0),"",IF(F25<E25,"MANQUE",IF(F25>E25,"EN TROP","OK"))) | L25: =IF(OR(J25="",K25=""),"",K25-J25) | M25: =IF(OR(J25="",K25="",N(J25)=0),"",IF(K25<J25,"MANQUE",IF(K25>J25,"EN TROP","OK"))) | Q25: =IF(OR(O25="",P25=""),"",P25-O25) | R25: =IF(OR(O25="",P25="",N(O25)=0),"",IF(P25<O25,"MANQUE",IF(P25>O25,"EN TROP","OK"))) | V25: =IF(OR(T25="",U25=""),"",U25-T25) | W25: =IF(OR(T25="",U25="",N(T25)=0),"",IF(U25<T25,"MANQUE",IF(U25>T25,"EN TROP","OK"))) | X25: =IF(A25="","",COUNTIF(H25:W25,"MANQUE"))
A26: =IF(Produits!$A$24="","",Produits!$A$24) | B26: =IF(Produits!$A$24="","",Produits!$B$24) | C26: =IF(Produits!$A$24="","",Produits!$C$24) | G26: =IF(OR(E26="",F26=""),"",F26-E26) | H26: =IF(OR(E26="",F26="",N(E26)=0),"",IF(F26<E26,"MANQUE",IF(F26>E26,"EN TROP","OK"))) | L26: =IF(OR(J26="",K26=""),"",K26-J26) | M26: =IF(OR(J26="",K26="",N(J26)=0),"",IF(K26<J26,"MANQUE",IF(K26>J26,"EN TROP","OK"))) | Q26: =IF(OR(O26="",P26=""),"",P26-O26) | R26: =IF(OR(O26="",P26="",N(O26)=0),"",IF(P26<O26,"MANQUE",IF(P26>O26,"EN TROP","OK"))) | V26: =IF(OR(T26="",U26=""),"",U26-T26) | W26: =IF(OR(T26="",U26="",N(T26)=0),"",IF(U26<T26,"MANQUE",IF(U26>T26,"EN TROP","OK"))) | X26: =IF(A26="","",COUNTIF(H26:W26,"MANQUE"))
A27: =IF(Produits!$A$25="","",Produits!$A$25) | B27: =IF(Produits!$A$25="","",Produits!$B$25) | C27: =IF(Produits!$A$25="","",Produits!$C$25) | G27: =IF(OR(E27="",F27=""),"",F27-E27) | H27: =IF(OR(E27="",F27="",N(E27)=0),"",IF(F27<E27,"MANQUE",IF(F27>E27,"EN TROP","OK"))) | L27: =IF(OR(J27="",K27=""),"",K27-J27) | M27: =IF(OR(J27="",K27="",N(J27)=0),"",IF(K27<J27,"MANQUE",IF(K27>J27,"EN TROP","OK"))) | Q27: =IF(OR(O27="",P27=""),"",P27-O27) | R27: =IF(OR(O27="",P27="",N(O27)=0),"",IF(P27<O27,"MANQUE",IF(P27>O27,"EN TROP","OK"))) | V27: =IF(OR(T27="",U27=""),"",U27-T27) | W27: =IF(OR(T27="",U27="",N(T27)=0),"",IF(U27<T27,"MANQUE",IF(U27>T27,"EN TROP","OK"))) | X27: =IF(A27="","",COUNTIF(H27:W27,"MANQUE"))
A28: =IF(Produits!$A$26="","",Produits!$A$26) | B28: =IF(Produits!$A$26="","",Produits!$B$26) | C28: =IF(Produits!$A$26="","",Produits!$C$26) | G28: =IF(OR(E28="",F28=""),"",F28-E28) | H28: =IF(OR(E28="",F28="",N(E28)=0),"",IF(F28<E28,"MANQUE",IF(F28>E28,"EN TROP","OK"))) | L28: =IF(OR(J28="",K28=""),"",K28-J28) | M28: =IF(OR(J28="",K28="",N(J28)=0),"",IF(K28<J28,"MANQUE",IF(K28>J28,"EN TROP","OK"))) | Q28: =IF(OR(O28="",P28=""),"",P28-O28) | R28: =IF(OR(O28="",P28="",N(O28)=0),"",IF(P28<O28,"MANQUE",IF(P28>O28,"EN TROP","OK"))) | V28: =IF(OR(T28="",U28=""),"",U28-T28) | W28: =IF(OR(T28="",U28="",N(T28)=0),"",IF(U28<T28,"MANQUE",IF(U28>T28,"EN TROP","OK"))) | X28: =IF(A28="","",COUNTIF(H28:W28,"MANQUE"))
A29: =IF(Produits!$A$27="","",Produits!$A$27) | B29: =IF(Produits!$A$27="","",Produits!$B$27) | C29: =IF(Produits!$A$27="","",Produits!$C$27) | G29: =IF(OR(E29="",F29=""),"",F29-E29) | H29: =IF(OR(E29="",F29="",N(E29)=0),"",IF(F29<E29,"MANQUE",IF(F29>E29,"EN TROP","OK"))) | L29: =IF(OR(J29="",K29=""),"",K29-J29) | M29: =IF(OR(J29="",K29="",N(J29)=0),"",IF(K29<J29,"MANQUE",IF(K29>J29,"EN TROP","OK"))) | Q29: =IF(OR(O29="",P29=""),"",P29-O29) | R29: =IF(OR(O29="",P29="",N(O29)=0),"",IF(P29<O29,"MANQUE",IF(P29>O29,"EN TROP","OK"))) | V29: =IF(OR(T29="",U29=""),"",U29-T29) | W29: =IF(OR(T29="",U29="",N(T29)=0),"",IF(U29<T29,"MANQUE",IF(U29>T29,"EN TROP","OK"))) | X29: =IF(A29="","",COUNTIF(H29:W29,"MANQUE"))
A30: =IF(Produits!$A$28="","",Produits!$A$28) | B30: =IF(Produits!$A$28="","",Produits!$B$28) | C30: =IF(Produits!$A$28="","",Produits!$C$28) | G30: =IF(OR(E30="",F30=""),"",F30-E30) | H30: =IF(OR(E30="",F30="",N(E30)=0),"",IF(F30<E30,"MANQUE",IF(F30>E30,"EN TROP","OK"))) | L30: =IF(OR(J30="",K30=""),"",K30-J30) | M30: =IF(OR(J30="",K30="",N(J30)=0),"",IF(K30<J30,"MANQUE",IF(K30>J30,"EN TROP","OK"))) | Q30: =IF(OR(O30="",P30=""),"",P30-O30) | R30: =IF(OR(O30="",P30="",N(O30)=0),"",IF(P30<O30,"MANQUE",IF(P30>O30,"EN TROP","OK"))) | V30: =IF(OR(T30="",U30=""),"",U30-T30) | W30: =IF(OR(T30="",U30="",N(T30)=0),"",IF(U30<T30,"MANQUE",IF(U30>T30,"EN TROP","OK"))) | X30: =IF(A30="","",COUNTIF(H30:W30,"MANQUE"))
A31: =IF(Produits!$A$29="","",Produits!$A$29) | B31: =IF(Produits!$A$29="","",Produits!$B$29) | C31: =IF(Produits!$A$29="","",Produits!$C$29) | G31: =IF(OR(E31="",F31=""),"",F31-E31) | H31: =IF(OR(E31="",F31="",N(E31)=0),"",IF(F31<E31,"MANQUE",IF(F31>E31,"EN TROP","OK"))) | L31: =IF(OR(J31="",K31=""),"",K31-J31) | M31: =IF(OR(J31="",K31="",N(J31)=0),"",IF(K31<J31,"MANQUE",IF(K31>J31,"EN TROP","OK"))) | Q31: =IF(OR(O31="",P31=""),"",P31-O31) | R31: =IF(OR(O31="",P31="",N(O31)=0),"",IF(P31<O31,"MANQUE",IF(P31>O31,"EN TROP","OK"))) | V31: =IF(OR(T31="",U31=""),"",U31-T31) | W31: =IF(OR(T31="",U31="",N(T31)=0),"",IF(U31<T31,"MANQUE",IF(U31>T31,"EN TROP","OK"))) | X31: =IF(A31="","",COUNTIF(H31:W31,"MANQUE"))
A32: =IF(Produits!$A$30="","",Produits!$A$30) | B32: =IF(Produits!$A$30="","",Produits!$B$30) | C32: =IF(Produits!$A$30="","",Produits!$C$30) | G32: =IF(OR(E32="",F32=""),"",F32-E32) | H32: =IF(OR(E32="",F32="",N(E32)=0),"",IF(F32<E32,"MANQUE",IF(F32>E32,"EN TROP","OK"))) | L32: =IF(OR(J32="",K32=""),"",K32-J32) | M32: =IF(OR(J32="",K32="",N(J32)=0),"",IF(K32<J32,"MANQUE",IF(K32>J32,"EN TROP","OK"))) | Q32: =IF(OR(O32="",P32=""),"",P32-O32) | R32: =IF(OR(O32="",P32="",N(O32)=0),"",IF(P32<O32,"MANQUE",IF(P32>O32,"EN TROP","OK"))) | V32: =IF(OR(T32="",U32=""),"",U32-T32) | W32: =IF(OR(T32="",U32="",N(T32)=0),"",IF(U32<T32,"MANQUE",IF(U32>T32,"EN TROP","OK"))) | X32: =IF(A32="","",COUNTIF(H32:W32,"MANQUE"))
A33: =IF(Produits!$A$31="","",Produits!$A$31) | B33: =IF(Produits!$A$31="","",Produits!$B$31) | C33: =IF(Produits!$A$31="","",Produits!$C$31) | G33: =IF(OR(E33="",F33=""),"",F33-E33) | H33: =IF(OR(E33="",F33="",N(E33)=0),"",IF(F33<E33,"MANQUE",IF(F33>E33,"EN TROP","OK"))) | L33: =IF(OR(J33="",K33=""),"",K33-J33) | M33: =IF(OR(J33="",K33="",N(J33)=0),"",IF(K33<J33,"MANQUE",IF(K33>J33,"EN TROP","OK"))) | Q33: =IF(OR(O33="",P33=""),"",P33-O33) | R33: =IF(OR(O33="",P33="",N(O33)=0),"",IF(P33<O33,"MANQUE",IF(P33>O33,"EN TROP","OK"))) | V33: =IF(OR(T33="",U33=""),"",U33-T33) | W33: =IF(OR(T33="",U33="",N(T33)=0),"",IF(U33<T33,"MANQUE",IF(U33>T33,"EN TROP","OK"))) | X33: =IF(A33="","",COUNTIF(H33:W33,"MANQUE"))
A34: =IF(Produits!$A$32="","",Produits!$A$32) | B34: =IF(Produits!$A$32="","",Produits!$B$32) | C34: =IF(Produits!$A$32="","",Produits!$C$32) | G34: =IF(OR(E34="",F34=""),"",F34-E34) | H34: =IF(OR(E34="",F34="",N(E34)=0),"",IF(F34<E34,"MANQUE",IF(F34>E34,"EN TROP","OK"))) | L34: =IF(OR(J34="",K34=""),"",K34-J34) | M34: =IF(OR(J34="",K34="",N(J34)=0),"",IF(K34<J34,"MANQUE",IF(K34>J34,"EN TROP","OK"))) | Q34: =IF(OR(O34="",P34=""),"",P34-O34) | R34: =IF(OR(O34="",P34="",N(O34)=0),"",IF(P34<O34,"MANQUE",IF(P34>O34,"EN TROP","OK"))) | V34: =IF(OR(T34="",U34=""),"",U34-T34) | W34: =IF(OR(T34="",U34="",N(T34)=0),"",IF(U34<T34,"MANQUE",IF(U34>T34,"EN TROP","OK"))) | X34: =IF(A34="","",COUNTIF(H34:W34,"MANQUE"))
A35: =IF(Produits!$A$33="","",Produits!$A$33) | B35: =IF(Produits!$A$33="","",Produits!$B$33) | C35: =IF(Produits!$A$33="","",Produits!$C$33) | G35: =IF(OR(E35="",F35=""),"",F35-E35) | H35: =IF(OR(E35="",F35="",N(E35)=0),"",IF(F35<E35,"MANQUE",IF(F35>E35,"EN TROP","OK"))) | L35: =IF(OR(J35="",K35=""),"",K35-J35) | M35: =IF(OR(J35="",K35="",N(J35)=0),"",IF(K35<J35,"MANQUE",IF(K35>J35,"EN TROP","OK"))) | Q35: =IF(OR(O35="",P35=""),"",P35-O35) | R35: =IF(OR(O35="",P35="",N(O35)=0),"",IF(P35<O35,"MANQUE",IF(P35>O35,"EN TROP","OK"))) | V35: =IF(OR(T35="",U35=""),"",U35-T35) | W35: =IF(OR(T35="",U35="",N(T35)=0),"",IF(U35<T35,"MANQUE",IF(U35>T35,"EN TROP","OK"))) | X35: =IF(A35="","",COUNTIF(H35:W35,"MANQUE"))
A36: =IF(Produits!$A$34="","",Produits!$A$34) | B36: =IF(Produits!$A$34="","",Produits!$B$34) | C36: =IF(Produits!$A$34="","",Produits!$C$34) | G36: =IF(OR(E36="",F36=""),"",F36-E36) | H36: =IF(OR(E36="",F36="",N(E36)=0),"",IF(F36<E36,"MANQUE",IF(F36>E36,"EN TROP","OK"))) | L36: =IF(OR(J36="",K36=""),"",K36-J36) | M36: =IF(OR(J36="",K36="",N(J36)=0),"",IF(K36<J36,"MANQUE",IF(K36>J36,"EN TROP","OK"))) | Q36: =IF(OR(O36="",P36=""),"",P36-O36) | R36: =IF(OR(O36="",P36="",N(O36)=0),"",IF(P36<O36,"MANQUE",IF(P36>O36,"EN TROP","OK"))) | V36: =IF(OR(T36="",U36=""),"",U36-T36) | W36: =IF(OR(T36="",U36="",N(T36)=0),"",IF(U36<T36,"MANQUE",IF(U36>T36,"EN TROP","OK"))) | X36: =IF(A36="","",COUNTIF(H36:W36,"MANQUE"))
A37: =IF(Produits!$A$35="","",Produits!$A$35) | B37: =IF(Produits!$A$35="","",Produits!$B$35) | C37: =IF(Produits!$A$35="","",Produits!$C$35) | G37: =IF(OR(E37="",F37=""),"",F37-E37) | H37: =IF(OR(E37="",F37="",N(E37)=0),"",IF(F37<E37,"MANQUE",IF(F37>E37,"EN TROP","OK"))) | L37: =IF(OR(J37="",K37=""),"",K37-J37) | M37: =IF(OR(J37="",K37="",N(J37)=0),"",IF(K37<J37,"MANQUE",IF(K37>J37,"EN TROP","OK"))) | Q37: =IF(OR(O37="",P37=""),"",P37-O37) | R37: =IF(OR(O37="",P37="",N(O37)=0),"",IF(P37<O37,"MANQUE",IF(P37>O37,"EN TROP","OK"))) | V37: =IF(OR(T37="",U37=""),"",U37-T37) | W37: =IF(OR(T37="",U37="",N(T37)=0),"",IF(U37<T37,"MANQUE",IF(U37>T37,"EN TROP","OK"))) | X37: =IF(A37="","",COUNTIF(H37:W37,"MANQUE"))
A38: =IF(Produits!$A$36="","",Produits!$A$36) | B38: =IF(Produits!$A$36="","",Produits!$B$36) | C38: =IF(Produits!$A$36="","",Produits!$C$36) | G38: =IF(OR(E38="",F38=""),"",F38-E38) | H38: =IF(OR(E38="",F38="",N(E38)=0),"",IF(F38<E38,"MANQUE",IF(F38>E38,"EN TROP","OK"))) | L38: =IF(OR(J38="",K38=""),"",K38-J38) | M38: =IF(OR(J38="",K38="",N(J38)=0),"",IF(K38<J38,"MANQUE",IF(K38>J38,"EN TROP","OK"))) | Q38: =IF(OR(O38="",P38=""),"",P38-O38) | R38: =IF(OR(O38="",P38="",N(O38)=0),"",IF(P38<O38,"MANQUE",IF(P38>O38,"EN TROP","OK"))) | V38: =IF(OR(T38="",U38=""),"",U38-T38) | W38: =IF(OR(T38="",U38="",N(T38)=0),"",IF(U38<T38,"MANQUE",IF(U38>T38,"EN TROP","OK"))) | X38: =IF(A38="","",COUNTIF(H38:W38,"MANQUE"))
A39: =IF(Produits!$A$37="","",Produits!$A$37) | B39: =IF(Produits!$A$37="","",Produits!$B$37) | C39: =IF(Produits!$A$37="","",Produits!$C$37) | G39: =IF(OR(E39="",F39=""),"",F39-E39) | H39: =IF(OR(E39="",F39="",N(E39)=0),"",IF(F39<E39,"MANQUE",IF(F39>E39,"EN TROP","OK"))) | L39: =IF(OR(J39="",K39=""),"",K39-J39) | M39: =IF(OR(J39="",K39="",N(J39)=0),"",IF(K39<J39,"MANQUE",IF(K39>J39,"EN TROP","OK"))) | Q39: =IF(OR(O39="",P39=""),"",P39-O39) | R39: =IF(OR(O39="",P39="",N(O39)=0),"",IF(P39<O39,"MANQUE",IF(P39>O39,"EN TROP","OK"))) | V39: =IF(OR(T39="",U39=""),"",U39-T39) | W39: =IF(OR(T39="",U39="",N(T39)=0),"",IF(U39<T39,"MANQUE",IF(U39>T39,"EN TROP","OK"))) | X39: =IF(A39="","",COUNTIF(H39:W39,"MANQUE"))
A40: =IF(Produits!$A$38="","",Produits!$A$38) | B40: =IF(Produits!$A$38="","",Produits!$B$38) | C40: =IF(Produits!$A$38="","",Produits!$C$38) | G40: =IF(OR(E40="",F40=""),"",F40-E40) | H40: =IF(OR(E40="",F40="",N(E40)=0),"",IF(F40<E40,"MANQUE",IF(F40>E40,"EN TROP","OK"))) | L40: =IF(OR(J40="",K40=""),"",K40-J40) | M40: =IF(OR(J40="",K40="",N(J40)=0),"",IF(K40<J40,"MANQUE",IF(K40>J40,"EN TROP","OK"))) | Q40: =IF(OR(O40="",P40=""),"",P40-O40) | R40: =IF(OR(O40="",P40="",N(O40)=0),"",IF(P40<O40,"MANQUE",IF(P40>O40,"EN TROP","OK"))) | V40: =IF(OR(T40="",U40=""),"",U40-T40) | W40: =IF(OR(T40="",U40="",N(T40)=0),"",IF(U40<T40,"MANQUE",IF(U40>T40,"EN TROP","OK"))) | X40: =IF(A40="","",COUNTIF(H40:W40,"MANQUE"))
A41: =IF(Produits!$A$39="","",Produits!$A$39) | B41: =IF(Produits!$A$39="","",Produits!$B$39) | C41: =IF(Produits!$A$39="","",Produits!$C$39) | G41: =IF(OR(E41="",F41=""),"",F41-E41) | H41: =IF(OR(E41="",F41="",N(E41)=0),"",IF(F41<E41,"MANQUE",IF(F41>E41,"EN TROP","OK"))) | L41: =IF(OR(J41="",K41=""),"",K41-J41) | M41: =IF(OR(J41="",K41="",N(J41)=0),"",IF(K41<J41,"MANQUE",IF(K41>J41,"EN TROP","OK"))) | Q41: =IF(OR(O41="",P41=""),"",P41-O41) | R41: =IF(OR(O41="",P41="",N(O41)=0),"",IF(P41<O41,"MANQUE",IF(P41>O41,"EN TROP","OK"))) | V41: =IF(OR(T41="",U41=""),"",U41-T41) | W41: =IF(OR(T41="",U41="",N(T41)=0),"",IF(U41<T41,"MANQUE",IF(U41>T41,"EN TROP","OK"))) | X41: =IF(A41="","",COUNTIF(H41:W41,"MANQUE"))
A42: =IF(Produits!$A$40="","",Produits!$A$40) | B42: =IF(Produits!$A$40="","",Produits!$B$40) | C42: =IF(Produits!$A$40="","",Produits!$C$40) | G42: =IF(OR(E42="",F42=""),"",F42-E42) | H42: =IF(OR(E42="",F42="",N(E42)=0),"",IF(F42<E42,"MANQUE",IF(F42>E42,"EN TROP","OK"))) | L42: =IF(OR(J42="",K42=""),"",K42-J42) | M42: =IF(OR(J42="",K42="",N(J42)=0),"",IF(K42<J42,"MANQUE",IF(K42>J42,"EN TROP","OK"))) | Q42: =IF(OR(O42="",P42=""),"",P42-O42) | R42: =IF(OR(O42="",P42="",N(O42)=0),"",IF(P42<O42,"MANQUE",IF(P42>O42,"EN TROP","OK"))) | V42: =IF(OR(T42="",U42=""),"",U42-T42) | W42: =IF(OR(T42="",U42="",N(T42)=0),"",IF(U42<T42,"MANQUE",IF(U42>T42,"EN TROP","OK"))) | X42: =IF(A42="","",COUNTIF(H42:W42,"MANQUE"))
...

Sheet Réclamations
A1: Réclamations fournisseurs
A2: Une ligne par livraison incomplète
A4: Date | B4: Produit | C4: Fournisseur | D4: Commandé | E4: Reçu | F4: Manque | G4: Ce que j'ai fait | H4: Réglé ?
A5: =DATE(2026,10,5) | B5: Farine T55 | C5: =IF(B5="","",IFERROR(INDEX(Produits!$B$5:$B$44,MATCH(B5,Produits!$A$5:$A$44,0)),"")) | D5: 10 | E5: 7 | F5: =IF(OR(D5="",E5=""),"",D5-E5) | G5: Appelé Metro, avoir promis | H5: Non
C6: =IF(B6="","",IFERROR(INDEX(Produits!$B$5:$B$44,MATCH(B6,Produits!$A$5:$A$44,0)),"")) | F6: =IF(OR(D6="",E6=""),"",D6-E6)
C7: =IF(B7="","",IFERROR(INDEX(Produits!$B$5:$B$44,MATCH(B7,Produits!$A$5:$A$44,0)),"")) | F7: =IF(OR(D7="",E7=""),"",D7-E7)
C8: =IF(B8="","",IFERROR(INDEX(Produits!$B$5:$B$44,MATCH(B8,Produits!$A$5:$A$44,0)),"")) | F8: =IF(OR(D8="",E8=""),"",D8-E8)
C9: =IF(B9="","",IFERROR(INDEX(Produits!$B$5:$B$44,MATCH(B9,Produits!$A$5:$A$44,0)),"")) | F9: =IF(OR(D9="",E9=""),"",D9-E9)
C10: =IF(B10="","",IFERROR(INDEX(Produits!$B$5:$B$44,MATCH(B10,Produits!$A$5:$A$44,0)),"")) | F10: =IF(OR(D10="",E10=""),"",D10-E10)
C11: =IF(B11="","",IFERROR(INDEX(Produits!$B$5:$B$44,MATCH(B11,Produits!$A$5:$A$44,0)),"")) | F11: =IF(OR(D11="",E11=""),"",D11-E11)
C12: =IF(B12="","",IFERROR(INDEX(Produits!$B$5:$B$44,MATCH(B12,Produits!$A$5:$A$44,0)),"")) | F12: =IF(OR(D12="",E12=""),"",D12-E12)
C13: =IF(B13="","",IFERROR(INDEX(Produits!$B$5:$B$44,MATCH(B13,Produits!$A$5:$A$44,0)),"")) | F13: =IF(OR(D13="",E13=""),"",D13-E13)
C14: =IF(B14="","",IFERROR(INDEX(Produits!$B$5:$B$44,MATCH(B14,Produits!$A$5:$A$44,0)),"")) | F14: =IF(OR(D14="",E14=""),"",D14-E14)
C15: =IF(B15="","",IFERROR(INDEX(Produits!$B$5:$B$44,MATCH(B15,Produits!$A$5:$A$44,0)),"")) | F15: =IF(OR(D15="",E15=""),"",D15-E15)
C16: =IF(B16="","",IFERROR(INDEX(Produits!$B$5:$B$44,MATCH(B16,Produits!$A$5:$A$44,0)),"")) | F16: =IF(OR(D16="",E16=""),"",D16-E16)
C17: =IF(B17="","",IFERROR(INDEX(Produits!$B$5:$B$44,MATCH(B17,Produits!$A$5:$A$44,0)),"")) | F17: =IF(OR(D17="",E17=""),"",D17-E17)
... C64: =IF(B64="","",IFERROR(INDEX(Produits!$B$5:$B$44,MATCH(B64,Produits!$A$5:$A$44,0)),"")) | F64: =IF(OR(D64="",E64=""),"",D64-E64)
