Workbook

Sheet Mode d'emploi
A1: 7 · Tableau de bord
A2: Proposition de tableau de gestion des stocks — Excel et Google Sheets
A4: L'idée | B4: Même saisie que le cahier classique, plus une page de résumé : combien tu as dépensé ce mois-ci, combien de livraisons étaient incomplètes, quels produits sont sous le minimum, et un graphique des 10 produits qui te coûtent le plus.
A6: Comment faire | B6: 1. Onglet Produits : produit, fournisseur, unité, stock minimum, prix unitaire.
B7: 2. Onglet du mois : Stock, Commandé, Reçu chaque semaine.
B8: 3. Onglet Tableau de bord : tout se calcule, rien à remplir.
B9: 4. Nouveau mois : duplique l'onglet du mois et change la référence en haut du tableau de bord (ou garde un fichier par mois).
A11: Les onglets | B11: Tableau de bord — les chiffres clés et le graphique.
B12: Produits — ta liste, avec minimum et prix.
B13: Octobre 2026 — la saisie de la semaine.
A15: Couleurs | B15: Cases jaunes = à remplir. Cases blanches = calculées toutes seules, ne pas y toucher.
B16: Chiffres en bleu = exemple pour montrer le fonctionnement, à effacer.
B17: Rouge = il manque quelque chose (livraison incomplète, stock trop bas).
A19: Google Sheets | B19: Fichier > Importer > Importer ce fichier. Tout fonctionne pareil, y compris sur téléphone.

Sheet Tableau de bord
A1: Tableau de bord — Octobre 2026
A2: Calculé à partir de l'onglet Octobre 2026 — rien à remplir
K3: Calculs intermédiaires
A4: Dépensé ce mois-ci | C4: Livraisons incomplètes | E4: Produits sous le minimum | G4: Produits suivis | K4: Produit | L4: Reçu | M4: Prix | N4: Dépense (€) | O4: Dernier stock | P4: Sous le mini | Q4: Tri
A5: =SUM(N5:N44) | C5: =COUNTIF('Octobre 2026'!R7:R46,"<0") | E5: =SUM(P5:P44) | G5: =COUNTA(Produits!A5:A44) | K5: ='Octobre 2026'!A7 | L5: =N('Octobre 2026'!Q7) | M5: =N(Produits!E5) | N5: =L5*M5 | O5: ='Octobre 2026'!S7 | P5: =IF(AND(K5<>"",O5<>"",Produits!D5<>""),IF(N(O5)<=N(Produits!D5),1,0),0) | Q5: =IF(K5="",-1,N5+ROW()/1000000)
K6: ='Octobre 2026'!A8 | L6: =N('Octobre 2026'!Q8) | M6: =N(Produits!E6) | N6: =L6*M6 | O6: ='Octobre 2026'!S8 | P6: =IF(AND(K6<>"",O6<>"",Produits!D6<>""),IF(N(O6)<=N(Produits!D6),1,0),0) | Q6: =IF(K6="",-1,N6+ROW()/1000000)
K7: ='Octobre 2026'!A9 | L7: =N('Octobre 2026'!Q9) | M7: =N(Produits!E7) | N7: =L7*M7 | O7: ='Octobre 2026'!S9 | P7: =IF(AND(K7<>"",O7<>"",Produits!D7<>""),IF(N(O7)<=N(Produits!D7),1,0),0) | Q7: =IF(K7="",-1,N7+ROW()/1000000)
K8: ='Octobre 2026'!A10 | L8: =N('Octobre 2026'!Q10) | M8: =N(Produits!E8) | N8: =L8*M8 | O8: ='Octobre 2026'!S10 | P8: =IF(AND(K8<>"",O8<>"",Produits!D8<>""),IF(N(O8)<=N(Produits!D8),1,0),0) | Q8: =IF(K8="",-1,N8+ROW()/1000000)
A9: Top 10 des dépenses du mois | K9: ='Octobre 2026'!A11 | L9: =N('Octobre 2026'!Q11) | M9: =N(Produits!E9) | N9: =L9*M9 | O9: ='Octobre 2026'!S11 | P9: =IF(AND(K9<>"",O9<>"",Produits!D9<>""),IF(N(O9)<=N(Produits!D9),1,0),0) | Q9: =IF(K9="",-1,N9+ROW()/1000000)
A10: Rang | B10: Produit | D10: Reçu | E10: Dépense (€) | K10: ='Octobre 2026'!A12 | L10: =N('Octobre 2026'!Q12) | M10: =N(Produits!E10) | N10: =L10*M10 | O10: ='Octobre 2026'!S12 | P10: =IF(AND(K10<>"",O10<>"",Produits!D10<>""),IF(N(O10)<=N(Produits!D10),1,0),0) | Q10: =IF(K10="",-1,N10+ROW()/1000000)
A11: 1 | B11: =IF(LARGE($Q$5:$Q$44,1)<=0,"",INDEX($K$5:$K$44,MATCH(LARGE($Q$5:$Q$44,1),$Q$5:$Q$44,0))) | D11: =IF(B11="","",INDEX($L$5:$L$44,MATCH(LARGE($Q$5:$Q$44,1),$Q$5:$Q$44,0))) | E11: =IF(B11="","",INDEX($N$5:$N$44,MATCH(LARGE($Q$5:$Q$44,1),$Q$5:$Q$44,0))) | K11: ='Octobre 2026'!A13 | L11: =N('Octobre 2026'!Q13) | M11: =N(Produits!E11) | N11: =L11*M11 | O11: ='Octobre 2026'!S13 | P11: =IF(AND(K11<>"",O11<>"",Produits!D11<>""),IF(N(O11)<=N(Produits!D11),1,0),0) | Q11: =IF(K11="",-1,N11+ROW()/1000000)
A12: 2 | B12: =IF(LARGE($Q$5:$Q$44,2)<=0,"",INDEX($K$5:$K$44,MATCH(LARGE($Q$5:$Q$44,2),$Q$5:$Q$44,0))) | D12: =IF(B12="","",INDEX($L$5:$L$44,MATCH(LARGE($Q$5:$Q$44,2),$Q$5:$Q$44,0))) | E12: =IF(B12="","",INDEX($N$5:$N$44,MATCH(LARGE($Q$5:$Q$44,2),$Q$5:$Q$44,0))) | K12: ='Octobre 2026'!A14 | L12: =N('Octobre 2026'!Q14) | M12: =N(Produits!E12) | N12: =L12*M12 | O12: ='Octobre 2026'!S14 | P12: =IF(AND(K12<>"",O12<>"",Produits!D12<>""),IF(N(O12)<=N(Produits!D12),1,0),0) | Q12: =IF(K12="",-1,N12+ROW()/1000000)
A13: 3 | B13: =IF(LARGE($Q$5:$Q$44,3)<=0,"",INDEX($K$5:$K$44,MATCH(LARGE($Q$5:$Q$44,3),$Q$5:$Q$44,0))) | D13: =IF(B13="","",INDEX($L$5:$L$44,MATCH(LARGE($Q$5:$Q$44,3),$Q$5:$Q$44,0))) | E13: =IF(B13="","",INDEX($N$5:$N$44,MATCH(LARGE($Q$5:$Q$44,3),$Q$5:$Q$44,0))) | K13: ='Octobre 2026'!A15 | L13: =N('Octobre 2026'!Q15) | M13: =N(Produits!E13) | N13: =L13*M13 | O13: ='Octobre 2026'!S15 | P13: =IF(AND(K13<>"",O13<>"",Produits!D13<>""),IF(N(O13)<=N(Produits!D13),1,0),0) | Q13: =IF(K13="",-1,N13+ROW()/1000000)
A14: 4 | B14: =IF(LARGE($Q$5:$Q$44,4)<=0,"",INDEX($K$5:$K$44,MATCH(LARGE($Q$5:$Q$44,4),$Q$5:$Q$44,0))) | D14: =IF(B14="","",INDEX($L$5:$L$44,MATCH(LARGE($Q$5:$Q$44,4),$Q$5:$Q$44,0))) | E14: =IF(B14="","",INDEX($N$5:$N$44,MATCH(LARGE($Q$5:$Q$44,4),$Q$5:$Q$44,0))) | K14: ='Octobre 2026'!A16 | L14: =N('Octobre 2026'!Q16) | M14: =N(Produits!E14) | N14: =L14*M14 | O14: ='Octobre 2026'!S16 | P14: =IF(AND(K14<>"",O14<>"",Produits!D14<>""),IF(N(O14)<=N(Produits!D14),1,0),0) | Q14: =IF(K14="",-1,N14+ROW()/1000000)
A15: 5 | B15: =IF(LARGE($Q$5:$Q$44,5)<=0,"",INDEX($K$5:$K$44,MATCH(LARGE($Q$5:$Q$44,5),$Q$5:$Q$44,0))) | D15: =IF(B15="","",INDEX($L$5:$L$44,MATCH(LARGE($Q$5:$Q$44,5),$Q$5:$Q$44,0))) | E15: =IF(B15="","",INDEX($N$5:$N$44,MATCH(LARGE($Q$5:$Q$44,5),$Q$5:$Q$44,0))) | K15: ='Octobre 2026'!A17 | L15: =N('Octobre 2026'!Q17) | M15: =N(Produits!E15) | N15: =L15*M15 | O15: ='Octobre 2026'!S17 | P15: =IF(AND(K15<>"",O15<>"",Produits!D15<>""),IF(N(O15)<=N(Produits!D15),1,0),0) | Q15: =IF(K15="",-1,N15+ROW()/1000000)
A16: 6 | B16: =IF(LARGE($Q$5:$Q$44,6)<=0,"",INDEX($K$5:$K$44,MATCH(LARGE($Q$5:$Q$44,6),$Q$5:$Q$44,0))) | D16: =IF(B16="","",INDEX($L$5:$L$44,MATCH(LARGE($Q$5:$Q$44,6),$Q$5:$Q$44,0))) | E16: =IF(B16="","",INDEX($N$5:$N$44,MATCH(LARGE($Q$5:$Q$44,6),$Q$5:$Q$44,0))) | K16: ='Octobre 2026'!A18 | L16: =N('Octobre 2026'!Q18) | M16: =N(Produits!E16) | N16: =L16*M16 | O16: ='Octobre 2026'!S18 | P16: =IF(AND(K16<>"",O16<>"",Produits!D16<>""),IF(N(O16)<=N(Produits!D16),1,0),0) | Q16: =IF(K16="",-1,N16+ROW()/1000000)
A17: 7 | B17: =IF(LARGE($Q$5:$Q$44,7)<=0,"",INDEX($K$5:$K$44,MATCH(LARGE($Q$5:$Q$44,7),$Q$5:$Q$44,0))) | D17: =IF(B17="","",INDEX($L$5:$L$44,MATCH(LARGE($Q$5:$Q$44,7),$Q$5:$Q$44,0))) | E17: =IF(B17="","",INDEX($N$5:$N$44,MATCH(LARGE($Q$5:$Q$44,7),$Q$5:$Q$44,0))) | K17: ='Octobre 2026'!A19 | L17: =N('Octobre 2026'!Q19) | M17: =N(Produits!E17) | N17: =L17*M17 | O17: ='Octobre 2026'!S19 | P17: =IF(AND(K17<>"",O17<>"",Produits!D17<>""),IF(N(O17)<=N(Produits!D17),1,0),0) | Q17: =IF(K17="",-1,N17+ROW()/1000000)
A18: 8 | B18: =IF(LARGE($Q$5:$Q$44,8)<=0,"",INDEX($K$5:$K$44,MATCH(LARGE($Q$5:$Q$44,8),$Q$5:$Q$44,0))) | D18: =IF(B18="","",INDEX($L$5:$L$44,MATCH(LARGE($Q$5:$Q$44,8),$Q$5:$Q$44,0))) | E18: =IF(B18="","",INDEX($N$5:$N$44,MATCH(LARGE($Q$5:$Q$44,8),$Q$5:$Q$44,0))) | K18: ='Octobre 2026'!A20 | L18: =N('Octobre 2026'!Q20) | M18: =N(Produits!E18) | N18: =L18*M18 | O18: ='Octobre 2026'!S20 | P18: =IF(AND(K18<>"",O18<>"",Produits!D18<>""),IF(N(O18)<=N(Produits!D18),1,0),0) | Q18: =IF(K18="",-1,N18+ROW()/1000000)
A19: 9 | B19: =IF(LARGE($Q$5:$Q$44,9)<=0,"",INDEX($K$5:$K$44,MATCH(LARGE($Q$5:$Q$44,9),$Q$5:$Q$44,0))) | D19: =IF(B19="","",INDEX($L$5:$L$44,MATCH(LARGE($Q$5:$Q$44,9),$Q$5:$Q$44,0))) | E19: =IF(B19="","",INDEX($N$5:$N$44,MATCH(LARGE($Q$5:$Q$44,9),$Q$5:$Q$44,0))) | K19: ='Octobre 2026'!A21 | L19: =N('Octobre 2026'!Q21) | M19: =N(Produits!E19) | N19: =L19*M19 | O19: ='Octobre 2026'!S21 | P19: =IF(AND(K19<>"",O19<>"",Produits!D19<>""),IF(N(O19)<=N(Produits!D19),1,0),0) | Q19: =IF(K19="",-1,N19+ROW()/1000000)
A20: 10 | B20: =IF(LARGE($Q$5:$Q$44,10)<=0,"",INDEX($K$5:$K$44,MATCH(LARGE($Q$5:$Q$44,10),$Q$5:$Q$44,0))) | D20: =IF(B20="","",INDEX($L$5:$L$44,MATCH(LARGE($Q$5:$Q$44,10),$Q$5:$Q$44,0))) | E20: =IF(B20="","",INDEX($N$5:$N$44,MATCH(LARGE($Q$5:$Q$44,10),$Q$5:$Q$44,0))) | K20: ='Octobre 2026'!A22 | L20: =N('Octobre 2026'!Q22) | M20: =N(Produits!E20) | N20: =L20*M20 | O20: ='Octobre 2026'!S22 | P20: =IF(AND(K20<>"",O20<>"",Produits!D20<>""),IF(N(O20)<=N(Produits!D20),1,0),0) | Q20: =IF(K20="",-1,N20+ROW()/1000000)
K21: ='Octobre 2026'!A23 | L21: =N('Octobre 2026'!Q23) | M21: =N(Produits!E21) | N21: =L21*M21 | O21: ='Octobre 2026'!S23 | P21: =IF(AND(K21<>"",O21<>"",Produits!D21<>""),IF(N(O21)<=N(Produits!D21),1,0),0) | Q21: =IF(K21="",-1,N21+ROW()/1000000)
K22: ='Octobre 2026'!A24 | L22: =N('Octobre 2026'!Q24) | M22: =N(Produits!E22) | N22: =L22*M22 | O22: ='Octobre 2026'!S24 | P22: =IF(AND(K22<>"",O22<>"",Produits!D22<>""),IF(N(O22)<=N(Produits!D22),1,0),0) | Q22: =IF(K22="",-1,N22+ROW()/1000000)
K23: ='Octobre 2026'!A25 | L23: =N('Octobre 2026'!Q25) | M23: =N(Produits!E23) | N23: =L23*M23 | O23: ='Octobre 2026'!S25 | P23: =IF(AND(K23<>"",O23<>"",Produits!D23<>""),IF(N(O23)<=N(Produits!D23),1,0),0) | Q23: =IF(K23="",-1,N23+ROW()/1000000)
K24: ='Octobre 2026'!A26 | L24: =N('Octobre 2026'!Q26) | M24: =N(Produits!E24) | N24: =L24*M24 | O24: ='Octobre 2026'!S26 | P24: =IF(AND(K24<>"",O24<>"",Produits!D24<>""),IF(N(O24)<=N(Produits!D24),1,0),0) | Q24: =IF(K24="",-1,N24+ROW()/1000000)
K25: ='Octobre 2026'!A27 | L25: =N('Octobre 2026'!Q27) | M25: =N(Produits!E25) | N25: =L25*M25 | O25: ='Octobre 2026'!S27 | P25: =IF(AND(K25<>"",O25<>"",Produits!D25<>""),IF(N(O25)<=N(Produits!D25),1,0),0) | Q25: =IF(K25="",-1,N25+ROW()/1000000)
K26: ='Octobre 2026'!A28 | L26: =N('Octobre 2026'!Q28) | M26: =N(Produits!E26) | N26: =L26*M26 | O26: ='Octobre 2026'!S28 | P26: =IF(AND(K26<>"",O26<>"",Produits!D26<>""),IF(N(O26)<=N(Produits!D26),1,0),0) | Q26: =IF(K26="",-1,N26+ROW()/1000000)
K27: ='Octobre 2026'!A29 | L27: =N('Octobre 2026'!Q29) | M27: =N(Produits!E27) | N27: =L27*M27 | O27: ='Octobre 2026'!S29 | P27: =IF(AND(K27<>"",O27<>"",Produits!D27<>""),IF(N(O27)<=N(Produits!D27),1,0),0) | Q27: =IF(K27="",-1,N27+ROW()/1000000)
K28: ='Octobre 2026'!A30 | L28: =N('Octobre 2026'!Q30) | M28: =N(Produits!E28) | N28: =L28*M28 | O28: ='Octobre 2026'!S30 | P28: =IF(AND(K28<>"",O28<>"",Produits!D28<>""),IF(N(O28)<=N(Produits!D28),1,0),0) | Q28: =IF(K28="",-1,N28+ROW()/1000000)
K29: ='Octobre 2026'!A31 | L29: =N('Octobre 2026'!Q31) | M29: =N(Produits!E29) | N29: =L29*M29 | O29: ='Octobre 2026'!S31 | P29: =IF(AND(K29<>"",O29<>"",Produits!D29<>""),IF(N(O29)<=N(Produits!D29),1,0),0) | Q29: =IF(K29="",-1,N29+ROW()/1000000)
K30: ='Octobre 2026'!A32 | L30: =N('Octobre 2026'!Q32) | M30: =N(Produits!E30) | N30: =L30*M30 | O30: ='Octobre 2026'!S32 | P30: =IF(AND(K30<>"",O30<>"",Produits!D30<>""),IF(N(O30)<=N(Produits!D30),1,0),0) | Q30: =IF(K30="",-1,N30+ROW()/1000000)
K31: ='Octobre 2026'!A33 | L31: =N('Octobre 2026'!Q33) | M31: =N(Produits!E31) | N31: =L31*M31 | O31: ='Octobre 2026'!S33 | P31: =IF(AND(K31<>"",O31<>"",Produits!D31<>""),IF(N(O31)<=N(Produits!D31),1,0),0) | Q31: =IF(K31="",-1,N31+ROW()/1000000)
K32: ='Octobre 2026'!A34 | L32: =N('Octobre 2026'!Q34) | M32: =N(Produits!E32) | N32: =L32*M32 | O32: ='Octobre 2026'!S34 | P32: =IF(AND(K32<>"",O32<>"",Produits!D32<>""),IF(N(O32)<=N(Produits!D32),1,0),0) | Q32: =IF(K32="",-1,N32+ROW()/1000000)
... K44: ='Octobre 2026'!A46 | L44: =N('Octobre 2026'!Q46) | M44: =N(Produits!E44) | N44: =L44*M44 | O44: ='Octobre 2026'!S46 | P44: =IF(AND(K44<>"",O44<>"",Produits!D44<>""),IF(N(O44)<=N(Produits!D44),1,0),0) | Q44: =IF(K44="",-1,N44+ROW()/1000000)

Sheet Produits
A1: Mes produits
A2: Une ligne par produit. Tout le reste du fichier se remplit à partir de cette liste.
A4: Produit | B4: Fournisseur | C4: Unité | D4: Stock minimum | E4: Prix unitaire (€)
A5: Farine T55 | B5: Metro | C5: kg | D5: 5 | E5: 0.9
A6: Farine T45 | B6: Metro | C6: kg | D6: 3 | E6: 1.1
A7: Sucre semoule | B7: Metro | C7: kg | D7: 5 | E7: 1.2
A8: Sucre glace | B8: Metro | C8: kg | D8: 2 | E8: 1.8
A9: Beurre doux | B9: Crèmerie | C9: kg | D9: 4 | E9: 8.5
A10: Crème liquide 35% | B10: Crèmerie | C10: L | D10: 6 | E10: 4.2
A11: Lait entier | B11: Crèmerie | C11: L | D11: 5 | E11: 1.1
A12: Oeufs | B12: Crèmerie | C12: pièce | D12: 60 | E12: 0.25
A13: Chocolat blanc | B13: Transgourmet | C13: kg | D13: 2 | E13: 14
A14: Chocolat noir 70% | B14: Transgourmet | C14: kg | D14: 2 | E14: 13
A15: Levure chimique | B15: Transgourmet | C15: kg | D15: 0.5 | E15: 6
A16: Vanille (gousse) | B16: Transgourmet | C16: pièce | D16: 5 | E16: 2.5

Sheet Octobre 2026
A1: Octobre 2026
A2: Stock = ce qu'il reste · Commandé = ce que tu demandes · Reçu = ce qui est arrivé
A4: Produit | B4: Fournisseur | C4: Unité | D4: Semaine 1 | G4: Semaine 2 | J4: Semaine 3 | M4: Semaine 4 | P4: Total du mois
D6: Stock | E6: Commandé | F6: Reçu | G6: Stock | H6: Commandé | I6: Reçu | J6: Stock | K6: Commandé | L6: Reçu | M6: Stock | N6: Commandé | O6: Reçu | P6: Commandé | Q6: Reçu | R6: Écart | S6: Dernier stock
A7: =IF(Produits!$A$5="","",Produits!$A$5) | B7: =IF(Produits!$A$5="","",Produits!$B$5) | C7: =IF(Produits!$A$5="","",Produits!$C$5) | D7: 8 | E7: 10 | F7: 7 | G7: 5 | H7: 10 | I7: 10 | P7: =IF(COUNT(E7,H7,K7,N7)=0,"",SUM(E7,H7,K7,N7)) | Q7: =IF(COUNT(F7,I7,L7,O7)=0,"",SUM(F7,I7,L7,O7)) | R7: =IF(OR(P7="",Q7=""),"",Q7-P7) | S7: =IF(M7<>"",M7,IF(J7<>"",J7,IF(G7<>"",G7,IF(D7<>"",D7,""))))
A8: =IF(Produits!$A$6="","",Produits!$A$6) | B8: =IF(Produits!$A$6="","",Produits!$B$6) | C8: =IF(Produits!$A$6="","",Produits!$C$6) | D8: 2 | E8: 5 | F8: 5 | G8: 3 | H8: 3 | I8: 3 | P8: =IF(COUNT(E8,H8,K8,N8)=0,"",SUM(E8,H8,K8,N8)) | Q8: =IF(COUNT(F8,I8,L8,O8)=0,"",SUM(F8,I8,L8,O8)) | R8: =IF(OR(P8="",Q8=""),"",Q8-P8) | S8: =IF(M8<>"",M8,IF(J8<>"",J8,IF(G8<>"",G8,IF(D8<>"",D8,""))))
A9: =IF(Produits!$A$7="","",Produits!$A$7) | B9: =IF(Produits!$A$7="","",Produits!$B$7) | C9: =IF(Produits!$A$7="","",Produits!$C$7) | D9: 6 | E9: 10 | F9: 10 | G9: 7 | H9: 5 | I9: 5 | P9: =IF(COUNT(E9,H9,K9,N9)=0,"",SUM(E9,H9,K9,N9)) | Q9: =IF(COUNT(F9,I9,L9,O9)=0,"",SUM(F9,I9,L9,O9)) | R9: =IF(OR(P9="",Q9=""),"",Q9-P9) | S9: =IF(M9<>"",M9,IF(J9<>"",J9,IF(G9<>"",G9,IF(D9<>"",D9,""))))
A10: =IF(Produits!$A$8="","",Produits!$A$8) | B10: =IF(Produits!$A$8="","",Produits!$B$8) | C10: =IF(Produits!$A$8="","",Produits!$C$8) | D10: 1 | E10: 3 | F10: 3 | G10: 2 | H10: 0 | I10: 0 | P10: =IF(COUNT(E10,H10,K10,N10)=0,"",SUM(E10,H10,K10,N10)) | Q10: =IF(COUNT(F10,I10,L10,O10)=0,"",SUM(F10,I10,L10,O10)) | R10: =IF(OR(P10="",Q10=""),"",Q10-P10) | S10: =IF(M10<>"",M10,IF(J10<>"",J10,IF(G10<>"",G10,IF(D10<>"",D10,""))))
A11: =IF(Produits!$A$9="","",Produits!$A$9) | B11: =IF(Produits!$A$9="","",Produits!$B$9) | C11: =IF(Produits!$A$9="","",Produits!$C$9) | D11: 3 | E11: 5 | F11: 5 | G11: 4 | H11: 5 | I11: 5 | P11: =IF(COUNT(E11,H11,K11,N11)=0,"",SUM(E11,H11,K11,N11)) | Q11: =IF(COUNT(F11,I11,L11,O11)=0,"",SUM(F11,I11,L11,O11)) | R11: =IF(OR(P11="",Q11=""),"",Q11-P11) | S11: =IF(M11<>"",M11,IF(J11<>"",J11,IF(G11<>"",G11,IF(D11<>"",D11,""))))
A12: =IF(Produits!$A$10="","",Produits!$A$10) | B12: =IF(Produits!$A$10="","",Produits!$B$10) | C12: =IF(Produits!$A$10="","",Produits!$C$10) | D12: 4 | E12: 12 | F12: 12 | G12: 5 | H12: 10 | I12: 10 | P12: =IF(COUNT(E12,H12,K12,N12)=0,"",SUM(E12,H12,K12,N12)) | Q12: =IF(COUNT(F12,I12,L12,O12)=0,"",SUM(F12,I12,L12,O12)) | R12: =IF(OR(P12="",Q12=""),"",Q12-P12) | S12: =IF(M12<>"",M12,IF(J12<>"",J12,IF(G12<>"",G12,IF(D12<>"",D12,""))))
A13: =IF(Produits!$A$11="","",Produits!$A$11) | B13: =IF(Produits!$A$11="","",Produits!$B$11) | C13: =IF(Produits!$A$11="","",Produits!$C$11) | D13: 3 | E13: 6 | F13: 6 | G13: 4 | H13: 6 | I13: 6 | P13: =IF(COUNT(E13,H13,K13,N13)=0,"",SUM(E13,H13,K13,N13)) | Q13: =IF(COUNT(F13,I13,L13,O13)=0,"",SUM(F13,I13,L13,O13)) | R13: =IF(OR(P13="",Q13=""),"",Q13-P13) | S13: =IF(M13<>"",M13,IF(J13<>"",J13,IF(G13<>"",G13,IF(D13<>"",D13,""))))
A14: =IF(Produits!$A$12="","",Produits!$A$12) | B14: =IF(Produits!$A$12="","",Produits!$B$12) | C14: =IF(Produits!$A$12="","",Produits!$C$12) | D14: 40 | E14: 90 | F14: 90 | G14: 50 | H14: 60 | I14: 60 | P14: =IF(COUNT(E14,H14,K14,N14)=0,"",SUM(E14,H14,K14,N14)) | Q14: =IF(COUNT(F14,I14,L14,O14)=0,"",SUM(F14,I14,L14,O14)) | R14: =IF(OR(P14="",Q14=""),"",Q14-P14) | S14: =IF(M14<>"",M14,IF(J14<>"",J14,IF(G14<>"",G14,IF(D14<>"",D14,""))))
A15: =IF(Produits!$A$13="","",Produits!$A$13) | B15: =IF(Produits!$A$13="","",Produits!$B$13) | C15: =IF(Produits!$A$13="","",Produits!$C$13) | D15: 1.5 | E15: 3 | F15: 2 | G15: 2 | H15: 2 | I15: 2 | P15: =IF(COUNT(E15,H15,K15,N15)=0,"",SUM(E15,H15,K15,N15)) | Q15: =IF(COUNT(F15,I15,L15,O15)=0,"",SUM(F15,I15,L15,O15)) | R15: =IF(OR(P15="",Q15=""),"",Q15-P15) | S15: =IF(M15<>"",M15,IF(J15<>"",J15,IF(G15<>"",G15,IF(D15<>"",D15,""))))
A16: =IF(Produits!$A$14="","",Produits!$A$14) | B16: =IF(Produits!$A$14="","",Produits!$B$14) | C16: =IF(Produits!$A$14="","",Produits!$C$14) | D16: 2 | E16: 2 | F16: 2 | G16: 2 | H16: 2 | I16: 2 | P16: =IF(COUNT(E16,H16,K16,N16)=0,"",SUM(E16,H16,K16,N16)) | Q16: =IF(COUNT(F16,I16,L16,O16)=0,"",SUM(F16,I16,L16,O16)) | R16: =IF(OR(P16="",Q16=""),"",Q16-P16) | S16: =IF(M16<>"",M16,IF(J16<>"",J16,IF(G16<>"",G16,IF(D16<>"",D16,""))))
A17: =IF(Produits!$A$15="","",Produits!$A$15) | B17: =IF(Produits!$A$15="","",Produits!$B$15) | C17: =IF(Produits!$A$15="","",Produits!$C$15) | D17: 0.4 | E17: 1 | F17: 1 | G17: 0.6 | H17: 0 | I17: 0 | P17: =IF(COUNT(E17,H17,K17,N17)=0,"",SUM(E17,H17,K17,N17)) | Q17: =IF(COUNT(F17,I17,L17,O17)=0,"",SUM(F17,I17,L17,O17)) | R17: =IF(OR(P17="",Q17=""),"",Q17-P17) | S17: =IF(M17<>"",M17,IF(J17<>"",J17,IF(G17<>"",G17,IF(D17<>"",D17,""))))
A18: =IF(Produits!$A$16="","",Produits!$A$16) | B18: =IF(Produits!$A$16="","",Produits!$B$16) | C18: =IF(Produits!$A$16="","",Produits!$C$16) | D18: 6 | E18: 0 | F18: 0 | G18: 6 | H18: 0 | I18: 0 | P18: =IF(COUNT(E18,H18,K18,N18)=0,"",SUM(E18,H18,K18,N18)) | Q18: =IF(COUNT(F18,I18,L18,O18)=0,"",SUM(F18,I18,L18,O18)) | R18: =IF(OR(P18="",Q18=""),"",Q18-P18) | S18: =IF(M18<>"",M18,IF(J18<>"",J18,IF(G18<>"",G18,IF(D18<>"",D18,""))))
A19: =IF(Produits!$A$17="","",Produits!$A$17) | B19: =IF(Produits!$A$17="","",Produits!$B$17) | C19: =IF(Produits!$A$17="","",Produits!$C$17) | P19: =IF(COUNT(E19,H19,K19,N19)=0,"",SUM(E19,H19,K19,N19)) | Q19: =IF(COUNT(F19,I19,L19,O19)=0,"",SUM(F19,I19,L19,O19)) | R19: =IF(OR(P19="",Q19=""),"",Q19-P19) | S19: =IF(M19<>"",M19,IF(J19<>"",J19,IF(G19<>"",G19,IF(D19<>"",D19,""))))
A20: =IF(Produits!$A$18="","",Produits!$A$18) | B20: =IF(Produits!$A$18="","",Produits!$B$18) | C20: =IF(Produits!$A$18="","",Produits!$C$18) | P20: =IF(COUNT(E20,H20,K20,N20)=0,"",SUM(E20,H20,K20,N20)) | Q20: =IF(COUNT(F20,I20,L20,O20)=0,"",SUM(F20,I20,L20,O20)) | R20: =IF(OR(P20="",Q20=""),"",Q20-P20) | S20: =IF(M20<>"",M20,IF(J20<>"",J20,IF(G20<>"",G20,IF(D20<>"",D20,""))))
A21: =IF(Produits!$A$19="","",Produits!$A$19) | B21: =IF(Produits!$A$19="","",Produits!$B$19) | C21: =IF(Produits!$A$19="","",Produits!$C$19) | P21: =IF(COUNT(E21,H21,K21,N21)=0,"",SUM(E21,H21,K21,N21)) | Q21: =IF(COUNT(F21,I21,L21,O21)=0,"",SUM(F21,I21,L21,O21)) | R21: =IF(OR(P21="",Q21=""),"",Q21-P21) | S21: =IF(M21<>"",M21,IF(J21<>"",J21,IF(G21<>"",G21,IF(D21<>"",D21,""))))
A22: =IF(Produits!$A$20="","",Produits!$A$20) | B22: =IF(Produits!$A$20="","",Produits!$B$20) | C22: =IF(Produits!$A$20="","",Produits!$C$20) | P22: =IF(COUNT(E22,H22,K22,N22)=0,"",SUM(E22,H22,K22,N22)) | Q22: =IF(COUNT(F22,I22,L22,O22)=0,"",SUM(F22,I22,L22,O22)) | R22: =IF(OR(P22="",Q22=""),"",Q22-P22) | S22: =IF(M22<>"",M22,IF(J22<>"",J22,IF(G22<>"",G22,IF(D22<>"",D22,""))))
A23: =IF(Produits!$A$21="","",Produits!$A$21) | B23: =IF(Produits!$A$21="","",Produits!$B$21) | C23: =IF(Produits!$A$21="","",Produits!$C$21) | P23: =IF(COUNT(E23,H23,K23,N23)=0,"",SUM(E23,H23,K23,N23)) | Q23: =IF(COUNT(F23,I23,L23,O23)=0,"",SUM(F23,I23,L23,O23)) | R23: =IF(OR(P23="",Q23=""),"",Q23-P23) | S23: =IF(M23<>"",M23,IF(J23<>"",J23,IF(G23<>"",G23,IF(D23<>"",D23,""))))
A24: =IF(Produits!$A$22="","",Produits!$A$22) | B24: =IF(Produits!$A$22="","",Produits!$B$22) | C24: =IF(Produits!$A$22="","",Produits!$C$22) | P24: =IF(COUNT(E24,H24,K24,N24)=0,"",SUM(E24,H24,K24,N24)) | Q24: =IF(COUNT(F24,I24,L24,O24)=0,"",SUM(F24,I24,L24,O24)) | R24: =IF(OR(P24="",Q24=""),"",Q24-P24) | S24: =IF(M24<>"",M24,IF(J24<>"",J24,IF(G24<>"",G24,IF(D24<>"",D24,""))))
A25: =IF(Produits!$A$23="","",Produits!$A$23) | B25: =IF(Produits!$A$23="","",Produits!$B$23) | C25: =IF(Produits!$A$23="","",Produits!$C$23) | P25: =IF(COUNT(E25,H25,K25,N25)=0,"",SUM(E25,H25,K25,N25)) | Q25: =IF(COUNT(F25,I25,L25,O25)=0,"",SUM(F25,I25,L25,O25)) | R25: =IF(OR(P25="",Q25=""),"",Q25-P25) | S25: =IF(M25<>"",M25,IF(J25<>"",J25,IF(G25<>"",G25,IF(D25<>"",D25,""))))
A26: =IF(Produits!$A$24="","",Produits!$A$24) | B26: =IF(Produits!$A$24="","",Produits!$B$24) | C26: =IF(Produits!$A$24="","",Produits!$C$24) | P26: =IF(COUNT(E26,H26,K26,N26)=0,"",SUM(E26,H26,K26,N26)) | Q26: =IF(COUNT(F26,I26,L26,O26)=0,"",SUM(F26,I26,L26,O26)) | R26: =IF(OR(P26="",Q26=""),"",Q26-P26) | S26: =IF(M26<>"",M26,IF(J26<>"",J26,IF(G26<>"",G26,IF(D26<>"",D26,""))))
A27: =IF(Produits!$A$25="","",Produits!$A$25) | B27: =IF(Produits!$A$25="","",Produits!$B$25) | C27: =IF(Produits!$A$25="","",Produits!$C$25) | P27: =IF(COUNT(E27,H27,K27,N27)=0,"",SUM(E27,H27,K27,N27)) | Q27: =IF(COUNT(F27,I27,L27,O27)=0,"",SUM(F27,I27,L27,O27)) | R27: =IF(OR(P27="",Q27=""),"",Q27-P27) | S27: =IF(M27<>"",M27,IF(J27<>"",J27,IF(G27<>"",G27,IF(D27<>"",D27,""))))
A28: =IF(Produits!$A$26="","",Produits!$A$26) | B28: =IF(Produits!$A$26="","",Produits!$B$26) | C28: =IF(Produits!$A$26="","",Produits!$C$26) | P28: =IF(COUNT(E28,H28,K28,N28)=0,"",SUM(E28,H28,K28,N28)) | Q28: =IF(COUNT(F28,I28,L28,O28)=0,"",SUM(F28,I28,L28,O28)) | R28: =IF(OR(P28="",Q28=""),"",Q28-P28) | S28: =IF(M28<>"",M28,IF(J28<>"",J28,IF(G28<>"",G28,IF(D28<>"",D28,""))))
A29: =IF(Produits!$A$27="","",Produits!$A$27) | B29: =IF(Produits!$A$27="","",Produits!$B$27) | C29: =IF(Produits!$A$27="","",Produits!$C$27) | P29: =IF(COUNT(E29,H29,K29,N29)=0,"",SUM(E29,H29,K29,N29)) | Q29: =IF(COUNT(F29,I29,L29,O29)=0,"",SUM(F29,I29,L29,O29)) | R29: =IF(OR(P29="",Q29=""),"",Q29-P29) | S29: =IF(M29<>"",M29,IF(J29<>"",J29,IF(G29<>"",G29,IF(D29<>"",D29,""))))
A30: =IF(Produits!$A$28="","",Produits!$A$28) | B30: =IF(Produits!$A$28="","",Produits!$B$28) | C30: =IF(Produits!$A$28="","",Produits!$C$28) | P30: =IF(COUNT(E30,H30,K30,N30)=0,"",SUM(E30,H30,K30,N30)) | Q30: =IF(COUNT(F30,I30,L30,O30)=0,"",SUM(F30,I30,L30,O30)) | R30: =IF(OR(P30="",Q30=""),"",Q30-P30) | S30: =IF(M30<>"",M30,IF(J30<>"",J30,IF(G30<>"",G30,IF(D30<>"",D30,""))))
A31: =IF(Produits!$A$29="","",Produits!$A$29) | B31: =IF(Produits!$A$29="","",Produits!$B$29) | C31: =IF(Produits!$A$29="","",Produits!$C$29) | P31: =IF(COUNT(E31,H31,K31,N31)=0,"",SUM(E31,H31,K31,N31)) | Q31: =IF(COUNT(F31,I31,L31,O31)=0,"",SUM(F31,I31,L31,O31)) | R31: =IF(OR(P31="",Q31=""),"",Q31-P31) | S31: =IF(M31<>"",M31,IF(J31<>"",J31,IF(G31<>"",G31,IF(D31<>"",D31,""))))
A32: =IF(Produits!$A$30="","",Produits!$A$30) | B32: =IF(Produits!$A$30="","",Produits!$B$30) | C32: =IF(Produits!$A$30="","",Produits!$C$30) | P32: =IF(COUNT(E32,H32,K32,N32)=0,"",SUM(E32,H32,K32,N32)) | Q32: =IF(COUNT(F32,I32,L32,O32)=0,"",SUM(F32,I32,L32,O32)) | R32: =IF(OR(P32="",Q32=""),"",Q32-P32) | S32: =IF(M32<>"",M32,IF(J32<>"",J32,IF(G32<>"",G32,IF(D32<>"",D32,""))))
A33: =IF(Produits!$A$31="","",Produits!$A$31) | B33: =IF(Produits!$A$31="","",Produits!$B$31) | C33: =IF(Produits!$A$31="","",Produits!$C$31) | P33: =IF(COUNT(E33,H33,K33,N33)=0,"",SUM(E33,H33,K33,N33)) | Q33: =IF(COUNT(F33,I33,L33,O33)=0,"",SUM(F33,I33,L33,O33)) | R33: =IF(OR(P33="",Q33=""),"",Q33-P33) | S33: =IF(M33<>"",M33,IF(J33<>"",J33,IF(G33<>"",G33,IF(D33<>"",D33,""))))
A34: =IF(Produits!$A$32="","",Produits!$A$32) | B34: =IF(Produits!$A$32="","",Produits!$B$32) | C34: =IF(Produits!$A$32="","",Produits!$C$32) | P34: =IF(COUNT(E34,H34,K34,N34)=0,"",SUM(E34,H34,K34,N34)) | Q34: =IF(COUNT(F34,I34,L34,O34)=0,"",SUM(F34,I34,L34,O34)) | R34: =IF(OR(P34="",Q34=""),"",Q34-P34) | S34: =IF(M34<>"",M34,IF(J34<>"",J34,IF(G34<>"",G34,IF(D34<>"",D34,""))))
A35: =IF(Produits!$A$33="","",Produits!$A$33) | B35: =IF(Produits!$A$33="","",Produits!$B$33) | C35: =IF(Produits!$A$33="","",Produits!$C$33) | P35: =IF(COUNT(E35,H35,K35,N35)=0,"",SUM(E35,H35,K35,N35)) | Q35: =IF(COUNT(F35,I35,L35,O35)=0,"",SUM(F35,I35,L35,O35)) | R35: =IF(OR(P35="",Q35=""),"",Q35-P35) | S35: =IF(M35<>"",M35,IF(J35<>"",J35,IF(G35<>"",G35,IF(D35<>"",D35,""))))
A36: =IF(Produits!$A$34="","",Produits!$A$34) | B36: =IF(Produits!$A$34="","",Produits!$B$34) | C36: =IF(Produits!$A$34="","",Produits!$C$34) | P36: =IF(COUNT(E36,H36,K36,N36)=0,"",SUM(E36,H36,K36,N36)) | Q36: =IF(COUNT(F36,I36,L36,O36)=0,"",SUM(F36,I36,L36,O36)) | R36: =IF(OR(P36="",Q36=""),"",Q36-P36) | S36: =IF(M36<>"",M36,IF(J36<>"",J36,IF(G36<>"",G36,IF(D36<>"",D36,""))))
A37: =IF(Produits!$A$35="","",Produits!$A$35) | B37: =IF(Produits!$A$35="","",Produits!$B$35) | C37: =IF(Produits!$A$35="","",Produits!$C$35) | P37: =IF(COUNT(E37,H37,K37,N37)=0,"",SUM(E37,H37,K37,N37)) | Q37: =IF(COUNT(F37,I37,L37,O37)=0,"",SUM(F37,I37,L37,O37)) | R37: =IF(OR(P37="",Q37=""),"",Q37-P37) | S37: =IF(M37<>"",M37,IF(J37<>"",J37,IF(G37<>"",G37,IF(D37<>"",D37,""))))
A38: =IF(Produits!$A$36="","",Produits!$A$36) | B38: =IF(Produits!$A$36="","",Produits!$B$36) | C38: =IF(Produits!$A$36="","",Produits!$C$36) | P38: =IF(COUNT(E38,H38,K38,N38)=0,"",SUM(E38,H38,K38,N38)) | Q38: =IF(COUNT(F38,I38,L38,O38)=0,"",SUM(F38,I38,L38,O38)) | R38: =IF(OR(P38="",Q38=""),"",Q38-P38) | S38: =IF(M38<>"",M38,IF(J38<>"",J38,IF(G38<>"",G38,IF(D38<>"",D38,""))))
A39: =IF(Produits!$A$37="","",Produits!$A$37) | B39: =IF(Produits!$A$37="","",Produits!$B$37) | C39: =IF(Produits!$A$37="","",Produits!$C$37) | P39: =IF(COUNT(E39,H39,K39,N39)=0,"",SUM(E39,H39,K39,N39)) | Q39: =IF(COUNT(F39,I39,L39,O39)=0,"",SUM(F39,I39,L39,O39)) | R39: =IF(OR(P39="",Q39=""),"",Q39-P39) | S39: =IF(M39<>"",M39,IF(J39<>"",J39,IF(G39<>"",G39,IF(D39<>"",D39,""))))
A40: =IF(Produits!$A$38="","",Produits!$A$38) | B40: =IF(Produits!$A$38="","",Produits!$B$38) | C40: =IF(Produits!$A$38="","",Produits!$C$38) | P40: =IF(COUNT(E40,H40,K40,N40)=0,"",SUM(E40,H40,K40,N40)) | Q40: =IF(COUNT(F40,I40,L40,O40)=0,"",SUM(F40,I40,L40,O40)) | R40: =IF(OR(P40="",Q40=""),"",Q40-P40) | S40: =IF(M40<>"",M40,IF(J40<>"",J40,IF(G40<>"",G40,IF(D40<>"",D40,""))))
A41: =IF(Produits!$A$39="","",Produits!$A$39) | B41: =IF(Produits!$A$39="","",Produits!$B$39) | C41: =IF(Produits!$A$39="","",Produits!$C$39) | P41: =IF(COUNT(E41,H41,K41,N41)=0,"",SUM(E41,H41,K41,N41)) | Q41: =IF(COUNT(F41,I41,L41,O41)=0,"",SUM(F41,I41,L41,O41)) | R41: =IF(OR(P41="",Q41=""),"",Q41-P41) | S41: =IF(M41<>"",M41,IF(J41<>"",J41,IF(G41<>"",G41,IF(D41<>"",D41,""))))
A42: =IF(Produits!$A$40="","",Produits!$A$40) | B42: =IF(Produits!$A$40="","",Produits!$B$40) | C42: =IF(Produits!$A$40="","",Produits!$C$40) | P42: =IF(COUNT(E42,H42,K42,N42)=0,"",SUM(E42,H42,K42,N42)) | Q42: =IF(COUNT(F42,I42,L42,O42)=0,"",SUM(F42,I42,L42,O42)) | R42: =IF(OR(P42="",Q42=""),"",Q42-P42) | S42: =IF(M42<>"",M42,IF(J42<>"",J42,IF(G42<>"",G42,IF(D42<>"",D42,""))))
...
