Workbook

Sheet Mode d'emploi
A1: 15 · Les dates de péremption
A2: Proposition de tableau de gestion des stocks — Excel et Google Sheets
A4: L'idée | B4: Le suivi du stock habituel, plus un onglet pour les produits frais : à chaque livraison de crème, beurre, lait ou œufs, tu notes la date limite. Le fichier compte les jours restants et colore : rouge = périmé ou à utiliser aujourd'hui, orange = dans les 3 jours.
A6: Comment faire | B6: 1. Remplis l'onglet Produits une seule fois.
B7: 2. Chaque semaine : Stock, Commandé, Reçu dans l'onglet du mois, comme d'habitude.
B8: 3. À la livraison des produits frais : une ligne dans « Dates limites » avec la DLC écrite sur l'emballage.
B9: 4. Quand un lot est fini, choisis Oui dans « Terminé ? » : la ligne devient grise.
A11: Les onglets | B11: Produits — ta liste.
B12: Octobre 2026 — stock, commandé, reçu.
B13: Dates limites — les lots frais et leur DLC.
A15: Couleurs | B15: Cases jaunes = à remplir. Cases blanches = calculées toutes seules, ne pas y toucher.
B16: Chiffres en bleu = exemple pour montrer le fonctionnement, à effacer.
B17: Rouge = il manque quelque chose (livraison incomplète, stock trop bas).
A19: Google Sheets | B19: Fichier > Importer > Importer ce fichier. Tout fonctionne pareil, y compris sur téléphone.

Sheet Produits
A1: Mes produits
A2: Une ligne par produit. Tout le reste du fichier se remplit à partir de cette liste.
A4: Produit | B4: Fournisseur | C4: Unité
A5: Farine T55 | B5: Metro | C5: kg
A6: Farine T45 | B6: Metro | C6: kg
A7: Sucre semoule | B7: Metro | C7: kg
A8: Sucre glace | B8: Metro | C8: kg
A9: Beurre doux | B9: Crèmerie | C9: kg
A10: Crème liquide 35% | B10: Crèmerie | C10: L
A11: Lait entier | B11: Crèmerie | C11: L
A12: Oeufs | B12: Crèmerie | C12: pièce
A13: Chocolat blanc | B13: Transgourmet | C13: kg
A14: Chocolat noir 70% | B14: Transgourmet | C14: kg
A15: Levure chimique | B15: Transgourmet | C15: kg
A16: Vanille (gousse) | B16: Transgourmet | C16: pièce

Sheet Octobre 2026
A1: Octobre 2026
A2: Stock = ce qu'il reste · Commandé = ce que tu demandes · Reçu = ce qui est arrivé
A4: Produit | B4: Fournisseur | C4: Unité | D4: Semaine 1 | G4: Semaine 2 | J4: Semaine 3 | M4: Semaine 4 | P4: Total du mois
D6: Stock | E6: Commandé | F6: Reçu | G6: Stock | H6: Commandé | I6: Reçu | J6: Stock | K6: Commandé | L6: Reçu | M6: Stock | N6: Commandé | O6: Reçu | P6: Commandé | Q6: Reçu | R6: Écart | S6: Dernier stock
A7: =IF(Produits!$A$5="","",Produits!$A$5) | B7: =IF(Produits!$A$5="","",Produits!$B$5) | C7: =IF(Produits!$A$5="","",Produits!$C$5) | D7: 8 | E7: 10 | F7: 7 | G7: 5 | H7: 10 | I7: 10 | P7: =IF(COUNT(E7,H7,K7,N7)=0,"",SUM(E7,H7,K7,N7)) | Q7: =IF(COUNT(F7,I7,L7,O7)=0,"",SUM(F7,I7,L7,O7)) | R7: =IF(OR(P7="",Q7=""),"",Q7-P7) | S7: =IF(M7<>"",M7,IF(J7<>"",J7,IF(G7<>"",G7,IF(D7<>"",D7,""))))
A8: =IF(Produits!$A$6="","",Produits!$A$6) | B8: =IF(Produits!$A$6="","",Produits!$B$6) | C8: =IF(Produits!$A$6="","",Produits!$C$6) | D8: 2 | E8: 5 | F8: 5 | G8: 3 | H8: 3 | I8: 3 | P8: =IF(COUNT(E8,H8,K8,N8)=0,"",SUM(E8,H8,K8,N8)) | Q8: =IF(COUNT(F8,I8,L8,O8)=0,"",SUM(F8,I8,L8,O8)) | R8: =IF(OR(P8="",Q8=""),"",Q8-P8) | S8: =IF(M8<>"",M8,IF(J8<>"",J8,IF(G8<>"",G8,IF(D8<>"",D8,""))))
A9: =IF(Produits!$A$7="","",Produits!$A$7) | B9: =IF(Produits!$A$7="","",Produits!$B$7) | C9: =IF(Produits!$A$7="","",Produits!$C$7) | D9: 6 | E9: 10 | F9: 10 | G9: 7 | H9: 5 | I9: 5 | P9: =IF(COUNT(E9,H9,K9,N9)=0,"",SUM(E9,H9,K9,N9)) | Q9: =IF(COUNT(F9,I9,L9,O9)=0,"",SUM(F9,I9,L9,O9)) | R9: =IF(OR(P9="",Q9=""),"",Q9-P9) | S9: =IF(M9<>"",M9,IF(J9<>"",J9,IF(G9<>"",G9,IF(D9<>"",D9,""))))
A10: =IF(Produits!$A$8="","",Produits!$A$8) | B10: =IF(Produits!$A$8="","",Produits!$B$8) | C10: =IF(Produits!$A$8="","",Produits!$C$8) | D10: 1 | E10: 3 | F10: 3 | G10: 2 | H10: 0 | I10: 0 | P10: =IF(COUNT(E10,H10,K10,N10)=0,"",SUM(E10,H10,K10,N10)) | Q10: =IF(COUNT(F10,I10,L10,O10)=0,"",SUM(F10,I10,L10,O10)) | R10: =IF(OR(P10="",Q10=""),"",Q10-P10) | S10: =IF(M10<>"",M10,IF(J10<>"",J10,IF(G10<>"",G10,IF(D10<>"",D10,""))))
A11: =IF(Produits!$A$9="","",Produits!$A$9) | B11: =IF(Produits!$A$9="","",Produits!$B$9) | C11: =IF(Produits!$A$9="","",Produits!$C$9) | D11: 3 | E11: 5 | F11: 5 | G11: 4 | H11: 5 | I11: 5 | P11: =IF(COUNT(E11,H11,K11,N11)=0,"",SUM(E11,H11,K11,N11)) | Q11: =IF(COUNT(F11,I11,L11,O11)=0,"",SUM(F11,I11,L11,O11)) | R11: =IF(OR(P11="",Q11=""),"",Q11-P11) | S11: =IF(M11<>"",M11,IF(J11<>"",J11,IF(G11<>"",G11,IF(D11<>"",D11,""))))
A12: =IF(Produits!$A$10="","",Produits!$A$10) | B12: =IF(Produits!$A$10="","",Produits!$B$10) | C12: =IF(Produits!$A$10="","",Produits!$C$10) | D12: 4 | E12: 12 | F12: 12 | G12: 5 | H12: 10 | I12: 10 | P12: =IF(COUNT(E12,H12,K12,N12)=0,"",SUM(E12,H12,K12,N12)) | Q12: =IF(COUNT(F12,I12,L12,O12)=0,"",SUM(F12,I12,L12,O12)) | R12: =IF(OR(P12="",Q12=""),"",Q12-P12) | S12: =IF(M12<>"",M12,IF(J12<>"",J12,IF(G12<>"",G12,IF(D12<>"",D12,""))))
A13: =IF(Produits!$A$11="","",Produits!$A$11) | B13: =IF(Produits!$A$11="","",Produits!$B$11) | C13: =IF(Produits!$A$11="","",Produits!$C$11) | D13: 3 | E13: 6 | F13: 6 | G13: 4 | H13: 6 | I13: 6 | P13: =IF(COUNT(E13,H13,K13,N13)=0,"",SUM(E13,H13,K13,N13)) | Q13: =IF(COUNT(F13,I13,L13,O13)=0,"",SUM(F13,I13,L13,O13)) | R13: =IF(OR(P13="",Q13=""),"",Q13-P13) | S13: =IF(M13<>"",M13,IF(J13<>"",J13,IF(G13<>"",G13,IF(D13<>"",D13,""))))
A14: =IF(Produits!$A$12="","",Produits!$A$12) | B14: =IF(Produits!$A$12="","",Produits!$B$12) | C14: =IF(Produits!$A$12="","",Produits!$C$12) | D14: 40 | E14: 90 | F14: 90 | G14: 50 | H14: 60 | I14: 60 | P14: =IF(COUNT(E14,H14,K14,N14)=0,"",SUM(E14,H14,K14,N14)) | Q14: =IF(COUNT(F14,I14,L14,O14)=0,"",SUM(F14,I14,L14,O14)) | R14: =IF(OR(P14="",Q14=""),"",Q14-P14) | S14: =IF(M14<>"",M14,IF(J14<>"",J14,IF(G14<>"",G14,IF(D14<>"",D14,""))))
A15: =IF(Produits!$A$13="","",Produits!$A$13) | B15: =IF(Produits!$A$13="","",Produits!$B$13) | C15: =IF(Produits!$A$13="","",Produits!$C$13) | D15: 1.5 | E15: 3 | F15: 2 | G15: 2 | H15: 2 | I15: 2 | P15: =IF(COUNT(E15,H15,K15,N15)=0,"",SUM(E15,H15,K15,N15)) | Q15: =IF(COUNT(F15,I15,L15,O15)=0,"",SUM(F15,I15,L15,O15)) | R15: =IF(OR(P15="",Q15=""),"",Q15-P15) | S15: =IF(M15<>"",M15,IF(J15<>"",J15,IF(G15<>"",G15,IF(D15<>"",D15,""))))
A16: =IF(Produits!$A$14="","",Produits!$A$14) | B16: =IF(Produits!$A$14="","",Produits!$B$14) | C16: =IF(Produits!$A$14="","",Produits!$C$14) | D16: 2 | E16: 2 | F16: 2 | G16: 2 | H16: 2 | I16: 2 | P16: =IF(COUNT(E16,H16,K16,N16)=0,"",SUM(E16,H16,K16,N16)) | Q16: =IF(COUNT(F16,I16,L16,O16)=0,"",SUM(F16,I16,L16,O16)) | R16: =IF(OR(P16="",Q16=""),"",Q16-P16) | S16: =IF(M16<>"",M16,IF(J16<>"",J16,IF(G16<>"",G16,IF(D16<>"",D16,""))))
A17: =IF(Produits!$A$15="","",Produits!$A$15) | B17: =IF(Produits!$A$15="","",Produits!$B$15) | C17: =IF(Produits!$A$15="","",Produits!$C$15) | D17: 0.4 | E17: 1 | F17: 1 | G17: 0.6 | H17: 0 | I17: 0 | P17: =IF(COUNT(E17,H17,K17,N17)=0,"",SUM(E17,H17,K17,N17)) | Q17: =IF(COUNT(F17,I17,L17,O17)=0,"",SUM(F17,I17,L17,O17)) | R17: =IF(OR(P17="",Q17=""),"",Q17-P17) | S17: =IF(M17<>"",M17,IF(J17<>"",J17,IF(G17<>"",G17,IF(D17<>"",D17,""))))
A18: =IF(Produits!$A$16="","",Produits!$A$16) | B18: =IF(Produits!$A$16="","",Produits!$B$16) | C18: =IF(Produits!$A$16="","",Produits!$C$16) | D18: 6 | E18: 0 | F18: 0 | G18: 6 | H18: 0 | I18: 0 | P18: =IF(COUNT(E18,H18,K18,N18)=0,"",SUM(E18,H18,K18,N18)) | Q18: =IF(COUNT(F18,I18,L18,O18)=0,"",SUM(F18,I18,L18,O18)) | R18: =IF(OR(P18="",Q18=""),"",Q18-P18) | S18: =IF(M18<>"",M18,IF(J18<>"",J18,IF(G18<>"",G18,IF(D18<>"",D18,""))))
A19: =IF(Produits!$A$17="","",Produits!$A$17) | B19: =IF(Produits!$A$17="","",Produits!$B$17) | C19: =IF(Produits!$A$17="","",Produits!$C$17) | P19: =IF(COUNT(E19,H19,K19,N19)=0,"",SUM(E19,H19,K19,N19)) | Q19: =IF(COUNT(F19,I19,L19,O19)=0,"",SUM(F19,I19,L19,O19)) | R19: =IF(OR(P19="",Q19=""),"",Q19-P19) | S19: =IF(M19<>"",M19,IF(J19<>"",J19,IF(G19<>"",G19,IF(D19<>"",D19,""))))
A20: =IF(Produits!$A$18="","",Produits!$A$18) | B20: =IF(Produits!$A$18="","",Produits!$B$18) | C20: =IF(Produits!$A$18="","",Produits!$C$18) | P20: =IF(COUNT(E20,H20,K20,N20)=0,"",SUM(E20,H20,K20,N20)) | Q20: =IF(COUNT(F20,I20,L20,O20)=0,"",SUM(F20,I20,L20,O20)) | R20: =IF(OR(P20="",Q20=""),"",Q20-P20) | S20: =IF(M20<>"",M20,IF(J20<>"",J20,IF(G20<>"",G20,IF(D20<>"",D20,""))))
A21: =IF(Produits!$A$19="","",Produits!$A$19) | B21: =IF(Produits!$A$19="","",Produits!$B$19) | C21: =IF(Produits!$A$19="","",Produits!$C$19) | P21: =IF(COUNT(E21,H21,K21,N21)=0,"",SUM(E21,H21,K21,N21)) | Q21: =IF(COUNT(F21,I21,L21,O21)=0,"",SUM(F21,I21,L21,O21)) | R21: =IF(OR(P21="",Q21=""),"",Q21-P21) | S21: =IF(M21<>"",M21,IF(J21<>"",J21,IF(G21<>"",G21,IF(D21<>"",D21,""))))
A22: =IF(Produits!$A$20="","",Produits!$A$20) | B22: =IF(Produits!$A$20="","",Produits!$B$20) | C22: =IF(Produits!$A$20="","",Produits!$C$20) | P22: =IF(COUNT(E22,H22,K22,N22)=0,"",SUM(E22,H22,K22,N22)) | Q22: =IF(COUNT(F22,I22,L22,O22)=0,"",SUM(F22,I22,L22,O22)) | R22: =IF(OR(P22="",Q22=""),"",Q22-P22) | S22: =IF(M22<>"",M22,IF(J22<>"",J22,IF(G22<>"",G22,IF(D22<>"",D22,""))))
A23: =IF(Produits!$A$21="","",Produits!$A$21) | B23: =IF(Produits!$A$21="","",Produits!$B$21) | C23: =IF(Produits!$A$21="","",Produits!$C$21) | P23: =IF(COUNT(E23,H23,K23,N23)=0,"",SUM(E23,H23,K23,N23)) | Q23: =IF(COUNT(F23,I23,L23,O23)=0,"",SUM(F23,I23,L23,O23)) | R23: =IF(OR(P23="",Q23=""),"",Q23-P23) | S23: =IF(M23<>"",M23,IF(J23<>"",J23,IF(G23<>"",G23,IF(D23<>"",D23,""))))
A24: =IF(Produits!$A$22="","",Produits!$A$22) | B24: =IF(Produits!$A$22="","",Produits!$B$22) | C24: =IF(Produits!$A$22="","",Produits!$C$22) | P24: =IF(COUNT(E24,H24,K24,N24)=0,"",SUM(E24,H24,K24,N24)) | Q24: =IF(COUNT(F24,I24,L24,O24)=0,"",SUM(F24,I24,L24,O24)) | R24: =IF(OR(P24="",Q24=""),"",Q24-P24) | S24: =IF(M24<>"",M24,IF(J24<>"",J24,IF(G24<>"",G24,IF(D24<>"",D24,""))))
A25: =IF(Produits!$A$23="","",Produits!$A$23) | B25: =IF(Produits!$A$23="","",Produits!$B$23) | C25: =IF(Produits!$A$23="","",Produits!$C$23) | P25: =IF(COUNT(E25,H25,K25,N25)=0,"",SUM(E25,H25,K25,N25)) | Q25: =IF(COUNT(F25,I25,L25,O25)=0,"",SUM(F25,I25,L25,O25)) | R25: =IF(OR(P25="",Q25=""),"",Q25-P25) | S25: =IF(M25<>"",M25,IF(J25<>"",J25,IF(G25<>"",G25,IF(D25<>"",D25,""))))
A26: =IF(Produits!$A$24="","",Produits!$A$24) | B26: =IF(Produits!$A$24="","",Produits!$B$24) | C26: =IF(Produits!$A$24="","",Produits!$C$24) | P26: =IF(COUNT(E26,H26,K26,N26)=0,"",SUM(E26,H26,K26,N26)) | Q26: =IF(COUNT(F26,I26,L26,O26)=0,"",SUM(F26,I26,L26,O26)) | R26: =IF(OR(P26="",Q26=""),"",Q26-P26) | S26: =IF(M26<>"",M26,IF(J26<>"",J26,IF(G26<>"",G26,IF(D26<>"",D26,""))))
A27: =IF(Produits!$A$25="","",Produits!$A$25) | B27: =IF(Produits!$A$25="","",Produits!$B$25) | C27: =IF(Produits!$A$25="","",Produits!$C$25) | P27: =IF(COUNT(E27,H27,K27,N27)=0,"",SUM(E27,H27,K27,N27)) | Q27: =IF(COUNT(F27,I27,L27,O27)=0,"",SUM(F27,I27,L27,O27)) | R27: =IF(OR(P27="",Q27=""),"",Q27-P27) | S27: =IF(M27<>"",M27,IF(J27<>"",J27,IF(G27<>"",G27,IF(D27<>"",D27,""))))
A28: =IF(Produits!$A$26="","",Produits!$A$26) | B28: =IF(Produits!$A$26="","",Produits!$B$26) | C28: =IF(Produits!$A$26="","",Produits!$C$26) | P28: =IF(COUNT(E28,H28,K28,N28)=0,"",SUM(E28,H28,K28,N28)) | Q28: =IF(COUNT(F28,I28,L28,O28)=0,"",SUM(F28,I28,L28,O28)) | R28: =IF(OR(P28="",Q28=""),"",Q28-P28) | S28: =IF(M28<>"",M28,IF(J28<>"",J28,IF(G28<>"",G28,IF(D28<>"",D28,""))))
A29: =IF(Produits!$A$27="","",Produits!$A$27) | B29: =IF(Produits!$A$27="","",Produits!$B$27) | C29: =IF(Produits!$A$27="","",Produits!$C$27) | P29: =IF(COUNT(E29,H29,K29,N29)=0,"",SUM(E29,H29,K29,N29)) | Q29: =IF(COUNT(F29,I29,L29,O29)=0,"",SUM(F29,I29,L29,O29)) | R29: =IF(OR(P29="",Q29=""),"",Q29-P29) | S29: =IF(M29<>"",M29,IF(J29<>"",J29,IF(G29<>"",G29,IF(D29<>"",D29,""))))
A30: =IF(Produits!$A$28="","",Produits!$A$28) | B30: =IF(Produits!$A$28="","",Produits!$B$28) | C30: =IF(Produits!$A$28="","",Produits!$C$28) | P30: =IF(COUNT(E30,H30,K30,N30)=0,"",SUM(E30,H30,K30,N30)) | Q30: =IF(COUNT(F30,I30,L30,O30)=0,"",SUM(F30,I30,L30,O30)) | R30: =IF(OR(P30="",Q30=""),"",Q30-P30) | S30: =IF(M30<>"",M30,IF(J30<>"",J30,IF(G30<>"",G30,IF(D30<>"",D30,""))))
A31: =IF(Produits!$A$29="","",Produits!$A$29) | B31: =IF(Produits!$A$29="","",Produits!$B$29) | C31: =IF(Produits!$A$29="","",Produits!$C$29) | P31: =IF(COUNT(E31,H31,K31,N31)=0,"",SUM(E31,H31,K31,N31)) | Q31: =IF(COUNT(F31,I31,L31,O31)=0,"",SUM(F31,I31,L31,O31)) | R31: =IF(OR(P31="",Q31=""),"",Q31-P31) | S31: =IF(M31<>"",M31,IF(J31<>"",J31,IF(G31<>"",G31,IF(D31<>"",D31,""))))
A32: =IF(Produits!$A$30="","",Produits!$A$30) | B32: =IF(Produits!$A$30="","",Produits!$B$30) | C32: =IF(Produits!$A$30="","",Produits!$C$30) | P32: =IF(COUNT(E32,H32,K32,N32)=0,"",SUM(E32,H32,K32,N32)) | Q32: =IF(COUNT(F32,I32,L32,O32)=0,"",SUM(F32,I32,L32,O32)) | R32: =IF(OR(P32="",Q32=""),"",Q32-P32) | S32: =IF(M32<>"",M32,IF(J32<>"",J32,IF(G32<>"",G32,IF(D32<>"",D32,""))))
A33: =IF(Produits!$A$31="","",Produits!$A$31) | B33: =IF(Produits!$A$31="","",Produits!$B$31) | C33: =IF(Produits!$A$31="","",Produits!$C$31) | P33: =IF(COUNT(E33,H33,K33,N33)=0,"",SUM(E33,H33,K33,N33)) | Q33: =IF(COUNT(F33,I33,L33,O33)=0,"",SUM(F33,I33,L33,O33)) | R33: =IF(OR(P33="",Q33=""),"",Q33-P33) | S33: =IF(M33<>"",M33,IF(J33<>"",J33,IF(G33<>"",G33,IF(D33<>"",D33,""))))
A34: =IF(Produits!$A$32="","",Produits!$A$32) | B34: =IF(Produits!$A$32="","",Produits!$B$32) | C34: =IF(Produits!$A$32="","",Produits!$C$32) | P34: =IF(COUNT(E34,H34,K34,N34)=0,"",SUM(E34,H34,K34,N34)) | Q34: =IF(COUNT(F34,I34,L34,O34)=0,"",SUM(F34,I34,L34,O34)) | R34: =IF(OR(P34="",Q34=""),"",Q34-P34) | S34: =IF(M34<>"",M34,IF(J34<>"",J34,IF(G34<>"",G34,IF(D34<>"",D34,""))))
A35: =IF(Produits!$A$33="","",Produits!$A$33) | B35: =IF(Produits!$A$33="","",Produits!$B$33) | C35: =IF(Produits!$A$33="","",Produits!$C$33) | P35: =IF(COUNT(E35,H35,K35,N35)=0,"",SUM(E35,H35,K35,N35)) | Q35: =IF(COUNT(F35,I35,L35,O35)=0,"",SUM(F35,I35,L35,O35)) | R35: =IF(OR(P35="",Q35=""),"",Q35-P35) | S35: =IF(M35<>"",M35,IF(J35<>"",J35,IF(G35<>"",G35,IF(D35<>"",D35,""))))
A36: =IF(Produits!$A$34="","",Produits!$A$34) | B36: =IF(Produits!$A$34="","",Produits!$B$34) | C36: =IF(Produits!$A$34="","",Produits!$C$34) | P36: =IF(COUNT(E36,H36,K36,N36)=0,"",SUM(E36,H36,K36,N36)) | Q36: =IF(COUNT(F36,I36,L36,O36)=0,"",SUM(F36,I36,L36,O36)) | R36: =IF(OR(P36="",Q36=""),"",Q36-P36) | S36: =IF(M36<>"",M36,IF(J36<>"",J36,IF(G36<>"",G36,IF(D36<>"",D36,""))))
A37: =IF(Produits!$A$35="","",Produits!$A$35) | B37: =IF(Produits!$A$35="","",Produits!$B$35) | C37: =IF(Produits!$A$35="","",Produits!$C$35) | P37: =IF(COUNT(E37,H37,K37,N37)=0,"",SUM(E37,H37,K37,N37)) | Q37: =IF(COUNT(F37,I37,L37,O37)=0,"",SUM(F37,I37,L37,O37)) | R37: =IF(OR(P37="",Q37=""),"",Q37-P37) | S37: =IF(M37<>"",M37,IF(J37<>"",J37,IF(G37<>"",G37,IF(D37<>"",D37,""))))
A38: =IF(Produits!$A$36="","",Produits!$A$36) | B38: =IF(Produits!$A$36="","",Produits!$B$36) | C38: =IF(Produits!$A$36="","",Produits!$C$36) | P38: =IF(COUNT(E38,H38,K38,N38)=0,"",SUM(E38,H38,K38,N38)) | Q38: =IF(COUNT(F38,I38,L38,O38)=0,"",SUM(F38,I38,L38,O38)) | R38: =IF(OR(P38="",Q38=""),"",Q38-P38) | S38: =IF(M38<>"",M38,IF(J38<>"",J38,IF(G38<>"",G38,IF(D38<>"",D38,""))))
A39: =IF(Produits!$A$37="","",Produits!$A$37) | B39: =IF(Produits!$A$37="","",Produits!$B$37) | C39: =IF(Produits!$A$37="","",Produits!$C$37) | P39: =IF(COUNT(E39,H39,K39,N39)=0,"",SUM(E39,H39,K39,N39)) | Q39: =IF(COUNT(F39,I39,L39,O39)=0,"",SUM(F39,I39,L39,O39)) | R39: =IF(OR(P39="",Q39=""),"",Q39-P39) | S39: =IF(M39<>"",M39,IF(J39<>"",J39,IF(G39<>"",G39,IF(D39<>"",D39,""))))
A40: =IF(Produits!$A$38="","",Produits!$A$38) | B40: =IF(Produits!$A$38="","",Produits!$B$38) | C40: =IF(Produits!$A$38="","",Produits!$C$38) | P40: =IF(COUNT(E40,H40,K40,N40)=0,"",SUM(E40,H40,K40,N40)) | Q40: =IF(COUNT(F40,I40,L40,O40)=0,"",SUM(F40,I40,L40,O40)) | R40: =IF(OR(P40="",Q40=""),"",Q40-P40) | S40: =IF(M40<>"",M40,IF(J40<>"",J40,IF(G40<>"",G40,IF(D40<>"",D40,""))))
A41: =IF(Produits!$A$39="","",Produits!$A$39) | B41: =IF(Produits!$A$39="","",Produits!$B$39) | C41: =IF(Produits!$A$39="","",Produits!$C$39) | P41: =IF(COUNT(E41,H41,K41,N41)=0,"",SUM(E41,H41,K41,N41)) | Q41: =IF(COUNT(F41,I41,L41,O41)=0,"",SUM(F41,I41,L41,O41)) | R41: =IF(OR(P41="",Q41=""),"",Q41-P41) | S41: =IF(M41<>"",M41,IF(J41<>"",J41,IF(G41<>"",G41,IF(D41<>"",D41,""))))
A42: =IF(Produits!$A$40="","",Produits!$A$40) | B42: =IF(Produits!$A$40="","",Produits!$B$40) | C42: =IF(Produits!$A$40="","",Produits!$C$40) | P42: =IF(COUNT(E42,H42,K42,N42)=0,"",SUM(E42,H42,K42,N42)) | Q42: =IF(COUNT(F42,I42,L42,O42)=0,"",SUM(F42,I42,L42,O42)) | R42: =IF(OR(P42="",Q42=""),"",Q42-P42) | S42: =IF(M42<>"",M42,IF(J42<>"",J42,IF(G42<>"",G42,IF(D42<>"",D42,""))))
...

Sheet Dates limites
A1: Dates limites (DLC)
A2: Jours restants calculés à partir de la date du jour
A4: Reçu le | B4: Produit | C4: Quantité | D4: DLC | E4: Jours restants | F4: État | G4: Terminé ?
A5: =TODAY()-3 | B5: Crème liquide 35% | C5: 6 | D5: =TODAY()+1 | E5: =IF(D5="","",D5-TODAY()) | F5: =IF(E5="","",IF(G5="Oui","Terminé",IF(E5<0,"PÉRIMÉ",IF(E5<=1,"AUJOURD'HUI",IF(E5<=3,"BIENTÔT","OK"))))) | G5: Non
A6: =TODAY()-3 | B6: Oeufs | C6: 90 | D6: =TODAY()+12 | E6: =IF(D6="","",D6-TODAY()) | F6: =IF(E6="","",IF(G6="Oui","Terminé",IF(E6<0,"PÉRIMÉ",IF(E6<=1,"AUJOURD'HUI",IF(E6<=3,"BIENTÔT","OK"))))) | G6: Non
A7: =TODAY()-3 | B7: Lait entier | C7: 6 | D7: =TODAY()+3 | E7: =IF(D7="","",D7-TODAY()) | F7: =IF(E7="","",IF(G7="Oui","Terminé",IF(E7<0,"PÉRIMÉ",IF(E7<=1,"AUJOURD'HUI",IF(E7<=3,"BIENTÔT","OK"))))) | G7: Non
A8: =TODAY()-3 | B8: Beurre doux | C8: 5 | D8: =TODAY()+20 | E8: =IF(D8="","",D8-TODAY()) | F8: =IF(E8="","",IF(G8="Oui","Terminé",IF(E8<0,"PÉRIMÉ",IF(E8<=1,"AUJOURD'HUI",IF(E8<=3,"BIENTÔT","OK"))))) | G8: Non
A9: =TODAY()-10 | B9: Crème liquide 35% | C9: 6 | D9: =TODAY()-2 | E9: =IF(D9="","",D9-TODAY()) | F9: =IF(E9="","",IF(G9="Oui","Terminé",IF(E9<0,"PÉRIMÉ",IF(E9<=1,"AUJOURD'HUI",IF(E9<=3,"BIENTÔT","OK"))))) | G9: Oui
E10: =IF(D10="","",D10-TODAY()) | F10: =IF(E10="","",IF(G10="Oui","Terminé",IF(E10<0,"PÉRIMÉ",IF(E10<=1,"AUJOURD'HUI",IF(E10<=3,"BIENTÔT","OK")))))
E11: =IF(D11="","",D11-TODAY()) | F11: =IF(E11="","",IF(G11="Oui","Terminé",IF(E11<0,"PÉRIMÉ",IF(E11<=1,"AUJOURD'HUI",IF(E11<=3,"BIENTÔT","OK")))))
E12: =IF(D12="","",D12-TODAY()) | F12: =IF(E12="","",IF(G12="Oui","Terminé",IF(E12<0,"PÉRIMÉ",IF(E12<=1,"AUJOURD'HUI",IF(E12<=3,"BIENTÔT","OK")))))
E13: =IF(D13="","",D13-TODAY()) | F13: =IF(E13="","",IF(G13="Oui","Terminé",IF(E13<0,"PÉRIMÉ",IF(E13<=1,"AUJOURD'HUI",IF(E13<=3,"BIENTÔT","OK")))))
E14: =IF(D14="","",D14-TODAY()) | F14: =IF(E14="","",IF(G14="Oui","Terminé",IF(E14<0,"PÉRIMÉ",IF(E14<=1,"AUJOURD'HUI",IF(E14<=3,"BIENTÔT","OK")))))
E15: =IF(D15="","",D15-TODAY()) | F15: =IF(E15="","",IF(G15="Oui","Terminé",IF(E15<0,"PÉRIMÉ",IF(E15<=1,"AUJOURD'HUI",IF(E15<=3,"BIENTÔT","OK")))))
E16: =IF(D16="","",D16-TODAY()) | F16: =IF(E16="","",IF(G16="Oui","Terminé",IF(E16<0,"PÉRIMÉ",IF(E16<=1,"AUJOURD'HUI",IF(E16<=3,"BIENTÔT","OK")))))
E17: =IF(D17="","",D17-TODAY()) | F17: =IF(E17="","",IF(G17="Oui","Terminé",IF(E17<0,"PÉRIMÉ",IF(E17<=1,"AUJOURD'HUI",IF(E17<=3,"BIENTÔT","OK")))))
E18: =IF(D18="","",D18-TODAY()) | F18: =IF(E18="","",IF(G18="Oui","Terminé",IF(E18<0,"PÉRIMÉ",IF(E18<=1,"AUJOURD'HUI",IF(E18<=3,"BIENTÔT","OK")))))
E19: =IF(D19="","",D19-TODAY()) | F19: =IF(E19="","",IF(G19="Oui","Terminé",IF(E19<0,"PÉRIMÉ",IF(E19<=1,"AUJOURD'HUI",IF(E19<=3,"BIENTÔT","OK")))))
E20: =IF(D20="","",D20-TODAY()) | F20: =IF(E20="","",IF(G20="Oui","Terminé",IF(E20<0,"PÉRIMÉ",IF(E20<=1,"AUJOURD'HUI",IF(E20<=3,"BIENTÔT","OK")))))
E21: =IF(D21="","",D21-TODAY()) | F21: =IF(E21="","",IF(G21="Oui","Terminé",IF(E21<0,"PÉRIMÉ",IF(E21<=1,"AUJOURD'HUI",IF(E21<=3,"BIENTÔT","OK")))))
... E84: =IF(D84="","",D84-TODAY()) | F84: =IF(E84="","",IF(G84="Oui","Terminé",IF(E84<0,"PÉRIMÉ",IF(E84<=1,"AUJOURD'HUI",IF(E84<=3,"BIENTÔT","OK")))))
