Workbook

Sheet Mode d'emploi
A1: 20 · Le suivi par étiquettes
A2: Proposition de tableau de gestion des stocks — Excel et Google Sheets
A4: L'idée | B4: Chaque produit a une étiquette de couleur par semaine qui dit où il en est : À commander, Commandé, Livré, Manquant, Rien à commander. En haut, un compteur t'indique combien de produits restent à traiter cette semaine. Comme un tableau de suivi, mais dans ton tableur.
A6: Comment faire | B6: 1. Remplis l'onglet Produits une seule fois.
B7: 2. Vendredi : Stock, puis choisis l'étiquette (À commander, puis Commandé une fois la commande passée).
B8: 3. Livraison : Reçu, puis l'étiquette Livré ou Manquant.
B9: 4. Le compteur « À traiter » en haut de chaque semaine doit tomber à 0.
A11: Les onglets | B11: Produits — ta liste.
B12: Octobre 2026 — stock, commandé, reçu et étiquette pour chaque semaine.
A14: Couleurs | B14: Cases jaunes = à remplir. Cases blanches = calculées toutes seules, ne pas y toucher.
B15: Chiffres en bleu = exemple pour montrer le fonctionnement, à effacer.
B16: Rouge = il manque quelque chose (livraison incomplète, stock trop bas).
A18: Google Sheets | B18: Fichier > Importer > Importer ce fichier. Tout fonctionne pareil, y compris sur téléphone.

Sheet Produits
A1: Mes produits
A2: Une ligne par produit. Tout le reste du fichier se remplit à partir de cette liste.
A4: Produit | B4: Fournisseur | C4: Unité
A5: Farine T55 | B5: Metro | C5: kg
A6: Farine T45 | B6: Metro | C6: kg
A7: Sucre semoule | B7: Metro | C7: kg
A8: Sucre glace | B8: Metro | C8: kg
A9: Beurre doux | B9: Crèmerie | C9: kg
A10: Crème liquide 35% | B10: Crèmerie | C10: L
A11: Lait entier | B11: Crèmerie | C11: L
A12: Oeufs | B12: Crèmerie | C12: pièce
A13: Chocolat blanc | B13: Transgourmet | C13: kg
A14: Chocolat noir 70% | B14: Transgourmet | C14: kg
A15: Levure chimique | B15: Transgourmet | C15: kg
A16: Vanille (gousse) | B16: Transgourmet | C16: pièce

Sheet Octobre 2026
A1: Octobre 2026
A2: Étiquette : À commander → Commandé → Livré (ou Manquant)
A3: À traiter : | G3: =COUNTIF(G7:G46,"À commander")+COUNTIF(G7:G46,"Commandé")+COUNTIF(G7:G46,"Manquant") | K3: =COUNTIF(K7:K46,"À commander")+COUNTIF(K7:K46,"Commandé")+COUNTIF(K7:K46,"Manquant") | O3: =COUNTIF(O7:O46,"À commander")+COUNTIF(O7:O46,"Commandé")+COUNTIF(O7:O46,"Manquant") | S3: =COUNTIF(S7:S46,"À commander")+COUNTIF(S7:S46,"Commandé")+COUNTIF(S7:S46,"Manquant")
A4: Produit | B4: Fournisseur | C4: Unité | D4: Semaine 1 | H4: Semaine 2 | L4: Semaine 3 | P4: Semaine 4
D6: Stock | E6: Commandé | F6: Reçu | G6: Étiquette | H6: Stock | I6: Commandé | J6: Reçu | K6: Étiquette | L6: Stock | M6: Commandé | N6: Reçu | O6: Étiquette | P6: Stock | Q6: Commandé | R6: Reçu | S6: Étiquette
A7: =IF(Produits!$A$5="","",Produits!$A$5) | B7: =IF(Produits!$A$5="","",Produits!$B$5) | C7: =IF(Produits!$A$5="","",Produits!$C$5) | D7: 8 | E7: 10 | F7: 7 | G7: Manquant | H7: 5 | I7: 10 | J7: 10 | K7: Livré | O7: À commander
A8: =IF(Produits!$A$6="","",Produits!$A$6) | B8: =IF(Produits!$A$6="","",Produits!$B$6) | C8: =IF(Produits!$A$6="","",Produits!$C$6) | D8: 2 | E8: 5 | F8: 5 | G8: Livré | H8: 3 | I8: 3 | J8: 3 | K8: Livré | O8: Commandé
A9: =IF(Produits!$A$7="","",Produits!$A$7) | B9: =IF(Produits!$A$7="","",Produits!$B$7) | C9: =IF(Produits!$A$7="","",Produits!$C$7) | D9: 6 | E9: 10 | F9: 10 | G9: Livré | H9: 7 | I9: 5 | J9: 5 | K9: Livré | O9: À commander
A10: =IF(Produits!$A$8="","",Produits!$A$8) | B10: =IF(Produits!$A$8="","",Produits!$B$8) | C10: =IF(Produits!$A$8="","",Produits!$C$8) | D10: 1 | E10: 3 | F10: 3 | G10: Livré | H10: 2 | I10: 0 | J10: 0 | K10: Rien à commander | O10: Rien à commander
A11: =IF(Produits!$A$9="","",Produits!$A$9) | B11: =IF(Produits!$A$9="","",Produits!$B$9) | C11: =IF(Produits!$A$9="","",Produits!$C$9) | D11: 3 | E11: 5 | F11: 5 | G11: Livré | H11: 4 | I11: 5 | J11: 5 | K11: Livré | O11: Commandé
A12: =IF(Produits!$A$10="","",Produits!$A$10) | B12: =IF(Produits!$A$10="","",Produits!$B$10) | C12: =IF(Produits!$A$10="","",Produits!$C$10) | D12: 4 | E12: 12 | F12: 12 | G12: Livré | H12: 5 | I12: 10 | J12: 10 | K12: Livré | O12: Commandé
A13: =IF(Produits!$A$11="","",Produits!$A$11) | B13: =IF(Produits!$A$11="","",Produits!$B$11) | C13: =IF(Produits!$A$11="","",Produits!$C$11) | D13: 3 | E13: 6 | F13: 6 | G13: Livré | H13: 4 | I13: 6 | J13: 6 | K13: Livré | O13: À commander
A14: =IF(Produits!$A$12="","",Produits!$A$12) | B14: =IF(Produits!$A$12="","",Produits!$B$12) | C14: =IF(Produits!$A$12="","",Produits!$C$12) | D14: 40 | E14: 90 | F14: 90 | G14: Livré | H14: 50 | I14: 60 | J14: 60 | K14: Livré | O14: Commandé
A15: =IF(Produits!$A$13="","",Produits!$A$13) | B15: =IF(Produits!$A$13="","",Produits!$B$13) | C15: =IF(Produits!$A$13="","",Produits!$C$13) | D15: 1.5 | E15: 3 | F15: 2 | G15: Manquant | H15: 2 | I15: 2 | J15: 2 | K15: Livré | O15: À commander
A16: =IF(Produits!$A$14="","",Produits!$A$14) | B16: =IF(Produits!$A$14="","",Produits!$B$14) | C16: =IF(Produits!$A$14="","",Produits!$C$14) | D16: 2 | E16: 2 | F16: 2 | G16: Livré | H16: 2 | I16: 2 | J16: 2 | K16: Livré | O16: Rien à commander
A17: =IF(Produits!$A$15="","",Produits!$A$15) | B17: =IF(Produits!$A$15="","",Produits!$B$15) | C17: =IF(Produits!$A$15="","",Produits!$C$15) | D17: 0.4 | E17: 1 | F17: 1 | G17: Livré | H17: 0.6 | I17: 0 | J17: 0 | K17: Rien à commander | O17: Rien à commander
A18: =IF(Produits!$A$16="","",Produits!$A$16) | B18: =IF(Produits!$A$16="","",Produits!$B$16) | C18: =IF(Produits!$A$16="","",Produits!$C$16) | D18: 6 | E18: 0 | F18: 0 | G18: Rien à commander | H18: 6 | I18: 0 | J18: 0 | K18: Rien à commander | O18: Rien à commander
A19: =IF(Produits!$A$17="","",Produits!$A$17) | B19: =IF(Produits!$A$17="","",Produits!$B$17) | C19: =IF(Produits!$A$17="","",Produits!$C$17)
A20: =IF(Produits!$A$18="","",Produits!$A$18) | B20: =IF(Produits!$A$18="","",Produits!$B$18) | C20: =IF(Produits!$A$18="","",Produits!$C$18)
A21: =IF(Produits!$A$19="","",Produits!$A$19) | B21: =IF(Produits!$A$19="","",Produits!$B$19) | C21: =IF(Produits!$A$19="","",Produits!$C$19)
A22: =IF(Produits!$A$20="","",Produits!$A$20) | B22: =IF(Produits!$A$20="","",Produits!$B$20) | C22: =IF(Produits!$A$20="","",Produits!$C$20)
A23: =IF(Produits!$A$21="","",Produits!$A$21) | B23: =IF(Produits!$A$21="","",Produits!$B$21) | C23: =IF(Produits!$A$21="","",Produits!$C$21)
A24: =IF(Produits!$A$22="","",Produits!$A$22) | B24: =IF(Produits!$A$22="","",Produits!$B$22) | C24: =IF(Produits!$A$22="","",Produits!$C$22)
A25: =IF(Produits!$A$23="","",Produits!$A$23) | B25: =IF(Produits!$A$23="","",Produits!$B$23) | C25: =IF(Produits!$A$23="","",Produits!$C$23)
A26: =IF(Produits!$A$24="","",Produits!$A$24) | B26: =IF(Produits!$A$24="","",Produits!$B$24) | C26: =IF(Produits!$A$24="","",Produits!$C$24)
A27: =IF(Produits!$A$25="","",Produits!$A$25) | B27: =IF(Produits!$A$25="","",Produits!$B$25) | C27: =IF(Produits!$A$25="","",Produits!$C$25)
A28: =IF(Produits!$A$26="","",Produits!$A$26) | B28: =IF(Produits!$A$26="","",Produits!$B$26) | C28: =IF(Produits!$A$26="","",Produits!$C$26)
A29: =IF(Produits!$A$27="","",Produits!$A$27) | B29: =IF(Produits!$A$27="","",Produits!$B$27) | C29: =IF(Produits!$A$27="","",Produits!$C$27)
A30: =IF(Produits!$A$28="","",Produits!$A$28) | B30: =IF(Produits!$A$28="","",Produits!$B$28) | C30: =IF(Produits!$A$28="","",Produits!$C$28)
A31: =IF(Produits!$A$29="","",Produits!$A$29) | B31: =IF(Produits!$A$29="","",Produits!$B$29) | C31: =IF(Produits!$A$29="","",Produits!$C$29)
A32: =IF(Produits!$A$30="","",Produits!$A$30) | B32: =IF(Produits!$A$30="","",Produits!$B$30) | C32: =IF(Produits!$A$30="","",Produits!$C$30)
A33: =IF(Produits!$A$31="","",Produits!$A$31) | B33: =IF(Produits!$A$31="","",Produits!$B$31) | C33: =IF(Produits!$A$31="","",Produits!$C$31)
A34: =IF(Produits!$A$32="","",Produits!$A$32) | B34: =IF(Produits!$A$32="","",Produits!$B$32) | C34: =IF(Produits!$A$32="","",Produits!$C$32)
A35: =IF(Produits!$A$33="","",Produits!$A$33) | B35: =IF(Produits!$A$33="","",Produits!$B$33) | C35: =IF(Produits!$A$33="","",Produits!$C$33)
A36: =IF(Produits!$A$34="","",Produits!$A$34) | B36: =IF(Produits!$A$34="","",Produits!$B$34) | C36: =IF(Produits!$A$34="","",Produits!$C$34)
A37: =IF(Produits!$A$35="","",Produits!$A$35) | B37: =IF(Produits!$A$35="","",Produits!$B$35) | C37: =IF(Produits!$A$35="","",Produits!$C$35)
A38: =IF(Produits!$A$36="","",Produits!$A$36) | B38: =IF(Produits!$A$36="","",Produits!$B$36) | C38: =IF(Produits!$A$36="","",Produits!$C$36)
A39: =IF(Produits!$A$37="","",Produits!$A$37) | B39: =IF(Produits!$A$37="","",Produits!$B$37) | C39: =IF(Produits!$A$37="","",Produits!$C$37)
A40: =IF(Produits!$A$38="","",Produits!$A$38) | B40: =IF(Produits!$A$38="","",Produits!$B$38) | C40: =IF(Produits!$A$38="","",Produits!$C$38)
A41: =IF(Produits!$A$39="","",Produits!$A$39) | B41: =IF(Produits!$A$39="","",Produits!$B$39) | C41: =IF(Produits!$A$39="","",Produits!$C$39)
...
